Workbook
Name __HDV50: #REF!
Name __HDV50: #REF!
Name __HDV50: #REF!
Name __LDV50: #REF!
Name __LDV50: #REF!
Name __LDV50: #REF!
Name _1995_Implicit_GDP_Deflator: #REF!
Name _1995_Implicit_GDP_Deflator: #REF!
Name _1995_Implicit_GDP_Deflator: #REF!
Name _2001_Implicit_GDP_Deflator: #REF!
Name _2001_Implicit_GDP_Deflator: #REF!
Name _2001_Implicit_GDP_Deflator: #REF!
Name Age_of_car: #REF!
Name Age_of_car: #REF!
Name Age_of_car: #REF!
Name AnswerData: #REF!
Name avg_water_heater_PJ: '[1]AEO HW'!$B$33
Name bprint: #REF!
Name btu_per_watthr: #REF!
Name btu_per_watthr: #REF!
Name btu_per_watthr: #REF!
Name CAPCST: '[2]AEO16 Com Tech'!$H$103:$H$4268
Name CMM_SUPPLY_CRV_TABLE: [3]cum2025curves!#REF!
Name conv: #REF!
Name conv: #REF!
Name conv: #REF!
Name cprint: #REF!
Name CRI: '[2]AEO16 Com Tech'!$AF$103:$AF$4268
Name days_per_year: #REF!
Name days_per_year: #REF!
Name days_per_year: #REF!
Name Diesel_Car_CO: #REF!
Name Diesel_Car_CO: #REF!
Name Diesel_Car_CO: #REF!
Name Diesel_Car_Nox: #REF!
Name Diesel_Car_Nox: #REF!
Name Diesel_Car_Nox: #REF!
Name Diesel_Car_PM: #REF!
Name Diesel_Car_PM: #REF!
Name Diesel_Car_PM: #REF!
Name Diesel_Car_VOCs: #REF!
Name Diesel_Car_VOCs: #REF!
Name Diesel_Car_VOCs: #REF!
Name Diesel_HDT_CO: #REF!
Name Diesel_HDT_CO: #REF!
Name Diesel_HDT_CO: #REF!
Name Diesel_HDT_NOx: #REF!
Name Diesel_HDT_NOx: #REF!
Name Diesel_HDT_NOx: #REF!
Name Diesel_HDT_PM: #REF!
Name Diesel_HDT_PM: #REF!
Name Diesel_HDT_PM: #REF!
Name Diesel_HDT_SO2: #REF!
Name Diesel_HDT_SO2: #REF!
Name Diesel_HDT_SO2: #REF!
Name Diesel_HDT_VOCs: #REF!
Name Diesel_HDT_VOCs: #REF!
Name Diesel_HDT_VOCs: #REF!
Name Diesel_LDT_CO: #REF!
Name Diesel_LDT_CO: #REF!

Sheet ANSv6.0-Commodities
A1: ANSWER-Commodities
B7: CommName | C7: CommDesc | D7: CommUnit | E7: Set Memberships | F7: Comment

Sheet ANSv6.1-Commodities
A1: ANSWER-Commodities
B7: CommName | C7: CommDesc | D7: CommUnit | E7: Set Memberships | F7: Comment

Sheet Commodities
B6: ~FI_Comm
B7: Region | C7: Csets | D7: CommName | E7: CommDesc | F7: Unit | G7: LimType | H7: CTSLvl | I7: PeakTS | J7: Ctype | O7: Comment
B24: *Demands
B25: R2,R3,R4,R5,R6 | C25: DEM | D25: TL | E25: Transportation Light Duty | F25: bn-vmt
B26: *Energy Carriers
B27: R2,R3,R4,R5,R6 | C27: NRG | D27: TRNDSL | E27: DSL to TRN | F27: PJ
B28: R2,R3,R4,R5,R6 | C28: NRG | D28: TLGSL | E28: GSL to TRN | F28: PJ
B29: *R2,R3,R4,R5,R6 | C29: NRG | D29: TLE85X | E29: E85X to TL | F29: PJ
B30: *R2,R3,R4,R5,R6 | C30: NRG | D30: TRNCNG | E30: CNG to TRN | F30: PJ
B31: *R2,R3,R4,R5,R6 | C31: NRG | D31: TRNLPGX | E31: LPGX to TRN | F31: PJ
B32: R2,R3,R4,R5,R6 | C32: NRG | D32: TRNELC | E32: ELC to TRN | F32: PJ
B33: *Energy Carriers
B34: R2,R3,R4,R5,R6 | C34: NRG | D34: ELC | E34: Electricity | F34: PJ
B35: *R2,R3,R4,R5,R6 | C35: NRG | D35: TRNNGA | E35: Natural Gas to Transportation Sector | F35: PJ
B36: *R2,R3,R4,R5,R6 | C36: NRG | D36: TRNCNGH | E36: CNG to TRN - Heavy Duty Vehicles | F36: PJ
B37: R2,R3,R4,R5,R6 | C37: NRG | D37: TRNCNGL | E37: CNG to TRN - Light Duty Vehicles | F37: PJ
B38: *R2,R3,R4,R5,R6 | C38: NRG | D38: TRNCNGX | E38: CNGX to TRN | F38: PJ
B39: *R2,R3,R4,R5,R6 | C39: NRG | D39: TRDSLL | E39: DSLL to Blend | F39: PJ
B40: *R2,R3,R4,R5,R6 | C40: NRG | D40: TRDSLU | E40: DSLU to Blend | F40: PJ
B41: *R2,R3,R4,R5,R6 | C41: NRG | D41: TRNDSLB | E41: DSL combo of DSLL and DSLU | F41: PJ
B42: *R2,R3,R4,R5,R6 | C42: NRG | D42: TRNE10 | E42: E10 Blend | F42: PJ
B43: *R2,R3,R4,R5,R6 | C43: NRG | D43: TRNE85 | E43: E85 Blend | F43: PJ
B44: *R2,R3,R4,R5,R6 | C44: NRG | D44: TRNETH | E44: Ethanol to Transportation Sector | F44: PJ
B45: *R2,R3,R4,R5,R6 | C45: NRG | D45: TRGSLC1 | E45: CONV GSL to TRN after Collection | F45: PJ
... B63: R2,R3,R4,R5,R6 | C63: NRG | D63: ZZDMY | E63: Dummy commodity | F63: PJ
B64: *Emissions Commodities
B65: *R2,R3,R4,R5,R6 | C65: ENV | D65: CO2 | E65: Carbon dioxide emissions | F65: Mt
B66: R2,R3,R4,R5,R6 | C66: ENV | D66: NOX | E66: NOx emissions | F66: kt
B67: R2,R3,R4,R5,R6 | C67: ENV | D67: SO2 | E67: SO2 emissions | F67: kt
B68: R2,R3,R4,R5,R6 | C68: ENV | D68: PM10 | E68: PM10 emissions | F68: kt
B69: *R2,R3,R4,R5,R6 | C69: ENV | D69: PM25 | E69: PM2.5 emissions | F69: kt
B70: *R2,R3,R4,R5,R6 | C70: ENV | D70: CO | E70: Carbon monoxide | F70: kt
B71: *R2,R3,R4,R5,R6 | C71: ENV | D71: N2O | E71: Nitrous oxide | F71: kt
B72: *R2,R3,R4,R5,R6 | C72: ENV | D72: CH4 | E72: Methane | F72: kt
B73: *R2,R3,R4,R5,R6 | C73: ENV | D73: VOC | E73: VOCs | F73: kt
B74: *R2,R3,R4,R5,R6 | C74: ENV | D74: NH3 | E74: Ammonia | F74: kt
B75: *R2,R3,R4,R5,R6 | C75: ENV | D75: BC | E75: Black carbon | F75: kt
B76: *R2,R3,R4,R5,R6 | C76: ENV | D76: OC | E76: Organic carbon | F76: kt
... B81: *R2,R3,R4,R5,R6 | C81: ENV | D81: PM25T | E81: Transportation sector PM25 | F81: kt

Sheet ANSv6.0-Technologies
A1: ANSWER-Technologies
B7: TechName | C7: TechDesc | D7: TACTUnit | E7: TCAPUnit | F7: Set Memberships | G7: Comment

Sheet ANSv6.1-Technologies
A1: ANSWER-Technologies
B7: TechName | C7: TechDesc | D7: TACTUnit | E7: TCAPUnit | F7: Set Memberships | G7: Comment

Sheet Technologies
B6: ~FI_Process
B7: Sets | C7: TechName | D7: TechDesc | E7: Tact | F7: Tcap | G7: PrimaryCG | H7: Vintage | M7: Region
B8: * Light Duty Vehicle Demand Technologies
B9: DMD | C9: =TechData_All!A9 -> TLMCGSLC11 | D9: =TechData_All!C9 -> TL.GSL.MC.CONV.2011 | E9: bn-vmt | F9: bn-vmt/a | M9: R2,R3,R4,R5,R6
B10: DMD | C10: =TechData_All!A10 -> TLMCELC100 | D10: =TechData_All!C10 -> TL.ELC.MC.ELC100 | E10: bn-vmt | F10: bn-vmt/a | M10: R2,R3,R4,R5,R6
B11: DMD | C11: =TechData_All!A11 -> TLMCELC200 | D11: =TechData_All!C11 -> TL.ELC.MC.ELC200 | E11: bn-vmt | F11: bn-vmt/a | M11: R2,R3,R4,R5,R6
B12: DMD | C12: =TechData_All!A12 -> TLCGSLC11 | D12: =TechData_All!C12 -> TL.GSL.C.CONV.2011 | E12: bn-vmt | F12: bn-vmt/a | M12: R2,R3,R4,R5,R6
B13: DMD | C13: =TechData_All!A13 -> TLCELC100 | D13: =TechData_All!C13 -> TL.ELC.C.ELC100 | E13: bn-vmt | F13: bn-vmt/a | M13: R2,R3,R4,R5,R6
B14: DMD | C14: =TechData_All!A14 -> TLCELC200 | D14: =TechData_All!C14 -> TL.ELC.C.ELC200 | E14: bn-vmt | F14: bn-vmt/a | M14: R2,R3,R4,R5,R6
B15: DMD | C15: =TechData_All!A15 -> TLCDSL11 | D15: =TechData_All!C15 -> TL.DSL.C.DSL.2011 | E15: bn-vmt | F15: bn-vmt/a | M15: R2,R3,R4,R5,R6
B16: DMD | C16: =TechData_All!A16 -> TLCCNG11 | D16: =TechData_All!C16 -> TL.CNG.C.CNG.2011 | E16: bn-vmt | F16: bn-vmt/a | M16: R2,R3,R4,R5,R6
B17: DMD | C17: =TechData_All!A17 -> TLCCNGX11 | D17: =TechData_All!C17 -> TL.CNGX.C.CNGX.2011 | E17: bn-vmt | F17: bn-vmt/a | M17: R2,R3,R4,R5,R6
B18: DMD | C18: =TechData_All!A18 -> *TLCDHEV15 | D18: =TechData_All!C18 -> TL.DSL.C.DHEV.2015 | E18: bn-vmt | F18: bn-vmt/a | M18: *R2,R3,R4,R5,R6
B19: DMD | C19: =TechData_All!A19 -> TLCETHX11 | D19: =TechData_All!C19 -> TL.E85X.C.ETHX.2011 | E19: bn-vmt | F19: bn-vmt/a | M19: R2,R3,R4,R5,R6
B20: DMD | C20: =TechData_All!A20 -> TLCFCH11 | D20: =TechData_All!C20 -> TL.H2.C.FCH.2011 | E20: bn-vmt | F20: bn-vmt/a | M20: *R2,R3,R4,R5,R6
... B23: DMD | C23: =TechData_All!A23 -> TLCGPHEV10 | D23: =TechData_All!C23 -> TL.GSL.C.PHEV.2011 | E23: bn-vmt | F23: bn-vmt/a | M23: R2,R3,R4,R5,R6
B24: DMD | C24: =TechData_All!A26 -> TLFGSLC11 | D24: =TechData_All!C26 -> TL.GSL.F.CONV.2011 | E24: bn-vmt | F24: bn-vmt/a | M24: R2,R3,R4,R5,R6
B25: DMD | C25: =TechData_All!A27 -> TLFELC100 | D25: =TechData_All!C27 -> Electric fullsize car w/100 mi range | E25: bn-vmt | F25: bn-vmt/a | M25: R2,R3,R4,R5,R6
B26: DMD | C26: =TechData_All!A28 -> TLFELC200 | D26: =TechData_All!C28 -> Electric fullsize car w/200 mi range | E26: bn-vmt | F26: bn-vmt/a | M26: R2,R3,R4,R5,R6
B27: DMD | C27: =TechData_All!A29 -> TLFCNG11 | D27: =TechData_All!C29 -> TL.CNG.F.CNG.2011 | E27: bn-vmt | F27: bn-vmt/a | M27: R2,R3,R4,R5,R6
B28: DMD | C28: =TechData_All!A30 -> TLFCNGX11 | D28: =TechData_All!C30 -> TL.CNGX.F.CNGX.2011 | E28: bn-vmt | F28: bn-vmt/a | M28: R2,R3,R4,R5,R6
B29: DMD | C29: =TechData_All!A31 -> *TLFDHEV20 | D29: =TechData_All!C31 -> TL.DSL.F.DHEV.2020 | E29: bn-vmt | F29: bn-vmt/a | M29: *R2,R3,R4,R5,R6
B30: DMD | C30: =TechData_All!A32 -> TLFDSL11 | D30: =TechData_All!C32 -> TL.DSL.F.DSL.2011 | E30: bn-vmt | F30: bn-vmt/a | M30: R2,R3,R4,R5,R6
B31: DMD | C31: =TechData_All!A33 -> TLFETHX11 | D31: =TechData_All!C33 -> TL.E85X.F.ETHX.2011 | E31: bn-vmt | F31: bn-vmt/a | M31: R2,R3,R4,R5,R6
B32: DMD | C32: =TechData_All!A34 -> TLFFCH15 | D32: =TechData_All!C34 -> TL.H2.F.FCH.2015 | E32: bn-vmt | F32: bn-vmt/a | M32: *R2,R3,R4,R5,R6
B33: DMD | C33: =TechData_All!A35 -> TLFGHEV11 | D33: =TechData_All!C35 -> TL.GSL.F.HEV.2011 | E33: bn-vmt | F33: bn-vmt/a | M33: R2,R3,R4,R5,R6
B34: DMD | C34: =TechData_All!A36 -> TLFLPGX11 | D34: =TechData_All!C36 -> TL.LPGX.F.LPGX.2011 | E34: bn-vmt | F34: bn-vmt/a | M34: R2,R3,R4,R5,R6
B35: DMD | C35: =TechData_All!A37 -> TLFGPHEV10 | D35: =TechData_All!C37 -> TL.GSL.F.PHEV.2011 | E35: bn-vmt | F35: bn-vmt/a | M35: R2,R3,R4,R5,R6
B36: DMD | C36: =TechData_All!A40 -> TLMGSLC11 | D36: =TechData_All!C40 -> TL.GSL.M.CONV.2011 | E36: bn-vmt | F36: bn-vmt/a | M36: R2,R3,R4,R5,R6
B37: DMD | C37: =TechData_All!A41 -> *TLMELC100 | D37: =TechData_All!C41 -> Electric minivan w/100 mi range | E37: bn-vmt | F37: bn-vmt/a | M37: *R2,R3,R4,R5,R6
B38: DMD | C38: =TechData_All!A42 -> TLMELC200 | D38: =TechData_All!C42 -> Electric minivan w/200 mi range | E38: bn-vmt | F38: bn-vmt/a | M38: R2,R3,R4,R5,R6
B39: DMD | C39: =TechData_All!A43 -> TLMCNG11 | D39: =TechData_All!C43 -> TL.CNG.M.CNG.2011 | E39: bn-vmt | F39: bn-vmt/a | M39: R2,R3,R4,R5,R6
B40: DMD | C40: =TechData_All!A44 -> TLMCNGX11 | D40: =TechData_All!C44 -> TL.CNGX.M.CNGX.2011 | E40: bn-vmt | F40: bn-vmt/a | M40: R2,R3,R4,R5,R6
B41: DMD | C41: =TechData_All!A45 -> *TLMDHEV15 | D41: =TechData_All!C45 -> TL.DSL.M.DHEV.2015 | E41: bn-vmt | F41: bn-vmt/a | M41: *R2,R3,R4,R5,R6
B42: DMD | C42: =TechData_All!A46 -> TLMDSL11 | D42: =TechData_All!C46 -> TL.DSL.M.DSL.2011 | E42: bn-vmt | F42: bn-vmt/a | M42: R2,R3,R4,R5,R6
B43: DMD | C43: =TechData_All!A47 -> TLMETHX11 | D43: =TechData_All!C47 -> TL.E85X.M.ETHX.2011 | E43: bn-vmt | F43: bn-vmt/a | M43: R2,R3,R4,R5,R6
B44: DMD | C44: =TechData_All!A48 -> TLMFCH15 | D44: =TechData_All!C48 -> TL.H2.M.FCH.2015 | E44: bn-vmt | F44: bn-vmt/a | M44: *R2,R3,R4,R5,R6
B45: DMD | C45: =TechData_All!A49 -> TLMGHEV11 | D45: =TechData_All!C49 -> TL.GSL.M.HEV.2011 | E45: bn-vmt | F45: bn-vmt/a | M45: R2,R3,R4,R5,R6
B46: DMD | C46: =TechData_All!A50 -> TLMLPG11 | D46: =TechData_All!C50 -> TL.LPG1.M.LPG.2011 | E46: bn-vmt | F46: bn-vmt/a | M46: R2,R3,R4,R5,R6
B47: DMD | C47: =TechData_All!A51 -> TLMLPGX11 | D47: =TechData_All!C51 -> TL.LPGX.M.LPGX.2011 | E47: bn-vmt | F47: bn-vmt/a | M47: R2,R3,R4,R5,R6
...

Sheet TechData_All
G1: 2010 | L1: 2010 | M1: 2015 | N1: 2020 | O1: 2025 | P1: 2030 | Q1: 2035 | R1: 2040 | S1: 2045 | T1: 2050 | U1: 2055 | AJ1: TechData
F6: ~FI_T
A7: TechName | B7: *Old_TechName | C7: *TechDesc | D7: *Units | E7: CommIN | F7: CommOUT | G7: NCAP_BND~2010 | H7: Share~UP | I7: NCAP_START | J7: *NCAP_START | K7: NCAP_TLIFE | L7: NCAP_COST~2010 | M7: NCAP_COST~2015 | N7: NCAP_COST~2020 | O7: NCAP_COST~2025 | P7: NCAP_COST~2030 | Q7: NCAP_COST~2035 | R7: NCAP_COST~2040 | S7: NCAP_COST~2045 | T7: NCAP_COST~2050 | U7: NCAP_COST~2055 | V7: EFF~2010 | W7: EFF~2015 | X7: EFF~2020 | Y7: EFF~2025 | Z7: EFF~2030 | AA7: EFF~2035 | AB7: EFF~2040 | AC7: EFF~2045 | AD7: EFF~2050 | AE7: EFF~2055 | AF7: NCAP_FOM | AG7: NCAP_DRATE | AH7: *NCAP_BND~UP~2010 | AJ7: Region
A8: * | B8: * | AJ8: * Light Duty Vehicle Demand Technologies
A9: TLMCGSLC11 | B9: TLMCCONV10 | C9: TL.GSL.MC.CONV.2011 | D9: bn-vmt, bn-vmt/a | E9: TLGSL | F9: TL | H9: 1 | I9: 2011 | J9: =INDEX(ConsolidatedVehData!$D$22:$D$858,MATCH(B9,ConsolidatedVehData!$A$22:$A$858,0)) -> 2010 | K9: 20 | L9: 3712.5791 | M9: 4299.2343 | N9: 4021.9395 | O9: 3744.6447 | P9: 3793.1888 | Q9: 3817.8798 | R9: 3843.5635 | S9: 3855.1902 | T9: 3866.0737 | U9: =T9 -> 3866.0737 | V9: 0.19166001 | W9: 0.2064227 | X9: 0.20015938 | Y9: 0.21589175 | Z9: 0.23045573 | AA9: 0.23605123 | AB9: 0.24107086 | AC9: 0.241691 | AD9: 0.24218659 | AE9: =AD9 -> 0.24218659 | AF9: =INDEX(ConsolidatedVehData!$AB$22:$AB$858,MATCH(B9,ConsolidatedVehData!$A$22:$A$858,0)) -> #REF! | AG9: 0.18 | AH9: 0 | AJ9: =Technologies!M9 -> R2,R3,R4,R5,R6
A10: TLMCELC100 | B10: TLMCELC | C10: TL.ELC.MC.ELC100 | D10: bn-vmt, bn-vmt/a | E10: TRNELC | F10: TL | G10: =IF($J10<G$1,0,"") | H10: 1 | I10: 2015 | J10: 2015 | K10: 20 | L10: 0 | M10: 5477.8845 | N10: 8085.3899 | O10: 2374.9122 | P10: 2217.2659 | Q10: 2175.3377 | R10: 2152.692 | S10: 2142.3738 | T10: 2136.6045 | U10: =T10 -> 2136.6045 | V10: 0 | W10: 0.85944227 | X10: 0.97494472 | Y10: 0.81749126 | Z10: 0.83015957 | AA10: 0.82928761 | AB10: 0.82870929 | AC10: 0.82855578 | AD10: 0.82863039 | AE10: =AD10 -> 0.82863039 | AF10: =0.5*AF9 -> #REF! | AG10: 0.28 | AH10: 0 | AJ10: =Technologies!M10 -> R2,R3,R4,R5,R6
A11: TLMCELC200 | B11: TLMCELCB | C11: TL.ELC.MC.ELC200 | D11: bn-vmt, bn-vmt/a | E11: TRNELC | F11: TL | G11: =IF($J11<G$1,0,"") | H11: 1 | I11: 2020 | J11: 2020 | K11: 20 | L11: 10354.508 | M11: 7408.9244 | N11: 9315.0119 | O11: 2649.8886 | P11: 2414.1394 | Q11: 2353.3601 | R11: 2319.8834 | S11: 2302.6679 | T11: 2291.7672 | U11: =T11 -> 2291.7672 | V11: 0.59552355 | W11: 0.92912184 | X11: 1.0846238 | Y11: 0.44861171 | Z11: 0.45396177 | AA11: 0.45414417 | AB11: 0.45459692 | AC11: 0.45304073 | AD11: 0.45213833 | AE11: =AD11 -> 0.45213833 | AF11: =0.5*AF9 -> #REF! | AG11: 0.28 | AH11: 0 | AJ11: =Technologies!M11 -> R2,R3,R4,R5,R6
A12: TLCGSLC11 | B12: TLCCONV10 | C12: TL.GSL.C.CONV.2011 | D12: bn-vmt, bn-vmt/a | E12: TLGSL | F12: TL | H12: 1 | I12: 2011 | J12: =INDEX(ConsolidatedVehData!$D$22:$D$858,MATCH(B12,ConsolidatedVehData!$A$22:$A$858,0)) -> 2010 | K12: 20 | L12: 1748.8504 | M12: 1901.0124 | N12: 2466.093 | O12: 2150.7212 | P12: 2202.3614 | Q12: 2227.2998 | R12: 2253.8266 | S12: 2273.1456 | T12: 2291.2155 | U12: =T12 -> 2291.2155 | V12: 0.22757469 | W12: 0.24750373 | X12: 0.25858033 | Y12: 0.29690918 | Z12: 0.31083696 | AA12: 0.31103711 | AB12: 0.31387333 | AC12: 0.31319474 | AD12: 0.31277284 | AE12: =AD12 -> 0.31277284 | AF12: =INDEX(ConsolidatedVehData!$AB$22:$AB$858,MATCH(B12,ConsolidatedVehData!$A$22:$A$858,0)) -> #REF! | AG12: 0.18 | AH12: 0 | AJ12: =Technologies!M12 -> R2,R3,R4,R5,R6
A13: TLCELC100 | B13: TLCELC | C13: TL.ELC.C.ELC100 | D13: bn-vmt, bn-vmt/a | E13: TRNELC | F13: TL | G13: =IF($J13<G$1,0,"") | H13: 1 | I13: 2015 | J13: 2015 | K13: 20 | L13: 3231.3899 | M13: 2911.6157 | N13: 3298.8823 | O13: 864.98095 | P13: 807.11825 | Q13: 794.63399 | R13: 785.75554 | S13: 781.90594 | T13: 780.76753 | U13: =T13 -> 780.76753 | V13: 0.85638231 | W13: 0.85638231 | X13: 0.93986126 | Y13: 0.80791486 | Z13: 0.82064163 | AA13: 0.82094258 | AB13: 0.82145798 | AC13: 0.82158957 | AD13: 0.82145676 | AE13: =AD13 -> 0.82145676 | AF13: =0.5*AF12 -> #REF! | AG13: 0.28 | AH13: 0 | AJ13: =Technologies!M13 -> R2,R3,R4,R5,R6
A14: TLCELC200 | B14: TLCELCB | C14: TL.ELC.C.ELC200 | D14: bn-vmt, bn-vmt/a | E14: TRNELC | F14: TL | G14: =IF($J14<G$1,0,"") | H14: 1 | I14: 2020 | J14: 2020 | K14: 20 | L14: 0 | M14: 0 | N14: 3827.0933 | O14: 2457.8977 | P14: 2231.8283 | Q14: 2172.4737 | R14: 2138.6708 | S14: 2122.9681 | T14: 2112.5633 | U14: =T14 -> 2112.5633 | V14: 0 | W14: 0 | X14: 1.0623621 | Y14: 0.87517546 | Z14: 0.89148181 | AA14: 0.89484281 | AB14: 0.89972484 | AC14: 0.90136399 | AD14: 0.9023557 | AE14: =AD14 -> 0.9023557 | AF14: =0.5*AF12 -> #REF! | AG14: 0.28 | AH14: 0 | AJ14: =Technologies!M14 -> R2,R3,R4,R5,R6
A15: TLCDSL11 | B15: TLCDSL10 | C15: TL.DSL.C.DSL.2011 | D15: bn-vmt, bn-vmt/a | E15: TRNDSL | F15: TL | H15: 1 | I15: 2011 | J15: =INDEX(ConsolidatedVehData!$D$22:$D$858,MATCH(B15,ConsolidatedVehData!$A$22:$A$858,0)) -> 2010 | K15: 20 | L15: 1966.6678 | M15: 2215.9891 | N15: 2784.0095 | O15: 2407.211 | P15: 2444.0793 | Q15: 2467.188 | R15: 2487.8222 | S15: 2504.3427 | T15: 2519.2067 | U15: =T15 -> 2519.2067 | V15: 0.28561862 | W15: 0.31185469 | X15: 0.32167604 | Y15: 0.3371585 | Z15: 0.34630264 | AA15: 0.3466543 | AB15: 0.34829945 | AC15: 0.3465202 | AD15: 0.34503343 | AE15: =AD15 -> 0.34503343 | AF15: =INDEX(ConsolidatedVehData!$AB$22:$AB$858,MATCH(B15,ConsolidatedVehData!$A$22:$A$858,0)) -> #REF! | AG15: 0.24 | AH15: 0 | AJ15: =Technologies!M15 -> R2,R3,R4,R5,R6
A16: TLCCNG11 | B16: TLCCNG10 | C16: TL.CNG.C.CNG.2011 | D16: bn-vmt, bn-vmt/a | E16: TRNCNGL | F16: TL | H16: 1 | I16: 2011 | J16: =INDEX(ConsolidatedVehData!$D$22:$D$858,MATCH(B16,ConsolidatedVehData!$A$22:$A$858,0)) -> 2010 | K16: 20 | L16: 2358.8235 | M16: 2469.0886 | N16: 2911.51 | O16: 1452.4185 | P16: 1455.3022 | Q16: 1455.3466 | R16: 1471.4272 | S16: 1474.6165 | T16: 1476.0495 | U16: =T16 -> 1476.0495 | V16: 0.24668554 | W16: 0.27278546 | X16: 0.28755158 | Y16: 0.21060449 | Z16: 0.22011832 | AA16: 0.21760381 | AB16: 0.21777031 | AC16: 0.21706947 | AD16: 0.21649927 | AE16: =AD16 -> 0.21649927 | AF16: =INDEX(ConsolidatedVehData!$AB$22:$AB$858,MATCH(B16,ConsolidatedVehData!$A$22:$A$858,0)) -> #REF! | AG16: 0.24 | AH16: 0 | AJ16: =Technologies!M16 -> R2,R3,R4,R5,R6
A17: TLCCNGX11 | B17: TLCCNGX10 | C17: TL.CNGX.C.CNGX.2011 | D17: bn-vmt, bn-vmt/a | E17: TRNCNGX | F17: TL | G17: 0 | H17: 1 | I17: 2011 | J17: =INDEX(ConsolidatedVehData!$D$22:$D$858,MATCH(B17,ConsolidatedVehData!$A$22:$A$858,0)) -> 2010 | K17: 20 | L17: 2239.4732 | M17: 2351.055 | N17: 2795.2967 | O17: 1392.1924 | P17: 1395.1176 | Q17: 1395.3633 | R17: 1411.7446 | S17: 1414.856 | T17: 1416.332 | U17: =T17 -> 1416.332 | V17: 0.22859409 | W17: 0.25257915 | X17: 0.26734603 | Y17: 0.19610634 | Z17: 0.2048795 | AA17: 0.20272311 | AB17: 0.20355799 | AC17: 0.20296736 | AD17: 0.20252472 | AE17: =AD17 -> 0.20252472 | AF17: =INDEX(ConsolidatedVehData!$AB$22:$AB$858,MATCH(B17,ConsolidatedVehData!$A$22:$A$858,0)) -> #REF! | AG17: 0.24 | AH17: 0 | AJ17: =Technologies!M17 -> R2,R3,R4,R5,R6
A18: *TLCDHEV15 | B18: TLCDHEV15 | C18: TL.DSL.C.DHEV.2015 | D18: bn-vmt, bn-vmt/a | E18: TRNDSL | F18: TL | H18: 1 | I18: 2020 | J18: 2020 | K18: 20 | L18: 0 | M18: 0 | N18: 0 | O18: 0 | P18: 0 | Q18: 0 | R18: 0 | S18: 0 | T18: 0 | U18: =T18 -> 0 | V18: 0 | W18: 0 | X18: 0 | Y18: 0 | Z18: 0 | AA18: 0 | AB18: 0 | AC18: 0 | AD18: 0 | AE18: =AD18 -> 0 | AJ18: =Technologies!M18 -> *R2,R3,R4,R5,R6
A19: TLCETHX11 | B19: TLCETHX10 | C19: TL.E85X.C.ETHX.2011 | D19: bn-vmt, bn-vmt/a | E19: TLE85X | F19: TL | H19: 1 | I19: 2011 | J19: =INDEX(ConsolidatedVehData!$D$22:$D$858,MATCH(B19,ConsolidatedVehData!$A$22:$A$858,0)) -> 2010 | K19: 20 | L19: 1757.5977 | M19: 1909.6327 | N19: 2474.4068 | O19: 2158.0922 | P19: 2209.7187 | Q19: 2234.5437 | R19: 2260.9156 | S19: 2280.1852 | T19: 2298.2913 | U19: =T19 -> 2298.2913 | V19: 0.22981262 | W19: 0.24997875 | X19: 0.26097025 | Y19: 0.29964882 | Z19: 0.3137066 | AA19: 0.31382515 | AB19: 0.31658023 | AC19: 0.31587693 | AD19: 0.31548409 | AE19: =AD19 -> 0.31548409 | AF19: =INDEX(ConsolidatedVehData!$AB$22:$AB$858,MATCH(B19,ConsolidatedVehData!$A$22:$A$858,0)) -> #REF! | AG19: 0.18 | AH19: 0 | AJ19: =Technologies!M19 -> R2,R3,R4,R5,R6
A20: TLCFCH11 | B20: TLCFCH10 | C20: TL.H2.C.FCH.2011 | D20: bn-vmt, bn-vmt/a | E20: TRNH2 | F20: TL | H20: 1 | I20: 2011 | J20: =INDEX(ConsolidatedVehData!$D$22:$D$858,MATCH(B20,ConsolidatedVehData!$A$22:$A$858,0)) -> 2010 | K20: 20 | L20: =M20 -> 6353.3245 | M20: 6353.3245 | N20: 5699.9065 | O20: 4601.7849 | P20: 4195.0068 | Q20: 3880.7048 | R20: 3630.7102 | S20: 3435.624 | T20: 3280.9057 | U20: =T20 -> 3280.9057 | V20: =W20 -> 0.35093368 | W20: 0.35093368 | X20: 0.36515866 | Y20: 0.35101908 | Z20: 0.35524503 | AA20: 0.35650584 | AB20: 0.35825788 | AC20: 0.3588399 | AD20: 0.35917241 | AE20: =AD20 -> 0.35917241 | AF20: =INDEX(ConsolidatedVehData!$AB$22:$AB$858,MATCH(B20,ConsolidatedVehData!$A$22:$A$858,0)) -> #REF! | AG20: 0.28 | AH20: 0 | AJ20: =Technologies!M20 -> *R2,R3,R4,R5,R6
A21: TLCGHEV11 | B21: TLCHEV10 | C21: TL.GSL.C.HEV.2011 | D21: bn-vmt, bn-vmt/a | E21: TLGSL | F21: TL | H21: 1 | I21: 2011 | J21: =INDEX(ConsolidatedVehData!$D$22:$D$858,MATCH(B21,ConsolidatedVehData!$A$22:$A$858,0)) -> 2010 | K21: 20 | L21: 2045.0717 | M21: 2310.5405 | N21: 2798.8912 | O21: 2241.7542 | P21: 2260.4491 | Q21: 2270.3986 | R21: 2285.5443 | S21: 2297.8918 | T21: 2308.9777 | U21: =T21 -> 2308.9777 | V21: 0.32799402 | W21: 0.35888038 | X21: 0.36700087 | Y21: 0.41269668 | Z21: 0.4283797 | AA21: 0.42446001 | AB21: 0.42498343 | AC21: 0.42304113 | AD21: 0.42188661 | AE21: =AD21 -> 0.42188661 | AF21: =INDEX(ConsolidatedVehData!$AB$22:$AB$858,MATCH(B21,ConsolidatedVehData!$A$22:$A$858,0)) -> #REF! | AG21: 0.24 | AH21: 0 | AJ21: =Technologies!M21 -> R2,R3,R4,R5,R6
A22: TLCLPGX11 | B22: TLCLPGX10 | C22: TL.LPGX.C.LPGX.2011 | D22: bn-vmt, bn-vmt/a | E22: TRNLPGX | F22: TL | G22: 0 | H22: 1 | I22: 2011 | J22: =INDEX(ConsolidatedVehData!$D$22:$D$858,MATCH(B22,ConsolidatedVehData!$A$22:$A$858,0)) -> 2010 | K22: 20 | L22: 2185.701 | M22: 2298.0063 | N22: 2742.8219 | O22: 1363.9481 | P22: 1366.8996 | Q22: 1367.3921 | R22: 1383.2663 | S22: 1386.3685 | T22: 1387.8669 | U22: =T22 -> 1387.8669 | V22: 0.22859558 | W22: 0.25257915 | X22: 0.26791547 | Y22: 0.19666915 | Z22: 0.20534171 | AA22: 0.20347386 | AB22: 0.20408735 | AC22: 0.20350064 | AD22: 0.20301152 | AE22: =AD22 -> 0.20301152 | AF22: =INDEX(ConsolidatedVehData!$AB$22:$AB$858,MATCH(B22,ConsolidatedVehData!$A$22:$A$858,0)) -> #REF! | AG22: 0.24 | AH22: 0 | AJ22: =Technologies!M22 -> R2,R3,R4,R5,R6
A23: TLCGPHEV10 | B23: TLCPHVG10 | C23: TL.GSL.C.PHEV.2011 | D23: bn-vmt, bn-vmt/a | E23: TLGSL | H23: =1-H24 -> #REF! | I23: 2011 | J23: =INDEX(ConsolidatedVehData!$D$22:$D$858,MATCH(B23,ConsolidatedVehData!$A$22:$A$858,0)) -> 2010 | K23: 20 | L23: =M23 -> 2523.1024 | M23: 2523.1024 | N23: 2866.7614 | O23: 2599.4581 | P23: 2562.0364 | Q23: 2530.4634 | R23: 2522.7612 | S23: 2525.1092 | T23: 2530.9021 | U23: =T23 -> 2530.9021 | V23: 0 | W23: 0.38308764 | X23: 0.40544253 | Y23: 0.3695289 | Z23: 0.38301035 | AA23: 0.38358568 | AB23: 0.38653686 | AC23: 0.38620726 | AD23: 0.38601724 | AE23: =AD23 -> 0.38601724 | AF23: =INDEX(ConsolidatedVehData!$AB$22:$AB$858,MATCH(B23,ConsolidatedVehData!$A$22:$A$858,0)) -> #REF! | AG23: 0.28 | AH23: 0 | AJ23: =Technologies!M23 -> R2,R3,R4,R5,R6
E24: TRNELC | H24: =INDEX(ConsolidatedVehData!$AG$22:$AG$858,MATCH(B23,ConsolidatedVehData!$A$22:$A$858,0)) -> #REF!
F25: TL
A26: TLFGSLC11 | B26: TLFCONV10 | C26: TL.GSL.F.CONV.2011 | D26: bn-vmt, bn-vmt/a | E26: TLGSL | F26: TL | H26: 1 | I26: 2011 | J26: =INDEX(ConsolidatedVehData!$D$22:$D$858,MATCH(B26,ConsolidatedVehData!$A$22:$A$858,0)) -> 2010 | K26: 20 | L26: 2179.1253 | M26: 2184.927 | N26: 2278.4535 | O26: 2051.7269 | P26: 2101.5781 | Q26: 2123.2134 | R26: 2148.88 | S26: 2168.9391 | T26: 2187.4473 | U26: =T26 -> 2187.4473 | V26: 0.22579871 | W26: 0.23205197 | X26: 0.28321835 | Y26: 0.31323662 | Z26: 0.32667799 | AA26: 0.3234353 | AB26: 0.32541914 | AC26: 0.32429831 | AD26: 0.3240026 | AE26: =AD26 -> 0.3240026 | AF26: =INDEX(ConsolidatedVehData!$AB$22:$AB$858,MATCH(B26,ConsolidatedVehData!$A$22:$A$858,0)) -> #REF! | AG26: 0.18 | AH26: 0 | AJ26: =Technologies!M24 -> R2,R3,R4,R5,R6
A27: TLFELC100 | B27: TLFELC | C27: Electric fullsize car w/100 mi range | D27: bn-vmt, bn-vmt/a | E27: TRNELC | F27: TL | G27: =IF($J27<G$1,0,"") | H27: 1 | I27: 2015 | J27: 2015 | K27: 20 | L27: 0 | M27: 3177.0824 | N27: 3098.4757 | O27: 3307.3787 | P27: 3165.3446 | Q27: 3123.8024 | R27: 3107.4457 | S27: 3095.8173 | T27: 3089.6312 | U27: =T27 -> 3089.6312 | V27: 0 | W27: 0.78511683 | X27: 0.9259943 | Y27: 0.43737237 | Z27: 0.44310991 | AA27: 0.44192602 | AB27: 0.44265342 | AC27: 0.44104703 | AD27: 0.44006058 | AE27: =AD27 -> 0.44006058 | AF27: =0.5*AF26 -> #REF! | AG27: 0.28 | AH27: 0 | AJ27: =Technologies!M25 -> R2,R3,R4,R5,R6
A28: TLFELC200 | B28: TLFELCB | C28: Electric fullsize car w/200 mi range | D28: bn-vmt, bn-vmt/a | E28: TRNELC | F28: TL | G28: =IF($J28<G$1,0,"") | H28: 1 | I28: 2015 | J28: 2020 | K28: 20 | L28: 0 | M28: 5564.2245 | N28: 3851.1125 | O28: 3556.7185 | P28: 3344.6153 | Q28: 3285.9921 | R28: 3259.6683 | S28: 3241.6917 | T28: 3230.6826 | U28: =T28 -> 3230.6826 | V28: 0 | W28: 0.74385125 | X28: 1.0203922 | Y28: 0.83899436 | Z28: 0.85207635 | AA28: 0.85551207 | AB28: 0.86053925 | AC28: 0.86214255 | AD28: 0.86362892 | AE28: =AD28 -> 0.86362892 | AF28: =0.5*AF26 -> #REF! | AG28: 0.28 | AH28: 0 | AJ28: =Technologies!M26 -> R2,R3,R4,R5,R6
A29: TLFCNG11 | B29: TLFCNG10 | C29: TL.CNG.F.CNG.2011 | D29: bn-vmt, bn-vmt/a | E29: TRNCNGL | F29: TL | H29: 1 | I29: 2011 | J29: =INDEX(ConsolidatedVehData!$D$22:$D$858,MATCH(B29,ConsolidatedVehData!$A$22:$A$858,0)) -> 2010 | K29: 20 | L29: 3234.3071 | M29: 3766.3624 | N29: 3294.0991 | O29: 1256.4477 | P29: 1263.0512 | Q29: 1269.7657 | R29: 1277.3889 | S29: 1284.3992 | T29: 1289.0091 | U29: =T29 -> 1289.0091 | V29: 0.21524556 | W29: 0.20358325 | X29: 0.27604705 | Y29: 0.14465131 | Z29: 0.15258005 | AA29: 0.15149485 | AB29: 0.15165203 | AC29: 0.15184142 | AD29: 0.15221818 | AE29: =AD29 -> 0.15221818 | AF29: =INDEX(ConsolidatedVehData!$AB$22:$AB$858,MATCH(B29,ConsolidatedVehData!$A$22:$A$858,0)) -> #REF! | AG29: 0.24 | AH29: 0 | AJ29: =Technologies!M27 -> R2,R3,R4,R5,R6
A30: TLFCNGX11 | B30: TLFCNGX10 | C30: TL.CNGX.F.CNGX.2011 | D30: bn-vmt, bn-vmt/a | E30: TRNCNGX | F30: TL | G30: 0 | H30: 1 | I30: 2011 | J30: =INDEX(ConsolidatedVehData!$D$22:$D$858,MATCH(B30,ConsolidatedVehData!$A$22:$A$858,0)) -> 2010 | K30: 20 | L30: 3115.1547 | M30: 3648.3286 | N30: 3178.4352 | O30: 1208.2291 | P30: 1214.7574 | Q30: 1221.2051 | R30: 1229.3399 | S30: 1236.1255 | T30: 1240.6188 | U30: =T30 -> 1240.6188 | V30: 0.19950468 | W30: 0.188503 | X30: 0.25684155 | Y30: 0.13455921 | Z30: 0.14172782 | AA30: 0.1411638 | AB30: 0.14192617 | AC30: 0.14212214 | AD30: 0.1424639 | AE30: =AD30 -> 0.1424639 | AF30: =INDEX(ConsolidatedVehData!$AB$22:$AB$858,MATCH(B30,ConsolidatedVehData!$A$22:$A$858,0)) -> #REF! | AG30: 0.24 | AH30: 0 | AJ30: =Technologies!M28 -> R2,R3,R4,R5,R6
A31: *TLFDHEV20 | B31: TLFDHEV20 | C31: TL.DSL.F.DHEV.2020 | D31: bn-vmt, bn-vmt/a | E31: TRNDSL | F31: TL | H31: 1 | I31: 2020 | J31: 2020 | K31: 20 | L31: 0 | M31: 0 | N31: 0 | O31: 0 | P31: 0 | Q31: 0 | R31: 0 | S31: 0 | T31: 0 | U31: =T31 -> 0 | V31: 0 | W31: 0 | X31: 0 | Y31: 0 | Z31: 0 | AA31: 0 | AB31: 0 | AC31: 0 | AD31: 0 | AE31: =AD31 -> 0 | AF31: =INDEX(ConsolidatedVehData!$AB$22:$AB$858,MATCH(B31,ConsolidatedVehData!$A$22:$A$858,0)) -> #REF! | AG31: 0.24 | AH31: 0 | AJ31: =Technologies!M29 -> *R2,R3,R4,R5,R6
A32: TLFDSL11 | B32: TLFDSL10 | C32: TL.DSL.F.DSL.2011 | D32: bn-vmt, bn-vmt/a | E32: TRNDSL | F32: TL | H32: 1 | I32: 2011 | J32: =INDEX(ConsolidatedVehData!$D$22:$D$858,MATCH(B32,ConsolidatedVehData!$A$22:$A$858,0)) -> 2010 | K32: 20 | L32: 2363.327 | M32: 2499.9035 | N32: 2579.3047 | O32: 2308.1866 | P32: 2346.1751 | Q32: 2366.7932 | R32: 2385.387 | S32: 2402.2835 | T32: 2417.3441 | U32: =T32 -> 2417.3441 | V32: 0.28280164 | W32: 0.29238549 | X32: 0.34441447 | Y32: 0.35329348 | Z32: 0.36168984 | AA32: 0.35997545 | AB32: 0.36001047 | AC32: 0.35778709 | AD32: 0.3562221 | AE32: =AD32 -> 0.3562221 | AF32: =INDEX(ConsolidatedVehData!$AB$22:$AB$858,MATCH(B32,ConsolidatedVehData!$A$22:$A$858,0)) -> #REF! | AG32: 0.24 | AH32: 0 | AJ32: =Technologies!M30 -> R2,R3,R4,R5,R6
A33: TLFETHX11 | B33: TLFETHX10 | C33: TL.E85X.F.ETHX.2011 | D33: bn-vmt, bn-vmt/a | E33: TLE85X | F33: TL | H33: 1 | I33: 2011 | J33: =INDEX(ConsolidatedVehData!$D$22:$D$858,MATCH(B33,ConsolidatedVehData!$A$22:$A$858,0)) -> 2010 | K33: 20 | L33: 2187.8082 | M33: 2193.5473 | N33: 2286.83 | O33: 2059.1174 | P33: 2108.942 | Q33: 2130.4823 | R33: 2155.919 | S33: 2175.9227 | T33: 2194.3704 | U33: =T33 -> 2194.3704 | V33: 0.22803315 | W33: 0.23437248 | X33: 0.28588027 | Y33: 0.31611825 | Z33: 0.32972952 | AA33: 0.32634247 | AB33: 0.32819896 | AC33: 0.32705964 | AD33: 0.32676928 | AE33: =AD33 -> 0.32676928 | AF33: =INDEX(ConsolidatedVehData!$AB$22:$AB$858,MATCH(B33,ConsolidatedVehData!$A$22:$A$858,0)) -> #REF! | AG33: 0.18 | AH33: 0 | AJ33: =Technologies!M31 -> R2,R3,R4,R5,R6
A34: TLFFCH15 | B34: TLFFCH15 | C34: TL.H2.F.FCH.2015 | D34: bn-vmt, bn-vmt/a | E34: TRNH2 | F34: TL | H34: 1 | I34: 2015 | J34: =INDEX(ConsolidatedVehData!$D$22:$D$858,MATCH(B34,ConsolidatedVehData!$A$22:$A$858,0)) -> 2015 | K34: 20 | L34: 0 | M34: 6562.3822 | N34: 5616.4373 | O34: =N34 -> 5616.4373 | P34: =O34 -> 5616.4373 | Q34: =P34 -> 5616.4373 | R34: =Q34 -> 5616.4373 | S34: =R34 -> 5616.4373 | T34: =S34 -> 5616.4373 | U34: =T34 -> 5616.4373 | V34: 0 | W34: 0.32451983 | X34: 0.35073268 | Y34: 0.33713548 | Z34: 0.3403773 | AA34: 0.34172423 | AB34: 0.34364203 | AC34: 0.34424208 | AD34: 0.34479546 | AE34: =AD34 -> 0.34479546 | AF34: =INDEX(ConsolidatedVehData!$AB$22:$AB$858,MATCH(B34,ConsolidatedVehData!$A$22:$A$858,0)) -> #REF! | AG34: 0.28 | AH34: 0 | AJ34: =Technologies!M32 -> *R2,R3,R4,R5,R6
A35: TLFGHEV11 | B35: TLFHEV10 | C35: TL.GSL.F.HEV.2011 | D35: bn-vmt, bn-vmt/a | E35: TLGSL | F35: TL | H35: 1 | I35: 2011 | J35: =INDEX(ConsolidatedVehData!$D$22:$D$858,MATCH(B35,ConsolidatedVehData!$A$22:$A$858,0)) -> 2010 | K35: 20 | L35: 2486.9194 | M35: 2655.1751 | N35: 2653.098 | O35: 3425.4638 | P35: 3441.2605 | Q35: 3446.8041 | R35: 3462.0924 | S35: 3466.3832 | T35: 3471.5982 | U35: =T35 -> 3471.5982 | V35: 0.32530032 | W35: 0.33647538 | X35: 0.40311534 | Y35: 0.43755224 | Z35: 0.45167565 | AA35: 0.44469431 | AB35: 0.44385239 | AC35: 0.44100435 | AD35: 0.43943756 | AE35: =AD35 -> 0.43943756 | AF35: =INDEX(ConsolidatedVehData!$AB$22:$AB$858,MATCH(B35,ConsolidatedVehData!$A$22:$A$858,0)) -> #REF! | AG35: 0.24 | AH35: 0 | AJ35: =Technologies!M33 -> R2,R3,R4,R5,R6
A36: TLFLPGX11 | B36: TLFLPGX10 | C36: TL.LPGX.F.LPGX.2011 | D36: bn-vmt, bn-vmt/a | E36: TRNLPGX | F36: TL | G36: 0 | H36: 1 | I36: 2011 | J36: =INDEX(ConsolidatedVehData!$D$22:$D$858,MATCH(B36,ConsolidatedVehData!$A$22:$A$858,0)) -> 2010 | K36: 20 | L36: 2656.2576 | M36: 2655.7344 | N36: 2748.0052 | O36: 2477.9709 | P36: 2483.9551 | Q36: 2491.7264 | R36: 2518.7688 | S36: 2523.8147 | T36: 2528.3317 | U36: =T36 -> 2528.3317 | V36: 0.22579725 | W36: 0.23205197 | X36: 0.28290242 | Y36: 0.31267899 | Z36: 0.32600022 | AA36: 0.32277826 | AB36: 0.32477509 | AC36: 0.32364406 | AD36: 0.32332167 | AE36: =AD36 -> 0.32332167 | AF36: =INDEX(ConsolidatedVehData!$AB$22:$AB$858,MATCH(B36,ConsolidatedVehData!$A$22:$A$858,0)) -> #REF! | AG36: 0.24 | AH36: 0 | AJ36: =Technologies!M34 -> R2,R3,R4,R5,R6
A37: TLFGPHEV10 | B37: TLFPHVG10 | C37: TL.GSL.F.PHEV.2011 | D37: bn-vmt, bn-vmt/a | E37: TLGSL | H37: =1-H38 -> #REF! | I37: 2011 | J37: =INDEX(ConsolidatedVehData!$D$22:$D$858,MATCH(B37,ConsolidatedVehData!$A$22:$A$858,0)) -> 2010 | K37: 20 | L37: =M37 -> 3073.2874 | M37: 3073.2874 | N37: 3036.1525 | O37: 2543.3387 | P37: 2500.6987 | Q37: 2464.1416 | R37: 2451.7027 | S37: 2453.0904 | T37: 2458.582 | U37: =T37 -> 2458.582 | V37: 0 | W37: 0.3445613 | X37: 0.41990311 | Y37: 0.38127558 | Z37: 0.39388941 | AA37: 0.39160311 | AB37: 0.39367271 | AC37: 0.3930067 | AD37: 0.39297739 | AE37: =AD37 -> 0.39297739 | AF37: =INDEX(ConsolidatedVehData!$AB$22:$AB$858,MATCH(B37,ConsolidatedVehData!$A$22:$A$858,0)) -> #REF! | AG37: 0.28 | AJ37: =Technologies!M35 -> R2,R3,R4,R5,R6
E38: TRNELC | H38: =INDEX(ConsolidatedVehData!$AG$22:$AG$858,MATCH(B37,ConsolidatedVehData!$A$22:$A$858,0)) -> #REF!
F39: TL
A40: TLMGSLC11 | B40: TLMCONV10 | C40: TL.GSL.M.CONV.2011 | D40: bn-vmt, bn-vmt/a | E40: TLGSL | F40: TL | H40: 1 | I40: 2011 | J40: =INDEX(ConsolidatedVehData!$D$22:$D$858,MATCH(B40,ConsolidatedVehData!$A$22:$A$858,0)) -> 2010 | K40: 20 | L40: 2351.4662 | M40: 2290.0448 | N40: 2474.0619 | O40: 2156.3581 | P40: 2230.9836 | Q40: 2251.4764 | R40: 2264.918 | S40: 2270.7773 | T40: 2276.9184 | U40: =T40 -> 2276.9184 | V40: 0.1717302 | W40: 0.17812069 | X40: 0.19408797 | Y40: 0.2577156 | Z40: 0.28219751 | AA40: 0.28619193 | AB40: 0.29021088 | AC40: 0.29062154 | AD40: 0.290962 | AE40: =AD40 -> 0.290962 | AF40: =INDEX(ConsolidatedVehData!$AB$22:$AB$858,MATCH(B40,ConsolidatedVehData!$A$22:$A$858,0)) -> #REF! | AG40: 0.18 | AH40: 0 | AJ40: =Technologies!M36 -> R2,R3,R4,R5,R6
A41: *TLMELC100 | B41: TLMELC | C41: Electric minivan w/100 mi range | D41: bn-vmt, bn-vmt/a | E41: TRNELC | F41: TL | G41: =IF($J41<G$1,0,"") | H41: 1 | I41: 2020 | J41: 2020 | K41: 20 | AF41: =0.5*AF40 -> #REF! | AG41: 0.28 | AH41: 0 | AJ41: =Technologies!M37 -> *R2,R3,R4,R5,R6
A42: TLMELC200 | B42: TLMELCB | C42: Electric minivan w/200 mi range | D42: bn-vmt, bn-vmt/a | E42: TRNELC | F42: TL | G42: =IF($J42<G$1,0,"") | H42: 1 | I42: 2025 | J42: 2020 | K42: 20 | L42: 0 | M42: 0 | N42: 0 | O42: 4308.6384 | P42: 3966.185 | Q42: 3865.5484 | R42: 3808.5568 | S42: 3773.2593 | T42: 3751.9724 | U42: =T42 -> 3751.9724 | V42: 0 | W42: 0 | X42: 0 | Y42: 0.40134315 | Z42: 0.41106552 | AA42: 0.41594254 | AB42: 0.41744451 | AC42: 0.41874 | AD42: 0.41841515 | AE42: =AD42 -> 0.41841515 | AF42: =0.5*AF40 -> #REF! | AG42: 0.28 | AH42: 0 | AJ42: =Technologies!M38 -> R2,R3,R4,R5,R6
A43: TLMCNG11 | B43: TLMCNG10 | C43: TL.CNG.M.CNG.2011 | D43: bn-vmt, bn-vmt/a | E43: TRNCNGL | F43: TL | H43: 1 | I43: 2011 | J43: =INDEX(ConsolidatedVehData!$D$22:$D$858,MATCH(B43,ConsolidatedVehData!$A$22:$A$858,0)) -> 2010 | K43: 20 | L43: 3112.5723 | M43: 3108.9537 | N43: 3135.9421 | O43: 1381.0306 | P43: 1394.1899 | Q43: 1382.2454 | R43: 1389.6202 | S43: 1386.7896 | T43: 1390.2892 | U43: =T43 -> 1390.2892 | V43: 0.18511771 | W43: 0.18640126 | X43: 0.20024204 | Y43: 0.11349073 | Z43: 0.1226857 | AA43: 0.12382378 | AB43: 0.12597156 | AC43: 0.12595119 | AD43: 0.12645011 | AE43: =AD43 -> 0.12645011 | AF43: =INDEX(ConsolidatedVehData!$AB$22:$AB$858,MATCH(B43,ConsolidatedVehData!$A$22:$A$858,0)) -> #REF! | AG43: 0.24 | AH43: 0 | AJ43: =Technologies!M39 -> R2,R3,R4,R5,R6
A44: TLMCNGX11 | B44: TLMCNGX10 | C44: TL.CNGX.M.CNGX.2011 | D44: bn-vmt, bn-vmt/a | E44: TRNCNGX | F44: TL | G44: 0 | H44: 1 | I44: 2011 | J44: =INDEX(ConsolidatedVehData!$D$22:$D$858,MATCH(B44,ConsolidatedVehData!$A$22:$A$858,0)) -> 2010 | K44: 20 | L44: 3030.8887 | M44: 3027.859 | N44: 3058.7997 | O44: 1349.61 | P44: 1362.1957 | Q44: 1350.8203 | R44: 1358.5732 | S44: 1355.8073 | T44: 1359.157 | U44: =T44 -> 1359.157 | V44: 0.17158124 | W44: 0.17259373 | X44: 0.18659671 | Y44: 0.10545418 | Z44: 0.11400587 | AA44: 0.11534939 | AB44: 0.1174622 | AC44: 0.11736505 | AD44: 0.11782057 | AE44: =AD44 -> 0.11782057 | AF44: =INDEX(ConsolidatedVehData!$AB$22:$AB$858,MATCH(B44,ConsolidatedVehData!$A$22:$A$858,0)) -> #REF! | AG44: 0.24 | AH44: 0 | AJ44: =Technologies!M40 -> R2,R3,R4,R5,R6
...

Sheet TechData-Emis
G1: * | H1: * | I1: * | J1: * | K1: * | L1: * | M1: * | N1: * | O1: * | P1: * | Q1: * | R1: * | S1: * | T1: * | AY1: * | AZ1: * | BA1: * | BB1: * | BC1: * | BD1: * | BE1: * | BF1: * | BG1: * | BH1: * | BI1: * | BJ1: * | BK1: * | BL1: * | BM1: * | BN1: * | BO1: * | BP1: * | BQ1: * | BR1: * | BS1: * | BT1: * | BU1: * | BV1: * | BW1: * | BX1: * | BY1: * | BZ1: * | CA1: * | CB1: * | CC1: * | CD1: * | CE1: * | CF1: * | CG1: * | CH1: * | CI1: * | CJ1: * | CK1: * | CL1: * | CM1: * | CN1: * | CO1: * | CP1: * | CQ1: * | CR1: * | CS1: * | CT1: * | CU1: * | CV1: * | CW1: * | CX1: * | CY1: * | CZ1: * | DA1: * | DB1: * | DC1: * | DD1: * | DE1: * | DF1: * | DG1: * | DH1: * | DI1: * | DJ1: * | DK1: * | DL1: * | DM1: * | DN1: * | DO1: * | DP1: * | DQ1: * | DR1: * | DS1: * | DT1: * | DU1: * | DV1: * | DW1: * | DX1: * | DY1: * | DZ1: * | EA1: * | EB1: * | EC1: * | ED1: * | EE1: * | EF1: * | EG1: * | EH1: * | EI1: * | EJ1: * | EK1: * | EL1: * | EM1: * | EN1: * | EO1: * | EP1: * | EQ1: * | ER1: * | ES1: * | ET1: * | EU1: * | EV1: * | EW1: * | EX1: * | EY1: * | EZ1: * | FA1: * | FB1: * | FC1: * | FD1: * | FE1: * | FF1: * | FG1: * | FH1: * | FI1: * | FJ1: * | FK1: * | FL1: * | FM1: * | FN1: * | FO1: * | FP1: * | FQ1: * | FR1: * | FS1: * | FT1: * | FU1: * | FV1: * | FW1: * | FX1: *
K2: CO2 | L2: CO2 | M2: CO2 | N2: CO2 | O2: CO2 | P2: CO2 | Q2: CO2 | R2: CO2 | S2: CO2 | T2: CO2 | U2: NOX | V2: NOX | W2: NOX | X2: NOX | Y2: NOX | Z2: NOX | AA2: NOX | AB2: NOX | AC2: NOX | AD2: NOX | AE2: SO2 | AF2: SO2 | AG2: SO2 | AH2: SO2 | AI2: SO2 | AJ2: SO2 | AK2: SO2 | AL2: SO2 | AM2: SO2 | AN2: SO2 | AO2: PM10 | AP2: PM10 | AQ2: PM10 | AR2: PM10 | AS2: PM10 | AT2: PM10 | AU2: PM10 | AV2: PM10 | AW2: PM10 | AX2: PM10 | AY2: PM25 | AZ2: PM25 | BA2: PM25 | BB2: PM25 | BC2: PM25 | BD2: PM25 | BE2: PM25 | BF2: PM25 | BG2: PM25 | BH2: PM25 | BI2: CO | BJ2: CO | BK2: CO | BL2: CO | BM2: CO | BN2: CO | BO2: CO | BP2: CO | BQ2: CO | BR2: CO | BS2: VOC | BT2: VOC | BU2: VOC | BV2: VOC | BW2: VOC | BX2: VOC | BY2: VOC | BZ2: VOC | CA2: VOC | CB2: VOC | CC2: NH3 | CD2: NH3 | CE2: NH3 | CF2: NH3 | CG2: NH3 | CH2: NH3 | CI2: NH3 | CJ2: NH3 | CK2: NH3 | CL2: NH3 | CM2: N2O | CN2: N2O | CO2: N2O | CP2: N2O | CQ2: N2O | CR2: N2O | CS2: N2O | CT2: N2O | CU2: N2O | CV2: N2O | CW2: BC | CX2: BC | CY2: BC | CZ2: BC | DA2: BC | DB2: BC | DC2: BC | DD2: BC | DE2: BC | DF2: BC | DG2: OC | DH2: OC | DI2: OC | DJ2: OC | DK2: OC | DL2: OC | DM2: OC | DN2: OC | DO2: OC | DP2: OC | DQ2: CH4 | DR2: CH4 | DS2: CH4 | DT2: CH4 | DU2: CH4 | DV2: CH4 | DW2: CH4 | DX2: CH4 | DY2: CH4 | DZ2: CH4 | EA2: =CONCATENATE(K2,"T") -> CO2T | EB2: =CONCATENATE(L2,"T") -> CO2T | EC2: =CONCATENATE(M2,"T") -> CO2T | ED2: =CONCATENATE(N2,"T") -> CO2T | EE2: =CONCATENATE(O2,"T") -> CO2T | EF2: =CONCATENATE(P2,"T") -> CO2T | EG2: =CONCATENATE(Q2,"T") -> CO2T | EH2: =CONCATENATE(R2,"T") -> CO2T | ... FX2: =CONCATENATE(BH2,"T") -> PM25T
F7: ~FI_T
A8: Region | B8: TechName | C8: *TechDesc | D8: *Units | E8: *CommIN | F8: *CommOUT | G8: *Type | H8: *Fuel | I8: *Adjustment | J8: *Categories for tracking emissions | K8: *ENV_ACT~CO2~2010 | L8: *ENV_ACT~CO2~2015 | M8: *ENV_ACT~CO2~2020 | N8: *ENV_ACT~CO2~2025 | O8: *ENV_ACT~CO2~2030 | P8: *ENV_ACT~CO2~2035 | Q8: *ENV_ACT~CO2~2040 | R8: *ENV_ACT~CO2~2045 | S8: *ENV_ACT~CO2~2050 | T8: *ENV_ACT~CO2~2055 | U8: ENV_ACT~NOX~2010 | V8: ENV_ACT~NOX~2015 | W8: ENV_ACT~NOX~2020 | X8: ENV_ACT~NOX~2025 | Y8: ENV_ACT~NOX~2030 | Z8: ENV_ACT~NOX~2035 | AA8: ENV_ACT~NOX~2040 | AB8: ENV_ACT~NOX~2045 | AC8: ENV_ACT~NOX~2050 | AD8: ENV_ACT~NOX~2055 | AE8: ENV_ACT~SO2~2010 | AF8: ENV_ACT~SO2~2015 | AG8: ENV_ACT~SO2~2020 | AH8: ENV_ACT~SO2~2025 | AI8: ENV_ACT~SO2~2030 | AJ8: ENV_ACT~SO2~2035 | AK8: ENV_ACT~SO2~2040 | AL8: ENV_ACT~SO2~2045 | AM8: ENV_ACT~SO2~2050 | AN8: ENV_ACT~SO2~2055 | AO8: ENV_ACT~PM10~2010 | AP8: ENV_ACT~PM10~2015 | AQ8: ENV_ACT~PM10~2020 | AR8: ENV_ACT~PM10~2025 | AS8: ENV_ACT~PM10~2030 | AT8: ENV_ACT~PM10~2035 | AU8: ENV_ACT~PM10~2040 | AV8: ENV_ACT~PM10~2045 | AW8: ENV_ACT~PM10~2050 | AX8: ENV_ACT~PM10~2055 | AY8: ENV_ACT~PM25~2010 | AZ8: ENV_ACT~PM25~2015 | BA8: ENV_ACT~PM25~2020 | BB8: ENV_ACT~PM25~2025 | BC8: ENV_ACT~PM25~2030 | BD8: ENV_ACT~PM25~2035 | BE8: ENV_ACT~PM25~2040 | BF8: ENV_ACT~PM25~2045 | BG8: ENV_ACT~PM25~2050 | BH8: ENV_ACT~PM25~2055 | BI8: ENV_ACT~CO~2010 | BJ8: ENV_ACT~CO~2015 | BK8: ENV_ACT~CO~2020 | BL8: ENV_ACT~CO~2025 | BM8: ENV_ACT~CO~2030 | BN8: ENV_ACT~CO~2035 | BO8: ENV_ACT~CO~2040 | BP8: ENV_ACT~CO~2045 | BQ8: ENV_ACT~CO~2050 | BR8: ENV_ACT~CO~2055 | BS8: ENV_ACT~VOC~2010 | BT8: ENV_ACT~VOC~2015 | BU8: ENV_ACT~VOC~2020 | BV8: ENV_ACT~VOC~2025 | BW8: ENV_ACT~VOC~2030 | BX8: ENV_ACT~VOC~2035 | BY8: ENV_ACT~VOC~2040 | BZ8: ENV_ACT~VOC~2045 | CA8: ENV_ACT~VOC~2050 | CB8: ENV_ACT~VOC~2055 | CC8: ENV_ACT~NH3~2010 | CD8: ENV_ACT~NH3~2015 | CE8: ENV_ACT~NH3~2020 | CF8: ENV_ACT~NH3~2025 | CG8: ENV_ACT~NH3~2030 | CH8: ENV_ACT~NH3~2035 | CI8: ENV_ACT~NH3~2040 | CJ8: ENV_ACT~NH3~2045 | CK8: ENV_ACT~NH3~2050 | CL8: ENV_ACT~NH3~2055 | CM8: ENV_ACT~N2O~2010 | CN8: ENV_ACT~N2O~2015 | CO8: ENV_ACT~N2O~2020 | CP8: ENV_ACT~N2O~2025 | CQ8: ENV_ACT~N2O~2030 | CR8: ENV_ACT~N2O~2035 | CS8: ENV_ACT~N2O~2040 | CT8: ENV_ACT~N2O~2045 | CU8: ENV_ACT~N2O~2050 | CV8: ENV_ACT~N2O~2055 | CW8: ENV_ACT~BC~2010 | CX8: ENV_ACT~BC~2015 | CY8: ENV_ACT~BC~2020 | CZ8: ENV_ACT~BC~2025 | DA8: ENV_ACT~BC~2030 | DB8: ENV_ACT~BC~2035 | DC8: ENV_ACT~BC~2040 | DD8: ENV_ACT~BC~2045 | DE8: ENV_ACT~BC~2050 | DF8: ENV_ACT~BC~2055 | DG8: *ENV_ACT~OC~2010 | DH8: *ENV_ACT~OC~2015 | DI8: *ENV_ACT~OC~2020 | DJ8: *ENV_ACT~OC~2025 | DK8: *ENV_ACT~OC~2030 | DL8: *ENV_ACT~OC~2035 | DM8: *ENV_ACT~OC~2040 | DN8: *ENV_ACT~OC~2045 | DO8: *ENV_ACT~OC~2050 | DP8: *ENV_ACT~OC~2055 | DQ8: *ENV_ACT~CH4~2010 | DR8: *ENV_ACT~CH4~2015 | DS8: *ENV_ACT~CH4~2020 | DT8: *ENV_ACT~CH4~2025 | DU8: *ENV_ACT~CH4~2030 | DV8: *ENV_ACT~CH4~2035 | DW8: *ENV_ACT~CH4~2040 | DX8: *ENV_ACT~CH4~2045 | DY8: *ENV_ACT~CH4~2050 | DZ8: *ENV_ACT~CH4~2055 | EA8: *ENV_ACT~CO2T~2010 | EB8: *ENV_ACT~CO2T~2015 | EC8: *ENV_ACT~CO2T~2020 | ED8: *ENV_ACT~CO2T~2025 | EE8: *ENV_ACT~CO2T~2030 | EF8: *ENV_ACT~CO2T~2035 | EG8: *ENV_ACT~CO2T~2040 | EH8: *ENV_ACT~CO2T~2045 | EI8: *ENV_ACT~CO2T~2050 | EJ8: *ENV_ACT~CO2T~2055 | EK8: *ENV_ACT~NOXT~2010 | EL8: *ENV_ACT~NOXT~2015 | EM8: *ENV_ACT~NOXT~2020 | EN8: *ENV_ACT~NOXT~2025 | EO8: *ENV_ACT~NOXT~2030 | EP8: *ENV_ACT~NOXT~2035 | EQ8: *ENV_ACT~NOXT~2040 | ER8: *ENV_ACT~NOXT~2045 | ES8: *ENV_ACT~NOXT~2050 | ET8: *ENV_ACT~NOXT~2055 | EU8: *ENV_ACT~SO2T~2010 | EV8: *ENV_ACT~SO2T~2015 | EW8: *ENV_ACT~SO2T~2020 | EX8: *ENV_ACT~SO2T~2025 | EY8: *ENV_ACT~SO2T~2030 | EZ8: *ENV_ACT~SO2T~2035 | FA8: *ENV_ACT~SO2T~2040 | FB8: *ENV_ACT~SO2T~2045 | FC8: *ENV_ACT~SO2T~2050 | FD8: *ENV_ACT~SO2T~2055 | FE8: *ENV_ACT~PM10T~2010 | FF8: *ENV_ACT~PM10T~2015 | FG8: *ENV_ACT~PM10T~2020 | FH8: *ENV_ACT~PM10T~2025 | FI8: *ENV_ACT~PM10T~2030 | FJ8: *ENV_ACT~PM10T~2035 | FK8: *ENV_ACT~PM10T~2040 | FL8: *ENV_ACT~PM10T~2045 | FM8: *ENV_ACT~PM10T~2050 | FN8: *ENV_ACT~PM10T~2055 | FO8: *ENV_ACT~PM25T~2010 | FP8: *ENV_ACT~PM25T~2015 | FQ8: *ENV_ACT~PM25T~2020 | FR8: *ENV_ACT~PM25T~2025 | FS8: *ENV_ACT~PM25T~2030 | FT8: *ENV_ACT~PM25T~2035 | FU8: *ENV_ACT~PM25T~2040 | FV8: *ENV_ACT~PM25T~2045 | FW8: *ENV_ACT~PM25T~2050 | FX8: *ENV_ACT~PM25T~2055
A9: * New Vehicles | EA9: =K9 -> 0 | EB9: =L9 -> 0 | EC9: =M9 -> 0 | ED9: =N9 -> 0 | EE9: =O9 -> 0 | EF9: =P9 -> 0 | EG9: =Q9 -> 0 | EH9: =R9 -> 0 | ... FX9: =BH9 -> 0
