Workbook
Name Btu_to_J: Conversions!$M$3
Name deflate_1983: Conversions!$H$3
Name deflate_1984: Conversions!$H$4
Name deflate_1985: Conversions!$H$5
Name deflate_1986: Conversions!$H$6
Name deflate_1987: Conversions!$H$7
Name deflate_1988: Conversions!$H$8
Name deflate_1989: Conversions!$H$9
Name deflate_1990: Conversions!$H$10
Name deflate_1991: Conversions!$H$11
Name deflate_1992: Conversions!$H$12
Name deflate_1993: Conversions!$H$13
Name deflate_1994: Conversions!$H$14
Name deflate_1995: Conversions!$H$15
Name deflate_1996: Conversions!$H$16
Name deflate_1997: Conversions!$H$17
Name deflate_1998: Conversions!$H$18
Name deflate_1999: Conversions!$H$19
Name deflate_2000: Conversions!$H$20
Name deflate_2001: Conversions!$H$21
Name deflate_2002: Conversions!$H$22
Name deflate_2003: Conversions!$H$23
Name deflate_2004: Conversions!$H$24
Name deflate_2005: Conversions!$H$25
Name deflate_2006: Conversions!$H$26
Name deflate_2007: Conversions!$H$27
Name deflate_2008: Conversions!$H$28
Name deflate_2009: Conversions!$H$29
Name deflate_2010: Conversions!$H$30
Name deflate_2011: Conversions!$H$31
Name deflate_2012: Conversions!$H$32
Name deflate_2012: Conversions!$H$32
Name deflate_2013: Conversions!$H$33
Name GW_to_Pja: Conversions!$L$9
Name GW_to_Pja: Conversions!$M$9
Name I_D: WindTimeSlices!$X$8
Name I_N: WindTimeSlices!$Y$8
Name INF: #REF!
Name IQ_CH: 110000
Name IQ_CQ: 5000
Name IQ_CY: 10000
Name IQ_DAILY: 500000
Name IQ_FH: 100000
Name IQ_FQ: 500
Name IQ_FY: 1000
Name IQ_LTM: 2000
Name IQ_MONTH: 15000
Name IQ_NTM: 6000
Name IQ_WEEK: 50000
Name IQ_YTD: 3000
Name kWh_to_btu_hr: Conversions!$M$11
Name kWh_to_MJ: Conversions!$M$4
Name lookup_deflator_2013: TechData_NewCap!$AB$5
Name lookup_deflator_2023: TechData_NewCap!$P$29
Name mills_kWh_to__Million_PJ: Conversions!$M$10
Name MMBtu_to_J: Conversions!$M$7
Name MWh_to_PJ: Conversions!$M$5
Name PJ_to_J: Conversions!$M$6
Name S_D: WindTimeSlices!$Z$8
Name S_N: WindTimeSlices!$AA$8

Sheet Documentation
A1: worksheet | B1: table | C1: data_use | D1: dependency_1 | E1: dependency_2 | F1: dependency_3 | G1: dependency_4 | H1: update_freq | I1: formula | J1: source | K1: description | L1: notes
A2: Commodities | B2: =Commodities!$C$6 -> ELC_subres_commodities | C2: output | H2: NA | I2: - | J2: - | K2: Definitions of commodities and technologies; no need to update
A3: Technologies | B3: =Technologies!$C$6 -> ELC_subres_technologies | C3: output | H3: NA | I3: - | J3: - | K3: Definitions of commodities and technologies; no need to update
A4: TechData_NewCap | B4: =TechData_NewCap!$B$5 -> new_capacity_conventional_technologies | C4: output | D4: =B5 -> AEO_raw_cost_data | E4: =B6 -> lifetime_assumptions | F4: =B9 -> 2023_new_cap_cost_data | H4: Updated | J4: - | K4: Technical specs (Best Buy) for new natural gas and nuclear technology.
A5: 2013 Cap Raw Data | B5: ='2013 Cap Raw Data'!$A$3 -> AEO_raw_cost_data | C5: input | H5: Historical Reference Data | J5: Assumptions to the Annual Energy Outlook 2014, Early Release (http://www.eia.gov/forecasts/aeo/assumptions/pdf/table8_2_2014er.pdf) | K5: 2014 release of AEO costs of new tech installation
A6: LifetimeAssumptions | B6: =LifetimeAssumptions!$B$1 -> lifetime_assumptions | C6: input
A7: TechData_NewCap | B7: =TechData_NewCap!$B$29 -> new_battery_storage | C7: output | D7: =B8 -> regional_base_cost | E7: =B9 -> 2023_new_cap_cost_data | F7: =B5 -> AEO_raw_cost_data | H7: Updated | K7: Technical specs (Best Buy) for new battery energy storage.
A8: 2023_Regional_Cost_Factor | B8: ='2023_Regional_Cost_Factor'!$A$3 -> regional_base_cost | C8: input | H8: Updated | J8: https://www.eia.gov/outlooks/aeo/assumptions/pdf/elec_cost_perf.pdf | K8: Regional cost shifters for base cost of new capital
A9: 2023 Cap Raw Data | B9: ='2023 Cap Raw Data'!$A$4 -> 2023_new_cap_cost_data | C9: input | H9: Updated | J9: https://www.eia.gov/outlooks/aeo/assumptions/pdf/elec_cost_perf.pdf | K9: Cost and performance of new technologies
A10: TechData_NewCap | B10: =TechData_NewCap!$B$44 -> new_cap_CHP | C10: output | H10: Update Needed | J10: Hard Coded | K10: Cost and performance of CHP technologies
A11: TechData_SolarWind | B11: =TechData_SolarWind!$B$5 -> solarPV_technologies | C11: output | D11: =B12 -> #REF! | H11: Need to find source | J11: Mostly hard coded | K11: Cost inputs for solar technologies
A12: SOL | B12: =#REF! -> #REF! | C12: input | H12: Update Needed | J12: SEIA, NY State solar targets | K12: Capacity for rest of state solar installation
A13: TechData_SolarWind | B13: =TechData_SolarWind!$B$8 -> wind_technologies | C13: output | D13: ATB | E13: =B6 -> lifetime_assumptions | F13: Nrel_ReEDS | I13: AEO Cost Assumptions, multiplied by NREL ReEDS scaling factors to get cost at different technology steps, multiplied by ATB for how cost, FOM scale over time | K13: Costs, capacity, and activity factors for wind
A14: TechData_Hydro | B14: =TechData_Hydro!$B$5 -> conventional_hydro | C14: output | H14: Need to find source | K14: Cost and activity factor for existing conventional hydro
A15: TechData_Hydro | B15: =TechData_Hydro!$B$11 -> reversible_hydro | C15: output | H15: Need to find source | K15: Cost and activity factor for existing reversible hydro
A16: TechData_CoalResid | B16: =#REF! -> #REF! | C16: output | H16: NA | K16: No residual coal after 2020. No need to update.
A17: ATB_Capex | B17: =ATB_CAPEX!$C$1 -> ATB_capex | C17: input | H17: Updated | J17: https://atb.nrel.gov/electricity/2024/data | K17: NREL Annual Technology Baseline.
A18: ATB_CF | B18: =ATB_CF!$C$1 -> ATB_CF | C18: input | H18: Updated | J18: https://atb.nrel.gov/electricity/2024/data | K18: NREL Annual Technology Baseline.
A19: ATB_FOM | B19: =ATB_FOM!$F$1 -> ATB_FOM | C19: input | H19: Updated | J19: https://atb.nrel.gov/electricity/2024/data | K19: NREL Annual Technology Baseline.
A20: ATB_VOM | B20: =ATB_VOM!$G$1 -> ATB_VOM | C20: input | H20: Updated | J20: https://atb.nrel.gov/electricity/2024/data | K20: NREL Annual Technology Baseline.

Sheet Commodities
B1: Commodities | C1: _GLOBAL,R0,R1,R2,R3,R4,R5,R6
B6: ~FI_Comm | C6: ELC_subres_commodities
B7: Region | C7: CommName | D7: CommDesc | E7: Unit | F7: Csets | G7: LimType | H7: CTSLvl | I7: PeakTS | J7: Ctype | O7: Comment
B8: R1,R2,R3,R4,R5,R6 | C8: ELC | D8: Electricity | E8: PJ | F8: NRG
B9: R1 | C9: RDMDELC | D9: Dummy ELC demand | E9: PJ | F9: DEM
B10: R0,R1 | C10: ELCNB | D10: Electricity from R0 | E10: PJ | F10: NRG
B11: R2, R3, R4, R5, R6 | C11: ELCR1 | D11: Electricity from R1 (NE) | E11: PJ
B12: R1,R3,R4,R5,R6 | C12: ELCR2 | D12: Electricity from R2 (BK) | E12: PJ
B13: R1,R2,R3,R4,R5,R6 | C13: ELCR3 | D13: Electricity from R3 (BX) | E13: PJ
B14: R1,R2,R3,R4,R5,R6 | C14: ELCR4 | D14: Electricity from R4 (MH) | E14: PJ
B15: R1,R2,R3,R4,R5,R6 | C15: ELCR5 | D15: Electricity from R5 (SI) | E15: PJ
B16: R1,R2,R3,R4,R5,R6 | C16: ELCR6 | D16: Electricity from R6 (QN) | E16: PJ
B17: *Material Carriers to Nuclear Techs
B18: R0 | C18: NURN | D18: Natural Uranium | E18: t | F18: MAT
B19: R0 | C19: URD | D19: Depleted uranium generated during enrichment | E19: t
B20: R0,R1,R2,R3,R4,R5,R6 | C20: URNA | D20: Enriched Uranium (4.5%) for LWRs | E20: t
B21: R0,R1,R2,R3,R4,R5,R6 | C21: URNB | D21: Enriched Uranium (9%) for PBMRs | E21: t
B22: R0,R1,R2,R3,R4,R5,R6 | C22: URNC | D22: Enriched Uranium (19%) for GT-MHRs | E22: t
B23: R1,R2,R3,R4,R5,R6 | C23: USPTA | D23: Spent U from LWRs | E23: t
B24: R1,R2,R3,R4,R5,R6 | C24: USPTB | D24: Spent U from PBMRs | E24: t
B25: R1,R2,R3,R4,R5,R6 | C25: USPTC | D25: Spent U from GT-MHRs | E25: t
B26: *Coal Energy Carriers
B27: R1 | C27: CSTMBH | D27: High Sulfur Bituminous to SOx Control | E27: PJ | F27: NRG
B28: R1 | C28: CSTMBM | D28: Medium Sulfur Bituminous to SOx Control | E28: PJ
B29: R1 | C29: CSTMBL | D29: Low Sulfur Bituminous to SOx Control | E29: PJ
B30: R1 | C30: CSTMSM | D30: Medium Sulfur Sub-Bituminous to SOx Control | E30: PJ
B31: R1 | C31: CSTMSL | D31: Low Sulfur Sub-Bituminous to SOx Control | E31: PJ
B32: R1 | C32: CSTMLH | D32: High Sulfur Lignite to SOx Control | E32: PJ
B33: R1 | C33: CSTMLM | D33: Medium Sulfur Lignite to SOx Control | E33: PJ
B34: R1 | C34: CSTMBIT1O | D34: Bituminous to NOX Control Over 100MW | E34: PJ
B35: R1 | C35: CSTMSUB1O | D35: Sub-Bituminous to NOX Control Over 100MW | E35: PJ
B36: R1 | C36: CSTMLIG1O | D36: Lignite to NOX Control Over 100MW | E36: PJ
B37: R1 | C37: CSTMBIT1U | D37: Bituminous to NOX Control Under 100MW | E37: PJ
B38: R1 | C38: CSTMSUB1U | D38: Sub-Bituminous to NOX Control Under 100MW | E38: PJ
B39: R1 | C39: CSTMLIG1U | D39: Lignite to NOX Control Under 100MW | E39: PJ
... B66: R1 | C66: COALIGCC | D66: Coal to IGCC | E66: PJ
B67: *Non-Coal Energy Carriers to Conversion Techs
B68: R1,R2,R3,R4,R5,R6 | C68: ELCDSLEA | D68: Diesel | E68: PJ | F68: NRG
B69: R1,R2,R3,R4,R5,R6 | C69: ELCDSL | D69: Diesel to the electric system | E69: PJ
B70: R1,R2,R3,R4,R5,R6 | C70: ELCDSLPN | D70: Diesel to the electric system PN | E70: PJ
...

Sheet Technologies
B1: _GLOBAL,R0,R1,R2,R3,R4,R5,R6 | M1: Technologies
B6: ~FI_Process | C6: ELC_subres_technologies
B7: TechName | C7: TechDesc | D7: Tact | E7: Tcap | F7: Sets | G7: Tslvl | H7: PrimaryCG | I7: Vintage | M7: Region | P7: Comment
B8: *Electricity production New capacity
B9: ENGACC11 | C9: Natural Gas - Combined-Cycle (Turbine) | D9: PJ | E9: GW | F9: ELE | G9: DAYNITE
B10: ENGACC15 | C10: Natural Gas - Combined-Cycle (Turbine) | D10: PJ | E10: GW | F10: ELE | G10: DAYNITE
B11: ENGACC20 | C11: Natural Gas - Combined-Cycle (Turbine) | D11: PJ | E11: GW | F11: ELE | G11: DAYNITE
B12: ENGAACC20 | C12: Natural Gas - Advanced Combined-Cycle (Turbine) | D12: PJ | E12: GW | F12: ELE | G12: DAYNITE
B13: ENGACC25 | C13: Natural Gas - Advanced Combined-Cycle (Turbine) | D13: PJ | E13: GW | F13: ELE | G13: DAYNITE
B14: ENGACT11 | C14: Natural Gas - Combustion Turbine | D14: PJ | E14: GW | F14: ELE | G14: DAYNITE
B15: ENGACT15 | C15: Natural Gas - Combustion Turbine | D15: PJ | E15: GW | F15: ELE | G15: DAYNITE
B16: ENGACT20 | C16: Natural Gas - Combustion Turbine | D16: PJ | E16: GW | F16: ELE | G16: DAYNITE
B17: ENGAACT20 | C17: Natural Gas - Advanced Combustion Turbine | D17: PJ | E17: GW | F17: ELE | G17: DAYNITE
B18: EURNALWR28 | C18: Nuclear LWRs in 2028 | D18: PJ | E18: GW | F18: ELE | G18: SEASON | H18: NRGO
B19: EURNASMR | C19: Advanced nuclear technology: Small Modular Reactors | D19: PJ | E19: GW | F19: ELE | G19: SEASON | H19: NRGO
B20: *CHP production New capacity
B21: ECHPBIO11 | C21: Electric sector BIO CHP | D21: PJ | E21: GW | F21: HPL | G21: SEASON
B22: ECHPCOAL11 | C22: Electric sector Coal CHP | D22: PJ | E22: GW | F22: HPL | G22: DAYNITE
B23: ECHPNGA11 | C23: Electric sector NGA CHP | D23: PJ | E23: GW | F23: HPL | G23: DAYNITE
B24: ECHPOIL11 | C24: Electric sector Oil CHP | D24: PJ | E24: GW | F24: HPL | G24: DAYNITE
B25: *Hydro production New capacity
B26: EHYDCONR11 | C26: Hydroelectric, Conventional | D26: PJ | E26: GW | F26: ELE | G26: DAYNITE
B27: SHYDREVRIN11 | C27: Hydroelectric, Reversible | D27: PJ | E27: GW | F27: STG | G27: DAYNITE
B28: EHYDREVROUT11 | C28: Hydroelectric, Reversible | D28: PJ | E28: GW | F28: ELE | G28: DAYNITE
B29: *Utility-Scale Battery
B30: SSTOBATUTI-IN | C30: Electricity Battery Storage 4-hour Utility Scale | D30: PJ | E30: GW | F30: STG | G30: DAYNITE
B31: ESTOBATUTI-OUT | C31: Electricity Battery Storage 4-hour Utility Scale | D31: PJ | E31: GW | F31: ELE | G31: DAYNITE
B32: =TechData_NewCap!A34 -> SSTOBAT10HRUTI-IN | C32: =TechData_NewCap!B34 -> Electricity Battery Storage 10-hour Utility Scale | D32: PJ | E32: GW | F32: STG | G32: DAYNITE
B33: =TechData_NewCap!A35 -> ESTOBAT10HRUTI-OUT | C33: =TechData_NewCap!B35 -> Electricity Battery Storage 10-hour Utility Scale | D33: PJ | E33: GW | F33: ELE | G33: DAYNITE
B34: *Solar wind electricity production New capacity
B35: * Solar PV Technologies | G35: DAYNITE
B36: =TechData_SolarWind!A6 -> ESOLPVCLOWCOST | C36: =TechData_SolarWind!B6 -> Solar PV Centralized Generation, Low Cost | D36: PJ | E36: GW | F36: ELE | G36: DAYNITE
B37: =TechData_SolarWind!A7 -> ESOLPVCHIGHCOST | C37: =TechData_SolarWind!B7 -> Solar PV Centralized Generation, High Cost | D37: PJ | E37: GW | F37: ELE | G37: DAYNITE
B38: * Wind Technologies | C38: 0 | D38: PJ | E38: GW | F38: ELE | G38: DAYNITE
B39: =TechData_SolarWind!A9 -> EWNDONLOWCOST | C39: =TechData_SolarWind!B9 -> Onshore Wind, Low Cost | D39: PJ | E39: GW | F39: ELE | G39: DAYNITE
B40: =TechData_SolarWind!A10 -> EWNDONHIGHCOST | C40: =TechData_SolarWind!B10 -> Onshore Wind, High Cost | D40: PJ | E40: GW | F40: ELE | G40: DAYNITE
B41: =TechData_SolarWind!A11 -> EWNDOFFIX | C41: =TechData_SolarWind!B11 -> Offshore Wind Fixed Bottom | D41: PJ | E41: GW | F41: ELE | G41: DAYNITE
B42: =TechData_SolarWind!A12 -> EWNDOFFIX | C42: =TechData_SolarWind!B12 -> Offshore Wind Fixed Bottom | D42: PJ | E42: GW | F42: ELE | G42: DAYNITE
B43: =TechData_SolarWind!A13 -> EWNDOFFLT | C43: =TechData_SolarWind!B13 -> Offshore Wind Floating | D43: PJ | E43: GW | F43: ELE | G43: DAYNITE

Sheet TechData_NewCap
A1: _GLOBAL,R0,R1,R2,R3,R4,R5,R6
E3: ~FI_T
A4: TechName | B4: *TechDesc | C4: *Units | D4: Region | E4: CommIN | F4: CommOUT | G4: NCAP_START | H4: PRC_CAPACT | I4: EFF~2010 | J4: EFF~2015 | K4: EFF~2020 | L4: EFF~2025 | M4: EFF~2055 | N4: Output | O4: *lookup | P4: NCAP_TLIFE | Q4: Peak | R4: NCAP_DRATE | S4: NCAP_AFA | T4: NCAP_BND~UP~2015 | U4: NCAP_BND~UP~2020 | V4: NCAP_BND~UP~2025 | W4: NCAP_BND~UP~2030 | X4: NCAP_BND~UP~2035 | Y4: NCAP_BND~UP~2055 | Z4: *lookup | AA4: *Regional Cost Lookup | AB4: NCAP_FOM~2010 | AC4: ACT_COST~2010 | AD4: NCAP_FOM~2020 | AE4: ACT_COST~2020 | AF4: NCAP_COST~2010 | AG4: NCAP_COST~2015 | AH4: NCAP_COST~2020 | AI4: *LOOKUP: ATB Tech | AJ4: *LOOKUP: ATB TechDetail | AK4: *ATB CAPEX Base | AL4: NCAP_COST~2025 | AM4: NCAP_COST~2030 | AN4: NCAP_COST~2035 | AO4: NCAP_COST~2040 | AP4: NCAP_COST~2045 | AQ4: NCAP_COST~2050 | AR4: *ATB FOM Base | AS4: NCAP_FOM~2025 | AT4: NCAP_FOM~2030 | AU4: NCAP_FOM~2035 | AV4: NCAP_FOM~2040 | AW4: NCAP_FOM~2045 | AX4: NCAP_FOM~2050 | AY4: *ATB VOM Base | AZ4: ACT_COST~2025 | BA4: ACT_COST~2030 | BB4: ACT_COST~2035 | BC4: ACT_COST~2040 | BD4: ACT_COST~2045 | BE4: ACT_COST~2050 | BF4: Input~2010 | BG4: Input~2015 | BH4: Input~2020 | BI4: Input~2055 | BJ4: Region | BK4: ENV_ACT~CO2CPP~2010 | BL4: ENV_ACT~CO2CPP~2015 | BM4: ENV_ACT~CO2CPP~2020 | BN4: ENV_ACT~CO2CPP~2025 | BO4: ENV_ACT~CO2CPP~2055
A5: * | B5: new_capacity_conventional_technologies | I5: Burnup (MWD/kgHM): | J5: 50 | O5: Lookup from LifetimeAssumptions | Z5: Lookup from New Cap Raw Data | AB5: 2012 | AC5: 2022 | AL5: 2025 | AM5: 2030 | AN5: 2035 | AO5: 2040 | AP5: 2045 | AQ5: 2050 | AS5: 2025 | AT5: 2030 | AU5: 2035 | AV5: 2040 | AW5: 2045 | AX5: 2050 | AZ5: 2025 | BA5: 2030 | BB5: 2035 | BC5: 2040 | BD5: 2045 | BE5: 2050 | BK5: 57.838547
A6: ENGACC11 | B6: Natural Gas - Combined-Cycle (Turbine) | C6: PJ, GW | D6: R1,R2,R3,R4,R5,R6 | E6: ELCNGCEA | F6: ELC | G6: 2011 | H6: =GW_to_Pja -> 31.536 | I6: =1/BF6 -> 0.53774626 | J6: =1/BG6 -> 0.55751634 | K6: =1/BH6 -> 0.55751634 | L6: =1/BI6 -> 0.55751634 | M6: =L6 -> 0.55751634 | O6: =LifetimeAssumptions!$B$7 -> Existing Gas & oil turbines | P6: =_xlfn.XLOOKUP($O6, LifetimeAssumptions[technology],LifetimeAssumptions[Lifetime]) -> 50 | Q6: =_xlfn.XLOOKUP($O6, LifetimeAssumptions[technology],LifetimeAssumptions[Peak (con)]) -> 0.95 | R6: =_xlfn.XLOOKUP($O6, LifetimeAssumptions[technology],LifetimeAssumptions[Discrate]) -> 0.15 | S6: =_xlfn.XLOOKUP($O6, LifetimeAssumptions[technology],LifetimeAssumptions[AF]) -> 0.9 | T6: 0 | U6: 0 | V6: 0 | W6: 0 | X6: 0 | Y6: 0 | Z6: ='2013 Cap Raw Data'!$A$8 -> Conv Gas/Oil Comb Cycle | AB6: =_xlfn.XLOOKUP($Z6, NewCapCosts2013[Technology],NewCapCosts2013[Fixed O&M ($2012/kW)])*_xlfn.XLOOKUP($AB$5,GDP_deflator[Year],GDP_deflator[Multiply By (for $2005)]) -> 11.526453 | AC6: =_xlfn.XLOOKUP($Z6, NewCapCosts2013[Technology],NewCapCosts2013[Variable O&M ($2012 mills/kWh)])*_xlfn.XLOOKUP($AB$5,GDP_deflator[Year],GDP_deflator[Multiply By (for $2005)])*mills_kWh_to__Million_PJ -> 0.87520524 | AD6: =_xlfn.XLOOKUP($Z6, NewCapCosts2013[Technology],NewCapCosts2013[Fixed O&M ($2012/kW)])*_xlfn.XLOOKUP($AB$5,GDP_deflator[Year],GDP_deflator[Multiply By (for $2005)]) -> 11.526453 | AE6: =_xlfn.XLOOKUP($Z6, NewCapCosts2013[Technology],NewCapCosts2013[Variable O&M ($2012 mills/kWh)])*_xlfn.XLOOKUP($AB$5,GDP_deflator[Year],GDP_deflator[Multiply By (for $2005)])*mills_kWh_to__Million_PJ -> 0.87520524 | AF6: =_xlfn.XLOOKUP($Z6, NewCapCosts2013[Technology],NewCapCosts2013[Base Overnight Costs in 2012 ($2012/kW)])*_xlfn.XLOOKUP($AB$5,GDP_deflator[Year],GDP_deflator[Multiply By (for $2005)]) -> 762.30376 | AG6: =AF6 -> 762.30376 | AH6: =AG6 -> 762.30376 | AI6: =ATB_CAPEX!$E$490 -> NaturalGas_FE | AJ6: =ATB_CAPEX!$F$485 -> CTAvgCF | AK6: =SUMIFS(ATB_CAPEX[2022],ATB_CAPEX[CostCase],"Conservative",ATB_CAPEX[Technology],$AI6, ATB_CAPEX[TechDetail],$AJ6) -> 1348.8151 | AL6: =$AH6 * SUMIFS(INDIRECT("ATB_CAPEX["&AL$5&"]"),ATB_CAPEX[CostCase],"Conservative",ATB_CAPEX[Technology],$AI6, ATB_CAPEX[TechDetail],$AJ6)/$AK6 -> 745.67718 | AM6: =$AH6 * SUMIFS(INDIRECT("ATB_CAPEX["&AM$5&"]"),ATB_CAPEX[CostCase],"Conservative",ATB_CAPEX[Technology],$AI6, ATB_CAPEX[TechDetail],$AJ6)/$AK6 -> 718.02918 | AN6: =$AH6 * SUMIFS(INDIRECT("ATB_CAPEX["&AN$5&"]"),ATB_CAPEX[CostCase],"Conservative",ATB_CAPEX[Technology],$AI6, ATB_CAPEX[TechDetail],$AJ6)/$AK6 -> 690.3182 | AO6: =$AH6 * SUMIFS(INDIRECT("ATB_CAPEX["&AO$5&"]"),ATB_CAPEX[CostCase],"Conservative",ATB_CAPEX[Technology],$AI6, ATB_CAPEX[TechDetail],$AJ6)/$AK6 -> 662.67021 | AP6: =$AH6 * SUMIFS(INDIRECT("ATB_CAPEX["&AP$5&"]"),ATB_CAPEX[CostCase],"Conservative",ATB_CAPEX[Technology],$AI6, ATB_CAPEX[TechDetail],$AJ6)/$AK6 -> 635.02221 | AQ6: =$AH6 * SUMIFS(INDIRECT("ATB_CAPEX["&AQ$5&"]"),ATB_CAPEX[CostCase],"Conservative",ATB_CAPEX[Technology],$AI6, ATB_CAPEX[TechDetail],$AJ6)/$AK6 -> 607.31123 | AR6: =SUMIFS(ATB_FOM[2022],ATB_FOM[CostCase],"Conservative",ATB_FOM[Technology],$AI6, ATB_FOM[TechDetail],$AJ6) -> 26.1 | AS6: =$AB6 * SUMIFS(INDIRECT("ATB_FOM["&AS$5&"]"),ATB_FOM[CostCase],"Conservative",ATB_FOM[Technology],$AI6, ATB_FOM[TechDetail],$AJ6)/$AR6 -> 11.349802 | AT6: =$AB6 * SUMIFS(INDIRECT("ATB_FOM["&AT$5&"]"),ATB_FOM[CostCase],"Conservative",ATB_FOM[Technology],$AI6, ATB_FOM[TechDetail],$AJ6)/$AR6 -> 11.040664 | AU6: =$AB6 * SUMIFS(INDIRECT("ATB_FOM["&AU$5&"]"),ATB_FOM[CostCase],"Conservative",ATB_FOM[Technology],$AI6, ATB_FOM[TechDetail],$AJ6)/$AR6 -> 10.687363 | AV6: =$AB6 * SUMIFS(INDIRECT("ATB_FOM["&AV$5&"]"),ATB_FOM[CostCase],"Conservative",ATB_FOM[Technology],$AI6, ATB_FOM[TechDetail],$AJ6)/$AR6 -> 10.378224 | AW6: =$AB6 * SUMIFS(INDIRECT("ATB_FOM["&AW$5&"]"),ATB_FOM[CostCase],"Conservative",ATB_FOM[Technology],$AI6, ATB_FOM[TechDetail],$AJ6)/$AR6 -> 10.069085 | AX6: =$AB6 * SUMIFS(INDIRECT("ATB_FOM["&AX$5&"]"),ATB_FOM[CostCase],"Conservative",ATB_FOM[Technology],$AI6, ATB_FOM[TechDetail],$AJ6)/$AR6 -> 9.7157841 | AY6: =SUMIFS(ATB_VOM[2022],ATB_VOM[CostCase],"Conservative",ATB_VOM[Technology],$AI6, ATB_VOM[TechDetail],$AJ6) -> 6.94 | AZ6: =$AC6 * SUMIFS(INDIRECT("ATB_VOM["&AZ$5&"]"),ATB_VOM[CostCase],"Conservative",ATB_VOM[Technology],$AI6, ATB_VOM[TechDetail],$AJ6)/$AY6 -> 0.87520524 | BA6: =$AC6 * SUMIFS(INDIRECT("ATB_VOM["&BA$5&"]"),ATB_VOM[CostCase],"Conservative",ATB_VOM[Technology],$AI6, ATB_VOM[TechDetail],$AJ6)/$AY6 -> 0.87520524 | BB6: =$AC6 * SUMIFS(INDIRECT("ATB_VOM["&BB$5&"]"),ATB_VOM[CostCase],"Conservative",ATB_VOM[Technology],$AI6, ATB_VOM[TechDetail],$AJ6)/$AY6 -> 0.87520524 | BC6: =$AC6 * SUMIFS(INDIRECT("ATB_VOM["&BC$5&"]"),ATB_VOM[CostCase],"Conservative",ATB_VOM[Technology],$AI6, ATB_VOM[TechDetail],$AJ6)/$AY6 -> 0.87520524 | BD6: =$AC6 * SUMIFS(INDIRECT("ATB_VOM["&BD$5&"]"),ATB_VOM[CostCase],"Conservative",ATB_VOM[Technology],$AI6, ATB_VOM[TechDetail],$AJ6)/$AY6 -> 0.87520524 | BE6: =$AC6 * SUMIFS(INDIRECT("ATB_VOM["&BE$5&"]"),ATB_VOM[CostCase],"Conservative",ATB_VOM[Technology],$AI6, ATB_VOM[TechDetail],$AJ6)/$AY6 -> 0.87520524 | BF6: =_xlfn.XLOOKUP($Z6, NewCapCosts2013[Technology],NewCapCosts2013[Heatrate in 2013 (Btu/kWhr)])*0.9/kWh_to_btu_hr -> 1.8596131 | BG6: =_xlfn.XLOOKUP($Z6, NewCapCosts2013[Technology],NewCapCosts2013[Heatrate nth-of-a-kind (Btu/kWr)])*0.9/kWh_to_btu_hr -> 1.7936694 | BH6: =_xlfn.XLOOKUP($Z6, NewCapCosts2013[Technology],NewCapCosts2013[Heatrate nth-of-a-kind (Btu/kWr)])*0.9/kWh_to_btu_hr -> 1.7936694 | BI6: =_xlfn.XLOOKUP($Z6, NewCapCosts2013[Technology],NewCapCosts2013[Heatrate nth-of-a-kind (Btu/kWr)])*0.9/kWh_to_btu_hr -> 1.7936694 | BJ6: R2,R3,R4,R5,R6 | BK6: =$BK$5*BF6 -> 107.55732 | BM6: =$BK$5*BH6 -> 103.74323 | BN6: =$BK$5*BI6 -> 103.74323
A7: ENGACC15 | B7: Natural Gas - Combined-Cycle (Turbine) | C7: PJ, GW | D7: R1 | E7: ELCNGCEA | F7: ELC | G7: 2015 | H7: =GW_to_Pja -> 31.536 | I7: =1/BF7 -> 0.53774626 | J7: =1/BG7 -> 0.55751634 | K7: =1/BH7 -> 0.55751634 | L7: =1/BI7 -> 0.55751634 | M7: =L7 -> 0.55751634 | O7: =LifetimeAssumptions!$B$7 -> Existing Gas & oil turbines | P7: =_xlfn.XLOOKUP($O7, LifetimeAssumptions[technology],LifetimeAssumptions[Lifetime]) -> 50 | Q7: =_xlfn.XLOOKUP($O7, LifetimeAssumptions[technology],LifetimeAssumptions[Peak (con)]) -> 0.95 | R7: =_xlfn.XLOOKUP($O7, LifetimeAssumptions[technology],LifetimeAssumptions[Discrate]) -> 0.15 | S7: =_xlfn.XLOOKUP($O7, LifetimeAssumptions[technology],LifetimeAssumptions[AF]) -> 0.9 | U7: 0 | V7: 0 | W7: 0 | X7: 0 | Y7: 0 | Z7: ='2013 Cap Raw Data'!$A$8 -> Conv Gas/Oil Comb Cycle | AB7: =_xlfn.XLOOKUP($Z7, NewCapCosts2013[Technology],NewCapCosts2013[Fixed O&M ($2012/kW)])*_xlfn.XLOOKUP($AB$5,GDP_deflator[Year],GDP_deflator[Multiply By (for $2005)]) -> 11.526453 | AC7: =_xlfn.XLOOKUP($Z7, NewCapCosts2013[Technology],NewCapCosts2013[Variable O&M ($2012 mills/kWh)])*_xlfn.XLOOKUP($AB$5,GDP_deflator[Year],GDP_deflator[Multiply By (for $2005)])*mills_kWh_to__Million_PJ -> 0.87520524 | AD7: =_xlfn.XLOOKUP($Z7, NewCapCosts2013[Technology],NewCapCosts2013[Fixed O&M ($2012/kW)])*_xlfn.XLOOKUP($AB$5,GDP_deflator[Year],GDP_deflator[Multiply By (for $2005)]) -> 11.526453 | AE7: =_xlfn.XLOOKUP($Z7, NewCapCosts2013[Technology],NewCapCosts2013[Variable O&M ($2012 mills/kWh)])*_xlfn.XLOOKUP($AB$5,GDP_deflator[Year],GDP_deflator[Multiply By (for $2005)])*mills_kWh_to__Million_PJ -> 0.87520524 | AF7: =_xlfn.XLOOKUP($Z7, NewCapCosts2013[Technology],NewCapCosts2013[Base Overnight Costs in 2012 ($2012/kW)])*_xlfn.XLOOKUP($AB$5,GDP_deflator[Year],GDP_deflator[Multiply By (for $2005)]) -> 762.30376 | AG7: =AF7 -> 762.30376 | AH7: =AG7 -> 762.30376 | AI7: =ATB_CAPEX!$E$490 -> NaturalGas_FE | AJ7: =ATB_CAPEX!$F$485 -> CTAvgCF | AK7: =SUMIFS(ATB_CAPEX[2022],ATB_CAPEX[CostCase],"Conservative",ATB_CAPEX[Technology],$AI7, ATB_CAPEX[TechDetail],$AJ7) -> 1348.8151 | AL7: =$AH7 * SUMIFS(INDIRECT("ATB_CAPEX["&AL$5&"]"),ATB_CAPEX[CostCase],"Conservative",ATB_CAPEX[Technology],$AI7, ATB_CAPEX[TechDetail],$AJ7)/$AK7 -> 745.67718 | AM7: =$AH7 * SUMIFS(INDIRECT("ATB_CAPEX["&AM$5&"]"),ATB_CAPEX[CostCase],"Conservative",ATB_CAPEX[Technology],$AI7, ATB_CAPEX[TechDetail],$AJ7)/$AK7 -> 718.02918 | AN7: =$AH7 * SUMIFS(INDIRECT("ATB_CAPEX["&AN$5&"]"),ATB_CAPEX[CostCase],"Conservative",ATB_CAPEX[Technology],$AI7, ATB_CAPEX[TechDetail],$AJ7)/$AK7 -> 690.3182 | AO7: =$AH7 * SUMIFS(INDIRECT("ATB_CAPEX["&AO$5&"]"),ATB_CAPEX[CostCase],"Conservative",ATB_CAPEX[Technology],$AI7, ATB_CAPEX[TechDetail],$AJ7)/$AK7 -> 662.67021 | AP7: =$AH7 * SUMIFS(INDIRECT("ATB_CAPEX["&AP$5&"]"),ATB_CAPEX[CostCase],"Conservative",ATB_CAPEX[Technology],$AI7, ATB_CAPEX[TechDetail],$AJ7)/$AK7 -> 635.02221 | AQ7: =$AH7 * SUMIFS(INDIRECT("ATB_CAPEX["&AQ$5&"]"),ATB_CAPEX[CostCase],"Conservative",ATB_CAPEX[Technology],$AI7, ATB_CAPEX[TechDetail],$AJ7)/$AK7 -> 607.31123 | AR7: =SUMIFS(ATB_FOM[2022],ATB_FOM[CostCase],"Conservative",ATB_FOM[Technology],$AI7, ATB_FOM[TechDetail],$AJ7) -> 26.1 | AS7: =$AB7 * SUMIFS(INDIRECT("ATB_FOM["&AS$5&"]"),ATB_FOM[CostCase],"Conservative",ATB_FOM[Technology],$AI7, ATB_FOM[TechDetail],$AJ7)/$AR7 -> 11.349802 | AT7: =$AB7 * SUMIFS(INDIRECT("ATB_FOM["&AT$5&"]"),ATB_FOM[CostCase],"Conservative",ATB_FOM[Technology],$AI7, ATB_FOM[TechDetail],$AJ7)/$AR7 -> 11.040664 | AU7: =$AB7 * SUMIFS(INDIRECT("ATB_FOM["&AU$5&"]"),ATB_FOM[CostCase],"Conservative",ATB_FOM[Technology],$AI7, ATB_FOM[TechDetail],$AJ7)/$AR7 -> 10.687363 | AV7: =$AB7 * SUMIFS(INDIRECT("ATB_FOM["&AV$5&"]"),ATB_FOM[CostCase],"Conservative",ATB_FOM[Technology],$AI7, ATB_FOM[TechDetail],$AJ7)/$AR7 -> 10.378224 | AW7: =$AB7 * SUMIFS(INDIRECT("ATB_FOM["&AW$5&"]"),ATB_FOM[CostCase],"Conservative",ATB_FOM[Technology],$AI7, ATB_FOM[TechDetail],$AJ7)/$AR7 -> 10.069085 | AX7: =$AB7 * SUMIFS(INDIRECT("ATB_FOM["&AX$5&"]"),ATB_FOM[CostCase],"Conservative",ATB_FOM[Technology],$AI7, ATB_FOM[TechDetail],$AJ7)/$AR7 -> 9.7157841 | AY7: =SUMIFS(ATB_VOM[2022],ATB_VOM[CostCase],"Conservative",ATB_VOM[Technology],$AI7, ATB_VOM[TechDetail],$AJ7) -> 6.94 | AZ7: =$AC7 * SUMIFS(INDIRECT("ATB_VOM["&AZ$5&"]"),ATB_VOM[CostCase],"Conservative",ATB_VOM[Technology],$AI7, ATB_VOM[TechDetail],$AJ7)/$AY7 -> 0.87520524 | BA7: =$AC7 * SUMIFS(INDIRECT("ATB_VOM["&BA$5&"]"),ATB_VOM[CostCase],"Conservative",ATB_VOM[Technology],$AI7, ATB_VOM[TechDetail],$AJ7)/$AY7 -> 0.87520524 | BB7: =$AC7 * SUMIFS(INDIRECT("ATB_VOM["&BB$5&"]"),ATB_VOM[CostCase],"Conservative",ATB_VOM[Technology],$AI7, ATB_VOM[TechDetail],$AJ7)/$AY7 -> 0.87520524 | BC7: =$AC7 * SUMIFS(INDIRECT("ATB_VOM["&BC$5&"]"),ATB_VOM[CostCase],"Conservative",ATB_VOM[Technology],$AI7, ATB_VOM[TechDetail],$AJ7)/$AY7 -> 0.87520524 | BD7: =$AC7 * SUMIFS(INDIRECT("ATB_VOM["&BD$5&"]"),ATB_VOM[CostCase],"Conservative",ATB_VOM[Technology],$AI7, ATB_VOM[TechDetail],$AJ7)/$AY7 -> 0.87520524 | BE7: =$AC7 * SUMIFS(INDIRECT("ATB_VOM["&BE$5&"]"),ATB_VOM[CostCase],"Conservative",ATB_VOM[Technology],$AI7, ATB_VOM[TechDetail],$AJ7)/$AY7 -> 0.87520524 | BF7: =_xlfn.XLOOKUP($Z7, NewCapCosts2013[Technology],NewCapCosts2013[Heatrate in 2013 (Btu/kWhr)])*0.9/kWh_to_btu_hr -> 1.8596131 | BG7: =_xlfn.XLOOKUP($Z7, NewCapCosts2013[Technology],NewCapCosts2013[Heatrate nth-of-a-kind (Btu/kWr)])*0.9/kWh_to_btu_hr -> 1.7936694 | BH7: =_xlfn.XLOOKUP($Z7, NewCapCosts2013[Technology],NewCapCosts2013[Heatrate nth-of-a-kind (Btu/kWr)])*0.9/kWh_to_btu_hr -> 1.7936694 | BI7: =_xlfn.XLOOKUP($Z7, NewCapCosts2013[Technology],NewCapCosts2013[Heatrate nth-of-a-kind (Btu/kWr)])*0.9/kWh_to_btu_hr -> 1.7936694 | BJ7: R2,R3,R4,R5,R6 | BK7: =$BK$5*BF7 -> 107.55732 | BM7: =$BK$5*BH7 -> 103.74323 | BN7: =$BK$5*BI7 -> 103.74323
A8: ENGACC20 | B8: Natural Gas - Combined-Cycle (Turbine) | C8: PJ, GW | D8: R1 | E8: ELCNGCEA | F8: ELC | G8: 2020 | H8: =GW_to_Pja -> 31.536 | I8: =1/BF8 -> 0.53774626 | J8: =1/BG8 -> 0.55751634 | K8: =1/BH8 -> 0.55751634 | L8: =1/BI8 -> 0.55751634 | M8: =L8 -> 0.55751634 | O8: =LifetimeAssumptions!$B$8 -> New Gas & oil turbines | P8: =_xlfn.XLOOKUP($O8, LifetimeAssumptions[technology],LifetimeAssumptions[Lifetime]) -> 30 | Q8: =_xlfn.XLOOKUP($O8, LifetimeAssumptions[technology],LifetimeAssumptions[Peak (con)]) -> 0.95 | R8: =_xlfn.XLOOKUP($O8, LifetimeAssumptions[technology],LifetimeAssumptions[Discrate]) -> 0.15 | S8: =_xlfn.XLOOKUP($O8, LifetimeAssumptions[technology],LifetimeAssumptions[AF]) -> 0.9 | V8: 0 | W8: 0 | X8: 0 | Y8: 0 | Z8: ='2013 Cap Raw Data'!$A$8 -> Conv Gas/Oil Comb Cycle | AB8: =_xlfn.XLOOKUP($Z8, NewCapCosts2013[Technology],NewCapCosts2013[Fixed O&M ($2012/kW)])*_xlfn.XLOOKUP($AB$5,GDP_deflator[Year],GDP_deflator[Multiply By (for $2005)]) -> 11.526453 | AC8: =_xlfn.XLOOKUP($Z8, NewCapCosts2013[Technology],NewCapCosts2013[Variable O&M ($2012 mills/kWh)])*_xlfn.XLOOKUP($AB$5,GDP_deflator[Year],GDP_deflator[Multiply By (for $2005)])*mills_kWh_to__Million_PJ -> 0.87520524 | AD8: =_xlfn.XLOOKUP($Z8, NewCapCosts2013[Technology],NewCapCosts2013[Fixed O&M ($2012/kW)])*_xlfn.XLOOKUP($AB$5,GDP_deflator[Year],GDP_deflator[Multiply By (for $2005)]) -> 11.526453 | AE8: =_xlfn.XLOOKUP($Z8, NewCapCosts2013[Technology],NewCapCosts2013[Variable O&M ($2012 mills/kWh)])*_xlfn.XLOOKUP($AB$5,GDP_deflator[Year],GDP_deflator[Multiply By (for $2005)])*mills_kWh_to__Million_PJ -> 0.87520524 | AF8: =_xlfn.XLOOKUP($Z8, NewCapCosts2013[Technology],NewCapCosts2013[Base Overnight Costs in 2012 ($2012/kW)])*_xlfn.XLOOKUP($AB$5,GDP_deflator[Year],GDP_deflator[Multiply By (for $2005)]) -> 762.30376 | AG8: =AF8 -> 762.30376 | AH8: =AG8 -> 762.30376 | AI8: =ATB_CAPEX!$E$490 -> NaturalGas_FE | AJ8: =ATB_CAPEX!$F$485 -> CTAvgCF | AK8: =SUMIFS(ATB_CAPEX[2022],ATB_CAPEX[CostCase],"Conservative",ATB_CAPEX[Technology],$AI8, ATB_CAPEX[TechDetail],$AJ8) -> 1348.8151 | AL8: =$AH8 * SUMIFS(INDIRECT("ATB_CAPEX["&AL$5&"]"),ATB_CAPEX[CostCase],"Conservative",ATB_CAPEX[Technology],$AI8, ATB_CAPEX[TechDetail],$AJ8)/$AK8 -> 745.67718 | AM8: =$AH8 * SUMIFS(INDIRECT("ATB_CAPEX["&AM$5&"]"),ATB_CAPEX[CostCase],"Conservative",ATB_CAPEX[Technology],$AI8, ATB_CAPEX[TechDetail],$AJ8)/$AK8 -> 718.02918 | AN8: =$AH8 * SUMIFS(INDIRECT("ATB_CAPEX["&AN$5&"]"),ATB_CAPEX[CostCase],"Conservative",ATB_CAPEX[Technology],$AI8, ATB_CAPEX[TechDetail],$AJ8)/$AK8 -> 690.3182 | AO8: =$AH8 * SUMIFS(INDIRECT("ATB_CAPEX["&AO$5&"]"),ATB_CAPEX[CostCase],"Conservative",ATB_CAPEX[Technology],$AI8, ATB_CAPEX[TechDetail],$AJ8)/$AK8 -> 662.67021 | AP8: =$AH8 * SUMIFS(INDIRECT("ATB_CAPEX["&AP$5&"]"),ATB_CAPEX[CostCase],"Conservative",ATB_CAPEX[Technology],$AI8, ATB_CAPEX[TechDetail],$AJ8)/$AK8 -> 635.02221 | AQ8: =$AH8 * SUMIFS(INDIRECT("ATB_CAPEX["&AQ$5&"]"),ATB_CAPEX[CostCase],"Conservative",ATB_CAPEX[Technology],$AI8, ATB_CAPEX[TechDetail],$AJ8)/$AK8 -> 607.31123 | AR8: =SUMIFS(ATB_FOM[2022],ATB_FOM[CostCase],"Conservative",ATB_FOM[Technology],$AI8, ATB_FOM[TechDetail],$AJ8) -> 26.1 | AS8: =$AB8 * SUMIFS(INDIRECT("ATB_FOM["&AS$5&"]"),ATB_FOM[CostCase],"Conservative",ATB_FOM[Technology],$AI8, ATB_FOM[TechDetail],$AJ8)/$AR8 -> 11.349802 | AT8: =$AB8 * SUMIFS(INDIRECT("ATB_FOM["&AT$5&"]"),ATB_FOM[CostCase],"Conservative",ATB_FOM[Technology],$AI8, ATB_FOM[TechDetail],$AJ8)/$AR8 -> 11.040664 | AU8: =$AB8 * SUMIFS(INDIRECT("ATB_FOM["&AU$5&"]"),ATB_FOM[CostCase],"Conservative",ATB_FOM[Technology],$AI8, ATB_FOM[TechDetail],$AJ8)/$AR8 -> 10.687363 | AV8: =$AB8 * SUMIFS(INDIRECT("ATB_FOM["&AV$5&"]"),ATB_FOM[CostCase],"Conservative",ATB_FOM[Technology],$AI8, ATB_FOM[TechDetail],$AJ8)/$AR8 -> 10.378224 | AW8: =$AB8 * SUMIFS(INDIRECT("ATB_FOM["&AW$5&"]"),ATB_FOM[CostCase],"Conservative",ATB_FOM[Technology],$AI8, ATB_FOM[TechDetail],$AJ8)/$AR8 -> 10.069085 | AX8: =$AB8 * SUMIFS(INDIRECT("ATB_FOM["&AX$5&"]"),ATB_FOM[CostCase],"Conservative",ATB_FOM[Technology],$AI8, ATB_FOM[TechDetail],$AJ8)/$AR8 -> 9.7157841 | AY8: =SUMIFS(ATB_VOM[2022],ATB_VOM[CostCase],"Conservative",ATB_VOM[Technology],$AI8, ATB_VOM[TechDetail],$AJ8) -> 6.94 | AZ8: =$AC8 * SUMIFS(INDIRECT("ATB_VOM["&AZ$5&"]"),ATB_VOM[CostCase],"Conservative",ATB_VOM[Technology],$AI8, ATB_VOM[TechDetail],$AJ8)/$AY8 -> 0.87520524 | BA8: =$AC8 * SUMIFS(INDIRECT("ATB_VOM["&BA$5&"]"),ATB_VOM[CostCase],"Conservative",ATB_VOM[Technology],$AI8, ATB_VOM[TechDetail],$AJ8)/$AY8 -> 0.87520524 | BB8: =$AC8 * SUMIFS(INDIRECT("ATB_VOM["&BB$5&"]"),ATB_VOM[CostCase],"Conservative",ATB_VOM[Technology],$AI8, ATB_VOM[TechDetail],$AJ8)/$AY8 -> 0.87520524 | BC8: =$AC8 * SUMIFS(INDIRECT("ATB_VOM["&BC$5&"]"),ATB_VOM[CostCase],"Conservative",ATB_VOM[Technology],$AI8, ATB_VOM[TechDetail],$AJ8)/$AY8 -> 0.87520524 | BD8: =$AC8 * SUMIFS(INDIRECT("ATB_VOM["&BD$5&"]"),ATB_VOM[CostCase],"Conservative",ATB_VOM[Technology],$AI8, ATB_VOM[TechDetail],$AJ8)/$AY8 -> 0.87520524 | BE8: =$AC8 * SUMIFS(INDIRECT("ATB_VOM["&BE$5&"]"),ATB_VOM[CostCase],"Conservative",ATB_VOM[Technology],$AI8, ATB_VOM[TechDetail],$AJ8)/$AY8 -> 0.87520524 | BF8: =_xlfn.XLOOKUP($Z8, NewCapCosts2013[Technology],NewCapCosts2013[Heatrate in 2013 (Btu/kWhr)])*0.9/kWh_to_btu_hr -> 1.8596131 | BG8: =_xlfn.XLOOKUP($Z8, NewCapCosts2013[Technology],NewCapCosts2013[Heatrate nth-of-a-kind (Btu/kWr)])*0.9/kWh_to_btu_hr -> 1.7936694 | BH8: =_xlfn.XLOOKUP($Z8, NewCapCosts2013[Technology],NewCapCosts2013[Heatrate nth-of-a-kind (Btu/kWr)])*0.9/kWh_to_btu_hr -> 1.7936694 | BI8: =_xlfn.XLOOKUP($Z8, NewCapCosts2013[Technology],NewCapCosts2013[Heatrate nth-of-a-kind (Btu/kWr)])*0.9/kWh_to_btu_hr -> 1.7936694 | BJ8: R2,R3,R4,R5,R6
A9: ENGAACC20 | B9: Natural Gas - Advanced Combined-Cycle (Turbine) | C9: PJ, GW | D9: R1 | E9: ELCNGCEA | F9: ELC | G9: 2020 | H9: =GW_to_Pja -> 31.536 | I9: =1/BF9 -> 0.58959737 | J9: =1/BG9 -> 0.598628 | K9: =1/BH9 -> 0.598628 | L9: =1/BI9 -> 0.598628 | M9: =L9 -> 0.598628 | O9: =LifetimeAssumptions!$B$8 -> New Gas & oil turbines | P9: =_xlfn.XLOOKUP($O9, LifetimeAssumptions[technology],LifetimeAssumptions[Lifetime]) -> 30 | Q9: =_xlfn.XLOOKUP($O9, LifetimeAssumptions[technology],LifetimeAssumptions[Peak (con)]) -> 0.95 | R9: =_xlfn.XLOOKUP($O9, LifetimeAssumptions[technology],LifetimeAssumptions[Discrate]) -> 0.15 | S9: =_xlfn.XLOOKUP($O9, LifetimeAssumptions[technology],LifetimeAssumptions[AF]) -> 0.9 | V9: 0 | W9: 0 | X9: 0 | Y9: 0 | Z9: ='2013 Cap Raw Data'!$A$9 -> Adv Gas/Oil Comb Cycle (CC) | AB9: =_xlfn.XLOOKUP($Z9, NewCapCosts2013[Technology],NewCapCosts2013[Fixed O&M ($2012/kW)])*_xlfn.XLOOKUP($AB$5,GDP_deflator[Year],GDP_deflator[Multiply By (for $2005)]) -> 13.451904 | AC9: =_xlfn.XLOOKUP($Z9, NewCapCosts2013[Technology],NewCapCosts2013[Variable O&M ($2012 mills/kWh)])*_xlfn.XLOOKUP($AB$5,GDP_deflator[Year],GDP_deflator[Multiply By (for $2005)])*mills_kWh_to__Million_PJ -> 0.79497809 | AD9: =_xlfn.XLOOKUP($Z9, NewCapCosts2013[Technology],NewCapCosts2013[Fixed O&M ($2012/kW)])*_xlfn.XLOOKUP($AB$5,GDP_deflator[Year],GDP_deflator[Multiply By (for $2005)]) -> 13.451904 | AE9: =_xlfn.XLOOKUP($Z9, NewCapCosts2013[Technology],NewCapCosts2013[Variable O&M ($2012 mills/kWh)])*_xlfn.XLOOKUP($AB$5,GDP_deflator[Year],GDP_deflator[Multiply By (for $2005)])*mills_kWh_to__Million_PJ -> 0.79497809 | AF9: =_xlfn.XLOOKUP($Z9, NewCapCosts2013[Technology],NewCapCosts2013[Base Overnight Costs in 2012 ($2012/kW)])*_xlfn.XLOOKUP($AB$5,GDP_deflator[Year],GDP_deflator[Multiply By (for $2005)]) -> 827.06895 | AG9: =AF9 -> 827.06895 | AH9: =AG9 -> 827.06895 | AI9: =ATB_CAPEX!$E$490 -> NaturalGas_FE | AJ9: =ATB_CAPEX!$F$485 -> CTAvgCF | AK9: =SUMIFS(ATB_CAPEX[2022],ATB_CAPEX[CostCase],"Conservative",ATB_CAPEX[Technology],$AI9, ATB_CAPEX[TechDetail],$AJ9) -> 1348.8151 | AL9: =$AH9 * SUMIFS(INDIRECT("ATB_CAPEX["&AL$5&"]"),ATB_CAPEX[CostCase],"Conservative",ATB_CAPEX[Technology],$AI9, ATB_CAPEX[TechDetail],$AJ9)/$AK9 -> 809.02977 | AM9: =$AH9 * SUMIFS(INDIRECT("ATB_CAPEX["&AM$5&"]"),ATB_CAPEX[CostCase],"Conservative",ATB_CAPEX[Technology],$AI9, ATB_CAPEX[TechDetail],$AJ9)/$AK9 -> 779.03281 | AN9: =$AH9 * SUMIFS(INDIRECT("ATB_CAPEX["&AN$5&"]"),ATB_CAPEX[CostCase],"Conservative",ATB_CAPEX[Technology],$AI9, ATB_CAPEX[TechDetail],$AJ9)/$AK9 -> 748.96751 | AO9: =$AH9 * SUMIFS(INDIRECT("ATB_CAPEX["&AO$5&"]"),ATB_CAPEX[CostCase],"Conservative",ATB_CAPEX[Technology],$AI9, ATB_CAPEX[TechDetail],$AJ9)/$AK9 -> 718.97055 | AP9: =$AH9 * SUMIFS(INDIRECT("ATB_CAPEX["&AP$5&"]"),ATB_CAPEX[CostCase],"Conservative",ATB_CAPEX[Technology],$AI9, ATB_CAPEX[TechDetail],$AJ9)/$AK9 -> 688.97358 | AQ9: =$AH9 * SUMIFS(INDIRECT("ATB_CAPEX["&AQ$5&"]"),ATB_CAPEX[CostCase],"Conservative",ATB_CAPEX[Technology],$AI9, ATB_CAPEX[TechDetail],$AJ9)/$AK9 -> 658.90828 | AR9: =SUMIFS(ATB_FOM[2022],ATB_FOM[CostCase],"Conservative",ATB_FOM[Technology],$AI9, ATB_FOM[TechDetail],$AJ9) -> 26.1 | AS9: =$AB9 * SUMIFS(INDIRECT("ATB_FOM["&AS$5&"]"),ATB_FOM[CostCase],"Conservative",ATB_FOM[Technology],$AI9, ATB_FOM[TechDetail],$AJ9)/$AR9 -> 13.245745 | AT9: =$AB9 * SUMIFS(INDIRECT("ATB_FOM["&AT$5&"]"),ATB_FOM[CostCase],"Conservative",ATB_FOM[Technology],$AI9, ATB_FOM[TechDetail],$AJ9)/$AR9 -> 12.884966 | AU9: =$AB9 * SUMIFS(INDIRECT("ATB_FOM["&AU$5&"]"),ATB_FOM[CostCase],"Conservative",ATB_FOM[Technology],$AI9, ATB_FOM[TechDetail],$AJ9)/$AR9 -> 12.472647 | AV9: =$AB9 * SUMIFS(INDIRECT("ATB_FOM["&AV$5&"]"),ATB_FOM[CostCase],"Conservative",ATB_FOM[Technology],$AI9, ATB_FOM[TechDetail],$AJ9)/$AR9 -> 12.111868 | AW9: =$AB9 * SUMIFS(INDIRECT("ATB_FOM["&AW$5&"]"),ATB_FOM[CostCase],"Conservative",ATB_FOM[Technology],$AI9, ATB_FOM[TechDetail],$AJ9)/$AR9 -> 11.751089 | AX9: =$AB9 * SUMIFS(INDIRECT("ATB_FOM["&AX$5&"]"),ATB_FOM[CostCase],"Conservative",ATB_FOM[Technology],$AI9, ATB_FOM[TechDetail],$AJ9)/$AR9 -> 11.33877 | AY9: =SUMIFS(ATB_VOM[2022],ATB_VOM[CostCase],"Conservative",ATB_VOM[Technology],$AI9, ATB_VOM[TechDetail],$AJ9) -> 6.94 | AZ9: =$AC9 * SUMIFS(INDIRECT("ATB_VOM["&AZ$5&"]"),ATB_VOM[CostCase],"Conservative",ATB_VOM[Technology],$AI9, ATB_VOM[TechDetail],$AJ9)/$AY9 -> 0.79497809 | BA9: =$AC9 * SUMIFS(INDIRECT("ATB_VOM["&BA$5&"]"),ATB_VOM[CostCase],"Conservative",ATB_VOM[Technology],$AI9, ATB_VOM[TechDetail],$AJ9)/$AY9 -> 0.79497809 | BB9: =$AC9 * SUMIFS(INDIRECT("ATB_VOM["&BB$5&"]"),ATB_VOM[CostCase],"Conservative",ATB_VOM[Technology],$AI9, ATB_VOM[TechDetail],$AJ9)/$AY9 -> 0.79497809 | BC9: =$AC9 * SUMIFS(INDIRECT("ATB_VOM["&BC$5&"]"),ATB_VOM[CostCase],"Conservative",ATB_VOM[Technology],$AI9, ATB_VOM[TechDetail],$AJ9)/$AY9 -> 0.79497809 | BD9: =$AC9 * SUMIFS(INDIRECT("ATB_VOM["&BD$5&"]"),ATB_VOM[CostCase],"Conservative",ATB_VOM[Technology],$AI9, ATB_VOM[TechDetail],$AJ9)/$AY9 -> 0.79497809 | BE9: =$AC9 * SUMIFS(INDIRECT("ATB_VOM["&BE$5&"]"),ATB_VOM[CostCase],"Conservative",ATB_VOM[Technology],$AI9, ATB_VOM[TechDetail],$AJ9)/$AY9 -> 0.79497809 | BF9: =_xlfn.XLOOKUP($Z9, NewCapCosts2013[Technology],NewCapCosts2013[Heatrate in 2013 (Btu/kWhr)])*0.9/kWh_to_btu_hr -> 1.6960727 | BG9: =_xlfn.XLOOKUP($Z9, NewCapCosts2013[Technology],NewCapCosts2013[Heatrate nth-of-a-kind (Btu/kWr)])*0.9/kWh_to_btu_hr -> 1.6704865 | BH9: =_xlfn.XLOOKUP($Z9, NewCapCosts2013[Technology],NewCapCosts2013[Heatrate nth-of-a-kind (Btu/kWr)])*0.9/kWh_to_btu_hr -> 1.6704865 | BI9: =_xlfn.XLOOKUP($Z9, NewCapCosts2013[Technology],NewCapCosts2013[Heatrate nth-of-a-kind (Btu/kWr)])*0.9/kWh_to_btu_hr -> 1.6704865 | BJ9: R2,R3,R4,R5,R6
A10: ENGACC25 | B10: Natural Gas - Combined-Cycle (Turbine) | C10: PJ, GW | D10: R1 | E10: ELCNGCEA | F10: ELC | G10: 2025 | H10: =GW_to_Pja -> 31.536 | I10: =1/BF10 -> 0.59515088 | J10: =1/BG10 -> 0.59515088 | K10: =1/BH10 -> 0.59515088 | L10: =1/BI10 -> 0.59515088 | M10: =L10 -> 0.59515088 | O10: =LifetimeAssumptions!$B$8 -> New Gas & oil turbines | P10: =_xlfn.XLOOKUP($O10, LifetimeAssumptions[technology],LifetimeAssumptions[Lifetime]) -> 30 | Q10: =_xlfn.XLOOKUP($O10, LifetimeAssumptions[technology],LifetimeAssumptions[Peak (con)]) -> 0.95 | R10: =_xlfn.XLOOKUP($O10, LifetimeAssumptions[technology],LifetimeAssumptions[Discrate]) -> 0.15 | S10: =_xlfn.XLOOKUP($O10, LifetimeAssumptions[technology],LifetimeAssumptions[AF]) -> 0.9 | Z10: ='2023 Cap Raw Data'!$A$10 -> Combined-cycle—multi-shaft | AA10: ='2023_Regional_Cost_Factor'!$A$9 -> CC – multi shaft | AB10: =_xlfn.XLOOKUP($Z10, NewCapCosts2023[Technology],NewCapCosts2023[Fixed O&M (2022$/Kw-y)])*_xlfn.XLOOKUP($AC$5,GDP_deflator[Year],GDP_deflator[Multiply By (for $2005)]) -> 9.4882051 | AC10: =_xlfn.XLOOKUP($Z10, NewCapCosts2023[Technology],NewCapCosts2023[Variable O&Mf (2022 $/MWh)])*_xlfn.XLOOKUP($AC$5,GDP_deflator[Year],GDP_deflator[Multiply By (for $2005)])*mills_kWh_to__Million_PJ -> 0.40398315 | AD10: =_xlfn.XLOOKUP($Z10, NewCapCosts2023[Technology],NewCapCosts2023[Fixed O&M (2022$/Kw-y)])*_xlfn.XLOOKUP($AC$5,GDP_deflator[Year],GDP_deflator[Multiply By (for $2005)]) -> 9.4882051 | AE10: =_xlfn.XLOOKUP($Z10, NewCapCosts2023[Technology],NewCapCosts2023[Variable O&Mf (2022 $/MWh)])*_xlfn.XLOOKUP($AC$5,GDP_deflator[Year],GDP_deflator[Multiply By (for $2005)])*mills_kWh_to__Million_PJ -> 0.40398315 | AF10: =_xlfn.XLOOKUP($AA10,NewCapRegionalCosts[Technology], NewCapRegionalCosts[9 (NYUP)])*_xlfn.XLOOKUP($AC$5,GDP_deflator[Year],GDP_deflator[Multiply By (for $2005)]) -> 946.79625 | AG10: =AF10 -> 946.79625 | AH10: =AG10 -> 946.79625 | AI10: =ATB_CAPEX!$E$490 -> NaturalGas_FE | AJ10: =ATB_CAPEX!$F$485 -> CTAvgCF | AK10: =SUMIFS(ATB_CAPEX[2022],ATB_CAPEX[CostCase],"Conservative",ATB_CAPEX[Technology],$AI10, ATB_CAPEX[TechDetail],$AJ10) -> 1348.8151 | AL10: =$AH10 * SUMIFS(INDIRECT("ATB_CAPEX["&AL$5&"]"),ATB_CAPEX[CostCase],"Conservative",ATB_CAPEX[Technology],$AI10, ATB_CAPEX[TechDetail],$AJ10)/$AK10 -> 926.1457 | AM10: =$AH10 * SUMIFS(INDIRECT("ATB_CAPEX["&AM$5&"]"),ATB_CAPEX[CostCase],"Conservative",ATB_CAPEX[Technology],$AI10, ATB_CAPEX[TechDetail],$AJ10)/$AK10 -> 891.80634 | AN10: =$AH10 * SUMIFS(INDIRECT("ATB_CAPEX["&AN$5&"]"),ATB_CAPEX[CostCase],"Conservative",ATB_CAPEX[Technology],$AI10, ATB_CAPEX[TechDetail],$AJ10)/$AK10 -> 857.38877 | AO10: =$AH10 * SUMIFS(INDIRECT("ATB_CAPEX["&AO$5&"]"),ATB_CAPEX[CostCase],"Conservative",ATB_CAPEX[Technology],$AI10, ATB_CAPEX[TechDetail],$AJ10)/$AK10 -> 823.04941 | AP10: =$AH10 * SUMIFS(INDIRECT("ATB_CAPEX["&AP$5&"]"),ATB_CAPEX[CostCase],"Conservative",ATB_CAPEX[Technology],$AI10, ATB_CAPEX[TechDetail],$AJ10)/$AK10 -> 788.71006 | AQ10: =$AH10 * SUMIFS(INDIRECT("ATB_CAPEX["&AQ$5&"]"),ATB_CAPEX[CostCase],"Conservative",ATB_CAPEX[Technology],$AI10, ATB_CAPEX[TechDetail],$AJ10)/$AK10 -> 754.29248 | AR10: =SUMIFS(ATB_FOM[2022],ATB_FOM[CostCase],"Conservative",ATB_FOM[Technology],$AI10, ATB_FOM[TechDetail],$AJ10) -> 26.1 | AS10: =$AB10 * SUMIFS(INDIRECT("ATB_FOM["&AS$5&"]"),ATB_FOM[CostCase],"Conservative",ATB_FOM[Technology],$AI10, ATB_FOM[TechDetail],$AJ10)/$AR10 -> 9.342792 | AT10: =$AB10 * SUMIFS(INDIRECT("ATB_FOM["&AT$5&"]"),ATB_FOM[CostCase],"Conservative",ATB_FOM[Technology],$AI10, ATB_FOM[TechDetail],$AJ10)/$AR10 -> 9.0883191 | AU10: =$AB10 * SUMIFS(INDIRECT("ATB_FOM["&AU$5&"]"),ATB_FOM[CostCase],"Conservative",ATB_FOM[Technology],$AI10, ATB_FOM[TechDetail],$AJ10)/$AR10 -> 8.7974929 | AV10: =$AB10 * SUMIFS(INDIRECT("ATB_FOM["&AV$5&"]"),ATB_FOM[CostCase],"Conservative",ATB_FOM[Technology],$AI10, ATB_FOM[TechDetail],$AJ10)/$AR10 -> 8.5430199 | AW10: =$AB10 * SUMIFS(INDIRECT("ATB_FOM["&AW$5&"]"),ATB_FOM[CostCase],"Conservative",ATB_FOM[Technology],$AI10, ATB_FOM[TechDetail],$AJ10)/$AR10 -> 8.288547 | AX10: =$AB10 * SUMIFS(INDIRECT("ATB_FOM["&AX$5&"]"),ATB_FOM[CostCase],"Conservative",ATB_FOM[Technology],$AI10, ATB_FOM[TechDetail],$AJ10)/$AR10 -> 7.9977208 | AY10: =SUMIFS(ATB_VOM[2022],ATB_VOM[CostCase],"Conservative",ATB_VOM[Technology],$AI10, ATB_VOM[TechDetail],$AJ10) -> 6.94 | AZ10: =$AC10 * SUMIFS(INDIRECT("ATB_VOM["&AZ$5&"]"),ATB_VOM[CostCase],"Conservative",ATB_VOM[Technology],$AI10, ATB_VOM[TechDetail],$AJ10)/$AY10 -> 0.40398315 | BA10: =$AC10 * SUMIFS(INDIRECT("ATB_VOM["&BA$5&"]"),ATB_VOM[CostCase],"Conservative",ATB_VOM[Technology],$AI10, ATB_VOM[TechDetail],$AJ10)/$AY10 -> 0.40398315 | BB10: =$AC10 * SUMIFS(INDIRECT("ATB_VOM["&BB$5&"]"),ATB_VOM[CostCase],"Conservative",ATB_VOM[Technology],$AI10, ATB_VOM[TechDetail],$AJ10)/$AY10 -> 0.40398315 | BC10: =$AC10 * SUMIFS(INDIRECT("ATB_VOM["&BC$5&"]"),ATB_VOM[CostCase],"Conservative",ATB_VOM[Technology],$AI10, ATB_VOM[TechDetail],$AJ10)/$AY10 -> 0.40398315 | BD10: =$AC10 * SUMIFS(INDIRECT("ATB_VOM["&BD$5&"]"),ATB_VOM[CostCase],"Conservative",ATB_VOM[Technology],$AI10, ATB_VOM[TechDetail],$AJ10)/$AY10 -> 0.40398315 | BE10: =$AC10 * SUMIFS(INDIRECT("ATB_VOM["&BE$5&"]"),ATB_VOM[CostCase],"Conservative",ATB_VOM[Technology],$AI10, ATB_VOM[TechDetail],$AJ10)/$AY10 -> 0.40398315 | BF10: =_xlfn.XLOOKUP($Z10, NewCapCosts2023[Technology],NewCapCosts2023[Heat rateg (Btu/kWh)])*0.9/kWh_to_btu_hr -> 1.6802462 | BG10: =_xlfn.XLOOKUP($Z10, NewCapCosts2023[Technology],NewCapCosts2023[Heat rateg (Btu/kWh)])*0.9/kWh_to_btu_hr -> 1.6802462 | BH10: =_xlfn.XLOOKUP($Z10, NewCapCosts2023[Technology],NewCapCosts2023[Heat rateg (Btu/kWh)])*0.9/kWh_to_btu_hr -> 1.6802462 | BI10: =_xlfn.XLOOKUP($Z10, NewCapCosts2023[Technology],NewCapCosts2023[Heat rateg (Btu/kWh)])*0.9/kWh_to_btu_hr -> 1.6802462 | BJ10: R2,R3,R4,R5,R6
A11: *ENGACC25 | B11: Natural Gas - Combined-Cycle (Turbine) | C11: PJ, GW | D11: R2,R3,R4,R5,R6 | E11: ELCNGCEA | F11: ELC | G11: 2025 | H11: =GW_to_Pja -> 31.536 | I11: =1/BF11 -> 0.59515088 | J11: =1/BG11 -> 0.59515088 | K11: =1/BH11 -> 0.59515088 | L11: =1/BI11 -> 0.59515088 | M11: =L11 -> 0.59515088 | O11: =LifetimeAssumptions!$B$8 -> New Gas & oil turbines | P11: =_xlfn.XLOOKUP($O11, LifetimeAssumptions[technology],LifetimeAssumptions[Lifetime]) -> 30 | Q11: =_xlfn.XLOOKUP($O11, LifetimeAssumptions[technology],LifetimeAssumptions[Peak (con)]) -> 0.95 | R11: =_xlfn.XLOOKUP($O11, LifetimeAssumptions[technology],LifetimeAssumptions[Discrate]) -> 0.15 | S11: =_xlfn.XLOOKUP($O11, LifetimeAssumptions[technology],LifetimeAssumptions[AF]) -> 0.9 | Z11: ='2023 Cap Raw Data'!$A$10 -> Combined-cycle—multi-shaft | AA11: ='2023_Regional_Cost_Factor'!$A$9 -> CC – multi shaft | AB11: =_xlfn.XLOOKUP($Z11, NewCapCosts2023[Technology],NewCapCosts2023[Fixed O&M (2022$/Kw-y)])*_xlfn.XLOOKUP($AC$5,GDP_deflator[Year],GDP_deflator[Multiply By (for $2005)]) -> 9.4882051 | AC11: =_xlfn.XLOOKUP($Z11, NewCapCosts2023[Technology],NewCapCosts2023[Variable O&Mf (2022 $/MWh)])*_xlfn.XLOOKUP($AC$5,GDP_deflator[Year],GDP_deflator[Multiply By (for $2005)])*mills_kWh_to__Million_PJ -> 0.40398315 | AD11: =_xlfn.XLOOKUP($Z11, NewCapCosts2023[Technology],NewCapCosts2023[Fixed O&M (2022$/Kw-y)])*_xlfn.XLOOKUP($AC$5,GDP_deflator[Year],GDP_deflator[Multiply By (for $2005)]) -> 9.4882051 | AE11: =_xlfn.XLOOKUP($Z11, NewCapCosts2023[Technology],NewCapCosts2023[Variable O&Mf (2022 $/MWh)])*_xlfn.XLOOKUP($AC$5,GDP_deflator[Year],GDP_deflator[Multiply By (for $2005)])*mills_kWh_to__Million_PJ -> 0.40398315 | AF11: =_xlfn.XLOOKUP($AA11,NewCapRegionalCosts[Technology], NewCapRegionalCosts[8 (NYCW)])*_xlfn.XLOOKUP($AC$5,GDP_deflator[Year],GDP_deflator[Multiply By (for $2005)]) -> 1318.8732 | AG11: =AF11 -> 1318.8732 | AH11: =AG11 -> 1318.8732 | AI11: =ATB_CAPEX!$E$490 -> NaturalGas_FE | AJ11: =ATB_CAPEX!$F$485 -> CTAvgCF | AK11: =SUMIFS(ATB_CAPEX[2022],ATB_CAPEX[CostCase],"Conservative",ATB_CAPEX[Technology],$AI11, ATB_CAPEX[TechDetail],$AJ11) -> 1348.8151 | AL11: =$AH11 * SUMIFS(INDIRECT("ATB_CAPEX["&AL$5&"]"),ATB_CAPEX[CostCase],"Conservative",ATB_CAPEX[Technology],$AI11, ATB_CAPEX[TechDetail],$AJ11)/$AK11 -> 1290.1073 | AM11: =$AH11 * SUMIFS(INDIRECT("ATB_CAPEX["&AM$5&"]"),ATB_CAPEX[CostCase],"Conservative",ATB_CAPEX[Technology],$AI11, ATB_CAPEX[TechDetail],$AJ11)/$AK11 -> 1242.273 | AN11: =$AH11 * SUMIFS(INDIRECT("ATB_CAPEX["&AN$5&"]"),ATB_CAPEX[CostCase],"Conservative",ATB_CAPEX[Technology],$AI11, ATB_CAPEX[TechDetail],$AJ11)/$AK11 -> 1194.3299 | AO11: =$AH11 * SUMIFS(INDIRECT("ATB_CAPEX["&AO$5&"]"),ATB_CAPEX[CostCase],"Conservative",ATB_CAPEX[Technology],$AI11, ATB_CAPEX[TechDetail],$AJ11)/$AK11 -> 1146.4957 | AP11: =$AH11 * SUMIFS(INDIRECT("ATB_CAPEX["&AP$5&"]"),ATB_CAPEX[CostCase],"Conservative",ATB_CAPEX[Technology],$AI11, ATB_CAPEX[TechDetail],$AJ11)/$AK11 -> 1098.6614 | AQ11: =$AH11 * SUMIFS(INDIRECT("ATB_CAPEX["&AQ$5&"]"),ATB_CAPEX[CostCase],"Conservative",ATB_CAPEX[Technology],$AI11, ATB_CAPEX[TechDetail],$AJ11)/$AK11 -> 1050.7183 | AR11: =SUMIFS(ATB_FOM[2022],ATB_FOM[CostCase],"Conservative",ATB_FOM[Technology],$AI11, ATB_FOM[TechDetail],$AJ11) -> 26.1 | AS11: =$AB11 * SUMIFS(INDIRECT("ATB_FOM["&AS$5&"]"),ATB_FOM[CostCase],"Conservative",ATB_FOM[Technology],$AI11, ATB_FOM[TechDetail],$AJ11)/$AR11 -> 9.342792 | AT11: =$AB11 * SUMIFS(INDIRECT("ATB_FOM["&AT$5&"]"),ATB_FOM[CostCase],"Conservative",ATB_FOM[Technology],$AI11, ATB_FOM[TechDetail],$AJ11)/$AR11 -> 9.0883191 | AU11: =$AB11 * SUMIFS(INDIRECT("ATB_FOM["&AU$5&"]"),ATB_FOM[CostCase],"Conservative",ATB_FOM[Technology],$AI11, ATB_FOM[TechDetail],$AJ11)/$AR11 -> 8.7974929 | AV11: =$AB11 * SUMIFS(INDIRECT("ATB_FOM["&AV$5&"]"),ATB_FOM[CostCase],"Conservative",ATB_FOM[Technology],$AI11, ATB_FOM[TechDetail],$AJ11)/$AR11 -> 8.5430199 | AW11: =$AB11 * SUMIFS(INDIRECT("ATB_FOM["&AW$5&"]"),ATB_FOM[CostCase],"Conservative",ATB_FOM[Technology],$AI11, ATB_FOM[TechDetail],$AJ11)/$AR11 -> 8.288547 | AX11: =$AB11 * SUMIFS(INDIRECT("ATB_FOM["&AX$5&"]"),ATB_FOM[CostCase],"Conservative",ATB_FOM[Technology],$AI11, ATB_FOM[TechDetail],$AJ11)/$AR11 -> 7.9977208 | AY11: =SUMIFS(ATB_VOM[2022],ATB_VOM[CostCase],"Conservative",ATB_VOM[Technology],$AI11, ATB_VOM[TechDetail],$AJ11) -> 6.94 | AZ11: =$AC11 * SUMIFS(INDIRECT("ATB_VOM["&AZ$5&"]"),ATB_VOM[CostCase],"Conservative",ATB_VOM[Technology],$AI11, ATB_VOM[TechDetail],$AJ11)/$AY11 -> 0.40398315 | BA11: =$AC11 * SUMIFS(INDIRECT("ATB_VOM["&BA$5&"]"),ATB_VOM[CostCase],"Conservative",ATB_VOM[Technology],$AI11, ATB_VOM[TechDetail],$AJ11)/$AY11 -> 0.40398315 | BB11: =$AC11 * SUMIFS(INDIRECT("ATB_VOM["&BB$5&"]"),ATB_VOM[CostCase],"Conservative",ATB_VOM[Technology],$AI11, ATB_VOM[TechDetail],$AJ11)/$AY11 -> 0.40398315 | BC11: =$AC11 * SUMIFS(INDIRECT("ATB_VOM["&BC$5&"]"),ATB_VOM[CostCase],"Conservative",ATB_VOM[Technology],$AI11, ATB_VOM[TechDetail],$AJ11)/$AY11 -> 0.40398315 | BD11: =$AC11 * SUMIFS(INDIRECT("ATB_VOM["&BD$5&"]"),ATB_VOM[CostCase],"Conservative",ATB_VOM[Technology],$AI11, ATB_VOM[TechDetail],$AJ11)/$AY11 -> 0.40398315 | BE11: =$AC11 * SUMIFS(INDIRECT("ATB_VOM["&BE$5&"]"),ATB_VOM[CostCase],"Conservative",ATB_VOM[Technology],$AI11, ATB_VOM[TechDetail],$AJ11)/$AY11 -> 0.40398315 | BF11: =_xlfn.XLOOKUP($Z11, NewCapCosts2023[Technology],NewCapCosts2023[Heat rateg (Btu/kWh)])*0.9/kWh_to_btu_hr -> 1.6802462 | BG11: =_xlfn.XLOOKUP($Z11, NewCapCosts2023[Technology],NewCapCosts2023[Heat rateg (Btu/kWh)])*0.9/kWh_to_btu_hr -> 1.6802462 | BH11: =_xlfn.XLOOKUP($Z11, NewCapCosts2023[Technology],NewCapCosts2023[Heat rateg (Btu/kWh)])*0.9/kWh_to_btu_hr -> 1.6802462 | BI11: =_xlfn.XLOOKUP($Z11, NewCapCosts2023[Technology],NewCapCosts2023[Heat rateg (Btu/kWh)])*0.9/kWh_to_btu_hr -> 1.6802462 | BJ11: R2,R3,R4,R5,R6
A12: ENGACT11 | B12: Natural Gas - Combustion Turbine | C12: PJ, GW | D12: R1,R2,R3,R4,R5,R6 | E12: ELCNGAEA | F12: ELC | G12: 2011 | H12: =GW_to_Pja -> 31.536 | I12: =1/BF12 -> 0.34726675 | J12: =1/BG12 -> 0.36278575 | K12: =1/BH12 -> 0.36278575 | L12: =1/BI12 -> 0.36278575 | M12: =L12 -> 0.36278575 | O12: =LifetimeAssumptions!$B$7 -> Existing Gas & oil turbines | P12: =_xlfn.XLOOKUP($O12, LifetimeAssumptions[technology],LifetimeAssumptions[Lifetime]) -> 50 | Q12: =_xlfn.XLOOKUP($O12, LifetimeAssumptions[technology],LifetimeAssumptions[Peak (con)]) -> 0.95 | R12: =_xlfn.XLOOKUP($O12, LifetimeAssumptions[technology],LifetimeAssumptions[Discrate]) -> 0.15 | S12: =_xlfn.XLOOKUP($O12, LifetimeAssumptions[technology],LifetimeAssumptions[AF]) -> 0.9 | T12: 0 | U12: 0 | V12: 0 | W12: 0 | X12: 0 | Y12: 0 | Z12: ='2013 Cap Raw Data'!$A$11 -> Conv Combustion Turbine | AB12: =_xlfn.XLOOKUP($Z12, NewCapCosts2013[Technology],NewCapCosts2013[Fixed O&M ($2012/kW)])*_xlfn.XLOOKUP($AB$5,GDP_deflator[Year],GDP_deflator[Multiply By (for $2005)]) -> 6.4240064 | AC12: =_xlfn.XLOOKUP($Z12, NewCapCosts2013[Technology],NewCapCosts2013[Variable O&M ($2012 mills/kWh)])*_xlfn.XLOOKUP($AB$5,GDP_deflator[Year],GDP_deflator[Multiply By (for $2005)])*mills_kWh_to__Million_PJ -> 3.7560891 | AD12: =_xlfn.XLOOKUP($Z12, NewCapCosts2013[Technology],NewCapCosts2013[Fixed O&M ($2012/kW)])*_xlfn.XLOOKUP($AB$5,GDP_deflator[Year],GDP_deflator[Multiply By (for $2005)]) -> 6.4240064 | AE12: =_xlfn.XLOOKUP($Z12, NewCapCosts2013[Technology],NewCapCosts2013[Variable O&M ($2012 mills/kWh)])*_xlfn.XLOOKUP($AB$5,GDP_deflator[Year],GDP_deflator[Multiply By (for $2005)])*mills_kWh_to__Million_PJ -> 3.7560891 | AF12: =_xlfn.XLOOKUP($Z12, NewCapCosts2013[Technology],NewCapCosts2013[Base Overnight Costs in 2012 ($2012/kW)])*_xlfn.XLOOKUP($AB$5,GDP_deflator[Year],GDP_deflator[Multiply By (for $2005)]) -> 808.68964 | AG12: =AF12 -> 808.68964 | AH12: =AG12 -> 808.68964 | AI12: =ATB_CAPEX!$E$490 -> NaturalGas_FE | AJ12: =ATB_CAPEX!$F$488 -> CCAvgCF | AK12: =SUMIFS(ATB_CAPEX[2022],ATB_CAPEX[CostCase],"Conservative",ATB_CAPEX[Technology],$AI12, ATB_CAPEX[TechDetail],$AJ12) -> 1499.253 | AL12: =$AH12 * SUMIFS(INDIRECT("ATB_CAPEX["&AL$5&"]"),ATB_CAPEX[CostCase],"Conservative",ATB_CAPEX[Technology],$AI12, ATB_CAPEX[TechDetail],$AJ12)/$AK12 -> 793.78292 | AM12: =$AH12 * SUMIFS(INDIRECT("ATB_CAPEX["&AM$5&"]"),ATB_CAPEX[CostCase],"Conservative",ATB_CAPEX[Technology],$AI12, ATB_CAPEX[TechDetail],$AJ12)/$AK12 -> 768.89831 | AN12: =$AH12 * SUMIFS(INDIRECT("ATB_CAPEX["&AN$5&"]"),ATB_CAPEX[CostCase],"Conservative",ATB_CAPEX[Technology],$AI12, ATB_CAPEX[TechDetail],$AJ12)/$AK12 -> 744.0137 | AO12: =$AH12 * SUMIFS(INDIRECT("ATB_CAPEX["&AO$5&"]"),ATB_CAPEX[CostCase],"Conservative",ATB_CAPEX[Technology],$AI12, ATB_CAPEX[TechDetail],$AJ12)/$AK12 -> 719.12909 | AP12: =$AH12 * SUMIFS(INDIRECT("ATB_CAPEX["&AP$5&"]"),ATB_CAPEX[CostCase],"Conservative",ATB_CAPEX[Technology],$AI12, ATB_CAPEX[TechDetail],$AJ12)/$AK12 -> 694.24449 | AQ12: =$AH12 * SUMIFS(INDIRECT("ATB_CAPEX["&AQ$5&"]"),ATB_CAPEX[CostCase],"Conservative",ATB_CAPEX[Technology],$AI12, ATB_CAPEX[TechDetail],$AJ12)/$AK12 -> 669.41999 | AR12: =SUMIFS(ATB_FOM[2022],ATB_FOM[CostCase],"Conservative",ATB_FOM[Technology],$AI12, ATB_FOM[TechDetail],$AJ12) -> 34.5 | AS12: =$AB12 * SUMIFS(INDIRECT("ATB_FOM["&AS$5&"]"),ATB_FOM[CostCase],"Conservative",ATB_FOM[Technology],$AI12, ATB_FOM[TechDetail],$AJ12)/$AR12 -> 6.3122846 | AT12: =$AB12 * SUMIFS(INDIRECT("ATB_FOM["&AT$5&"]"),ATB_FOM[CostCase],"Conservative",ATB_FOM[Technology],$AI12, ATB_FOM[TechDetail],$AJ12)/$AR12 -> 6.1074612 | AU12: =$AB12 * SUMIFS(INDIRECT("ATB_FOM["&AU$5&"]"),ATB_FOM[CostCase],"Conservative",ATB_FOM[Technology],$AI12, ATB_FOM[TechDetail],$AJ12)/$AR12 -> 5.9212581 | AV12: =$AB12 * SUMIFS(INDIRECT("ATB_FOM["&AV$5&"]"),ATB_FOM[CostCase],"Conservative",ATB_FOM[Technology],$AI12, ATB_FOM[TechDetail],$AJ12)/$AR12 -> 5.735055 | AW12: =$AB12 * SUMIFS(INDIRECT("ATB_FOM["&AW$5&"]"),ATB_FOM[CostCase],"Conservative",ATB_FOM[Technology],$AI12, ATB_FOM[TechDetail],$AJ12)/$AR12 -> 5.5488519 | AX12: =$AB12 * SUMIFS(INDIRECT("ATB_FOM["&AX$5&"]"),ATB_FOM[CostCase],"Conservative",ATB_FOM[Technology],$AI12, ATB_FOM[TechDetail],$AJ12)/$AR12 -> 5.3626489 | AY12: =SUMIFS(ATB_VOM[2022],ATB_VOM[CostCase],"Conservative",ATB_VOM[Technology],$AI12, ATB_VOM[TechDetail],$AJ12) -> 2.17 | AZ12: =$AC12 * SUMIFS(INDIRECT("ATB_VOM["&AZ$5&"]"),ATB_VOM[CostCase],"Conservative",ATB_VOM[Technology],$AI12, ATB_VOM[TechDetail],$AJ12)/$AY12 -> 3.7041616 | BA12: =$AC12 * SUMIFS(INDIRECT("ATB_VOM["&BA$5&"]"),ATB_VOM[CostCase],"Conservative",ATB_VOM[Technology],$AI12, ATB_VOM[TechDetail],$AJ12)/$AY12 -> 3.6003066 | BB12: =$AC12 * SUMIFS(INDIRECT("ATB_VOM["&BB$5&"]"),ATB_VOM[CostCase],"Conservative",ATB_VOM[Technology],$AI12, ATB_VOM[TechDetail],$AJ12)/$AY12 -> 3.5137608 | BC12: =$AC12 * SUMIFS(INDIRECT("ATB_VOM["&BC$5&"]"),ATB_VOM[CostCase],"Conservative",ATB_VOM[Technology],$AI12, ATB_VOM[TechDetail],$AJ12)/$AY12 -> 3.427215 | BD12: =$AC12 * SUMIFS(INDIRECT("ATB_VOM["&BD$5&"]"),ATB_VOM[CostCase],"Conservative",ATB_VOM[Technology],$AI12, ATB_VOM[TechDetail],$AJ12)/$AY12 -> 3.3406691 | BE12: =$AC12 * SUMIFS(INDIRECT("ATB_VOM["&BE$5&"]"),ATB_VOM[CostCase],"Conservative",ATB_VOM[Technology],$AI12, ATB_VOM[TechDetail],$AJ12)/$AY12 -> 3.2368141 | BF12: =_xlfn.XLOOKUP($Z12, NewCapCosts2013[Technology],NewCapCosts2013[Heatrate in 2013 (Btu/kWhr)])*0.9/kWh_to_btu_hr -> 2.8796307 | BG12: =_xlfn.XLOOKUP($Z12, NewCapCosts2013[Technology],NewCapCosts2013[Heatrate nth-of-a-kind (Btu/kWr)])*0.9/kWh_to_btu_hr -> 2.7564478 | BH12: =_xlfn.XLOOKUP($Z12, NewCapCosts2013[Technology],NewCapCosts2013[Heatrate nth-of-a-kind (Btu/kWr)])*0.9/kWh_to_btu_hr -> 2.7564478 | BI12: =_xlfn.XLOOKUP($Z12, NewCapCosts2013[Technology],NewCapCosts2013[Heatrate nth-of-a-kind (Btu/kWr)])*0.9/kWh_to_btu_hr -> 2.7564478 | BJ12: R2,R3,R4,R5,R6
