Workbook
Name _1995_Implicit_GDP_Deflator: 'RTEKTY Conv'!#REF!
Name _2001_Implicit_GDP_Deflator: 'RTEKTY Conv'!#REF!
Name avg_water_heater_PJ: #REF!
Name avg_water_heater_PJ: #REF!
Name avg_water_heater_PJ: #REF!
Name btu_per_watthr: 'RTEKTY Conv'!#REF!
Name btu_per_watthr: '[1]Conversion Factors'!$B$5
Name days_per_year: 'RTEKTY Conv'!#REF!
Name days_per_year: '[1]Conversion Factors'!$B$3
Name dollar____per__m: 'RTEKTY Conv'!#REF!
Name dollar____per__m: '[1]Conversion Factors'!$B$7
Name hours_per_day: 'RTEKTY Conv'!#REF!
Name hours_per_day: '[1]Conversion Factors'!$B$2
Name j_per_btu: 'RTEKTY Conv'!#REF!
Name j_per_btu: '[1]Conversion Factors'!$B$4
Name j_per_pj: 'RTEKTY Conv'!#REF!
Name j_per_pj: '[1]Conversion Factors'!$B$6
Name kwhr_per_j: 'RTEKTY Conv'!#REF!
Name lumens_per_billion_lumens: '[1]Conversion Factors'!$B$9
Name unit_per_million_unit: 'RTEKTY Conv'!#REF!

Sheet ANSv6.1-Commodities
A1: ANSWER-Commodities
B7: CommName | C7: CommDesc | D7: CommUnit | E7: Set Memberships | F7: Comment

Sheet ANSv6.1-Technologies
A1: ANSWER-Technologies
B7: TechName | C7: TechDesc | D7: TACTUnit | E7: TCAPUnit | F7: Set Memberships | G7: Comment

Sheet Commodities
B1: Commodities | D1: _GLOBAL,R0,R1,R2,R3,R4,R5,R6
B6: ~FI_Comm
B7: Region | C7: Csets | D7: CommName | E7: CommDesc | F7: Unit | G7: LimType | H7: CTSLvl | I7: PeakTS | J7: Ctype

Sheet Technologies
C1: _GLOBAL,R0,R1,R2,R3,R4,R5,R6 | K1: Technologies
B6: ~FI_Process
B7: Sets | C7: TechName | D7: TechDesc | E7: Tact | F7: Tcap | G7: PrimaryCG | H7: Vintage | I7: Tslvl | K7: Region
B8: *Space Heating
B9: *Electric Radiant Heating
B10: DMD | C10: =TechData_DMD!A10 -> RSHERDBS10 | D10: =TechData_DMD!B10 -> Electric Radiant Base.RSH.ELC.10 | E10: PJ | F10: PJ/a | K10: =TechData_DMD!BF10 -> R2,R3,R4,R5,R6
B11: DMD | C11: =TechData_DMD!A11 -> RSHERUV115 | D11: =TechData_DMD!B11 -> Electric Resistance Unit Heater Ver1.RSH.ELC.15 | E11: PJ | F11: PJ/a | K11: =TechData_DMD!BF11 -> R2,R3,R4,R5,R6
B12: DMD | C12: =TechData_DMD!A12 -> RSHERUV120 | D12: =TechData_DMD!B12 -> Electric Resistance Unit Heater Ver1.RSH.ELC.20 | E12: PJ | F12: PJ/a | K12: =TechData_DMD!BF12 -> R2,R3,R4,R5,R6
B13: DMD | C13: =TechData_DMD!A13 -> RSHERUV122 | D13: =TechData_DMD!B13 -> Electric Resistance Unit Heater Ver1.RSH.ELC.22 | E13: PJ | F13: PJ/a | K13: =TechData_DMD!BF13 -> R2,R3,R4,R5,R6
B14: *Electric Furnaces
B15: DMD | C15: =TechData_DMD!A15 -> RSHEFRV115 | D15: =TechData_DMD!B15 -> Electric Furnace Ver1.RSH.ELC.15 | E15: PJ | F15: PJ/a | K15: =TechData_DMD!BF15 -> R2,R3,R4,R5,R6
B16: DMD | C16: =TechData_DMD!A16 -> RSHEFRV120 | D16: =TechData_DMD!B16 -> Electric Furnace Ver1.RSH.ELC.20 | E16: PJ | F16: PJ/a | K16: =TechData_DMD!BF16 -> R2,R3,R4,R5,R6
B17: DMD | C17: =TechData_DMD!A17 -> RSHEFRV122 | D17: =TechData_DMD!B17 -> Electric Furnace Ver1.RSH.ELC.22 | E17: PJ | F17: PJ/a | K17: =TechData_DMD!BF17 -> R2,R3,R4,R5,R6
B18: *Electric Heat Pumps (Residential Air Source Heat Pumps)
B19: DMD | C19: =TechData_DMD!A19 -> RSHEHPBS15 | D19: =TechData_DMD!B19 -> Electric Heat Pump Base.RSH.ELC.15 | E19: PJ | F19: PJ/a | I19: DAYNITE | K19: =TechData_DMD!BF19 -> R2,R3,R4,R5,R6
B20: DMD | C20: =TechData_DMD!A22 -> RSHEHPB120 | D20: =TechData_DMD!B22 -> Electric Heat Pump Base.RSH.ELC.20 | E20: PJ | F20: PJ/a | I20: DAYNITE | K20: =TechData_DMD!BF22 -> R2,R3,R4,R5,R6
B21: DMD | C21: =TechData_DMD!A25 -> RSHEHPBS22 | D21: =TechData_DMD!B25 -> Electric Heat Pump Base.RSH.ELC.22 | E21: PJ | F21: PJ/a | I21: DAYNITE | K21: =TechData_DMD!BF25 -> R2,R3,R4,R5,R6
B22: DMD | C22: =TechData_DMD!A28 -> RSHEHPV122 | D22: =TechData_DMD!B28 -> Electric Heat Pump Ver1.RSH.ELC.22 | E22: PJ | F22: PJ/a | I22: DAYNITE | K22: R2,R3,R4,R5,R6
B23: DMD | C23: =TechData_DMD!A31 -> RSHEHPV123 | D23: =TechData_DMD!B31 -> Electric Heat Pump Ver1.RSH.ELC.23 | E23: PJ | F23: PJ/a | I23: DAYNITE | K23: =TechData_DMD!BF31 -> R2,R3,R4,R5,R6
B24: DMD | C24: =TechData_DMD!A34 -> RSHEHPV223 | D24: =TechData_DMD!B34 -> Electric Heat Pump Ver2.RSH.ELC.23 | E24: PJ | F24: PJ/a | I24: DAYNITE | K24: =TechData_DMD!BF34 -> R2,R3,R4,R5,R6
B25: DMD | C25: =TechData_DMD!A37 -> RSHEHPV323 | D25: =TechData_DMD!B37 -> Electric Heat Pump Ver3.RSH.ELC.23 | E25: PJ | F25: PJ/a | I25: DAYNITE | K25: =TechData_DMD!BF37 -> R2,R3,R4,R5,R6
B26: DMD | C26: =TechData_DMD!A40 -> RSHEHPV130 | D26: =TechData_DMD!B40 -> Electric Heat Pump Ver1.RSH.ELC.30 | E26: PJ | F26: PJ/a | I26: DAYNITE | K26: =TechData_DMD!BF40 -> R2,R3,R4,R5,R6
B27: DMD | C27: =TechData_DMD!A43 -> RSHEHPV230 | D27: =TechData_DMD!B43 -> Electric Heat Pump Ver2.RSH.ELC.30 | E27: PJ | F27: PJ/a | I27: DAYNITE | K27: =TechData_DMD!BF43 -> R2,R3,R4,R5,R6
B28: DMD | C28: =TechData_DMD!A46 -> RSHEHPV140 | D28: =TechData_DMD!B46 -> Electric Heat Pump Ver1.RSH.ELC.40 | E28: PJ | F28: PJ/a | I28: DAYNITE | K28: =TechData_DMD!BF46 -> R2,R3,R4,R5,R6
B29: DMD | C29: =TechData_DMD!A49 -> RSHEHPV240 | D29: =TechData_DMD!B49 -> Electric Heat Pump Ver2.RSH.ELC.40 | E29: PJ | F29: PJ/a | I29: DAYNITE | K29: R2,R3,R4,R5,R6
B30: DMD | C30: =TechData_DMD!A52 -> RSHEHPV150 | D30: =TechData_DMD!B52 -> Electric Heat Pump Ver1.RSH.ELC.50 | E30: PJ | F30: PJ/a | I30: DAYNITE | K30: =TechData_DMD!BF52 -> R2,R3,R4,R5,R6
B31: DMD | C31: =TechData_DMD!A55 -> RSHEHPV250 | D31: =TechData_DMD!B55 -> Electric Heat Pump Ver2.RSH.ELC.50 | E31: PJ | F31: PJ/a | I31: DAYNITE | K31: =TechData_DMD!BF55 -> R2,R3,R4,R5,R6
B32: *Natural Gas Furnaces (Residential Gas-Fired Furnaces - North)
B33: DMD | C33: =TechData_DMD!A59 -> RSHNFRBS15 | D33: =TechData_DMD!B59 -> Natural Gas Furnace Base.RSH.NGA.15 | E33: PJ | F33: PJ/a | K33: =TechData_DMD!BF59 -> R2,R3,R4,R5,R6
B34: DMD | C34: =TechData_DMD!A60 -> RSHNFRBS20 | D34: =TechData_DMD!B60 -> Natural Gas Furnace Base.RSH.NGA.20 | E34: PJ | F34: PJ/a | K34: =TechData_DMD!BF60 -> R2,R3,R4,R5,R6
B35: DMD | C35: =TechData_DMD!A61 -> RSHNFRV122 | D35: =TechData_DMD!B61 -> Natural Gas Furnace Ver1.RSH.NGA.22 | E35: PJ | F35: PJ/a | K35: =TechData_DMD!BF61 -> R2,R3,R4,R5,R6
B36: DMD | C36: =TechData_DMD!A62 -> RSHNFRV222 | D36: =TechData_DMD!B62 -> Natural Gas Furnace Ver2.RSH.NGA.22 | E36: PJ | F36: PJ/a | K36: =TechData_DMD!BF62 -> R2,R3,R4,R5,R6
B37: DMD | C37: =TechData_DMD!A63 -> RSHNFRV322 | D37: =TechData_DMD!B63 -> Natural Gas Furnace Ver3.RSH.NGA.22 | E37: PJ | F37: PJ/a | K37: =TechData_DMD!BF63 -> R2,R3,R4,R5,R6
B38: DMD | C38: =TechData_DMD!A64 -> RSHNFRV422 | D38: =TechData_DMD!B64 -> Natural Gas Furnace Ver4.RSH.NGA.22 | E38: PJ | F38: PJ/a | K38: =TechData_DMD!BF64 -> R2,R3,R4,R5,R6
B39: *Natural Gas Radiant Heating (Residential Gas-Fired Boiler Radiants)
B40: DMD | C40: =TechData_DMD!A66 -> RSHNBRBS15 | D40: =TechData_DMD!B66 -> Natural Gas Boiler Radiant Base.RSH.NGA.15 | E40: PJ | F40: PJ/a | K40: =TechData_DMD!BF66 -> R2,R3,R4,R5,R6
B41: DMD | C41: =TechData_DMD!A67 -> RSHNBRBS20 | D41: =TechData_DMD!B67 -> Natural Gas Boiler Radiant Base.RSH.NGA.20 | E41: PJ | F41: PJ/a | K41: =TechData_DMD!BF67 -> R2,R3,R4,R5,R6
B42: DMD | C42: =TechData_DMD!A68 -> RSHNBRV122 | D42: =TechData_DMD!B68 -> Natural Gas Boiler Radiant Ver 1.RSH.NGA.22 | E42: PJ | F42: PJ/a | K42: =TechData_DMD!BF68 -> R2,R3,R4,R5,R6
B43: DMD | C43: =TechData_DMD!A69 -> RSHNBRV222 | D43: =TechData_DMD!B69 -> Natural Gas Boiler Radiant Ver 2.RSH.NGA.22 | E43: PJ | F43: PJ/a | K43: =TechData_DMD!BF69 -> R2,R3,R4,R5,R6
B44: DMD | C44: =TechData_DMD!A70 -> RSHNBRV322 | D44: =TechData_DMD!B70 -> Natural Gas Boiler Radiant Ver 3.RSH.NGA.22 | E44: PJ | F44: PJ/a | K44: =TechData_DMD!BF70 -> R2,R3,R4,R5,R6
...

Sheet TechData_DMD
A1: _GLOBAL,R0,R1,R2,R3,R4,R5,R6 | K1: R2 | L1: R3 | M1: R4 | N1: R5 | O1: R6 | AO1: R2 | AP1: R3 | AQ1: R4 | AR1: R5 | AS1: R6 | AT1: R2 | AU1: R3 | AV1: R4 | AW1: R5 | AX1: R6 | AY1: R2 | AZ1: R3 | BA1: R4 | BB1: R5 | BC1: R6 | BF1: TechData
E6: ~FI_T
A7: TechName | B7: *TechDesc | C7: *Units | D7: CommIN | E7: CommOUT | F7: NCAP_START | G7: NCAP_TLIFE | H7: NCAP_COST | I7: EFF | J7: Share~UP | K7: NCAP_AF~R2 | L7: NCAP_AF~R3 | M7: NCAP_AF~R4 | N7: NCAP_AF~R5 | O7: NCAP_AF~R6 | P7: NCAP_FOM | Q7: NCAP_DRATE | R7: NCAP_BND~2010 | S7: NCAP_BND~2015 | T7: NCAP_BND~2020 | U7: NCAP_BND~2025 | V7: NCAP_BND~2030 | W7: NCAP_BND~2035 | X7: NCAP_BND~2040 | Y7: NCAP_BND~2045 | Z7: NCAP_BND~2050 | AA7: NCAP_BND~2055 | AD7: *GROWTH~2015 | AE7: *GROWTH~2020 | AF7: *GROWTH~2025 | AG7: *GROWTH~2030 | AH7: *GROWTH~2035 | AI7: *GROWTH~2040 | AJ7: *GROWTH~2045 | AK7: *GROWTH~2050 | AL7: *GROWTH~2055 | AO7: PRC_RESID~R2~2010 | AP7: PRC_RESID~R3~2010 | AQ7: PRC_RESID~R4~2010 | AR7: PRC_RESID~R5~2010 | AS7: PRC_RESID~R6~2010 | AT7: PRC_RESID~R2~2015 | AU7: PRC_RESID~R3~2015 | AV7: PRC_RESID~R4~2015 | AW7: PRC_RESID~R5~2015 | AX7: PRC_RESID~R6~2015 | AY7: PRC_RESID~R2~2020 | AZ7: PRC_RESID~R3~2020 | BA7: PRC_RESID~R4~2020 | BB7: PRC_RESID~R5~2020 | BC7: PRC_RESID~R6~2020 | BF7: Region
A8: *Space Heating | BF8: *Space Heating
A9: *Electric Radiant Heating | BF9: *Electric Radiant Heating
A10: ='EIA23 EQ Cost'!B8 -> RSHERDBS10 | B10: ='EIA23 EQ Cost'!C8 -> Electric Radiant Base.RSH.ELC.10 | C10: PJ | D10: RESELC | E10: RSH | F10: ='EIA23 EQ Cost'!G8 -> 2011 | G10: ='EIA23 EQ Cost'!H8 -> 22.5 | H10: ='EIA23 EQ Cost'!J8 -> 3.74 | I10: ='EIA23 EQ Cost'!K8 -> 1 | J10: 1 | K10: 0.16 | L10: 0.16 | M10: 0.16 | N10: 0.16 | O10: 0.16 | Q10: 0.18 | R10: 0 | S10: 0 | T10: =SUM(AT10:AX10)*1.12 -> #REF! | U10: =T10*1.12 -> #REF! | V10: =U10*1.12 -> #REF! | W10: =V10*1.12 -> #REF! | X10: =W10*1.12 -> #REF! | Y10: =X10*1.12 -> #REF! | Z10: =Y10*1.12 -> #REF! | AA10: =Z10*1.12 -> #REF! | AE10: 1.1 | AF10: =AE10 -> 1.1 | AG10: =AF10 -> 1.1 | AH10: =AG10 -> 1.1 | AI10: =AH10 -> 1.1 | AJ10: =AI10 -> 1.1 | AK10: =AJ10 -> 1.1 | AL10: =AK10 -> 1.1 | AO10: =Resid!V7 -> #REF! | AP10: =Resid!W7 -> #REF! | AQ10: =Resid!X7 -> #REF! | AR10: =Resid!Y7 -> #REF! | AS10: =Resid!Z7 -> #REF! | AT10: =AO10*15/20 -> #REF! | AU10: =AP10*15/20 -> #REF! | AV10: =AQ10*15/20 -> #REF! | AW10: =AR10*15/20 -> #REF! | AX10: =AS10*15/20 -> #REF! | BF10: R2,R3,R4,R5,R6
A11: ='EIA23 EQ Cost'!B9 -> RSHERUV115 | B11: ='EIA23 EQ Cost'!C9 -> Electric Resistance Unit Heater Ver1.RSH.ELC.15 | C11: PJ | D11: RESELC | E11: RSH | F11: ='EIA23 EQ Cost'!G9 -> 2015 | G11: ='EIA23 EQ Cost'!H9 -> 22.5 | H11: ='EIA23 EQ Cost'!J9 -> 3.4718966 | I11: ='EIA23 EQ Cost'!K9 -> 1 | J11: 1 | K11: 0.16 | L11: 0.16 | M11: 0.16 | N11: 0.16 | O11: 0.16 | Q11: 0.18 | BF11: R2,R3,R4,R5,R6
A12: ='EIA23 EQ Cost'!B10 -> RSHERUV120 | B12: ='EIA23 EQ Cost'!C10 -> Electric Resistance Unit Heater Ver1.RSH.ELC.20 | C12: PJ | D12: RESELC | E12: RSH | F12: ='EIA23 EQ Cost'!G10 -> 2020 | G12: ='EIA23 EQ Cost'!H10 -> 22.5 | H12: ='EIA23 EQ Cost'!J10 -> 3.4718966 | I12: ='EIA23 EQ Cost'!K10 -> 1 | J12: 1 | K12: 0.16 | L12: 0.16 | M12: 0.16 | N12: 0.16 | O12: 0.16 | Q12: 0.18 | BF12: R2,R3,R4,R5,R6
A13: ='EIA23 EQ Cost'!B11 -> RSHERUV122 | B13: ='EIA23 EQ Cost'!C11 -> Electric Resistance Unit Heater Ver1.RSH.ELC.22 | C13: PJ | D13: RESELC | E13: RSH | F13: ='EIA23 EQ Cost'!G11 -> 2022 | G13: ='EIA23 EQ Cost'!H11 -> 22.5 | H13: ='EIA23 EQ Cost'!J11 -> 8.0098408 | I13: ='EIA23 EQ Cost'!K11 -> 1 | J13: 1 | K13: 0.16 | L13: 0.16 | M13: 0.16 | N13: 0.16 | O13: 0.16 | Q13: 0.18 | BF13: R2,R3,R4,R5,R6
A14: ='EIA23 EQ Cost'!B12 -> *Electric Furnaces | BF14: =A14 -> *Electric Furnaces
A15: ='EIA23 EQ Cost'!B13 -> RSHEFRV115 | B15: ='EIA23 EQ Cost'!C13 -> Electric Furnace Ver1.RSH.ELC.15 | C15: PJ | D15: RESELC | E15: RSH | F15: ='EIA23 EQ Cost'!G13 -> 2015 | G15: ='EIA23 EQ Cost'!H13 -> 22.5 | H15: ='EIA23 EQ Cost'!J13 -> 0.98095202 | I15: ='EIA23 EQ Cost'!K13 -> 0.98 | J15: 1 | K15: 0.16 | L15: 0.16 | M15: 0.16 | N15: 0.16 | O15: 0.16 | Q15: 0.18 | BF15: R2,R3,R4,R5,R6
A16: ='EIA23 EQ Cost'!B14 -> RSHEFRV120 | B16: ='EIA23 EQ Cost'!C14 -> Electric Furnace Ver1.RSH.ELC.20 | C16: PJ | D16: RESELC | E16: RSH | F16: ='EIA23 EQ Cost'!G14 -> 2020 | G16: ='EIA23 EQ Cost'!H14 -> 22.5 | H16: ='EIA23 EQ Cost'!J14 -> 0.98095202 | I16: ='EIA23 EQ Cost'!K14 -> 0.98 | J16: 1 | K16: 0.16 | L16: 0.16 | M16: 0.16 | N16: 0.16 | O16: 0.16 | Q16: 0.18 | BF16: R2,R3,R4,R5,R6
A17: ='EIA23 EQ Cost'!B15 -> RSHEFRV122 | B17: ='EIA23 EQ Cost'!C15 -> Electric Furnace Ver1.RSH.ELC.22 | C17: PJ | D17: RESELC | E17: RSH | F17: ='EIA23 EQ Cost'!G15 -> 2022 | G17: ='EIA23 EQ Cost'!H15 -> 22.5 | H17: ='EIA23 EQ Cost'!J15 -> 1.1254333 | I17: ='EIA23 EQ Cost'!K15 -> 1 | J17: 1 | K17: 0.16 | L17: 0.16 | M17: 0.16 | N17: 0.16 | O17: 0.16 | Q17: 0.18 | BF17: R2,R3,R4,R5,R6
A18: ='EIA23 EQ Cost'!B16 -> *Electric Heat Pumps (Residential Air Source Heat Pumps) | BF18: =A18 -> *Electric Heat Pumps (Residential Air Source Heat Pumps)
A19: ='EIA23 EQ Cost'!B17 -> RSHEHPBS15 | B19: ='EIA23 EQ Cost'!C17 -> Electric Heat Pump Base.RSH.ELC.15 | C19: PJ | D19: RESELC | F19: ='EIA23 EQ Cost'!G17 -> 2015 | G19: ='EIA23 EQ Cost'!H17 -> 15.5 | H19: ='EIA23 EQ Cost'!J17 -> 8.3165467 | K19: =0.16*2 -> 0.32 | L19: =0.16*2 -> 0.32 | M19: =0.16*2 -> 0.32 | N19: =0.16*2 -> 0.32 | O19: =0.16*2 -> 0.32 | Q19: 0.18 | T19: 0 | U19: 0 | V19: 0 | W19: 0 | X19: 0 | Y19: 0 | Z19: 0 | AA19: 0 | AO19: =Resid!V10 -> #REF! | AP19: =Resid!W10 -> #REF! | AQ19: =Resid!X10 -> #REF! | AR19: =Resid!Y10 -> #REF! | AS19: =Resid!Z10 -> #REF! | AT19: =AO19 -> #REF! | AU19: =AP19 -> #REF! | AV19: =AQ19 -> #REF! | AW19: =AR19 -> #REF! | AX19: =AS19 -> #REF! | BF19: R2,R3,R4,R5,R6
E20: RSH | J20: 0.75
E21: RSC | J21: 0.5
A22: ='EIA23 EQ Cost'!B18 -> RSHEHPB120 | B22: ='EIA23 EQ Cost'!C18 -> Electric Heat Pump Base.RSH.ELC.20 | C22: PJ | D22: RESELC | F22: ='EIA23 EQ Cost'!G18 -> 2020 | G22: ='EIA23 EQ Cost'!H18 -> 15.5 | H22: ='EIA23 EQ Cost'!J18 -> 9.8821833 | K22: =0.16*2 -> 0.32 | L22: =0.16*2 -> 0.32 | M22: =0.16*2 -> 0.32 | N22: =0.16*2 -> 0.32 | O22: =0.16*2 -> 0.32 | Q22: 0.18 | U22: 0 | V22: 0 | W22: 0 | X22: 0 | Y22: 0 | Z22: 0 | AA22: 0 | BF22: R2,R3,R4,R5,R6
E23: RSH | J23: 0.75
E24: RSC | J24: 0.5
A25: ='EIA23 EQ Cost'!B19 -> RSHEHPBS22 | B25: ='EIA23 EQ Cost'!C19 -> Electric Heat Pump Base.RSH.ELC.22 | C25: PJ | D25: RESELC | F25: ='EIA23 EQ Cost'!G19 -> 2022 | G25: ='EIA23 EQ Cost'!H19 -> 15.5 | H25: ='EIA23 EQ Cost'!J19 -> 9.8821833 | K25: =0.16*2 -> 0.32 | L25: =0.16*2 -> 0.32 | M25: =0.16*2 -> 0.32 | N25: =0.16*2 -> 0.32 | O25: =0.16*2 -> 0.32 | Q25: 0.18 | V25: 0 | W25: 0 | X25: 0 | Y25: 0 | Z25: 0 | AA25: 0 | BF25: R2,R3,R4,R5,R6
E26: RSH | J26: 0.75
E27: RSC | J27: 0.5
A28: ='EIA23 EQ Cost'!B20 -> RSHEHPV122 | B28: ='EIA23 EQ Cost'!C20 -> Electric Heat Pump Ver1.RSH.ELC.22 | C28: PJ | D28: RESELC | F28: ='EIA23 EQ Cost'!G20 -> 2022 | G28: ='EIA23 EQ Cost'!H20 -> 15.5 | H28: ='EIA23 EQ Cost'!J20 -> 12.381456 | K28: =0.16*2 -> 0.32 | L28: =0.16*2 -> 0.32 | M28: =0.16*2 -> 0.32 | N28: =0.16*2 -> 0.32 | O28: =0.16*2 -> 0.32 | Q28: 0.18 | V28: 0 | W28: 0 | X28: 0 | Y28: 0 | Z28: 0 | AA28: 0
E29: RSH | J29: 0.75
E30: RSC | J30: 0.5
A31: ='EIA23 EQ Cost'!B21 -> RSHEHPV123 | B31: ='EIA23 EQ Cost'!C21 -> Electric Heat Pump Ver1.RSH.ELC.23 | C31: PJ | D31: RESELC | F31: ='EIA23 EQ Cost'!G21 -> 2023 | G31: ='EIA23 EQ Cost'!H21 -> 15.5 | H31: ='EIA23 EQ Cost'!J21 -> 9.7816379 | K31: =0.16*2 -> 0.32 | L31: =0.16*2 -> 0.32 | M31: =0.16*2 -> 0.32 | N31: =0.16*2 -> 0.32 | O31: =0.16*2 -> 0.32 | Q31: 0.18 | V31: 0 | W31: 0 | X31: 0 | Y31: 0 | Z31: 0 | AA31: 0 | BF31: R2,R3,R4,R5,R6
E32: RSH | J32: 0.75
E33: RSC | J33: 0.5
A34: ='EIA23 EQ Cost'!B22 -> RSHEHPV223 | B34: ='EIA23 EQ Cost'!C22 -> Electric Heat Pump Ver2.RSH.ELC.23 | C34: PJ | D34: RESELC | F34: ='EIA23 EQ Cost'!G22 -> 2023 | G34: ='EIA23 EQ Cost'!H22 -> 15.5 | H34: ='EIA23 EQ Cost'!J22 -> 9.9683652 | K34: =0.16*2 -> 0.32 | L34: =0.16*2 -> 0.32 | M34: =0.16*2 -> 0.32 | N34: =0.16*2 -> 0.32 | O34: =0.16*2 -> 0.32 | Q34: 0.18 | V34: 0 | W34: 0 | X34: 0 | Y34: 0 | Z34: 0 | AA34: 0 | BF34: R2,R3,R4,R5,R6
E35: RSH | J35: 0.75
E36: RSC | J36: 0.5
A37: ='EIA23 EQ Cost'!B23 -> RSHEHPV323 | B37: ='EIA23 EQ Cost'!C23 -> Electric Heat Pump Ver3.RSH.ELC.23 | C37: PJ | D37: RESELC | F37: ='EIA23 EQ Cost'!G23 -> 2023 | G37: ='EIA23 EQ Cost'!H23 -> 15.5 | H37: ='EIA23 EQ Cost'!J23 -> 12.381456 | K37: =0.16*2 -> 0.32 | L37: =0.16*2 -> 0.32 | M37: =0.16*2 -> 0.32 | N37: =0.16*2 -> 0.32 | O37: =0.16*2 -> 0.32 | Q37: 0.18 | V37: 0 | W37: 0 | X37: 0 | Y37: 0 | Z37: 0 | AA37: 0 | BF37: R2,R3,R4,R5,R6
E38: RSH | J38: 0.75
E39: RSC | J39: 0.5
A40: ='EIA23 EQ Cost'!B24 -> RSHEHPV130 | B40: ='EIA23 EQ Cost'!C24 -> Electric Heat Pump Ver1.RSH.ELC.30 | C40: PJ | D40: RESELC | F40: ='EIA23 EQ Cost'!G24 -> 2030 | G40: ='EIA23 EQ Cost'!H24 -> 15.5 | H40: ='EIA23 EQ Cost'!J24 -> 9.9683652 | K40: =0.16*2 -> 0.32 | L40: =0.16*2 -> 0.32 | M40: =0.16*2 -> 0.32 | N40: =0.16*2 -> 0.32 | O40: =0.16*2 -> 0.32 | Q40: 0.18 | X40: 0 | Y40: 0 | Z40: 0 | AA40: 0 | BF40: R2,R3,R4,R5,R6
E41: RSH | J41: 0.75
E42: RSC | J42: 0.5
A43: ='EIA23 EQ Cost'!B25 -> RSHEHPV230 | B43: ='EIA23 EQ Cost'!C25 -> Electric Heat Pump Ver2.RSH.ELC.30 | C43: PJ | D43: RESELC | F43: ='EIA23 EQ Cost'!G25 -> 2030 | G43: ='EIA23 EQ Cost'!H25 -> 15.5 | H43: ='EIA23 EQ Cost'!J25 -> 12.381456 | K43: =0.16*2 -> 0.32 | L43: =0.16*2 -> 0.32 | M43: =0.16*2 -> 0.32 | N43: =0.16*2 -> 0.32 | O43: =0.16*2 -> 0.32 | Q43: 0.18 | X43: 0 | Y43: 0 | Z43: 0 | AA43: 0 | BF43: R2,R3,R4,R5,R6
E44: RSH | J44: 0.75
...

Sheet TechData_SolarPV
A1: TechData | B1: _GLOBAL,R0,R1,R2,R3,R4,R5,R6
F4: ~FI_T
A5: Region | B5: TechName | C5: *TechDesc | D5: *Units | E5: CommIN | F5: CommOUT | G5: NCAP_START | H5: NCAP_TLIFE | I5: PRC_CAPACT | J5: EFF | K5: Peak | L5: NCAP_COST~2010 | M5: NCAP_COST~2015 | N5: NCAP_COST~2020 | O5: NCAP_COST~2025 | P5: NCAP_COST~2030 | Q5: NCAP_COST~2035 | R5: NCAP_COST~2040 | S5: NCAP_COST~2045 | T5: NCAP_COST~2050 | U5: NCAP_COST~2055 | V5: NCAP_FOM | W5: NCAP_AF~IDAM | X5: NCAP_AF~IDPM | Y5: *NCAP_AF~IP | Z5: NCAP_AF~IP | AA5: NCAP_AF~IN | AB5: NCAP_AF~SDAM | AC5: NCAP_AF~SDPM | AD5: *NCAP_AF~SP | AE5: NCAP_AF~SP | AF5: NCAP_AF~SN | AG5: NCAP_AF~WDAM | AH5: NCAP_AF~WDPM | AI5: *NCAP_AF~WP | AJ5: NCAP_AF~WP | AK5: NCAP_AF~WN | AL5: NCAP_DRATE | AN5: Input | AO5: Output | AQ5: ACT_BND~FX~2010 | AR5: ACT_BND~FX~2015 | AS5: ACT_BND~LO~2020 | AT5: ACT_BND~LO~2025 | AU5: ACT_BND~LO~2030 | AV5: ACT_BND~LO~2035 | AW5: ACT_BND~LO~2040 | AX5: ACT_BND~LO~2045 | AY5: ACT_BND~LO~2050 | AZ5: ACT_BND~LO~2055 | BA5: ACT_BND~UP~2020 | BB5: ACT_BND~UP~2025 | BC5: ACT_BND~UP~2030 | BD5: ACT_BND~UP~2035 | BE5: ACT_BND~UP~2040 | BF5: ACT_BND~UP~2045 | BG5: ACT_BND~UP~2050 | BH5: ACT_BND~UP~2055
A6: * Solar PV Technologies
A7: *R1 | B7: ="ESOLPVRES"&RIGHT(G7,2) -> ESOLPVRES11 | C7: Solar PV Distributed Residential Generation | E7: SOLRES | F7: RESELC | G7: 2011 | H7: 30 | I7: 31.536 | J7: =AO7/AN7 -> 0.34965035 | K7: 0.1 | L7: 6546.9995 | M7: 3903.1781 | N7: 3453.8021 | O7: 3004.4261 | P7: 2839.3022 | Q7: 2674.1784 | R7: 2596.418 | S7: 2558.6683 | T7: 2540.0679 | U7: 2530.8353 | V7: 10 | W7: 0 | X7: 0.31357247 | Y7: 0.31357247 | Z7: =Y7*0.2 -> 0.062714494 | AA7: 0 | AB7: 0.3060734 | AC7: 0.3060734 | AD7: 0.3060734 | AE7: =AD7*0.2 -> 0.061214679 | AF7: 0 | AG7: 0.3020009 | AH7: 0.3020009 | AI7: 0.3020009 | AJ7: =AI7*0.2 -> 0.06040018 | AK7: 0 | AL7: 0.15 | AN7: 2.86 | AO7: 1
A8: R2 | B8: ="ESOLPVRES"&RIGHT(G8,2) -> ESOLPVRES11 | C8: Solar PV Distributed Residential Generation | E8: SOLRES | F8: RESELC | G8: 2011 | H8: 30 | I8: 31.536 | J8: =AO8/AN8 -> 0.34965035 | K8: 0.1 | L8: 6546.9995 | M8: 3903.1781 | N8: 3453.8021 | O8: 3004.4261 | P8: 2839.3022 | Q8: 2674.1784 | R8: 2596.418 | S8: 2558.6683 | T8: 2540.0679 | U8: 2530.8353 | V8: 10 | W8: 0 | X8: 0.317351 | Y8: 0.317351 | Z8: =Y8*0.2 -> 0.0634702 | AA8: 0 | AB8: 0.30541737 | AC8: 0.30541737 | AD8: 0.30541737 | AE8: =AD8*0.2 -> 0.061083474 | AF8: 0 | AG8: 0.29271621 | AH8: 0.29271621 | AI8: 0.29271621 | AJ8: =AI8*0.2 -> 0.058543242 | AK8: 0 | AL8: 0.15 | AN8: 2.86 | AO8: 1 | AQ8: ='Rooftop Calc'!AC65 -> 0.0071945835 | AR8: ='Rooftop Calc'!AC71 -> 0.109328 | AS8: ='Rooftop Calc'!AC77 -> 0.24496493 | AT8: ='Rooftop Calc'!AC84 -> 0.43039234 | AU8: ='Rooftop Calc'!AC91 -> 0.61581975 | AV8: ='Rooftop Calc'!AC98 -> 0.80124716 | AW8: ='Rooftop Calc'!AC105 -> 0.98667458 | AX8: ='Rooftop Calc'!AC112 -> 1.1649074 | AY8: ='Rooftop Calc'!AC119 -> 1.2410068 | AZ8: ='Rooftop Calc'!AC126 -> 1.3072238 | BA8: ='Rooftop Calc'!AK77 -> 0.37640069 | BB8: ='Rooftop Calc'!AK84 -> 0.64269247 | BC8: ='Rooftop Calc'!AK91 -> 0.90976515 | BD8: ='Rooftop Calc'!AK98 -> 1.1760569 | BE8: ='Rooftop Calc'!AK105 -> 1.4431296 | BF8: ='Rooftop Calc'!AK112 -> 1.7094214 | BG8: ='Rooftop Calc'!AK119 -> 1.9764941 | BH8: ='Rooftop Calc'!AK126 -> 2.2427859
A9: R3 | B9: ="ESOLPVRES"&RIGHT(G9,2) -> ESOLPVRES11 | C9: Solar PV Distributed Residential Generation | E9: SOLRES | F9: RESELC | G9: 2011 | H9: 30 | I9: 31.536 | J9: =AO9/AN9 -> 0.34965035 | K9: 0.1 | L9: 6546.9995 | M9: 3903.1781 | N9: 3453.8021 | O9: 3004.4261 | P9: 2839.3022 | Q9: 2674.1784 | R9: 2596.418 | S9: 2558.6683 | T9: 2540.0679 | U9: 2530.8353 | V9: 10 | W9: 0 | X9: 0.29713464 | Y9: 0.29713464 | Z9: =Y9*0.2 -> 0.059426928 | AA9: 0 | AB9: 0.30672516 | AC9: 0.30672516 | AD9: 0.30672516 | AE9: =AD9*0.2 -> 0.061345033 | AF9: 0 | AG9: 0.26137287 | AH9: 0.26137287 | AI9: 0.26137287 | AJ9: =AI9*0.2 -> 0.052274574 | AK9: 0 | AL9: 0.15 | AN9: 2.86 | AO9: 1 | AQ9: ='Rooftop Calc'!AD65 -> 0.0037523355 | AR9: ='Rooftop Calc'!AD71 -> 0.073448493 | AS9: ='Rooftop Calc'!AD77 -> 0.13820064 | AT9: ='Rooftop Calc'!AD84 -> 0.20768834 | AU9: ='Rooftop Calc'!AD91 -> 0.27717603 | AV9: ='Rooftop Calc'!AD98 -> 0.34666373 | AW9: ='Rooftop Calc'!AD105 -> 0.41615142 | AX9: ='Rooftop Calc'!AD112 -> 0.48188678 | AY9: ='Rooftop Calc'!AD119 -> 0.47792598 | AZ9: ='Rooftop Calc'!AD126 -> 0.46631225 | BA9: ='Rooftop Calc'!AL77 -> 0.25287267 | BB9: ='Rooftop Calc'!AL84 -> 0.43177221 | BC9: ='Rooftop Calc'!AL91 -> 0.61119639 | BD9: ='Rooftop Calc'!AL98 -> 0.79009593 | BE9: ='Rooftop Calc'!AL105 -> 0.96952011 | BF9: ='Rooftop Calc'!AL112 -> 1.1484197 | BG9: ='Rooftop Calc'!AL119 -> 1.3278438 | BH9: ='Rooftop Calc'!AL126 -> 1.5067434
A10: R4 | B10: ="ESOLPVRES"&RIGHT(G10,2) -> ESOLPVRES11 | C10: Solar PV Distributed Residential Generation | E10: SOLRES | F10: RESELC | G10: 2011 | H10: 30 | I10: 31.536 | J10: =AO10/AN10 -> 0.34965035 | K10: 0.1 | L10: 6546.9995 | M10: 3903.1781 | N10: 3453.8021 | O10: 3004.4261 | P10: 2839.3022 | Q10: 2674.1784 | R10: 2596.418 | S10: 2558.6683 | T10: 2540.0679 | U10: 2530.8353 | V10: 10 | W10: 0 | X10: 0.33039362 | Y10: 0.33039362 | Z10: =Y10*0.2 -> 0.066078724 | AA10: 0 | AB10: 0.32440092 | AC10: 0.32440092 | AD10: 0.32440092 | AE10: =AD10*0.2 -> 0.064880183 | AF10: 0 | AG10: 0.34679382 | AH10: 0.34679382 | AI10: 0.34679382 | AJ10: =AI10*0.2 -> 0.069358764 | AK10: 0 | AL10: 0.15 | AN10: 2.86 | AO10: 1 | AQ10: ='Rooftop Calc'!AE65 -> 0.0011972254 | AR10: ='Rooftop Calc'!AE71 -> 0.0093117528 | AS10: ='Rooftop Calc'!AE77 -> 0.017877615 | AT10: ='Rooftop Calc'!AE84 -> 0.024528867 | AU10: ='Rooftop Calc'!AE91 -> 0.031180119 | AV10: ='Rooftop Calc'!AE98 -> 0.037831371 | AW10: ='Rooftop Calc'!AE105 -> 0.044482623 | AX10: ='Rooftop Calc'!AE112 -> 0.04993665 | AY10: ='Rooftop Calc'!AE119 -> 0.047276149 | AZ10: ='Rooftop Calc'!AE126 -> 0.042167162 | BA10: ='Rooftop Calc'!AM77 -> 0.032059035 | BB10: ='Rooftop Calc'!AM84 -> 0.054739804 | BC10: ='Rooftop Calc'!AM91 -> 0.077487086 | BD10: ='Rooftop Calc'!AM98 -> 0.10016786 | BE10: ='Rooftop Calc'!AM105 -> 0.12291514 | BF10: ='Rooftop Calc'!AM112 -> 0.14559591 | BG10: ='Rooftop Calc'!AM119 -> 0.16834319 | BH10: ='Rooftop Calc'!AM126 -> 0.19102396
A11: R5 | B11: ="ESOLPVRES"&RIGHT(G11,2) -> ESOLPVRES11 | C11: Solar PV Distributed Residential Generation | E11: SOLRES | F11: RESELC | G11: 2011 | H11: 30 | I11: 31.536 | J11: =AO11/AN11 -> 0.34965035 | K11: 0.1 | L11: 6546.9995 | M11: 3903.1781 | N11: 3453.8021 | O11: 3004.4261 | P11: 2839.3022 | Q11: 2674.1784 | R11: 2596.418 | S11: 2558.6683 | T11: 2540.0679 | U11: 2530.8353 | V11: 10 | W11: 0 | X11: 0.34379748 | Y11: 0.34379748 | Z11: =Y11*0.2 -> 0.068759495 | AA11: 0 | AB11: 0.29466039 | AC11: 0.29466039 | AD11: 0.29466039 | AE11: =AD11*0.2 -> 0.058932078 | AF11: 0 | AG11: 0.36077416 | AH11: 0.36077416 | AI11: 0.36077416 | AJ11: =AI11*0.2 -> 0.072154833 | AK11: 0 | AL11: 0.15 | AN11: 2.86 | AO11: 1 | AQ11: ='Rooftop Calc'!AF65 -> 0.0017437956 | AR11: ='Rooftop Calc'!AF71 -> 0.32034551 | AS11: ='Rooftop Calc'!AF77 -> 0.57042833 | AT11: ='Rooftop Calc'!AF84 -> 1.0833094 | AU11: ='Rooftop Calc'!AF91 -> 1.5961905 | AV11: ='Rooftop Calc'!AF98 -> 2.1090715 | AW11: ='Rooftop Calc'!AF105 -> 2.6219526 | AX11: ='Rooftop Calc'!AF112 -> 3.1330899 | AY11: ='Rooftop Calc'!AF119 -> 3.3256254 | AZ11: ='Rooftop Calc'!AF126 -> 3.7957449 | BA11: ='Rooftop Calc'!AN77 -> 1.1029038 | BB11: ='Rooftop Calc'!AN84 -> 1.883174 | BC11: ='Rooftop Calc'!AN91 -> 2.6657323 | BD11: ='Rooftop Calc'!AN98 -> 3.4460025 | BE11: ='Rooftop Calc'!AN105 -> 4.2285608 | BF11: ='Rooftop Calc'!AN112 -> 5.0088309 | BG11: ='Rooftop Calc'!AN119 -> 5.7913893 | BH11: ='Rooftop Calc'!AN126 -> 6.5716594
A12: R6 | B12: ="ESOLPVRES"&RIGHT(G12,2) -> ESOLPVRES11 | C12: Solar PV Distributed Residential Generation | E12: SOLRES | F12: RESELC | G12: 2011 | H12: 30 | I12: 31.536 | J12: =AO12/AN12 -> 0.34965035 | K12: 0.1 | L12: 6546.9995 | M12: 3903.1781 | N12: 3453.8021 | O12: 3004.4261 | P12: 2839.3022 | Q12: 2674.1784 | R12: 2596.418 | S12: 2558.6683 | T12: 2540.0679 | U12: 2530.8353 | V12: 10 | W12: 0 | X12: 0.34054374 | Y12: 0.34054374 | Z12: =Y12*0.2 -> 0.068108748 | AA12: 0 | AB12: 0.30737101 | AC12: 0.30737101 | AD12: 0.30737101 | AE12: =AD12*0.2 -> 0.061474202 | AF12: 0 | AG12: 0.32128124 | AH12: 0.32128124 | AI12: 0.32128124 | AJ12: =AI12*0.2 -> 0.064256247 | AK12: 0 | AL12: 0.15 | AN12: 2.86 | AO12: 1 | AQ12: ='Rooftop Calc'!AG65 -> 0.012993033 | AR12: ='Rooftop Calc'!AG71 -> 0.17523498 | AS12: ='Rooftop Calc'!AG77 -> 0.47194746 | AT12: ='Rooftop Calc'!AG84 -> 0.89934986 | AU12: ='Rooftop Calc'!AG91 -> 1.3267523 | AV12: ='Rooftop Calc'!AG98 -> 1.7541547 | AW12: ='Rooftop Calc'!AG105 -> 2.1815571 | AX12: ='Rooftop Calc'!AG112 -> 2.5959664 | AY12: ='Rooftop Calc'!AG119 -> 2.8481338 | AZ12: ='Rooftop Calc'!AG126 -> 3.138694 | BA12: ='Rooftop Calc'!AO77 -> 0.60330901 | BB12: ='Rooftop Calc'!AO84 -> 1.0301314 | BC12: ='Rooftop Calc'!AO91 -> 1.4582054 | BD12: ='Rooftop Calc'!AO98 -> 1.8850278 | BE12: ='Rooftop Calc'!AO105 -> 2.3131018 | BF12: ='Rooftop Calc'!AO112 -> 2.7399241 | BG12: ='Rooftop Calc'!AO119 -> 3.1679982 | BH12: ='Rooftop Calc'!AO126 -> 3.5948205
A13: * | AQ13: =SUM(AQ8:AQ12) -> 0.026880973 | AR13: =SUM(AR8:AR12) -> 0.68766875 | AS13: =SUM(AS8:AS12) -> 1.443419 | AT13: =SUM(AT8:AT12) -> 2.6452688 | AU13: =SUM(AU8:AU12) -> 3.8471186 | AV13: =SUM(AV8:AV12) -> 5.0489684 | AW13: =SUM(AW8:AW12) -> 6.2508183 | AX13: =SUM(AX8:AX12) -> 7.4257871 | ... BH13: =SUM(BH8:BH12) -> 14.107033
A14: *

Sheet TechData-Emis
A1: TechData | B1: _GLOBAL,R0,R1,R2,R3,R4,R5,R6
F4: FI_T
A5: Region | B5: TechName | C5: *TechDesc | D5: *Units | E5: CommIN | F5: CommOUT | G5: NCAP_START | H5: NCAP_LIFE | I5: EFF | J5: ENV_ACT~CO2~2010 | K5: ENV_ACT~CO2~2055 | L5: ENV_ACT~NOX~2010 | M5: ENV_ACT~NOX~2055 | N5: ENV_ACT~PM10~2010 | O5: ENV_ACT~PM10~2055 | P5: ENV_ACT~PM25~2010 | Q5: ENV_ACT~PM25~2055 | R5: ENV_ACT~VOC~2010 | S5: ENV_ACT~VOC~2055 | T5: ENV_ACT~CO~2010 | U5: ENV_ACT~CO~2055 | V5: ENV_ACT~CH4~2010 | W5: ENV_ACT~CH4~2055 | X5: ENV_ACT~N2O~2010 | Y5: ENV_ACT~N2O~2055 | Z5: ENV_ACT~BC~2010 | AA5: ENV_ACT~BC~2055 | AB5: ENV_ACT~OC~2010 | AC5: ENV_ACT~OC~2055 | AD5: ENV_ACT~SO2~2010 | AE5: ENV_ACT~SO2~2055 | AF5: ENV_ACT~CO2R | AG5: ENV_ACT~NOXR | AH5: ENV_ACT~PM10R | AI5: ENV_ACT~SO2R | AJ5: ENV_ACT~NOX2CR
A6: * Residential
A7: * | B7: SERESCOA | C7: Emissions: COA to RES | D7: PJ | E7: RESCOA | F7: RESCOAEA | G7: 2010 | H7: 55 | I7: 1 | J7: =EmisCO2Coef!D19 -> 0.10060378 | K7: =J7 -> 0.10060378
A8: R2,R3,R4,R5,R6 | B8: SERESNGA | C8: Emissions: NGA to RES | D8: PJ | E8: RESNGA | F8: RESNGAEA | G8: 2010 | H8: 55 | I8: 1 | J8: =EmisCO2Coef!D9 -> 0.055983606 | K8: =J8 -> 0.055983606 | L8: =EmisRes!H6 -> 0.039275865 | M8: =L8 -> 0.039275865 | N8: =EmisRes!I6 -> 0.00021727074 | O8: =N8 -> 0.00021727074 | P8: =EmisRes!J6 -> 0.00017966619 | Q8: =P8 -> 0.00017966619 | R8: =EmisRes!K6 -> 0.0022980559 | S8: =R8 -> 0.0022980559 | T8: =EmisRes!L6 -> 0.016713134 | U8: =T8 -> 0.016713134 | V8: =EmisRes!M6 -> 0.0047390856 | W8: =V8 -> 0.0047390856 | X8: =EmisRes!N6 -> 9.4781712e-05 | Y8: =X8 -> 9.4781712e-05 | Z8: =P8*#REF! -> #REF! | AA8: =Z8 -> #REF! | AB8: =R8*#REF! -> #REF! | AC8: =AB8 -> #REF! | AD8: =EmisRes!G6 -> 0.00025069701 | AE8: =AD8 -> 0.00025069701 | AF8: =J8*1000 -> 55.983606 | AG8: =L8 -> 0.039275865 | AH8: =N8 -> 0.00021727074 | AI8: =AD8 -> 0.00025069701 | AJ8: =AG8 -> 0.039275865
A9: * | B9: SERESBIO | C9: Emissions: BIO to RES | D9: PJ | E9: RESBIO | F9: RESBIOEA | G9: 2010 | H9: 55 | I9: 1 | L9: =EmisRes!H5 -> 0.12680826 | M9: =L9 -> 0.12680826 | N9: =EmisRes!I5 -> 0.70373709 | O9: =N9 -> 0.70373709 | P9: =EmisRes!J5 -> 0.6052139 | Q9: =P9 -> 0.6052139 | R9: =EmisRes!K5 -> 1.1519338 | S9: =R9 -> 1.1519338 | T9: =EmisRes!L5 -> 5.1881544 | U9: =T9 -> 5.1881544 | V9: =EmisRes!M5 -> 0.1872974 | W9: =V9 -> 0.1872974 | X9: =EmisRes!N5 -> 0.0039808319 | Y9: =X9 -> 0.0039808319 | Z9: =P9*#REF! -> #REF! | AA9: =Z9 -> #REF! | AB9: =R9*#REF! -> #REF! | AC9: =AB9 -> #REF! | AD9: =EmisRes!G5 -> 0.010748065 | AE9: =AD9 -> 0.010748065 | AF9: =J9*1000 -> 0 | AG9: =L9 -> 0.12680826 | AH9: =N9 -> 0.70373709 | AI9: =AD9 -> 0.010748065 | AJ9: =AG9 -> 0.12680826
A10: R2,R3,R4,R5,R6 | B10: SERESDSL | C10: Emissions: DSL to RES | D10: PJ | E10: RESDSL | F10: RESDSLEA | G10: 2010 | H10: 55 | I10: 1 | J10: =EmisCO2Coef!D10 -> 0.077180565 | K10: =J10 -> 0.077180565 | L10: =EmisRes!H7 -> 0.055800636 | M10: =L10 -> 0.055800636 | N10: =EmisRes!I7 -> 0.0073780841 | O10: =N10 -> 0.0073780841 | P10: =EmisRes!J7 -> 0.0066030752 | Q10: =P10 -> 0.0066030752 | R10: =EmisRes!K7 -> 0.0021700247 | S10: =R10 -> 0.0021700247 | T10: =EmisRes!L7 -> 0.015500177 | U10: =T10 -> 0.015500177 | V10: =EmisRes!M7 -> 0.0055180629 | W10: =V10 -> 0.0055180629 | X10: =EmisRes!N7 -> 0.00056869027 | Y10: =X10 -> 0.00056869027 | Z10: =P10*#REF! -> #REF! | AA10: =Z10 -> #REF! | AB10: =R10*#REF! -> #REF! | AC10: =AB10 -> #REF! | AD10: =EmisRes!G7 -> 0.1320615 | AE10: =AD10 -> 0.1320615 | AF10: =J10*1000 -> 77.180565 | AG10: =L10 -> 0.055800636 | AH10: =N10 -> 0.0073780841 | AI10: =AD10 -> 0.1320615 | AJ10: =AG10 -> 0.055800636
A11: * | B11: SERESKER | C11: Emissions: KER to RES | D11: PJ | E11: RESKER | F11: RESKEREA | G11: 2010 | H11: 55 | I11: 1 | J11: =EmisCO2Coef!D12 -> 0.076294281 | K11: =J11 -> 0.076294281 | L11: =EmisRes!H9 -> 0.05732605 | M11: =L11 -> 0.05732605 | N11: =EmisRes!I23 -> 0.0072612997 | O11: =N11 -> 0.0072612997 | P11: =EmisRes!J23 -> 0.0065288001 | Q11: =P11 -> 0.0065288001 | R11: =EmisRes!K23 -> 0.0021401725 | S11: =R11 -> 0.0021401725 | T11: =EmisRes!L23 -> 0.015923903 | U11: =T11 -> 0.015923903 | V11: =EmisRes!M23 -> 0.0056689094 | W11: =V11 -> 0.0056689094 | X11: =EmisRes!N23 -> 0.00056869027 | Y11: =X11 -> 0.00056869027 | Z11: =P11*#REF! -> #REF! | AA11: =Z11 -> #REF! | AB11: =R11*#REF! -> #REF! | AC11: =AB11 -> #REF! | AD11: =EmisRes!G23 -> 0.13567165 | AE11: =AD11 -> 0.13567165 | AF11: =J11*1000 -> 76.294281 | AG11: =L11 -> 0.05732605 | AH11: =N11 -> 0.0072612997 | AI11: =AD11 -> 0.13567165 | AJ11: =AG11 -> 0.05732605
A12: * | B12: SERESLPG | C12: Emissions: LPG to RES | D12: PJ | E12: RESLPG | F12: RESLPGEA | G12: 2010 | H12: 55 | I12: 1 | J12: =EmisCO2Coef!D13 -> 0.065711628 | K12: =J12 -> 0.065711628 | L12: =EmisRes!H8 -> 0.062863259 | M12: =L12 -> 0.062863259 | N12: =EmisRes!I22 -> 0.0002345644 | O12: =N12 -> 0.0002345644 | P12: =EmisRes!J22 -> 0.00018765152 | Q12: =P12 -> 0.00018765152 | R12: =EmisRes!K22 -> 0.0024394698 | S12: =R12 -> 0.0024394698 | T12: =EmisRes!L22 -> 0.017826894 | U12: =T12 -> 0.017826894 | V12: =EmisRes!M22 -> 0.010425988 | W12: =V12 -> 0.010425988 | X12: =EmisRes!N22 -> 0.00056869027 | Y12: =X12 -> 0.00056869027 | Z12: =P12*#REF! -> #REF! | AA12: =Z12 -> #REF! | AB12: =R12*#REF! -> #REF! | AC12: =AB12 -> #REF! | AD12: =EmisRes!G22 -> 0.00028147728 | AE12: =AD12 -> 0.00028147728 | AF12: =J12*1000 -> 65.711628 | AG12: =L12 -> 0.062863259 | AH12: =N12 -> 0.0002345644 | AI12: =AD12 -> 0.00028147728 | AJ12: =AG12 -> 0.062863259
A13: * Industrial

Sheet TechData_ZZ
A1: TechData | B1: _GLOBAL,R0,R1,R2,R3,R4,R5,R6
F4: FI_T
A5: Region | B5: TechName | C5: *TechDesc | D5: *Units | E5: CommIN | F5: CommOUT | G5: EFF | H5: ACT_COST
A6: * ZZ<dm>INFES Backstop Technologies
A7: R2,R3,R4,R5,R6 | B7: ZZRLT | C7: Residential Lighting - ZZINFES backstop | D7: PJ | E7: ZZDMY | F7: RLT | G7: 1 | H7: 9999
A8: *R2,R3,R4,R5,R6 | B8: ZZRFZ | C8: Residential Freezing - ZZINFES backstop | D8: PJ | E8: ZZDMY | F8: RFZ | G8: 1 | H8: 9999
A9: *R2,R3,R4,R5,R6 | B9: ZZRRF | C9: Residential Refrigeration - ZZINFES backstop | D9: PJ | E9: ZZDMY | F9: RRF | G9: 1 | H9: 9999
A10: R2,R3,R4,R5,R6 | B10: ZZRSC | C10: Residential Cooling - ZZINFES backstop | D10: PJ | E10: ZZDMY | F10: RSC | G10: 1 | H10: 9999
A11: *R2,R3,R4,R5,R6 | B11: ZZRSH | C11: Residential Heating - ZZINFES backstop | D11: PJ | E11: ZZDMY | F11: RSH | G11: 1 | H11: 9999
A12: R2,R3,R4,R5,R6 | B12: ZZRWH | C12: Residential Water Heating - ZZINFES backstop | D12: PJ | E12: ZZDMY | F12: RWH | G12: 1 | H12: 9999
A13: *
A14: * Dummy and Backstop Water Technologies
A15: *
A16: R2,R3,R4,R5,R6 | B16: ZZDMYRBLD | C16: Dummy RES Building to meet POPDM | D16: Mt, Mt/a | E16: ZZDMYH2O | F16: POPDMRES | G16: 1 | H16: 999999
A17: R2,R3,R4,R5,R6 | B17: ZZDMYRRFDM | C17: Dummy technology to meet RWROOFDM | D17: Mt, Mt/a | E17: ZZDMYH2O | F17: RWROOFDM | G17: 1 | H17: 999999
A18: *

Sheet TechData_SESC
A1: TechData | B1: _GLOBAL,R0,R1,R2,R3,R4,R5,R6
F4: FI_T
A5: Region | B5: TechName | C5: *TechDesc | D5: *Units | E5: CommIN | F5: CommOUT | G5: NCAP_START | H5: NCAP_TLIFE | I5: EFF | J5: Share~UP | K5: Share~UP | L5: Peak | M5: NCAP_AF | N5: PRC_CAPACT | O5: NCAP_COST | Q5: Input | R5: Output | S5: Input | T5: Output
A6: * Collectors
A7: * Emissions Accounting
A8: R2,R3,R4,R5,R6 | B8: SCRESELC | C8: Collector: ELC to RES | D8: PJ | E8: ELC | F8: RESELC | G8: 2010 | I8: =T8/S8 -> 1 | L8: 1 | M8: 1 | N8: 1 | S8: 1 | T8: 1
A9: *
A10: * Building Retrofit Collectors
A11: R2,R3,R4,R5,R6 | B11: XELCRBLD | C11: Collects ELC for use in buildings | D11: PJ | E11: RESELC | F11: RESELCBLD | G11: 2010 | I11: =T11/S11 -> 1 | L11: 1 | M11: 1 | N11: 1 | O11: 0 | S11: 1 | T11: 1
A12: R2,R3,R4,R5,R6 | B12: XNGARBLD | C12: Collects NGA for use in buildings | D12: PJ | E12: RESNGAEA | F12: RESNGABLD | G12: 2010 | M12: 1 | N12: 1 | O12: 0 | Q12: 1 | R12: 1
A13: *R2,R3,R4,R5,R6 | B13: XRFLRBLD | C13: Collects RFL for use in buildings | D13: PJ | E13: RESRFLEA | F13: RESRFLBLD | G13: 2010 | M13: 1 | N13: 1 | O13: 0 | Q13: 1 | R13: 1
A14: R2,R3,R4,R5,R6 | B14: XDSLRBLD | C14: Collects DSL for use in buildings | D14: PJ | E14: RESDSLEA | F14: RESDSLBLD | G14: 2010 | M14: 1 | N14: 1 | O14: 0 | Q14: 1 | R14: 1
A15: R2,R3,R4,R5,R6 | B15: RELCHE | C15: High efficiency building ELC without retrofits | D15: PJ | E15: RESELCBLD | F15: RESELCRB | G15: 2010 | I15: =T15/S15 -> 1 | L15: 1 | M15: 1 | N15: 1 | O15: 0 | S15: 1 | T15: 1
A16: R2,R3,R4,R5,R6 | B16: RBLDBAUHE | C16: High efficiency building energy without retrofits | D16: PJ | E16: RESNGABLD | G16: 2010 | I16: =SUM(R19,R20,R21)/SUM(Q16,Q17,Q18) -> 1 | J16: =Q16/SUM(Q16,Q17,Q18) -> 0.33333333 | M16: 1 | N16: 1 | O16: 0 | Q16: 1
E17: RESDSLBLD | J17: =Q17/SUM(Q16,Q17,Q18) -> 0.33333333 | Q17: 1
A18: * | E18: RESRFLBLD | J18: =Q18/SUM(Q16,Q17,Q18) -> 0.33333333 | Q18: 1
F19: RESNGARB | K19: =R19/SUM(R19,R20,R21) -> 0.33333333 | R19: 1
F20: RESDSLRB | K20: =R20/SUM(R19,R20,R21) -> 0.33333333 | R20: 1
A21: * | F21: RESRFLRB | K21: =R21/SUM(R19,R20,R21) -> 0.33333333 | R21: 1
A22: R2,R3,R4,R5,R6 | B22: RELCBAU | C22: Building ELC without retrofits | D22: PJ | E22: RESELCBLD | F22: RESELCRM | G22: 2010 | I22: =T22/S22 -> 1 | L22: 1 | M22: 1 | N22: 1 | O22: 0 | S22: 1 | T22: 1
A23: R2,R3,R4,R5,R6 | B23: RBLDBAU | C23: Building energy without retrofits | D23: PJ | E23: RESNGABLD | G23: 2010 | I23: =SUM(R26,R27,R28)/SUM(Q23,Q24,Q25) -> 1 | J23: =Q23/SUM(Q23,Q24,Q25) -> 0.33333333 | M23: 1 | N23: 1 | O23: 0 | Q23: 1
E24: RESDSLBLD | J24: =Q24/SUM(Q23,Q24,Q25) -> 0.33333333 | Q24: 1
A25: * | E25: RESRFLBLD | J25: =Q25/SUM(Q23,Q24,Q25) -> 0.33333333 | Q25: 1
F26: RESNGARM | K26: =R26/SUM(R26,R27,R28) -> 0.33333333 | R26: 1
F27: RESDSLRM | K27: =R27/SUM(R26,R27,R28) -> 0.33333333 | R27: 1
A28: * | F28: RESRFLRM | K28: =R28/SUM(R26,R27,R28) -> 0.33333333 | R28: 1
A29: R2,R3,R4,R5,R6 | B29: RELCR10 | C29: Building ELC retrofit for 10% energy reduction | D29: PJ | E29: RESELCBLD | F29: RESELCRB | G29: 2015 | I29: =T29/S29 -> 1 | L29: 1 | M29: 1 | N29: 1 | O29: 0.25 | S29: 1 | T29: 1
A30: R2,R3,R4,R5,R6 | B30: RBLDR10 | C30: Building retrofit for 10% energy reduction | D30: PJ | E30: RESNGABLD | G30: 2015 | I30: =SUM(R33,R34,R35)/SUM(Q30,Q31,Q32) -> 1.1 | J30: =Q30/SUM(Q30,Q31,Q32) -> 0.33333333 | M30: 1 | N30: 1 | O30: 0.25 | Q30: 1
E31: RESDSLBLD | J31: =Q31/SUM(Q30,Q31,Q32) -> 0.33333333 | Q31: 1
A32: * | E32: RESRFLBLD | J32: =Q32/SUM(Q30,Q31,Q32) -> 0.33333333 | Q32: 1
F33: RESNGARB | K33: =R33/SUM(R33,R34,R35) -> 0.33333333 | R33: 1.1
F34: RESDSLRB | K34: =R34/SUM(R33,R34,R35) -> 0.33333333 | R34: 1.1
A35: * | F35: RESRFLRB | K35: =R35/SUM(R33,R34,R35) -> 0.33333333 | R35: 1.1
A36: R2,R3,R4,R5,R6 | B36: RELCR25 | C36: Building ELC retrofit for 25% energy reduction | D36: PJ | E36: RESELCBLD | F36: RESELCRM | G36: 2020 | I36: =T36/S36 -> 1 | L36: 1 | M36: 1 | N36: 1 | O36: 0.5 | S36: 1 | T36: 1
A37: R2,R3,R4,R5,R6 | B37: RBLDR25 | C37: Building retrofit for 25% energy reduction | D37: PJ | E37: RESNGABLD | G37: 2020 | I37: =SUM(R40,R41,R42)/SUM(Q37,Q38,Q39) -> 1.25 | J37: =Q37/SUM(Q37,Q38,Q39) -> 0.33333333 | M37: 1 | N37: 1 | O37: 0.5 | Q37: 1
E38: RESDSLBLD | J38: =Q38/SUM(Q37,Q38,Q39) -> 0.33333333 | Q38: 1
A39: * | E39: RESRFLBLD | J39: =Q39/SUM(Q37,Q38,Q39) -> 0.33333333 | Q39: 1
F40: RESNGARM | K40: =R40/SUM(R40,R41,R42) -> 0.33333333 | R40: 1.25
F41: RESDSLRM | K41: =R41/SUM(R40,R41,R42) -> 0.33333333 | R41: 1.25
A42: * | F42: RESRFLRM | K42: =R42/SUM(R40,R41,R42) -> 0.33333333 | R42: 1.25
...

Sheet Retrofit
B2: Measure No. | C2: Name | D2: Energy Demand Reduction (% kBtu/sqft) | E2: Cost per Sqft | F2: % of Residential Area Eligible | G2: Cost Calculation | H2: Restriction Calculation
B3: 1 | C3: Insulation – walls | D3: 0.1 | E3: 65.19 | F3: 0.267 | G3: $41.75 per square foot wall area; wall area calculated as average perimeter area times height in eligible single-family homes | H3: Only single-family homes built before 2005
B4: 2 | C4: Ventilation overhaul | D4: 0.03 | E4: 1 | F4: 0.482 | G4: $1 per sqft | H4: Only homes built after 1945
B5: 3 | C5: Smart thermostats | D5: 0.08 | E5: 0.52 | F5: 0.948 | G5: $500 / apartment (average size 962 sqft) | H5: All homes except steam-heated
B6: 4 | C6: Insulation – roof | D6: 0.05 | E6: 1.5 | F6: 0.897 | G6: $13 / roof area (90% of footprint); foot print is 0.129 of total area | H6: Only homes built before 2005
B7: 5 | C7: Window replacement | D7: 0.08 | E7: 5 | F7: 0.897 | G7: Cost given | H7: Only homes built before 2005
C10: 2005 Building eff (Btu / sqft )
C11: Brooklyn | D11: Bronx | E11: Manhattan | F11: Queens | G11: Staten Island | H11: NYC | K11: 2005 | L11: 2010 | M11: 2015 | N11: 2020 | O11: 2025 | P11: 2030 | Q11: 2035 | R11: 2040 | S11: 2045 | T11: 2050 | U11: 2055
C12: 51602.374 | D12: 55661.045 | E12: 62470.873 | F12: 32617.14 | G12: 56174.924 | H12: 50587.643 | J12: % of new build | K12: 0 | L12: 0.028275072 | M12: 0.055803665 | N12: 0.080498063 | O12: 0.09788161 | P12: 0.11446455 | Q12: 0.13106521 | R12: 0.14813324 | S12: 0.16193016 | T12: 0.1770404 | U12: 0.1916742
C14: Cost per Btu (M $ 2010 / PJa)
C15: Brooklyn | D15: Bronx | E15: Manhattan | F15: Queens | G15: Staten Island | H15: NYC | J15: Max penetration (% Btu) | K15: 2005 | L15: 2010 | M15: 2015 | N15: 2020 | O15: 2025 | P15: 2030 | Q15: 2035 | R15: 2040 | S15: 2045 | T15: 2050 | U15: 2055
B16: Smart thermostats | C16: =$E5/C$12/$U$28/$C$31*10^-6 -> 7.0017166 | D16: =$E5/D$12/$U$28/$C$31*10^-6 -> 6.4911681 | E16: =$E5/E$12/$U$28/$C$31*10^-6 -> 5.7835785 | F16: =$E5/F$12/$U$28/$C$31*10^-6 -> 11.077158 | G16: =$E5/G$12/$U$28/$C$31*10^-6 -> 6.431788 | H16: =$E5/H$12/$U$28/$C$31*10^-6 -> 7.1421631 | J16: Smart thermostats | K16: =$D$5*$F$5*(1-K$12) -> 0.07584 | L16: =$D$5*$F$5*(1-L$12) -> 0.073695619 | M16: =$D$5*$F$5*(1-M$12) -> 0.07160785 | N16: =$D$5*$F$5*(1-N$12) -> 0.069735027 | O16: =$D$5*$F$5*(1-O$12) -> 0.068416659 | P16: =$D$5*$F$5*(1-P$12) -> 0.067159008 | Q16: =$D$5*$F$5*(1-Q$12) -> 0.065900015 | R16: =$D$5*$F$5*(1-R$12) -> 0.064605575 | ... U16: =$D$5*$F$5*(1-U$12) -> 0.061303428
B17: Ventilation overhaul | C17: =$E4/C$12/$U$28/$C$31*10^-6 -> 13.46484 | D17: =$E4/D$12/$U$28/$C$31*10^-6 -> 12.483016 | E17: =$E4/E$12/$U$28/$C$31*10^-6 -> 11.122266 | F17: =$E4/F$12/$U$28/$C$31*10^-6 -> 21.302226 | G17: =$E4/G$12/$U$28/$C$31*10^-6 -> 12.368823 | H17: =$E4/H$12/$U$28/$C$31*10^-6 -> 13.734929 | J17: Ventilation overhaul | K17: =$D$4*$F$4*(1-K$12) -> 0.01446 | L17: =$D$4*$F$4*(1-L$12) -> 0.014051142 | M17: =$D$4*$F$4*(1-M$12) -> 0.013653079 | N17: =$D$4*$F$4*(1-N$12) -> 0.013295998 | O17: =$D$4*$F$4*(1-O$12) -> 0.013044632 | P17: =$D$4*$F$4*(1-P$12) -> 0.012804843 | Q17: =$D$4*$F$4*(1-Q$12) -> 0.012564797 | R17: =$D$4*$F$4*(1-R$12) -> 0.012317993 | ... U17: =$D$4*$F$4*(1-U$12) -> 0.011688391
B18: Insulation – roof | C18: =$E6/C$12/$U$28/$C$31*10^-6 -> 20.197259 | D18: =$E6/D$12/$U$28/$C$31*10^-6 -> 18.724523 | E18: =$E6/E$12/$U$28/$C$31*10^-6 -> 16.6834 | F18: =$E6/F$12/$U$28/$C$31*10^-6 -> 31.953339 | G18: =$E6/G$12/$U$28/$C$31*10^-6 -> 18.553234 | H18: =$E6/H$12/$U$28/$C$31*10^-6 -> 20.602393 | J18: Insulation – roof | K18: =$D$3*$F$3*(1-K$12) -> 0.0267 | L18: =$D$3*$F$3*(1-L$12) -> 0.025945056 | M18: =$D$3*$F$3*(1-M$12) -> 0.025210042 | N18: =$D$3*$F$3*(1-N$12) -> 0.024550702 | O18: =$D$3*$F$3*(1-O$12) -> 0.024086561 | P18: =$D$3*$F$3*(1-P$12) -> 0.023643796 | Q18: =$D$3*$F$3*(1-Q$12) -> 0.023200559 | R18: =$D$3*$F$3*(1-R$12) -> 0.022744842 | ... U18: =$D$3*$F$3*(1-U$12) -> 0.021582299
B19: Window replacement | C19: =$E7/C$12/$U$28/$C$31*10^-6 -> 67.324198 | D19: =$E7/D$12/$U$28/$C$31*10^-6 -> 62.415078 | E19: =$E7/E$12/$U$28/$C$31*10^-6 -> 55.611332 | F19: =$E7/F$12/$U$28/$C$31*10^-6 -> 106.51113 | G19: =$E7/G$12/$U$28/$C$31*10^-6 -> 61.844115 | H19: =$E7/H$12/$U$28/$C$31*10^-6 -> 68.674645 | J19: Window replacement | K19: =$D$7*$F$7*(1-K$12) -> 0.07176 | L19: =$D$7*$F$7*(1-L$12) -> 0.069730981 | M19: =$D$7*$F$7*(1-M$12) -> 0.067755529 | N19: =$D$7*$F$7*(1-N$12) -> 0.065983459 | O19: =$D$7*$F$7*(1-O$12) -> 0.064736016 | P19: =$D$7*$F$7*(1-P$12) -> 0.063546024 | Q19: =$D$7*$F$7*(1-Q$12) -> 0.062354761 | R19: =$D$7*$F$7*(1-R$12) -> 0.061129958 | ... U19: =$D$7*$F$7*(1-U$12) -> 0.058005459
B20: Insulation – walls | C20: =$E3/C$12/$U$28/$C$31*10^-6 -> 877.77289 | D20: =$E3/D$12/$U$28/$C$31*10^-6 -> 813.76779 | E20: =$E3/E$12/$U$28/$C$31*10^-6 -> 725.06054 | F20: =$E3/F$12/$U$28/$C$31*10^-6 -> 1388.6921 | G20: =$E3/G$12/$U$28/$C$31*10^-6 -> 806.32357 | H20: =$E3/H$12/$U$28/$C$31*10^-6 -> 895.38002 | J20: Insulation – walls | K20: =$D$6*$F$6*(1-K$12) -> 0.04485 | L20: =$D$6*$F$6*(1-L$12) -> 0.043581863 | M20: =$D$6*$F$6*(1-M$12) -> 0.042347206 | N20: =$D$6*$F$6*(1-N$12) -> 0.041239662 | O20: =$D$6*$F$6*(1-O$12) -> 0.04046001 | P20: =$D$6*$F$6*(1-P$12) -> 0.039716265 | Q20: =$D$6*$F$6*(1-Q$12) -> 0.038971725 | R20: =$D$6*$F$6*(1-R$12) -> 0.038206224 | ... U20: =$D$6*$F$6*(1-U$12) -> 0.036253412
B25: https://fred.stlouisfed.org/series/FPCPITOTLZGUSA
C26: 2005 | D26: 2006 | E26: 2007 | F26: 2008 | G26: 2009 | H26: 2010 | I26: 2011 | J26: 2012 | K26: 2013 | L26: 2014 | M26: 2015 | N26: 2016 | O26: 2017 | P26: 2018 | Q26: 2019 | R26: 2020 | S26: 2021 | T26: 2022 | U26: 2023
B27: Inflation | C27: 0.033927468 | D27: 0.032259441 | E27: 0.028526725 | F27: 0.038391003 | G27: -0.0035554627 | H27: 0.016400434 | I27: 0.031568416 | J27: 0.020693373 | K27: 0.014648327 | L27: 0.01622223 | M27: 0.0011862714 | N27: 0.012615832 | O27: 0.0213011 | P27: 0.024425833 | Q27: 0.018122101 | R27: 0.012335844 | S27: 0.046978589 | T27: 0.080027998 | U27: 0
B28: Cumulated ref 2010 | C28: 1.1358175 | D28: 1.0985466 | E28: 1.0642156 | F28: 1.034699 | G28: 0.99644454 | H28: 1 | I28: 1.0164004 | J28: 1.0484866 | K28: 1.0701833 | L28: 1.0858597 | M28: 1.1034748 | N28: 1.1047838 | O28: 1.1187216 | P28: 1.1425516 | Q28: 1.1704593 | R28: 1.1916705 | S28: 1.2063708 | T28: 1.2630444 | U28: 1.3641233
B31: Btu to PJ | C31: 1.055056e-12

Sheet EIA23 EQ Cost
A1: See 2023_COMET_Residential_Cost_Data for details
G3: START | H3: LIFE | I3: CAPITAL COST update wrt EIA | J3: INVCOST | K3: EFF | L3: Capacity | M3: CF
I4: 2005$/unit | L4: btu/hr
B5: TechName | C5: TechDesc | D5: Units | E5: CommIN | F5: CommOUT | G5: TID | H5: TID
A6: *Space Heating
A7: *Electric Radiant Heating | B7: =A7 -> *Electric Radiant Heating
A8: R2,R3,R4,R5,R6 | B8: RSHERDBS10 | C8: Electric Radiant Base.RSH.ELC.10 | D8: PJ | E8: RESELC | F8: RSH | G8: 2011 | H8: 22.5 | I8: 162.45802 | J8: 3.74 | K8: 1
A9: R2,R3,R4,R5,R6 | B9: RSHERUV115 | C9: Electric Resistance Unit Heater Ver1.RSH.ELC.15 | D9: PJ | E9: RESELC | F9: RSH | G9: 2015 | H9: 22.5 | I9: 162.45802 | J9: 3.4718966 | K9: 1 | L9: 3500
A10: R2,R3,R4,R5,R6 | B10: RSHERUV120 | C10: Electric Resistance Unit Heater Ver1.RSH.ELC.20 | D10: PJ | E10: RESELC | F10: RSH | G10: 2020 | H10: 22.5 | I10: 162.45802 | J10: 3.4718966 | K10: 1 | L10: 3500
A11: R2,R3,R4,R5,R6 | B11: RSHERUV122 | C11: Electric Resistance Unit Heater Ver1.RSH.ELC.22 | D11: PJ | E11: RESELC | F11: RSH | G11: 2022 | H11: 22.5 | I11: 546.13547 | J11: 8.0098408 | K11: 1 | L11: 5100
A12: *Electric Furnaces | B12: =A12 -> *Electric Furnaces
A13: R2,R3,R4,R5,R6 | B13: RSHEFRV115 | C13: Electric Furnace Ver1.RSH.ELC.15 | D13: Electric Furnace Ver1.RSH.ELC.15 | E13: RESELC | F13: RSH | G13: 2015 | H13: 22.5 | I13: 891.79083 | J13: 0.98095202 | K13: 0.98 | L13: 68000 | M13: 0.16
A14: R2,R3,R4,R5,R6 | B14: RSHEFRV120 | C14: Electric Furnace Ver1.RSH.ELC.20 | D14: Electric Furnace Ver1.RSH.ELC.20 | E14: RESELC | F14: RSH | G14: 2020 | H14: 22.5 | I14: 891.79083 | J14: 0.98095202 | K14: 0.98 | L14: 68000 | M14: 0.16
A15: R2,R3,R4,R5,R6 | B15: RSHEFRV122 | C15: Electric Furnace Ver1.RSH.ELC.22 | D15: Electric Furnace Ver1.RSH.ELC.22 | E15: RESELC | F15: RSH | G15: 2022 | H15: 22.5 | I15: 1023.1399 | J15: 1.1254333 | K15: 1 | L15: 68000 | M15: 0.16
A16: *Electric Heat Pumps (Residential Air Source Heat Pumps) | B16: =A16 -> *Electric Heat Pumps (Residential Air Source Heat Pumps)
A17: R2,R3,R4,R5,R6 | B17: RSHEHPBS15 | C17: Electric Heat Pump Base.RSH.ELC.15 | D17: PJ | E17: RESELC | F17: RSH | G17: 2015 | H17: 15.5 | I17: 4002.6891 | J17: 8.3165467 | K17: 6.7 | L17: 36000 | M17: 0.15
A18: R2,R3,R4,R5,R6 | B18: RSHEHPB120 | C18: Electric Heat Pump Base.RSH.ELC.20 | D18: PJ | E18: RESELC | F18: RSH | G18: 2020 | H18: 15.5 | I18: 4756.2178 | J18: 9.8821833 | K18: 7.3 | L18: 36000 | M18: 0.15
A19: R2,R3,R4,R5,R6 | B19: RSHEHPBS22 | C19: Electric Heat Pump Base.RSH.ELC.22 | D19: PJ | E19: RESELC | F19: RSH | G19: 2022 | H19: 15.5 | I19: 4756.2178 | J19: 9.8821833 | K19: 7.3 | L19: 36000 | M19: 0.15
A20: R2,R3,R4,R5,R6 | B20: RSHEHPV122 | C20: Electric Heat Pump Ver1.RSH.ELC.22 | D20: PJ | E20: RESELC | F20: RSH | G20: 2022 | H20: 15.5 | I20: 5959.0984 | J20: 12.381456 | K20: 10.6 | L20: 36000 | M20: 0.15
A21: R2,R3,R4,R5,R6 | B21: RSHEHPV123 | C21: Electric Heat Pump Ver1.RSH.ELC.23 | D21: PJ | E21: RESELC | F21: RSH | G21: 2023 | H21: 15.5 | I21: 4707.826 | J21: 9.7816379 | K21: 7.5 | L21: 36000 | M21: 0.15
A22: R2,R3,R4,R5,R6 | B22: RSHEHPV223 | C22: Electric Heat Pump Ver2.RSH.ELC.23 | D22: PJ | E22: RESELC | F22: RSH | G22: 2023 | H22: 15.5 | I22: 4797.6964 | J22: 9.9683652 | K22: 8.1 | L22: 36000
A23: R2,R3,R4,R5,R6 | B23: RSHEHPV323 | C23: Electric Heat Pump Ver3.RSH.ELC.23 | D23: PJ | E23: RESELC | F23: RSH | G23: 2023 | H23: 15.5 | I23: 5959.0984 | J23: 12.381456 | K23: 10.6 | L23: 36000 | M23: 0.15
A24: R2,R3,R4,R5,R6 | B24: RSHEHPV130 | C24: Electric Heat Pump Ver1.RSH.ELC.30 | D24: PJ | E24: RESELC | F24: RSH | G24: 2030 | H24: 15.5 | I24: 4797.6964 | J24: 9.9683652 | K24: 7.8 | L24: 36000
A25: R2,R3,R4,R5,R6 | B25: RSHEHPV230 | C25: Electric Heat Pump Ver2.RSH.ELC.30 | D25: PJ | E25: RESELC | F25: RSH | G25: 2030 | H25: 15.5 | I25: 5959.0984 | J25: 12.381456 | K25: 10.6 | L25: 36000 | M25: 0.15
A26: R2,R3,R4,R5,R6 | B26: RSHEHPV140 | C26: Electric Heat Pump Ver1.RSH.ELC.40 | D26: PJ | E26: RESELC | F26: RSH | G26: 2040 | H26: 15.5 | I26: 5005.0896 | J26: 10.399274 | K26: 7.9 | L26: 36000 | M26: 0.15
A27: R2,R3,R4,R5,R6 | B27: RSHEHPV240 | C27: Electric Heat Pump Ver2.RSH.ELC.40 | D27: PJ | E27: RESELC | F27: RSH | G27: 2040 | H27: 15.5 | I27: 5959.0984 | J27: 12.381456 | K27: 10.6 | L27: 36000 | M27: 0.15
A28: R2,R3,R4,R5,R6 | B28: RSHEHPV150 | C28: Electric Heat Pump Ver1.RSH.ELC.50 | D28: PJ | E28: RESELC | F28: RSH | G28: 2050 | H28: 15.5 | I28: 5067.3076 | J28: 10.528547 | K28: 7.9 | L28: 36000 | M28: 0.15
A29: R2,R3,R4,R5,R6 | B29: RSHEHPV250 | C29: Electric Heat Pump Ver2.RSH.ELC.50 | D29: PJ | E29: RESELC | F29: RSH | G29: 2050 | H29: 15.5 | I29: 5959.0984 | J29: 12.381456 | K29: 10.6 | L29: 36000
A30: *Natural Gas Furnaces (Residential Gas-Fired Furnaces - North) | B30: =A30 -> *Natural Gas Furnaces (Residential Gas-Fired Furnaces - North)
A31: R2,R3,R4,R5,R6 | B31: RSHNFRBS15 | C31: Natural Gas Furnace Base.RSH.NGA.15 | D31: PJ | E31: RESNGAEA | F31: RSH | G31: 2015 | H31: 21.5 | I31: 1990.9749 | J31: 1.8615276 | K31: 0.8 | L31: 80000
A32: R2,R3,R4,R5,R6 | B32: RSHNFRBS20 | C32: Natural Gas Furnace Base.RSH.NGA.20 | D32: PJ | E32: RESNGAEA | F32: RSH | G32: 2020 | H32: 21.5 | I32: 1990.9749 | J32: 1.8615276 | K32: 0.8 | L32: 80000
A33: R2,R3,R4,R5,R6 | B33: RSHNFRV122 | C33: Natural Gas Furnace Ver1.RSH.NGA.22 | D33: PJ | E33: RESNGAEA | F33: RSH | G33: 2022 | H33: 21.5 | I33: 2550.9366 | J33: 2.3850822 | K33: 0.8 | L33: 80000
A34: R2,R3,R4,R5,R6 | B34: RSHNFRV222 | C34: Natural Gas Furnace Ver2.RSH.NGA.22 | D34: PJ | E34: RESNGAEA | F34: RSH | G34: 2022 | H34: 21.5 | I34: 2855.1133 | J34: 2.6694822 | K34: 0.9 | L34: 80000
A35: R2,R3,R4,R5,R6 | B35: RSHNFRV322 | C35: Natural Gas Furnace Ver3.RSH.NGA.22 | D35: PJ | E35: RESNGAEA | F35: RSH | G35: 2022 | H35: 21.5 | I35: 2868.9395 | J35: 2.6824095 | K35: 0.95 | L35: 80000
A36: R2,R3,R4,R5,R6 | B36: RSHNFRV422 | C36: Natural Gas Furnace Ver4.RSH.NGA.22 | D36: PJ | E36: RESNGAEA | F36: RSH | G36: 2022 | H36: 21.5 | I36: 2986.4623 | J36: 2.7922913 | K36: 0.99 | L36: 80000
A37: *Natural Gas Radiant Heating (Residential Gas-Fired Boiler Radiants) | B37: =A37 -> *Natural Gas Radiant Heating (Residential Gas-Fired Boiler Radiants)
A38: R2,R3,R4,R5,R6 | B38: RSHNBRBS15 | C38: Natural Gas Boiler Radiant Base.RSH.NGA.15 | D38: PJ | E38: RESNGAEA | F38: RSH | G38: 2015 | H38: 25 | I38: 5364.5712 | J38: 4.0126261 | K38: 0.82 | L38: 100000
A39: R2,R3,R4,R5,R6 | B39: RSHNBRBS20 | C39: Natural Gas Boiler Radiant Base.RSH.NGA.20 | D39: PJ | E39: RESNGAEA | F39: RSH | G39: 2020 | H39: 25 | I39: 4106.3857 | J39: 3.0715205 | K39: 0.95 | L39: 100000
A40: R2,R3,R4,R5,R6 | B40: RSHNBRV122 | C40: Natural Gas Boiler Radiant Ver 1.RSH.NGA.22 | D40: PJ | E40: RESNGAEA | F40: RSH | G40: 2022 | H40: 25 | I40: 6014.4033 | J40: 4.4986916 | K40: 0.84 | L40: 100000
A41: R2,R3,R4,R5,R6 | B41: RSHNBRV222 | C41: Natural Gas Boiler Radiant Ver 2.RSH.NGA.22 | D41: PJ | E41: RESNGAEA | F41: RSH | G41: 2022 | H41: 25 | I41: 4106.3857 | J41: 3.0715205 | K41: 0.95 | L41: 100000
...

Sheet Resid
B1: TechName | C1: TechDesc | D1: Units | E1: CommIN | F1: CommOUT | G1: START | H1: LIFE | I1: INVCOST | J1: EFF | K1: MA(ENT) | L1: OUT(DM) | M1: CF | N1: FIXOM | O1: DISCRATE | P1: RESID EPAUS9r 2010 | Q1: RESID EPAUS9r (%) | R1: EFF | T1: Resid Total | U1: Demand Total | V1: RESID | AA1: DEMAND
A2: *Space Heating | V2: BR | W2: BX | X2: MN | Y2: SI | Z2: QN | AA2: BR | AB2: BX | AC2: MN | AD2: SI | AE2: QN
U3: =SUM(U5:U52) -> #REF! | AA3: =ResDemand!E19 -> #REF! | AB3: =ResDemand!E20 -> #REF! | AC3: =ResDemand!E21 -> #REF! | AD3: =ResDemand!E22 -> #REF! | AE3: =ResDemand!E23 -> #REF! | AF3: =SUM(AA3:AE3)-U3 -> #REF!
A4: ELC | M4: =M6 -> 0.16 | P4: =SUM(P5:P21) -> #REF! | Q4: =A4 -> ELC | T4: ='2010 Fuel Share'!C72 -> #REF! | AA4: =SUM(AA6:AA52) -> #REF! | AB4: =SUM(AB6:AB52) -> #REF! | AC4: =SUM(AC6:AC52) -> #REF! | AD4: =SUM(AD6:AD52) -> #REF! | AE4: =SUM(AE6:AE52) -> #REF!
A5: *Electric Radiant
A6: R1,R2,R3,R4,R5,R6 | B6: RSHERDBS05 | C6: Electric Radiant Base.RSH.ELC.05 | D6: PJ | E6: RESELC | F6: RSH | G6: 2005 | H6: 20 | J6: 1 | K6: 1 | L6: 1 | M6: 0.16 | O6: 0.18 | R6: =J6 -> 1
A7: R1,R2,R3,R4,R5,R6 | B7: RSHERDBS10 | C7: Electric Radiant Base.RSH.ELC.10 | D7: PJ | E7: RESELC | F7: RSH | G7: 2010 | H7: 20 | I7: 3.7369871 | J7: 1 | K7: 1 | L7: 1 | M7: 0.16 | O7: 0.18 | P7: =#REF! -> #REF! | Q7: =P7/$P$4 -> #REF! | R7: =J7 -> 1 | T7: =T4*$Q$7*$R$7/$M$7 -> #REF! | U7: =T7*$M$7 -> #REF! | V7: =$T7*AA$3/$U$3 -> #REF! | W7: =$T7*AB$3/$U$3 -> #REF! | X7: =$T7*AC$3/$U$3 -> #REF! | Y7: =$T7*AD$3/$U$3 -> #REF! | Z7: =$T7*AE$3/$U$3 -> #REF! | AA7: =$U7*AA3/$U$3 -> #REF! | AB7: =$U7*AB3/$U$3 -> #REF! | AC7: =$U7*AC3/$U$3 -> #REF! | AD7: =$U7*AD3/$U$3 -> #REF! | AE7: =$U7*AE3/$U$3 -> #REF!
A8: *Electric Heat Pump
A9: R1,R2,R3,R4,R5,R6 | B9: RSHEHPBS05 | C9: Electric Heat Pump Base.RSH.ELC.05 | D9: PJ | E9: RESELC | F9: RSH | G9: 2005 | H9: 15 | J9: 2.2657 | K9: 1 | L9: 1 | M9: 0.16 | O9: 0.18 | R9: =J9 -> 2.2657
A10: R1,R2,R3,R4,R5,R6 | B10: RSHEHPV110 | C10: Electric Heat Pump Ver1.RSH.ELC.10 | D10: PJ | E10: RESELC | F10: RSH | G10: 2010 | H10: 15 | I10: 6.5561178 | J10: 2.26 | K10: 1 | L10: 1 | M10: 0.16 | O10: 0.18 | P10: =#REF! -> #REF! | Q10: =P10/$P$4 -> #REF! | R10: =J10 -> 2.26 | T10: =T4*$Q$10*$R$10/$M$10 -> #REF! | U10: =T10*$M$10 -> #REF! | V10: =$T10*AA$3/$U$3 -> #REF! | W10: =$T10*AB$3/$U$3 -> #REF! | X10: =$T10*AC$3/$U$3 -> #REF! | Y10: =$T10*AD$3/$U$3 -> #REF! | Z10: =$T10*AE$3/$U$3 -> #REF! | AA10: =$U10*AA$3/$U$3 -> #REF! | AB10: =$U10*AB3/$U$3 -> #REF! | AC10: =$U10*AC3/$U$3 -> #REF! | AD10: =$U10*AD3/$U$3 -> #REF! | AE10: =$U10*AE3/$U$3 -> #REF!
A11: R1,R2,R3,R4,R5,R6 | B11: RSHEHPV115 | C11: Electric Heat Pump Ver1.RSH.ELC.15 | D11: PJ | E11: RESELC | F11: RSH | G11: 2015 | H11: 15 | I11: 6.7609965 | J11: 2.4 | K11: 1 | L11: 1 | M11: 0.16 | O11: 0.18 | R11: =J11 -> 2.4
A12: R1,R2,R3,R4,R5,R6 | B12: RSHEHPV210 | C12: Electric Heat Pump Ver2.RSH.ELC.10 | D12: PJ | E12: RESELC | F12: RSH | G12: 2010 | H12: 15 | I12: 8.8097833 | J12: 2.4 | K12: 1 | L12: 1 | M12: 0.16 | O12: 0.18 | R12: =J12 -> 2.4
A13: R1,R2,R3,R4,R5,R6 | B13: RSHEHPV215 | C13: Electric Heat Pump Ver2.RSH.ELC.15 | D13: PJ | E13: RESELC | F13: RSH | G13: 2015 | H13: 15 | I13: 9.3561264 | J13: 2.58 | K13: 1 | L13: 1 | M13: 0.16 | O13: 0.18 | R13: =J13 -> 2.58
A14: R1,R2,R3,R4,R5,R6 | B14: RSHEHPV310 | C14: Electric Heat Pump Ver3.RSH.ELC.10 | D14: PJ | E14: RESELC | F14: RSH | G14: 2010 | H14: 15 | I14: 9.7658838 | J14: 2.49 | K14: 1 | L14: 1 | M14: 0.16 | O14: 0.18 | R14: =J14 -> 2.49
A15: R1,R2,R3,R4,R5,R6 | B15: RSHEHPV315 | C15: Electric Heat Pump Ver3.RSH.ELC.15 | D15: PJ | E15: RESELC | F15: RSH | G15: 2015 | H15: 15 | I15: 9.7658838 | J15: 2.49 | K15: 1 | L15: 1 | M15: 0.16 | O15: 0.18 | R15: =J15 -> 2.49
A16: R1,R2,R3,R4,R5,R6 | B16: RSHEHPV320 | C16: Electric Heat Pump Ver3.RSH.ELC.20 | D16: PJ | E16: RESELC | F16: RSH | G16: 2020 | H16: 15 | I16: 10.243934 | J16: 2.78 | K16: 1 | L16: 1 | M16: 0.16 | O16: 0.18 | R16: =J16 -> 2.78
A17: R1,R2,R3,R4,R5,R6 | B17: RSHEHPV330 | C17: Electric Heat Pump Ver3.RSH.ELC.30 | D17: PJ | E17: RESELC | F17: RSH | G17: 2030 | H17: 15 | I17: 10.243934 | J17: 2.8 | K17: 1 | L17: 1 | M17: 0.16 | O17: 0.18 | R17: =J17 -> 2.8
A18: R1,R2,R3,R4,R5,R6 | B18: RSHEHPV410 | C18: Electric Heat Pump Ver4.RSH.ELC.10 | D18: PJ | E18: RESELC | F18: RSH | G18: 2010 | H18: 15 | I18: 10.926863 | J18: 3.14 | K18: 1 | L18: 1 | M18: 0.16 | O18: 0.18 | R18: =J18 -> 3.14
A19: R1,R2,R3,R4,R5,R6 | B19: RSHEHPV420 | C19: Electric Heat Pump Ver4.RSH.ELC.20 | D19: PJ | E19: RESELC | F19: RSH | G19: 2020 | H19: 15 | I19: 11.200035 | J19: 3.17 | K19: 1 | L19: 1 | M19: 0.16 | O19: 0.18 | R19: =J19 -> 3.17
A20: R1,R2,R3,R4,R5,R6 | B20: RSHEHPV430 | C20: Electric Heat Pump Ver4.RSH.ELC.30 | D20: PJ | E20: RESELC | F20: RSH | G20: 2030 | H20: 15 | I20: 11.268327 | J20: 3.22 | K20: 1 | L20: 1 | M20: 0.16 | O20: 0.18 | R20: =J20 -> 3.22
A21: R1,R2,R3,R4,R5,R6 | B21: RSHEHPV435 | C21: Electric Heat Pump Ver4.RSH.ELC.35 | D21: PJ | E21: RESELC | F21: RSH | G21: 2035 | H21: 15 | I21: 11.268327 | J21: 3.22 | K21: 1 | L21: 1 | M21: 0.16 | O21: 0.18 | R21: =J21 -> 3.22
A22: NGA | M22: =M24 -> 0.16 | P22: =SUM(P23:P35) -> #REF! | Q22: NGA | T22: ='2010 Fuel Share'!C73 -> #REF! | AF22: =(U25+U32+U39+U45)/U3 -> #REF!
A23: *Natural Gas Furnace
A24: R1,R2,R3,R4,R5,R6 | B24: RSHNFRBS05 | C24: Natural Gas Furnace Base.RSH.NGA.05 | D24: PJ | E24: RESNGAEA | F24: RSH | G24: 2005 | H24: 15 | J24: 0.81440002 | K24: 1 | L24: 1 | M24: 0.16 | O24: 0.18 | R24: =J24 -> 0.81440002
A25: R1,R2,R3,R4,R5,R6 | B25: RSHNFRV110 | C25: Natural Gas Furnace Ver1.RSH.NGA.10 | D25: PJ | E25: RESNGAEA | F25: RSH | G25: 2010 | H25: 15 | I25: 4.9170883 | J25: 0.78 | K25: 1 | L25: 1 | M25: 0.16 | O25: 0.18 | P25: =#REF! -> #REF! | Q25: =P25/$P$22 -> #REF! | R25: =J25 -> 0.78 | T25: =T22*$Q$25*$R$25/$M$25 -> #REF! | U25: =T22*$Q$25*$R$25 -> #REF! | V25: =$T25*AA$3/$U$3 -> #REF! | W25: =$T25*AB$3/$U$3 -> #REF! | X25: =$T25*AC$3/$U$3 -> #REF! | Y25: =$T25*AD$3/$U$3 -> #REF! | Z25: =$T25*AE$3/$U$3 -> #REF! | AA25: =$U25*AA$3/$U$3 -> #REF! | AB25: =$U25*AB$3/$U$3 -> #REF! | AC25: =$U25*AC$3/$U$3 -> #REF! | AD25: =$U25*AD$3/$U$3 -> #REF! | AE25: =$U25*AE$3/$U$3 -> #REF!
A26: R1,R2,R3,R4,R5,R6 | B26: RSHNFRV210 | C26: Natural Gas Furnace Ver2.RSH.NGA.10 | D26: PJ | E26: RESNGAEA | F26: RSH | G26: 2010 | H26: 15 | I26: 4.9170883 | J26: 0.8 | K26: 1 | L26: 1 | M26: 0.16 | O26: 0.18 | R26: =J26 -> 0.8
A27: R1,R2,R3,R4,R5,R6 | B27: RSHNFRV310 | C27: Natural Gas Furnace Ver3.RSH.NGA.10 | D27: PJ | E27: RESNGAEA | F27: RSH | G27: 2010 | H27: 20 | I27: 5.4087972 | J27: 0.9 | K27: 1 | L27: 1 | M27: 0.16 | O27: 0.18 | R27: =J27 -> 0.9
A28: R1,R2,R3,R4,R5,R6 | B28: RSHNFRV410 | C28: Natural Gas Furnace Ver4.RSH.NGA.10 | D28: PJ | E28: RESNGAEA | F28: RSH | G28: 2010 | H28: 20 | I28: 6.2938731 | J28: 0.95 | K28: 1 | L28: 1 | M28: 0.16 | O28: 0.18 | R28: =J28 -> 0.95
A29: R1,R2,R3,R4,R5,R6 | B29: RSHNFRV510 | C29: Natural Gas Furnace Ver5.RSH.NGA.10 | D29: PJ | E29: RESNGAEA | F29: RSH | G29: 2010 | H29: 20 | I29: 7.3756325 | J29: 0.98 | K29: 1 | L29: 1 | M29: 0.16 | O29: 0.18 | R29: =J29 -> 0.98
A30: *Natural Gas Radiant
A31: R1,R2,R3,R4,R5,R6 | B31: RSHNRDBS05 | C31: Natural Gas Radiant Base.RSH.NGA.05 | D31: PJ | E31: RESNGAEA | F31: RSH | G31: 2005 | H31: 20 | J31: 0.8 | K31: 1 | L31: 1 | M31: 0.16 | O31: 0.18 | R31: =J31 -> 0.8
A32: R1,R2,R3,R4,R5,R6 | B32: RSHNRDV110 | C32: Natural Gas Radiant Ver1.RSH.NGA.10 | D32: PJ | E32: RESNGAEA | F32: RSH | G32: 2010 | H32: 20 | I32: 6.4905566 | J32: 0.8 | K32: 1 | L32: 1 | M32: 0.16 | O32: 0.18 | P32: =#REF! -> #REF! | Q32: =P32/$P$22 -> #REF! | R32: =J32 -> 0.8 | T32: =T22*$Q$32*$R$32/$M$32 -> #REF! | U32: =T22*$Q$32*$R$32 -> #REF! | V32: =$T32*AA$3/$U$3 -> #REF! | W32: =$T32*AB$3/$U$3 -> #REF! | X32: =$T32*AC$3/$U$3 -> #REF! | Y32: =$T32*AD$3/$U$3 -> #REF! | Z32: =$T32*AE$3/$U$3 -> #REF! | AA32: =$U32*AA$3/$U$3 -> #REF! | AB32: =$U32*AB$3/$U$3 -> #REF! | AC32: =$U32*AC$3/$U$3 -> #REF! | AD32: =$U32*AD$3/$U$3 -> #REF! | AE32: =$U32*AE$3/$U$3 -> #REF!
