Workbook
Name __HDV50: #REF!
Name __LDV50: #REF!
Name _1995_Implicit_GDP_Deflator: #REF!
Name _1995_Implicit_GDP_Deflator: #REF!
Name _2001_Implicit_GDP_Deflator: #REF!
Name _2001_Implicit_GDP_Deflator: #REF!
Name _HDV50: #REF!
Name _HDV50: #REF!
Name _LDV50: #REF!
Name _LDV50: #REF!
Name Age_of_car: #REF!
Name Age_of_car: #REF!
Name avg_water_heater_PJ: '[1]AEO HW'!$B$33
Name Aviation_Detail_Table: '[2]Marine and Aviation'!$I$27:$Z$31
Name Aviation_Detail_Table_Years: '[2]Marine and Aviation'!$I$27:$Z$27
Name btu_per_watthr: #REF!
Name btu_per_watthr: #REF!
Name CH4GWP_20YR: '[2]RELA TABLE'!$D$8
Name ConEd_Steam_Table: '[2]ConEd Steam'!$I$11:$Z$15
Name ConEd_Steam_Years: '[2]ConEd Steam'!$I$11:$Z$11
Name conv: #REF!
Name conv: #REF!
Name Convert_MMbtu_to_GJ: '[2]Unit conversions'!$F$25
Name days_per_year: #REF!
Name days_per_year: #REF!
Name Diesel_Car_CO: #REF!
Name Diesel_Car_CO: #REF!
Name Diesel_Car_Nox: #REF!
Name Diesel_Car_Nox: #REF!
Name Diesel_Car_PM: #REF!
Name Diesel_Car_PM: #REF!
Name Diesel_Car_VOCs: #REF!
Name Diesel_Car_VOCs: #REF!
Name Diesel_HDT_CO: #REF!
Name Diesel_HDT_CO: #REF!
Name Diesel_HDT_NOx: #REF!
Name Diesel_HDT_NOx: #REF!
Name Diesel_HDT_PM: #REF!
Name Diesel_HDT_PM: #REF!
Name Diesel_HDT_SO2: #REF!
Name Diesel_HDT_SO2: #REF!
Name Diesel_HDT_VOCs: #REF!
Name Diesel_HDT_VOCs: #REF!
Name Diesel_LDT_CO: #REF!
Name Diesel_LDT_CO: #REF!
Name Diesel_LDT_Nox: #REF!
Name Diesel_LDT_Nox: #REF!
Name Diesel_LDT_PM: #REF!
Name Diesel_LDT_PM: #REF!
Name Diesel_LDT_VOCs: #REF!
Name Diesel_LDT_VOCs: #REF!
Name Diesel_Rail_Table: [2]Transit!$I$26:$Z$29
Name Diesel_Rail_Table_Years: [2]Transit!$I$26:$Z$26
Name dollar____per__m: #REF!
Name dollar____per__m: #REF!
Name EF_table_electricity_and_steam: '[2]EF EL and Steam'!$D$5:$Z$81
Name EF_table_road_trans: '[2]EF road transport'!$J$25:$AA$2225
Name Elec_Vehicle_Assump: '[2]EF road transport'!$B$16:$C$23
Name Electric_Traction_Summary_Table: [2]Transit!$I$12:$Z$22
Name Electric_Traction_Summary_Table_Years: [2]Transit!$I$12:$Z$12

Sheet ANSv6.0-Commodities
A1: ANSWER-Commodities
B7: CommName | C7: CommDesc | D7: CommUnit | E7: Set Memberships | F7: Comment

Sheet UC_TRNHDV
B3: ~UC_Sets: R_E: AllRegions
H5: ~UC_T: UC_COMPRD
B6: UC_N | C6: Pset_PN | D6: Pset_PD | E6: Pset_CI | F6: Pset_CO | G6: Cset_CN | H6: Year | I6: LimType | J6: UC_FLO | K6: UC_RHSRTS | L6: UC_RHSRTS~0 | M6: R0 | N6: R1 | O6: R2 | P6: R3 | Q6: R4 | R6: R5 | S6: R6
B8: ="UC_"&G8&RIGHT(E8,3)&I8 -> UC_TBCNGUP | C8: TB* | E8: TBCNG | F8: TB | G8: TB | H8: 2020 | I8: UP | J8: 1 | K8: 0 | L8: 15 | O8: -0.2 | P8: =O8 -> -0.2 | Q8: =P8 -> -0.2 | R8: =Q8 -> -0.2 | S8: =R8 -> -0.2
C9: TB* | E9: TBCNG | F9: TB | G9: TB | H9: 2025 | J9: 1 | O9: -0.23571429 | P9: =O9 -> -0.23571429 | Q9: =P9 -> -0.23571429 | R9: =Q9 -> -0.23571429 | S9: =R9 -> -0.23571429
C10: TB* | E10: TBCNG | F10: TB | G10: TB | H10: 2030 | J10: 1 | O10: -0.27142857 | P10: =O10 -> -0.27142857 | Q10: =P10 -> -0.27142857 | R10: =Q10 -> -0.27142857 | S10: =R10 -> -0.27142857
C11: TB* | E11: TBCNG | F11: TB | G11: TB | H11: 2035 | J11: 1 | O11: -0.30714286 | P11: =O11 -> -0.30714286 | Q11: =P11 -> -0.30714286 | R11: =Q11 -> -0.30714286 | S11: =R11 -> -0.30714286
C12: TB* | E12: TBCNG | F12: TB | G12: TB | H12: 2040 | J12: 1 | O12: -0.34285714 | P12: =O12 -> -0.34285714 | Q12: =P12 -> -0.34285714 | R12: =Q12 -> -0.34285714 | S12: =R12 -> -0.34285714
C13: TB* | E13: TBCNG | F13: TB | G13: TB | H13: 2045 | J13: 1 | O13: -0.38452381 | P13: =O13 -> -0.38452381 | Q13: =P13 -> -0.38452381 | R13: =Q13 -> -0.38452381 | S13: =R13 -> -0.38452381
C14: TB* | E14: TBCNG | F14: TB | G14: TB | H14: 2050 | J14: 1 | O14: -0.42619048 | P14: =O14 -> -0.42619048 | Q14: =P14 -> -0.42619048 | R14: =Q14 -> -0.42619048 | S14: =R14 -> -0.42619048
C15: TB* | E15: TBCNG | F15: TB | G15: TB | H15: 2055 | J15: 1 | O15: =O14 -> -0.42619048 | P15: =P14 -> -0.42619048 | Q15: =Q14 -> -0.42619048 | R15: =R14 -> -0.42619048 | S15: =S14 -> -0.42619048
B16: ="UC_"&G16&RIGHT(E16,3)&I16 -> UC_TBDSLLO | C16: TB* | E16: TBDSL | F16: TB | G16: TB | H16: 2015 | I16: LO | J16: 1 | K16: 0 | L16: 15 | O16: =-('2010 GHG'!$I$6+'2010 GHG'!$I$10)*0.95/('2010 GHG'!$I$2+'2010 GHG'!$I$6+'2010 GHG'!$I$10) -> -0.79953404 | P16: =O16 -> -0.79953404 | Q16: =P16 -> -0.79953404 | R16: =Q16 -> -0.79953404 | S16: =R16 -> -0.79953404
C17: TB* | E17: TBDSL | F17: TB | G17: TB | H17: 2020 | J17: 1 | O17: =O16*U17 -> -0.63962723 | P17: =O17 -> -0.63962723 | Q17: =P17 -> -0.63962723 | R17: =Q17 -> -0.63962723 | S17: =R17 -> -0.63962723 | U17: 0.8
C18: TB* | E18: TBDSL | F18: TB | G18: TB | H18: 2025 | J18: 1 | O18: =O17*U18 -> -0.51170178 | P18: =O18 -> -0.51170178 | Q18: =P18 -> -0.51170178 | R18: =Q18 -> -0.51170178 | S18: =R18 -> -0.51170178 | U18: 0.8
C19: TB* | E19: TBDSL | F19: TB | G19: TB | H19: 2030 | J19: 1 | O19: =O18*U19 -> -0.38377634 | P19: =O19 -> -0.38377634 | Q19: =P19 -> -0.38377634 | R19: =Q19 -> -0.38377634 | S19: =R19 -> -0.38377634 | U19: 0.75
C20: TB* | E20: TBDSL | F20: TB | G20: TB | H20: 2035 | J20: 1 | O20: =O19*U20 -> -0.30702107 | P20: =O20 -> -0.30702107 | Q20: =P20 -> -0.30702107 | R20: =Q20 -> -0.30702107 | S20: =R20 -> -0.30702107 | U20: 0.8
C21: TB* | E21: TBDSL | F21: TB | G21: TB | H21: 2040 | J21: 1 | O21: =O20*U21 -> -0.24561686 | P21: =O21 -> -0.24561686 | Q21: =P21 -> -0.24561686 | R21: =Q21 -> -0.24561686 | S21: =R21 -> -0.24561686 | U21: 0.8
C22: TB* | E22: TBDSL | F22: TB | G22: TB | H22: 2045 | J22: 1 | O22: =O21*U22 -> -0.19649348 | P22: =O22 -> -0.19649348 | Q22: =P22 -> -0.19649348 | R22: =Q22 -> -0.19649348 | S22: =R22 -> -0.19649348 | U22: 0.8
C23: TB* | E23: TBDSL | F23: TB | G23: TB | H23: 2050 | J23: 1 | O23: =O22*U23 -> -0.15719479 | P23: =O23 -> -0.15719479 | Q23: =P23 -> -0.15719479 | R23: =Q23 -> -0.15719479 | S23: =R23 -> -0.15719479 | U23: 0.8
C24: TB* | E24: TBDSL | F24: TB | G24: TB | H24: 2055 | J24: 1 | O24: =O23*U24 -> -0.12575583 | P24: =O24 -> -0.12575583 | Q24: =P24 -> -0.12575583 | R24: =Q24 -> -0.12575583 | S24: =R24 -> -0.12575583 | U24: 0.8
B25: ="UC_"&G25&RIGHT(E25,3)&I25 -> UC_TBELCLO | C25: TB* | E25: TRNELC | F25: TB | G25: TB | H25: 2015 | I25: LO | J25: 1 | K25: 0 | L25: 15 | O25: 0 | P25: 0 | Q25: 0 | R25: 0 | S25: 0
C26: TB* | E26: TRNELC | F26: TB | G26: TB | H26: 2020 | J26: 1 | O26: 0 | P26: 0 | Q26: 0 | R26: 0 | S26: 0 | U26: 0.8
C27: TB* | E27: TRNELC | F27: TB | G27: TB | H27: 2025 | J27: 1 | O27: -0.00031 | P27: -0.00031 | Q27: -0.00031 | R27: -0.00031 | S27: -0.00031 | U27: 0.8
C28: TB* | E28: TRNELC | F28: TB | G28: TB | H28: 2030 | J28: 1 | O28: -0.00031 | P28: -0.00031 | Q28: -0.00031 | R28: -0.00031 | S28: -0.00031 | U28: 0.75
C29: TB* | E29: TRNELC | F29: TB | G29: TB | H29: 2035 | J29: 1 | O29: -0.00031 | P29: -0.00031 | Q29: -0.00031 | R29: -0.00031 | S29: -0.00031 | U29: 0.8
C30: TB* | E30: TRNELC | F30: TB | G30: TB | H30: 2040 | J30: 1 | O30: -0.00031 | P30: -0.00031 | Q30: -0.00031 | R30: -0.00031 | S30: -0.00031 | U30: 0.8
C31: TB* | E31: TRNELC | F31: TB | G31: TB | H31: 2045 | J31: 1 | O31: -0.00031 | P31: -0.00031 | Q31: -0.00031 | R31: -0.00031 | S31: -0.00031 | U31: 0.8
C32: TB* | E32: TRNELC | F32: TB | G32: TB | H32: 2050 | J32: 1 | O32: -0.00031 | P32: -0.00031 | Q32: -0.00031 | R32: -0.00031 | S32: -0.00031 | U32: 0.8
C33: TB* | E33: TRNELC | F33: TB | G33: TB | H33: 2055 | J33: 1 | O33: -0.00031 | P33: -0.00031 | Q33: -0.00031 | R33: -0.00031 | S33: -0.00031 | U33: 0.8
B34: ="UC_"&G34&"Commuter"&I34 -> UC_TRPCommuterLO | C34: TP* | D34: *Commuter* | F34: TRP | G34: TRP | H34: 2010 | I34: LO | J34: 1 | K34: 0 | L34: 15 | O34: 0 | P34: =O34 -> 0 | Q34: =P34 -> 0 | R34: =Q34 -> 0 | S34: =R34 -> 0 | U34: 0.5
C35: TP* | D35: *Commuter* | F35: TRP | G35: TRP | H35: 2015 | J35: 1 | O35: =-TRP!$H$6 -> -0.0042418397 | P35: =O35 -> -0.0042418397 | Q35: =P35 -> -0.0042418397 | R35: =Q35 -> -0.0042418397 | S35: =R35 -> -0.0042418397
C36: TP* | D36: *Commuter* | F36: TRP | G36: TRP | H36: 2020 | J36: 1
C37: TP* | D37: *Commuter* | F37: TRP | G37: TRP | H37: 2025 | J37: 1
C38: TP* | D38: *Commuter* | F38: TRP | G38: TRP | H38: 2030 | J38: 1
C39: TP* | D39: *Commuter* | F39: TRP | G39: TRP | H39: 2035 | J39: 1
C40: TP* | D40: *Commuter* | F40: TRP | G40: TRP | H40: 2040 | J40: 1
C41: TP* | D41: *Commuter* | F41: TRP | G41: TRP | H41: 2045 | J41: 1
C42: TP* | D42: *Commuter* | F42: TRP | G42: TRP | H42: 2050 | J42: 1
C43: TP* | D43: *Commuter* | F43: TRP | G43: TRP | H43: 2055 | J43: 1 | O43: =O35 -> -0.0042418397 | P43: =O43 -> -0.0042418397 | Q43: =P43 -> -0.0042418397 | R43: =Q43 -> -0.0042418397 | S43: =R43 -> -0.0042418397
B44: ="UC_"&G44&RIGHT(E44,3)&I44 -> UC_THSGSLLO | C44: THS* | E44: THGSL | F44: THS | G44: THS | H44: 2010 | I44: LO | J44: 1 | K44: 0 | L44: 15 | O44: 0 | P44: =O44 -> 0 | Q44: =P44 -> 0 | R44: =Q44 -> 0 | S44: =R44 -> 0
...

Sheet UC_TRNHDVb
A1: Heavy duty vehicle historical boundary calibration
F5: ~UC_Sets: R_S: AllRegions
K7: ~UC_T: UC_FLO
F8: UC_N | G8: Pset_PN | H8: Pset_PD | I8: Pset_CI | J8: Cset_CN | K8: Year | L8: LimType | M8: UC_RHSRT | N8: UC_RHSRT~0 | O8: AllRegions
A9: 2015 | B9: ='ON-Road Historical share'!L21 -> THS | C9: ='ON-Road Historical share'!M21 -> CNG | F9: ="UC_"&J9&C9&"FX"&A9 -> UC_THSCNGFX2015 | G9: =IF(D9="",B9&"*"&C9&"*",B9&"*"&C9&"*"&",-"&B9&"*"&D9) -> THS*CNG* | J9: =B9 -> THS | K9: =A9 -> 2015 | L9: FX | M9: 0 | N9: -1 | O9: =O10-1 -> -1
G10: =IF(D9="",B9&"*"&",-"&B9&"*"&C9&"*",B9&"*"&",-"&B9&"*"&C9&"*"&","&B9&"*"&D9&"*") -> THS*,-THS*CNG* | J10: =J9 -> THS | K10: =K9 -> 2015 | O10: ='ON-Road Historical share'!U21 -> 0
A11: 2020 | B11: =B9 -> THS | C11: =C9 -> CNG | F11: ="UC_"&J11&C11&"FX"&A11 -> UC_THSCNGFX2020 | G11: =IF(D11="",B11&"*"&C11&"*",B11&"*"&C11&"*"&",-"&B11&"*"&D11) -> THS*CNG* | J11: =B11 -> THS | K11: =A11 -> 2020 | L11: FX | M11: 0 | N11: -1 | O11: =O12-1 -> -0.99326135
G12: =IF(D11="",B11&"*"&",-"&B11&"*"&C11&"*",B11&"*"&",-"&B11&"*"&C11&"*"&","&B11&"*"&D11&"*") -> THS*,-THS*CNG* | J12: =J11 -> THS | K12: =K11 -> 2020 | O12: ='ON-Road Historical share'!V21 -> 0.0067386512
A13: 2025 | B13: =B11 -> THS | C13: =C11 -> CNG | F13: ="UC_"&J13&C13&"FX"&A13 -> UC_THSCNGFX2025 | G13: =IF(D13="",B13&"*"&C13&"*",B13&"*"&C13&"*"&",-"&B13&"*"&D13) -> THS*CNG* | J13: =B13 -> THS | K13: =A13 -> 2025 | L13: FX | M13: 0 | N13: -1 | O13: =O14-1 -> -0.99057703
G14: =IF(D13="",B13&"*"&",-"&B13&"*"&C13&"*",B13&"*"&",-"&B13&"*"&C13&"*"&","&B13&"*"&D13&"*") -> THS*,-THS*CNG* | J14: =J13 -> THS | K14: =K13 -> 2025 | O14: ='ON-Road Historical share'!W21 -> 0.0094229723
A15: =A9 -> 2015 | B15: ='ON-Road Historical share'!L22 -> THS | C15: ='ON-Road Historical share'!M22 -> DSL | D15: ='ON-Road Historical share'!N36 -> DHEV | F15: ="UC_"&J15&C15&"FX"&A15 -> UC_THSDSLFX2015 | G15: =IF(D15="",B15&"*"&C15&"*",B15&"*"&C15&"*"&",-"&B15&"*"&D15&"*") -> THS*DSL*,-THS*DHEV* | J15: =B15 -> THS | K15: =A15 -> 2015 | L15: FX | M15: 0 | N15: -1 | O15: =O16-1 -> 0
G16: =IF(D15="",B15&"*"&",-"&B15&"*"&C15&"*",B15&"*"&",-"&B15&"*"&C15&"*"&","&B15&"*"&D15&"*") -> THS*,-THS*DSL*,THS*DHEV* | J16: =J15 -> THS | K16: =K15 -> 2015 | O16: ='ON-Road Historical share'!U22 -> 1
A17: =A11 -> 2020 | B17: =B15 -> THS | C17: =C15 -> DSL | D17: =D15 -> DHEV | F17: ="UC_"&J17&C17&"FX"&A17 -> UC_THSDSLFX2020 | G17: =IF(D17="",B17&"*"&C17&"*",B17&"*"&C17&"*"&",-"&B17&"*"&D17&"*") -> THS*DSL*,-THS*DHEV* | J17: =B17 -> THS | K17: =A17 -> 2020 | L17: FX | M17: 0 | N17: -1 | O17: =O18-1 -> -0.022539545
G18: =IF(D17="",B17&"*"&",-"&B17&"*"&C17&"*",B17&"*"&",-"&B17&"*"&C17&"*"&","&B17&"*"&D17&"*") -> THS*,-THS*DSL*,THS*DHEV* | J18: =J17 -> THS | K18: =K17 -> 2020 | O18: ='ON-Road Historical share'!V22 -> 0.97746046
A19: =A13 -> 2025 | B19: =B17 -> THS | C19: =C17 -> DSL | D19: =D17 -> DHEV | F19: ="UC_"&J19&C19&"FX"&A19 -> UC_THSDSLFX2025 | G19: =IF(D19="",B19&"*"&C19&"*",B19&"*"&C19&"*"&",-"&B19&"*"&D19&"*") -> THS*DSL*,-THS*DHEV* | J19: =B19 -> THS | K19: =A19 -> 2025 | L19: FX | M19: 0 | N19: -1 | O19: =O20-1 -> -0.031457208
G20: =IF(D19="",B19&"*"&",-"&B19&"*"&C19&"*",B19&"*"&",-"&B19&"*"&C19&"*"&","&B19&"*"&D19&"*") -> THS*,-THS*DSL*,THS*DHEV* | J20: =J19 -> THS | K20: =K19 -> 2025 | O20: ='ON-Road Historical share'!W22 -> 0.96854279
A21: =A15 -> 2015 | B21: ='ON-Road Historical share'!L23 -> THS | C21: ='ON-Road Historical share'!M23 -> DSLH | F21: ="UC_"&J21&C21&"FX"&A21 -> UC_THSDSLHFX2015 | G21: =IF(D21="",B21&"*"&C21&"*",B21&"*"&C21&"*"&",-"&B21&"*"&D21) -> THS*DSLH* | J21: =B21 -> THS | K21: =A21 -> 2015 | L21: FX | M21: 0 | N21: -1 | O21: =O22-1 -> -1
G22: =IF(D21="",B21&"*"&",-"&B21&"*"&C21&"*",B21&"*"&",-"&B21&"*"&C21&"*"&","&B21&"*"&D21&"*") -> THS*,-THS*DSLH* | J22: =J21 -> THS | K22: =K21 -> 2015 | O22: ='ON-Road Historical share'!U23 -> 0
A23: =A17 -> 2020 | B23: =B21 -> THS | C23: =C21 -> DSLH | F23: ="UC_"&J23&C23&"FX"&A23 -> UC_THSDSLHFX2020 | G23: =IF(D23="",B23&"*"&C23&"*",B23&"*"&C23&"*"&",-"&B23&"*"&D23) -> THS*DSLH* | J23: =B23 -> THS | K23: =A23 -> 2020 | L23: FX | M23: 0 | N23: -1 | O23: =O24-1 -> -0.99855748
G24: =IF(D23="",B23&"*"&",-"&B23&"*"&C23&"*",B23&"*"&",-"&B23&"*"&C23&"*"&","&B23&"*"&D23&"*") -> THS*,-THS*DSLH* | J24: =J23 -> THS | K24: =K23 -> 2020 | O24: ='ON-Road Historical share'!V23 -> 0.0014425177
A25: =A19 -> 2025 | B25: =B23 -> THS | C25: =C23 -> DSLH | F25: ="UC_"&J25&C25&"FX"&A25 -> UC_THSDSLHFX2025 | G25: =IF(D25="",B25&"*"&C25&"*",B25&"*"&C25&"*"&",-"&B25&"*"&D25) -> THS*DSLH* | J25: =B25 -> THS | K25: =A25 -> 2025 | L25: FX | M25: 0 | N25: -1 | O25: =O26-1 -> -0.99798378
G26: =IF(D25="",B25&"*"&",-"&B25&"*"&C25&"*",B25&"*"&",-"&B25&"*"&C25&"*"&","&B25&"*"&D25&"*") -> THS*,-THS*DSLH* | J26: =J25 -> THS | K26: =K25 -> 2025 | O26: ='ON-Road Historical share'!W23 -> 0.0020162159
A27: =A21 -> 2015 | B27: ='ON-Road Historical share'!L24 -> THS | C27: ='ON-Road Historical share'!M24 -> ELC | F27: ="UC_"&J27&C27&"FX"&A27 -> UC_THSELCFX2015 | G27: =IF(D27="",B27&"*"&C27&"*",B27&"*"&C27&"*"&",-"&B27&"*"&D27) -> THS*ELC* | J27: =B27 -> THS | K27: =A27 -> 2015 | L27: FX | M27: 0 | N27: -1 | O27: =O28-1 -> -1
G28: =IF(D27="",B27&"*"&",-"&B27&"*"&C27&"*",B27&"*"&",-"&B27&"*"&C27&"*"&","&B27&"*"&D27&"*") -> THS*,-THS*ELC* | J28: =J27 -> THS | K28: =K27 -> 2015 | O28: ='ON-Road Historical share'!U24 -> 0
A29: =A23 -> 2020 | B29: =B27 -> THS | C29: =C27 -> ELC | F29: ="UC_"&J29&C29&"FX"&A29 -> UC_THSELCFX2020 | G29: =IF(D29="",B29&"*"&C29&"*",B29&"*"&C29&"*"&",-"&B29&"*"&D29) -> THS*ELC* | J29: =B29 -> THS | K29: =A29 -> 2020 | L29: FX | M29: 0 | N29: -1 | O29: =O30-1 -> -1
G30: =IF(D29="",B29&"*"&",-"&B29&"*"&C29&"*",B29&"*"&",-"&B29&"*"&C29&"*"&","&B29&"*"&D29&"*") -> THS*,-THS*ELC* | J30: =J29 -> THS | K30: =K29 -> 2020 | O30: ='ON-Road Historical share'!V24 -> 0
A31: =A25 -> 2025 | B31: =B29 -> THS | C31: =C29 -> ELC | F31: ="UC_"&J31&C31&"FX"&A31 -> UC_THSELCFX2025 | G31: =IF(D31="",B31&"*"&C31&"*",B31&"*"&C31&"*"&",-"&B31&"*"&D31) -> THS*ELC* | J31: =B31 -> THS | K31: =A31 -> 2025 | L31: FX | M31: 0 | N31: -1 | O31: =O32-1 -> -1
G32: =IF(D31="",B31&"*"&",-"&B31&"*"&C31&"*",B31&"*"&",-"&B31&"*"&C31&"*"&","&B31&"*"&D31&"*") -> THS*,-THS*ELC* | J32: =J31 -> THS | K32: =K31 -> 2025 | O32: ='ON-Road Historical share'!W24 -> 0
A33: =A27 -> 2015 | B33: ='ON-Road Historical share'!L25 -> THS | C33: ='ON-Road Historical share'!M25 -> GSL | D33: ='ON-Road Historical share'!N25 -> GSLH | F33: ="UC_"&J33&C33&"FX"&A33 -> UC_THSGSLFX2015 | G33: =IF(D33="",B33&"*"&C33&"*",B33&"*"&C33&"*"&",-"&B33&"*"&D33&"*") -> THS*GSL*,-THS*GSLH* | J33: =B33 -> THS | K33: =A33 -> 2015 | L33: FX | M33: 0 | N33: -1 | O33: =O34-1 -> -1
G34: =IF(D33="",B33&"*"&",-"&B33&"*"&C33&"*",B33&"*"&",-"&B33&"*"&C33&"*"&","&B33&"*"&D33&"*") -> THS*,-THS*GSL*,THS*GSLH* | J34: =J33 -> THS | K34: =K33 -> 2015 | O34: ='ON-Road Historical share'!U25 -> 0
A35: =A29 -> 2020 | B35: =B33 -> THS | C35: =C33 -> GSL | D35: =D33 -> GSLH | F35: ="UC_"&J35&C35&"FX"&A35 -> UC_THSGSLFX2020 | G35: =IF(D35="",B35&"*"&C35&"*",B35&"*"&C35&"*"&",-"&B35&"*"&D35&"*") -> THS*GSL*,-THS*GSLH* | J35: =B35 -> THS | K35: =A35 -> 2020 | L35: FX | M35: 0 | N35: -1 | O35: =O36-1 -> -0.98564162
G36: =IF(D35="",B35&"*"&",-"&B35&"*"&C35&"*",B35&"*"&",-"&B35&"*"&C35&"*"&","&B35&"*"&D35&"*") -> THS*,-THS*GSL*,THS*GSLH* | J36: =J35 -> THS | K36: =K35 -> 2020 | O36: ='ON-Road Historical share'!V25 -> 0.014358376
A37: =A31 -> 2025 | B37: =B35 -> THS | C37: =C35 -> GSL | D37: =D35 -> GSLH | F37: ="UC_"&J37&C37&"FX"&A37 -> UC_THSGSLFX2025 | G37: =IF(D37="",B37&"*"&C37&"*",B37&"*"&C37&"*"&",-"&B37&"*"&D37&"*") -> THS*GSL*,-THS*GSLH* | J37: =B37 -> THS | K37: =A37 -> 2025 | L37: FX | M37: 0 | N37: -1 | O37: =O38-1 -> -0.97998198
G38: =IF(D37="",B37&"*"&",-"&B37&"*"&C37&"*",B37&"*"&",-"&B37&"*"&C37&"*"&","&B37&"*"&D37&"*") -> THS*,-THS*GSL*,THS*GSLH* | J38: =J37 -> THS | K38: =K37 -> 2025 | O38: ='ON-Road Historical share'!W25 -> 0.02001802
A39: =A33 -> 2015 | B39: =B33 -> THS | C39: =D33 -> GSLH | F39: ="UC_"&J39&C39&"FX"&A39 -> UC_THSGSLHFX2015 | G39: =IF(D39="",B39&"*"&C39&"*",B39&"*"&C39&"*"&",-"&B39&"*"&D39&"*") -> THS*GSLH* | J39: =B39 -> THS | K39: =A39 -> 2015 | L39: FX | M39: 0 | N39: -1 | O39: =O40-1 -> -1
G40: =IF(D39="",B39&"*"&",-"&B39&"*"&C39&"*",B39&"*"&",-"&B39&"*"&C39&"*"&","&B39&"*"&D39&"*") -> THS*,-THS*GSLH* | J40: =J39 -> THS | K40: =K39 -> 2015 | O40: 0
A41: =A35 -> 2020 | B41: =B39 -> THS | C41: =C39 -> GSLH | F41: ="UC_"&J41&C41&"FX"&A41 -> UC_THSGSLHFX2020 | G41: =IF(D41="",B41&"*"&C41&"*",B41&"*"&C41&"*"&",-"&B41&"*"&D41&"*") -> THS*GSLH* | J41: =B41 -> THS | K41: =A41 -> 2020 | L41: FX | M41: 0 | N41: -1 | O41: =O42-1 -> -1
G42: =IF(D41="",B41&"*"&",-"&B41&"*"&C41&"*",B41&"*"&",-"&B41&"*"&C41&"*"&","&B41&"*"&D41&"*") -> THS*,-THS*GSLH* | J42: =J41 -> THS | K42: =K41 -> 2020 | O42: 0
A43: =A37 -> 2025 | B43: =B41 -> THS | C43: =C41 -> GSLH | F43: ="UC_"&J43&C43&"FX"&A43 -> UC_THSGSLHFX2025 | G43: =IF(D43="",B43&"*"&C43&"*",B43&"*"&C43&"*"&",-"&B43&"*"&D43&"*") -> THS*GSLH* | J43: =B43 -> THS | K43: =A43 -> 2025 | L43: FX | M43: 0 | N43: -1 | O43: =O44-1 -> -1
G44: =IF(D43="",B43&"*"&",-"&B43&"*"&C43&"*",B43&"*"&",-"&B43&"*"&C43&"*"&","&B43&"*"&D43&"*") -> THS*,-THS*GSLH* | J44: =J43 -> THS | K44: =K43 -> 2025 | O44: 0
...

Sheet ON-Road Historical share
Z2: On-road transportation
Z4: Header key | AC4: NOTE
Z5: Feeds | AA5: Community tab via INDEX | AC5: Table 3 of this tab should be populated by values from "On Road Transportation Summary 20XX" workbook. Use the VMT values in "table 3" of the "20XX Summary" tab
Z6: Feeds | AA6: Historical tab via 'aggregate tag'
Z7: Feeds | AA7: Both Community and Historical tab
AC9: 1000 | AF9: This step is required to correct the the fact that, to avoid problems when dividing by zero. the model set some cells to values fractionally higher than zero.
AC10: 0.001 | AF10: Lower bound for percentage of VMT to utilize - anything with a percentage below this will be set to 0 VMT
Z11: Table 1
Y12: Aggregate tag | Z12: Data source | AA12: GPC Sector | AB12: GPC Sub-sector | AC12: GPC Sub-sector class | AD12: GPC Sub-sector class agg | AE12: Address/service | AF12: Fuel type | AG12: Reported units | AH12: CY2022 | AI12: CY2021 | AJ12: CY2020 | AK12: CY2019 | AL12: CY2018 | AM12: CY2017 | AN12: CY2016 | AO12: CY2015 | AP12: CY2014 | AQ12: CY2013 | AR12: CY2012 | AS12: CY2011 | AT12: CY2010 | AU12: CY2009 | AV12: CY2008 | AW12: CY2007 | AX12: CY2006 | AY12: CY2005
Y13: Heavy duty trucks(private)CNG | Z13: NYMTC BPM | AA13: Transportation | AB13: On-road | AC13: Heavy duty trucks | AD13: Heavy duty trucks | AE13: (private) | AF13: CNG | AG13: VMT | AH13: 6398791.5 | AI13: 5317833.8 | AJ13: 4068498.7 | AK13: 3481673.7 | AL13: 2552442.9 | AM13: 1633232.8 | AN13: 805661.85 | AO13: 0 | AP13: 0 | AQ13: 0 | AR13: 0 | AS13: 0 | AT13: 0 | AU13: 0 | AV13: 0 | AW13: 0 | AX13: 0 | AY13: 0
Y14: Heavy duty trucks(private)Diesel | Z14: NYMTC BPM | AA14: Transportation | AB14: On-road | AC14: Heavy duty trucks | AD14: Heavy duty trucks | AE14: (private) | AF14: Diesel | AG14: VMT | AH14: 5.5015747e+08 | AI14: 5.3597055e+08 | AJ14: 4.9440372e+08 | AK14: 5.3136798e+08 | AL14: 5.2184428e+08 | AM14: 5.0321127e+08 | AN14: 4.9875703e+08 | AO14: 4.9188555e+08 | AP14: 4.8019396e+08 | AQ14: 4.9395273e+08 | AR14: 4.9204316e+08 | AS14: 5.0093796e+08 | AT14: 5.0243622e+08 | AU14: 4.5058508e+08 | AV14: 4.9222673e+08 | AW14: 5.1459198e+08 | AX14: 5.0452045e+08 | AY14: 4.9340266e+08
Y15: Heavy duty trucks(private)Electricity | Z15: NYMTC BPM | AA15: Transportation | AB15: On-road | AC15: Heavy duty trucks | AD15: Heavy duty trucks | AE15: (private) | AF15: Electricity | AG15: VMT | AH15: 0 | AI15: 0 | AJ15: 0 | AK15: 0 | AL15: 0 | AM15: 0 | AN15: 0 | AO15: 0 | AP15: 0 | AQ15: 0 | AR15: 0 | AS15: 0 | AT15: 0 | AU15: 0 | AV15: 0 | AW15: 0 | AX15: 0 | AY15: 0
Q16: 2019 | Y16: Heavy duty trucks(private)Gasoline | Z16: NYMTC BPM | AA16: Transportation | AB16: On-road | AC16: Heavy duty trucks | AD16: Heavy duty trucks | AE16: (private) | AF16: Gasoline | AG16: VMT | AH16: 11503965 | AI16: 9560569.4 | AJ16: 7314461.9 | AK16: 6259434 | AL16: 4588820.1 | AM16: 2936223.3 | AN16: 1448377.6 | AO16: 0 | AP16: 0 | AQ16: 0 | AR16: 0 | AS16: 0 | AT16: 0 | AU16: 0 | AV16: 0 | AW16: 0 | AX16: 0 | AY16: 0
O17: 2010 | P17: 2015 | Q17: 2021 | R17: 2022 | Y17: Heavy duty trucks(public)Diesel | Z17: NYMTC BPM | AA17: Transportation | AB17: On-road | AC17: Heavy duty trucks | AD17: Heavy duty trucks | AE17: (public) | AF17: Diesel | AG17: VMT | AH17: 1.0149074e+08 | AI17: 98705425 | AJ17: 90896735 | AK17: 97529071 | AL17: 95621910 | AM17: 92055591 | AN17: 91091462 | AO17: 89690607 | AP17: 87558751 | AQ17: 90067524 | AR17: 89719324 | AS17: 91341199 | AT17: 91614385 | AU17: 91587216 | AV17: 1.0005141e+08 | AW17: 1.0459742e+08 | AX17: 1.0255025e+08 | AY17: 1.0029041e+08
Y18: Heavy duty trucks(public)Diesel Hybrid | Z18: NYMTC BPM | AA18: Transportation | AB18: On-road | AC18: Heavy duty trucks | AD18: Heavy duty trucks | AE18: (public) | AF18: Diesel Hybrid | AG18: VMT | AH18: 1348977.7 | AI18: 1121090.5 | AJ18: 857706.76 | AK18: 733991.13 | AL18: 538090.85 | AM18: 344303.41 | AN18: 169834.93 | AO18: 0 | AP18: 0 | AQ18: 0 | AR18: 0 | AS18: 0 | AT18: 0 | AU18: 0 | AV18: 0 | AW18: 0 | AX18: 0 | AY18: 0
O19: Billion VMT | P19: Billion VMT | Q19: Billion VMT | R19: Billion VMT | S19: Billion VMT | Y19: Heavy duty trucks(public)Gasoline | Z19: NYMTC BPM | AA19: Transportation | AB19: On-road | AC19: Heavy duty trucks | AD19: Heavy duty trucks | AE19: (public) | AF19: Gasoline | AG19: VMT | AH19: 793516.32 | AI19: 659465.01 | AJ19: 504533.39 | AK19: 431759.49 | AL19: 316524.03 | AM19: 202531.41 | AN19: 99902.898 | AO19: 0 | AP19: 0 | AQ19: 0 | AR19: 0 | AS19: 0 | AT19: 0 | AU19: 0 | AV19: 0 | AW19: 0 | AX19: 0 | AY19: 0
B20: Row Labels | C20: Sum of CY2010 | D20: Sum of CY2015 | E20: Sum of CY2019 | F20: Sum of CY2021 | G20: Sum of CY2022 | O20: 2010 | P20: 2015 | Q20: 2020 | R20: 2022 | S20: 2025 | T20: Share 2010 | U20: Share 2015 | V20: Share 2020 | W20: Share 2025 | Y20: Medium duty trucks(private)CNG | Z20: NYMTC BPM | AA20: Transportation | AB20: On-road | AC20: Medium duty trucks | AD20: Medium duty trucks | AE20: (private) | AF20: CNG | AG20: VMT | AH20: 0 | AI20: 0 | AJ20: 0 | AK20: 0 | AL20: 0 | AM20: 0 | AN20: 0 | AO20: 0 | AP20: 0 | AQ20: 0 | AR20: 0 | AS20: 0 | AT20: 0 | AU20: 0 | AV20: 0 | AW20: 0 | AX20: 0 | AY20: 0
B21: Transportation | C21: 2.1148664e+10 | D21: 2.1182701e+10 | E21: 2.3114015e+10 | F21: 2.1741184e+10 | G21: 2.2959328e+10 | J21: Heavy duty trucks | K21: CNG | L21: THS | M21: CNG | O21: =(GETPIVOTDATA("Sum of CY"&$O$17,$B$20,"GPC Sector","Transportation","GPC Sub-sector","On-road","GPC Sub-sector class agg",$J21,"Fuel type",$K21))/10^6 -> 0 | P21: =(GETPIVOTDATA("Sum of CY"&$P$17,$B$20,"GPC Sector","Transportation","GPC Sub-sector","On-road","GPC Sub-sector class agg",$J21,"Fuel type",$K21))/10^6 -> 0 | Q21: =(GETPIVOTDATA("Sum of CY"&$Q$17,$B$20,"GPC Sector","Transportation","GPC Sub-sector","On-road","GPC Sub-sector class agg",$J21,"Fuel type",$K21)+GETPIVOTDATA("Sum of CY"&$Q$16,$B$20,"GPC Sector","Transportation","GPC Sub-sector","On-road","GPC Sub-sector class agg",$J21,"Fuel type",$K21))/2/10^6 -> 4.6241466 | R21: =(GETPIVOTDATA("Sum of CY"&$R$17,$B$20,"GPC Sector","Transportation","GPC Sub-sector","On-road","GPC Sub-sector class agg",$J21,"Fuel type",$K21))/10^6 -> 6.7146953 | S21: =IF(Q21+(R21-Q21)*5/2<0,0,Q21+(R21-Q21)*5/2) -> 9.8505182 | T21: =O21/SUMIFS(O:O,$L:$L,$L21) -> 0 | U21: =P21/SUMIFS(P:P,$L:$L,$L21) -> 0 | V21: =Q21/SUMIFS(Q:Q,$L:$L,$L21) -> 0.0067386512 | W21: =R21/SUMIFS(R:R,$L:$L,$L21) -> 0.0094229723 | Y21: Medium duty trucks(private)Diesel | Z21: NYMTC BPM | AA21: Transportation | AB21: On-road | AC21: Medium duty trucks | AD21: Medium duty trucks | AE21: (private) | AF21: Diesel | AG21: VMT | AH21: 11279307 | AI21: 27518399 | AJ21: 40144153 | AK21: 65719096 | AL21: 82839477 | AM21: 97508882 | AN21: 1.1235775e+08 | AO21: 1.2758889e+08 | AP21: 1.2048793e+08 | AQ21: 1.1411586e+08 | AR21: 1.0810908e+08 | AS21: 1.0605027e+08 | AT21: 1.054526e+08 | AU21: 1.0180514e+08 | AV21: 1.0463898e+08 | AW21: 1.0318043e+08 | AX21: 98103289 | AY21: 92375248
B22: On-road | C22: 2.1148664e+10 | D22: 2.1182701e+10 | E22: 2.3114015e+10 | F22: 2.1741184e+10 | G22: 2.2959328e+10 | J22: Heavy duty trucks | K22: Diesel | L22: THS | M22: DSL | N22: DSLH | O22: =(GETPIVOTDATA("Sum of CY"&$O$17,$B$20,"GPC Sector","Transportation","GPC Sub-sector","On-road","GPC Sub-sector class agg",$J22,"Fuel type",$K22))/10^6 -> 633.35834 | P22: =(GETPIVOTDATA("Sum of CY"&$P$17,$B$20,"GPC Sector","Transportation","GPC Sub-sector","On-road","GPC Sub-sector class agg",$J22,"Fuel type",$K22))/10^6 -> 621.59706 | Q22: =(GETPIVOTDATA("Sum of CY"&$Q$17,$B$20,"GPC Sector","Transportation","GPC Sub-sector","On-road","GPC Sub-sector class agg",$J22,"Fuel type",$K22)+GETPIVOTDATA("Sum of CY"&$Q$16,$B$20,"GPC Sector","Transportation","GPC Sub-sector","On-road","GPC Sub-sector class agg",$J22,"Fuel type",$K22))/2/10^6 -> 670.74557 | R22: =(GETPIVOTDATA("Sum of CY"&$R$17,$B$20,"GPC Sector","Transportation","GPC Sub-sector","On-road","GPC Sub-sector class agg",$J22,"Fuel type",$K22))/10^6 -> 690.1718 | S22: =IF(Q22+(R22-Q22)*5/2<0,0,Q22+(R22-Q22)*5/2) -> 719.31114 | T22: =O22/SUMIFS(O:O,$L:$L,$L22) -> 1 | U22: =P22/SUMIFS(P:P,$L:$L,$L22) -> 1 | V22: =Q22/SUMIFS(Q:Q,$L:$L,$L22) -> 0.97746046 | W22: =R22/SUMIFS(R:R,$L:$L,$L22) -> 0.96854279 | Y22: Medium duty trucks(private)Electricity | Z22: NYMTC BPM | AA22: Transportation | AB22: On-road | AC22: Medium duty trucks | AD22: Medium duty trucks | AE22: (private) | AF22: Electricity | AG22: VMT | AH22: 6205269.6 | AI22: 4937836.3 | AJ22: 3706644.4 | AK22: 3511328.2 | AL22: 2600150.9 | AM22: 1676984.2 | AN22: 820134.07 | AO22: 0 | AP22: 0 | AQ22: 0 | AR22: 0 | AS22: 0 | AT22: 0 | AU22: 0 | AV22: 0 | AW22: 0 | AX22: 0 | AY22: 0
B23: Buses | C23: 3.6282221e+08 | D23: 3.5717938e+08 | E23: 3.2287465e+08 | F23: 3.1066619e+08 | G23: 3.3052685e+08 | J23: Heavy duty trucks | K23: Diesel Hybrid | L23: THS | M23: DSLH | O23: =(GETPIVOTDATA("Sum of CY"&$O$17,$B$20,"GPC Sector","Transportation","GPC Sub-sector","On-road","GPC Sub-sector class agg",$J23,"Fuel type",$K23))/10^6 -> 0 | P23: =(GETPIVOTDATA("Sum of CY"&$P$17,$B$20,"GPC Sector","Transportation","GPC Sub-sector","On-road","GPC Sub-sector class agg",$J23,"Fuel type",$K23))/10^6 -> 0 | Q23: =(GETPIVOTDATA("Sum of CY"&$Q$17,$B$20,"GPC Sector","Transportation","GPC Sub-sector","On-road","GPC Sub-sector class agg",$J23,"Fuel type",$K23)+GETPIVOTDATA("Sum of CY"&$Q$16,$B$20,"GPC Sector","Transportation","GPC Sub-sector","On-road","GPC Sub-sector class agg",$J23,"Fuel type",$K23))/2/10^6 -> 0.98987368 | R23: =(GETPIVOTDATA("Sum of CY"&$R$17,$B$20,"GPC Sector","Transportation","GPC Sub-sector","On-road","GPC Sub-sector class agg",$J23,"Fuel type",$K23))/10^6 -> 1.4367309 | S23: =IF(Q23+(R23-Q23)*5/2<0,0,Q23+(R23-Q23)*5/2) -> 2.1070167 | T23: =O23/SUMIFS(O:O,$L:$L,$L23) -> 0 | U23: =P23/SUMIFS(P:P,$L:$L,$L23) -> 0 | V23: =Q23/SUMIFS(Q:Q,$L:$L,$L23) -> 0.0014425177 | W23: =R23/SUMIFS(R:R,$L:$L,$L23) -> 0.0020162159 | Y23: Medium duty trucks(private)Gasoline | Z23: NYMTC BPM | AA23: Transportation | AB23: On-road | AC23: Medium duty trucks | AD23: Medium duty trucks | AE23: (private) | AF23: Gasoline | AG23: VMT | AH23: 5.0550421e+08 | AI23: 4.5310636e+08 | AJ23: 3.9357101e+08 | AK23: 4.4877002e+08 | AL23: 4.2603506e+08 | AM23: 3.9566163e+08 | AN23: 3.7085217e+08 | AO23: 3.4990353e+08 | AP23: 3.3939282e+08 | AQ23: 3.3027735e+08 | AR23: 3.2160736e+08 | AS23: 3.2439318e+08 | AT23: 3.3180789e+08 | AU23: 3.2964821e+08 | AV23: 3.4883299e+08 | AW23: 3.5429561e+08 | AX23: 3.4714298e+08 | AY23: 3.3702346e+08
B24: CNG | C24: 37590232 | D24: 40318337 | E24: 30250532 | F24: 33248656 | G24: 43719634 | J24: Heavy duty trucks | K24: Electricity | L24: THS | M24: ELC | O24: =(GETPIVOTDATA("Sum of CY"&$O$17,$B$20,"GPC Sector","Transportation","GPC Sub-sector","On-road","GPC Sub-sector class agg",$J24,"Fuel type",$K24))/10^6 -> 0 | P24: =(GETPIVOTDATA("Sum of CY"&$P$17,$B$20,"GPC Sector","Transportation","GPC Sub-sector","On-road","GPC Sub-sector class agg",$J24,"Fuel type",$K24))/10^6 -> 0 | Q24: =(GETPIVOTDATA("Sum of CY"&$Q$17,$B$20,"GPC Sector","Transportation","GPC Sub-sector","On-road","GPC Sub-sector class agg",$J24,"Fuel type",$K24)+GETPIVOTDATA("Sum of CY"&$Q$16,$B$20,"GPC Sector","Transportation","GPC Sub-sector","On-road","GPC Sub-sector class agg",$J24,"Fuel type",$K24))/2/10^6 -> 0 | R24: =(GETPIVOTDATA("Sum of CY"&$R$17,$B$20,"GPC Sector","Transportation","GPC Sub-sector","On-road","GPC Sub-sector class agg",$J24,"Fuel type",$K24))/10^6 -> 0 | S24: =IF(Q24+(R24-Q24)*5/2<0,0,Q24+(R24-Q24)*5/2) -> 0 | T24: =O24/SUMIFS(O:O,$L:$L,$L24) -> 0 | U24: =P24/SUMIFS(P:P,$L:$L,$L24) -> 0 | V24: =Q24/SUMIFS(Q:Q,$L:$L,$L24) -> 0 | W24: =R24/SUMIFS(R:R,$L:$L,$L24) -> 0 | Y24: Medium duty trucks(public)CNG | Z24: NYMTC BPM | AA24: Transportation | AB24: On-road | AC24: Medium duty trucks | AD24: Medium duty trucks | AE24: (public) | AF24: CNG | AG24: VMT | AH24: 203240.43 | AI24: 479415.07 | AJ24: 693742.48 | AK24: 1131591.1 | AL24: 1423438.4 | AM24: 1673275 | AN24: 1926293.1 | AO24: 2185919.8 | AP24: 1892491.4 | AQ24: 1625562.1 | AR24: 1375390.8 | AS24: 1180900.9 | AT24: 999669.21 | AU24: 804110.87 | AV24: 633860.62 | AW24: 426304.96 | AX24: 207454.24 | AY24: 0
B25: Diesel | C25: 3.2523198e+08 | D25: 3.1686105e+08 | E25: 2.6569582e+08 | F25: 2.3535036e+08 | G25: 2.3602512e+08 | J25: Heavy duty trucks | K25: Gasoline | L25: THS | M25: GSL | N25: GSLH | O25: =(GETPIVOTDATA("Sum of CY"&$O$17,$B$20,"GPC Sector","Transportation","GPC Sub-sector","On-road","GPC Sub-sector class agg",$J25,"Fuel type",$K25))/10^6 -> 0 | P25: =(GETPIVOTDATA("Sum of CY"&$P$17,$B$20,"GPC Sector","Transportation","GPC Sub-sector","On-road","GPC Sub-sector class agg",$J25,"Fuel type",$K25))/10^6 -> 0 | Q25: =(GETPIVOTDATA("Sum of CY"&$Q$17,$B$20,"GPC Sector","Transportation","GPC Sub-sector","On-road","GPC Sub-sector class agg",$J25,"Fuel type",$K25)+GETPIVOTDATA("Sum of CY"&$Q$16,$B$20,"GPC Sector","Transportation","GPC Sub-sector","On-road","GPC Sub-sector class agg",$J25,"Fuel type",$K25))/2/10^6 -> 9.8528969 | R25: =(GETPIVOTDATA("Sum of CY"&$R$17,$B$20,"GPC Sector","Transportation","GPC Sub-sector","On-road","GPC Sub-sector class agg",$J25,"Fuel type",$K25))/10^6 -> 14.264597 | S25: =IF(Q25+(R25-Q25)*5/2<0,0,Q25+(R25-Q25)*5/2) -> 20.882147 | T25: =O25/SUMIFS(O:O,$L:$L,$L25) -> 0 | U25: =P25/SUMIFS(P:P,$L:$L,$L25) -> 0 | V25: =Q25/SUMIFS(Q:Q,$L:$L,$L25) -> 0.014358376 | W25: =R25/SUMIFS(R:R,$L:$L,$L25) -> 0.02001802 | Y25: Medium duty trucks(public)Diesel | Z25: NYMTC BPM | AA25: Transportation | AB25: On-road | AC25: Medium duty trucks | AD25: Medium duty trucks | AE25: (public) | AF25: Diesel | AG25: VMT | AH25: 29125917 | AI25: 27669746 | AJ25: 25492232 | AK25: 30858138 | AL25: 31130769 | AM25: 30758549 | AN25: 30711878 | AO25: 30914243 | AP25: 29858653 | AQ25: 28932714 | AR25: 28054156 | AS25: 28178739 | AT25: 28703354 | AU25: 28939167 | AV25: 30498827 | AW25: 30851646 | AX25: 30108174 | AY25: 29114935
B26: Electricity | C26: 0 | D26: 0 | E26: 0 | F26: 0 | G26: 23359.435 | J26: Medium duty trucks | K26: CNG | L26: TM | M26: CNG | O26: =(GETPIVOTDATA("Sum of CY"&$O$17,$B$20,"GPC Sector","Transportation","GPC Sub-sector","On-road","GPC Sub-sector class agg",$J26,"Fuel type",$K26))/10^6 -> 0.99966921 | P26: =(GETPIVOTDATA("Sum of CY"&$P$17,$B$20,"GPC Sector","Transportation","GPC Sub-sector","On-road","GPC Sub-sector class agg",$J26,"Fuel type",$K26))/10^6 -> 2.1859198 | Q26: =(GETPIVOTDATA("Sum of CY"&$Q$17,$B$20,"GPC Sector","Transportation","GPC Sub-sector","On-road","GPC Sub-sector class agg",$J26,"Fuel type",$K26)+GETPIVOTDATA("Sum of CY"&$Q$16,$B$20,"GPC Sector","Transportation","GPC Sub-sector","On-road","GPC Sub-sector class agg",$J26,"Fuel type",$K26))/2/10^6 -> 0.80550309 | R26: =(GETPIVOTDATA("Sum of CY"&$R$17,$B$20,"GPC Sector","Transportation","GPC Sub-sector","On-road","GPC Sub-sector class agg",$J26,"Fuel type",$K26))/10^6 -> 0.20324043 | S26: =IF(Q26+(R26-Q26)*5/2<0,0,Q26+(R26-Q26)*5/2) -> 0 | T26: =O26/SUMIFS(O:O,$L:$L,$L26) -> 0.002017697 | U26: =P26/SUMIFS(P:P,$L:$L,$L26) -> 0.0040402438 | V26: =Q26/SUMIFS(Q:Q,$L:$L,$L26) -> 0.0014167659 | W26: =R26/SUMIFS(R:R,$L:$L,$L26) -> 0.00034295117 | Y26: Medium duty trucks(public)Electricity | Z26: NYMTC BPM | AA26: Transportation | AB26: On-road | AC26: Medium duty trucks | AD26: Medium duty trucks | AE26: (public) | AF26: Electricity | AG26: VMT | AH26: 109437.16 | AI26: 87084.344 | AJ26: 65370.721 | AK26: 0 | AL26: 0 | AM26: 0 | AN26: 0 | AO26: 0 | AP26: 0 | AQ26: 0 | AR26: 0 | AS26: 0 | AT26: 0 | AU26: 0 | AV26: 0 | AW26: 0 | AX26: 0 | AY26: 0
B27: Gasoline | C27: 0 | D27: 0 | E27: 26928292 | F27: 42067176 | G27: 50758730 | J27: Medium duty trucks | K27: Diesel | L27: TM | M27: DSL | N27: DSLAH | O27: =(GETPIVOTDATA("Sum of CY"&$O$17,$B$20,"GPC Sector","Transportation","GPC Sub-sector","On-road","GPC Sub-sector class agg",$J27,"Fuel type",$K27))/10^6 -> 134.15595 | P27: =(GETPIVOTDATA("Sum of CY"&$P$17,$B$20,"GPC Sector","Transportation","GPC Sub-sector","On-road","GPC Sub-sector class agg",$J27,"Fuel type",$K27))/10^6 -> 158.50314 | Q27: =(GETPIVOTDATA("Sum of CY"&$Q$17,$B$20,"GPC Sector","Transportation","GPC Sub-sector","On-road","GPC Sub-sector class agg",$J27,"Fuel type",$K27)+GETPIVOTDATA("Sum of CY"&$Q$16,$B$20,"GPC Sector","Transportation","GPC Sub-sector","On-road","GPC Sub-sector class agg",$J27,"Fuel type",$K27))/2/10^6 -> 75.88269 | R27: =(GETPIVOTDATA("Sum of CY"&$R$17,$B$20,"GPC Sector","Transportation","GPC Sub-sector","On-road","GPC Sub-sector class agg",$J27,"Fuel type",$K27))/10^6 -> 40.405224 | S27: =IF(Q27+(R27-Q27)*5/2<0,0,Q27+(R27-Q27)*5/2) -> 0 | T27: =O27/SUMIFS(O:O,$L:$L,$L27) -> 0.27077563 | U27: =P27/SUMIFS(P:P,$L:$L,$L27) -> 0.29296195 | V27: =Q27/SUMIFS(Q:Q,$L:$L,$L27) -> 0.13346691 | W27: =R27/SUMIFS(R:R,$L:$L,$L27) -> 0.068180423 | Y27: Medium duty trucks(public)Gasoline | Z27: NYMTC BPM | AA27: Transportation | AB27: On-road | AC27: Medium duty trucks | AD27: Medium duty trucks | AE27: (public) | AF27: Gasoline | AG27: VMT | AH27: 38365540 | AI27: 34953813 | AJ27: 30888269 | AK27: 35867768 | AL27: 34714445 | AM27: 32907375 | AN27: 31524379 | AO27: 30444016 | AP27: 29449261 | AQ27: 28581066 | AR27: 27756626 | AS27: 27923282 | AT27: 28487102 | AU27: 28765219 | AV27: 30361708 | AW27: 30759426 | AX27: 30063296 | AY27: 29114935
B28: Heavy duty trucks | C28: 6.3335834e+08 | D28: 6.2159706e+08 | E28: 6.8032162e+08 | F28: 6.9210336e+08 | G28: 7.1258782e+08 | J28: Medium duty trucks | K28: Electricity | L28: TM | M28: ELC | O28: =(GETPIVOTDATA("Sum of CY"&$O$17,$B$20,"GPC Sector","Transportation","GPC Sub-sector","On-road","GPC Sub-sector class agg",$J28,"Fuel type",$K28))/10^6 -> 0 | P28: =(GETPIVOTDATA("Sum of CY"&$P$17,$B$20,"GPC Sector","Transportation","GPC Sub-sector","On-road","GPC Sub-sector class agg",$J28,"Fuel type",$K28))/10^6 -> 0 | Q28: =(GETPIVOTDATA("Sum of CY"&$Q$17,$B$20,"GPC Sector","Transportation","GPC Sub-sector","On-road","GPC Sub-sector class agg",$J28,"Fuel type",$K28)+GETPIVOTDATA("Sum of CY"&$Q$16,$B$20,"GPC Sector","Transportation","GPC Sub-sector","On-road","GPC Sub-sector class agg",$J28,"Fuel type",$K28))/2/10^6 -> 4.2681244 | R28: =(GETPIVOTDATA("Sum of CY"&$R$17,$B$20,"GPC Sector","Transportation","GPC Sub-sector","On-road","GPC Sub-sector class agg",$J28,"Fuel type",$K28))/10^6 -> 6.3147068 | S28: =IF(Q28+(R28-Q28)*5/2<0,0,Q28+(R28-Q28)*5/2) -> 9.3845804 | T28: =O28/SUMIFS(O:O,$L:$L,$L28) -> 0 | U28: =P28/SUMIFS(P:P,$L:$L,$L28) -> 0 | V28: =Q28/SUMIFS(Q:Q,$L:$L,$L28) -> 0.0075070265 | W28: =R28/SUMIFS(R:R,$L:$L,$L28) -> 0.010655537
B29: CNG | C29: 0 | D29: 0 | E29: 3660521.7 | F29: 5587771.6 | G29: 6714695.3 | J29: Medium duty trucks | K29: Gasoline | L29: TM | M29: GSL | N29: GSLAH | O29: =(GETPIVOTDATA("Sum of CY"&$O$17,$B$20,"GPC Sector","Transportation","GPC Sub-sector","On-road","GPC Sub-sector class agg",$J29,"Fuel type",$K29))/10^6 -> 360.29499 | P29: =(GETPIVOTDATA("Sum of CY"&$P$17,$B$20,"GPC Sector","Transportation","GPC Sub-sector","On-road","GPC Sub-sector class agg",$J29,"Fuel type",$K29))/10^6 -> 380.34755 | Q29: =(GETPIVOTDATA("Sum of CY"&$Q$17,$B$20,"GPC Sector","Transportation","GPC Sub-sector","On-road","GPC Sub-sector class agg",$J29,"Fuel type",$K29)+GETPIVOTDATA("Sum of CY"&$Q$16,$B$20,"GPC Sector","Transportation","GPC Sub-sector","On-road","GPC Sub-sector class agg",$J29,"Fuel type",$K29))/2/10^6 -> 486.34898 | R29: =(GETPIVOTDATA("Sum of CY"&$R$17,$B$20,"GPC Sector","Transportation","GPC Sub-sector","On-road","GPC Sub-sector class agg",$J29,"Fuel type",$K29))/10^6 -> 543.86975 | S29: =IF(Q29+(R29-Q29)*5/2<0,0,Q29+(R29-Q29)*5/2) -> 630.15089 | T29: =O29/SUMIFS(O:O,$L:$L,$L29) -> 0.72720667 | U29: =P29/SUMIFS(P:P,$L:$L,$L29) -> 0.70299781 | V29: =Q29/SUMIFS(Q:Q,$L:$L,$L29) -> 0.85541899 | W29: =R29/SUMIFS(R:R,$L:$L,$L29) -> 0.91773453 | Y29: Medium duty trucks(public)Gasoline Hybrid | Z29: NYMTC BPM | AA29: Transportation | AB29: On-road | AC29: Medium duty trucks | AD29: Medium duty trucks | AE29: (public) | AF29: Gasoline Hybrid | AG29: VMT | AH29: 1829163.9 | AI29: 1455552.6 | AJ29: 1092624.9 | AK29: 1035046.9 | AL29: 766451.24 | AM29: 494321.78 | AN29: 241740.79 | AO29: 0 | AP29: 0 | AQ29: 0 | AR29: 0 | AS29: 0 | AT29: 0 | AU29: 0 | AV29: 0 | AW29: 0 | AX29: 0 | AY29: 0
B30: Diesel | C30: 6.3335834e+08 | D30: 6.2159706e+08 | E30: 6.6807256e+08 | F30: 6.7341859e+08 | G30: 6.901718e+08 | J30: Medium duty trucks | K30: Gasoline Hybrid | L30: TM | M30: GSLAH | O30: =(GETPIVOTDATA("Sum of CY"&$O$17,$B$20,"GPC Sector","Transportation","GPC Sub-sector","On-road","GPC Sub-sector class agg",$J30,"Fuel type",$K30))/10^6 -> 0 | P30: =(GETPIVOTDATA("Sum of CY"&$P$17,$B$20,"GPC Sector","Transportation","GPC Sub-sector","On-road","GPC Sub-sector class agg",$J30,"Fuel type",$K30))/10^6 -> 0 | Q30: =(GETPIVOTDATA("Sum of CY"&$Q$17,$B$20,"GPC Sector","Transportation","GPC Sub-sector","On-road","GPC Sub-sector class agg",$J30,"Fuel type",$K30)+GETPIVOTDATA("Sum of CY"&$Q$16,$B$20,"GPC Sector","Transportation","GPC Sub-sector","On-road","GPC Sub-sector class agg",$J30,"Fuel type",$K30))/2/10^6 -> 1.2452997 | R30: =(GETPIVOTDATA("Sum of CY"&$R$17,$B$20,"GPC Sector","Transportation","GPC Sub-sector","On-road","GPC Sub-sector class agg",$J30,"Fuel type",$K30))/10^6 -> 1.8291639 | S30: =IF(Q30+(R30-Q30)*5/2<0,0,Q30+(R30-Q30)*5/2) -> 2.7049601 | T30: =O30/SUMIFS(O:O,$L:$L,$L30) -> 0 | U30: =P30/SUMIFS(P:P,$L:$L,$L30) -> 0 | V30: =Q30/SUMIFS(Q:Q,$L:$L,$L30) -> 0.0021903059 | W30: =R30/SUMIFS(R:R,$L:$L,$L30) -> 0.0030865605 | Y30: Passenger cars(private)CNG | Z30: NYMTC BPM | AA30: Transportation | AB30: On-road | AC30: Passenger cars | AD30: Passenger cars | AE30: (private) | AF30: CNG | AG30: VMT | AH30: 0 | AI30: 0 | AJ30: 0 | AK30: 0 | AL30: 0 | AM30: 0 | AN30: 0 | AO30: 0 | AP30: 0 | AQ30: 0 | AR30: 0 | AS30: 0 | AT30: 0 | AU30: 0 | AV30: 0 | AW30: 0 | AX30: 0 | AY30: 0
B31: Diesel Hybrid | C31: 0 | D31: 0 | E31: 783672.32 | F31: 1196075 | G31: 1436730.9 | J31: Buses | K31: Diesel | L31: TB | M31: DSL | N31: DSLAH | O31: =(GETPIVOTDATA("Sum of CY"&$O$17,$B$20,"GPC Sector","Transportation","GPC Sub-sector","On-road","GPC Sub-sector class agg",$J31,"Fuel type",$K31))/10^6 -> 325.23198 | P31: =(GETPIVOTDATA("Sum of CY"&$P$17,$B$20,"GPC Sector","Transportation","GPC Sub-sector","On-road","GPC Sub-sector class agg",$J31,"Fuel type",$K31))/10^6 -> 316.86105 | Q31: =(GETPIVOTDATA("Sum of CY"&$Q$17,$B$20,"GPC Sector","Transportation","GPC Sub-sector","On-road","GPC Sub-sector class agg",$J31,"Fuel type",$K31)+GETPIVOTDATA("Sum of CY"&$Q$16,$B$20,"GPC Sector","Transportation","GPC Sub-sector","On-road","GPC Sub-sector class agg",$J31,"Fuel type",$K31))/2/10^6 -> 250.52309 | R31: =(GETPIVOTDATA("Sum of CY"&$R$17,$B$20,"GPC Sector","Transportation","GPC Sub-sector","On-road","GPC Sub-sector class agg",$J31,"Fuel type",$K31))/10^6 -> 236.02512 | S31: =IF(Q31+(R31-Q31)*5/2<0,0,Q31+(R31-Q31)*5/2) -> 214.27817 | T31: =O31/SUMIFS(O:O,$L:$L,$L31) -> 0.8963949 | U31: =P31/SUMIFS(P:P,$L:$L,$L31) -> 0.8871202 | V31: =Q31/SUMIFS(Q:Q,$L:$L,$L31) -> 0.79086643 | W31: =R31/SUMIFS(R:R,$L:$L,$L31) -> 0.7140876 | Y31: Passenger cars(private)Diesel | Z31: NYMTC BPM | AA31: Transportation | AB31: On-road | AC31: Passenger cars | AD31: Passenger cars | AE31: (private) | AF31: Diesel | AG31: VMT | AH31: 1.35695e+08 | AI31: 1.4437044e+08 | AJ31: 1.3173031e+08 | AK31: 1.8782774e+08 | AL31: 2.0056401e+08 | AM31: 2.1055994e+08 | AN31: 2.2449686e+08 | AO31: 2.3373521e+08 | AP31: 2.1338913e+08 | AQ31: 2.0071866e+08 | AR31: 1.8734238e+08 | AS31: 1.7681504e+08 | AT31: 1.6846715e+08 | AU31: 1.477483e+08 | AV31: 1.3670816e+08 | AW31: 1.2828366e+08 | AX31: 1.1487412e+08 | AY31: 1.0151048e+08
B32: Electricity | C32: 0 | D32: 0 | E32: 0 | F32: 0 | G32: 0 | J32: Buses | K32: Electricity | L32: TB | M32: ELC | O32: =(GETPIVOTDATA("Sum of CY"&$O$17,$B$20,"GPC Sector","Transportation","GPC Sub-sector","On-road","GPC Sub-sector class agg",$J32,"Fuel type",$K32))/10^6 -> 0 | P32: =(GETPIVOTDATA("Sum of CY"&$P$17,$B$20,"GPC Sector","Transportation","GPC Sub-sector","On-road","GPC Sub-sector class agg",$J32,"Fuel type",$K32))/10^6 -> 0 | Q32: =(GETPIVOTDATA("Sum of CY"&$Q$17,$B$20,"GPC Sector","Transportation","GPC Sub-sector","On-road","GPC Sub-sector class agg",$J32,"Fuel type",$K32)+GETPIVOTDATA("Sum of CY"&$Q$16,$B$20,"GPC Sector","Transportation","GPC Sub-sector","On-road","GPC Sub-sector class agg",$J32,"Fuel type",$K32))/2/10^6 -> 0 | R32: =(GETPIVOTDATA("Sum of CY"&$R$17,$B$20,"GPC Sector","Transportation","GPC Sub-sector","On-road","GPC Sub-sector class agg",$J32,"Fuel type",$K32))/10^6 -> 0.023359436 | S32: =IF(Q32+(R32-Q32)*5/2<0,0,Q32+(R32-Q32)*5/2) -> 0.058398589 | T32: =O32/SUMIFS(O:O,$L:$L,$L32) -> 0 | U32: =P32/SUMIFS(P:P,$L:$L,$L32) -> 0 | V32: =Q32/SUMIFS(Q:Q,$L:$L,$L32) -> 0 | W32: =R32/SUMIFS(R:R,$L:$L,$L32) -> 7.0673338e-05 | Y32: Passenger cars(private)Diesel Hybrid | Z32: NYMTC BPM | AA32: Transportation | AB32: On-road | AC32: Passenger cars | AD32: Passenger cars | AE32: (private) | AF32: Diesel Hybrid | AG32: VMT | AH32: 0 | AI32: 0 | AJ32: 0 | AK32: 0 | AL32: 0 | AM32: 0 | AN32: 0 | AO32: 0 | AP32: 0 | AQ32: 0 | AR32: 0 | AS32: 0 | AT32: 0 | AU32: 0 | AV32: 0 | AW32: 0 | AX32: 0 | AY32: 0
B33: Gasoline | C33: 0 | D33: 0 | E33: 7804870.5 | F33: 11900923 | G33: 14264597 | J33: Buses | K33: Gasoline | L33: TB | M33: GSL | N33: GSLAH | O33: =(GETPIVOTDATA("Sum of CY"&$O$17,$B$20,"GPC Sector","Transportation","GPC Sub-sector","On-road","GPC Sub-sector class agg",$J33,"Fuel type",$K33))/10^6 -> 0 | P33: =(GETPIVOTDATA("Sum of CY"&$P$17,$B$20,"GPC Sector","Transportation","GPC Sub-sector","On-road","GPC Sub-sector class agg",$J33,"Fuel type",$K33))/10^6 -> 0 | Q33: =(GETPIVOTDATA("Sum of CY"&$Q$17,$B$20,"GPC Sector","Transportation","GPC Sub-sector","On-road","GPC Sub-sector class agg",$J33,"Fuel type",$K33)+GETPIVOTDATA("Sum of CY"&$Q$16,$B$20,"GPC Sector","Transportation","GPC Sub-sector","On-road","GPC Sub-sector class agg",$J33,"Fuel type",$K33))/2/10^6 -> 34.497734 | R33: =(GETPIVOTDATA("Sum of CY"&$R$17,$B$20,"GPC Sector","Transportation","GPC Sub-sector","On-road","GPC Sub-sector class agg",$J33,"Fuel type",$K33))/10^6 -> 50.75873 | S33: =IF(Q33+(R33-Q33)*5/2<0,0,Q33+(R33-Q33)*5/2) -> 75.150223 | T33: =O33/SUMIFS(O:O,$L:$L,$L33) -> 0 | U33: =P33/SUMIFS(P:P,$L:$L,$L33) -> 0 | V33: =Q33/SUMIFS(Q:Q,$L:$L,$L33) -> 0.10890453 | W33: =R33/SUMIFS(R:R,$L:$L,$L33) -> 0.15356916 | Y33: Passenger cars(private)Electricity | Z33: NYMTC BPM | AA33: Transportation | AB33: On-road | AC33: Passenger cars | AD33: Passenger cars | AE33: (private) | AF33: Electricity | AG33: VMT | AH33: 5.1605221e+08 | AI33: 4.2124991e+08 | AJ33: 2.9089884e+08 | AK33: 3.0556262e+08 | AL33: 2.2896976e+08 | AM33: 1.5384059e+08 | AN33: 84861122 | AO33: 0 | AP33: 0 | AQ33: 0 | AR33: 0 | AS33: 0 | AT33: 0 | AU33: 0 | AV33: 0 | AW33: 0 | AX33: 0 | AY33: 0
B34: Medium duty trucks | C34: 4.9545061e+08 | D34: 5.410366e+08 | E34: 5.8689299e+08 | F34: 5.502082e+08 | G34: 5.9262208e+08 | J34: Buses | K34: CNG | L34: TB | M34: CNG | O34: =(GETPIVOTDATA("Sum of CY"&$O$17,$B$20,"GPC Sector","Transportation","GPC Sub-sector","On-road","GPC Sub-sector class agg",$J34,"Fuel type",$K34))/10^6 -> 37.590232 | P34: =(GETPIVOTDATA("Sum of CY"&$P$17,$B$20,"GPC Sector","Transportation","GPC Sub-sector","On-road","GPC Sub-sector class agg",$J34,"Fuel type",$K34))/10^6 -> 40.318337 | Q34: =(GETPIVOTDATA("Sum of CY"&$Q$17,$B$20,"GPC Sector","Transportation","GPC Sub-sector","On-road","GPC Sub-sector class agg",$J34,"Fuel type",$K34)+GETPIVOTDATA("Sum of CY"&$Q$16,$B$20,"GPC Sector","Transportation","GPC Sub-sector","On-road","GPC Sub-sector class agg",$J34,"Fuel type",$K34))/2/10^6 -> 31.749594 | R34: =(GETPIVOTDATA("Sum of CY"&$R$17,$B$20,"GPC Sector","Transportation","GPC Sub-sector","On-road","GPC Sub-sector class agg",$J34,"Fuel type",$K34))/10^6 -> 43.719634 | S34: =IF(Q34+(R34-Q34)*5/2<0,0,Q34+(R34-Q34)*5/2) -> 61.674693 | T34: =O34/SUMIFS(O:O,$L:$L,$L34) -> 0.1036051 | U34: =P34/SUMIFS(P:P,$L:$L,$L34) -> 0.1128798 | V34: =Q34/SUMIFS(Q:Q,$L:$L,$L34) -> 0.10022904 | W34: =R34/SUMIFS(R:R,$L:$L,$L34) -> 0.13227256 | Y34: Passenger cars(private)Fuel Cell | Z34: NYMTC BPM | AA34: Transportation | AB34: On-road | AC34: Passenger cars | AD34: Passenger cars | AE34: (private) | AF34: Fuel Cell | AG34: VMT | AH34: 0 | AI34: 0 | AJ34: 0 | AK34: 0 | AL34: 0 | AM34: 0 | AN34: 0 | AO34: 0 | AP34: 0 | AQ34: 0 | AR34: 0 | AS34: 0 | AT34: 0 | AU34: 0 | AV34: 0 | AW34: 0 | AX34: 0 | AY34: 0
B35: CNG | C35: 999669.21 | D35: 2185919.8 | E35: 1131591.1 | F35: 479415.07 | G35: 203240.43 | J35: Passenger cars | K35: CNG | L35: TL | M35: CNG | O35: =(GETPIVOTDATA("Sum of CY"&$O$17,$B$20,"GPC Sector","Transportation","GPC Sub-sector","On-road","GPC Sub-sector class agg",$J35,"Fuel type",$K35))/10^6 -> 0 | P35: =(GETPIVOTDATA("Sum of CY"&$P$17,$B$20,"GPC Sector","Transportation","GPC Sub-sector","On-road","GPC Sub-sector class agg",$J35,"Fuel type",$K35))/10^6 -> 0 | Q35: =(GETPIVOTDATA("Sum of CY"&$Q$17,$B$20,"GPC Sector","Transportation","GPC Sub-sector","On-road","GPC Sub-sector class agg",$J35,"Fuel type",$K35)+GETPIVOTDATA("Sum of CY"&$Q$16,$B$20,"GPC Sector","Transportation","GPC Sub-sector","On-road","GPC Sub-sector class agg",$J35,"Fuel type",$K35))/2/10^6 -> 0 | R35: =(GETPIVOTDATA("Sum of CY"&$R$17,$B$20,"GPC Sector","Transportation","GPC Sub-sector","On-road","GPC Sub-sector class agg",$J35,"Fuel type",$K35))/10^6 -> 0 | S35: =IF(Q35+(R35-Q35)*5/2<0,0,Q35+(R35-Q35)*5/2) -> 0 | T35: =O35/SUMIFS(O:O,$L:$L,$L35) -> 0 | U35: =P35/SUMIFS(P:P,$L:$L,$L35) -> 0 | V35: =Q35/SUMIFS(Q:Q,$L:$L,$L35) -> 0 | W35: =R35/SUMIFS(R:R,$L:$L,$L35) -> 0 | Y35: Passenger cars(private)Gasoline | Z35: NYMTC BPM | AA35: Transportation | AB35: On-road | AC35: Passenger cars | AD35: Passenger cars | AE35: (private) | AF35: Gasoline | AG35: VMT | AH35: 1.941655e+10 | AI35: 1.8575339e+10 | AJ35: 1.5425812e+10 | AK35: 2.0215104e+10 | AL35: 2.0000031e+10 | AM35: 1.9586529e+10 | AN35: 1.9592916e+10 | AO35: 1.92342e+10 | AP35: 1.8617848e+10 | AQ35: 1.8632353e+10 | AR35: 1.8575946e+10 | AS35: 1.8811296e+10 | AT35: 1.9330346e+10 | AU35: 1.839386e+10 | AV35: 1.8596344e+10 | AW35: 1.922786e+10 | AX35: 1.9165763e+10 | AY35: 1.909094e+10
B36: Diesel | C36: 1.3415595e+08 | D36: 1.5850314e+08 | E36: 96577234 | F36: 55188145 | G36: 40405224 | J36: Passenger cars | K36: Diesel | L36: TL | M36: DSL | N36: DHEV | O36: =(GETPIVOTDATA("Sum of CY"&$O$17,$B$20,"GPC Sector","Transportation","GPC Sub-sector","On-road","GPC Sub-sector class agg",$J36,"Fuel type",$K36))/10^6 -> 168.46715 | P36: =(GETPIVOTDATA("Sum of CY"&$P$17,$B$20,"GPC Sector","Transportation","GPC Sub-sector","On-road","GPC Sub-sector class agg",$J36,"Fuel type",$K36))/10^6 -> 233.73521 | Q36: =(GETPIVOTDATA("Sum of CY"&$Q$17,$B$20,"GPC Sector","Transportation","GPC Sub-sector","On-road","GPC Sub-sector class agg",$J36,"Fuel type",$K36)+GETPIVOTDATA("Sum of CY"&$Q$16,$B$20,"GPC Sector","Transportation","GPC Sub-sector","On-road","GPC Sub-sector class agg",$J36,"Fuel type",$K36))/2/10^6 -> 166.58711 | R36: =(GETPIVOTDATA("Sum of CY"&$R$17,$B$20,"GPC Sector","Transportation","GPC Sub-sector","On-road","GPC Sub-sector class agg",$J36,"Fuel type",$K36))/10^6 -> 136.39804 | S36: =IF(Q36+(R36-Q36)*5/2<0,0,Q36+(R36-Q36)*5/2) -> 91.114447 | T36: =O36/SUMIFS(O:O,$L:$L,$L36) -> 0.0085703245 | U36: =P36/SUMIFS(P:P,$L:$L,$L36) -> 0.011887125 | V36: =Q36/SUMIFS(Q:Q,$L:$L,$L36) -> 0.0079874655 | W36: =R36/SUMIFS(R:R,$L:$L,$L36) -> 0.0063965792 | Y36: Passenger cars(private)Gasoline Hybrid | Z36: NYMTC BPM | AA36: Transportation | AB36: On-road | AC36: Passenger cars | AD36: Passenger cars | AE36: (private) | AF36: Gasoline Hybrid | AG36: VMT | AH36: 1.1234244e+09 | AI36: 9.2239951e+08 | AJ36: 6.4207891e+08 | AK36: 6.8232775e+08 | AL36: 5.2082815e+08 | AM36: 3.6201683e+08 | AN36: 2.1696355e+08 | AO36: 73260466 | AP36: 63748539 | AQ36: 56644696 | AR36: 49357650 | AS36: 42793719 | AT36: 36603697 | AU36: 27832626 | AV36: 21080315 | AW36: 0 | AX36: 0 | AY36: 0
B37: Electricity | C37: 0 | D37: 0 | E37: 3511328.2 | F37: 5024920.7 | G37: 6314706.8 | J37: Passenger cars | K37: Diesel Hybrid | L37: TL | M37: DHEV | O37: =(GETPIVOTDATA("Sum of CY"&$O$17,$B$20,"GPC Sector","Transportation","GPC Sub-sector","On-road","GPC Sub-sector class agg",$J37,"Fuel type",$K37))/10^6 -> 0 | P37: =(GETPIVOTDATA("Sum of CY"&$P$17,$B$20,"GPC Sector","Transportation","GPC Sub-sector","On-road","GPC Sub-sector class agg",$J37,"Fuel type",$K37))/10^6 -> 0 | Q37: =(GETPIVOTDATA("Sum of CY"&$Q$17,$B$20,"GPC Sector","Transportation","GPC Sub-sector","On-road","GPC Sub-sector class agg",$J37,"Fuel type",$K37)+GETPIVOTDATA("Sum of CY"&$Q$16,$B$20,"GPC Sector","Transportation","GPC Sub-sector","On-road","GPC Sub-sector class agg",$J37,"Fuel type",$K37))/2/10^6 -> 0 | R37: =(GETPIVOTDATA("Sum of CY"&$R$17,$B$20,"GPC Sector","Transportation","GPC Sub-sector","On-road","GPC Sub-sector class agg",$J37,"Fuel type",$K37))/10^6 -> 0 | S37: =IF(Q37+(R37-Q37)*5/2<0,0,Q37+(R37-Q37)*5/2) -> 0 | T37: =O37/SUMIFS(O:O,$L:$L,$L37) -> 0 | U37: =P37/SUMIFS(P:P,$L:$L,$L37) -> 0 | V37: =Q37/SUMIFS(Q:Q,$L:$L,$L37) -> 0 | W37: =R37/SUMIFS(R:R,$L:$L,$L37) -> 0 | Y37: Passenger cars(public)Diesel | Z37: NYMTC BPM | AA37: Transportation | AB37: On-road | AC37: Passenger cars | AD37: Passenger cars | AE37: (public) | AF37: Diesel | AG37: VMT | AH37: 703039.39 | AI37: 570519.24 | AJ37: 390768.72 | AK37: 405511.25 | AL37: 297871.47 | AM37: 192538.86 | AN37: 0 | AO37: 0 | AP37: 0 | AQ37: 0 | AR37: 0 | AS37: 0 | AT37: 0 | AU37: 0 | AV37: 0 | AW37: 0 | AX37: 0 | AY37: 0
B38: Gasoline | C38: 3.6029499e+08 | D38: 3.8034755e+08 | E38: 4.8463779e+08 | F38: 4.8806017e+08 | G38: 5.4386975e+08 | J38: Passenger cars | K38: Electricity | L38: TL | M38: ELC | O38: =(GETPIVOTDATA("Sum of CY"&$O$17,$B$20,"GPC Sector","Transportation","GPC Sub-sector","On-road","GPC Sub-sector class agg",$J38,"Fuel type",$K38))/10^6 -> 0.90905831 | P38: =(GETPIVOTDATA("Sum of CY"&$P$17,$B$20,"GPC Sector","Transportation","GPC Sub-sector","On-road","GPC Sub-sector class agg",$J38,"Fuel type",$K38))/10^6 -> 1.8133946 | Q38: =(GETPIVOTDATA("Sum of CY"&$Q$17,$B$20,"GPC Sector","Transportation","GPC Sub-sector","On-road","GPC Sub-sector class agg",$J38,"Fuel type",$K38)+GETPIVOTDATA("Sum of CY"&$Q$16,$B$20,"GPC Sector","Transportation","GPC Sub-sector","On-road","GPC Sub-sector class agg",$J38,"Fuel type",$K38))/2/10^6 -> 381.67212 | R38: =(GETPIVOTDATA("Sum of CY"&$R$17,$B$20,"GPC Sector","Transportation","GPC Sub-sector","On-road","GPC Sub-sector class agg",$J38,"Fuel type",$K38))/10^6 -> 541.56249 | S38: =IF(Q38+(R38-Q38)*5/2<0,0,Q38+(R38-Q38)*5/2) -> 781.39806 | T38: =O38/SUMIFS(O:O,$L:$L,$L38) -> 4.6245957e-05 | U38: =P38/SUMIFS(P:P,$L:$L,$L38) -> 9.2224224e-05 | V38: =Q38/SUMIFS(Q:Q,$L:$L,$L38) -> 0.018300293 | W38: =R38/SUMIFS(R:R,$L:$L,$L38) -> 0.025397339 | Y38: Passenger cars(public)Electricity | Z38: NYMTC BPM | AA38: Transportation | AB38: On-road | AC38: Passenger cars | AD38: Passenger cars | AE38: (public) | AF38: Electricity | AG38: VMT | AH38: 25510287 | AI38: 20967448 | AJ38: 14616172 | AK38: 15564262 | AL38: 11918473 | AM38: 8331686 | AN38: 5058829.9 | AO38: 1813394.6 | AP38: 1583208.3 | AQ38: 1406782.3 | AR38: 1225806.5 | AS38: 1062789.4 | AT38: 909058.31 | AU38: 726947.08 | AV38: 550585.47 | AW38: 379090.94 | AX38: 188719.02 | AY38: 0
B39: Gasoline Hybrid | C39: 0 | D39: 0 | E39: 1035046.9 | F39: 1455552.6 | G39: 1829163.9 | J39: Passenger cars | K39: Fuel Cell | L39: TL | M39: FCH | O39: =(GETPIVOTDATA("Sum of CY"&$O$17,$B$20,"GPC Sector","Transportation","GPC Sub-sector","On-road","GPC Sub-sector class agg",$J39,"Fuel type",$K39))/10^6 -> 0 | P39: =(GETPIVOTDATA("Sum of CY"&$P$17,$B$20,"GPC Sector","Transportation","GPC Sub-sector","On-road","GPC Sub-sector class agg",$J39,"Fuel type",$K39))/10^6 -> 0 | Q39: =(GETPIVOTDATA("Sum of CY"&$Q$17,$B$20,"GPC Sector","Transportation","GPC Sub-sector","On-road","GPC Sub-sector class agg",$J39,"Fuel type",$K39)+GETPIVOTDATA("Sum of CY"&$Q$16,$B$20,"GPC Sector","Transportation","GPC Sub-sector","On-road","GPC Sub-sector class agg",$J39,"Fuel type",$K39))/2/10^6 -> 0 | R39: =(GETPIVOTDATA("Sum of CY"&$R$17,$B$20,"GPC Sector","Transportation","GPC Sub-sector","On-road","GPC Sub-sector class agg",$J39,"Fuel type",$K39))/10^6 -> 0 | S39: =IF(Q39+(R39-Q39)*5/2<0,0,Q39+(R39-Q39)*5/2) -> 0 | T39: =O39/SUMIFS(O:O,$L:$L,$L39) -> 0 | U39: =P39/SUMIFS(P:P,$L:$L,$L39) -> 0 | V39: =Q39/SUMIFS(Q:Q,$L:$L,$L39) -> 0 | W39: =R39/SUMIFS(R:R,$L:$L,$L39) -> 0 | Y39: Passenger cars(public)Gasoline | Z39: NYMTC BPM | AA39: Transportation | AB39: On-road | AC39: Passenger cars | AD39: Passenger cars | AE39: (public) | AF39: Gasoline | AG39: VMT | AH39: 60193563 | AI39: 64760164 | AJ39: 59615495 | AK39: 85616592 | AL39: 91969012 | AM39: 97039031 | AN39: 1.0390693e+08 | AO39: 1.0858461e+08 | AP39: 1.0625847e+08 | AQ39: 1.074871e+08 | AR39: 1.0830146e+08 | AS39: 1.1082517e+08 | AT39: 1.1506377e+08 | AU39: 1.1632625e+08 | AV39: 1.1879588e+08 | AW39: 1.2405676e+08 | AX39: 1.2487605e+08 | AY39: 1.2560096e+08
B40: Passenger cars | C40: 1.9657033e+10 | D40: 1.9662888e+10 | E40: 2.1523925e+10 | F40: 2.0188206e+10 | G40: 2.1323592e+10 | J40: Passenger cars | K40: Gasoline | L40: TL | M40: GSL | N40: G*HEV | O40: =(GETPIVOTDATA("Sum of CY"&$O$17,$B$20,"GPC Sector","Transportation","GPC Sub-sector","On-road","GPC Sub-sector class agg",$J40,"Fuel type",$K40))/10^6 -> 19445.41 | P40: =(GETPIVOTDATA("Sum of CY"&$P$17,$B$20,"GPC Sector","Transportation","GPC Sub-sector","On-road","GPC Sub-sector class agg",$J40,"Fuel type",$K40))/10^6 -> 19342.785 | Q40: =(GETPIVOTDATA("Sum of CY"&$Q$17,$B$20,"GPC Sector","Transportation","GPC Sub-sector","On-road","GPC Sub-sector class agg",$J40,"Fuel type",$K40)+GETPIVOTDATA("Sum of CY"&$Q$16,$B$20,"GPC Sector","Transportation","GPC Sub-sector","On-road","GPC Sub-sector class agg",$J40,"Fuel type",$K40))/2/10^6 -> 19470.41 | R40: =(GETPIVOTDATA("Sum of CY"&$R$17,$B$20,"GPC Sector","Transportation","GPC Sub-sector","On-road","GPC Sub-sector class agg",$J40,"Fuel type",$K40))/10^6 -> 19476.743 | S40: =IF(Q40+(R40-Q40)*5/2<0,0,Q40+(R40-Q40)*5/2) -> 19486.244 | T40: =O40/SUMIFS(O:O,$L:$L,$L40) -> 0.98923424 | U40: =P40/SUMIFS(P:P,$L:$L,$L40) -> 0.98372044 | V40: =Q40/SUMIFS(Q:Q,$L:$L,$L40) -> 0.93356102 | W40: =R40/SUMIFS(R:R,$L:$L,$L40) -> 0.91338944 | Y40: Passenger cars(public)Gasoline Hybrid | Z40: NYMTC BPM | AA40: Transportation | AB40: On-road | AC40: Passenger cars | AD40: Passenger cars | AE40: (public) | AF40: Gasoline Hybrid | AG40: VMT | AH40: 45463214 | AI40: 38548714 | AJ40: 27990497 | AK40: 31516999 | AL40: 26175605 | AM40: 20829477 | AN40: 16124534 | AO40: 11294162 | AP40: 9827839.5 | AQ40: 8732667.2 | AR40: 7609251.2 | AS40: 6597314.8 | AT40: 5643022 | AU40: 4512558 | AV40: 3417785.1 | AW40: 2353224.7 | AX40: 1171482.1 | AY40: 0
B41: CNG | C41: 0 | D41: 0 | E41: 0 | F41: 0 | G41: 0 | J41: Passenger cars | K41: Gasoline Hybrid | L41: TL | M41: G*HEV | O41: =(GETPIVOTDATA("Sum of CY"&$O$17,$B$20,"GPC Sector","Transportation","GPC Sub-sector","On-road","GPC Sub-sector class agg",$J41,"Fuel type",$K41))/10^6 -> 42.246719 | P41: =(GETPIVOTDATA("Sum of CY"&$P$17,$B$20,"GPC Sector","Transportation","GPC Sub-sector","On-road","GPC Sub-sector class agg",$J41,"Fuel type",$K41))/10^6 -> 84.554628 | Q41: =(GETPIVOTDATA("Sum of CY"&$Q$17,$B$20,"GPC Sector","Transportation","GPC Sub-sector","On-road","GPC Sub-sector class agg",$J41,"Fuel type",$K41)+GETPIVOTDATA("Sum of CY"&$Q$16,$B$20,"GPC Sector","Transportation","GPC Sub-sector","On-road","GPC Sub-sector class agg",$J41,"Fuel type",$K41))/2/10^6 -> 837.39649 | R41: =(GETPIVOTDATA("Sum of CY"&$R$17,$B$20,"GPC Sector","Transportation","GPC Sub-sector","On-road","GPC Sub-sector class agg",$J41,"Fuel type",$K41))/10^6 -> 1168.8876 | S41: =IF(Q41+(R41-Q41)*5/2<0,0,Q41+(R41-Q41)*5/2) -> 1666.1243 | T41: =O41/SUMIFS(O:O,$L:$L,$L41) -> 0.002149191 | U41: =P41/SUMIFS(P:P,$L:$L,$L41) -> 0.004300214 | V41: =Q41/SUMIFS(Q:Q,$L:$L,$L41) -> 0.040151221 | W41: =R41/SUMIFS(R:R,$L:$L,$L41) -> 0.054816639 | Y41: School Bus(private)Diesel | Z41: NYMTC BPM | AA41: Transportation | AB41: On-road | AC41: School Bus | AD41: Buses | AE41: (private) | AF41: Diesel | AG41: VMT | AH41: 27085733 | AI41: 33218126 | AJ41: 39431287 | AK41: 45357985 | AL41: 51012827 | AM41: 56388434 | AN41: 61478026 | AO41: 66295314 | AP41: 64796685 | AQ41: 63298056 | AR41: 61799427 | AS41: 60300798 | AT41: 58802169 | AU41: 57303540 | AV41: 55804912 | AW41: 54306283 | AX41: 52807654 | AY41: 51309025
