Workbook

Sheet GHG-SUP
C2: ~TFM_INS
C3: TimeSlice | D3: LimType | E3: Attribute | F3: Year | G3: Other_Indexes | H3: Pset_PN | I3: PSET_CI | J3: PSET_CO | K3: Pset_PD | L3: Cset_CN | M3: AllRegions | N3: R0 | O3: R1 | P3: R2 | Q3: R3 | R3: R4 | S3: R5 | T3: R6
E4: FLO_EMIS | F4: 2010 | G4: ACT | H4: ="SEC"&J4 -> SECC* | J4: C* | L4: CO2 | N4: =#REF! -> #REF!
E5: FLO_EMIS | F5: 2015 | G5: ACT | H5: ="SEC"&J5 -> SECC* | J5: C* | L5: CO2 | N5: =N4 -> #REF!
E6: FLO_EMIS | F6: 2020 | G6: ACT | H6: ="SEC"&J6 -> SECC* | J6: C* | L6: CO2 | N6: =N5 -> #REF!
E7: FLO_EMIS | F7: 2055 | G7: ACT | H7: ="SEC"&J7 -> SECC* | J7: C* | L7: CO2 | N7: =N6 -> #REF!
E8: FLO_EMIS | F8: 2010 | G8: ACT | H8: ="SEC"&J8 -> SECC* | J8: C* | L8: VOC | N8: =#REF! -> #REF!
E9: FLO_EMIS | F9: 2015 | G9: ACT | H9: ="SEC"&J9 -> SECC* | J9: C* | L9: VOC | N9: =N8 -> #REF!
E10: FLO_EMIS | F10: 2020 | G10: ACT | H10: ="SEC"&J10 -> SECC* | J10: C* | L10: VOC | N10: =N9 -> #REF!
E11: FLO_EMIS | F11: 2055 | G11: ACT | H11: ="SEC"&J11 -> SECC* | J11: C* | L11: VOC | N11: =N10 -> #REF!
E12: FLO_EMIS | F12: 2010 | G12: ACT | H12: ="SEC"&J12 -> SECC* | J12: C* | L12: CO | N12: =#REF! -> #REF!
E13: FLO_EMIS | F13: 2015 | G13: ACT | H13: ="SEC"&J13 -> SECC* | J13: C* | L13: CO | N13: =N12 -> #REF!
E14: FLO_EMIS | F14: 2020 | G14: ACT | H14: ="SEC"&J14 -> SECC* | J14: C* | L14: CO | N14: =N13 -> #REF!
E15: FLO_EMIS | F15: 2055 | G15: ACT | H15: ="SEC"&J15 -> SECC* | J15: C* | L15: CO | N15: =N14 -> #REF!
E16: FLO_EMIS | F16: 2010 | G16: ACT | H16: ="SEC"&J16 -> SECC* | J16: C* | L16: NOX | N16: =#REF! -> #REF!
E17: FLO_EMIS | F17: 2015 | G17: ACT | H17: ="SEC"&J17 -> SECC* | J17: C* | L17: NOX | N17: =N16 -> #REF!
E18: FLO_EMIS | F18: 2020 | G18: ACT | H18: ="SEC"&J18 -> SECC* | J18: C* | L18: NOX | N18: =N17 -> #REF!
E19: FLO_EMIS | F19: 2055 | G19: ACT | H19: ="SEC"&J19 -> SECC* | J19: C* | L19: NOX | N19: =N18 -> #REF!
E20: FLO_EMIS | F20: 2010 | G20: ACT | H20: ="SEC"&J20 -> SECC* | J20: C* | L20: PM10 | N20: =#REF! -> #REF!
E21: FLO_EMIS | F21: 2015 | G21: ACT | H21: ="SEC"&J21 -> SECC* | J21: C* | L21: PM10 | N21: =N20 -> #REF!
E22: FLO_EMIS | F22: 2020 | G22: ACT | H22: ="SEC"&J22 -> SECC* | J22: C* | L22: PM10 | N22: =N21 -> #REF!
E23: FLO_EMIS | F23: 2055 | G23: ACT | H23: ="SEC"&J23 -> SECC* | J23: C* | L23: PM10 | N23: =N22 -> #REF!
E24: FLO_EMIS | F24: 2010 | G24: ACT | H24: ="SEC"&J24 -> SECC* | J24: C* | L24: PM25 | N24: =#REF! -> #REF!
E25: FLO_EMIS | F25: 2015 | G25: ACT | H25: ="SEC"&J25 -> SECC* | J25: C* | L25: PM25 | N25: =N24 -> #REF!
E26: FLO_EMIS | F26: 2020 | G26: ACT | H26: ="SEC"&J26 -> SECC* | J26: C* | L26: PM25 | N26: =N25 -> #REF!
E27: FLO_EMIS | F27: 2055 | G27: ACT | H27: ="SEC"&J27 -> SECC* | J27: C* | L27: PM25 | N27: =N26 -> #REF!
E28: FLO_EMIS | F28: 2010 | G28: ACT | H28: ="SEC"&J28 -> SECC* | J28: C* | L28: SO2 | N28: =#REF! -> #REF!
E29: FLO_EMIS | F29: 2015 | G29: ACT | H29: ="SEC"&J29 -> SECC* | J29: C* | L29: SO2 | N29: =N28 -> #REF!
E30: FLO_EMIS | F30: 2020 | G30: ACT | H30: ="SEC"&J30 -> SECC* | J30: C* | L30: SO2 | N30: =N29 -> #REF!
E31: FLO_EMIS | F31: 2055 | G31: ACT | H31: ="SEC"&J31 -> SECC* | J31: C* | L31: SO2 | N31: =N30 -> #REF!
E32: FLO_EMIS | F32: 2010 | G32: ACT | H32: ="SEC"&J32 -> SECC* | J32: C* | L32: CH4 | N32: =#REF! -> #REF!
E33: FLO_EMIS | F33: 2015 | G33: ACT | H33: ="SEC"&J33 -> SECC* | J33: C* | L33: CH4 | N33: =N32 -> #REF!
E34: FLO_EMIS | F34: 2020 | G34: ACT | H34: ="SEC"&J34 -> SECC* | J34: C* | L34: CH4 | N34: =N33 -> #REF!
E35: FLO_EMIS | F35: 2055 | G35: ACT | H35: ="SEC"&J35 -> SECC* | J35: C* | L35: CH4 | N35: =N34 -> #REF!
E36: FLO_EMIS | F36: 2010 | G36: ACT | H36: ="SEC"&J36 -> SECC* | J36: C* | L36: N2O | N36: =#REF! -> #REF!
E37: FLO_EMIS | F37: 2015 | G37: ACT | H37: ="SEC"&J37 -> SECC* | J37: C* | L37: N2O | N37: =N36 -> #REF!
E38: FLO_EMIS | F38: 2020 | G38: ACT | H38: ="SEC"&J38 -> SECC* | J38: C* | L38: N2O | N38: =N37 -> #REF!
E39: FLO_EMIS | F39: 2055 | G39: ACT | H39: ="SEC"&J39 -> SECC* | J39: C* | L39: N2O | N39: =N38 -> #REF!
E40: FLO_EMIS | F40: 2010 | G40: ACT | H40: ="SEC"&J40 -> SECC* | J40: C* | L40: OC | N40: =#REF! -> #REF!
E41: FLO_EMIS | F41: 2015 | G41: ACT | H41: ="SEC"&J41 -> SECC* | J41: C* | L41: OC | N41: =N40 -> #REF!
...

Sheet GHG-ELC
C2: ~TFM_INS
C3: TimeSlice | D3: LimType | E3: Attribute | F3: Year | G3: Other_Indexes | H3: Pset_PN | I3: PSET_CI | J3: PSET_CO | K3: Pset_PD | L3: Cset_CN | M3: AllRegions | N3: R0 | O3: R1 | P3: R2 | Q3: R3 | R3: R4 | S3: R5 | T3: R6
E4: FLO_EMIS | G4: ACT | H4: SECSTBHFGO | L4: SO2 | O4: ='Retrofit - ELC'!C6-'Retrofit - ELC'!$D$6 -> -1.1268508
E5: FLO_EMIS | G5: ACT | H5: SECSTBMFGO | L5: SO2 | O5: ='Retrofit - ELC'!$E$6-'Retrofit - ELC'!$F$6 -> -0.50478579
E6: FLO_EMIS | G6: ACT | H6: SECSTBLFGO | L6: SO2 | O6: ='Retrofit - ELC'!$G$6-'Retrofit - ELC'!$H$6 -> -0.14010986
E7: FLO_EMIS | G7: ACT | H7: SECSTSMFGO | L7: SO2 | O7: ='Retrofit - ELC'!$E$12-'Retrofit - ELC'!$F$12 -> -0.34112163
E8: FLO_EMIS | G8: ACT | H8: SECSTSLFGO | L8: SO2 | O8: ='Retrofit - ELC'!$G$12-'Retrofit - ELC'!$H$12 -> -0.19686958
E9: FLO_EMIS | G9: ACT | H9: SECSTLHFGO | L9: SO2 | O9: ='Retrofit - ELC'!$C$18-'Retrofit - ELC'!$D$18 -> -0.91646048
E10: FLO_EMIS | G10: ACT | H10: SECSTLMFGO | L10: SO2 | O10: ='Retrofit - ELC'!$E$18-'Retrofit - ELC'!$F$18 -> -0.63448162
E11: FLO_EMIS | G11: ACT | H11: SECSTBHFGU | L11: SO2 | O11: ='Retrofit - ELC'!$C$6-'Retrofit - ELC'!$D$6 -> -1.1268508
E12: FLO_EMIS | G12: ACT | H12: SECSTBMFGU | L12: SO2 | O12: ='Retrofit - ELC'!$E$6-'Retrofit - ELC'!$F$6 -> -0.50478579
E13: FLO_EMIS | G13: ACT | H13: SECSTBLFGU | L13: SO2 | O13: ='Retrofit - ELC'!$G$6-'Retrofit - ELC'!$H$6 -> -0.14010986
E14: FLO_EMIS | G14: ACT | H14: SECSTSMFGU | L14: SO2 | O14: ='Retrofit - ELC'!$E$12-'Retrofit - ELC'!$F$12 -> -0.34112163
E15: FLO_EMIS | G15: ACT | H15: SECSTSLFGU | L15: SO2 | O15: ='Retrofit - ELC'!$G$12-'Retrofit - ELC'!$H$12 -> -0.19686958
E16: FLO_EMIS | G16: ACT | H16: SECSTLHFGU | L16: SO2 | O16: ='Retrofit - ELC'!$C$18-'Retrofit - ELC'!$D$18 -> -0.91646048
E17: FLO_EMIS | G17: ACT | H17: SECSTLMFGU | L17: SO2 | O17: ='Retrofit - ELC'!$E$18-'Retrofit - ELC'!$F$18 -> -0.63448162
E18: FLO_EMIS | G18: ACT | H18: SECSTBHFGO | L18: SO2E | O18: =O4 -> -1.1268508
E19: FLO_EMIS | G19: ACT | H19: SECSTBMFGO | L19: SO2E | O19: =O5 -> -0.50478579
E20: FLO_EMIS | G20: ACT | H20: SECSTBLFGO | L20: SO2E | O20: =O6 -> -0.14010986
E21: FLO_EMIS | G21: ACT | H21: SECSTSMFGO | L21: SO2E | O21: =O7 -> -0.34112163
E22: FLO_EMIS | G22: ACT | H22: SECSTSLFGO | L22: SO2E | O22: =O8 -> -0.19686958
E23: FLO_EMIS | G23: ACT | H23: SECSTLHFGO | L23: SO2E | O23: =O9 -> -0.91646048
E24: FLO_EMIS | G24: ACT | H24: SECSTLMFGO | L24: SO2E | O24: =O10 -> -0.63448162
E25: FLO_EMIS | G25: ACT | H25: SECSTBHFGU | L25: SO2E | O25: =O11 -> -1.1268508
E26: FLO_EMIS | G26: ACT | H26: SECSTBMFGU | L26: SO2E | O26: =O12 -> -0.50478579
E27: FLO_EMIS | G27: ACT | H27: SECSTBLFGU | L27: SO2E | O27: =O13 -> -0.14010986
E28: FLO_EMIS | G28: ACT | H28: SECSTSMFGU | L28: SO2E | O28: =O14 -> -0.34112163
E29: FLO_EMIS | G29: ACT | H29: SECSTSLFGU | L29: SO2E | O29: =O15 -> -0.19686958
... E31: FLO_EMIS | G31: ACT | H31: SECSTLMFGU | L31: SO2E | O31: =O17 -> -0.63448162
E32: FLO_EMIS | G32: ACT | H32: SECSTBLNBO | L32: NOX | O32: ='Retrofit - ELC'!$D$25-'Retrofit - ELC'!$C$25 -> -0.1164154
E33: FLO_EMIS | G33: ACT | H33: SECSTBSCRO | L33: NOX | O33: ='Retrofit - ELC'!$E$25-'Retrofit - ELC'!$D$25 -> -0.1822319
E34: FLO_EMIS | G34: ACT | H34: SECSTBSNCO | L34: NOX | O34: ='Retrofit - ELC'!$F$25-'Retrofit - ELC'!$D$25 -> -0.11061362
E35: FLO_EMIS | G35: ACT | H35: SECSTBSC2O | L35: NOX | O35: ='Retrofit - ELC'!$G$25-'Retrofit - ELC'!$C$25 -> -0.26973369
E36: FLO_EMIS | G36: ACT | H36: SECSTBSN2O | L36: NOX | O36: ='Retrofit - ELC'!$H$25-'Retrofit - ELC'!$C$25 -> -0.15474498
E37: FLO_EMIS | G37: ACT | H37: SECSTBLS2O | L37: NOX | O37: ='Retrofit - ELC'!$I$25-'Retrofit - ELC'!$C$25 -> -0.30039735
E38: FLO_EMIS | G38: ACT | H38: SECSTBLN2O | L38: NOX | O38: ='Retrofit - ELC'!$J$25-'Retrofit - ELC'!$C$25 -> -0.23140412
E39: FLO_EMIS | G39: ACT | H39: SECSTSLNBO | L39: NOX | O39: ='Retrofit - ELC'!$D$30-'Retrofit - ELC'!$C$30 -> -0.14308236
E40: FLO_EMIS | G40: ACT | H40: SECSTSSCRO | L40: NOX | O40: ='Retrofit - ELC'!$E$30-'Retrofit - ELC'!$D$30 -> -0.17732445
E41: FLO_EMIS | G41: ACT | H41: SECSTSSNCO | L41: NOX | O41: ='Retrofit - ELC'!$F$30-'Retrofit - ELC'!$D$30 -> -0.13134727
E42: FLO_EMIS | G42: ACT | H42: SECSTSSC2O | L42: NOX | O42: ='Retrofit - ELC'!$G$30-'Retrofit - ELC'!$C$30 -> -0.28173297
...

Sheet Emissions - REF
A1: Updated emission factor from GREET(Beta), dated Dec 21st, 2012
A2: Refinery emissions per unit outputs
A4: Conventional gasoline, onsite emissions (kT/PJ)
B5: 2005 | C5: 2010 | D5: 2015 | E5: 2020
A6: VOC | B6: 0.002354489 | C6: 0.002323298 | D6: 0.002323298 | E6: 0.002323298
A7: CO | B7: 0.004303286 | C7: 0.003558378 | D7: 0.003558378 | E7: 0.003558378
A8: NOx | B8: 0.009465847 | C8: 0.008144765 | D8: 0.007228721 | E8: 0.00683861
A9: PM10 | B9: 0.00225246 | C9: 0.001952885 | D9: 0.001736782 | E9: 0.00166413
A10: PM2.5 | B10: 0.001243051 | C10: 0.001086119 | D10: 0.001013099 | E10: 0.000941026
A11: SOx | B11: 0.009231452 | C11: 0.007105053 | D11: 0.006111093 | E11: 0.00568511
A12: CH4 | B12: 0.000186316 | C12: 0.000186316 | D12: 0.000186316 | E12: 0.000186316
A13: N2O | B13: 9.9824e-05 | C13: 9.9824e-05 | D13: 9.9824e-05 | E13: 9.9824e-05
A14: CO2 | B14: 6.1227432 | C14: 6.124011 | D14: 6.124011 | E14: 6.124011
A15: CO2Biogenic | B15: =B42/1000000 -> 0 | C15: =C42/1000000 -> 0 | D15: =D42/1000000 -> 0 | E15: =E42/1000000 -> 0
A17: Reformulated gasoline, onsite Emissions (kT/PJ)
B18: 2005 | C18: 2010 | D18: 2015 | E18: 2020
A19: VOC | B19: 0.002354219 | C19: 0.002323027 | D19: 0.002323027 | E19: 0.002323027
A20: CO | B20: 0.004298525 | C20: 0.003553682 | D20: 0.003553682 | E20: 0.003553682
A21: NOx | B21: 0.009421162 | C21: 0.008107528 | D21: 0.007194463 | E21: 0.006805841
A22: PM10 | B22: 0.002237565 | C22: 0.001939658 | D22: 0.001726355 | E22: 0.001655193
A23: PM2.5 | B23: 0.00123337 | C23: 0.001077521 | D23: 0.001006322 | E23: 0.000935217
A24: SOx | B24: 0.009165232 | C24: 0.007044704 | D24: 0.006050744 | E24: 0.005624762
A25: CH4 | B25: 0.000185351 | C25: 0.000185351 | D25: 0.000185351 | E25: 0.000185351
A26: N2O | B26: 9.9717e-05 | C26: 9.9717e-05 | D26: 9.9717e-05 | E26: 9.9717e-05
A27: CO2 | B27: 6.0990561 | C27: 6.1003237 | D27: 6.1003237 | E27: 6.1003237
A28: CO2Biogenic | B28: 0 | C28: 0 | D28: 0 | E28: 0
A30: Jet fuel, onsite emissions (kT/PJ)
B31: 2005 | C31: 2010 | D31: 2015 | E31: 2020
A32: VOC | B32: 0.000159747 | C32: 0.000130362 | D32: 0.000130362 | E32: 0.000130362
A33: CO | B33: 0.003077782 | C33: 0.002375158 | D33: 0.002375158 | E33: 0.002375158
A34: NOx | B34: 0.008263487 | C34: 0.006917476 | D34: 0.00601345 | E34: 0.005625476
A35: PM10 | B35: 0.002038953 | C35: 0.00173366 | D35: 0.001491726 | E35: 0.001402946
A36: PM2.5 | B36: 0.001158822 | C36: 0.000996048 | D36: 0.000902429 | E36: 0.000821276
A37: SOx | B37: 0.005663935 | C37: 0.003577855 | D37: 0.002640019 | E37: 0.00223809
A38: CH4 | B38: 0.000187993 | C38: 0.000187993 | D38: 0.000187993 | E38: 0.000187993
A39: N2O | B39: 9.244e-05 | C39: 9.244e-05 | D39: 9.244e-05 | E39: 9.244e-05
A40: CO2 | B40: 5.0043131 | C40: 5.0055088 | D40: 5.0055088 | E40: 5.0055088
A41: CO2Biogenic | B41: 0 | C41: 0 | D41: 0 | E41: 0
A43: Conventional diesel, onsite emissions (kT/PJ)
B44: 2005 | C44: 2010 | D44: 2015 | E44: 2020
...

Sheet Retrofit - ELC
B1: Data generated with the EPA/NRMRL/APPCD CUECost spreadsheet model
B3: SOX Control Summary
B4: Bituminous | C4: High Sulfur | E4: Medium Sulfur | G4: Low Sulfur
C5: FGD (SECSTMBHFG) | D5: Pass (SECSTMBHPT) | E5: FGD (SECSTMBMFG) | F5: Pass (SECSTMBMPT) | G5: FGD (SECSTMBLFG) | H5: Pass (SECSTMBLPT)
B6: Equilibrium Emissions Rate (kT/PJ) | C6: 0.059311582 | D6: 1.1861624 | E6: 0.022017182 | F6: 0.52680297 | G6: 0.007384394 | H6: 0.14749425
B7: Capital Cost (m$/PJ/yr) | C7: 2.6322316 | E7: 1.9397894 | G7: 3.1387047
B8: Variable O&M (m$/PJ) | C8: 0.3006257 | E8: 0.21797395 | G8: 0.34990926
B10: Sub-Bituminous | C10: High Sulfur | E10: Medium Sulfur | G10: Low Sulfur
C11: FGD (SECSTMSHFG) | D11: Pass (SECSTMSHPT) | E11: FGD (SECSTMSMFG) | F11: Pass (SECSTMSMPT) | G11: FGD (SECSTMSLFG) | H11: Pass (SECSTMSLPT)
B12: Equilibrium Emissions Rate (kT/PJ) | C12: N/A | D12: N/A | E12: 0.017954111 | F12: 0.35907574 | G12: 0.010354962 | H12: 0.20722455
B13: Capital Cost (m$/PJ/yr) | C13: N/A | E13: 1.8680997 | G13: 2.4832624
B14: Variable O&M (m$/PJ) | C14: N/A | E14: 0.22666376 | G14: 0.25235776
B16: Lignite | C16: High Sulfur | E16: Medium Sulfur | G16: Low Sulfur
C17: FGD (SECSTMLHFG) | D17: Pass (SECSTMLHPT) | E17: FGD (SECSTMLMFG) | F17: Pass (SECSTMLMPT) | G17: FGD | H17: Pass
B18: Equilibrium Emissions Rate (kT/PJ) | C18: 0.048256727 | D18: 0.9647172 | E18: 0.03334584 | F18: 0.66782746 | G18: N/A | H18: N/A
B19: Capital Cost (m$/PJ/yr) | C19: 1.9028621 | E19: 1.7693982 | G19: N/A
B20: Variable O&M (m$/PJ) | C20: 0.23452508 | E20: 0.229388 | G20: N/A
B23: NOX Control Summary | L23: Calculated $/tonne removed
B24: Bituminous | C24: Pass Through (SECSTMBPT/2) | D24: LNB (SECSTMBLNB) | E24: SCR (after LNB, SECSTMBSCR) | F24: SNCR (after LNB, SECSTMBSNC) | G24: SCR only (SECSTMBSC2) | H24: SNCR only (SECSTMBSN2) | I24: LNB-SCR (SECSTMBLS2) | J24: LNB-SNCR (SECSTMBLN2) | L24: LNB (SECSTMBLNB) | M24: SCR (after LNB, SECSTMBSCR) | N24: SNCR (after LNB, SECSTMBSNC) | O24: SCR only (SECSTMBSC2) | P24: SNCR only (SECSTMBSN2) | Q24: LNB-SCR (SECSTMBLS2) | R24: LNB-SNCR (SECSTMBLN2)
B25: Equilibrium Emissions Rate (kT/PJ) | C25: 0.34639283 | D25: 0.22997743 | E25: 0.047745523 | F25: 0.11936381 | G25: 0.076659143 | H25: 0.19164786 | I25: 0.045995486 | J25: 0.11498871 | L25: =(D26+D27)*1000000/((C25-D25)*1000) -> 1835.705 | M25: =(E26+E27)*1000000/((C25-E25)*1000) -> 2727.9428 | N25: =(F26+F27)*1000000/((C25-F25)*1000) -> 545.75321 | O25: =(G26+G27)*1000000/((C25-G25)*1000) -> 3258.9695 | P25: =(H26+H27)*1000000/((C25-H25)*1000) -> 1125.1149 | Q25: =(I26+I27)*1000000/((C25-I25)*1000) -> 3523.2852 | R25: =(J26+J27)*1000000/((C25-J25)*1000) -> 1523.0785
B26: Capital Cost (m$/PJ/yr) | D26: 0.20789446 | E26: 0.66512172 | F26: 0.078552329 | G26: 0.76318038 | H26: 0.10455476 | I26: 0.94847608 | J26: 0.30305871
B27: Variable O&M (m$/PJ) | D27: 0.0058098808 | E27: 0.14957106 | F27: 0.04534949 | G27: 0.11587348 | H27: 0.069551114 | I27: 0.10990944 | J27: 0.049387931
L28: Calculated $/tonne removed
B29: Sub-Bituminous | C29: Pass Through (SECSTMSPT/2) | D29: LNB (SECSTMSLNB) | E29: SCR (after LNB, SECSTMSSCR) | F29: SNCR (after LNB, SECSTMSSNC) | G29: SCR only (SECSTMSSC2) | H29: SNCR only (SECSTMSSN2) | I29: LNB-SCR (SECSTMSLS2) | J29: LNB-SNCR (SECSTMSLN2) | L29: LNB (SECSTMBLNB) | M29: SCR (after LNB, SECSTMBSCR) | N29: SNCR (after LNB, SECSTMBSNC) | O29: SCR only (SECSTMBSC2) | P29: SNCR only (SECSTMBSN2) | Q29: LNB-SCR (SECSTMBLS2) | R29: LNB-SNCR (SECSTMBLN2)
B30: Equilibrium Emissions Rate (kT/PJ) | C30: 0.35105827 | D30: 0.20797591 | E30: 0.030651455 | F30: 0.076628637 | G30: 0.069325303 | H30: 0.17331326 | I30: 0.041595182 | J30: 0.10398795 | L30: =(D31+D32)*1000000/((C30-D30)*1000) -> 1435.0803 | M30: =(E31+E32)*1000000/((C30-E30)*1000) -> 2325.7259 | N30: =(F31+F32)*1000000/((C30-F30)*1000) -> 357.32969 | O30: =(G31+G32)*1000000/((C30-G30)*1000) -> 3105.9962 | P30: =(H31+H32)*1000000/((C30-H30)*1000) -> 900.67535 | Q30: =(I31+I32)*1000000/((C30-I30)*1000) -> 3392.7459 | R30: =(J31+J32)*1000000/((C30-J30)*1000) -> 1351.3962
B31: Capital Cost (m$/PJ/yr) | D31: 0.19951384 | E31: 0.64700165 | F31: 0.069391685 | G31: 0.75678625 | H31: 0.096804473 | I31: 0.93650317 | J31: 0.28827588
B32: Variable O&M (m$/PJ) | D32: 0.0058208355 | E32: 0.098176768 | F32: 0.028670169 | G32: 0.11827527 | H32: 0.063286079 | I32: 0.11342646 | J32: 0.045614005
L33: Calculated $/tonne removed
B34: Lignite | C34: Pass Through (SECSTMLPT/2) | D34: LNB (SECSTMLLNB) | E34: SCR (after LNB, SECSTMLSCR) | F34: SNCR (after LNB, SECSTMLSNC) | G34: SCR only (SECSTMLSC2) | H34: SNCR only (SECSTMLSN2) | I34: LNB-SCR (SECSTMLLS2) | J34: LNB-SNCR (SECSTMLLN2) | L34: LNB (SECSTMBLNB) | M34: SCR (after LNB, SECSTMBSCR) | N34: SNCR (after LNB, SECSTMBSNC) | O34: SCR only (SECSTMBSC2) | P34: SNCR only (SECSTMBSN2) | Q34: LNB-SCR (SECSTMBLS2) | R34: LNB-SNCR (SECSTMBLN2)
B35: Equilibrium Emissions Rate (kT/PJ) | C35: 0.20057923 | D35: 0.12839031 | E35: 0.039226347 | F35: 0.098065867 | G35: 0.042796769 | H35: 0.10699192 | I35: 0.025678061 | J35: 0.064195154 | L35: =(D36+D37)*1000000/((C35-D35)*1000) -> 2296.1831 | M35: =(E36+E37)*1000000/((C35-E35)*1000) -> 4889.6577 | N35: =(F36+F37)*1000000/((C35-F35)*1000) -> 1083.109 | O35: =(G36+G37)*1000000/((C35-G35)*1000) -> 4743.0702 | P35: =(H36+H37)*1000000/((C35-H35)*1000) -> 1143.5103 | Q35: =(I36+I37)*1000000/((C35-I35)*1000) -> 5117.5766 | R35: =(J36+J37)*1000000/((C35-J35)*1000) -> 1856.4064
B36: Capital Cost (m$/PJ/yr) | D36: 0.16097879 | E36: 0.6805863 | F36: 0.075029313 | G36: 0.63922747 | H36: 0.068316629 | I36: 0.78772395 | J36: 0.2242033
B37: Variable O&M (m$/PJ) | D37: 0.0047801848 | E37: 0.10837405 | F37: 0.036003828 | G37: 0.10914581 | H37: 0.038701415 | I37: 0.10734615 | J37: 0.028980971
B41: RESID capacity for air pollution controls by Region. Based on EPA eGrid data (Original workbook "Coal Plant 9R RESIDS for 2000.xls")
B43: FGD Data
E44: Nameplate capacity in PJ/yr
B46: Sum of EffNPC(PJ) | E46: FGD
B47: EPA9Rregion | C47: Coal Type | D47: Coal S Content | E47: N | F47: Y | G47: Grand Total | H47: Data from:
B48: 1 | C48: BIT | D48: L | E48: 53.687876 | G48: 53.687876 | H48: EIA767 (yr. 2000)
D49: M | E49: 18.7488 | G49: 18.7488 | H49: eGRID2002 (yr. 2000)
C50: SUB | D50: L | E50: 12.58425 | G50: 12.58425
...

Sheet Water Data
A1: Source: Madknick et al. (2011), A Review of Operational Water Consumption and Withdrawal Factors for Electricity Generating Technologies. NREL: Golden, CO
A2: Table 1. Water Consumption Factors for Renewable Technologies (gal/MWh)
A3: Table 2. Water Consumption Factors for Non-renewable Technologies (gal/MWh) | L3: N/a for "source" and "table" ==> withdrawals not reported and assumed to be equal to consumption.
A4: Table 3. Water Withdrawal Factors for Electricity Generating Technologies (gal/MWh) | Y4: nonrenewable = | Z4: NR
D6: Withdrawals (H20W) | O6: Consumption (H20C) | AB6: Percent water withdrawal consumed
D7: Million gallons H2O/PJ | H7: gallons H2O/MWh | O7: Million gallons H2O/PJ | S7: gallons H2O/MWh
A8: Fuel Type | B8: Cooling | C8: Technology | D8: Median | E8: Min | F8: Max | H8: Median | I8: Min | J8: Max | K8: n | L8: Source(s) | M8: Table | O8: Median | P8: Min | Q8: Max | S8: Median | T8: Min | U8: Max | V8: n | W8: Source(s) | X8: Table | Z8: R or NR
A9: Biopower | B9: Dry | C9: Biogas | D9: =H9*((1/Conversions!$K$5)*(1/1000000)) -> 9.7222249 | H9: 35 | L9: n/a | M9: n/a | O9: =S9*((1/Conversions!$K$5)*(1/1000000)) -> 9.7222249 | P9: =T9*((1/Conversions!$K$5)*(1/1000000)) -> 9.7222249 | Q9: =U9*((1/Conversions!$K$5)*(1/1000000)) -> 9.7222249 | S9: 35 | T9: 35 | U9: 35 | V9: 1 | W9: [51] | X9: 1 | Z9: R | AB9: =S9/H9 -> 1
A10: Biopower | B10: Once-through | C10: Steam | D10: =H10*((1/Conversions!$K$5)*(1/1000000)) -> 9722.2249 | E10: =I10*((1/Conversions!$K$5)*(1/1000000)) -> 5555.5571 | F10: =J10*((1/Conversions!$K$5)*(1/1000000)) -> 13888.893 | H10: 35000 | I10: 20000 | J10: 50000 | K10: 1 | L10: [50] | M10: 3 | O10: =S10*((1/Conversions!$K$5)*(1/1000000)) -> 83.333356 | P10: =T10*((1/Conversions!$K$5)*(1/1000000)) -> 83.333356 | Q10: =U10*((1/Conversions!$K$5)*(1/1000000)) -> 83.333356 | S10: 300 | T10: 300 | U10: 300 | V10: 1 | W10: [50] | X10: 1 | Z10: R | AB10: =S10/H10 -> 0.0085714286
A11: Biopower | B11: Pond | C11: Steam | D11: =H11*((1/Conversions!$K$5)*(1/1000000)) -> 125.00003 | E11: =I11*((1/Conversions!$K$5)*(1/1000000)) -> 83.333356 | F11: =J11*((1/Conversions!$K$5)*(1/1000000)) -> 166.66671 | H11: 450 | I11: 300 | J11: 600 | K11: 1 | L11: [50] | M11: 3 | O11: =S11*((1/Conversions!$K$5)*(1/1000000)) -> 108.33336 | P11: =T11*((1/Conversions!$K$5)*(1/1000000)) -> 83.333356 | Q11: =U11*((1/Conversions!$K$5)*(1/1000000)) -> 133.33337 | S11: 390 | T11: 300 | U11: 480 | V11: 1 | W11: [50] | X11: 1 | Z11: R | AB11: =S11/H11 -> 0.86666667
A12: Biopower | B12: Tower | C12: Biogas | D12: =H12*((1/Conversions!$K$5)*(1/1000000)) -> 65.277796 | H12: =S12 -> 235 | L12: n/a | M12: n/a | O12: =S12*((1/Conversions!$K$5)*(1/1000000)) -> 65.277796 | P12: =T12*((1/Conversions!$K$5)*(1/1000000)) -> 65.277796 | Q12: =U12*((1/Conversions!$K$5)*(1/1000000)) -> 65.277796 | S12: 235 | T12: 235 | U12: 235 | V12: 1 | W12: [52] | X12: 1 | Z12: R | AB12: =S12/H12 -> 1
A13: Biopower | B13: Tower | C13: Steam | D13: =H13*((1/Conversions!$K$5)*(1/1000000)) -> 243.88896 | E13: =I13*((1/Conversions!$K$5)*(1/1000000)) -> 138.88893 | F13: =J13*((1/Conversions!$K$5)*(1/1000000)) -> 405.55567 | H13: 878 | I13: 500 | J13: 1460 | K13: 2 | L13: [49] | M13: 3 | O13: =S13*((1/Conversions!$K$5)*(1/1000000)) -> 153.61115 | P13: =T13*((1/Conversions!$K$5)*(1/1000000)) -> 133.33337 | Q13: =U13*((1/Conversions!$K$5)*(1/1000000)) -> 268.05563 | S13: 553 | T13: 480 | U13: 965 | V13: 4 | W13: [49-51] | X13: 1 | Z13: R | AB13: =S13/H13 -> 0.62984055
A14: Coal | B14: Once-through | C14: Generic | D14: =H14*((1/Conversions!$K$5)*(1/1000000)) -> 10097.225 | E14: =I14*((1/Conversions!$K$5)*(1/1000000)) -> 5555.5571 | F14: =J14*((1/Conversions!$K$5)*(1/1000000)) -> 13888.893 | H14: 36350 | I14: 20000 | J14: 50000 | K14: 4 | L14: [11, 27, 50, 58] | M14: 3 | O14: =S14*((1/Conversions!$K$5)*(1/1000000)) -> 69.444464 | P14: =T14*((1/Conversions!$K$5)*(1/1000000)) -> 27.777785 | Q14: =U14*((1/Conversions!$K$5)*(1/1000000)) -> 88.05558 | S14: 250 | T14: 100 | U14: 317 | V14: 4 | W14: [10, 27, 50, 58] | X14: 2 | Z14: NR | AB14: =S14/H14 -> 0.0068775791
A15: Coal | B15: Once-through | C15: Subcritical | D15: =H15*((1/Conversions!$K$5)*(1/1000000)) -> 7524.4465 | E15: =I15*((1/Conversions!$K$5)*(1/1000000)) -> 7512.7799 | F15: =J15*((1/Conversions!$K$5)*(1/1000000)) -> 7531.391 | H15: 27088 | I15: 27046 | J15: 27113 | K15: 3 | L15: [57] | M15: 3 | O15: =S15*((1/Conversions!$K$5)*(1/1000000)) -> 31.388898 | P15: =T15*((1/Conversions!$K$5)*(1/1000000)) -> 19.722228 | Q15: =U15*((1/Conversions!$K$5)*(1/1000000)) -> 38.333344 | S15: 113 | T15: 71 | U15: 138 | V15: 3 | W15: [57] | X15: 2 | Z15: NR | AB15: =S15/H15 -> 0.0041715889
A16: Coal | B16: Once-through | C16: Supercritical | D16: =H16*((1/Conversions!$K$5)*(1/1000000)) -> 6275.0017 | E16: =I16*((1/Conversions!$K$5)*(1/1000000)) -> 6264.1684 | F16: =J16*((1/Conversions!$K$5)*(1/1000000)) -> 6280.8351 | H16: 22590 | I16: 22551 | J16: 22611 | K16: 3 | L16: [57] | M16: 3 | O16: =S16*((1/Conversions!$K$5)*(1/1000000)) -> 28.611119 | P16: =T16*((1/Conversions!$K$5)*(1/1000000)) -> 17.777783 | Q16: =U16*((1/Conversions!$K$5)*(1/1000000)) -> 34.444454 | S16: 103 | T16: 64 | U16: 124 | V16: 3 | W16: [57] | X16: 2 | Z16: NR | AB16: =S16/H16 -> 0.0045595396
A17: Coal | B17: Pond | C17: Generic | D17: =H17*((1/Conversions!$K$5)*(1/1000000)) -> 3395.8343 | E17: =I17*((1/Conversions!$K$5)*(1/1000000)) -> 83.333356 | F17: =J17*((1/Conversions!$K$5)*(1/1000000)) -> 6666.6685 | H17: 12225 | I17: 300 | J17: 24000 | K17: 2 | L17: [27, 50] | M17: 3 | O17: =S17*((1/Conversions!$K$5)*(1/1000000)) -> 151.38893 | P17: =T17*((1/Conversions!$K$5)*(1/1000000)) -> 83.333356 | Q17: =U17*((1/Conversions!$K$5)*(1/1000000)) -> 194.4445 | S17: 545 | T17: 300 | U17: 700 | V17: 2 | W17: [27, 50] | X17: 2 | Z17: NR | AB17: =S17/H17 -> 0.044580777
A18: Coal | B18: Pond | C18: Subcritical | D18: =H18*((1/Conversions!$K$5)*(1/1000000)) -> 4976.1125 | E18: =I18*((1/Conversions!$K$5)*(1/1000000)) -> 4960.8347 | F18: =J18*((1/Conversions!$K$5)*(1/1000000)) -> 4979.7236 | H18: 17914 | I18: 17859 | J18: 17927 | K18: 3 | L18: [57] | M18: 3 | O18: =S18*((1/Conversions!$K$5)*(1/1000000)) -> 216.38895 | P18: =T18*((1/Conversions!$K$5)*(1/1000000)) -> 204.72228 | Q18: =U18*((1/Conversions!$K$5)*(1/1000000)) -> 223.3334 | S18: 779 | T18: 737 | U18: 804 | V18: 3 | W18: [57] | X18: 2 | Z18: NR | AB18: =S18/H18 -> 0.043485542
A19: Coal | B19: Pond | C19: Supercritical | D19: =H19*((1/Conversions!$K$5)*(1/1000000)) -> 4179.4456 | E19: =I19*((1/Conversions!$K$5)*(1/1000000)) -> 4165.5567 | F19: =J19*((1/Conversions!$K$5)*(1/1000000)) -> 4182.5012 | H19: 15046 | I19: 14996 | J19: 15057 | K19: 3 | L19: [57] | M19: 3 | O19: =S19*((1/Conversions!$K$5)*(1/1000000)) -> 11.66667 | P19: =T19*((1/Conversions!$K$5)*(1/1000000)) -> 1.1111114 | Q19: =U19*((1/Conversions!$K$5)*(1/1000000)) -> 17.777783 | S19: 42 | T19: 4 | U19: 64 | V19: 3 | W19: [57] | X19: 2 | Z19: NR | AB19: =S19/H19 -> 0.0027914396
A20: Coal | B20: Tower | C20: Generic | D20: =H20*((1/Conversions!$K$5)*(1/1000000)) -> 279.16674 | E20: =I20*((1/Conversions!$K$5)*(1/1000000)) -> 138.88893 | F20: =J20*((1/Conversions!$K$5)*(1/1000000)) -> 333.33343 | H20: 1005 | I20: 500 | J20: 1200 | K20: 4 | L20: [27, 35, 50, 58] | M20: 3 | O20: =S20*((1/Conversions!$K$5)*(1/1000000)) -> 190.83339 | P20: =T20*((1/Conversions!$K$5)*(1/1000000)) -> 133.33337 | Q20: =U20*((1/Conversions!$K$5)*(1/1000000)) -> 305.55564 | S20: 687 | T20: 480 | U20: 1100 | V20: 5 | W20: [10, 14, 27, 50, 58] | X20: 2 | Z20: NR | AB20: =S20/H20 -> 0.68358209
A21: Coal | B21: Tower | C21: IGCC | D21: =H21*((1/Conversions!$K$5)*(1/1000000)) -> 108.33336 | E21: =I21*((1/Conversions!$K$5)*(1/1000000)) -> 99.444472 | F21: =J21*((1/Conversions!$K$5)*(1/1000000)) -> 168.0556 | H21: 390 | I21: 358 | J21: 605 | K21: 11 | L21: [12, 13, 35, 59] | M21: 3 | O21: =S21*((1/Conversions!$K$5)*(1/1000000)) -> 103.33336 | P21: =T21*((1/Conversions!$K$5)*(1/1000000)) -> 88.333358 | Q21: =U21*((1/Conversions!$K$5)*(1/1000000)) -> 121.94448 | S21: 372 | T21: 318 | U21: 439 | V21: 7 | W21: [13, 59] | X21: 2 | Z21: NR | AB21: =S21/H21 -> 0.95384615
A22: Coal | B22: Tower | C22: IGCC with CCS | D22: =H22*((1/Conversions!$K$5)*(1/1000000)) -> 162.77782 | E22: =I22*((1/Conversions!$K$5)*(1/1000000)) -> 133.05559 | F22: =J22*((1/Conversions!$K$5)*(1/1000000)) -> 188.33339 | H22: 586 | I22: 479 | J22: 678 | K22: 6 | L22: [12, 59] | M22: 3 | O22: =S22*((1/Conversions!$K$5)*(1/1000000)) -> 150.00004 | P22: =T22*((1/Conversions!$K$5)*(1/1000000)) -> 145.00004 | Q22: =U22*((1/Conversions!$K$5)*(1/1000000)) -> 155.00004 | S22: 540 | T22: 522 | U22: 558 | V22: 3 | W22: [59] | X22: 2 | Z22: NR | AB22: =S22/H22 -> 0.92150171
A23: Coal | B23: Tower | C23: Subcritical | D23: =H23*((1/Conversions!$K$5)*(1/1000000)) -> 147.50004 | E23: =I23*((1/Conversions!$K$5)*(1/1000000)) -> 128.61115 | F23: =J23*((1/Conversions!$K$5)*(1/1000000)) -> 188.33339 | H23: 531 | I23: 463 | J23: 678 | K23: 7 | L23: [12, 13, 57, 59, 61] | M23: 3 | O23: =S23*((1/Conversions!$K$5)*(1/1000000)) -> 130.83337 | P23: =T23*((1/Conversions!$K$5)*(1/1000000)) -> 109.44447 | Q23: =U23*((1/Conversions!$K$5)*(1/1000000)) -> 184.4445 | S23: 471 | T23: 394 | U23: 664 | V23: 6 | W23: [13, 57, 59, 61] | X23: 2 | Z23: NR | AB23: =S23/H23 -> 0.88700565
A24: Coal | B24: Tower | C24: Subcritical with CCS | D24: =H24*((1/Conversions!$K$5)*(1/1000000)) -> 354.72232 | E24: =I24*((1/Conversions!$K$5)*(1/1000000)) -> 340.00009 | F24: =J24*((1/Conversions!$K$5)*(1/1000000)) -> 369.16677 | H24: 1277 | I24: 1224 | J24: 1329 | K24: 2 | L24: [12, 59] | M24: 3 | O24: =S24*((1/Conversions!$K$5)*(1/1000000)) -> 261.66674 | P24: =T24*((1/Conversions!$K$5)*(1/1000000)) -> 261.66674 | Q24: =U24*((1/Conversions!$K$5)*(1/1000000)) -> 261.66674 | S24: 942 | T24: 942 | U24: 942 | V24: 1 | W24: [59] | X24: 2 | Z24: NR | AB24: =S24/H24 -> 0.73766641
... A26: Coal | B26: Tower | C26: Supercritical with CCS | D26: =H26*((1/Conversions!$K$5)*(1/1000000)) -> 311.94453 | E26: =I26*((1/Conversions!$K$5)*(1/1000000)) -> 305.00008 | F26: =J26*((1/Conversions!$K$5)*(1/1000000)) -> 318.88898 | H26: 1123 | I26: 1098 | J26: 1148 | K26: 2 | L26: [12, 59] | M26: 3 | O26: =S26*((1/Conversions!$K$5)*(1/1000000)) -> 235.00007 | P26: =T26*((1/Conversions!$K$5)*(1/1000000)) -> 235.00007 | Q26: =U26*((1/Conversions!$K$5)*(1/1000000)) -> 235.00007 | S26: 846 | T26: 846 | U26: 846 | V26: 1 | W26: [59] | X26: 2 | Z26: NR | AB26: =S26/H26 -> 0.75333927
A27: CSP | B27: Dry | C27: Power Tower | D27: =H27*((1/Conversions!$K$5)*(1/1000000)) -> 7.2222242 | H27: =S27 -> 26 | L27: n/a | M27: n/a | O27: =S27*((1/Conversions!$K$5)*(1/1000000)) -> 7.2222242 | P27: =T27*((1/Conversions!$K$5)*(1/1000000)) -> 7.2222242 | Q27: =U27*((1/Conversions!$K$5)*(1/1000000)) -> 7.2222242 | S27: 26 | T27: 26 | U27: 26 | V27: 1 | W27: [48] | X27: 1 | Z27: R | AB27: =S27/H27 -> 1
A28: CSP | B28: Dry | C28: Trough | D28: =H28*((1/Conversions!$K$5)*(1/1000000)) -> 21.666673 | H28: =S28 -> 78 | L28: n/a | M28: n/a | O28: =S28*((1/Conversions!$K$5)*(1/1000000)) -> 21.666673 | P28: =T28*((1/Conversions!$K$5)*(1/1000000)) -> 11.944448 | Q28: =U28*((1/Conversions!$K$5)*(1/1000000)) -> 21.944451 | S28: 78 | T28: 43 | U28: 79 | V28: 10 | W28: [38, 42-44] | X28: 1 | Z28: R | AB28: =S28/H28 -> 1
A29: CSP | B29: Hybrid | C29: Power Tower | D29: =H29*((1/Conversions!$K$5)*(1/1000000)) -> 47.222235 | H29: =S29 -> 170 | L29: n/a | M29: n/a | O29: =S29*((1/Conversions!$K$5)*(1/1000000)) -> 47.222235 | P29: =T29*((1/Conversions!$K$5)*(1/1000000)) -> 25.000007 | Q29: =U29*((1/Conversions!$K$5)*(1/1000000)) -> 69.444464 | S29: 170 | T29: 90 | U29: 250 | V29: 2 | W29: [47] | X29: 1 | Z29: R | AB29: =S29/H29 -> 1
A30: CSP | B30: Hybrid | C30: Trough | D30: =H30*((1/Conversions!$K$5)*(1/1000000)) -> 93.888915 | H30: =S30 -> 338 | L30: n/a | M30: n/a | O30: =S30*((1/Conversions!$K$5)*(1/1000000)) -> 93.888915 | P30: =T30*((1/Conversions!$K$5)*(1/1000000)) -> 29.166675 | Q30: =U30*((1/Conversions!$K$5)*(1/1000000)) -> 95.83336 | S30: 338 | T30: 105 | U30: 345 | V30: 3 | W30: [42, 47] | X30: 1 | Z30: R | AB30: =S30/H30 -> 1
A31: CSP | B31: N/A | C31: Stirling | D31: =H31*((1/Conversions!$K$5)*(1/1000000)) -> 1.3888893 | H31: =S31 -> 5 | L31: n/a | M31: n/a | O31: =S31*((1/Conversions!$K$5)*(1/1000000)) -> 1.3888893 | P31: =T31*((1/Conversions!$K$5)*(1/1000000)) -> 1.1111114 | Q31: =U31*((1/Conversions!$K$5)*(1/1000000)) -> 1.6666671 | S31: 5 | T31: 4 | U31: 6 | V31: 2 | W31: [34, 49] | X31: 1 | Z31: R | AB31: =S31/H31 -> 1
A32: CSP | B32: Tower | C32: Fresnel | D32: =H32*((1/Conversions!$K$5)*(1/1000000)) -> 277.77785 | H32: =S32 -> 1000 | L32: n/a | M32: n/a | O32: =S32*((1/Conversions!$K$5)*(1/1000000)) -> 277.77785 | P32: =T32*((1/Conversions!$K$5)*(1/1000000)) -> 277.77785 | Q32: =U32*((1/Conversions!$K$5)*(1/1000000)) -> 277.77785 | S32: 1000 | T32: 1000 | U32: 1000 | V32: 1 | W32: [47] | X32: 1 | Z32: R | AB32: =S32/H32 -> 1
A33: CSP | B33: Tower | C33: Power Tower | D33: =H33*((1/Conversions!$K$5)*(1/1000000)) -> 218.33339 | H33: =S33 -> 786 | L33: n/a | M33: n/a | O33: =S33*((1/Conversions!$K$5)*(1/1000000)) -> 218.33339 | P33: =T33*((1/Conversions!$K$5)*(1/1000000)) -> 205.55561 | Q33: =U33*((1/Conversions!$K$5)*(1/1000000)) -> 238.88896 | S33: 786 | T33: 740 | U33: 860 | V33: 4 | W33: [34, 39-41] | X33: 1 | Z33: R | AB33: =S33/H33 -> 1
A34: CSP | B34: Tower | C34: Trough | D34: =H34*((1/Conversions!$K$5)*(1/1000000)) -> 240.27784 | H34: =S34 -> 865 | L34: n/a | M34: n/a | O34: =S34*((1/Conversions!$K$5)*(1/1000000)) -> 240.27784 | P34: =T34*((1/Conversions!$K$5)*(1/1000000)) -> 201.38894 | Q34: =U34*((1/Conversions!$K$5)*(1/1000000)) -> 293.61119 | S34: 865 | T34: 725 | U34: 1057 | V34: 17 | W34: [10, 34, 37-46] | X34: 1 | Z34: R | AB34: =S34/H34 -> 1
A35: Geothermal | B35: Dry | C35: Binary | D35: =H35*((1/Conversions!$K$5)*(1/1000000)) -> 37.50001 | H35: =S35 -> 135 | L35: n/a | M35: n/a | O35: =S35*((1/Conversions!$K$5)*(1/1000000)) -> 37.50001 | P35: =T35*((1/Conversions!$K$5)*(1/1000000)) -> 0 | Q35: =U35*((1/Conversions!$K$5)*(1/1000000)) -> 75.000021 | S35: 135 | T35: 0 | U35: 270 | V35: 2 | W35: [19, 51] | X35: 1 | Z35: R | AB35: =S35/H35 -> 1
A36: Geothermal | B36: Dry | C36: EGS | D36: =H36*((1/Conversions!$K$5)*(1/1000000)) -> 236.11118 | H36: =S36 -> 850 | L36: n/a | M36: n/a | O36: =S36*((1/Conversions!$K$5)*(1/1000000)) -> 236.11118 | P36: =T36*((1/Conversions!$K$5)*(1/1000000)) -> 83.333356 | Q36: =U36*((1/Conversions!$K$5)*(1/1000000)) -> 493.88903 | S36: 850 | T36: 300 | U36: 1778 | V36: 2 | W36: [19, 51] | X36: 1 | Z36: R | AB36: =S36/H36 -> 1
A37: Geothermal | B37: Dry | C37: Flash | D37: =H37*((1/Conversions!$K$5)*(1/1000000)) -> 0 | H37: =S37 -> 0 | L37: n/a | M37: n/a | O37: =S37*((1/Conversions!$K$5)*(1/1000000)) -> 0 | P37: =T37*((1/Conversions!$K$5)*(1/1000000)) -> 0 | Q37: =U37*((1/Conversions!$K$5)*(1/1000000)) -> 0 | S37: 0 | T37: 0 | U37: 0 | V37: 1 | W37: [51] | X37: 1 | Z37: R | AB37: =S37/H37 -> #DIV/0!
A38: Geothermal | B38: Hybrid | C38: EGS | D38: =H38*((1/Conversions!$K$5)*(1/1000000)) -> 390.55566 | H38: =S38 -> 1406 | L38: n/a | M38: n/a | O38: =S38*((1/Conversions!$K$5)*(1/1000000)) -> 390.55566 | P38: =T38*((1/Conversions!$K$5)*(1/1000000)) -> 225.8334 | Q38: =U38*((1/Conversions!$K$5)*(1/1000000)) -> 555.27793 | S38: 1406 | T38: 813 | U38: 1999 | V38: 2 | W38: [51, 56] | X38: 1 | Z38: R | AB38: =S38/H38 -> 1
... A45: Hydropower | B45: N/A | C45: Aggregated in-stream & reservoir | D45: =H45*((1/Conversions!$K$5)*(1/1000000)) -> 1247.5003 | H45: =S45 -> 4491 | L45: n/a | M45: n/a | O45: =S45*((1/Conversions!$K$5)*(1/1000000)) -> 1247.5003 | P45: =T45*((1/Conversions!$K$5)*(1/1000000)) -> 395.83344 | Q45: =U45*((1/Conversions!$K$5)*(1/1000000)) -> 5000.0014 | S45: 4491 | T45: 1425 | U45: 18000 | V45: 3 | W45: [22, 23] | X45: 1 | Z45: R | AB45: =S45/H45 -> 1
A46: Natural Gas | B46: Dry | C46: Combined Cycle | D46: =H46*((1/Conversions!$K$5)*(1/1000000)) -> 0.55555571 | E46: =I46*((1/Conversions!$K$5)*(1/1000000)) -> 0 | F46: =J46*((1/Conversions!$K$5)*(1/1000000)) -> 1.1111114 | H46: 2 | I46: 0 | J46: 4 | K46: 2 | L46: [50, 57] | M46: 3 | O46: =S46*((1/Conversions!$K$5)*(1/1000000)) -> 0.55555571 | P46: =T46*((1/Conversions!$K$5)*(1/1000000)) -> 0 | Q46: =U46*((1/Conversions!$K$5)*(1/1000000)) -> 1.1111114 | S46: 2 | T46: 0 | U46: 4 | V46: 2 | W46: [50, 57] | X46: 2 | Z46: NR | AB46: =S46/H46 -> 1
A47: Natural Gas | B47: Inlet | C47: Steam | D47: =H47*((1/Conversions!$K$5)*(1/1000000)) -> 118.05559 | E47: =I47*((1/Conversions!$K$5)*(1/1000000)) -> 27.777785 | F47: =J47*((1/Conversions!$K$5)*(1/1000000)) -> 208.33339 | H47: 425 | I47: 100 | J47: 750 | K47: 1 | L47: [49] | M47: 3 | O47: =S47*((1/Conversions!$K$5)*(1/1000000)) -> 94.444471 | P47: =T47*((1/Conversions!$K$5)*(1/1000000)) -> 22.222228 | Q47: =U47*((1/Conversions!$K$5)*(1/1000000)) -> 166.66671 | S47: 340 | T47: 80 | U47: 600 | V47: 1 | W47: [49] | X47: 2 | Z47: NR | AB47: =S47/H47 -> 0.8
A48: Natural Gas | B48: Once-through | C48: Combined Cycle | D48: =H48*((1/Conversions!$K$5)*(1/1000000)) -> 3161.112 | E48: =I48*((1/Conversions!$K$5)*(1/1000000)) -> 2083.3339 | F48: =J48*((1/Conversions!$K$5)*(1/1000000)) -> 5555.5571 | H48: 11380 | I48: 7500 | J48: 20000 | K48: 2 | L48: [50, 57] | M48: 3 | O48: =S48*((1/Conversions!$K$5)*(1/1000000)) -> 27.777785 | P48: =T48*((1/Conversions!$K$5)*(1/1000000)) -> 5.5555571 | Q48: =U48*((1/Conversions!$K$5)*(1/1000000)) -> 27.777785 | S48: 100 | T48: 20 | U48: 100 | V48: 3 | W48: [50, 57, 60] | X48: 2 | Z48: NR | AB48: =S48/H48 -> 0.0087873462
...

Sheet CompositeGREETEFs
B1: Using factors labeled *-EPA where available
B2: Methodology for 2005 and 2010 appears to be different than for 2015 and 2020. If 2005&10 are less than 2015, 2015 factor is used.
B3: Correction for GREET factors being based upon LHVs | E3: =1/1.1 -> 0.90909091
B4: Note: for 2015 values, the 2013 values from the GREET2014 update are used. | U4: 2020 value from GREET12. 2010 is 10% greater, 2020 is 10% greater.
B5: Assuming biomass-to-steam and biomass-to-IGCC require 1/10th of energy input from lignite and bit. coal, respectively. This factors into the CO2 EF. This assumptions should be revisited in the future.
B6: Using typical bit. coal CO2 EF for IGCC
B8: kT/PJ | C8: VOC | D8: VOC | E8: VOC | F8: VOC | G8: VOC | H8: VOC | I8: CO | J8: CO | K8: CO | L8: CO | M8: CO | N8: CO | O8: NOX | P8: NOX | Q8: NOX | R8: NOX | S8: NOX | T8: NOX | U8: PM10 | V8: PM10 | W8: PM10 | X8: PM10 | Y8: PM10 | Z8: PM10 | AA8: PM25 | AB8: PM25 | AC8: PM25 | AD8: PM25 | AE8: PM25 | AF8: PM25 | AG8: SO2 | AH8: SO2 | AI8: SO2 | AJ8: SO2 | AK8: SO2 | AL8: SO2 | AM8: CH4 | AN8: CH4 | AO8: CH4 | AP8: CH4 | AQ8: CH4 | AR8: CH4 | AS8: N2O | AT8: N2O | AU8: N2O | AV8: N2O | AW8: N2O | AX8: N2O | AY8: BC | AZ8: BC | BA8: BC | BB8: BC | BC8: BC | BD8: BC | BE8: CO2 | BF8: CO2 | BG8: CO2 | BH8: CO2 | BI8: CO2 | BJ8: CO2 | BK8: OC | BL8: OC | BM8: OC | BN8: OC | BO8: OC | BP8: OC
C9: 2005 | D9: 2010 | E9: 2015 | F9: 2020 | G9: 2025 | H9: 2030-2055 | I9: 2005 | J9: 2010 | K9: 2015 | L9: 2020 | M9: 2025 | N9: 2030-2055 | O9: 2005 | P9: 2010 | Q9: 2015 | R9: 2020 | S9: 2025 | T9: 2030-2055 | U9: 2005 | V9: 2010 | W9: 2015 | X9: 2020 | Y9: 2025 | Z9: 2030-2055 | AA9: 2005 | AB9: 2010 | AC9: 2015 | AD9: 2020 | AE9: 2025 | AF9: 2030-2055 | AG9: 2005 | AH9: 2010 | AI9: 2015 | AJ9: 2020 | AK9: 2025 | AL9: 2030-2055 | AM9: 2005 | AN9: 2010 | AO9: 2015 | AP9: 2020 | AQ9: 2025 | AR9: 2030-2055 | AS9: 2005 | AT9: 2010 | AU9: 2015 | AV9: 2020 | AW9: 2025 | AX9: 2030-2055 | AY9: 2005 | AZ9: 2010 | BA9: 2015 | BB9: 2020 | BC9: 2025 | BD9: 2030-2055 | BE9: 2005 | BF9: 2010 | BG9: 2015 | BH9: 2020 | BI9: 2025 | BJ9: 2030-2055 | BK9: 2005 | BL9: 2010 | BM9: 2015 | BN9: 2020 | BO9: 2025 | BP9: 2030-2055
B10: IGCC turbine | C10: =IF($E$3*$C28*0.000947817>D10,$E$3*$C28*0.000947817,D10) -> 0.0012157907 | D10: =IF($E$3*$D28*0.000947817>E10,$E$3*$D28*0.000947817,E10) -> 0.00061893915 | E10: =$E$3*$H$28*0.453592*947817/1000000 -> 0.00036865137 | F10: =$E$3*$I$28*0.453592*947817/1000000 -> 0.0003857812 | G10: =(F10+H10)/2 -> 0.00039518087 | H10: =$E$3*$J$28*0.453592*947817/1000000 -> 0.00040458053 | I10: =IF($E$3*$C29*0.000947817>J10,$E$3*$C29*0.000947817,J10) -> 0.010901619 | J10: =IF($E$3*$D29*0.000947817>K10,$E$3*$D29*0.000947817,K10) -> 0.010901619 | K10: =$E$3*$H$29*0.453592*947817/1000000 -> 0.0064556856 | L10: =$E$3*$I$29*0.453592*947817/1000000 -> 0.0067556569 | M10: =(L10+N10)/2 -> 0.0069202603 | N10: =$E$3*$J$29*0.453592*947817/1000000 -> 0.0070848638 | O10: =IF($E$3*$C30*0.000947817>P10,$E$3*$C30*0.000947817,P10) -> 0.036278127 | P10: =IF($E$3*$D30*0.000947817>Q10,$E$3*$D30*0.000947817,Q10) -> 0.018840017 | Q10: =$E$3*$H$30*0.453592*947817/1000000 -> 0.01115599 | R10: =$E$3*$I$30*0.453592*947817/1000000 -> 0.011674367 | S10: =(R10+T10)/2 -> 0.011958816 | T10: =$E$3*$J$30*0.453592*947817/1000000 -> 0.012243266 | U10: =IF($E$3*$C31*0.000947817>V10,$E$3*$C31*0.000947817,V10) -> 0.005374984 | V10: =IF($E$3*$D31*0.000947817>W10,$E$3*$D31*0.000947817,W10) -> 0.0026168366 | W10: =$E$3*$H$31*0.453592*947817/1000000 -> 0.0015512292 | X10: =$E$3*$I$31*0.453592*947817/1000000 -> 0.001623309 | Y10: =(X10+Z10)/2 -> 0.0016628614 | Z10: =$E$3*$J$31*0.453592*947817/1000000 -> 0.0017024137 | AA10: =IF($E$3*$C32*0.000947817>AB10,$E$3*$C32*0.000947817,AB10) -> 0.002687492 | AB10: =IF($E$3*$D32*0.000947817>AC10,$E$3*$D32*0.000947817,AC10) -> 0.001314019 | AC10: =$E$3*$H$32*0.453592*947817/1000000 -> 0 | AD10: =$E$3*$I$32*0.453592*947817/1000000 -> 0 | AE10: =(AD10+AF10)/2 -> 0 | AF10: =$E$3*$J$32*0.453592*947817/1000000 -> 0 | AG10: =IF($E$3*$C33*0.000947817>AH10,$E$3*$C33*0.000947817,AH10) -> 0.036278127 | AH10: =IF($E$3*$D33*0.000947817>AI10,$E$3*$D33*0.000947817,AI10) -> 0.0068923529 | AI10: =$E$3*$H$33*0.453592*947817/1000000 -> 0.0040814207 | AJ10: =$E$3*$I$33*0.453592*947817/1000000 -> 0.0042710689 | AK10: =(AJ10+AL10)/2 -> 0.0043751347 | AL10: =$E$3*$J$33*0.453592*947817/1000000 -> 0.0044792005 | AM10: =IF($E$3*$C34*0.000947817>AN10,$E$3*$C34*0.000947817,AN10) -> 0.004392701 | AN10: =IF($E$3*$D34*0.000947817>AO10,$E$3*$D34*0.000947817,AO10) -> 0.0041066326 | AO10: =$E$3*$H$34*0.453592*947817/1000000 -> 0.00066516887 | AP10: =$E$3*$I$34*0.453592*947817/1000000 -> 0.00069607675 | AQ10: =(AP10+AR10)/2 -> 0.00071303685 | AR10: =$E$3*$J$34*0.453592*947817/1000000 -> 0.00072999695 | AS10: =IF($E$3*$C35*0.000947817>AT10,$E$3*$C35*0.000947817,AT10) -> 0.004392701 | AT10: =IF($E$3*$D35*0.000947817>AU10,$E$3*$D35*0.000947817,AU10) -> 0.0041066326 | AU10: =$E$3*$H$35*0.453592*947817/1000000 -> 0.0009977533 | AV10: =$E$3*$I$35*0.453592*947817/1000000 -> 0.0010441151 | AW10: =(AV10+AX10)/2 -> 0.0010695553 | AX10: =$E$3*$J$35*0.453592*947817/1000000 -> 0.0010949954 | AY10: =$E$3*AA10*#REF! -> #REF! | AZ10: =$E$3*AB10*#REF! -> #REF! | BA10: =$E$3*$H$36*0.453592*947817/1000000 -> 0 | BB10: =$E$3*$I$36*0.453592*947817/1000000 -> 0 | BC10: =(BB10+BD10)/2 -> 0 | BD10: =$E$3*$J$36*0.453592*947817/1000000 -> 0 | BE10: =BE11 -> 83.357128 | BF10: =BF11 -> 83.357128 | BG10: =BG11 -> 83.357128 | BH10: =BH11 -> 83.357128 | BI10: =BI11 -> 83.357128 | BJ10: =BJ11 -> 83.357128 | BK10: =$E$3*AA10*#REF! -> #REF! | BL10: =$E$3*AB10*#REF! -> #REF! | BM10: =$E$3*AC10*#REF! -> #REF! | BO10: =(BN10+BP10)/2 -> #REF! | BP10: =$E$3*AF10*#REF! -> #REF!
B11: utility coal boiler - bituminous | C11: =IF($E$3*$C41*0.000947817>D11,$E$3*$C41*0.000947817,D11) -> 0.0011589217 | D11: =IF($E$3*$D41*0.000947817>E11,$E$3*$D41*0.000947817,E11) -> 0.0011589217 | E11: =$E$3*$H$41*0.453592*947817/1000000 -> 0.0010343132 | F11: =$E$3*$I$41*0.453592*947817/1000000 -> 0.0010343132 | G11: =(F11+H11)/2 -> 0.0010343132 | H11: =$E$3*$J$41*0.453592*947817/1000000 -> 0.0010343132 | I11: =IF($E$3*$C42*0.000947817>J11,$E$3*$C42*0.000947817,J11) -> 0.013067811 | J11: =IF($E$3*$D42*0.000947817>K11,$E$3*$D42*0.000947817,K11) -> 0.0095134977 | K11: =$E$3*$H$42*0.453592*947817/1000000 -> 0.008716262 | L11: =$E$3*$I$42*0.453592*947817/1000000 -> 0.008716262 | M11: =(L11+N11)/2 -> 0.008716262 | N11: =$E$3*$J$42*0.453592*947817/1000000 -> 0.008716262 | O11: =IF($E$3*$C43*0.000947817>P11,$E$3*$C43*0.000947817,P11) -> 0.13787808 | P11: =IF($E$3*$D43*0.000947817>Q11,$E$3*$D43*0.000947817,Q11) -> 0.12988703 | Q11: =$E$3*$H$43*0.453592*947817/1000000 -> 0.12988703 | R11: =$E$3*$I$43*0.453592*947817/1000000 -> 0.11226549 | S11: =(R11+T11)/2 -> 0.097580881 | T11: =$E$3*$J$43*0.453592*947817/1000000 -> 0.082896269 | U11: =IF($E$3*$C44*0.000947817>V11,$E$3*$C44*0.000947817,V11) -> 0.013103139 | V11: =IF($E$3*$D44*0.000947817>W11,$E$3*$D44*0.000947817,W11) -> 0.013103139 | W11: =$E$3*E44*0.000947817 -> 0.013103139 | X11: =$E$3*F44*0.000947817 -> 0.013103139 | Y11: =X11 -> 0.013103139 | Z11: =Y11 -> 0.013103139 | AA11: =IF($E$3*$C45*0.000947817>AB11,$E$3*$C45*0.000947817,AB11) -> 0.010297601 | AB11: =IF($E$3*$D45*0.000947817>AC11,$E$3*$D45*0.000947817,AC11) -> 0.010297601 | AC11: =AD11 -> 0.010297601 | AD11: =$E$3*F45*0.000947817 -> 0.010297601 | AE11: =AD11 -> 0.010297601 | AF11: =AE11 -> 0.010297601 | AG11: =IF($E$3*$C46*0.000947817>AH11,$E$3*$C46*0.000947817,AH11) -> 0.42017954 | AH11: =IF($E$3*$D46*0.000947817>AI11,$E$3*$D46*0.000947817,AI11) -> 0.42017954 | AI11: =$E$3*$H$46*0.453592*947817/1000000 -> 0.42017954 | AJ11: =$E$3*$I$46*0.453592*947817/1000000 -> 0.064315956 | AK11: =(AJ11+AL11)/2 -> 0.06179046 | AL11: =$E$3*$J$46*0.453592*947817/1000000 -> 0.059264964 | AM11: =IF($E$3*$C47*0.000947817>AN11,$E$3*$C47*0.000947817,AN11) -> 0.0010494919 | AN11: =IF($E$3*$D47*0.000947817>AO11,$E$3*$D47*0.000947817,AO11) -> 0.00096677334 | AO11: =$E$3*$H$47*0.453592*947817/1000000 -> 0.00095625183 | AP11: =$E$3*$I$47*0.453592*947817/1000000 -> 0.00095625183 | AQ11: =(AP11+AR11)/2 -> 0.00095625183 | AR11: =$E$3*$J$47*0.453592*947817/1000000 -> 0.00095625183 | AS11: =IF($E$3*$C48*0.000947817>AT11,$E$3*$C48*0.000947817,AT11) -> 0.0014286187 | AT11: =IF($E$3*$D48*0.000947817>AU11,$E$3*$D48*0.000947817,AU11) -> 0.0014286187 | AU11: =$E$3*$H$48*0.453592*947817/1000000 -> 0.0014042177 | AV11: =$E$3*$I$48*0.453592*947817/1000000 -> 0.0014042177 | AW11: =(AV11+AX11)/2 -> 0.0014042177 | AX11: =$E$3*$J$48*0.453592*947817/1000000 -> 0.0014042177 | AY11: =$E$3*AA11*#REF! -> #REF! | AZ11: =$E$3*AB11*#REF! -> #REF! | BA11: =$E$3*$H$49*0.453592*947817/1000000 -> 0.00031691144 | BB11: =$E$3*$I$49*0.453592*947817/1000000 -> 0.00029172458 | BC11: =(BB11+BD11)/2 -> 0.0002761309 | BD11: =$E$3*$J$49*0.453592*947817/1000000 -> 0.00026053723 | BE11: =IF($E$3*$C50*0.000947817>BF11,$E$3*$C50*0.000947817,BF11) -> 83.357128 | BF11: =IF($E$3*$D50*0.000947817>BG11,$E$3*$D50*0.000947817,BG11) -> 83.357128 | BG11: =$E$3*$H$50*0.453592*947817/1000000 -> 83.357128 | BH11: =$E$3*$I$50*0.453592*947817/1000000 -> 83.357128 | BI11: =(BH11+BJ11)/2 -> 83.357128 | BJ11: =$E$3*$J$50*0.453592*947817/1000000 -> 83.357128 | BK11: =$E$3*AA11*#REF! -> #REF! | BL11: =$E$3*AB11*#REF! -> #REF! | BM11: =$E$3*AC11*#REF! -> #REF! | BO11: =(BN11+BP11)/2 -> #REF! | BP11: =$E$3*AF11*#REF! -> #REF!
B12: Utility coal boiler - subbituminous | C12: =IF(C11>D12,C11,D12) -> 0.0012286199 | D12: =IF(D11>E12,D11,E12) -> 0.0012286199 | E12: =$E$3*$H$54*0.453592*947817/1000000 -> 0.0012286199 | F12: =$E$3*$I$54*0.453592*947817/1000000 -> 0.0012286199 | G12: =(F12+H12)/2 -> 0.0012286199 | H12: =$E$3*$J$54*0.453592*947817/1000000 -> 0.0012286199 | I12: =IF(I11>J12,I11,J12) -> 0.013067811 | J12: =IF(J11>K12,J11,K12) -> 0.01034293 | K12: =$E$3*$H$55*0.453592*947817/1000000 -> 0.01034293 | L12: =$E$3*$I$55*0.453592*947817/1000000 -> 0.01034293 | M12: =(L12+N12)/2 -> 0.01034293 | N12: =$E$3*$J$55*0.453592*947817/1000000 -> 0.01034293 | O12: =IF(O11>P12,O11,P12) -> 0.13787808 | P12: =IF(P11>Q12,P11,Q12) -> 0.12988703 | Q12: =$E$3*$H$56*0.453592*947817/1000000 -> 0.11262998 | R12: =$E$3*$I$56*0.453592*947817/1000000 -> 0.098068201 | S12: =(R12+T12)/2 -> 0.085933384 | T12: =$E$3*$J$56*0.453592*947817/1000000 -> 0.073798566 | U12: =IF(U11>V12,U11,V12) -> 0.013103139 | V12: =IF(V11>W12,V11,W12) -> 0.013103139 | W12: =$E$3*E44*0.000947817 -> 0.013103139 | X12: =$E$3*F44*0.000947817 -> 0.013103139 | Y12: =X12 -> 0.013103139 | Z12: =Y12 -> 0.013103139 | AA12: =IF(AA11>AB12,AA11,AB12) -> 0.010297601 | AB12: =IF(AB11>AC12,AB11,AC12) -> 0.010297601 | AC12: =AD12 -> 0.010297601 | AD12: =$E$3*F45*0.000947817 -> 0.010297601 | AE12: =AD12 -> 0.010297601 | AF12: =AE12 -> 0.010297601 | AG12: =IF(AG11>AH12,AG11,AH12) -> 0.42017954 | AH12: =IF(AH11>AI12,AH11,AI12) -> 0.42017954 | AI12: =$E$3*$H$59*0.453592*947817/1000000 -> 0.23963253 | AJ12: =$E$3*$I$59*0.453592*947817/1000000 -> 0.063796411 | AK12: =(AJ12+AL12)/2 -> 0.061291317 | AL12: =$E$3*$J$59*0.453592*947817/1000000 -> 0.058786222 | AM12: =IF(AM11>AN12,AM11,AN12) -> 0.0010494919 | AN12: =IF(AN11>AO12,AN11,AO12) -> 0.00097205764 | AO12: =$E$3*$H$60*0.453592*947817/1000000 -> 0.00097205764 | AP12: =$E$3*$I$60*0.453592*947817/1000000 -> 0.00097205764 | AQ12: =(AP12+AR12)/2 -> 0.00097205764 | AR12: =$E$3*$J$60*0.453592*947817/1000000 -> 0.00097205764 | AS12: =IF(AS11>AT12,AS11,AT12) -> 0.0014487723 | AT12: =IF(AT11>AU12,AT11,AU12) -> 0.0014487723 | AU12: =$E$3*$H$61*0.453592*947817/1000000 -> 0.0014487723 | AV12: =$E$3*$I$61*0.453592*947817/1000000 -> 0.0014487723 | AW12: =(AV12+AX12)/2 -> 0.0014487723 | AX12: =$E$3*$J$61*0.453592*947817/1000000 -> 0.0014487723 | AY12: =AY11 -> #REF! | AZ12: =AZ11 -> #REF! | BA12: =$E$3*$H$62*0.453592*947817/1000000 -> 8.7925493e-05 | BB12: =$E$3*$I$62*0.453592*947817/1000000 -> 0.00060555899 | BC12: =(BB12+BD12)/2 -> 0.00057253719 | BD12: =$E$3*$J$62*0.453592*947817/1000000 -> 0.00053951539 | BE12: =IF(BE11>BF12,BE11,BF12) -> 85.512283 | BF12: =IF(BF11>BG12,BF11,BG12) -> 85.512283 | BG12: =$E$3*$H$63*0.453592*947817/1000000 -> 85.512283 | BH12: =$E$3*$I$63*0.453592*947817/1000000 -> 85.512283 | BI12: =(BH12+BJ12)/2 -> 85.512283 | BJ12: =$E$3*$J$63*0.453592*947817/1000000 -> 85.512283
B13: Utility coal boiler - lignite | C13: =IF(C12>D13,C12,D13) -> 0.0012581068 | D13: =IF(D12>E13,D12,E13) -> 0.0012581068 | E13: =$E$3*$H$67*0.453592*947817/1000000 -> 0.0012581068 | F13: =$E$3*$I$67*0.453592*947817/1000000 -> 0.0012581068 | G13: =(F13+H13)/2 -> 0.0012581068 | H13: =$E$3*$J$67*0.453592*947817/1000000 -> 0.0012581068 | I13: =IF(I12>J13,I12,J13) -> 0.013067811 | J13: =IF(J12>K13,J12,K13) -> 0.010591161 | K13: =$E$3*$H$68*0.453592*947817/1000000 -> 0.010591161 | L13: =$E$3*$I$68*0.453592*947817/1000000 -> 0.010591161 | M13: =(L13+N13)/2 -> 0.010591161 | N13: =$E$3*$J$68*0.453592*947817/1000000 -> 0.010591161 | O13: =IF(O12>P13,O12,P13) -> 0.13787808 | P13: =IF(P12>Q13,P12,Q13) -> 0.12988703 | Q13: =$E$3*$H$69*0.453592*947817/1000000 -> 0.1153331 | R13: =$E$3*$I$69*0.453592*947817/1000000 -> 0.10042184 | S13: =(R13+T13)/2 -> 0.087995785 | T13: =$E$3*$J$69*0.453592*947817/1000000 -> 0.075569732 | U13: =IF(U12>V13,U12,V13) -> 0.013103139 | V13: =IF(V12>W13,V12,W13) -> 0.013103139 | W13: =$E$3*E44*0.000947817 -> 0.013103139 | X13: =$E$3*F44*0.000947817 -> 0.013103139 | Y13: =X13 -> 0.013103139 | Z13: =Y13 -> 0.013103139 | AA13: =IF(AA12>AB13,AA12,AB13) -> 0.010297601 | AB13: =IF(AB12>AC13,AB12,AC13) -> 0.010297601 | AC13: =AD13 -> 0.010297601 | AD13: =$E$3*F45*0.000947817 -> 0.010297601 | AE13: =AD13 -> 0.010297601 | AF13: =AE13 -> 0.010297601 | AG13: =IF(AG12>AH13,AG12,AH13) -> 0.42017954 | AH13: =IF(AH12>AI13,AH12,AI13) -> 0.42017954 | AI13: =$E$3*$H$72*0.453592*947817/1000000 -> 0.24538371 | AJ13: =$E$3*$I$72*0.453592*947817/1000000 -> 0.065327525 | AK13: =(AJ13+AL13)/2 -> 0.062762308 | AL13: =$E$3*$J$72*0.453592*947817/1000000 -> 0.060197091 | AM13: =IF(AM12>AN13,AM12,AN13) -> 0.0010494919 | AN13: =IF(AN12>AO13,AN12,AO13) -> 0.00099538703 | AO13: =$E$3*$H$73*0.453592*947817/1000000 -> 0.00099538703 | AP13: =$E$3*$I$73*0.453592*947817/1000000 -> 0.00099538703 | AQ13: =(AP13+AR13)/2 -> 0.00099538703 | AR13: =$E$3*$J$73*0.453592*947817/1000000 -> 0.00099538703 | AS13: =IF(AS12>AT13,AS12,AT13) -> 0.0014835429 | AT13: =IF(AT12>AU13,AT12,AU13) -> 0.0014835429 | AU13: =$E$3*$H$74*0.453592*947817/1000000 -> 0.0014835429 | AV13: =$E$3*$I$74*0.453592*947817/1000000 -> 0.0014835429 | AW13: =(AV13+AX13)/2 -> 0.0014835429 | AX13: =$E$3*$J$74*0.453592*947817/1000000 -> 0.0014835429 | AY13: =AY12 -> #REF! | AZ13: =AZ12 -> #REF! | BA13: =$E$3*$H$75*0.453592*947817/1000000 -> 9.0035704e-05 | BB13: =$E$3*$I$75*0.453592*947817/1000000 -> 0.0006200924 | BC13: =(BB13+BD13)/2 -> 0.00058627808 | BD13: =$E$3*$J$75*0.453592*947817/1000000 -> 0.00055246376 | BE13: =IF(BE12>BF13,BE12,BF13) -> 87.564578 | BF13: =IF(BF12>BG13,BF12,BG13) -> 87.564578 | BG13: =$E$3*$H$76*0.453592*947817/1000000 -> 87.564578 | BH13: =$E$3*$I$76*0.453592*947817/1000000 -> 87.564578 | BI13: =(BH13+BJ13)/2 -> 87.564578 | BJ13: =$E$3*$J$76*0.453592*947817/1000000 -> 87.564578
B14: Natural gas boiler | C14: =IF($E$3*$C79*0.000947817>D14,$E$3*$C79*0.000947817,D14) -> 0.0022471879 | D14: =IF($E$3*$D79*0.000947817>E14,$E$3*$D79*0.000947817,E14) -> 0.0022471879 | E14: =$E$3*$H$79*0.453592*947817/1000000 -> 0.0022107225 | F14: =$E$3*$I$79*0.453592*947817/1000000 -> 0.0022107225 | G14: =(F14+H14)/2 -> 0.0022107225 | H14: =$E$3*$J$79*0.453592*947817/1000000 -> 0.0022107225 | I14: =IF($E$3*$C80*0.000947817>J14,$E$3*$C80*0.000947817,J14) -> 0.033841375 | J14: =IF($E$3*$D80*0.000947817>K14,$E$3*$D80*0.000947817,K14) -> 0.033841375 | K14: =$E$3*$H$80*0.453592*947817/1000000 -> 0.032766927 | L14: =$E$3*$I$80*0.453592*947817/1000000 -> 0.032766927 | M14: =(L14+N14)/2 -> 0.032766927 | N14: =$E$3*$J$80*0.453592*947817/1000000 -> 0.032766927 | O14: =IF($E$3*$C81*0.000947817>P14,$E$3*$C81*0.000947817,P14) -> 0.069342292 | P14: =IF($E$3*$D81*0.000947817>Q14,$E$3*$D81*0.000947817,Q14) -> 0.069342292 | Q14: =$E$3*$H$81*0.453592*947817/1000000 -> 0.067305647 | R14: =$E$3*$I$81*0.453592*947817/1000000 -> 0.060143818 | S14: =(R14+T14)/2 -> 0.053694517 | T14: =$E$3*$J$81*0.453592*947817/1000000 -> 0.047245217 | U14: =IF($E$3*$C82*0.000947817>V14,$E$3*$C82*0.000947817,V14) -> 0.0029322011 | V14: =IF($E$3*$D82*0.000947817>W14,$E$3*$D82*0.000947817,W14) -> 0.0029322011 | W14: =$E$3*$H$82*0.453592*947817/1000000 -> 0.002836156 | X14: =$E$3*$I$82*0.453592*947817/1000000 -> 0.002836156 | Y14: =(X14+Z14)/2 -> 0.002836156 | Z14: =$E$3*$J$82*0.453592*947817/1000000 -> 0.002836156 | AA14: =IF($E$3*$C83*0.000947817>AB14,$E$3*$C83*0.000947817,AB14) -> 0.0029322011 | AB14: =IF($E$3*$D83*0.000947817>AC14,$E$3*$D83*0.000947817,AC14) -> 0.0029322011 | AC14: =$E$3*$H$83*0.453592*947817/1000000 -> 0.002836156 | AD14: =$E$3*$I$83*0.453592*947817/1000000 -> 0.002836156 | AE14: =(AD14+AF14)/2 -> 0.002836156 | AF14: =$E$3*$J$83*0.453592*947817/1000000 -> 0.002836156 | AG14: =IF($E$3*$C84*0.000947817>AH14,$E$3*$C84*0.000947817,AH14) -> 0.00038666625 | AH14: =IF($E$3*$D84*0.000947817>AI14,$E$3*$D84*0.000947817,AI14) -> 0.00038666625 | AI14: =$E$3*$H$84*0.453592*947817/1000000 -> 0.00036095069 | AJ14: =$E$3*$I$84*0.453592*947817/1000000 -> 0.00036095069 | AK14: =(AJ14+AL14)/2 -> 0.00036095069 | AL14: =$E$3*$J$84*0.453592*947817/1000000 -> 0.00036095069 | AM14: =IF($E$3*$C85*0.000947817>AN14,$E$3*$C85*0.000947817,AN14) -> 0.0010072856 | AN14: =IF($E$3*$D85*0.000947817>AO14,$E$3*$D85*0.000947817,AO14) -> 0.0010072856 | AO14: =$E$3*$H$85*0.453592*947817/1000000 -> 0.0010072856 | AP14: =$E$3*$I$85*0.453592*947817/1000000 -> 0.0010072856 | AQ14: =(AP14+AR14)/2 -> 0.0010072856 | AR14: =$E$3*$J$85*0.453592*947817/1000000 -> 0.0010072856 | AS14: =IF($E$3*$C86*0.000947817>AT14,$E$3*$C86*0.000947817,AT14) -> 0.00095040196 | AT14: =IF($E$3*$D86*0.000947817>AU14,$E$3*$D86*0.000947817,AU14) -> 0.00011495757 | AU14: =$E$3*$H$86*0.453592*947817/1000000 -> 0.00011495757 | AV14: =$E$3*$I$86*0.453592*947817/1000000 -> 0.00011495757 | AW14: =(AV14+AX14)/2 -> 0.00011495757 | AX14: =$E$3*$J$86*0.453592*947817/1000000 -> 0.00011495757 | AY14: =$E$3*AA14*#REF! -> #REF! | AZ14: =$E$3*AB14*#REF! -> #REF! | BA14: =$E$3*$H$87*0.453592*947817/1000000 -> 0.0010777393 | BB14: =$E$3*$I$87*0.453592*947817/1000000 -> 0.0010777393 | BC14: =(BB14+BD14)/2 -> 0.0010777393 | BD14: =$E$3*$J$87*0.453592*947817/1000000 -> 0.0010777393 | BE14: =IF($E$3*$C88*0.000947817>BF14,$E$3*$C88*0.000947817,BF14) -> 50.74211 | BF14: =IF($E$3*$D88*0.000947817>BG14,$E$3*$D88*0.000947817,BG14) -> 50.74211 | BG14: =$E$3*$H$88*0.453592*947817/1000000 -> 50.74211 | BH14: =$E$3*$I$88*0.453592*947817/1000000 -> 50.74211 | BI14: =(BH14+BJ14)/2 -> 50.74211 | BJ14: =$E$3*$J$88*0.453592*947817/1000000 -> 50.74211 | BK14: =$E$3*AA14*#REF! -> #REF! | BL14: =$E$3*AB14*#REF! -> #REF! | BM14: =$E$3*AC14*#REF! -> #REF! | BO14: =(BN14+BP14)/2 -> #REF! | BP14: =$E$3*AF14*#REF! -> #REF!
B15: Natural gas turbine (large) | C15: =IF($E$3*$C91*0.000947817>D15,$E$3*$C91*0.000947817,D15) -> 0.0035896415 | D15: =IF($E$3*$D91*0.000947817>E15,$E$3*$D91*0.000947817,E15) -> 0.0011356571 | E15: =$E$3*$H$91*0.453592*947817/1000000 -> 0.00096598296 | F15: =$E$3*$I$91*0.453592*947817/1000000 -> 0.00096598296 | G15: =(F15+H15)/2 -> 0.00096598296 | H15: =$E$3*$J$91*0.453592*947817/1000000 -> 0.00096598296 | I15: =IF($E$3*$C92*0.000947817>J15,$E$3*$C92*0.000947817,J15) -> 0.043063635 | J15: =IF($E$3*$D92*0.000947817>K15,$E$3*$D92*0.000947817,K15) -> 0.043063635 | K15: =$E$3*$H$92*0.453592*947817/1000000 -> 0.018329644 | L15: =$E$3*$I$92*0.453592*947817/1000000 -> 0.018329644 | M15: =(L15+N15)/2 -> 0.018329644 | N15: =$E$3*$J$92*0.453592*947817/1000000 -> 0.018329644 | O15: =IF($E$3*$C93*0.000947817>P15,$E$3*$C93*0.000947817,P15) -> 0.039193956 | P15: =IF($E$3*$D93*0.000947817>Q15,$E$3*$D93*0.000947817,Q15) -> 0.031011323 | Q15: =$E$3*$H$93*0.453592*947817/1000000 -> 0.031011323 | R15: =$E$3*$I$93*0.453592*947817/1000000 -> 0.031011323 | S15: =(R15+T15)/2 -> 0.031011323 | T15: =$E$3*$J$93*0.453592*947817/1000000 -> 0.031011323 | U15: =IF($E$3*$C94*0.000947817>V15,$E$3*$C94*0.000947817,V15) -> 0.0032432574 | V15: =IF($E$3*$D94*0.000947817>W15,$E$3*$D94*0.000947817,W15) -> 0.0032432574 | W15: =$E$3*$H$94*0.453592*947817/1000000 -> 0.0030358202 | X15: =$E$3*$I$94*0.453592*947817/1000000 -> 0.0030358202 | Y15: =(X15+Z15)/2 -> 0.0030358202 | Z15: =$E$3*$J$94*0.453592*947817/1000000 -> 0.0030358202 | AA15: =IF($E$3*$C95*0.000947817>AB15,$E$3*$C95*0.000947817,AB15) -> 0.0032432574 | AB15: =IF($E$3*$D95*0.000947817>AC15,$E$3*$D95*0.000947817,AC15) -> 0.0032432574 | AC15: =$E$3*$H$95*0.453592*947817/1000000 -> 0.0030358202 | AD15: =$E$3*$I$95*0.453592*947817/1000000 -> 0.0030358202 | AE15: =(AD15+AF15)/2 -> 0.0030358202 | AF15: =$E$3*$J$95*0.453592*947817/1000000 -> 0.0030358202 | AG15: =IF($E$3*$C96*0.000947817>AH15,$E$3*$C96*0.000947817,AH15) -> 0.00057269621 | AH15: =IF($E$3*$D96*0.000947817>AI15,$E$3*$D96*0.000947817,AI15) -> 0.00057269621 | AI15: =$E$3*$H$96*0.453592*947817/1000000 -> 0.00057269621 | AJ15: =$E$3*$I$96*0.453592*947817/1000000 -> 0.00057269621 | AK15: =(AJ15+AL15)/2 -> 0.00057269621 | AL15: =$E$3*$J$96*0.453592*947817/1000000 -> 0.00057269621 | AM15: =IF($E$3*$C97*0.000947817>AN15,$E$3*$C97*0.000947817,AN15) -> 0.0036706367 | AN15: =IF($E$3*$D97*0.000947817>AO15,$E$3*$D97*0.000947817,AO15) -> 0.0036706367 | AO15: =$E$3*$H$97*0.453592*947817/1000000 -> 0.0010932488 | AP15: =$E$3*$I$97*0.453592*947817/1000000 -> 0.0010932488 | AQ15: =(AP15+AR15)/2 -> 0.0010932488 | AR15: =$E$3*$J$97*0.453592*947817/1000000 -> 0.0010932488 | AS15: =IF($E$3*$C98*0.000947817>AT15,$E$3*$C98*0.000947817,AT15) -> 0.0012924777 | AT15: =IF($E$3*$D98*0.000947817>AU15,$E$3*$D98*0.000947817,AU15) -> 0.0012924777 | AU15: =$E$3*$H$98*0.453592*947817/1000000 -> 0.00011842792 | AV15: =$E$3*$I$98*0.453592*947817/1000000 -> 0.00011842792 | AW15: =(AV15+AX15)/2 -> 0.00011842792 | AX15: =$E$3*$J$98*0.453592*947817/1000000 -> 0.00011842792 | AY15: =$E$3*AA15*#REF! -> #REF! | AZ15: =$E$3*AB15*#REF! -> #REF! | BA15: =$E$3*$H$99*0.453592*947817/1000000 -> 0.0019269206 | BB15: =$E$3*$I$99*0.453592*947817/1000000 -> 0.0019269206 | BC15: =(BB15+BD15)/2 -> 0.0019269206 | BD15: =$E$3*$J$99*0.453592*947817/1000000 -> 0.0019269206 | BE15: =IF($E$3*$C100*0.000947817>BF15,$E$3*$C100*0.000947817,BF15) -> 55.024794 | BF15: =IF($E$3*$D100*0.000947817>BG15,$E$3*$D100*0.000947817,BG15) -> 55.024794 | BG15: =$E$3*$H$100*0.453592*947817/1000000 -> 55.024794 | BH15: =$E$3*$I$100*0.453592*947817/1000000 -> 55.024794 | BI15: =(BH15+BJ15)/2 -> 55.024794 | BJ15: =$E$3*$J$100*0.453592*947817/1000000 -> 55.024794 | BK15: =$E$3*AA15*#REF! -> #REF! | BL15: =$E$3*AB15*#REF! -> #REF! | BM15: =$E$3*AC15*#REF! -> #REF! | BO15: =(BN15+BP15)/2 -> #REF! | BP15: =$E$3*AF15*#REF! -> #REF!
