Workbook
Name AnswerData: #REF!
Name AnswerData: #REF!
Name bprint: #REF!
Name bprint: #REF!
Name CMM_ANN_COAL_PRODUCTION: #REF!
Name CMM_BASE_YR_SUPPLY_CURVE: Types!$A$3:$AA$43
Name CMM_CENSUS_DMD_SHARE_FCTR: #REF!
Name CMM_ORIGIN_DEST_RATE: #REF!
Name CMM_SUPPLY_CRV_TABLE: [1]cum2025curves!#REF!
Name CMM_SUPPLY_CRV_TABLE: [2]cum2025curves!#REF!
Name CMM_TRAN_RATE_ESC_COMP: 'Rate esc'!$B$3:$D$2274
Name cprint: #REF!
Name cprint: #REF!
Name exch_rate: #REF!
Name exch_rate: #REF!
Name fitfile: [3]MODEL!$D$38
Name fitfile: [4]MODEL!$D$38
Name INF: [3]MODEL!$H$14
Name INF: [4]MODEL!$H$14
Name million_short_tons_to_short_ton: [5]Steps!$Y$5
Name million_short_tons_to_short_ton: [6]Steps!$Y$5
Name MMBTU_to_PJ: [5]Steps!$Y$6
Name MMBTU_to_PJ: [6]Steps!$Y$6
Name PPP: [3]MODEL!$D$12
Name PPP: [4]MODEL!$D$12
Name PPPEX: [3]MODEL!$D$13
Name PPPEX: [4]MODEL!$D$13
Name rail_coal: #REF!
Name rail_coal: #REF!

Sheet ANSv6.1-Commodities
A1: ANSWER-Commodities
B7: CommName | C7: CommDesc | D7: CommUnit | E7: Set Memberships | F7: Comment

Sheet UC_COA
A2: Maximum capacity technology growth:
A3: ~UC_Sets: R_E: R0
A4: ~UC_Sets: T_SUC:
G5: ~UC_T
A6: UC_N | B6: Pset_PN | C6: Pset_CI | D6: Pset_CO | E6: UC_ATTR | F6: Year | G6: LimType | H6: UC_CAP~2010 | I6: UC_CAP~2015 | J6: UC_CAP~2020 | K6: UC_CAP~2025 | L6: UC_CAP~2030 | M6: UC_CAP~2035 | N6: UC_CAP~2040 | O6: UC_CAP~2045 | P6: UC_CAP~2050 | Q6: UC_CAP~2055 | R6: UC_CAP~RHS | S6: UC_RHSRTS | T6: UC_RHSRTS~0 | U6: UC_Desc
A7: UC_GrowthOfCOAUP1 | B7: =TechData_R0!B13 -> MINCNAPMU1 | E7: CAP, GROWTH | G7: UP | H7: =TechData_R0!G13 -> 1.05 | I7: =H7 -> 1.05 | J7: =I7 -> 1.05 | K7: =J7 -> 1.05 | L7: =K7 -> 1.05 | M7: =L7 -> 1.05 | N7: =M7 -> 1.05 | O7: =N7 -> 1.05 | P7: =O7 -> 1.05 | Q7: =P7 -> 1.05 | R7: =MAX(TechData_R0!F13,1) -> 1 | T7: 5
A8: UC_GrowthOfCOAUP2 | B8: =TechData_R0!B14 -> MINCNAPMU2 | E8: CAP, GROWTH | G8: UP | H8: =TechData_R0!G14 -> 1.05 | I8: =H8 -> 1.05 | J8: =I8 -> 1.05 | K8: =J8 -> 1.05 | L8: =K8 -> 1.05 | M8: =L8 -> 1.05 | N8: =M8 -> 1.05 | O8: =N8 -> 1.05 | P8: =O8 -> 1.05 | Q8: =P8 -> 1.05 | R8: =MAX(TechData_R0!F14,1) -> 1 | T8: 5
A9: UC_GrowthOfCOAUP3 | B9: =TechData_R0!B15 -> MINCNAPMU3 | E9: CAP, GROWTH | G9: UP | H9: =TechData_R0!G15 -> 1.05 | I9: =H9 -> 1.05 | J9: =I9 -> 1.05 | K9: =J9 -> 1.05 | L9: =K9 -> 1.05 | M9: =L9 -> 1.05 | N9: =M9 -> 1.05 | O9: =N9 -> 1.05 | P9: =O9 -> 1.05 | Q9: =P9 -> 1.05 | R9: =MAX(TechData_R0!F15,1) -> 1 | T9: 5
A10: UC_GrowthOfCOAUP4 | B10: =TechData_R0!B16 -> MINCNAPMU4 | E10: CAP, GROWTH | G10: UP | H10: =TechData_R0!G16 -> 1.05 | I10: =H10 -> 1.05 | J10: =I10 -> 1.05 | K10: =J10 -> 1.05 | L10: =K10 -> 1.05 | M10: =L10 -> 1.05 | N10: =M10 -> 1.05 | O10: =N10 -> 1.05 | P10: =O10 -> 1.05 | Q10: =P10 -> 1.05 | R10: =MAX(TechData_R0!F16,1) -> 1 | T10: 5
A11: UC_GrowthOfCOAUP5 | B11: =TechData_R0!B17 -> MINCNAPMU5 | E11: CAP, GROWTH | G11: UP | H11: =TechData_R0!G17 -> 1.05 | I11: =H11 -> 1.05 | J11: =I11 -> 1.05 | K11: =J11 -> 1.05 | L11: =K11 -> 1.05 | M11: =L11 -> 1.05 | N11: =M11 -> 1.05 | O11: =N11 -> 1.05 | P11: =O11 -> 1.05 | Q11: =P11 -> 1.05 | R11: =MAX(TechData_R0!F17,1) -> 5.0108652 | T11: 5
A12: UC_GrowthOfCOAUP6 | B12: =TechData_R0!B18 -> MINCNAPMU6 | E12: CAP, GROWTH | G12: UP | H12: =TechData_R0!G18 -> 1.05 | I12: =H12 -> 1.05 | J12: =I12 -> 1.05 | K12: =J12 -> 1.05 | L12: =K12 -> 1.05 | M12: =L12 -> 1.05 | N12: =M12 -> 1.05 | O12: =N12 -> 1.05 | P12: =O12 -> 1.05 | Q12: =P12 -> 1.05 | R12: =MAX(TechData_R0!F18,1) -> 5.567628 | T12: 5
A13: UC_GrowthOfCOAUP8 | B13: =TechData_R0!B20 -> MINCNABMU1 | E13: CAP, GROWTH | G13: UP | H13: =TechData_R0!G20 -> 1.05 | I13: =H13 -> 1.05 | J13: =I13 -> 1.05 | K13: =J13 -> 1.05 | L13: =K13 -> 1.05 | M13: =L13 -> 1.05 | N13: =M13 -> 1.05 | O13: =N13 -> 1.05 | P13: =O13 -> 1.05 | Q13: =P13 -> 1.05 | R13: =MAX(TechData_R0!F19,1) -> 1 | T13: 5
A14: UC_GrowthOfCOAUP9 | B14: =TechData_R0!B21 -> MINCNABMU2 | E14: CAP, GROWTH | G14: UP | H14: =TechData_R0!G21 -> 1.05 | I14: =H14 -> 1.05 | J14: =I14 -> 1.05 | K14: =J14 -> 1.05 | L14: =K14 -> 1.05 | M14: =L14 -> 1.05 | N14: =M14 -> 1.05 | O14: =N14 -> 1.05 | P14: =O14 -> 1.05 | Q14: =P14 -> 1.05 | R14: =MAX(TechData_R0!F20,1) -> 1 | T14: 5
A15: UC_GrowthOfCOAUP10 | B15: =TechData_R0!B22 -> MINCNABMU3 | E15: CAP, GROWTH | G15: UP | H15: =TechData_R0!G22 -> 1.05 | I15: =H15 -> 1.05 | J15: =I15 -> 1.05 | K15: =J15 -> 1.05 | L15: =K15 -> 1.05 | M15: =L15 -> 1.05 | N15: =M15 -> 1.05 | O15: =N15 -> 1.05 | P15: =O15 -> 1.05 | Q15: =P15 -> 1.05 | R15: =MAX(TechData_R0!F21,1) -> 1 | T15: 5
A16: UC_GrowthOfCOAUP11 | B16: =TechData_R0!B23 -> MINCNABMU4 | E16: CAP, GROWTH | G16: UP | H16: =TechData_R0!G23 -> 1.05 | I16: =H16 -> 1.05 | J16: =I16 -> 1.05 | K16: =J16 -> 1.05 | L16: =K16 -> 1.05 | M16: =L16 -> 1.05 | N16: =M16 -> 1.05 | O16: =N16 -> 1.05 | P16: =O16 -> 1.05 | Q16: =P16 -> 1.05 | R16: =MAX(TechData_R0!F22,1) -> 1 | T16: 5
A17: UC_GrowthOfCOAUP12 | B17: =TechData_R0!B24 -> MINCNABMU5 | E17: CAP, GROWTH | G17: UP | H17: =TechData_R0!G24 -> 1.05 | I17: =H17 -> 1.05 | J17: =I17 -> 1.05 | K17: =J17 -> 1.05 | L17: =K17 -> 1.05 | M17: =L17 -> 1.05 | N17: =M17 -> 1.05 | O17: =N17 -> 1.05 | P17: =O17 -> 1.05 | Q17: =P17 -> 1.05 | R17: =MAX(TechData_R0!F23,1) -> 1 | T17: 5
A18: UC_GrowthOfCOAUP13 | B18: =TechData_R0!B25 -> MINCNABMU6 | E18: CAP, GROWTH | G18: UP | H18: =TechData_R0!G25 -> 1.05 | I18: =H18 -> 1.05 | J18: =I18 -> 1.05 | K18: =J18 -> 1.05 | L18: =K18 -> 1.05 | M18: =L18 -> 1.05 | N18: =M18 -> 1.05 | O18: =N18 -> 1.05 | P18: =O18 -> 1.05 | Q18: =P18 -> 1.05 | R18: =MAX(TechData_R0!F24,1) -> 7.146641 | T18: 5
A19: UC_GrowthOfCOAUP15 | B19: =TechData_R0!B27 -> MINCNABMS1 | E19: CAP, GROWTH | G19: UP | H19: =TechData_R0!G27 -> 1.05 | I19: =H19 -> 1.05 | J19: =I19 -> 1.05 | K19: =J19 -> 1.05 | L19: =K19 -> 1.05 | M19: =L19 -> 1.05 | N19: =M19 -> 1.05 | O19: =N19 -> 1.05 | P19: =O19 -> 1.05 | Q19: =P19 -> 1.05 | R19: =MAX(TechData_R0!F26,1) -> 1 | T19: 5
A20: UC_GrowthOfCOAUP16 | B20: =TechData_R0!B28 -> MINCNABMS2 | E20: CAP, GROWTH | G20: UP | H20: =TechData_R0!G28 -> 1.05 | I20: =H20 -> 1.05 | J20: =I20 -> 1.05 | K20: =J20 -> 1.05 | L20: =K20 -> 1.05 | M20: =L20 -> 1.05 | N20: =M20 -> 1.05 | O20: =N20 -> 1.05 | P20: =O20 -> 1.05 | Q20: =P20 -> 1.05 | R20: =MAX(TechData_R0!F27,1) -> 1 | T20: 5
A21: UC_GrowthOfCOAUP17 | B21: =TechData_R0!B29 -> MINCNABMS3 | E21: CAP, GROWTH | G21: UP | H21: =TechData_R0!G29 -> 1.05 | I21: =H21 -> 1.05 | J21: =I21 -> 1.05 | K21: =J21 -> 1.05 | L21: =K21 -> 1.05 | M21: =L21 -> 1.05 | N21: =M21 -> 1.05 | O21: =N21 -> 1.05 | P21: =O21 -> 1.05 | Q21: =P21 -> 1.05 | R21: =MAX(TechData_R0!F28,1) -> 1 | T21: 5
A22: UC_GrowthOfCOAUP18 | B22: =TechData_R0!B30 -> MINCNABMS4 | E22: CAP, GROWTH | G22: UP | H22: =TechData_R0!G30 -> 1.05 | I22: =H22 -> 1.05 | J22: =I22 -> 1.05 | K22: =J22 -> 1.05 | L22: =K22 -> 1.05 | M22: =L22 -> 1.05 | N22: =M22 -> 1.05 | O22: =N22 -> 1.05 | P22: =O22 -> 1.05 | Q22: =P22 -> 1.05 | R22: =MAX(TechData_R0!F29,1) -> 1 | T22: 5
A23: UC_GrowthOfCOAUP19 | B23: =TechData_R0!B31 -> MINCNABMS5 | E23: CAP, GROWTH | G23: UP | H23: =TechData_R0!G31 -> 1.05 | I23: =H23 -> 1.05 | J23: =I23 -> 1.05 | K23: =J23 -> 1.05 | L23: =K23 -> 1.05 | M23: =L23 -> 1.05 | N23: =M23 -> 1.05 | O23: =N23 -> 1.05 | P23: =O23 -> 1.05 | Q23: =P23 -> 1.05 | R23: =MAX(TechData_R0!F30,1) -> 1 | T23: 5
A24: UC_GrowthOfCOAUP20 | B24: =TechData_R0!B32 -> MINCNABMS6 | E24: CAP, GROWTH | G24: UP | H24: =TechData_R0!G32 -> 1.05 | I24: =H24 -> 1.05 | J24: =I24 -> 1.05 | K24: =J24 -> 1.05 | L24: =K24 -> 1.05 | M24: =L24 -> 1.05 | N24: =M24 -> 1.05 | O24: =N24 -> 1.05 | P24: =O24 -> 1.05 | Q24: =P24 -> 1.05 | R24: =MAX(TechData_R0!F31,1) -> 2.4977947 | T24: 5
A25: UC_GrowthOfCOAUP22 | B25: =TechData_R0!B34 -> MINCNABHU1 | E25: CAP, GROWTH | G25: UP | H25: =TechData_R0!G34 -> 1.05 | I25: =H25 -> 1.05 | J25: =I25 -> 1.05 | K25: =J25 -> 1.05 | L25: =K25 -> 1.05 | M25: =L25 -> 1.05 | N25: =M25 -> 1.05 | O25: =N25 -> 1.05 | P25: =O25 -> 1.05 | Q25: =P25 -> 1.05 | R25: =MAX(TechData_R0!F33,1) -> 1 | T25: 5
A26: UC_GrowthOfCOAUP23 | B26: =TechData_R0!B35 -> MINCNABHU2 | E26: CAP, GROWTH | G26: UP | H26: =TechData_R0!G35 -> 1.05 | I26: =H26 -> 1.05 | J26: =I26 -> 1.05 | K26: =J26 -> 1.05 | L26: =K26 -> 1.05 | M26: =L26 -> 1.05 | N26: =M26 -> 1.05 | O26: =N26 -> 1.05 | P26: =O26 -> 1.05 | Q26: =P26 -> 1.05 | R26: =MAX(TechData_R0!F34,1) -> 1 | T26: 5
A27: UC_GrowthOfCOAUP24 | B27: =TechData_R0!B36 -> MINCNABHU3 | E27: CAP, GROWTH | G27: UP | H27: =TechData_R0!G36 -> 1.05 | I27: =H27 -> 1.05 | J27: =I27 -> 1.05 | K27: =J27 -> 1.05 | L27: =K27 -> 1.05 | M27: =L27 -> 1.05 | N27: =M27 -> 1.05 | O27: =N27 -> 1.05 | P27: =O27 -> 1.05 | Q27: =P27 -> 1.05 | R27: =MAX(TechData_R0!F35,1) -> 1 | T27: 5
A28: UC_GrowthOfCOAUP25 | B28: =TechData_R0!B37 -> MINCNABHU4 | E28: CAP, GROWTH | G28: UP | H28: =TechData_R0!G37 -> 1.05 | I28: =H28 -> 1.05 | J28: =I28 -> 1.05 | K28: =J28 -> 1.05 | L28: =K28 -> 1.05 | M28: =L28 -> 1.05 | N28: =M28 -> 1.05 | O28: =N28 -> 1.05 | P28: =O28 -> 1.05 | Q28: =P28 -> 1.05 | R28: =MAX(TechData_R0!F36,1) -> 1 | T28: 5
A29: UC_GrowthOfCOAUP26 | B29: =TechData_R0!B38 -> MINCNABHU5 | E29: CAP, GROWTH | G29: UP | H29: =TechData_R0!G38 -> 1.05 | I29: =H29 -> 1.05 | J29: =I29 -> 1.05 | K29: =J29 -> 1.05 | L29: =K29 -> 1.05 | M29: =L29 -> 1.05 | N29: =M29 -> 1.05 | O29: =N29 -> 1.05 | P29: =O29 -> 1.05 | Q29: =P29 -> 1.05 | R29: =MAX(TechData_R0!F37,1) -> 1 | T29: 5
A30: UC_GrowthOfCOAUP27 | B30: =TechData_R0!B39 -> MINCNABHU6 | E30: CAP, GROWTH | G30: UP | H30: =TechData_R0!G39 -> 1.05 | I30: =H30 -> 1.05 | J30: =I30 -> 1.05 | K30: =J30 -> 1.05 | L30: =K30 -> 1.05 | M30: =L30 -> 1.05 | N30: =M30 -> 1.05 | O30: =N30 -> 1.05 | P30: =O30 -> 1.05 | Q30: =P30 -> 1.05 | R30: =MAX(TechData_R0!F38,1) -> 16.153404 | T30: 5
A31: UC_GrowthOfCOAUP29 | B31: =TechData_R0!B41 -> MINCNABHS1 | E31: CAP, GROWTH | G31: UP | H31: =TechData_R0!G41 -> 1.05 | I31: =H31 -> 1.05 | J31: =I31 -> 1.05 | K31: =J31 -> 1.05 | L31: =K31 -> 1.05 | M31: =L31 -> 1.05 | N31: =M31 -> 1.05 | O31: =N31 -> 1.05 | P31: =O31 -> 1.05 | Q31: =P31 -> 1.05 | R31: =MAX(TechData_R0!F40,1) -> 1 | T31: 5
A32: UC_GrowthOfCOAUP30 | B32: =TechData_R0!B42 -> MINCNABHS2 | E32: CAP, GROWTH | G32: UP | H32: =TechData_R0!G42 -> 1.05 | I32: =H32 -> 1.05 | J32: =I32 -> 1.05 | K32: =J32 -> 1.05 | L32: =K32 -> 1.05 | M32: =L32 -> 1.05 | N32: =M32 -> 1.05 | O32: =N32 -> 1.05 | P32: =O32 -> 1.05 | Q32: =P32 -> 1.05 | R32: =MAX(TechData_R0!F41,1) -> 1 | T32: 5
A33: UC_GrowthOfCOAUP31 | B33: =TechData_R0!B43 -> MINCNABHS3 | E33: CAP, GROWTH | G33: UP | H33: =TechData_R0!G43 -> 1.05 | I33: =H33 -> 1.05 | J33: =I33 -> 1.05 | K33: =J33 -> 1.05 | L33: =K33 -> 1.05 | M33: =L33 -> 1.05 | N33: =M33 -> 1.05 | O33: =N33 -> 1.05 | P33: =O33 -> 1.05 | Q33: =P33 -> 1.05 | R33: =MAX(TechData_R0!F42,1) -> 1 | T33: 5
A34: UC_GrowthOfCOAUP32 | B34: =TechData_R0!B44 -> MINCNABHS4 | E34: CAP, GROWTH | G34: UP | H34: =TechData_R0!G44 -> 1.05 | I34: =H34 -> 1.05 | J34: =I34 -> 1.05 | K34: =J34 -> 1.05 | L34: =K34 -> 1.05 | M34: =L34 -> 1.05 | N34: =M34 -> 1.05 | O34: =N34 -> 1.05 | P34: =O34 -> 1.05 | Q34: =P34 -> 1.05 | R34: =MAX(TechData_R0!F43,1) -> 1 | T34: 5
A35: UC_GrowthOfCOAUP33 | B35: =TechData_R0!B45 -> MINCNABHS5 | E35: CAP, GROWTH | G35: UP | H35: =TechData_R0!G45 -> 1.05 | I35: =H35 -> 1.05 | J35: =I35 -> 1.05 | K35: =J35 -> 1.05 | L35: =K35 -> 1.05 | M35: =L35 -> 1.05 | N35: =M35 -> 1.05 | O35: =N35 -> 1.05 | P35: =O35 -> 1.05 | Q35: =P35 -> 1.05 | R35: =MAX(TechData_R0!F44,1) -> 1 | T35: 5
A36: UC_GrowthOfCOAUP34 | B36: =TechData_R0!B46 -> MINCNABHS6 | E36: CAP, GROWTH | G36: UP | H36: =TechData_R0!G46 -> 1.05 | I36: =H36 -> 1.05 | J36: =I36 -> 1.05 | K36: =J36 -> 1.05 | L36: =K36 -> 1.05 | M36: =L36 -> 1.05 | N36: =M36 -> 1.05 | O36: =N36 -> 1.05 | P36: =O36 -> 1.05 | Q36: =P36 -> 1.05 | R36: =MAX(TechData_R0!F45,1) -> 3.9360356 | T36: 5
A37: UC_GrowthOfCOAUP36 | B37: =TechData_R0!B48 -> MINCCAPMU1 | E37: CAP, GROWTH | G37: UP | H37: =TechData_R0!G48 -> 1.05 | I37: =H37 -> 1.05 | J37: =I37 -> 1.05 | K37: =J37 -> 1.05 | L37: =K37 -> 1.05 | M37: =L37 -> 1.05 | N37: =M37 -> 1.05 | O37: =N37 -> 1.05 | P37: =O37 -> 1.05 | Q37: =P37 -> 1.05 | R37: =MAX(TechData_R0!F47,1) -> 1 | T37: 5
A38: UC_GrowthOfCOAUP37 | B38: =TechData_R0!B49 -> MINCCAPMU2 | E38: CAP, GROWTH | G38: UP | H38: =TechData_R0!G49 -> 1.05 | I38: =H38 -> 1.05 | J38: =I38 -> 1.05 | K38: =J38 -> 1.05 | L38: =K38 -> 1.05 | M38: =L38 -> 1.05 | N38: =M38 -> 1.05 | O38: =N38 -> 1.05 | P38: =O38 -> 1.05 | Q38: =P38 -> 1.05 | R38: =MAX(TechData_R0!F48,1) -> 1 | T38: 5
A39: UC_GrowthOfCOAUP38 | B39: =TechData_R0!B50 -> MINCCAPMU3 | E39: CAP, GROWTH | G39: UP | H39: =TechData_R0!G50 -> 1.05 | I39: =H39 -> 1.05 | J39: =I39 -> 1.05 | K39: =J39 -> 1.05 | L39: =K39 -> 1.05 | M39: =L39 -> 1.05 | N39: =M39 -> 1.05 | O39: =N39 -> 1.05 | P39: =O39 -> 1.05 | Q39: =P39 -> 1.05 | R39: =MAX(TechData_R0!F49,1) -> 1 | T39: 5
A40: UC_GrowthOfCOAUP39 | B40: =TechData_R0!B51 -> MINCCAPMU4 | E40: CAP, GROWTH | G40: UP | H40: =TechData_R0!G51 -> 1.05 | I40: =H40 -> 1.05 | J40: =I40 -> 1.05 | K40: =J40 -> 1.05 | L40: =K40 -> 1.05 | M40: =L40 -> 1.05 | N40: =M40 -> 1.05 | O40: =N40 -> 1.05 | P40: =O40 -> 1.05 | Q40: =P40 -> 1.05 | R40: =MAX(TechData_R0!F50,1) -> 1 | T40: 5
A41: UC_GrowthOfCOAUP40 | B41: =TechData_R0!B52 -> MINCCAPMU5 | E41: CAP, GROWTH | G41: UP | H41: =TechData_R0!G52 -> 1.05 | I41: =H41 -> 1.05 | J41: =I41 -> 1.05 | K41: =J41 -> 1.05 | L41: =K41 -> 1.05 | M41: =L41 -> 1.05 | N41: =M41 -> 1.05 | O41: =N41 -> 1.05 | P41: =O41 -> 1.05 | Q41: =P41 -> 1.05 | R41: =MAX(TechData_R0!F51,1) -> 1 | T41: 5
...

Sheet TechData_R0
A1: TechData | B1: R0 | J1: * | W1: * | X1: *
N4: 0.9
E5: START | F5: GROWTH_TIDr = right hand side of the growth constraint | G5: GROWTHr = growth rate | H5: GROWTHr | I5: GROWTHr | J5: DECAYr = decay rate of the production | K5: DECAYr | L5: COST | M5: COST | N5: COST | O5: COST | P5: COST | Q5: COST | R5: COST | S5: COST | T5: COST | U5: COST | V5: CUM | W5: BOUND(LO)Or | X5: BOUND(UP)Or
A11: Region | B11: TechName | C11: *TechDesc | D11: CommOUT | E11: *TID | F11: *TID | G11: *2010 | H11: *2015-2020 | I11: *2025-2055 | J11: *2010 | K11: *2010-2055 | L11: COST~2010 | M11: COST~2015 | N11: COST~2020 | O11: COST~2025 | P11: COST~2030 | Q11: COST~2035 | R11: COST~2040 | S11: COST~2045 | T11: COST~2050 | U11: COST~2055 | V11: ACT_BND~LO~2010 | W11: ACT_BND~UP~2005 | X11: ACT_BND~UP~2010
A12: *Coal minning
A13: R0 | B13: MINCNAPMU1 | C13: MIN.COA.NA.PMU.1 | D13: =CONCATENATE(MID(B13,4,6),"1") -> CNAPMU1 | E13: 2010 | G13: 1.05 | H13: 1.05 | I13: 1.05 | J13: 1.05 | K13: 1.005 | L13: =L15*'Production Steps'!$O$10 -> 2.4213307 | M13: =M15*'Production Steps'!$O$10 -> 2.9001275 | N13: =N15*'Production Steps'!$O$10 -> 3.3234457 | O13: =O15*'Production Steps'!$O$10 -> 3.9037571 | P13: =P15*'Production Steps'!$O$10 -> 4.2530556 | Q13: =Q15*'Production Steps'!$O$10 -> 4.6228547 | R13: =R15*'Production Steps'!$O$10 -> 5.0148483 | S13: =S15*'Production Steps'!$O$10 -> 5.4400809 | ... U13: =U15*'Production Steps'!$O$10 -> 6.4017761 | V13: =X13*0.8 -> 222.70512 | W13: ='Production Steps'!H7*1.1 -> 53.414848 | X13: ='Production Steps'!I7*1.1 -> 278.3814
B14: MINCNAPMU2 | C14: MIN.COA.NA.PMU.2 | D14: =CONCATENATE(MID(B14,4,6),"1") -> CNAPMU1 | E14: 2010 | G14: 1.05 | H14: 1.05 | I14: 1.05 | J14: 1.05 | K14: 1.005 | L14: =L15*'Production Steps'!$O$11 -> 2.7460091 | M14: =M15*'Production Steps'!$O$11 -> 3.2890082 | N14: =N15*'Production Steps'!$O$11 -> 3.7690896 | O14: =O15*'Production Steps'!$O$11 -> 4.4272154 | P14: =P15*'Production Steps'!$O$11 -> 4.8233517 | Q14: =Q15*'Production Steps'!$O$11 -> 5.2427375 | R14: =R15*'Production Steps'!$O$11 -> 5.6872939 | S14: =S15*'Production Steps'!$O$11 -> 6.1695463 | ... U14: =U15*'Production Steps'!$O$11 -> 7.2601961 | V14: =X14*0.8 -> 218.25102 | W14: ='Production Steps'!H8*1.1 -> 52.346551 | X14: ='Production Steps'!I8*1.1 -> 272.81377
B15: MINCNAPMU3 | C15: MIN.COA.NA.PMU.3 | D15: =CONCATENATE(MID(B15,4,6),"1") -> CNAPMU1 | E15: 2010 | G15: 1.05 | H15: 1.05 | I15: 1.05 | J15: 1.05 | K15: 1.005 | L15: ='AEO Coal Prices'!M7*'Production Steps'!$Q$17*$N$4 -> 2.7515122 | M15: ='AEO Coal Prices'!N7*'Production Steps'!$Q$17*$N$4 -> 3.2955994 | N15: ='AEO Coal Prices'!O7*'Production Steps'!$Q$17*$N$4 -> 3.7766429 | O15: ='AEO Coal Prices'!P7*'Production Steps'!$Q$17*$N$4 -> 4.4360876 | P15: ='AEO Coal Prices'!Q7*'Production Steps'!$Q$17*$N$4 -> 4.8330177 | Q15: ='AEO Coal Prices'!R7*'Production Steps'!$Q$17*$N$4 -> 5.253244 | R15: ='AEO Coal Prices'!S7*'Production Steps'!$Q$17*$N$4 -> 5.6986913 | S15: =R15*(1+(R15-Q15)/Q15) -> 6.1819102 | T15: =S15*(1+(S15-R15)/R15) -> 6.7061035 | U15: =T15*(1+(T15-S15)/S15) -> 7.2747456 | V15: =X15*0.8 -> 4.4541024 | W15: ='Production Steps'!H9*1.1 -> 1.068297 | X15: ='Production Steps'!I9*1.1 -> 5.567628
B16: MINCNAPMU4 | C16: MIN.COA.NA.PMU.4 | D16: =CONCATENATE(MID(B16,4,6),"1") -> CNAPMU1 | E16: 2010 | G16: 1.05 | H16: 1.05 | I16: 1.05 | J16: 1.05 | K16: 1.005 | L16: =L15*'Production Steps'!$O$13 -> 2.7597667 | M16: =M15*'Production Steps'!$O$13 -> 3.3054862 | N16: =N15*'Production Steps'!$O$13 -> 3.7879728 | O16: =O15*'Production Steps'!$O$13 -> 4.4493958 | P16: =P15*'Production Steps'!$O$13 -> 4.8475168 | Q16: =Q15*'Production Steps'!$O$13 -> 5.2690037 | R16: =R15*'Production Steps'!$O$13 -> 5.7157873 | S16: =S15*'Production Steps'!$O$13 -> 6.2004559 | ... U16: =U15*'Production Steps'!$O$13 -> 7.2965698 | V16: =X16*0.8 -> 4.4541024 | W16: ='Production Steps'!H10*1.1 -> 1.068297 | X16: ='Production Steps'!I10*1.1 -> 5.567628
B17: MINCNAPMU5 | C17: MIN.COA.NA.PMU.5 | D17: =CONCATENATE(MID(B17,4,6),"1") -> CNAPMU1 | E17: 2010 | F17: =X17*0.1 -> 5.0108652 | G17: 1.05 | H17: 1.05 | I17: 1.05 | J17: 1.05 | K17: 1.005 | L17: =L15*'Production Steps'!$O$14 -> 3.0816936 | M17: =M15*'Production Steps'!$O$14 -> 3.6910714 | N17: =N15*'Production Steps'!$O$14 -> 4.22984 | O17: =O15*'Production Steps'!$O$14 -> 4.9684181 | P17: =P15*'Production Steps'!$O$14 -> 5.4129798 | Q17: =Q15*'Production Steps'!$O$14 -> 5.8836332 | R17: =R15*'Production Steps'!$O$14 -> 6.3825342 | S17: =S15*'Production Steps'!$O$14 -> 6.9237394 | ... U17: =U15*'Production Steps'!$O$14 -> 8.147715 | W17: ='Production Steps'!H11*1.1 -> 9.6146726 | X17: ='Production Steps'!I11*1.1 -> 50.108652
B18: MINCNAPMU6 | C18: MIN.COA.NA.PMU.6 | D18: =CONCATENATE(MID(B18,4,6),"1") -> CNAPMU1 | E18: 2010 | F18: =X18*0.1 -> 5.567628 | G18: 1.05 | H18: 1.05 | I18: 1.05 | J18: 1.05 | K18: 1.005 | L18: =L15*'Production Steps'!$O$15 -> 4.2098136 | M18: =M15*'Production Steps'!$O$15 -> 5.0422672 | N18: =N15*'Production Steps'!$O$15 -> 5.7782636 | O18: =O15*'Production Steps'!$O$15 -> 6.787214 | P18: =P15*'Production Steps'!$O$15 -> 7.3945171 | Q18: =Q15*'Production Steps'!$O$15 -> 8.0374633 | R18: =R15*'Production Steps'!$O$15 -> 8.7189976 | S18: =S15*'Production Steps'!$O$15 -> 9.4583225 | ... U18: =U15*'Production Steps'!$O$15 -> 11.130361 | W18: ='Production Steps'!H12*1.1 -> 10.68297 | X18: ='Production Steps'!I12*1.1 -> 55.67628
A19: *
A20: R0 | B20: MINCNABMU1 | C20: MIN.COA.NA.BMU.1 | D20: =CONCATENATE(MID(B20,4,6),"1") -> CNABMU1 | E20: 2010 | G20: 1.05 | H20: 1.05 | I20: 1.05 | J20: 1.05 | K20: 1.05 | L20: =L22*'Production Steps'!$O$10 -> 1.6252417 | M20: =M22*'Production Steps'!$O$10 -> 1.7986292 | N20: =N22*'Production Steps'!$O$10 -> 1.958612 | O20: =O22*'Production Steps'!$O$10 -> 2.0465499 | P20: =P22*'Production Steps'!$O$10 -> 2.1387409 | Q20: =Q22*'Production Steps'!$O$10 -> 2.2263202 | R20: =R22*'Production Steps'!$O$10 -> 2.3239259 | S20: =S22*'Production Steps'!$O$10 -> 2.4258109 | ... U20: =U22*'Production Steps'!$O$10 -> 2.6431771 | V20: =X20*0.8 -> 317.62849 | W20: ='Production Steps'!H14*1.1*'Production Steps'!K14 -> 812.58462 | X20: ='Production Steps'!I14*1.1*'Production Steps'!K14 -> 397.03561
B21: MINCNABMU2 | C21: MIN.COA.NA.BMU.2 | D21: =CONCATENATE(MID(B21,4,6),"1") -> CNABMU1 | E21: 2010 | G21: 1.05 | H21: 1.05 | I21: 1.05 | J21: 1.05 | K21: 1.05 | L21: =L22*'Production Steps'!$O$11 -> 1.8431719 | M21: =M22*'Production Steps'!$O$11 -> 2.0398091 | N21: =N22*'Production Steps'!$O$11 -> 2.221244 | O21: =O22*'Production Steps'!$O$11 -> 2.3209736 | P21: =P22*'Production Steps'!$O$11 -> 2.4255266 | Q21: =Q22*'Production Steps'!$O$11 -> 2.5248495 | R21: =R22*'Production Steps'!$O$11 -> 2.6355433 | S21: =S22*'Production Steps'!$O$11 -> 2.7510901 | ... U21: =U22*'Production Steps'!$O$11 -> 2.9976031 | V21: =X21*0.8 -> 311.27592 | W21: ='Production Steps'!H15*1.1*'Production Steps'!K15 -> 796.33292 | X21: ='Production Steps'!I15*1.1*'Production Steps'!K15 -> 389.0949
B22: MINCNABMU3 | C22: MIN.COA.NA.BMU.3 | D22: =CONCATENATE(MID(B22,4,6),"1") -> CNABMU1 | E22: 2010 | G22: 1.05 | H22: 1.05 | I22: 1.05 | J22: 1.05 | K22: 1.05 | L22: ='AEO Coal Prices'!M8*'Production Steps'!$Q$17*$N$4 -> 1.8468656 | M22: ='AEO Coal Prices'!N8*'Production Steps'!$Q$17*$N$4 -> 2.0438969 | N22: ='AEO Coal Prices'!O8*'Production Steps'!$Q$17*$N$4 -> 2.2256954 | O22: ='AEO Coal Prices'!P8*'Production Steps'!$Q$17*$N$4 -> 2.3256249 | P22: ='AEO Coal Prices'!Q8*'Production Steps'!$Q$17*$N$4 -> 2.4303874 | Q22: ='AEO Coal Prices'!R8*'Production Steps'!$Q$17*$N$4 -> 2.5299093 | R22: ='AEO Coal Prices'!S8*'Production Steps'!$Q$17*$N$4 -> 2.6408249 | S22: =R22*(1+(R22-Q22)/Q22) -> 2.7566033 | T22: =S22*(1+(S22-R22)/R22) -> 2.8774576 | U22: =T22*(1+(T22-S22)/S22) -> 3.0036103 | V22: =X22*0.8 -> 6.3525698 | W22: ='Production Steps'!H16*1.1*'Production Steps'!K16 -> 16.251692 | X22: ='Production Steps'!I16*1.1*'Production Steps'!K16 -> 7.9407123
B23: MINCNABMU4 | C23: MIN.COA.NA.BMU.4 | D23: =CONCATENATE(MID(B23,4,6),"1") -> CNABMU1 | E23: 2010 | G23: 1.05 | H23: 1.05 | I23: 1.05 | J23: 1.05 | K23: 1.05 | L23: =L22*'Production Steps'!$O$13 -> 1.8524062 | M23: =M22*'Production Steps'!$O$13 -> 2.0500286 | N23: =N22*'Production Steps'!$O$13 -> 2.2323725 | O23: =O22*'Production Steps'!$O$13 -> 2.3326018 | P23: =P22*'Production Steps'!$O$13 -> 2.4376786 | Q23: =Q22*'Production Steps'!$O$13 -> 2.537499 | R23: =R22*'Production Steps'!$O$13 -> 2.6487474 | S23: =S22*'Production Steps'!$O$13 -> 2.7648731 | ... U23: =U22*'Production Steps'!$O$13 -> 3.0126212 | V23: =X23*0.8 -> 6.3525698 | W23: ='Production Steps'!H17*1.1*'Production Steps'!K17 -> 16.251692 | X23: ='Production Steps'!I17*1.1*'Production Steps'!K17 -> 7.9407123
B24: MINCNABMU5 | C24: MIN.COA.NA.BMU.5 | D24: =CONCATENATE(MID(B24,4,6),"1") -> CNABMU1 | E24: 2010 | F24: =X24*0.1 -> 7.146641 | G24: 1.05 | H24: 1.05 | I24: 1.05 | J24: 1.05 | K24: 1.05 | L24: =L22*'Production Steps'!$O$14 -> 2.0684895 | M24: =M22*'Production Steps'!$O$14 -> 2.2891645 | N24: =N22*'Production Steps'!$O$14 -> 2.4927788 | O24: =O22*'Production Steps'!$O$14 -> 2.6046999 | P24: =P22*'Production Steps'!$O$14 -> 2.7220339 | Q24: =Q22*'Production Steps'!$O$14 -> 2.8334984 | R24: =R22*'Production Steps'!$O$14 -> 2.9577239 | S24: =S22*'Production Steps'!$O$14 -> 3.0873957 | ... U24: =U22*'Production Steps'!$O$14 -> 3.3640436 | W24: ='Production Steps'!H18*1.1*'Production Steps'!K18 -> 146.26523 | X24: ='Production Steps'!I18*1.1*'Production Steps'!K18 -> 71.46641
B25: MINCNABMU6 | C25: MIN.COA.NA.BMU.6 | D25: =CONCATENATE(MID(B25,4,6),"1") -> CNABMU1 | E25: 2010 | F25: =X25*0.1 -> 7.9407123 | G25: 1.05 | H25: 1.05 | I25: 1.05 | J25: 1.05 | K25: 1.05 | L25: =L22*'Production Steps'!$O$15 -> 2.8257044 | M25: =M22*'Production Steps'!$O$15 -> 3.1271622 | N25: =N22*'Production Steps'!$O$15 -> 3.405314 | O25: =O22*'Production Steps'!$O$15 -> 3.5582061 | P25: =P22*'Production Steps'!$O$15 -> 3.7184927 | Q25: =Q22*'Production Steps'!$O$15 -> 3.8707612 | R25: =R22*'Production Steps'!$O$15 -> 4.0404622 | S25: =S22*'Production Steps'!$O$15 -> 4.2176031 | ... U25: =U22*'Production Steps'!$O$15 -> 4.5955238 | W25: ='Production Steps'!H19*1.1*'Production Steps'!K19 -> 162.51692 | X25: ='Production Steps'!I19*1.1*'Production Steps'!K19 -> 79.407123
A26: *
A27: R0 | B27: MINCNABMS1 | C27: MIN.COA.NA.BMS.1 | D27: =CONCATENATE(MID(B27,4,6),"1") -> CNABMS1 | E27: 2010 | G27: 1.05 | H27: 1.05 | I27: 1.05 | J27: 1.05 | K27: 1.05 | L27: =L29*'Production Steps'!$O$10 -> 1.6252417 | M27: =M29*'Production Steps'!$O$10 -> 1.7986292 | N27: =N29*'Production Steps'!$O$10 -> 1.958612 | O27: =O29*'Production Steps'!$O$10 -> 2.0465499 | P27: =P29*'Production Steps'!$O$10 -> 2.1387409 | Q27: =Q29*'Production Steps'!$O$10 -> 2.2263202 | R27: =R29*'Production Steps'!$O$10 -> 2.3239259 | S27: =S29*'Production Steps'!$O$10 -> 2.4258109 | ... U27: =U29*'Production Steps'!$O$10 -> 2.6431771 | V27: =X27*0.8 -> 111.0131 | W27: ='Production Steps'!H14*1.1*'Production Steps'!L14 -> 284.00329 | X27: ='Production Steps'!I14*1.1*'Production Steps'!L14 -> 138.76637
B28: MINCNABMS2 | C28: MIN.COA.NA.BMS.2 | D28: =CONCATENATE(MID(B28,4,6),"1") -> CNABMS1 | E28: 2010 | G28: 1.05 | H28: 1.05 | I28: 1.05 | J28: 1.05 | K28: 1.05 | L28: =L29*'Production Steps'!$O$11 -> 1.8431719 | M28: =M29*'Production Steps'!$O$11 -> 2.0398091 | N28: =N29*'Production Steps'!$O$11 -> 2.221244 | O28: =O29*'Production Steps'!$O$11 -> 2.3209736 | P28: =P29*'Production Steps'!$O$11 -> 2.4255266 | Q28: =Q29*'Production Steps'!$O$11 -> 2.5248495 | R28: =R29*'Production Steps'!$O$11 -> 2.6355433 | S28: =S29*'Production Steps'!$O$11 -> 2.7510901 | ... U28: =U29*'Production Steps'!$O$11 -> 2.9976031 | V28: =X28*0.8 -> 108.79284 | W28: ='Production Steps'!H15*1.1*'Production Steps'!L15 -> 278.32323 | X28: ='Production Steps'!I15*1.1*'Production Steps'!L15 -> 135.99105
B29: MINCNABMS3 | C29: MIN.COA.NA.BMS.3 | D29: =CONCATENATE(MID(B29,4,6),"1") -> CNABMS1 | E29: 2010 | G29: 1.05 | H29: 1.05 | I29: 1.05 | J29: 1.05 | K29: 1.05 | L29: =L22 -> 1.8468656 | M29: =M22 -> 2.0438969 | N29: =N22 -> 2.2256954 | O29: =O22 -> 2.3256249 | P29: =P22 -> 2.4303874 | Q29: =Q22 -> 2.5299093 | R29: =R22 -> 2.6408249 | S29: =R29*(1+(R29-Q29)/Q29) -> 2.7566033 | T29: =S29*(1+(S29-R29)/R29) -> 2.8774576 | U29: =T29*(1+(T29-S29)/S29) -> 3.0036103 | V29: =X29*0.8 -> 2.220262 | W29: ='Production Steps'!H16*1.1*'Production Steps'!L16 -> 5.6800658 | X29: ='Production Steps'!I16*1.1*'Production Steps'!L16 -> 2.7753275
B30: MINCNABMS4 | C30: MIN.COA.NA.BMS.4 | D30: =CONCATENATE(MID(B30,4,6),"1") -> CNABMS1 | E30: 2010 | G30: 1.05 | H30: 1.05 | I30: 1.05 | J30: 1.05 | K30: 1.05 | L30: =L29*'Production Steps'!$O$13 -> 1.8524062 | M30: =M29*'Production Steps'!$O$13 -> 2.0500286 | N30: =N29*'Production Steps'!$O$13 -> 2.2323725 | O30: =O29*'Production Steps'!$O$13 -> 2.3326018 | P30: =P29*'Production Steps'!$O$13 -> 2.4376786 | Q30: =Q29*'Production Steps'!$O$13 -> 2.537499 | R30: =R29*'Production Steps'!$O$13 -> 2.6487474 | S30: =S29*'Production Steps'!$O$13 -> 2.7648731 | ... U30: =U29*'Production Steps'!$O$13 -> 3.0126212 | V30: =X30*0.8 -> 2.220262 | W30: ='Production Steps'!H17*1.1*'Production Steps'!L17 -> 5.6800658 | X30: ='Production Steps'!I17*1.1*'Production Steps'!L17 -> 2.7753275
B31: MINCNABMS5 | C31: MIN.COA.NA.BMS.5 | D31: =CONCATENATE(MID(B31,4,6),"1") -> CNABMS1 | E31: 2010 | F31: =X31*0.1 -> 2.4977947 | G31: 1.05 | H31: 1.05 | I31: 1.05 | J31: 1.05 | K31: 1.05 | L31: =L29*'Production Steps'!$O$14 -> 2.0684895 | M31: =M29*'Production Steps'!$O$14 -> 2.2891645 | N31: =N29*'Production Steps'!$O$14 -> 2.4927788 | O31: =O29*'Production Steps'!$O$14 -> 2.6046999 | P31: =P29*'Production Steps'!$O$14 -> 2.7220339 | Q31: =Q29*'Production Steps'!$O$14 -> 2.8334984 | R31: =R29*'Production Steps'!$O$14 -> 2.9577239 | S31: =S29*'Production Steps'!$O$14 -> 3.0873957 | ... U31: =U29*'Production Steps'!$O$14 -> 3.3640436 | W31: ='Production Steps'!H18*1.1*'Production Steps'!L18 -> 51.120593 | X31: ='Production Steps'!I18*1.1*'Production Steps'!L18 -> 24.977947
B32: MINCNABMS6 | C32: MIN.COA.NA.BMS.6 | D32: =CONCATENATE(MID(B32,4,6),"1") -> CNABMS1 | E32: 2010 | F32: =X32*0.1 -> 2.7753275 | G32: 1.05 | H32: 1.05 | I32: 1.05 | J32: 1.05 | K32: 1.05 | L32: =L29*'Production Steps'!$O$15 -> 2.8257044 | M32: =M29*'Production Steps'!$O$15 -> 3.1271622 | N32: =N29*'Production Steps'!$O$15 -> 3.405314 | O32: =O29*'Production Steps'!$O$15 -> 3.5582061 | P32: =P29*'Production Steps'!$O$15 -> 3.7184927 | Q32: =Q29*'Production Steps'!$O$15 -> 3.8707612 | R32: =R29*'Production Steps'!$O$15 -> 4.0404622 | S32: =S29*'Production Steps'!$O$15 -> 4.2176031 | ... U32: =U29*'Production Steps'!$O$15 -> 4.5955238 | W32: ='Production Steps'!H19*1.1*'Production Steps'!L19 -> 56.800658 | X32: ='Production Steps'!I19*1.1*'Production Steps'!L19 -> 27.753275
A33: *
A34: R0 | B34: MINCNABHU1 | C34: MIN.COA.NA.BHU.1 | D34: =CONCATENATE(MID(B34,4,6),"1") -> CNABHU1 | E34: 2010 | G34: 1.05 | H34: 1.05 | I34: 1.05 | J34: 1.05 | K34: 1.005 | L34: =L36*'Production Steps'!$O$10 -> 1.5963672 | M34: =M36*'Production Steps'!$O$10 -> 1.7470789 | N34: =N36*'Production Steps'!$O$10 -> 1.9351 | O34: =O36*'Production Steps'!$O$10 -> 2.0183163 | P34: =P36*'Production Steps'!$O$10 -> 2.112953 | Q34: =Q36*'Production Steps'!$O$10 -> 2.1904386 | R34: =R36*'Production Steps'!$O$10 -> 2.2828618 | S34: =S36*'Production Steps'!$O$10 -> 2.3791847 | ... U34: =U36*'Production Steps'!$O$10 -> 2.5841947 | V34: =X34*0.8 -> 717.92908 | W34: ='Production Steps'!H21*1.1*'Production Steps'!K21 -> 708.60173 | X34: ='Production Steps'!I21*1.1*'Production Steps'!K21 -> 897.41135
B35: MINCNABHU2 | C35: MIN.COA.NA.BHU.2 | D35: =CONCATENATE(MID(B35,4,6),"1") -> CNABHU1 | E35: 2010 | G35: 1.05 | H35: 1.05 | I35: 1.05 | J35: 1.05 | K35: 1.005 | L35: =L36*'Production Steps'!$O$11 -> 1.8104255 | M35: =M36*'Production Steps'!$O$11 -> 1.9813462 | N35: =N36*'Production Steps'!$O$11 -> 2.1945793 | O35: =O36*'Production Steps'!$O$11 -> 2.2889541 | P35: =P36*'Production Steps'!$O$11 -> 2.3962808 | Q35: =Q36*'Production Steps'!$O$11 -> 2.4841565 | R35: =R36*'Production Steps'!$O$11 -> 2.5889728 | S35: =S36*'Production Steps'!$O$11 -> 2.6982118 | ... U35: =U36*'Production Steps'!$O$11 -> 2.9307117 | V35: =X35*0.8 -> 703.5705 | W35: ='Production Steps'!H22*1.1*'Production Steps'!K22 -> 694.42969 | X35: ='Production Steps'!I22*1.1*'Production Steps'!K22 -> 879.46313
B36: MINCNABHU3 | C36: MIN.COA.NA.BHU.3 | D36: =CONCATENATE(MID(B36,4,6),"1") -> CNABHU1 | E36: 2010 | G36: 1.05 | H36: 1.05 | I36: 1.05 | J36: 1.05 | K36: 1.005 | L36: ='AEO Coal Prices'!M9*'Production Steps'!$Q$17*$N$4 -> 1.8140536 | M36: ='AEO Coal Prices'!N9*'Production Steps'!$Q$17*$N$4 -> 1.9853169 | N36: ='AEO Coal Prices'!O9*'Production Steps'!$Q$17*$N$4 -> 2.1989772 | O36: ='AEO Coal Prices'!P9*'Production Steps'!$Q$17*$N$4 -> 2.2935412 | P36: ='AEO Coal Prices'!Q9*'Production Steps'!$Q$17*$N$4 -> 2.4010829 | Q36: ='AEO Coal Prices'!R9*'Production Steps'!$Q$17*$N$4 -> 2.4891348 | R36: ='AEO Coal Prices'!S9*'Production Steps'!$Q$17*$N$4 -> 2.5941612 | S36: =R36*(1+(R36-Q36)/Q36) -> 2.703619 | T36: =S36*(1+(S36-R36)/R36) -> 2.8176953 | U36: =T36*(1+(T36-S36)/S36) -> 2.9365849 | V36: =X36*0.8 -> 14.358582 | W36: ='Production Steps'!H23*1.1*'Production Steps'!K23 -> 14.172035 | X36: ='Production Steps'!I23*1.1*'Production Steps'!K23 -> 17.948227
B37: MINCNABHU4 | C37: MIN.COA.NA.BHU.4 | D37: =CONCATENATE(MID(B37,4,6),"1") -> CNABHU1 | E37: 2010 | G37: 1.05 | H37: 1.05 | I37: 1.05 | J37: 1.05 | K37: 1.005 | L37: =L36*'Production Steps'!$O$13 -> 1.8194958 | M37: =M36*'Production Steps'!$O$13 -> 1.9912728 | N37: =N36*'Production Steps'!$O$13 -> 2.2055742 | O37: =O36*'Production Steps'!$O$13 -> 2.3004218 | P37: =P36*'Production Steps'!$O$13 -> 2.4082862 | Q37: =Q36*'Production Steps'!$O$13 -> 2.4966022 | R37: =R36*'Production Steps'!$O$13 -> 2.6019436 | S37: =S36*'Production Steps'!$O$13 -> 2.7117299 | ... U37: =U36*'Production Steps'!$O$13 -> 2.9453947 | V37: =X37*0.8 -> 14.358582 | W37: ='Production Steps'!H24*1.1*'Production Steps'!K24 -> 14.172035 | X37: ='Production Steps'!I24*1.1*'Production Steps'!K24 -> 17.948227
B38: MINCNABHU5 | C38: MIN.COA.NA.BHU.5 | D38: =CONCATENATE(MID(B38,4,6),"1") -> CNABHU1 | E38: 2010 | F38: =X38*0.1 -> 16.153404 | G38: 1.05 | H38: 1.05 | I38: 1.05 | J38: 1.05 | K38: 1.005 | L38: =L36*'Production Steps'!$O$14 -> 2.03174 | M38: =M36*'Production Steps'!$O$14 -> 2.2235549 | N38: =N36*'Production Steps'!$O$14 -> 2.4628545 | O38: =O36*'Production Steps'!$O$14 -> 2.5687662 | P38: =P36*'Production Steps'!$O$14 -> 2.6892129 | Q38: =Q36*'Production Steps'!$O$14 -> 2.787831 | R38: =R36*'Production Steps'!$O$14 -> 2.9054605 | S38: =S36*'Production Steps'!$O$14 -> 3.0280533 | ... U38: =U36*'Production Steps'!$O$14 -> 3.2889751 | W38: ='Production Steps'!H25*1.1*'Production Steps'!K25 -> 127.54831 | X38: ='Production Steps'!I25*1.1*'Production Steps'!K25 -> 161.53404
B39: MINCNABHU6 | C39: MIN.COA.NA.BHU.6 | D39: =CONCATENATE(MID(B39,4,6),"1") -> CNABHU1 | E39: 2010 | F39: =X39*0.1 -> 17.948227 | G39: 1.05 | H39: 1.05 | I39: 1.05 | J39: 1.05 | K39: 1.005 | L39: =L36*'Production Steps'!$O$15 -> 2.775502 | M39: =M36*'Production Steps'!$O$15 -> 3.0375348 | N39: =N36*'Production Steps'!$O$15 -> 3.3644352 | O39: =O36*'Production Steps'!$O$15 -> 3.5091181 | P39: =P36*'Production Steps'!$O$15 -> 3.6736569 | Q39: =Q36*'Production Steps'!$O$15 -> 3.8083762 | R39: =R36*'Production Steps'!$O$15 -> 3.9690666 | S39: =S36*'Production Steps'!$O$15 -> 4.1365371 | ... U39: =U36*'Production Steps'!$O$15 -> 4.4929749 | W39: ='Production Steps'!H26*1.1*'Production Steps'!K26 -> 141.72035 | X39: ='Production Steps'!I26*1.1*'Production Steps'!K26 -> 179.48227
A40: *
A41: R0 | B41: MINCNABHS1 | C41: MIN.COA.NA.BHS.1 | D41: =CONCATENATE(MID(B41,4,6),"1") -> CNABHS1 | E41: 2010 | G41: 1.05 | H41: 1.05 | I41: 1.05 | J41: 1.05 | K41: 1.005 | L41: =L43*'Production Steps'!$O$10 -> 1.5963672 | M41: =M43*'Production Steps'!$O$10 -> 1.7470789 | N41: =N43*'Production Steps'!$O$10 -> 1.9351 | O41: =O43*'Production Steps'!$O$10 -> 2.0183163 | P41: =P43*'Production Steps'!$O$10 -> 2.112953 | Q41: =Q43*'Production Steps'!$O$10 -> 2.1904386 | R41: =R43*'Production Steps'!$O$10 -> 2.2828618 | S41: =S43*'Production Steps'!$O$10 -> 2.3791847 | ... U41: =U43*'Production Steps'!$O$10 -> 2.5841947 | V41: =X41*0.8 -> 174.93491 | W41: ='Production Steps'!H21*1.1*'Production Steps'!L21 -> 172.66215 | X41: ='Production Steps'!I21*1.1*'Production Steps'!L21 -> 218.66864
B42: MINCNABHS2 | C42: MIN.COA.NA.BHS.2 | D42: =CONCATENATE(MID(B42,4,6),"1") -> CNABHS1 | E42: 2010 | G42: 1.05 | H42: 1.05 | I42: 1.05 | J42: 1.05 | K42: 1.005 | L42: =L43*'Production Steps'!$O$11 -> 1.8104255 | M42: =M43*'Production Steps'!$O$11 -> 1.9813462 | N42: =N43*'Production Steps'!$O$11 -> 2.1945793 | O42: =O43*'Production Steps'!$O$11 -> 2.2889541 | P42: =P43*'Production Steps'!$O$11 -> 2.3962808 | Q42: =Q43*'Production Steps'!$O$11 -> 2.4841565 | R42: =R43*'Production Steps'!$O$11 -> 2.5889728 | S42: =S43*'Production Steps'!$O$11 -> 2.6982118 | ... U42: =U43*'Production Steps'!$O$11 -> 2.9307117 | V42: =X42*0.8 -> 171.43622 | W42: ='Production Steps'!H22*1.1*'Production Steps'!L22 -> 169.20891 | X42: ='Production Steps'!I22*1.1*'Production Steps'!L22 -> 214.29527
B43: MINCNABHS3 | C43: MIN.COA.NA.BHS.3 | D43: =CONCATENATE(MID(B43,4,6),"1") -> CNABHS1 | E43: 2010 | G43: 1.05 | H43: 1.05 | I43: 1.05 | J43: 1.05 | K43: 1.005 | L43: =L36 -> 1.8140536 | M43: =M36 -> 1.9853169 | N43: =N36 -> 2.1989772 | O43: =O36 -> 2.2935412 | P43: =P36 -> 2.4010829 | Q43: =Q36 -> 2.4891348 | R43: =R36 -> 2.5941612 | S43: =R43*(1+(R43-Q43)/Q43) -> 2.703619 | T43: =S43*(1+(S43-R43)/R43) -> 2.8176953 | U43: =T43*(1+(T43-S43)/S43) -> 2.9365849 | V43: =X43*0.8 -> 3.4986983 | W43: ='Production Steps'!H23*1.1*'Production Steps'!L23 -> 3.4532431 | X43: ='Production Steps'!I23*1.1*'Production Steps'!L23 -> 4.3733729
B44: MINCNABHS4 | C44: MIN.COA.NA.BHS.4 | D44: =CONCATENATE(MID(B44,4,6),"1") -> CNABHS1 | E44: 2010 | G44: 1.05 | H44: 1.05 | I44: 1.05 | J44: 1.05 | K44: 1.005 | L44: =L43*'Production Steps'!$O$13 -> 1.8194958 | M44: =M43*'Production Steps'!$O$13 -> 1.9912728 | N44: =N43*'Production Steps'!$O$13 -> 2.2055742 | O44: =O43*'Production Steps'!$O$13 -> 2.3004218 | P44: =P43*'Production Steps'!$O$13 -> 2.4082862 | Q44: =Q43*'Production Steps'!$O$13 -> 2.4966022 | R44: =R43*'Production Steps'!$O$13 -> 2.6019436 | S44: =S43*'Production Steps'!$O$13 -> 2.7117299 | ... U44: =U43*'Production Steps'!$O$13 -> 2.9453947 | V44: =X44*0.8 -> 3.4986983 | W44: ='Production Steps'!H24*1.1*'Production Steps'!L24 -> 3.4532431 | X44: ='Production Steps'!I24*1.1*'Production Steps'!L24 -> 4.3733729
B45: MINCNABHS5 | C45: MIN.COA.NA.BHS.5 | D45: =CONCATENATE(MID(B45,4,6),"1") -> CNABHS1 | E45: 2010 | F45: =X45*0.1 -> 3.9360356 | G45: 1.05 | H45: 1.05 | I45: 1.05 | J45: 1.05 | K45: 1.005 | L45: =L43*'Production Steps'!$O$14 -> 2.03174 | M45: =M43*'Production Steps'!$O$14 -> 2.2235549 | N45: =N43*'Production Steps'!$O$14 -> 2.4628545 | O45: =O43*'Production Steps'!$O$14 -> 2.5687662 | P45: =P43*'Production Steps'!$O$14 -> 2.6892129 | Q45: =Q43*'Production Steps'!$O$14 -> 2.787831 | R45: =R43*'Production Steps'!$O$14 -> 2.9054605 | S45: =S43*'Production Steps'!$O$14 -> 3.0280533 | ... U45: =U43*'Production Steps'!$O$14 -> 3.2889751 | W45: ='Production Steps'!H25*1.1*'Production Steps'!L25 -> 31.079188 | X45: ='Production Steps'!I25*1.1*'Production Steps'!L25 -> 39.360356
B46: MINCNABHS6 | C46: MIN.COA.NA.BHS.6 | D46: =CONCATENATE(MID(B46,4,6),"1") -> CNABHS1 | E46: 2010 | F46: =X46*0.1 -> 4.3733729 | G46: 1.05 | H46: 1.05 | I46: 1.05 | J46: 1.05 | K46: 1.005 | L46: =L43*'Production Steps'!$O$15 -> 2.775502 | M46: =M43*'Production Steps'!$O$15 -> 3.0375348 | N46: =N43*'Production Steps'!$O$15 -> 3.3644352 | O46: =O43*'Production Steps'!$O$15 -> 3.5091181 | P46: =P43*'Production Steps'!$O$15 -> 3.6736569 | Q46: =Q43*'Production Steps'!$O$15 -> 3.8083762 | R46: =R43*'Production Steps'!$O$15 -> 3.9690666 | S46: =S43*'Production Steps'!$O$15 -> 4.1365371 | ... U46: =U43*'Production Steps'!$O$15 -> 4.4929749 | W46: ='Production Steps'!H26*1.1*'Production Steps'!L26 -> 34.532431 | X46: ='Production Steps'!I26*1.1*'Production Steps'!L26 -> 43.733729
A47: *
...

Sheet ANSv6.1-Technologies
A1: ANSWER-Technologies
B7: TechName | C7: TechDesc | D7: TACTUnit | E7: TCAPUnit | F7: Set Memberships | G7: Comment

Sheet ANSv6.1-Constraints
A1: ANSWER-Constraints
B7: ConstrName | C7: ConstrDesc | D7: Units | E7: Set Memberships | F7: Comment

Sheet ANSv6.1-CommData
A1: ANSWER-CommData
B7: CommName | C7: CommDesc | D7: Units

Sheet ANSv6.1-TechData
A1: ANSWER-TechData
B7: TechName | C7: TechDesc | D7: Units | E7: CommIN | F7: CommOUT

Sheet AEO Coal Prices
A1: Coal Minemouth Prices by Region and Type, Reference case
A2: (2012 dollars per short ton) | L2: PJ per million btu | O2: 1.055056e-06
A4: Supply Regions and Coal Types | B4: 2005 | C4: 2010 | D4: 2015 | E4: 2020 | F4: 2025 | G4: 2030 | H4: 2035 | I4: 2040 | L4: 2005 | M4: 2010 | N4: 2015 | O4: 2020 | P4: 2025 | Q4: 2030 | R4: 2035 | S4: 2040 | X4: 2005 | Y4: 2010 | Z4: 2015 | AA4: 2020 | AB4: 2025 | AC4: 2030 | AD4: 2035 | AE4: 2040
A6: Northern Appalachia 1/ | B6: 35.065239 | C6: 54.224152 | D6: 67.093102 | E6: 75.796234 | F6: 84.36412 | G6: 89.95134 | H6: 96.711006 | I6: 103.28035
A7: Medium Sulfur (Premium) 2/ | B7: 70.030243 | C7: 83.834381 | D7: 105.43449 | E7: 120.82428 | F7: 141.92157 | G7: 154.62036 | H7: 168.06445 | I7: 182.31543 | L7: =B7*'Conversion Factors'!$C$38/Types!$R$9/$O$2/1000000 -> 2.4485497 | M7: =C7*'Conversion Factors'!$C$41/Types!$R$9/$O$2/1000000 -> 2.7793052 | N7: =D7*'Conversion Factors'!$C$44/Types!$R$9/$O$2/1000000 -> 3.3288883 | O7: =E7*'Conversion Factors'!$C$44/Types!$R$9/$O$2/1000000 -> 3.8147908 | P7: =F7*'Conversion Factors'!$C$44/Types!$R$9/$O$2/1000000 -> 4.4808965 | Q7: =G7*'Conversion Factors'!$C$44/Types!$R$9/$O$2/1000000 -> 4.8818361 | R7: =H7*'Conversion Factors'!$C$44/Types!$R$9/$O$2/1000000 -> 5.306307 | S7: =I7*'Conversion Factors'!$C$44/Types!$R$9/$O$2/1000000 -> 5.7562538 | U7: =L7/M7 -> 0.88099345 | X7: =L7*'AEO Coal Prod'!L7 -> 237.79802 | Y7: =M7*'AEO Coal Prod'!M7 -> 1406.7398 | Z7: =N7*'AEO Coal Prod'!N7 -> 1873.1986 | AA7: =O7*'AEO Coal Prod'!O7 -> 2590.0824 | AB7: =P7*'AEO Coal Prod'!P7 -> 3707.0742 | AC7: =Q7*'AEO Coal Prod'!Q7 -> 4138.155 | AD7: =R7*'AEO Coal Prod'!R7 -> 5012.3347 | AE7: =S7*'AEO Coal Prod'!S7 -> 5737.1816
A8: Medium Sulfur (Bituminous) | B8: 36.763557 | C8: 53.896236 | D8: 62.629608 | E8: 68.200325 | F8: 71.26239 | G8: 74.472549 | H8: 77.522125 | I8: 80.92083 | L8: =B8*'Conversion Factors'!$C$38/Types!$R$4/$O$2/1000000 -> 1.3420491 | M8: =C8*'Conversion Factors'!$C$41/Types!$R$4/$O$2/1000000 -> 1.8655208 | N8: =D8*'Conversion Factors'!$C$44/Types!$R$4/$O$2/1000000 -> 2.0645423 | O8: =E8*'Conversion Factors'!$C$44/Types!$R$4/$O$2/1000000 -> 2.2481772 | P8: =F8*'Conversion Factors'!$C$44/Types!$R$4/$O$2/1000000 -> 2.3491161 | Q8: =G8*'Conversion Factors'!$C$44/Types!$R$4/$O$2/1000000 -> 2.4549368 | R8: =H8*'Conversion Factors'!$C$44/Types!$R$4/$O$2/1000000 -> 2.5554639 | S8: =I8*'Conversion Factors'!$C$44/Types!$R$4/$O$2/1000000 -> 2.6674999 | U8: =L8/M8 -> 0.71939647 | X8: =L8*'AEO Coal Prod'!L8 -> 2675.7724 | Y8: =M8*'AEO Coal Prod'!M8 -> 1817.3632 | Z8: =N8*'AEO Coal Prod'!N8 -> 1112.6984 | AA8: =O8*'AEO Coal Prod'!O8 -> 1522.2824 | AB8: =P8*'AEO Coal Prod'!P8 -> 1502.9772 | AC8: =Q8*'AEO Coal Prod'!Q8 -> 1664.1689 | AD8: =R8*'AEO Coal Prod'!R8 -> 1650.1024 | AE8: =S8*'AEO Coal Prod'!S8 -> 1736.8888
A9: High Sulfur (Bituminous) | B9: 31.007643 | C9: 51.845879 | D9: 59.57877 | E9: 65.990654 | F9: 68.828491 | G9: 72.055786 | H9: 74.698196 | I9: 77.850006 | L9: =B9*'Conversion Factors'!$C$38/Types!$R$5/$O$2/1000000 -> 1.1557892 | M9: =C9*'Conversion Factors'!$C$41/Types!$R$5/$O$2/1000000 -> 1.8323774 | N9: =D9*'Conversion Factors'!$C$44/Types!$R$5/$O$2/1000000 -> 2.0053706 | O9: =E9*'Conversion Factors'!$C$44/Types!$R$5/$O$2/1000000 -> 2.2211891 | P9: =F9*'Conversion Factors'!$C$44/Types!$R$5/$O$2/1000000 -> 2.3167083 | Q9: =G9*'Conversion Factors'!$C$44/Types!$R$5/$O$2/1000000 -> 2.4253363 | R9: =H9*'Conversion Factors'!$C$44/Types!$R$5/$O$2/1000000 -> 2.5142776 | S9: =I9*'Conversion Factors'!$C$44/Types!$R$5/$O$2/1000000 -> 2.6203648 | U9: =L9/M9 -> 0.63075938 | X9: =L9*'AEO Coal Prod'!L9 -> 1851.9187 | Y9: =M9*'AEO Coal Prod'!M9 -> 3718.3268 | Z9: =N9*'AEO Coal Prod'!N9 -> 4772.208 | AA9: =O9*'AEO Coal Prod'!O9 -> 5355.0519 | AB9: =P9*'AEO Coal Prod'!P9 -> 5436.5377 | AC9: =Q9*'AEO Coal Prod'!Q9 -> 5576.119 | AD9: =R9*'AEO Coal Prod'!R9 -> 5835.2476 | AE9: =S9*'AEO Coal Prod'!S9 -> 6144.6021
A11: Central Appalachia | B11: 46.536526 | C11: 78.00705 | D11: 102.05424 | E11: 119.74264 | F11: 129.09392 | G11: 141.12996 | H11: 147.79279 | I11: 152.37442
A12: Medium Sulfur (Premium) 2/ | B12: 66.089821 | C12: 110.09124 | D12: 137.23921 | E12: 157.73831 | F12: 172.63171 | G12: 188.77013 | H12: 200.48785 | I12: 207.27634 | L12: =B12*'Conversion Factors'!$C$38/Types!$R$14/$O$2/1000000 -> 2.3107761 | M12: =C12*'Conversion Factors'!$C$41/Types!$R$14/$O$2/1000000 -> 3.6497813 | N12: =D12*'Conversion Factors'!$C$44/Types!$R$14/$O$2/1000000 -> 4.3330602 | O12: =E12*'Conversion Factors'!$C$44/Types!$R$14/$O$2/1000000 -> 4.9802793 | P12: =F12*'Conversion Factors'!$C$44/Types!$R$14/$O$2/1000000 -> 5.4505094 | Q12: =G12*'Conversion Factors'!$C$44/Types!$R$14/$O$2/1000000 -> 5.9600482 | R12: =H12*'Conversion Factors'!$C$44/Types!$R$14/$O$2/1000000 -> 6.3300126 | S12: =I12*'Conversion Factors'!$C$44/Types!$R$14/$O$2/1000000 -> 6.5443457 | U12: =L12/M12 -> 0.63312727 | X12: =L12*'AEO Coal Prod'!L12 -> 2514.7611 | Y12: =M12*'AEO Coal Prod'!M12 -> 6245.3669 | Z12: =N12*'AEO Coal Prod'!N12 -> 6469.3048 | AA12: =O12*'AEO Coal Prod'!O12 -> 7638.4753 | AB12: =P12*'AEO Coal Prod'!P12 -> 8010.4103 | AC12: =Q12*'AEO Coal Prod'!Q12 -> 8498.1819 | AD12: =R12*'AEO Coal Prod'!R12 -> 8531.6439 | AE12: =S12*'AEO Coal Prod'!S12 -> 7740.0688
A13: Low Sulfur (Bituminous) | B13: 44.572205 | C13: 69.05088 | D13: 74.815384 | E13: 79.993484 | F13: 83.592361 | G13: 94.048553 | H13: 101.10722 | I13: 111.37326 | L13: =B13*'Conversion Factors'!$C$38/Types!$R$10/$O$2/1000000 -> 1.6580388 | M13: =C13*'Conversion Factors'!$C$41/Types!$R$10/$O$2/1000000 -> 2.4355137 | N13: =D13*'Conversion Factors'!$C$44/Types!$R$10/$O$2/1000000 -> 2.5131285 | O13: =E13*'Conversion Factors'!$C$44/Types!$R$10/$O$2/1000000 -> 2.6870664 | P13: =F13*'Conversion Factors'!$C$44/Types!$R$10/$O$2/1000000 -> 2.8079565 | Q13: =G13*'Conversion Factors'!$C$44/Types!$R$10/$O$2/1000000 -> 3.1591912 | R13: =H13*'Conversion Factors'!$C$44/Types!$R$10/$O$2/1000000 -> 3.3962992 | S13: =I13*'Conversion Factors'!$C$44/Types!$R$10/$O$2/1000000 -> 3.7411466 | U13: =L13/M13 -> 0.6807758 | X13: =L13*'AEO Coal Prod'!L13 -> 2038.056 | Y13: =M13*'AEO Coal Prod'!M13 -> 890.30466 | Z13: =N13*'AEO Coal Prod'!N13 -> 368.58316 | AA13: =O13*'AEO Coal Prod'!O13 -> 385.28918 | AB13: =P13*'AEO Coal Prod'!P13 -> 341.03435 | AC13: =Q13*'AEO Coal Prod'!Q13 -> 430.72804 | AD13: =R13*'AEO Coal Prod'!R13 -> 450.95728 | AE13: =S13*'AEO Coal Prod'!S13 -> 517.01096
A14: Medium Sulfur (Bituminous) | B14: 42.024334 | C14: 65.239883 | D14: 69.93129 | E14: 75.058334 | F14: 77.891731 | G14: 80.787262 | H14: 83.894447 | I14: 87.105888 | L14: =B14*'Conversion Factors'!$C$38/Types!$R$11/$O$2/1000000 -> 1.5670643 | M14: =C14*'Conversion Factors'!$C$41/Types!$R$11/$O$2/1000000 -> 2.3066937 | N14: =D14*'Conversion Factors'!$C$44/Types!$R$11/$O$2/1000000 -> 2.3547821 | O14: =E14*'Conversion Factors'!$C$44/Types!$R$11/$O$2/1000000 -> 2.527424 | P14: =F14*'Conversion Factors'!$C$44/Types!$R$11/$O$2/1000000 -> 2.6228324 | Q14: =G14*'Conversion Factors'!$C$44/Types!$R$11/$O$2/1000000 -> 2.720333 | R14: =H14*'Conversion Factors'!$C$44/Types!$R$11/$O$2/1000000 -> 2.8249606 | S14: =I14*'Conversion Factors'!$C$44/Types!$R$11/$O$2/1000000 -> 2.9330988 | U14: =L14/M14 -> 0.67935515 | X14: =L14*'AEO Coal Prod'!L14 -> 6092.8748 | Y14: =M14*'AEO Coal Prod'!M14 -> 6560.0643 | Z14: =N14*'AEO Coal Prod'!N14 -> 3318.5751 | AA14: =O14*'AEO Coal Prod'!O14 -> 2769.0437 | AB14: =P14*'AEO Coal Prod'!P14 -> 2790.8921 | AC14: =Q14*'AEO Coal Prod'!Q14 -> 2582.6564 | AD14: =R14*'AEO Coal Prod'!R14 -> 2670.751 | AE14: =S14*'AEO Coal Prod'!S14 -> 2482.0496
A16: Southern Appalachia | B16: 55.298611 | C16: 78.789536 | D16: 125.83792 | E16: 140.53088 | F16: 144.94121 | G16: 154.81975 | H16: 162.00633 | I16: 168.1198
A17: Low Sulfur (Premium) 2/ | B17: 73.135132 | C17: 87.973717 | D17: 138.49081 | E17: 155.08452 | F17: 166.79222 | G17: 179.67328 | H17: 189.66991 | I17: 193.24593 | L17: =B17*'Conversion Factors'!$C$38/Types!$R$19/$O$2/1000000 -> 2.5571096 | M17: =C17*'Conversion Factors'!$C$41/Types!$R$19/$O$2/1000000 -> 2.9165339 | N17: =D17*'Conversion Factors'!$C$44/Types!$R$19/$O$2/1000000 -> 4.3725771 | O17: =E17*'Conversion Factors'!$C$44/Types!$R$19/$O$2/1000000 -> 4.8964909 | P17: =F17*'Conversion Factors'!$C$44/Types!$R$19/$O$2/1000000 -> 5.2661388 | Q17: =G17*'Conversion Factors'!$C$44/Types!$R$19/$O$2/1000000 -> 5.672833 | R17: =H17*'Conversion Factors'!$C$44/Types!$R$19/$O$2/1000000 -> 5.9884571 | S17: =I17*'Conversion Factors'!$C$44/Types!$R$19/$O$2/1000000 -> 6.1013629 | U17: =L17/M17 -> 0.87676321 | X17: =L17*'AEO Coal Prod'!L17 -> 573.31322 | Y17: =M17*'AEO Coal Prod'!M17 -> 826.77563 | Z17: =N17*'AEO Coal Prod'!N17 -> 1526.0323 | AA17: =O17*'AEO Coal Prod'!O17 -> 1776.0633 | AB17: =P17*'AEO Coal Prod'!P17 -> 1807.002 | AC17: =Q17*'AEO Coal Prod'!Q17 -> 1899.1006 | AD17: =R17*'AEO Coal Prod'!R17 -> 1905.3967 | AE17: =S17*'AEO Coal Prod'!S17 -> 2152.2281
A18: Low Sulfur (Bituminous) | B18: 49.286278 | C18: 77.487556 | D18: 86.502647 | E18: 92.004723 | F18: 94.471405 | G18: 101.28996 | H18: 106.77394 | I18: 113.03116 | L18: =B18*'Conversion Factors'!$C$38/Types!$R$15/$O$2/1000000 -> 1.7298314 | M18: =C18*'Conversion Factors'!$C$41/Types!$R$15/$O$2/1000000 -> 2.5786981 | N18: =D18*'Conversion Factors'!$C$44/Types!$R$15/$O$2/1000000 -> 2.7415765 | O18: =E18*'Conversion Factors'!$C$44/Types!$R$15/$O$2/1000000 -> 2.9159568 | P18: =F18*'Conversion Factors'!$C$44/Types!$R$15/$O$2/1000000 -> 2.9941347 | Q18: =G18*'Conversion Factors'!$C$44/Types!$R$15/$O$2/1000000 -> 3.2102391 | R18: =H18*'Conversion Factors'!$C$44/Types!$R$15/$O$2/1000000 -> 3.3840458 | S18: =I18*'Conversion Factors'!$C$44/Types!$R$15/$O$2/1000000 -> 3.5823593 | U18: =L18/M18 -> 0.67081577 | X18: =L18*'AEO Coal Prod'!L18 -> 24.864739 | Y18: =M18*'AEO Coal Prod'!M18 -> 32.062454 | Z18: =N18*'AEO Coal Prod'!N18 -> 49.756096 | AA18: =O18*'AEO Coal Prod'!O18 -> 39.901195 | AB18: =P18*'AEO Coal Prod'!P18 -> 38.447614 | AC18: =Q18*'AEO Coal Prod'!Q18 -> 40.995522 | AD18: =R18*'AEO Coal Prod'!R18 -> 42.510881 | AE18: =S18*'AEO Coal Prod'!S18 -> 41.182621
A19: Medium Sulfur (Bituminous) | B19: 44.334949 | C19: 63.498878 | D19: 80.878357 | E19: 70.212708 | F19: 72.388145 | G19: 74.909805 | H19: 77.534828 | I19: 80.763489 | L19: =B19*'Conversion Factors'!$C$38/Types!$R$16/$O$2/1000000 -> 1.6687904 | M19: =C19*'Conversion Factors'!$C$41/Types!$R$16/$O$2/1000000 -> 2.266274 | N19: =D19*'Conversion Factors'!$C$44/Types!$R$16/$O$2/1000000 -> 2.7490403 | O19: =E19*'Conversion Factors'!$C$44/Types!$R$16/$O$2/1000000 -> 2.3865169 | P19: =F19*'Conversion Factors'!$C$44/Types!$R$16/$O$2/1000000 -> 2.4604596 | Q19: =G19*'Conversion Factors'!$C$44/Types!$R$16/$O$2/1000000 -> 2.5461704 | R19: =H19*'Conversion Factors'!$C$44/Types!$R$16/$O$2/1000000 -> 2.6353944 | S19: =I19*'Conversion Factors'!$C$44/Types!$R$16/$O$2/1000000 -> 2.745136 | U19: =L19/M19 -> 0.73635862 | X19: =L19*'AEO Coal Prod'!L19 -> 553.14852 | Y19: =M19*'AEO Coal Prod'!M19 -> 509.0715 | Z19: =N19*'AEO Coal Prod'!N19 -> 210.10728 | AA19: =O19*'AEO Coal Prod'!O19 -> 145.40784 | AB19: =P19*'AEO Coal Prod'!P19 -> 215.69914 | AC19: =Q19*'AEO Coal Prod'!Q19 -> 225.94837 | AD19: =R19*'AEO Coal Prod'!R19 -> 234.89885 | AE19: =S19*'AEO Coal Prod'!S19 -> 240.15999
A21: Eastern Interior | B21: w | C21: 44.883808 | D21: 52.043491 | E21: 57.922966 | F21: 59.986744 | G21: 62.594608 | H21: 64.764236 | I21: 66.851547
A22: Medium Sulfur (Bituminous) | B22: 31.141741 | C22: 54.252983 | D22: 58.842049 | E22: 64.748085 | F22: 66.657181 | G22: 69.43602 | H22: 71.616425 | I22: 73.522926 | L22: =B22*'Conversion Factors'!$C$38/Types!$R$20/$O$2/1000000 -> 1.2721737 | M22: =C22*'Conversion Factors'!$C$41/Types!$R$20/$O$2/1000000 -> 2.1014446 | N22: =D22*'Conversion Factors'!$C$44/Types!$R$20/$O$2/1000000 -> 2.1706237 | O22: =E22*'Conversion Factors'!$C$44/Types!$R$20/$O$2/1000000 -> 2.3884914 | P22: =F22*'Conversion Factors'!$C$44/Types!$R$20/$O$2/1000000 -> 2.4589161 | Q22: =G22*'Conversion Factors'!$C$44/Types!$R$20/$O$2/1000000 -> 2.5614246 | R22: =H22*'Conversion Factors'!$C$44/Types!$R$20/$O$2/1000000 -> 2.6418576 | S22: =I22*'Conversion Factors'!$C$44/Types!$R$20/$O$2/1000000 -> 2.7121865 | U22: =L22/M22 -> 0.60538056 | X22: =L22*'AEO Coal Prod'!L22 -> 883.73754 | Y22: =M22*'AEO Coal Prod'!M22 -> 509.92359 | Z22: =N22*'AEO Coal Prod'!N22 -> 425.42013 | AA22: =O22*'AEO Coal Prod'!O22 -> 428.84363 | AB22: =P22*'AEO Coal Prod'!P22 -> 454.63815 | AC22: =Q22*'AEO Coal Prod'!Q22 -> 492.67564 | AD22: =R22*'AEO Coal Prod'!R22 -> 521.80672 | AE22: =S22*'AEO Coal Prod'!S22 -> 542.76888
A23: High Sulfur (Bituminous) | B23: 26.623665 | C23: 44.272259 | D23: 53.015858 | E23: 58.978973 | F23: 60.857269 | G23: 63.613976 | H23: 65.766449 | I23: 67.85173 | L23: =B23*'Conversion Factors'!$C$38/Types!$R$21/$O$2/1000000 -> 1.0761318 | M23: =C23*'Conversion Factors'!$C$41/Types!$R$21/$O$2/1000000 -> 1.6967588 | N23: =D23*'Conversion Factors'!$C$44/Types!$R$21/$O$2/1000000 -> 1.9350699 | O23: =E23*'Conversion Factors'!$C$44/Types!$R$21/$O$2/1000000 -> 2.1527226 | P23: =F23*'Conversion Factors'!$C$44/Types!$R$21/$O$2/1000000 -> 2.22128 | Q23: =G23*'Conversion Factors'!$C$44/Types!$R$21/$O$2/1000000 -> 2.3218994 | R23: =H23*'Conversion Factors'!$C$44/Types!$R$21/$O$2/1000000 -> 2.4004643 | S23: =I23*'Conversion Factors'!$C$44/Types!$R$21/$O$2/1000000 -> 2.4765767 | U23: =L23/M23 -> 0.63422793 | X23: =L23*'AEO Coal Prod'!L23 -> 1644.0719 | Y23: =M23*'AEO Coal Prod'!M23 -> 4327.2105 | Z23: =N23*'AEO Coal Prod'!N23 -> 6752.4218 | AA23: =O23*'AEO Coal Prod'!O23 -> 8377.1457 | AB23: =P23*'AEO Coal Prod'!P23 -> 9223.8597 | AC23: =Q23*'AEO Coal Prod'!Q23 -> 10594.216 | AD23: =R23*'AEO Coal Prod'!R23 -> 11665.128 | AE23: =S23*'AEO Coal Prod'!S23 -> 12609.018
A24: Medium Sulfur (Lignite) | B24: w | C24: 20.302601 | D24: 22.685019 | E24: 26.098757 | F24: 26.653751 | G24: 28.637218 | H24: 29.263145 | I24: 30.115891 | L24: =M24*$U$60 -> 1.1723251 | M24: =C24*'Conversion Factors'!$C$41/Types!$R$24/$O$2/1000000 -> 1.708684 | N24: =D24*'Conversion Factors'!$C$44/Types!$R$24/$O$2/1000000 -> 1.8182418 | O24: =E24*'Conversion Factors'!$C$44/Types!$R$24/$O$2/1000000 -> 2.0918586 | P24: =F24*'Conversion Factors'!$C$44/Types!$R$24/$O$2/1000000 -> 2.1363423 | Q24: =G24*'Conversion Factors'!$C$44/Types!$R$24/$O$2/1000000 -> 2.2953205 | R24: =H24*'Conversion Factors'!$C$44/Types!$R$24/$O$2/1000000 -> 2.3454895 | S24: =I24*'Conversion Factors'!$C$44/Types!$R$24/$O$2/1000000 -> 2.4138385
A26: Western Interior High Sulfur (Bituminous) | B26: 30.347471 | C26: 56.689579 | D26: 48.515842 | E26: 56.246765 | F26: 57.939674 | G26: 59.226864 | H26: 61.727329 | I26: 64.839836 | L26: =B26*'Conversion Factors'!$C$38/Types!$R$25/$O$2/1000000 -> 1.3132355 | M26: =C26*'Conversion Factors'!$C$41/Types!$R$25/$O$2/1000000 -> 2.3260236 | N26: =D26*'Conversion Factors'!$C$44/Types!$R$25/$O$2/1000000 -> 1.8958191 | O26: =E26*'Conversion Factors'!$C$44/Types!$R$25/$O$2/1000000 -> 2.1979149 | P26: =F26*'Conversion Factors'!$C$44/Types!$R$25/$O$2/1000000 -> 2.2640675 | Q26: =G26*'Conversion Factors'!$C$44/Types!$R$25/$O$2/1000000 -> 2.3143661 | R26: =H26*'Conversion Factors'!$C$44/Types!$R$25/$O$2/1000000 -> 2.412075 | S26: =I26*'Conversion Factors'!$C$44/Types!$R$25/$O$2/1000000 -> 2.5337002 | U26: =L26/M26 -> 0.5645839 | X26: =L26*'AEO Coal Prod'!L26 -> 77.434202 | Y26: =M26*'AEO Coal Prod'!M26 -> 92.825773 | Z26: =N26*'AEO Coal Prod'!N26 -> 48.195414 | AA26: =O26*'AEO Coal Prod'!O26 -> 34.121843 | AB26: =P26*'AEO Coal Prod'!P26 -> 42.511157 | AC26: =Q26*'AEO Coal Prod'!Q26 -> 32.680172 | AD26: =R26*'AEO Coal Prod'!R26 -> 30.101866 | AE26: =S26*'AEO Coal Prod'!S26 -> 31.192019
A28: Gulf | B28: w | C28: 18.071056 | D28: 21.312981 | E28: 23.479725 | F28: 25.807581 | G28: 27.817467 | H28: 28.947941 | I28: 29.977573
A29: Medium Sulfur (Lignite) | B29: w | C29: 19.59021 | D29: 21.080399 | E29: 23.227949 | F29: 26.073206 | G29: 28.448868 | H29: 29.704285 | I29: 30.773726 | L29: =M29*$U$60 -> 0.87066314 | M29: =C29*'Conversion Factors'!$C$41/Types!$R$26/$O$2/1000000 -> 1.2690065 | N29: =D29*'Conversion Factors'!$C$44/Types!$R$26/$O$2/1000000 -> 1.300487 | O29: =E29*'Conversion Factors'!$C$44/Types!$R$26/$O$2/1000000 -> 1.4329732 | P29: =F29*'Conversion Factors'!$C$44/Types!$R$26/$O$2/1000000 -> 1.6085021 | Q29: =G29*'Conversion Factors'!$C$44/Types!$R$26/$O$2/1000000 -> 1.7550609 | R29: =H29*'Conversion Factors'!$C$44/Types!$R$26/$O$2/1000000 -> 1.8325098 | S29: =I29*'Conversion Factors'!$C$44/Types!$R$26/$O$2/1000000 -> 1.8984855 | X29: =L29*'AEO Coal Prod'!L29 -> 288.33627 | Y29: =M29*'AEO Coal Prod'!M29 -> 701.68184 | Z29: =N29*'AEO Coal Prod'!N29 -> 551.96137 | AA29: =O29*'AEO Coal Prod'!O29 -> 696.37031 | AB29: =P29*'AEO Coal Prod'!P29 -> 914.03116 | AC29: =Q29*'AEO Coal Prod'!Q29 -> 1090.2552 | AD29: =R29*'AEO Coal Prod'!R29 -> 1137.6836 | AE29: =S29*'AEO Coal Prod'!S29 -> 1192.5656
A30: High Sulfur (Lignite) | B30: w | C30: 16.875051 | D30: 21.772913 | E30: 23.997196 | F30: 25.169128 | G30: 26.153002 | H30: 26.94739 | I30: 27.840399 | L30: =M30*$U$60 -> 0.84194174 | M30: =C30*'Conversion Factors'!$C$41/Types!$R$27/$O$2/1000000 -> 1.2271446 | N30: =D30*'Conversion Factors'!$C$44/Types!$R$27/$O$2/1000000 -> 1.5078898 | O30: =E30*'Conversion Factors'!$C$44/Types!$R$27/$O$2/1000000 -> 1.6619332 | P30: =F30*'Conversion Factors'!$C$44/Types!$R$27/$O$2/1000000 -> 1.7430957 | Q30: =G30*'Conversion Factors'!$C$44/Types!$R$27/$O$2/1000000 -> 1.8112342 | R30: =H30*'Conversion Factors'!$C$44/Types!$R$27/$O$2/1000000 -> 1.8662498 | S30: =I30*'Conversion Factors'!$C$44/Types!$R$27/$O$2/1000000 -> 1.9280954 | X30: =L30*'AEO Coal Prod'!L30 -> 285.22482 | Y30: =M30*'AEO Coal Prod'!M30 -> 168.1493 | Z30: =N30*'AEO Coal Prod'!N30 -> 288.28888 | AA30: =O30*'AEO Coal Prod'!O30 -> 350.03731 | AB30: =P30*'AEO Coal Prod'!P30 -> 367.09231 | AC30: =Q30*'AEO Coal Prod'!Q30 -> 380.20274 | AD30: =R30*'AEO Coal Prod'!R30 -> 390.20136 | AE30: =S30*'AEO Coal Prod'!S30 -> 401.91409
A32: Dakota Medium Sulfur (Lignite) | B32: w | C32: 14.62882 | D32: 17.979803 | E32: 21.409149 | F32: 22.995337 | G32: 24.480183 | H32: 25.694098 | I32: 27.030115 | L32: =M32*$U$60 -> 0.6624645 | M32: =C32*'Conversion Factors'!$C$41/Types!$R$28/$O$2/1000000 -> 0.96555342 | N32: =D32*'Conversion Factors'!$C$44/Types!$R$28/$O$2/1000000 -> 1.1301976 | O32: =E32*'Conversion Factors'!$C$44/Types!$R$28/$O$2/1000000 -> 1.3457638 | P32: =F32*'Conversion Factors'!$C$44/Types!$R$28/$O$2/1000000 -> 1.4454705 | Q32: =G32*'Conversion Factors'!$C$44/Types!$R$28/$O$2/1000000 -> 1.5388068 | R32: =H32*'Conversion Factors'!$C$44/Types!$R$28/$O$2/1000000 -> 1.6151126 | S32: =I32*'Conversion Factors'!$C$44/Types!$R$28/$O$2/1000000 -> 1.6990937 | X32: =L32*'AEO Coal Prod'!L32 -> 279.66636 | Y32: =M32*'AEO Coal Prod'!M32 -> 384.6888 | Z32: =N32*'AEO Coal Prod'!N32 -> 464.66476 | AA32: =O32*'AEO Coal Prod'!O32 -> 578.81875 | AB32: =P32*'AEO Coal Prod'!P32 -> 621.60499 | AC32: =Q32*'AEO Coal Prod'!Q32 -> 665.12456 | AD32: =R32*'AEO Coal Prod'!R32 -> 695.87673 | AE32: =S32*'AEO Coal Prod'!S32 -> 734.14123
A34: Western Montana | B34: w | C34: 16.278589 | D34: 20.247177 | E34: 24.778656 | F34: 26.633322 | G34: 28.590448 | H34: 30.840282 | I34: 33.202961
A35: Low Sulfur (Bituminous) | D35: 26.604315 | E35: 31.389259 | F35: 31.413757 | G35: 31.854862 | H35: 34.179668 | I35: 36.578922 | L35: =B35*'Conversion Factors'!$C$38/Types!$R$29/$O$2/1000000 -> 0 | M35: =C35*'Conversion Factors'!$C$41/Types!$R$29/$O$2/1000000 -> 0 | N35: =D35*'Conversion Factors'!$C$44/Types!$R$29/$O$2/1000000 -> 1.1151669 | O35: =E35*'Conversion Factors'!$C$44/Types!$R$29/$O$2/1000000 -> 1.3157363 | P35: =F35*'Conversion Factors'!$C$44/Types!$R$29/$O$2/1000000 -> 1.3167631 | Q35: =G35*'Conversion Factors'!$C$44/Types!$R$29/$O$2/1000000 -> 1.3352528 | R35: =H35*'Conversion Factors'!$C$44/Types!$R$29/$O$2/1000000 -> 1.4327012 | S35: =I35*'Conversion Factors'!$C$44/Types!$R$29/$O$2/1000000 -> 1.5332702 | X35: =L35*'AEO Coal Prod'!L35 -> 0 | Y35: =M35*'AEO Coal Prod'!M35 -> 0 | Z35: =N35*'AEO Coal Prod'!N35 -> 262.83126 | AA35: =O35*'AEO Coal Prod'!O35 -> 391.97945 | AB35: =P35*'AEO Coal Prod'!P35 -> 345.96942 | AC35: =Q35*'AEO Coal Prod'!Q35 -> 334.18081 | AD35: =R35*'AEO Coal Prod'!R35 -> 414.4516 | AE35: =S35*'AEO Coal Prod'!S35 -> 455.12471
