Workbook
Name _1995_Implicit_GDP_Deflator: 'RTEKTY Conv'!#REF!
Name _2001_Implicit_GDP_Deflator: 'RTEKTY Conv'!#REF!
Name avg_water_heater_PJ: #REF!
Name avg_water_heater_PJ: #REF!
Name avg_water_heater_PJ: #REF!
Name avg_water_heater_PJ: #REF!
Name btu_per_watthr: 'RTEKTY Conv'!#REF!
Name btu_per_watthr: '[1]Conversion Factors'!$B$5
Name days_per_year: 'RTEKTY Conv'!#REF!
Name days_per_year: '[1]Conversion Factors'!$B$3
Name dollar____per__m: 'RTEKTY Conv'!#REF!
Name dollar____per__m: '[1]Conversion Factors'!$B$7
Name hours_per_day: 'RTEKTY Conv'!#REF!
Name hours_per_day: '[1]Conversion Factors'!$B$2
Name j_per_btu: 'RTEKTY Conv'!#REF!
Name j_per_btu: '[1]Conversion Factors'!$B$4
Name j_per_pj: 'RTEKTY Conv'!#REF!
Name j_per_pj: '[1]Conversion Factors'!$B$6
Name kwhr_per_j: 'RTEKTY Conv'!#REF!
Name lumens_per_billion_lumens: '[1]Conversion Factors'!$B$9
Name unit_per_million_unit: 'RTEKTY Conv'!#REF!

Sheet ANSv6.1-Commodities
A1: ANSWER-Commodities
B7: CommName | C7: CommDesc | D7: CommUnit | E7: Set Memberships | F7: Comment

Sheet ANSv6.1-Technologies
A1: ANSWER-Technologies
B7: TechName | C7: TechDesc | D7: TACTUnit | E7: TCAPUnit | F7: Set Memberships | G7: Comment

Sheet UC_SOL
A1: Minimum production of decentralized Commercial PV
A2: ~UC_Sets: R_E: AllRegions
E3: ~UC_T: UC_RHSRTS~LO
A4: UC_N | B4: Pset_PN | C4: Pset_CI | D4: Cset_CN | E4: Year | F4: UC_FLO | G4: UC_RHSRTS~LO~0 | H4: R0 | I4: R1 | J4: R2 | K4: R3 | L4: R4 | M4: R5 | N4: R6 | O4: UC_Desc
A5: UC_SOLRESELCactLO | B5: ESOLPVRES* | C5: SOLRES | D5: RESELC | E5: 2010 | F5: 1 | G5: 15 | J5: ='Rooftop Calc'!AC$65 -> 0.0071945835 | K5: ='Rooftop Calc'!AD$65 -> 0.0037523355 | L5: ='Rooftop Calc'!AE$65 -> 0.0011972254 | M5: ='Rooftop Calc'!AF$65 -> 0.0017437956 | N5: ='Rooftop Calc'!AG$65 -> 0.012993033 | Q5: =SUM(J5:N5) -> 0.026880973
B6: ESOLPVRES* | C6: SOLRES | D6: RESELC | E6: 2015 | F6: 1 | J6: ='Rooftop Calc'!AC$71 -> 0.109328 | K6: ='Rooftop Calc'!AD$71 -> 0.073448493 | L6: ='Rooftop Calc'!AE$71 -> 0.0093117528 | M6: ='Rooftop Calc'!AF$71 -> 0.32034551 | N6: ='Rooftop Calc'!AG$71 -> 0.17523498 | Q6: =SUM(J6:N6) -> 0.68766875
B7: ESOLPVRES* | C7: SOLRES | D7: RESELC | E7: 2020 | F7: 1 | J7: ='Rooftop Calc'!AC$77 -> 0.24496493 | K7: ='Rooftop Calc'!AD$77 -> 0.13820064 | L7: ='Rooftop Calc'!AE$77 -> 0.017877615 | M7: ='Rooftop Calc'!AF$77 -> 0.57042833 | N7: ='Rooftop Calc'!AG$77 -> 0.47194746 | Q7: =SUM(J7:N7) -> 1.443419
B8: ESOLPVRES* | C8: SOLRES | D8: RESELC | E8: 2025 | F8: 1 | J8: ='Rooftop Calc'!AC$84 -> 0.43039234 | K8: ='Rooftop Calc'!AD$84 -> 0.20768834 | L8: ='Rooftop Calc'!AE$84 -> 0.024528867 | M8: ='Rooftop Calc'!AF$84 -> 1.0833094 | N8: ='Rooftop Calc'!AG$84 -> 0.89934986 | Q8: =SUM(J8:N8) -> 2.6452688
B9: ESOLPVRES* | C9: SOLRES | D9: RESELC | E9: 2030 | F9: 1 | J9: ='Rooftop Calc'!AC$91 -> 0.61581975 | K9: ='Rooftop Calc'!AD$91 -> 0.27717603 | L9: ='Rooftop Calc'!AE$91 -> 0.031180119 | M9: ='Rooftop Calc'!AF$91 -> 1.5961905 | N9: ='Rooftop Calc'!AG$91 -> 1.3267523 | Q9: =SUM(J9:N9) -> 3.8471186
B10: ESOLPVRES* | C10: SOLRES | D10: RESELC | E10: 2035 | F10: 1 | J10: ='Rooftop Calc'!AC$98 -> 0.80124716 | K10: ='Rooftop Calc'!AD$98 -> 0.34666373 | L10: ='Rooftop Calc'!AE$98 -> 0.037831371 | M10: ='Rooftop Calc'!AF$98 -> 2.1090715 | N10: ='Rooftop Calc'!AG$98 -> 1.7541547 | Q10: =SUM(J10:N10) -> 5.0489684
B11: ESOLPVRES* | C11: SOLRES | D11: RESELC | E11: 2040 | F11: 1 | J11: ='Rooftop Calc'!AC$105 -> 0.98667458 | K11: ='Rooftop Calc'!AD$105 -> 0.41615142 | L11: ='Rooftop Calc'!AE$105 -> 0.044482623 | M11: ='Rooftop Calc'!AF$105 -> 2.6219526 | N11: ='Rooftop Calc'!AG$105 -> 2.1815571 | Q11: =SUM(J11:N11) -> 6.2508183
B12: ESOLPVRES* | C12: SOLRES | D12: RESELC | E12: 2045 | F12: 1 | J12: ='Rooftop Calc'!AC$112 -> 1.1649074 | K12: ='Rooftop Calc'!AD$112 -> 0.48188678 | L12: ='Rooftop Calc'!AE$112 -> 0.04993665 | M12: ='Rooftop Calc'!AF$112 -> 3.1330899 | N12: ='Rooftop Calc'!AG$112 -> 2.5959664 | Q12: =SUM(J12:N12) -> 7.4257871
B13: ESOLPVRES* | C13: SOLRES | D13: RESELC | E13: 2050 | F13: 1 | J13: ='Rooftop Calc'!AC$119 -> 1.2410068 | K13: ='Rooftop Calc'!AD$119 -> 0.47792598 | L13: ='Rooftop Calc'!AE$119 -> 0.047276149 | M13: ='Rooftop Calc'!AF$119 -> 3.3256254 | N13: ='Rooftop Calc'!AG$119 -> 2.8481338 | Q13: =SUM(J13:N13) -> 7.9399682
B14: ESOLPVRES* | C14: SOLRES | D14: RESELC | E14: 2055 | F14: 1 | J14: ='Rooftop Calc'!AC$126 -> 1.3072238 | K14: ='Rooftop Calc'!AD$126 -> 0.46631225 | L14: ='Rooftop Calc'!AE$126 -> 0.042167162 | M14: ='Rooftop Calc'!AF$126 -> 3.7957449 | N14: ='Rooftop Calc'!AG$126 -> 3.138694 | Q14: =SUM(J14:N14) -> 8.7501421
A18: Maximum production of decentralized Commercial PV
A19: ~UC_Sets: R_E: AllRegions
E20: ~UC_T: UC_RHSRTS~UP
A21: UC_N | B21: Pset_PN | C21: Pset_CI | D21: Cset_CN | E21: Year | F21: UC_FLO | G21: UC_RHSRTS~UP~0 | H21: R0 | I21: R1 | J21: R2 | K21: R3 | L21: R4 | M21: R5 | N21: R6 | O21: UC_Desc
A22: UC_SOLRESELCactUP | B22: ESOLPVRES* | C22: SOLRES | D22: RESELC | E22: 2010 | F22: 1 | G22: 15 | J22: ='Rooftop Calc'!AC$65 -> 0.0071945835 | K22: ='Rooftop Calc'!AD$65 -> 0.0037523355 | L22: ='Rooftop Calc'!AE$65 -> 0.0011972254 | M22: ='Rooftop Calc'!AF$65 -> 0.0017437956 | N22: ='Rooftop Calc'!AG$65 -> 0.012993033
B23: ESOLPVRES* | C23: SOLRES | D23: RESELC | E23: 2015 | F23: 1 | J23: ='Rooftop Calc'!AC$71 -> 0.109328 | K23: ='Rooftop Calc'!AD$71 -> 0.073448493 | L23: ='Rooftop Calc'!AE$71 -> 0.0093117528 | M23: ='Rooftop Calc'!AF$71 -> 0.32034551 | N23: ='Rooftop Calc'!AG$71 -> 0.17523498
B24: ESOLPVRES* | C24: SOLRES | D24: RESELC | E24: 2020 | F24: 1 | J24: ='Rooftop Calc'!AK$77 -> 0.37640069 | K24: ='Rooftop Calc'!AL$77 -> 0.25287267 | L24: ='Rooftop Calc'!AM$77 -> 0.032059035 | M24: ='Rooftop Calc'!AN$77 -> 1.1029038 | N24: ='Rooftop Calc'!AO$77 -> 0.60330901
B25: ESOLPVRES* | C25: SOLRES | D25: RESELC | E25: 2025 | F25: 1 | J25: ='Rooftop Calc'!AK$84 -> 0.64269247 | K25: ='Rooftop Calc'!AL$84 -> 0.43177221 | L25: ='Rooftop Calc'!AM$84 -> 0.054739804 | M25: ='Rooftop Calc'!AN$84 -> 1.883174 | N25: ='Rooftop Calc'!AO$84 -> 1.0301314
B26: ESOLPVRES* | C26: SOLRES | D26: RESELC | E26: 2030 | F26: 1 | J26: ='Rooftop Calc'!AK$91 -> 0.90976515 | K26: ='Rooftop Calc'!AL$91 -> 0.61119639 | L26: ='Rooftop Calc'!AM$91 -> 0.077487086 | M26: ='Rooftop Calc'!AN$91 -> 2.6657323 | N26: ='Rooftop Calc'!AO$91 -> 1.4582054
B27: ESOLPVRES* | C27: SOLRES | D27: RESELC | E27: 2035 | F27: 1 | J27: ='Rooftop Calc'!AK$98 -> 1.1760569 | K27: ='Rooftop Calc'!AL$98 -> 0.79009593 | L27: ='Rooftop Calc'!AM$98 -> 0.10016786 | M27: ='Rooftop Calc'!AN$98 -> 3.4460025 | N27: ='Rooftop Calc'!AO$98 -> 1.8850278
B28: ESOLPVRES* | C28: SOLRES | D28: RESELC | E28: 2040 | F28: 1 | J28: ='Rooftop Calc'!AK$105 -> 1.4431296 | K28: ='Rooftop Calc'!AL$105 -> 0.96952011 | L28: ='Rooftop Calc'!AM$105 -> 0.12291514 | M28: ='Rooftop Calc'!AN$105 -> 4.2285608 | N28: ='Rooftop Calc'!AO$105 -> 2.3131018
B29: ESOLPVRES* | C29: SOLRES | D29: RESELC | E29: 2045 | F29: 1 | J29: ='Rooftop Calc'!AK$112 -> 1.7094214 | K29: ='Rooftop Calc'!AL$112 -> 1.1484197 | L29: ='Rooftop Calc'!AM$112 -> 0.14559591 | M29: ='Rooftop Calc'!AN$112 -> 5.0088309 | N29: ='Rooftop Calc'!AO$112 -> 2.7399241
B30: ESOLPVRES* | C30: SOLRES | D30: RESELC | E30: 2050 | F30: 1 | J30: ='Rooftop Calc'!AK$119 -> 1.9764941 | K30: ='Rooftop Calc'!AL$119 -> 1.3278438 | L30: ='Rooftop Calc'!AM$119 -> 0.16834319 | M30: ='Rooftop Calc'!AN$119 -> 5.7913893 | N30: ='Rooftop Calc'!AO$119 -> 3.1679982
B31: ESOLPVRES* | C31: SOLRES | D31: RESELC | E31: 2055 | F31: 1 | J31: ='Rooftop Calc'!AK$126 -> 2.2427859 | K31: ='Rooftop Calc'!AL$126 -> 1.5067434 | L31: ='Rooftop Calc'!AM$126 -> 0.19102396 | M31: ='Rooftop Calc'!AN$126 -> 6.5716594 | N31: ='Rooftop Calc'!AO$126 -> 3.5948205
A34: Maximum capacity of decentralized Residential PV
A35: ~UC_Sets: R_E: AllRegions
E36: ~UC_T: UC_RHSRTS~UP
A37: UC_N | B37: Pset_PN | C37: Pset_CI | D37: Cset_CN | E37: Year | F37: UC_CAP | G37: UC_RHSRTS~UP~0 | H37: R0 | I37: R1 | J37: R2 | K37: R3 | L37: R4 | M37: R5 | N37: R6 | O37: UC_Desc
A38: UC_SOLRESELCCAPUP | B38: ESOLPVRES* | E38: 2025 | F38: 1 | G38: 5 | J38: =J39 -> 0.47406169 | K38: =K39 -> 0.31848306 | L38: =L39 -> 0.040377078 | M38: =M39 -> 1.3890635 | N38: =N39 -> 0.75984369
B39: ESOLPVRES* | E39: 2050 | F39: 1 | J39: =J31/31.54/0.15 -> 0.47406169 | K39: =K31/31.54/0.15 -> 0.31848306 | L39: =L31/31.54/0.15 -> 0.040377078 | M39: =M31/31.54/0.15 -> 1.3890635 | N39: =N31/31.54/0.15 -> 0.75984369

Sheet UC_RET
A1: Maximum Retrofit penetration
B3: ~UC_Sets: R_E: AllRegions
G5: ~UC_T: UC_COMPRD
B6: UC_N | C6: Pset_PN | D6: Pset_PD | E6: Pset_CI | F6: Cset_CN | G6: Year | H6: UC_FLO | I6: UC_RHSRTS~UP | J6: UC_RHSRTS~UP~0 | K6: R0 | L6: R1 | M6: R2 | N6: R3 | O6: R4 | P6: R5 | Q6: R6
B7: ="UC_"&F7&RIGHT(C7,6)&"UP" -> UC_RSHRETSMTUP | C7: RSHRETSMT | F7: RSH | G7: 2025 | H7: 1 | I7: 0 | J7: 5 | M7: 0 | N7: 0 | O7: 0 | P7: 0 | Q7: 0
C8: RSHRETSMT | F8: RSH | G8: 2050 | M8: =-Retrofit!$U$16 -> -0.061303428 | N8: =-Retrofit!$U$16 -> -0.061303428 | O8: =-Retrofit!$U$16 -> -0.061303428 | P8: =-Retrofit!$U$16 -> -0.061303428 | Q8: =-Retrofit!$U$16 -> -0.061303428
C9: RSHRETSMT | F9: RSH | G9: 2055 | M9: =M8 -> -0.061303428 | N9: =N8 -> -0.061303428 | O9: =O8 -> -0.061303428 | P9: =P8 -> -0.061303428 | Q9: =Q8 -> -0.061303428
B10: ="UC_"&F10&RIGHT(C10,6)&"UP" -> UC_RSHRETVEOUP | C10: RSHRETVEO | F10: RSH | G10: 2025 | H10: 1 | I10: 0 | J10: 5 | M10: 0 | N10: 0 | O10: 0 | P10: 0 | Q10: 0
C11: RSHRETVEO | F11: RSH | G11: 2050 | M11: =-Retrofit!$U$17 -> -0.011688391 | N11: =-Retrofit!$U$17 -> -0.011688391 | O11: =-Retrofit!$U$17 -> -0.011688391 | P11: =-Retrofit!$U$17 -> -0.011688391 | Q11: =-Retrofit!$U$17 -> -0.011688391
C12: RSHRETVEO | F12: RSH | G12: 2055 | M12: =M11 -> -0.011688391 | N12: =N11 -> -0.011688391 | O12: =O11 -> -0.011688391 | P12: =P11 -> -0.011688391 | Q12: =Q11 -> -0.011688391
B13: ="UC_"&F13&RIGHT(C13,6)&"UP" -> UC_RSHRETINRUP | C13: RSHRETINR | F13: RSH | G13: 2025 | H13: 1 | I13: 0 | J13: 5 | M13: 0 | N13: 0 | O13: 0 | P13: 0 | Q13: 0
C14: RSHRETINR | F14: RSH | G14: 2050 | M14: =-Retrofit!$U$18 -> -0.021582299 | N14: =-Retrofit!$U$18 -> -0.021582299 | O14: =-Retrofit!$U$18 -> -0.021582299 | P14: =-Retrofit!$U$18 -> -0.021582299 | Q14: =-Retrofit!$U$18 -> -0.021582299
C15: RSHRETINR | F15: RSH | G15: 2055 | M15: =M14 -> -0.021582299 | N15: =N14 -> -0.021582299 | O15: =O14 -> -0.021582299 | P15: =P14 -> -0.021582299 | Q15: =Q14 -> -0.021582299
B16: ="UC_"&F16&RIGHT(C16,6)&"UP" -> UC_RSHRETWIRUP | C16: RSHRETWIR | F16: RSH | G16: 2025 | H16: 1 | I16: 0 | J16: 5 | M16: 0 | N16: 0 | O16: 0 | P16: 0 | Q16: 0
C17: RSHRETWIR | F17: RSH | G17: 2050 | M17: =-Retrofit!$U$19 -> -0.058005459 | N17: =-Retrofit!$U$19 -> -0.058005459 | O17: =-Retrofit!$U$19 -> -0.058005459 | P17: =-Retrofit!$U$19 -> -0.058005459 | Q17: =-Retrofit!$U$19 -> -0.058005459
C18: RSHRETWIR | F18: RSH | G18: 2055 | M18: =M17 -> -0.058005459 | N18: =N17 -> -0.058005459 | O18: =O17 -> -0.058005459 | P18: =P17 -> -0.058005459 | Q18: =Q17 -> -0.058005459
B19: ="UC_"&F19&RIGHT(C19,6)&"UP" -> UC_RSHRETINWUP | C19: RSHRETINW | F19: RSH | G19: 2025 | H19: 1 | I19: 0 | J19: 5 | M19: 0 | N19: 0 | O19: 0 | P19: 0 | Q19: 0
C20: RSHRETINW | F20: RSH | G20: 2050 | M20: =-Retrofit!$U$20 -> -0.036253412 | N20: =-Retrofit!$U$20 -> -0.036253412 | O20: =-Retrofit!$U$20 -> -0.036253412 | P20: =-Retrofit!$U$20 -> -0.036253412 | Q20: =-Retrofit!$U$20 -> -0.036253412
C21: RSHRETINW | F21: RSH | G21: 2055 | M21: =M20 -> -0.036253412 | N21: =N20 -> -0.036253412 | O21: =O20 -> -0.036253412 | P21: =P20 -> -0.036253412 | Q21: =Q20 -> -0.036253412

Sheet UC_DMD
A3: Minimum capacity technology growth:
A4: ~UC_Sets: R_E: R2,R3,R4,R5,R6
A5: ~UC_Sets: T_SUC:
G6: ~UC_T
A7: UC_N | B7: Pset_PN | C7: Pset_CI | D7: Pset_CO | E7: UC_ATTR | F7: Year | G7: LimType | H7: UC_CAP~2015 | I7: UC_CAP~2020 | J7: UC_CAP~2025 | K7: UC_CAP~2030 | L7: UC_CAP~2035 | M7: UC_CAP~2040 | N7: UC_CAP~2045 | O7: UC_CAP~2050 | P7: UC_CAP~2055 | Q7: UC_CAP~RHS | R7: UC_RHSRTS | S7: UC_RHSRTS~0 | T7: UC_Desc
A8: UC_GrowthOfRES1 | B8: RSHERDV1* | E8: CAP, GROWTH | G8: UP | I8: 1.1 | J8: =I8 -> 1.1 | K8: =J8 -> 1.1 | L8: =K8 -> 1.1 | M8: =L8 -> 1.1 | N8: =M8 -> 1.1 | O8: =N8 -> 1.1 | P8: =O8 -> 1.1 | Q8: 1 | S8: 5
A9: UC_GrowthOfRES2 | B9: RWHDWHBS* | E9: CAP, GROWTH | G9: UP | H9: 1.1 | I9: =H9 -> 1.1 | J9: =I9 -> 1.1 | K9: =J9 -> 1.1 | L9: =K9 -> 1.1 | M9: =L9 -> 1.1 | N9: =M9 -> 1.1 | O9: =N9 -> 1.1 | P9: =O9 -> 1.1 | Q9: 1 | S9: 5
A10: UC_GrowthOfRES3 | B10: RWHDWHV1* | E10: CAP, GROWTH | G10: UP | H10: 1.1 | I10: =H10 -> 1.1 | J10: =I10 -> 1.1 | K10: =J10 -> 1.1 | L10: =K10 -> 1.1 | M10: =L10 -> 1.1 | N10: =M10 -> 1.1 | O10: =N10 -> 1.1 | P10: =O10 -> 1.1 | Q10: 1 | S10: 5
A11: UC_GrowthOfRES4 | B11: RWHDWHV2* | E11: CAP, GROWTH | G11: UP | H11: 1.1 | I11: =H11 -> 1.1 | J11: =I11 -> 1.1 | K11: =J11 -> 1.1 | L11: =K11 -> 1.1 | M11: =L11 -> 1.1 | N11: =M11 -> 1.1 | O11: =N11 -> 1.1 | P11: =O11 -> 1.1 | Q11: 1 | S11: 5
A12: UC_GrowthOfRES5 | B12: RWHDWHV3* | E12: CAP, GROWTH | G12: UP | H12: 1.1 | I12: =H12 -> 1.1 | J12: =I12 -> 1.1 | K12: =J12 -> 1.1 | L12: =K12 -> 1.1 | M12: =L12 -> 1.1 | N12: =M12 -> 1.1 | O12: =N12 -> 1.1 | P12: =O12 -> 1.1 | Q12: 1 | S12: 5
A13: UC_GrowthOfRES6 | B13: RLTGCFLBS* | E13: CAP, GROWTH | G13: UP | I13: 1.15 | J13: =I13 -> 1.15 | K13: =J13 -> 1.15 | L13: =K13 -> 1.15 | M13: =L13 -> 1.15 | N13: =M13 -> 1.15 | O13: =N13 -> 1.15 | P13: =O13 -> 1.15 | Q13: 1 | S13: 5
A14: UC_GrowthOfRES7 | B14: RLTGCFL10,RLTGCFL11 | E14: CAP, GROWTH | G14: UP | I14: 1.15 | J14: =I14 -> 1.15 | K14: =J14 -> 1.15 | L14: =K14 -> 1.15 | M14: =L14 -> 1.15 | N14: =M14 -> 1.15 | O14: =N14 -> 1.15 | P14: =O14 -> 1.15 | Q14: 1 | S14: 5
A15: UC_GrowthOfRES8 | B15: RLTGCFL15 | E15: CAP, GROWTH | G15: UP | I15: 1.15 | J15: =I15 -> 1.15 | K15: =J15 -> 1.15 | L15: =K15 -> 1.15 | M15: =L15 -> 1.15 | N15: =M15 -> 1.15 | O15: =N15 -> 1.15 | P15: =O15 -> 1.15 | Q15: 1 | S15: 5
A16: UC_GrowthOfRES9 | B16: RLTGCFL20 | E16: CAP, GROWTH | G16: UP | I16: 1.15 | J16: =I16 -> 1.15 | K16: =J16 -> 1.15 | L16: =K16 -> 1.15 | M16: =L16 -> 1.15 | N16: =M16 -> 1.15 | O16: =N16 -> 1.15 | P16: =O16 -> 1.15 | Q16: 1 | S16: 5
A17: UC_GrowthOfRES10 | B17: RLTGCFL30 | E17: CAP, GROWTH | G17: UP | I17: 1.15 | J17: =I17 -> 1.15 | K17: =J17 -> 1.15 | L17: =K17 -> 1.15 | M17: =L17 -> 1.15 | N17: =M17 -> 1.15 | O17: =N17 -> 1.15 | P17: =O17 -> 1.15 | Q17: 1 | S17: 5
A18: UC_GrowthOfRES11 | B18: RLTGCFL40 | E18: CAP, GROWTH | G18: UP | I18: 1.15 | J18: =I18 -> 1.15 | K18: =J18 -> 1.15 | L18: =K18 -> 1.15 | M18: =L18 -> 1.15 | N18: =M18 -> 1.15 | O18: =N18 -> 1.15 | P18: =O18 -> 1.15 | Q18: 1 | S18: 5
A19: UC_GrowthOfRES12 | B19: RLTGLED10,RLTGLED11 | E19: CAP, GROWTH | G19: UP | I19: 1.15 | J19: =I19 -> 1.15 | K19: =J19 -> 1.15 | L19: =K19 -> 1.15 | M19: =L19 -> 1.15 | N19: =M19 -> 1.15 | O19: =N19 -> 1.15 | P19: =O19 -> 1.15 | Q19: 1 | S19: 5
A20: UC_GrowthOfRES13 | B20: RLTGLED15 | E20: CAP, GROWTH | G20: UP | I20: 1.15 | J20: =I20 -> 1.15 | K20: =J20 -> 1.15 | L20: =K20 -> 1.15 | M20: =L20 -> 1.15 | N20: =M20 -> 1.15 | O20: =N20 -> 1.15 | P20: =O20 -> 1.15 | Q20: 1 | S20: 5
A21: UC_GrowthOfRES14 | B21: RLTGLED20 | E21: CAP, GROWTH | G21: UP | I21: 1.15 | J21: =I21 -> 1.15 | K21: =J21 -> 1.15 | L21: =K21 -> 1.15 | M21: =L21 -> 1.15 | N21: =M21 -> 1.15 | O21: =N21 -> 1.15 | P21: =O21 -> 1.15 | Q21: 1 | S21: 5
A22: UC_GrowthOfRES15 | B22: RLTGLED25 | E22: CAP, GROWTH | G22: UP | I22: 1.15 | J22: =I22 -> 1.15 | K22: =J22 -> 1.15 | L22: =K22 -> 1.15 | M22: =L22 -> 1.15 | N22: =M22 -> 1.15 | O22: =N22 -> 1.15 | P22: =O22 -> 1.15 | Q22: 1 | S22: 5
A23: UC_GrowthOfRES16 | B23: RLTGLED30 | E23: CAP, GROWTH | G23: UP | I23: 1.15 | J23: =I23 -> 1.15 | K23: =J23 -> 1.15 | L23: =K23 -> 1.15 | M23: =L23 -> 1.15 | N23: =M23 -> 1.15 | O23: =N23 -> 1.15 | P23: =O23 -> 1.15 | Q23: 1 | S23: 5
A24: UC_GrowthOfRES17 | B24: RLTGLED40 | E24: CAP, GROWTH | G24: UP | I24: 1.15 | J24: =I24 -> 1.15 | K24: =J24 -> 1.15 | L24: =K24 -> 1.15 | M24: =L24 -> 1.15 | N24: =M24 -> 1.15 | O24: =N24 -> 1.15 | P24: =O24 -> 1.15 | Q24: 1 | S24: 5
... A31: UC_GrowthOfRES24 | B31: RLTECFL40 | E31: CAP, GROWTH | G31: UP | I31: 1.15 | J31: =I31 -> 1.15 | K31: =J31 -> 1.15 | L31: =K31 -> 1.15 | M31: =L31 -> 1.15 | N31: =M31 -> 1.15 | O31: =N31 -> 1.15 | P31: =O31 -> 1.15 | Q31: 1 | S31: 5

Sheet UC_RES
B2: ~UC_Sets: R_E: AllRegions | M2: 0.73 | N2: 0.73 | O2: 0.73 | P2: 0.73 | Q2: 0.73
G4: ~UC_T: UC_COMPRD
B5: UC_N | C5: Pset_PN | D5: Pset_PD | E5: Pset_CI | F5: Cset_CN | G5: Year | H5: UC_FLO | I5: UC_RHSRTS~LO | J5: UC_RHSRTS~LO~0 | K5: R0 | L5: R1 | M5: R2 | N5: R3 | O5: R4 | P5: R5 | Q5: R6
B6: ="UC_"&F6&RIGHT(E6,5)&"LO" -> UC_RSHDSLEALO | C6: RSH* | E6: RESDSLEA | F6: RSH | G6: 2015 | H6: 1 | I6: 0 | J6: 5 | M6: =-SUM(Original!$M$3:$M$12)/SUM(Original!$AS$3:$AS$12)*0.95 -> -0.17414271 | N6: =M6 -> -0.17414271 | O6: =N6 -> -0.17414271 | P6: =O6 -> -0.17414271 | Q6: =P6 -> -0.17414271
C7: RSH* | E7: RESDSLEA | F7: RSH | G7: 2020 | H7: 1 | M7: =M49 -> -0.12333941 | N7: =N49 -> -0.12333941 | O7: =O49 -> -0.12333941 | P7: =P49 -> -0.12333941 | Q7: =Q49 -> -0.12333941
C8: =C7 -> RSH* | E8: =E7 -> RESDSLEA | F8: =F7 -> RSH | G8: 2025 | H8: 1 | M8: =M7*0.95 -> -0.11717244 | N8: =N7*0.95 -> -0.11717244 | O8: =O7*0.95 -> -0.11717244 | P8: =P7*0.95 -> -0.11717244 | Q8: =Q7*0.95 -> -0.11717244
C9: RSH* | E9: RESDSLEA | F9: RSH | G9: 2055 | H9: 1 | M9: 0 | N9: 0 | O9: 0 | P9: 0 | Q9: 0
B10: ="UC_"&F10&RIGHT(E10,5)&"LO" -> UC_RSHESELCLO | C10: RSH* | E10: RESELC | F10: RSH | G10: 2015 | H10: 1 | I10: 0 | J10: 5 | M10: =-SUM(Original!$U$3:$U$12)/SUM(Original!$AS$3:$AS$12)*0.5 -> -0.0090098107 | N10: =M10 -> -0.0090098107 | O10: =N10 -> -0.0090098107 | P10: =O10 -> -0.0090098107 | Q10: =P10 -> -0.0090098107
C11: RSH* | E11: RESELC | F11: RSH | G11: 2020 | H11: 1 | M11: =M10 -> -0.0090098107 | N11: =N10 -> -0.0090098107 | O11: =O10 -> -0.0090098107 | P11: =P10 -> -0.0090098107 | Q11: =Q10 -> -0.0090098107
C12: =C11 -> RSH* | E12: =E11 -> RESELC | F12: =F11 -> RSH | G12: 2025 | H12: 1 | M12: =M11*0.95 -> -0.0085593202 | N12: =N11*0.95 -> -0.0085593202 | O12: =O11*0.95 -> -0.0085593202 | P12: =P11*0.95 -> -0.0085593202 | Q12: =Q11*0.95 -> -0.0085593202
C13: RSH* | E13: RESELC | F13: RSH | G13: 2055 | H13: 1 | M13: -0.003 | N13: =M13 -> -0.003 | O13: =N13 -> -0.003 | P13: =O13 -> -0.003 | Q13: =P13 -> -0.003
B14: ="UC_"&F14&RIGHT(E14,5)&"LO" -> UC_RSHNGAEALO | C14: RSH* | E14: RESNGAEA | F14: RSH | G14: 2015 | H14: 1 | I14: 0 | J14: 5 | M14: =-SUM(Original!$AC$3:$AC$12)/SUM(Original!$AS$3:$AS$12)*0.95 -> -0.73385435 | N14: =M14 -> -0.73385435 | O14: =N14 -> -0.73385435 | P14: =O14 -> -0.73385435 | Q14: =P14 -> -0.73385435
C15: RSH* | E15: RESNGAEA | F15: RSH | G15: 2020 | H15: 1 | M15: =M14 -> -0.73385435 | N15: =N14 -> -0.73385435 | O15: =O14 -> -0.73385435 | P15: =P14 -> -0.73385435 | Q15: =Q14 -> -0.73385435
C16: =C15 -> RSH* | E16: =E15 -> RESNGAEA | F16: =F15 -> RSH | G16: 2025 | H16: 1 | M16: =M15*0.95 -> -0.69716163 | N16: =N15*0.95 -> -0.69716163 | O16: =O15*0.95 -> -0.69716163 | P16: =P15*0.95 -> -0.69716163 | Q16: =Q15*0.95 -> -0.69716163
C17: RSH* | E17: RESNGAEA | F17: RSH | G17: 2055 | H17: 1 | M17: 0 | N17: 0 | O17: 0 | P17: 0 | Q17: 0
B18: ="UC_"&F18&RIGHT(E18,5)&"Furnace"&"LO" -> UC_RSHFurnaceLO | C18: RSH* | D18: *Furnace* | F18: RSH | G18: 2015 | H18: 1 | I18: 0 | J18: 5 | M18: =-'RECS RESID'!$AL$16*0.9 -> -0.46637561 | N18: =M18 -> -0.46637561 | O18: =N18 -> -0.46637561 | P18: =O18 -> -0.46637561 | Q18: =P18 -> -0.46637561
C19: RSH* | D19: *Furnace* | F19: RSH | G19: 2025 | H19: 1 | M19: =M18*0.9 -> -0.41973805 | N19: =N18*0.9 -> -0.41973805 | O19: =O18*0.9 -> -0.41973805 | P19: =P18*0.9 -> -0.41973805 | Q19: =Q18*0.9 -> -0.41973805
C20: RSH* | D20: *Furnace* | F20: RSH | G20: 2055 | H20: 1 | M20: =M18*M$2 -> -0.34045419 | N20: =N18*N$2 -> -0.34045419 | O20: =O18*O$2 -> -0.34045419 | P20: =P18*P$2 -> -0.34045419 | Q20: =Q18*Q$2 -> -0.34045419
B21: ="UC_"&F21&RIGHT(D21,5)&"LO" -> UC_RSHPump*LO | C21: RSH* | D21: *Heat Pump* | F21: RSH | G21: 2015 | H21: 1 | I21: 0 | J21: 5 | M21: -0.006448043 | N21: =M21 -> -0.006448043 | O21: =N21 -> -0.006448043 | P21: =O21 -> -0.006448043 | Q21: =P21 -> -0.006448043
C22: RSH* | D22: *Heat Pump* | F22: RSH | G22: 2025 | H22: 1 | M22: =M21*0.9 -> -0.0058032387 | N22: =N21*0.9 -> -0.0058032387 | O22: =O21*0.9 -> -0.0058032387 | P22: =P21*0.9 -> -0.0058032387 | Q22: =Q21*0.9 -> -0.0058032387
C23: RSH* | D23: *Heat Pump* | F23: RSH | G23: 2055 | H23: 1 | M23: =M21*M$2 -> -0.0047070714 | N23: =N21*N$2 -> -0.0047070714 | O23: =O21*O$2 -> -0.0047070714 | P23: =P21*P$2 -> -0.0047070714 | Q23: =Q21*Q$2 -> -0.0047070714
B24: ="UC_"&F24&RIGHT(E24,5)&"LO" -> UC_RSHLO | C24: RSH* | D24: *Radiant* | F24: RSH | G24: 2015 | H24: 1 | I24: 0 | J24: 5 | M24: =-'RECS RESID'!$AL$18*0.9 -> -0.42703251 | N24: =M24 -> -0.42703251 | O24: =N24 -> -0.42703251 | P24: =O24 -> -0.42703251 | Q24: =P24 -> -0.42703251
C25: RSH* | D25: *Radiant* | F25: RSH | G25: 2025 | H25: 1 | M25: =M24*0.9 -> -0.38432926 | N25: =N24*0.9 -> -0.38432926 | O25: =O24*0.9 -> -0.38432926 | P25: =P24*0.9 -> -0.38432926 | Q25: =Q24*0.9 -> -0.38432926
C26: RSH* | D26: *Radiant* | F26: RSH | G26: 2055 | H26: 1 | M26: =M24*M$2 -> -0.31173374 | N26: =N24*N$2 -> -0.31173374 | O26: =O24*O$2 -> -0.31173374 | P26: =P24*P$2 -> -0.31173374 | Q26: =Q24*Q$2 -> -0.31173374
B27: ="UC_"&F27&"UTI"&"LO" -> UC_RSHUTILO | C27: RSH*UTI* | F27: RSH | G27: 2015 | H27: 1 | I27: 0 | J27: 5 | M27: 0 | N27: 0 | O27: =-25.03*0.16/58 -> -0.069048276 | P27: 0 | Q27: 0
C28: RSH*UTI* | F28: RSH | G28: 2025 | H28: 1 | M28: 0 | N28: 0 | O28: =O52*0.95 -> -0.065595862 | P28: 0 | Q28: 0
C29: RSH*UTI* | F29: RSH | G29: 2055 | H29: 1 | M29: 0 | N29: 0 | O29: =O53*O2 -> -0.075607862 | P29: 0 | Q29: 0
M31: ='2010 GHG Emissions'!$M$2 -> 0.61168452 | N31: =M31 -> 0.61168452 | O31: =N31 -> 0.61168452 | P31: =O31 -> 0.61168452 | Q31: =P31 -> 0.61168452
M32: 1.2 | N32: 1.2 | O32: 1.2 | P32: 1.2 | Q32: 1.2
M33: 1.5 | N33: 1.5 | O33: 1.5 | P33: 1.5 | Q33: 1.5
B35: ~UC_Sets: R_E: AllRegions
G37: ~UC_T: UC_COMPRD
B38: UC_N | C38: Pset_PN | D38: Pset_PD | E38: Pset_CI | F38: Cset_CN | G38: Year | H38: UC_FLO | I38: UC_RHSRTS~UP | J38: UC_RHSRTS~UP~0 | K38: R0 | L38: R1 | M38: R2 | N38: R3 | O38: R4 | P38: R5 | Q38: R6
B39: ="UC_"&F39&RIGHT(E39,5)&"Furnace"&"UP" -> UC_RSHDSLEAFurnaceUP | C39: RSH* | D39: *Furnace* | E39: RESDSLEA | F39: RSH | G39: 2015 | H39: 1 | I39: 0 | J39: 5 | M39: =-0.15 -> -0.15 | N39: =M39 -> -0.15 | O39: =N39 -> -0.15 | P39: =O39 -> -0.15 | Q39: =P39 -> -0.15
C40: RSH* | D40: *Furnace* | E40: RESDSLEA | F40: RSH | G40: 2025 | H40: 1 | M40: =M39*M$31 -> -0.091752678 | N40: =N39*N$31 -> -0.091752678 | O40: =O39*O$31 -> -0.091752678 | P40: =P39*P$31 -> -0.091752678 | Q40: =Q39*Q$31 -> -0.091752678
C41: RSH* | D41: *Furnace* | E41: RESDSLEA | F41: RSH | G41: 2055 | H41: 1 | M41: =M40 -> -0.091752678 | N41: =N40 -> -0.091752678 | O41: =O40 -> -0.091752678 | P41: =P40 -> -0.091752678 | Q41: =Q40 -> -0.091752678
B42: ="UC_"&F42&RIGHT(E42,5)&"Furnace"&"UP" -> UC_RSHESELCFurnaceUP | C42: RSH* | D42: *Furnace* | E42: RESELC | F42: RSH | G42: 2020 | H42: 1 | I42: 0 | J42: 5 | M42: =-1.1*Assumptions_MI!$K$34 -> -0.044 | N42: =M42 -> -0.044 | O42: =N42 -> -0.044 | P42: =O42 -> -0.044 | Q42: =P42 -> -0.044
C43: RSH* | D43: *Furnace* | E43: RESELC | F43: RSH | G43: 2030 | H43: 1 | M43: =M42 -> -0.044 | N43: =N42 -> -0.044 | O43: =O42 -> -0.044 | P43: =P42 -> -0.044 | Q43: =Q42 -> -0.044
C44: RSH* | D44: *Furnace* | E44: RESELC | F44: RSH | G44: 2055 | H44: 1 | M44: =M43*M$33 -> -0.066 | N44: =N43*N$33 -> -0.066 | O44: =O43*O$33 -> -0.066 | P44: =P43*P$33 -> -0.066 | Q44: =Q43*Q$33 -> -0.066
B45: ="UC_"&F45&RIGHT(E45,5)&"UP" -> UC_RSHESELCUP | C45: RSH* | E45: RESELC | F45: RSH | G45: 2015 | H45: 1 | I45: 0 | J45: 5 | M45: =-SUM(Original!$U$3:$U$12)/SUM(Original!$AS$3:$AS$12) -> -0.018019621 | N45: =M45 -> -0.018019621 | O45: =N45 -> -0.018019621 | P45: =O45 -> -0.018019621 | Q45: =P45 -> -0.018019621
...

Sheet TechData_SolarPV
A1: TechData | B1: _GLOBAL,R0,R1,R2,R3,R4,R5,R6
F4: ~FI_T
A5: Region | B5: TechName | C5: *TechDesc | D5: *Units | E5: CommIN | F5: CommOUT | G5: NCAP_START | H5: NCAP_TLIFE | I5: PRC_CAPACT | J5: EFF | K5: Peak | L5: PRC_RESID~2010 | M5: NCAP_COST~2010 | N5: NCAP_COST~2015 | O5: NCAP_COST~2020 | P5: NCAP_COST~2025 | Q5: NCAP_COST~2030 | R5: NCAP_COST~2035 | S5: NCAP_COST~2040 | T5: NCAP_COST~2045 | U5: NCAP_COST~2050 | V5: NCAP_COST~2055 | W5: NCAP_FOM | X5: NCAP_AF~IDAM | Y5: NCAP_AF~IDPM | Z5: NCAP_AF~IP | AA5: NCAP_AF~IN | AB5: NCAP_AF~SDAM | AC5: NCAP_AF~SDPM | AD5: NCAP_AF~SP | AE5: NCAP_AF~SN | AF5: NCAP_AF~WDAM | AG5: NCAP_AF~WDPM | AH5: NCAP_AF~WP | AI5: NCAP_AF~WN | AJ5: NCAP_DRATE | AL5: Input | AM5: Output | AO5: ACT_BND~FX~2010 | AP5: ACT_BND~FX~2015 | AQ5: ACT_BND~LO~2020 | AR5: ACT_BND~LO~2025 | AS5: ACT_BND~LO~2030 | AT5: ACT_BND~LO~2035 | AU5: ACT_BND~LO~2040 | AV5: ACT_BND~LO~2045 | AW5: ACT_BND~LO~2050 | AX5: ACT_BND~LO~2055 | AY5: ACT_BND~UP~2020 | AZ5: ACT_BND~UP~2025 | BA5: ACT_BND~UP~2030 | BB5: ACT_BND~UP~2035 | BC5: ACT_BND~UP~2040 | BD5: ACT_BND~UP~2045 | BE5: ACT_BND~UP~2050 | BF5: ACT_BND~UP~2055
A6: * Solar PV Technologies
A7: *R1 | B7: ESOLPVRES | C7: Solar PV Distributed Residential Generation | E7: SOLRES | F7: ELC | G7: 2010 | H7: 30 | I7: 31.536 | J7: =AM7/AL7 -> 0.34965035 | K7: 0.3 | L7: =AO7/I7 -> 0 | M7: 6546.9995 | N7: 3903.1781 | O7: 3453.8021 | P7: 3004.4261 | Q7: 2839.3022 | R7: 2674.1784 | S7: 2596.418 | T7: 2558.6683 | U7: 2540.0679 | V7: 2530.8353 | W7: 10 | X7: 0 | Y7: 0.31357247 | Z7: 0.31357247 | AA7: 0 | AB7: 0.3060734 | AC7: 0.3060734 | AD7: 0.3060734 | AE7: 0 | AF7: 0.3020009 | AG7: 0.3020009 | AH7: 0.3020009 | AI7: 0 | AJ7: 0.15 | AL7: 2.86 | AM7: 1
A8: R2 | B8: ESOLPVRES | C8: Solar PV Distributed Residential Generation | E8: SOLRES | F8: ELC | G8: 2010 | H8: 30 | I8: 31.536 | J8: =AM8/AL8 -> 0.34965035 | K8: 0.3 | L8: =AO8/I8 -> 0.00022813875 | M8: 6546.9995 | N8: 3903.1781 | O8: 3453.8021 | P8: 3004.4261 | Q8: 2839.3022 | R8: 2674.1784 | S8: 2596.418 | T8: 2558.6683 | U8: 2540.0679 | V8: 2530.8353 | W8: 10 | X8: 0 | Y8: 0.317351 | Z8: 0.317351 | AA8: 0 | AB8: 0.30541737 | AC8: 0.30541737 | AD8: 0.30541737 | AE8: 0 | AF8: 0.29271621 | AG8: 0.29271621 | AH8: 0.29271621 | AI8: 0 | AJ8: 0.15 | AL8: 2.86 | AM8: 1 | AO8: ='Rooftop Calc'!AC65 -> 0.0071945835 | AP8: ='Rooftop Calc'!AC71 -> 0.109328 | AQ8: ='Rooftop Calc'!AC77 -> 0.24496493 | AR8: ='Rooftop Calc'!AC84 -> 0.43039234 | AS8: ='Rooftop Calc'!AC91 -> 0.61581975 | AT8: ='Rooftop Calc'!AC98 -> 0.80124716 | AU8: ='Rooftop Calc'!AC105 -> 0.98667458 | AV8: ='Rooftop Calc'!AC112 -> 1.1649074 | AW8: ='Rooftop Calc'!AC119 -> 1.2410068 | AX8: ='Rooftop Calc'!AC126 -> 1.3072238 | AY8: ='Rooftop Calc'!AK77 -> 0.37640069 | AZ8: ='Rooftop Calc'!AK84 -> 0.64269247 | BA8: ='Rooftop Calc'!AK91 -> 0.90976515 | BB8: ='Rooftop Calc'!AK98 -> 1.1760569 | BC8: ='Rooftop Calc'!AK105 -> 1.4431296 | BD8: ='Rooftop Calc'!AK112 -> 1.7094214 | BE8: ='Rooftop Calc'!AK119 -> 1.9764941 | BF8: ='Rooftop Calc'!AK126 -> 2.2427859
A9: R3 | B9: ESOLPVRES | C9: Solar PV Distributed Residential Generation | E9: SOLRES | F9: ELC | G9: 2010 | H9: 30 | I9: 31.536 | J9: =AM9/AL9 -> 0.34965035 | K9: 0.3 | L9: =AO9/I9 -> 0.00011898578 | M9: 6546.9995 | N9: 3903.1781 | O9: 3453.8021 | P9: 3004.4261 | Q9: 2839.3022 | R9: 2674.1784 | S9: 2596.418 | T9: 2558.6683 | U9: 2540.0679 | V9: 2530.8353 | W9: 10 | X9: 0 | Y9: 0.29713464 | Z9: 0.29713464 | AA9: 0 | AB9: 0.30672516 | AC9: 0.30672516 | AD9: 0.30672516 | AE9: 0 | AF9: 0.26137287 | AG9: 0.26137287 | AH9: 0.26137287 | AI9: 0 | AJ9: 0.15 | AL9: 2.86 | AM9: 1 | AO9: ='Rooftop Calc'!AD65 -> 0.0037523355 | AP9: ='Rooftop Calc'!AD71 -> 0.073448493 | AQ9: ='Rooftop Calc'!AD77 -> 0.13820064 | AR9: ='Rooftop Calc'!AD84 -> 0.20768834 | AS9: ='Rooftop Calc'!AD91 -> 0.27717603 | AT9: ='Rooftop Calc'!AD98 -> 0.34666373 | AU9: ='Rooftop Calc'!AD105 -> 0.41615142 | AV9: ='Rooftop Calc'!AD112 -> 0.48188678 | AW9: ='Rooftop Calc'!AD119 -> 0.47792598 | AX9: ='Rooftop Calc'!AD126 -> 0.46631225 | AY9: ='Rooftop Calc'!AL77 -> 0.25287267 | AZ9: ='Rooftop Calc'!AL84 -> 0.43177221 | BA9: ='Rooftop Calc'!AL91 -> 0.61119639 | BB9: ='Rooftop Calc'!AL98 -> 0.79009593 | BC9: ='Rooftop Calc'!AL105 -> 0.96952011 | BD9: ='Rooftop Calc'!AL112 -> 1.1484197 | BE9: ='Rooftop Calc'!AL119 -> 1.3278438 | BF9: ='Rooftop Calc'!AL126 -> 1.5067434
A10: R4 | B10: ESOLPVRES | C10: Solar PV Distributed Residential Generation | E10: SOLRES | F10: ELC | G10: 2010 | H10: 30 | I10: 31.536 | J10: =AM10/AL10 -> 0.34965035 | K10: 0.3 | L10: =AO10/I10 -> 3.7963767e-05 | M10: 6546.9995 | N10: 3903.1781 | O10: 3453.8021 | P10: 3004.4261 | Q10: 2839.3022 | R10: 2674.1784 | S10: 2596.418 | T10: 2558.6683 | U10: 2540.0679 | V10: 2530.8353 | W10: 10 | X10: 0 | Y10: 0.33039362 | Z10: 0.33039362 | AA10: 0 | AB10: 0.32440092 | AC10: 0.32440092 | AD10: 0.32440092 | AE10: 0 | AF10: 0.34679382 | AG10: 0.34679382 | AH10: 0.34679382 | AI10: 0 | AJ10: 0.15 | AL10: 2.86 | AM10: 1 | AO10: ='Rooftop Calc'!AE65 -> 0.0011972254 | AP10: ='Rooftop Calc'!AE71 -> 0.0093117528 | AQ10: ='Rooftop Calc'!AE77 -> 0.017877615 | AR10: ='Rooftop Calc'!AE84 -> 0.024528867 | AS10: ='Rooftop Calc'!AE91 -> 0.031180119 | AT10: ='Rooftop Calc'!AE98 -> 0.037831371 | AU10: ='Rooftop Calc'!AE105 -> 0.044482623 | AV10: ='Rooftop Calc'!AE112 -> 0.04993665 | AW10: ='Rooftop Calc'!AE119 -> 0.047276149 | AX10: ='Rooftop Calc'!AE126 -> 0.042167162 | AY10: ='Rooftop Calc'!AM77 -> 0.032059035 | AZ10: ='Rooftop Calc'!AM84 -> 0.054739804 | BA10: ='Rooftop Calc'!AM91 -> 0.077487086 | BB10: ='Rooftop Calc'!AM98 -> 0.10016786 | BC10: ='Rooftop Calc'!AM105 -> 0.12291514 | BD10: ='Rooftop Calc'!AM112 -> 0.14559591 | BE10: ='Rooftop Calc'!AM119 -> 0.16834319 | BF10: ='Rooftop Calc'!AM126 -> 0.19102396
A11: R5 | B11: ESOLPVRES | C11: Solar PV Distributed Residential Generation | E11: SOLRES | F11: ELC | G11: 2010 | H11: 30 | I11: 31.536 | J11: =AM11/AL11 -> 0.34965035 | K11: 0.3 | L11: =AO11/I11 -> 5.5295397e-05 | M11: 6546.9995 | N11: 3903.1781 | O11: 3453.8021 | P11: 3004.4261 | Q11: 2839.3022 | R11: 2674.1784 | S11: 2596.418 | T11: 2558.6683 | U11: 2540.0679 | V11: 2530.8353 | W11: 10 | X11: 0 | Y11: 0.34379748 | Z11: 0.34379748 | AA11: 0 | AB11: 0.29466039 | AC11: 0.29466039 | AD11: 0.29466039 | AE11: 0 | AF11: 0.36077416 | AG11: 0.36077416 | AH11: 0.36077416 | AI11: 0 | AJ11: 0.15 | AL11: 2.86 | AM11: 1 | AO11: ='Rooftop Calc'!AF65 -> 0.0017437956 | AP11: ='Rooftop Calc'!AF71 -> 0.32034551 | AQ11: ='Rooftop Calc'!AF77 -> 0.57042833 | AR11: ='Rooftop Calc'!AF84 -> 1.0833094 | AS11: ='Rooftop Calc'!AF91 -> 1.5961905 | AT11: ='Rooftop Calc'!AF98 -> 2.1090715 | AU11: ='Rooftop Calc'!AF105 -> 2.6219526 | AV11: ='Rooftop Calc'!AF112 -> 3.1330899 | AW11: ='Rooftop Calc'!AF119 -> 3.3256254 | AX11: ='Rooftop Calc'!AF126 -> 3.7957449 | AY11: ='Rooftop Calc'!AN77 -> 1.1029038 | AZ11: ='Rooftop Calc'!AN84 -> 1.883174 | BA11: ='Rooftop Calc'!AN91 -> 2.6657323 | BB11: ='Rooftop Calc'!AN98 -> 3.4460025 | BC11: ='Rooftop Calc'!AN105 -> 4.2285608 | BD11: ='Rooftop Calc'!AN112 -> 5.0088309 | BE11: ='Rooftop Calc'!AN119 -> 5.7913893 | BF11: ='Rooftop Calc'!AN126 -> 6.5716594
A12: R6 | B12: ESOLPVRES | C12: Solar PV Distributed Residential Generation | E12: SOLRES | F12: ELC | G12: 2010 | H12: 30 | I12: 31.536 | J12: =AM12/AL12 -> 0.34965035 | K12: 0.3 | L12: =AO12/I12 -> 0.00041200637 | M12: 6546.9995 | N12: 3903.1781 | O12: 3453.8021 | P12: 3004.4261 | Q12: 2839.3022 | R12: 2674.1784 | S12: 2596.418 | T12: 2558.6683 | U12: 2540.0679 | V12: 2530.8353 | W12: 10 | X12: 0 | Y12: 0.34054374 | Z12: 0.34054374 | AA12: 0 | AB12: 0.30737101 | AC12: 0.30737101 | AD12: 0.30737101 | AE12: 0 | AF12: 0.32128124 | AG12: 0.32128124 | AH12: 0.32128124 | AI12: 0 | AJ12: 0.15 | AL12: 2.86 | AM12: 1 | AO12: ='Rooftop Calc'!AG65 -> 0.012993033 | AP12: ='Rooftop Calc'!AG71 -> 0.17523498 | AQ12: ='Rooftop Calc'!AG77 -> 0.47194746 | AR12: ='Rooftop Calc'!AG84 -> 0.89934986 | AS12: ='Rooftop Calc'!AG91 -> 1.3267523 | AT12: ='Rooftop Calc'!AG98 -> 1.7541547 | AU12: ='Rooftop Calc'!AG105 -> 2.1815571 | AV12: ='Rooftop Calc'!AG112 -> 2.5959664 | AW12: ='Rooftop Calc'!AG119 -> 2.8481338 | AX12: ='Rooftop Calc'!AG126 -> 3.138694 | AY12: ='Rooftop Calc'!AO77 -> 0.60330901 | AZ12: ='Rooftop Calc'!AO84 -> 1.0301314 | BA12: ='Rooftop Calc'!AO91 -> 1.4582054 | BB12: ='Rooftop Calc'!AO98 -> 1.8850278 | BC12: ='Rooftop Calc'!AO105 -> 2.3131018 | BD12: ='Rooftop Calc'!AO112 -> 2.7399241 | BE12: ='Rooftop Calc'!AO119 -> 3.1679982 | BF12: ='Rooftop Calc'!AO126 -> 3.5948205
A13: * | AO13: =SUM(AO8:AO12) -> 0.026880973 | AP13: =SUM(AP8:AP12) -> 0.68766875 | AQ13: =SUM(AQ8:AQ12) -> 1.443419 | AR13: =SUM(AR8:AR12) -> 2.6452688 | AS13: =SUM(AS8:AS12) -> 3.8471186 | AT13: =SUM(AT8:AT12) -> 5.0489684 | AU13: =SUM(AU8:AU12) -> 6.2508183 | AV13: =SUM(AV8:AV12) -> 7.4257871 | ... BF13: =SUM(BF8:BF12) -> 14.107033
A14: *

Sheet TechData_DMD
A1: TechData | B1: _GLOBAL,R0,R1,R2,R3,R4,R5,R6 | L1: R2 | M1: R3 | N1: R4 | O1: R5 | P1: R6 | S1: R2 | T1: R3 | U1: R4 | V1: R5 | W1: R6 | X1: R2 | Y1: R3 | Z1: R4 | AA1: R5 | AB1: R6 | AC1: R2 | AD1: R3 | AE1: R4 | AF1: R5 | AG1: R6
A7: Region | B7: TechName | C7: *TechDesc | D7: *Units | E7: CommIN | F7: CommOUT | G7: NCAP_START | H7: NCAP_TLIFE | I7: NCAP_COST | J7: EFF | K7: Share~UP | L7: NCAP_AF~R2 | M7: NCAP_AF~R3 | N7: NCAP_AF~R4 | O7: NCAP_AF~R5 | P7: NCAP_AF~R6 | Q7: NCAP_FOM | R7: NCAP_DRATE | S7: PRC_RESID~R2~2010 | T7: PRC_RESID~R3~2010 | U7: PRC_RESID~R4~2010 | V7: PRC_RESID~R5~2010 | W7: PRC_RESID~R6~2010 | X7: PRC_RESID~R2~2015 | Y7: PRC_RESID~R3~2015 | Z7: PRC_RESID~R4~2015 | AA7: PRC_RESID~R5~2015 | AB7: PRC_RESID~R6~2015 | AC7: PRC_RESID~R2~2020 | AD7: PRC_RESID~R3~2020 | AE7: PRC_RESID~R4~2020 | AF7: PRC_RESID~R5~2020 | AG7: PRC_RESID~R6~2020 | AH7: NCAP_BND~2010 | AI7: NCAP_BND~2015 | AJ7: NCAP_BND~2020 | AK7: NCAP_BND~2025 | AL7: NCAP_BND~2030 | AM7: NCAP_BND~2035 | AN7: NCAP_BND~2040 | AO7: NCAP_BND~2045 | AP7: NCAP_BND~2050 | AQ7: NCAP_BND~2055 | AT7: *GROWTH~2015 | AU7: *GROWTH~2020 | AV7: *GROWTH~2025 | AW7: *GROWTH~2030 | AX7: *GROWTH~2035 | AY7: *GROWTH~2040 | AZ7: *GROWTH~2045 | BA7: *GROWTH~2050 | BB7: *GROWTH~2055
A8: *Space Heating
A9: *Electric Radiant Heating
A10: * | B10: RSHERDBS05 | C10: Electric Radiant Base.RSH.ELC.05 | D10: PJ | E10: RESELC | F10: =Commodities!$D$11 -> RSH | G10: 2010 | H10: 20 | J10: 1 | K10: 1 | L10: 0.16 | M10: 0.16 | N10: 0.16 | O10: 0.16 | P10: 0.16 | R10: 0.18 | AH10: 0 | AI10: 0 | AJ10: 0 | AK10: 0 | AL10: 0 | AM10: 0 | AN10: 0 | AO10: 0 | AP10: 0 | AQ10: 0
A11: R2,R3,R4,R5,R6 | B11: RSHERDV110 | C11: Electric Radiant Ver1.RSH.ELC.10 | D11: PJ | E11: RESELC | F11: =Commodities!$D$11 -> RSH | G11: 2010 | H11: 20 | I11: 3.7369871 | J11: 1 | K11: 1 | L11: 0.16 | M11: 0.16 | N11: 0.16 | O11: 0.16 | P11: 0.16 | R11: 0.18 | S11: =Resid!V7 -> 4.748916 | T11: =Resid!W7 -> 2.7595598 | U11: =Resid!X7 -> 4.555966 | V11: =Resid!Y7 -> 0.89318094 | W11: =Resid!Z7 -> 2.386034 | X11: =S11*15/20 -> 3.561687 | Y11: =T11*15/20 -> 2.0696698 | Z11: =U11*15/20 -> 3.4169745 | AA11: =V11*15/20 -> 0.66988571 | AB11: =W11*15/20 -> 1.7895255 | AH11: 0 | AI11: 0 | AJ11: =SUM(X11:AB11)*1.12 -> 12.888672 | AK11: =AJ11*1.12 -> 14.435312 | AL11: =AK11*1.12 -> 16.16755 | AM11: =AL11*1.12 -> 18.107656 | AN11: =AM11*1.12 -> 20.280574 | AO11: =AN11*1.12 -> 22.714243 | AP11: =AO11*1.12 -> 25.439952 | AQ11: =AP11*1.12 -> 28.492747 | AU11: 1.1 | AV11: =AU11 -> 1.1 | AW11: =AV11 -> 1.1 | AX11: =AW11 -> 1.1 | AY11: =AX11 -> 1.1 | AZ11: =AY11 -> 1.1 | BA11: =AZ11 -> 1.1 | BB11: =BA11 -> 1.1
A12: *Electric Resistance Furnaces
A13: * | B13: RSHEFRV120 | C13: Electric Resistance Furnace Ver1.RSH.ELC.20 | D13: PJ | E13: RESELC | F13: =Commodities!$D$11 -> RSH | G13: 2020 | H13: 15 | I13: 2.775407 | J13: 0.98 | K13: 1 | L13: 0.16 | M13: 0.16 | N13: 0.16 | O13: 0.16 | P13: 0.16 | R13: 0.18
A14: * | B14: RSHEFRV130 | C14: Electric Resistance Furnace Ver1.RSH.ELC.30 | D14: PJ | E14: RESELC | F14: =Commodities!$D$11 -> RSH | G14: 2030 | H14: 15 | I14: 2.775407 | J14: 0.98 | K14: 1 | L14: 0.16 | M14: 0.16 | N14: 0.16 | O14: 0.16 | P14: 0.16 | R14: 0.18
A15: * | B15: RSHEFRV230 | C15: Electric Resistance Furnace Ver2.RSH.ELC.30 | D15: PJ | E15: RESELC | F15: =Commodities!$D$11 -> RSH | G15: 2030 | H15: 30 | I15: 3.2831034 | J15: 0.98 | K15: 1 | L15: 0.16 | M15: 0.16 | N15: 0.16 | O15: 0.16 | P15: 0.16 | R15: 0.18
A16: * | B16: RSHEFRV140 | C16: Electric Resistance Furnace Ver1.RSH.ELC.40 | D16: PJ | E16: RESELC | F16: =Commodities!$D$11 -> RSH | G16: 2040 | H16: 15 | I16: 2.775407 | J16: 0.98 | K16: 1 | L16: 0.16 | M16: 0.16 | N16: 0.16 | O16: 0.16 | P16: 0.16 | R16: 0.18
A17: * | B17: RSHEFRV240 | C17: Electric Resistance Furnace Ver2.RSH.ELC.40 | D17: PJ | E17: RESELC | F17: =Commodities!$D$11 -> RSH | G17: 2040 | H17: 30 | I17: 3.2831034 | J17: 0.98 | K17: 1 | L17: 0.16 | M17: 0.16 | N17: 0.16 | O17: 0.16 | P17: 0.16 | R17: 0.18
A18: * | B18: RSHEFRV250 | C18: Electric Resistance Furnace Ver2.RSH.ELC.50 | D18: PJ | E18: RESELC | F18: =Commodities!$D$11 -> RSH | G18: 2050 | H18: 30 | I18: 3.2831034 | J18: 0.98 | K18: 1 | L18: 0.16 | M18: 0.16 | N18: 0.16 | O18: 0.16 | P18: 0.16 | R18: 0.18
A19: * | B19: RSHEFRV220 | C19: Electric Resistance Furnace Ver2.RSH.ELC.20 | D19: PJ | E19: RESELC | F19: =Commodities!$D$11 -> RSH | G19: 2020 | H19: 30 | I19: 2.2343255 | J19: 0.98 | K19: 1 | L19: 0.16 | M19: 0.16 | N19: 0.16 | O19: 0.16 | P19: 0.16 | R19: 0.18
A20: * | B20: RSHEFRV130 | C20: Electric Resistance Furnace Ver1.RSH.ELC.30 | D20: PJ | E20: RESELC | F20: =Commodities!$D$11 -> RSH | G20: 2030 | H20: 15 | I20: 1.8619379 | J20: 0.98 | K20: 1 | L20: 0.16 | M20: 0.16 | N20: 0.16 | O20: 0.16 | P20: 0.16 | R20: 0.18
A21: * | B21: RSHEFRV230 | C21: Electric Resistance Furnace Ver2.RSH.ELC.30 | D21: PJ | E21: RESELC | F21: =Commodities!$D$11 -> RSH | G21: 2030 | H21: 30 | I21: 2.2343255 | J21: 0.98 | K21: 1 | L21: 0.16 | M21: 0.16 | N21: 0.16 | O21: 0.16 | P21: 0.16 | R21: 0.18
A22: * | B22: RSHEFRV140 | C22: Electric Resistance Furnace Ver1.RSH.ELC.40 | D22: PJ | E22: RESELC | F22: =Commodities!$D$11 -> RSH | G22: 2040 | H22: 15 | I22: 1.8619379 | J22: 0.98 | K22: 1 | L22: 0.16 | M22: 0.16 | N22: 0.16 | O22: 0.16 | P22: 0.16 | R22: 0.18
A23: * | B23: RSHEFRV240 | C23: Electric Resistance Furnace Ver2.RSH.ELC.40 | D23: PJ | E23: RESELC | F23: =Commodities!$D$11 -> RSH | G23: 2040 | H23: 30 | I23: 2.2343255 | J23: 0.98 | K23: 1 | L23: 0.16 | M23: 0.16 | N23: 0.16 | O23: 0.16 | P23: 0.16 | R23: 0.18
A24: * | B24: RSHEFRV150 | C24: Electric Resistance Furnace Ver1.RSH.ELC.50 | D24: PJ | E24: RESELC | F24: =Commodities!$D$11 -> RSH | G24: 2050 | H24: 15 | I24: 1.8619379 | J24: 0.98 | K24: 1 | L24: 0.16 | M24: 0.16 | N24: 0.16 | O24: 0.16 | P24: 0.16 | R24: 0.18
A25: * | B25: RSHEFRV250 | C25: Electric Resistance Furnace Ver2.RSH.ELC.50 | D25: PJ | E25: RESELC | F25: =Commodities!$D$11 -> RSH | G25: 2050 | H25: 30 | I25: 2.2343255 | J25: 0.98 | K25: 1 | L25: 0.16 | M25: 0.16 | N25: 0.16 | O25: 0.16 | P25: 0.16 | R25: 0.18
A26: *Electric Heat Pumps
A27: * | B27: RSHEHPBS05 | C27: Electric Heat Pump Base.RSH.ELC.05 | D27: PJ | E27: RESELC | F27: =Commodities!$D$11 -> RSH | G27: 2010 | H27: 15 | I27: 4.0729892 | J27: 2.2657 | K27: 1 | L27: 0.16 | M27: 0.16 | N27: 0.16 | O27: 0.16 | P27: 0.16 | R27: 0.18 | AJ27: 0 | AK27: 0 | AL27: 0 | AM27: 0 | AN27: 0 | AO27: 0 | AP27: 0 | AQ27: 0
A28: R2,R3,R4,R5,R6 | B28: RSHEHPV110 | C28: Electric Heat Pump Ver1.RSH.ELC.10 | D28: PJ | E28: RESELC | F28: =Commodities!$D$11 -> RSH | G28: 2010 | H28: 15 | I28: 4.0729892 | J28: 2.26 | K28: 1 | L28: 0.16 | M28: 0.16 | N28: 0.16 | O28: 0.16 | P28: 0.16 | R28: 0.18 | S28: =Resid!V10 -> 2.4354858 | T28: =Resid!W10 -> 1.4152427 | U28: =Resid!X10 -> 2.3365312 | V28: =Resid!Y10 -> 0.45806863 | W28: =Resid!Z10 -> 1.2236797 | AH28: 0 | AI28: 0 | AJ28: 0 | AK28: 0 | AL28: 0 | AM28: 0 | AN28: 0 | AO28: 0 | AP28: 0 | AQ28: 0
A29: * | B29: RSHEHPV115 | C29: Electric Heat Pump Ver1.RSH.ELC.15 | D29: PJ | E29: RESELC | F29: =Commodities!$D$11 -> RSH | G29: 2015 | H29: 15 | I29: 4.0729892 | J29: 2.26 | K29: 1 | L29: 0.16 | M29: 0.16 | N29: 0.16 | O29: 0.16 | P29: 0.16 | R29: 0.18 | AH29: 0
A30: * | B30: RSHEHPV215 | C30: Electric Heat Pump Ver2.RSH.ELC.15 | D30: PJ | E30: RESELC | F30: =Commodities!$D$11 -> RSH | G30: 2015 | H30: 15 | I30: 6.1935761 | J30: 2.7442857 | K30: 1 | L30: 0.16 | M30: 0.16 | N30: 0.16 | O30: 0.16 | P30: 0.16 | R30: 0.18
A31: * | B31: RSHEHPV320 | C31: Electric Heat Pump Ver3.RSH.ELC.20 | D31: PJ | E31: RESELC | F31: =Commodities!$D$11 -> RSH | G31: 2020 | H31: 9 | I31: 6.3763853 | J31: 2.7765714 | K31: 1 | L31: 0.16 | M31: 0.16 | N31: 0.16 | O31: 0.16 | P31: 0.16 | R31: 0.18
A32: * | B32: RSHEHPV520 | C32: Electric Heat Pump Ver5.RSH.ELC.20 | D32: PJ | E32: RESELC | F32: =Commodities!$D$11 -> RSH | G32: 2020 | H32: 9 | I32: 7.8022972 | J32: 2.9057143 | K32: 1 | L32: 0.16 | M32: 0.16 | N32: 0.16 | O32: 0.16 | P32: 0.16 | R32: 0.18
A33: * | B33: RSHEHPV430 | C33: Electric Heat Pump Ver4.RSH.ELC.30 | D33: PJ | E33: RESELC | F33: =Commodities!$D$11 -> RSH | G33: 2030 | H33: 22 | I33: 6.5628507 | J33: 2.8411429 | K33: 1 | L33: 0.16 | M33: 0.16 | N33: 0.16 | O33: 0.16 | P33: 0.16 | R33: 0.18
A34: * | B34: RSHEHPV630 | C34: Electric Heat Pump Ver6.RSH.ELC.30 | D34: PJ | E34: RESELC | F34: =Commodities!$D$11 -> RSH | G34: 2030 | H34: 22 | I34: 7.879077 | J34: 2.9057143 | K34: 1 | L34: 0.16 | M34: 0.16 | N34: 0.16 | O34: 0.16 | P34: 0.16 | R34: 0.18
A35: * | B35: RSHEHPV440 | C35: Electric Heat Pump Ver4.RSH.ELC.40 | D35: PJ | E35: RESELC | F35: =Commodities!$D$11 -> RSH | G35: 2040 | H35: 22 | I35: 6.5628507 | J35: 2.8411429 | K35: 1 | L35: 0.16 | M35: 0.16 | N35: 0.16 | O35: 0.16 | P35: 0.16 | R35: 0.18
A36: * | B36: RSHEHPV640 | C36: Electric Heat Pump Ver6.RSH.ELC.40 | D36: PJ | E36: RESELC | F36: =Commodities!$D$11 -> RSH | G36: 2040 | H36: 22 | I36: 7.8022972 | J36: 2.9057143 | K36: 1 | L36: 0.16 | M36: 0.16 | N36: 0.16 | O36: 0.16 | P36: 0.16 | R36: 0.18
A37: * | B37: RSHEHPV210 | C37: Electric Heat Pump Ver2.RSH.ELC.10 | D37: PJ | E37: RESELC | F37: =Commodities!$D$11 -> RSH | G37: 2010 | H37: 15 | I37: 8.8097833 | J37: 2.4 | K37: 1 | L37: 0.16 | M37: 0.16 | N37: 0.16 | O37: 0.16 | P37: 0.16 | R37: 0.18 | AH37: 0 | AI37: 0 | AJ37: 0 | AK37: 0 | AL37: 0 | AM37: 0 | AN37: 0 | AO37: 0 | AP37: 0 | AQ37: 0
A38: * | B38: RSHEHPV215 | C38: Electric Heat Pump Ver2.RSH.ELC.15 | D38: PJ | E38: RESELC | F38: =Commodities!$D$11 -> RSH | G38: 2015 | H38: 15 | I38: 9.3561264 | J38: 2.58 | K38: 1 | L38: 0.16 | M38: 0.16 | N38: 0.16 | O38: 0.16 | P38: 0.16 | R38: 0.18 | AH38: 0
A39: * | B39: RSHEHPV310 | C39: Electric Heat Pump Ver3.RSH.ELC.10 | D39: PJ | E39: RESELC | F39: =Commodities!$D$11 -> RSH | G39: 2010 | H39: 15 | I39: 9.7658838 | J39: 2.49 | K39: 1 | L39: 0.16 | M39: 0.16 | N39: 0.16 | O39: 0.16 | P39: 0.16 | R39: 0.18 | AH39: 0 | AI39: 0 | AJ39: 0 | AK39: 0 | AL39: 0 | AM39: 0 | AN39: 0 | AO39: 0 | AP39: 0 | AQ39: 0
A40: * | B40: RSHEHPV315 | C40: Electric Heat Pump Ver3.RSH.ELC.15 | D40: PJ | E40: RESELC | F40: =Commodities!$D$11 -> RSH | G40: 2015 | H40: 15 | I40: 9.7658838 | J40: 2.49 | K40: 1 | L40: 0.16 | M40: 0.16 | N40: 0.16 | O40: 0.16 | P40: 0.16 | R40: 0.18 | AH40: 0 | AK40: 0 | AL40: 0 | AM40: 0 | AN40: 0 | AO40: 0 | AP40: 0 | AQ40: 0
A41: * | B41: RSHEHPV320 | C41: Electric Heat Pump Ver3.RSH.ELC.20 | D41: PJ | E41: RESELC | F41: =Commodities!$D$11 -> RSH | G41: 2020 | H41: 15 | I41: 10.243934 | J41: 2.78 | K41: 1 | L41: 0.16 | M41: 0.16 | N41: 0.16 | O41: 0.16 | P41: 0.16 | R41: 0.18 | AH41: 0 | AL41: 0 | AM41: 0 | AN41: 0 | AO41: 0 | AP41: 0 | AQ41: 0
A42: * | B42: RSHEHPV330 | C42: Electric Heat Pump Ver3.RSH.ELC.30 | D42: PJ | E42: RESELC | F42: =Commodities!$D$11 -> RSH | G42: 2030 | H42: 15 | I42: 10.243934 | J42: 2.8 | K42: 1 | L42: 0.16 | M42: 0.16 | N42: 0.16 | O42: 0.16 | P42: 0.16 | R42: 0.18 | AH42: 0
A43: * | B43: RSHEHPV410 | C43: Electric Heat Pump Ver4.RSH.ELC.10 | D43: PJ | E43: RESELC | F43: =Commodities!$D$11 -> RSH | G43: 2010 | H43: 15 | I43: 10.926863 | J43: 3.14 | K43: 1 | L43: 0.16 | M43: 0.16 | N43: 0.16 | O43: 0.16 | P43: 0.16 | R43: 0.18 | AH43: 0 | AJ43: 0 | AK43: 0 | AL43: 0 | AM43: 0 | AN43: 0 | AO43: 0 | AP43: 0 | AQ43: 0
A44: * | B44: RSHEHPV420 | C44: Electric Heat Pump Ver4.RSH.ELC.20 | D44: PJ | E44: RESELC | F44: =Commodities!$D$11 -> RSH | G44: 2020 | H44: 15 | I44: 11.200035 | J44: 3.17 | K44: 1 | L44: 0.16 | M44: 0.16 | N44: 0.16 | O44: 0.16 | P44: 0.16 | R44: 0.18 | AH44: 0 | AL44: 0 | AM44: 0 | AN44: 0 | AO44: 0 | AP44: 0 | AQ44: 0
A45: * | B45: RSHEHPV430 | C45: Electric Heat Pump Ver4.RSH.ELC.30 | D45: PJ | E45: RESELC | F45: =Commodities!$D$11 -> RSH | G45: 2030 | H45: 15 | I45: 11.268327 | J45: 3.22 | K45: 1 | L45: 0.16 | M45: 0.16 | N45: 0.16 | O45: 0.16 | P45: 0.16 | R45: 0.18 | AH45: 0 | AM45: 0 | AN45: 0 | AO45: 0 | AP45: 0 | AQ45: 0
...

Sheet Not used>>

Sheet Commodities
B1: Commodities | D1: _GLOBAL,R0,R1,R2,R3,R4,R5,R6
B7: Region | C7: Csets | D7: CommName | E7: CommDesc | F7: Unit | G7: LimType | H7: CTSLvl | I7: PeakTS | J7: Ctype
B8: *Demands
B9: R2,R3,R4,R5,R6 | C9: DEM | D9: RSC | E9: Residential Cooling | F9: PJ
B10: * | C10: DEM | D10: RFZ | E10: Residential Freezing | F10: PJ
B11: R2,R3,R4,R5,R6 | C11: DEM | D11: RSH | E11: Residential Heating | F11: PJ
B12: R2,R3,R4,R5,R6 | C12: DEM | D12: RLT | E12: Residential Lighting | F12: bn-lum-yr
B13: R2,R3,R4,R5,R6 | C13: DEM | D13: ROE | E13: Residential Other Appliances - ELC | F13: PJ
B14: R2,R3,R4,R5,R6 | C14: DEM | D14: ROG | E14: Residential Other Appliances - NGA | F14: PJ
B15: * | C15: DEM | D15: ROL | E15: Residential Other Appliances - LPG | F15: PJ
B16: * | C16: DEM | D16: RRF | E16: Residential Refrigeration | F16: PJ
B17: R2,R3,R4,R5,R6 | C17: DEM | D17: RWH | E17: Residential Water Heating | F17: PJ
B18: *Energy Carriers
B19: R2,R3,R4,R5,R6 | C19: NRG | D19: RESELC | E19: Electricity to Residential Sector | F19: PJ
B20: R2,R3,R4,R5,R6 | C20: NRG | D20: RESNGAEA | E20: Natural Gas to Residential Sector | F20: PJ
B21: R2,R3,R4,R5,R6 | C21: NRG | D21: RESDSLEA | E21: Diesel to Residential Sector | F21: PJ
B22: *R2,R3,R4,R5,R6 | C22: NRG | D22: RESKEREA | E22: Kerosene to Residential Sector | F22: PJ
B23: *R2,R3,R4,R5,R6 | C23: NRG | D23: RESLPGEA | E23: LPG to Residential Sector | F23: PJ
B24: *R2,R3,R4,R5,R6 | C24: NRG | D24: RESBIOEA | E24: Biomass-wood to Residential Sector after emissions | F24: PJ
B25: *Residential End Use Water Commodities for Demand Pass Through Technologies
B26: R2,R3,R4,R5,R6 | C26: MAT | D26: RBLDLEDMY | E26: Dummy water commodity for low eff buildings | F26: Mt
B27: *R2,R3,R4,R5,R6 | C27: MAT | D27: RBLDMEDMY | E27: Dummy water commodity for medium eff buildings | F27: Mt
B28: R2,R3,R4,R5,R6 | C28: MAT | D28: RBLDHEDMY | E28: Dummy water commodity for high eff buildings | F28: Mt
B29: R2,R3,R4,R5,R6 | C29: MAT | D29: RBROOFDMY | E29: Dummy water commodity for black roofs | F29: Mt
B30: R2,R3,R4,R5,R6 | C30: MAT | D30: RWTROOFDMY | E30: Dummy water commodity for white roofs | F30: Mt
B31: R2,R3,R4,R5,R6 | C31: MAT | D31: RGRF6DMY | E31: Dummy water commodity for green roofs | F31: Mt
B32: R2,R3,R4,R5,R6 | C32: MAT | D32: RGRF12DMY | E32: Dummy water commodity for green roofs | F32: Mt
B33: *Roof/GI Heating & Cooling Commodities
B34: *R2,R3,R4,R5,R6 | C34: NRG | D34: RHCRFBLK | E34: Heating/cooling from black roofs | F34: PJ
B35: *R2,R3,R4,R5,R6 | C35: NRG | D35: RHCRFWT | E35: Heating/cooling from white roofs | F35: PJ
B36: *R2,R3,R4,R5,R6 | C36: NRG | D36: RHCRFG6 | E36: Heating/cooling from 6 inch green roof | F36: PJ
B37: *R2,R3,R4,R5,R6 | C37: NRG | D37: RHCRFG12 | E37: Heating/cooling from 12 inch green roof | F37: PJ
B38: *Demand Commodities for NYC Population
B39: *
B40: R2,R3,R4,R5,R6 | C40: DEM | D40: POPDMRES | E40: Water Energy Demand per Capita | F40: Mt
B41: *R2,R3,R4,R5,R6 | C41: DEM | D41: POPBKRES | E41: Population Brooklyn | F41: Mt
B42: *R2,R3,R4,R5,R6 | C42: DEM | D42: POPBXRES | E42: Population Bronx | F42: Mt
B43: *R2,R3,R4,R5,R6 | C43: DEM | D43: POPMHRES | E43: Population Manhattan | F43: Mt
B44: *R2,R3,R4,R5,R6 | C44: DEM | D44: POPSIRES | E44: Population Staten Island | F44: Mt
B45: *R2,R3,R4,R5,R6 | C45: DEM | D45: POPQNRES | E45: Population Queens | F45: Mt
...

Sheet Technologies
B1: Technologies | D1: _GLOBAL,R0,R1,R2,R3,R4,R5,R6
B7: Region | C7: Sets | D7: TechName | E7: TechDesc | F7: Tact | G7: Tcap | H7: PrimaryCG | I7: Vintage
B8: *Space Heating
B9: *Electric Radiant
B10: =TechData_DMD!A10 -> * | C10: DMD | D10: =TechData_DMD!B10 -> RSHERDBS05 | E10: =TechData_DMD!C10 -> Electric Radiant Base.RSH.ELC.05 | F10: PJ | G10: PJ/a
B11: =TechData_DMD!A11 -> R2,R3,R4,R5,R6 | C11: DMD | D11: =TechData_DMD!B11 -> RSHERDV110 | E11: =TechData_DMD!C11 -> Electric Radiant Ver1.RSH.ELC.10 | F11: PJ | G11: PJ/a
B12: *Electric Resistance Furnaces
B13: =TechData_DMD!A13 -> * | C13: DMD | D13: =TechData_DMD!B13 -> RSHEFRV120 | E13: =TechData_DMD!C13 -> Electric Resistance Furnace Ver1.RSH.ELC.20 | F13: PJ | G13: PJ/a
B14: =TechData_DMD!A14 -> * | C14: DMD | D14: =TechData_DMD!B14 -> RSHEFRV130 | E14: =TechData_DMD!C14 -> Electric Resistance Furnace Ver1.RSH.ELC.30 | F14: PJ | G14: PJ/a
B15: =TechData_DMD!A15 -> * | C15: DMD | D15: =TechData_DMD!B15 -> RSHEFRV230 | E15: =TechData_DMD!C15 -> Electric Resistance Furnace Ver2.RSH.ELC.30 | F15: PJ | G15: PJ/a
B16: =TechData_DMD!A16 -> * | C16: DMD | D16: =TechData_DMD!B16 -> RSHEFRV140 | E16: =TechData_DMD!C16 -> Electric Resistance Furnace Ver1.RSH.ELC.40 | F16: PJ | G16: PJ/a
B17: =TechData_DMD!A17 -> * | C17: DMD | D17: =TechData_DMD!B17 -> RSHEFRV240 | E17: =TechData_DMD!C17 -> Electric Resistance Furnace Ver2.RSH.ELC.40 | F17: PJ | G17: PJ/a
B18: =TechData_DMD!A18 -> * | C18: DMD | D18: =TechData_DMD!B18 -> RSHEFRV250 | E18: =TechData_DMD!C18 -> Electric Resistance Furnace Ver2.RSH.ELC.50 | F18: PJ | G18: PJ/a
B19: =TechData_DMD!A19 -> * | C19: DMD | D19: =TechData_DMD!B19 -> RSHEFRV220 | E19: =TechData_DMD!C19 -> Electric Resistance Furnace Ver2.RSH.ELC.20 | F19: PJ | G19: PJ/a
B20: =TechData_DMD!A20 -> * | C20: DMD | D20: =TechData_DMD!B20 -> RSHEFRV130 | E20: =TechData_DMD!C20 -> Electric Resistance Furnace Ver1.RSH.ELC.30 | F20: PJ | G20: PJ/a
B21: =TechData_DMD!A21 -> * | C21: DMD | D21: =TechData_DMD!B21 -> RSHEFRV230 | E21: =TechData_DMD!C21 -> Electric Resistance Furnace Ver2.RSH.ELC.30 | F21: PJ | G21: PJ/a
B22: =TechData_DMD!A22 -> * | C22: DMD | D22: =TechData_DMD!B22 -> RSHEFRV140 | E22: =TechData_DMD!C22 -> Electric Resistance Furnace Ver1.RSH.ELC.40 | F22: PJ | G22: PJ/a
B23: =TechData_DMD!A23 -> * | C23: DMD | D23: =TechData_DMD!B23 -> RSHEFRV240 | E23: =TechData_DMD!C23 -> Electric Resistance Furnace Ver2.RSH.ELC.40 | F23: PJ | G23: PJ/a
B24: =TechData_DMD!A24 -> * | C24: DMD | D24: =TechData_DMD!B24 -> RSHEFRV150 | E24: =TechData_DMD!C24 -> Electric Resistance Furnace Ver1.RSH.ELC.50 | F24: PJ | G24: PJ/a
B25: =TechData_DMD!A25 -> * | C25: DMD | D25: =TechData_DMD!B25 -> RSHEFRV250 | E25: =TechData_DMD!C25 -> Electric Resistance Furnace Ver2.RSH.ELC.50 | F25: PJ | G25: PJ/a
B26: *Electric Heat Pump
B27: =TechData_DMD!A27 -> * | C27: DMD | D27: =TechData_DMD!B27 -> RSHEHPBS05 | E27: =TechData_DMD!C27 -> Electric Heat Pump Base.RSH.ELC.05 | F27: PJ | G27: PJ/a
B28: =TechData_DMD!A28 -> R2,R3,R4,R5,R6 | C28: DMD | D28: =TechData_DMD!B28 -> RSHEHPV110 | E28: =TechData_DMD!C28 -> Electric Heat Pump Ver1.RSH.ELC.10 | F28: PJ | G28: PJ/a
B29: =TechData_DMD!A29 -> * | C29: DMD | D29: =TechData_DMD!B29 -> RSHEHPV115 | E29: =TechData_DMD!C29 -> Electric Heat Pump Ver1.RSH.ELC.15 | F29: PJ | G29: PJ/a
B30: =TechData_DMD!A30 -> * | C30: DMD | D30: =TechData_DMD!B30 -> RSHEHPV215 | E30: =TechData_DMD!C30 -> Electric Heat Pump Ver2.RSH.ELC.15 | F30: PJ | G30: PJ/a
B31: =TechData_DMD!A31 -> * | C31: DMD | D31: =TechData_DMD!B31 -> RSHEHPV320 | E31: =TechData_DMD!C31 -> Electric Heat Pump Ver3.RSH.ELC.20 | F31: PJ | G31: PJ/a
B32: =TechData_DMD!A32 -> * | C32: DMD | D32: =TechData_DMD!B32 -> RSHEHPV520 | E32: =TechData_DMD!C32 -> Electric Heat Pump Ver5.RSH.ELC.20 | F32: PJ | G32: PJ/a
B33: =TechData_DMD!A33 -> * | C33: DMD | D33: =TechData_DMD!B33 -> RSHEHPV430 | E33: =TechData_DMD!C33 -> Electric Heat Pump Ver4.RSH.ELC.30 | F33: PJ | G33: PJ/a
B34: =TechData_DMD!A34 -> * | C34: DMD | D34: =TechData_DMD!B34 -> RSHEHPV630 | E34: =TechData_DMD!C34 -> Electric Heat Pump Ver6.RSH.ELC.30 | F34: PJ | G34: PJ/a
B35: =TechData_DMD!A35 -> * | C35: DMD | D35: =TechData_DMD!B35 -> RSHEHPV440 | E35: =TechData_DMD!C35 -> Electric Heat Pump Ver4.RSH.ELC.40 | F35: PJ | G35: PJ/a
B36: =TechData_DMD!A36 -> * | C36: DMD | D36: =TechData_DMD!B36 -> RSHEHPV640 | E36: =TechData_DMD!C36 -> Electric Heat Pump Ver6.RSH.ELC.40 | F36: PJ | G36: PJ/a
B37: =TechData_DMD!A37 -> * | C37: DMD | D37: =TechData_DMD!B37 -> RSHEHPV210 | E37: =TechData_DMD!C37 -> Electric Heat Pump Ver2.RSH.ELC.10 | F37: PJ | G37: PJ/a
B38: =TechData_DMD!A38 -> * | C38: DMD | D38: =TechData_DMD!B38 -> RSHEHPV215 | E38: =TechData_DMD!C38 -> Electric Heat Pump Ver2.RSH.ELC.15 | F38: PJ | G38: PJ/a
... B46: =TechData_DMD!A46 -> * | C46: DMD | D46: =TechData_DMD!B46 -> RSHEHPV435 | E46: =TechData_DMD!C46 -> Electric Heat Pump Ver4.RSH.ELC.35 | F46: PJ | G46: PJ/a
B47: *Natural Gas Furnace
B48: =TechData_DMD!A48 -> * | C48: DMD | D48: =TechData_DMD!B48 -> RSHNFRBS05 | E48: =TechData_DMD!C48 -> Natural Gas Furnace Base.RSH.NGA.05 | F48: PJ | G48: PJ/a
B49: =TechData_DMD!A49 -> R2,R3,R4,R5,R6 | C49: DMD | D49: =TechData_DMD!B49 -> RSHNFRV110 | E49: =TechData_DMD!C49 -> Natural Gas Furnace Ver1.RSH.NGA.10 | F49: PJ | G49: PJ/a
B50: =TechData_DMD!A50 -> * | C50: DMD | D50: =TechData_DMD!B50 -> RSHNFRV115 | E50: =TechData_DMD!C50 -> Natural Gas Furnace Ver1.RSH.NGA.15 | F50: PJ | G50: PJ/a
B51: =TechData_DMD!A51 -> * | C51: DMD | D51: =TechData_DMD!B51 -> RSHNFRV215 | E51: =TechData_DMD!C51 -> Natural Gas Furnace Ver2.RSH.NGA.15 | F51: PJ | G51: PJ/a
B52: =TechData_DMD!A52 -> * | C52: DMD | D52: =TechData_DMD!B52 -> RSHNFRV320 | E52: =TechData_DMD!C52 -> Natural Gas Furnace Ver3.RSH.NGA.20 | F52: PJ | G52: PJ/a
...

Sheet Retrofit
B2: Measure No. | C2: Name | D2: Energy Demand Reduction (% kBtu/sqft) | E2: Cost per Sqft | F2: % of Residential Area Eligible | G2: Cost Calculation | H2: Restriction Calculation
B3: 1 | C3: Insulation – walls | D3: 0.1 | E3: 65.19 | F3: 0.267 | G3: $41.75 per square foot wall area; wall area calculated as average perimeter area times height in eligible single-family homes | H3: Only single-family homes built before 2005
B4: 2 | C4: Ventilation overhaul | D4: 0.03 | E4: 1 | F4: 0.482 | G4: $1 per sqft | H4: Only homes built after 1945
B5: 3 | C5: Smart thermostats | D5: 0.08 | E5: 0.52 | F5: 0.948 | G5: $500 / apartment (average size 962 sqft) | H5: All homes except steam-heated
B6: 4 | C6: Insulation – roof | D6: 0.05 | E6: 1.5 | F6: 0.897 | G6: $13 / roof area (90% of footprint); foot print is 0.129 of total area | H6: Only homes built before 2005
B7: 5 | C7: Window replacement | D7: 0.08 | E7: 5 | F7: 0.897 | G7: Cost given | H7: Only homes built before 2005
C10: 2005 Building eff (Btu / sqft )
C11: Brooklyn | D11: Bronx | E11: Manhattan | F11: Queens | G11: Staten Island | H11: NYC | K11: 2005 | L11: 2010 | M11: 2015 | N11: 2020 | O11: 2025 | P11: 2030 | Q11: 2035 | R11: 2040 | S11: 2045 | T11: 2050 | U11: 2055
C12: 51602.374 | D12: 55661.045 | E12: 62470.873 | F12: 32617.14 | G12: 56174.924 | H12: 50587.643 | J12: % of new build | K12: 0 | L12: 0.028275072 | M12: 0.055803665 | N12: 0.080498063 | O12: 0.09788161 | P12: 0.11446455 | Q12: 0.13106521 | R12: 0.14813324 | S12: 0.16193016 | T12: 0.1770404 | U12: 0.1916742
C14: Cost per Btu (M $ 2010 / PJa)
C15: Brooklyn | D15: Bronx | E15: Manhattan | F15: Queens | G15: Staten Island | H15: NYC | J15: Max penetration (% Btu) | K15: 2005 | L15: 2010 | M15: 2015 | N15: 2020 | O15: 2025 | P15: 2030 | Q15: 2035 | R15: 2040 | S15: 2045 | T15: 2050 | U15: 2055
B16: Smart thermostats | C16: =$E5/C$12/$U$28/$C$31*10^-6 -> 7.0017166 | D16: =$E5/D$12/$U$28/$C$31*10^-6 -> 6.4911681 | E16: =$E5/E$12/$U$28/$C$31*10^-6 -> 5.7835785 | F16: =$E5/F$12/$U$28/$C$31*10^-6 -> 11.077158 | G16: =$E5/G$12/$U$28/$C$31*10^-6 -> 6.431788 | H16: =$E5/H$12/$U$28/$C$31*10^-6 -> 7.1421631 | J16: Smart thermostats | K16: =$D$5*$F$5*(1-K$12) -> 0.07584 | L16: =$D$5*$F$5*(1-L$12) -> 0.073695619 | M16: =$D$5*$F$5*(1-M$12) -> 0.07160785 | N16: =$D$5*$F$5*(1-N$12) -> 0.069735027 | O16: =$D$5*$F$5*(1-O$12) -> 0.068416659 | P16: =$D$5*$F$5*(1-P$12) -> 0.067159008 | Q16: =$D$5*$F$5*(1-Q$12) -> 0.065900015 | R16: =$D$5*$F$5*(1-R$12) -> 0.064605575 | ... U16: =$D$5*$F$5*(1-U$12) -> 0.061303428
B17: Ventilation overhaul | C17: =$E4/C$12/$U$28/$C$31*10^-6 -> 13.46484 | D17: =$E4/D$12/$U$28/$C$31*10^-6 -> 12.483016 | E17: =$E4/E$12/$U$28/$C$31*10^-6 -> 11.122266 | F17: =$E4/F$12/$U$28/$C$31*10^-6 -> 21.302226 | G17: =$E4/G$12/$U$28/$C$31*10^-6 -> 12.368823 | H17: =$E4/H$12/$U$28/$C$31*10^-6 -> 13.734929 | J17: Ventilation overhaul | K17: =$D$4*$F$4*(1-K$12) -> 0.01446 | L17: =$D$4*$F$4*(1-L$12) -> 0.014051142 | M17: =$D$4*$F$4*(1-M$12) -> 0.013653079 | N17: =$D$4*$F$4*(1-N$12) -> 0.013295998 | O17: =$D$4*$F$4*(1-O$12) -> 0.013044632 | P17: =$D$4*$F$4*(1-P$12) -> 0.012804843 | Q17: =$D$4*$F$4*(1-Q$12) -> 0.012564797 | R17: =$D$4*$F$4*(1-R$12) -> 0.012317993 | ... U17: =$D$4*$F$4*(1-U$12) -> 0.011688391
B18: Insulation – roof | C18: =$E6/C$12/$U$28/$C$31*10^-6 -> 20.197259 | D18: =$E6/D$12/$U$28/$C$31*10^-6 -> 18.724523 | E18: =$E6/E$12/$U$28/$C$31*10^-6 -> 16.6834 | F18: =$E6/F$12/$U$28/$C$31*10^-6 -> 31.953339 | G18: =$E6/G$12/$U$28/$C$31*10^-6 -> 18.553234 | H18: =$E6/H$12/$U$28/$C$31*10^-6 -> 20.602393 | J18: Insulation – roof | K18: =$D$3*$F$3*(1-K$12) -> 0.0267 | L18: =$D$3*$F$3*(1-L$12) -> 0.025945056 | M18: =$D$3*$F$3*(1-M$12) -> 0.025210042 | N18: =$D$3*$F$3*(1-N$12) -> 0.024550702 | O18: =$D$3*$F$3*(1-O$12) -> 0.024086561 | P18: =$D$3*$F$3*(1-P$12) -> 0.023643796 | Q18: =$D$3*$F$3*(1-Q$12) -> 0.023200559 | R18: =$D$3*$F$3*(1-R$12) -> 0.022744842 | ... U18: =$D$3*$F$3*(1-U$12) -> 0.021582299
B19: Window replacement | C19: =$E7/C$12/$U$28/$C$31*10^-6 -> 67.324198 | D19: =$E7/D$12/$U$28/$C$31*10^-6 -> 62.415078 | E19: =$E7/E$12/$U$28/$C$31*10^-6 -> 55.611332 | F19: =$E7/F$12/$U$28/$C$31*10^-6 -> 106.51113 | G19: =$E7/G$12/$U$28/$C$31*10^-6 -> 61.844115 | H19: =$E7/H$12/$U$28/$C$31*10^-6 -> 68.674645 | J19: Window replacement | K19: =$D$7*$F$7*(1-K$12) -> 0.07176 | L19: =$D$7*$F$7*(1-L$12) -> 0.069730981 | M19: =$D$7*$F$7*(1-M$12) -> 0.067755529 | N19: =$D$7*$F$7*(1-N$12) -> 0.065983459 | O19: =$D$7*$F$7*(1-O$12) -> 0.064736016 | P19: =$D$7*$F$7*(1-P$12) -> 0.063546024 | Q19: =$D$7*$F$7*(1-Q$12) -> 0.062354761 | R19: =$D$7*$F$7*(1-R$12) -> 0.061129958 | ... U19: =$D$7*$F$7*(1-U$12) -> 0.058005459
B20: Insulation – walls | C20: =$E3/C$12/$U$28/$C$31*10^-6 -> 877.77289 | D20: =$E3/D$12/$U$28/$C$31*10^-6 -> 813.76779 | E20: =$E3/E$12/$U$28/$C$31*10^-6 -> 725.06054 | F20: =$E3/F$12/$U$28/$C$31*10^-6 -> 1388.6921 | G20: =$E3/G$12/$U$28/$C$31*10^-6 -> 806.32357 | H20: =$E3/H$12/$U$28/$C$31*10^-6 -> 895.38002 | J20: Insulation – walls | K20: =$D$6*$F$6*(1-K$12) -> 0.04485 | L20: =$D$6*$F$6*(1-L$12) -> 0.043581863 | M20: =$D$6*$F$6*(1-M$12) -> 0.042347206 | N20: =$D$6*$F$6*(1-N$12) -> 0.041239662 | O20: =$D$6*$F$6*(1-O$12) -> 0.04046001 | P20: =$D$6*$F$6*(1-P$12) -> 0.039716265 | Q20: =$D$6*$F$6*(1-Q$12) -> 0.038971725 | R20: =$D$6*$F$6*(1-R$12) -> 0.038206224 | ... U20: =$D$6*$F$6*(1-U$12) -> 0.036253412
B25: https://fred.stlouisfed.org/series/FPCPITOTLZGUSA
