Workbook
Name AnswerData: #REF!
Name AnswerData: #REF!
Name bprint: #REF!
Name btu_per_watthr: '[1]Conversion Factors'!$B$5
Name CMM_SUPPLY_CRV_TABLE: [2]cum2025curves!#REF!
Name cprint: #REF!
Name days_per_year: '[1]Conversion Factors'!$B$3
Name dollar____per__m: '[1]Conversion Factors'!$B$7
Name exch_rate: #REF!
Name exch_rate: #REF!
Name fitfile: [3]MODEL!$D$38
Name hours_per_day: '[1]Conversion Factors'!$B$2
Name INF: [3]MODEL!$H$14
Name j_per_btu: '[1]Conversion Factors'!$B$4
Name j_per_pj: '[1]Conversion Factors'!$B$6
Name lumens_per_billion_lumens: '[1]Conversion Factors'!$B$9
Name MAXREC: #REF!
Name million_short_tons_to_short_ton: [4]Steps!$Y$5
Name MMBTU_to_PJ: [4]Steps!$Y$6
Name PPP: [3]MODEL!$D$12
Name PPPEX: [3]MODEL!$D$13
Name rail_coal: #REF!
Name rail_coal: #REF!
Name region1: [5]Regions!$B$3:$C$61
Name TECHNAME: #REF!
Name TRNDTYPE: #REF!

Sheet ANSv6.1-Commodities
A1: ANSWER-Commodities
B7: CommName | C7: CommDesc | D7: CommUnit | E7: Set Memberships | F7: Comment

Sheet UC_NGAa
A2: Maximum capacity technology growth:
A3: ~UC_Sets: R_E: R1
A4: ~UC_Sets: T_SUC:
G5: ~UC_T
A6: UC_N | B6: Pset_PN | C6: Pset_CI | D6: Pset_CO | E6: UC_ATTR | F6: Year | G6: LimType | H6: UC_CAP~2010 | I6: UC_CAP~2015 | J6: UC_CAP~2020 | K6: UC_CAP~2025 | L6: UC_CAP~2030 | M6: UC_CAP~2035 | N6: UC_CAP~2040 | O6: UC_CAP~2045 | P6: UC_CAP~2050 | Q6: UC_CAP~2055 | R6: UC_CAP~RHS | S6: UC_RHSRTS | T6: UC_RHSRTS~0 | U6: UC_Desc
A7: UC_GrowthOfNGAR1UP1 | B7: =TechData_R0!B9 -> MINNGAD1 | E7: CAP, GROWTH | G7: UP | H7: =TechData_R0!G9 -> 1.25 | I7: =TechData_R0!H9 -> 1.1 | J7: =I7 -> 1.1 | K7: =TechData_R0!I9 -> 1.1 | L7: =K7 -> 1.1 | M7: =L7 -> 1.1 | N7: =M7 -> 1.1 | O7: =N7 -> 1.1 | P7: =O7 -> 1.1 | Q7: =P7 -> 1.1 | R7: =MAX(1,TechData_R0!F9) -> 1 | T7: 5
A8: UC_GrowthOfNGAR1UP2 | B8: =TechData_R0!B10 -> MINNGAD2 | E8: CAP, GROWTH | G8: UP | H8: =TechData_R0!G10 -> 1.25 | I8: =TechData_R0!H10 -> 1.1 | J8: =I8 -> 1.1 | K8: =TechData_R0!I10 -> 1.1 | L8: =K8 -> 1.1 | M8: =L8 -> 1.1 | N8: =M8 -> 1.1 | O8: =N8 -> 1.1 | P8: =O8 -> 1.1 | Q8: =P8 -> 1.1 | R8: =MAX(1,TechData_R0!F10) -> 1 | T8: 5
A9: UC_GrowthOfNGAR1UP3 | B9: =TechData_R0!B11 -> MINNGAD3 | E9: CAP, GROWTH | G9: UP | H9: =TechData_R0!G11 -> 1.25 | I9: =TechData_R0!H11 -> 1.1 | J9: =I9 -> 1.1 | K9: =TechData_R0!I11 -> 1.1 | L9: =K9 -> 1.1 | M9: =L9 -> 1.1 | N9: =M9 -> 1.1 | O9: =N9 -> 1.1 | P9: =O9 -> 1.1 | Q9: =P9 -> 1.1 | R9: =MAX(1,TechData_R0!F11) -> 1 | T9: 5
A10: UC_GrowthOfNGAR1UP4 | B10: =TechData_R0!B12 -> MINNGAD4 | E10: CAP, GROWTH | G10: UP | H10: =TechData_R0!G12 -> 1.25 | I10: =TechData_R0!H12 -> 1.1 | J10: =I10 -> 1.1 | K10: =TechData_R0!I12 -> 1.1 | L10: =K10 -> 1.1 | M10: =L10 -> 1.1 | N10: =M10 -> 1.1 | O10: =N10 -> 1.1 | P10: =O10 -> 1.1 | Q10: =P10 -> 1.1 | R10: =MAX(1,TechData_R0!F12) -> 1 | T10: 5
A11: UC_GrowthOfNGAR1UP5 | B11: =TechData_R0!B13 -> MINNGAD5 | E11: CAP, GROWTH | G11: UP | H11: =TechData_R0!G13 -> 1.25 | I11: =TechData_R0!H13 -> 1.1 | J11: =I11 -> 1.1 | K11: =TechData_R0!I13 -> 1.1 | L11: =K11 -> 1.1 | M11: =L11 -> 1.1 | N11: =M11 -> 1.1 | O11: =N11 -> 1.1 | P11: =O11 -> 1.1 | Q11: =P11 -> 1.1 | R11: =MAX(1,TechData_R0!F13) -> #REF! | T11: 5
A12: UC_GrowthOfNGAR1UP6 | B12: =TechData_R0!B14 -> MINNGAD6 | E12: CAP, GROWTH | G12: UP | H12: =TechData_R0!G14 -> 1.25 | I12: =TechData_R0!H14 -> 1.1 | J12: =I12 -> 1.1 | K12: =TechData_R0!I14 -> 1.1 | L12: =K12 -> 1.1 | M12: =L12 -> 1.1 | N12: =M12 -> 1.1 | O12: =N12 -> 1.1 | P12: =O12 -> 1.1 | Q12: =P12 -> 1.1 | R12: =MAX(1,TechData_R0!F14) -> #REF! | T12: 5
G14: ~UC_T
A15: UC_N | B15: Pset_PN | C15: Pset_CI | D15: Pset_CO | E15: UC_ATTR | F15: Year | G15: LimType | H15: UC_CAP~2010 | I15: UC_CAP~2015 | J15: UC_CAP~2020 | K15: UC_CAP~2025 | L15: UC_CAP~2030 | M15: UC_CAP~2035 | N15: UC_CAP~2040 | O15: UC_CAP~2045 | P15: UC_CAP~2050 | Q15: UC_CAP~2055 | R15: UC_CAP~RHS | S15: UC_RHSRTS | T15: UC_RHSRTS~0 | U15: UC_Desc
A16: UC_GrowthOfNGAR1LO1 | B16: =TechData_R0!B9 -> MINNGAD1 | E16: CAP, GROWTH | G16: LO | H16: =1-TechData_R0!J9+1 -> 0.9 | I16: =1-TechData_R0!K9+1 -> 0.99 | J16: =I16 -> 0.99 | K16: =J16 -> 0.99 | L16: =K16 -> 0.99 | M16: =L16 -> 0.99 | N16: =M16 -> 0.99 | O16: =N16 -> 0.99 | P16: =O16 -> 0.99 | Q16: =P16 -> 0.99 | R16: 1 | T16: 5
A17: UC_GrowthOfNGAR1LO2 | B17: =TechData_R0!B10 -> MINNGAD2 | E17: CAP, GROWTH | G17: LO | H17: =1-TechData_R0!J10+1 -> 0.9 | I17: =1-TechData_R0!K10+1 -> 0.99 | J17: =I17 -> 0.99 | K17: =J17 -> 0.99 | L17: =K17 -> 0.99 | M17: =L17 -> 0.99 | N17: =M17 -> 0.99 | O17: =N17 -> 0.99 | P17: =O17 -> 0.99 | Q17: =P17 -> 0.99 | R17: 1 | T17: 5
A18: UC_GrowthOfNGAR1LO3 | B18: =TechData_R0!B11 -> MINNGAD3 | E18: CAP, GROWTH | G18: LO | H18: =1-TechData_R0!J11+1 -> 0.9 | I18: =1-TechData_R0!K11+1 -> 0.99 | J18: =I18 -> 0.99 | K18: =J18 -> 0.99 | L18: =K18 -> 0.99 | M18: =L18 -> 0.99 | N18: =M18 -> 0.99 | O18: =N18 -> 0.99 | P18: =O18 -> 0.99 | Q18: =P18 -> 0.99 | R18: 1 | T18: 5
A19: UC_GrowthOfNGAR1LO4 | B19: =TechData_R0!B12 -> MINNGAD4 | E19: CAP, GROWTH | G19: LO | H19: =1-TechData_R0!J12+1 -> 0.9 | I19: =1-TechData_R0!K12+1 -> 0.99 | J19: =I19 -> 0.99 | K19: =J19 -> 0.99 | L19: =K19 -> 0.99 | M19: =L19 -> 0.99 | N19: =M19 -> 0.99 | O19: =N19 -> 0.99 | P19: =O19 -> 0.99 | Q19: =P19 -> 0.99 | R19: 1 | T19: 5
A20: UC_GrowthOfNGAR1LO5 | B20: =TechData_R0!B13 -> MINNGAD5 | E20: CAP, GROWTH | G20: LO | H20: =1-TechData_R0!J13+1 -> 0.9 | I20: =1-TechData_R0!K13+1 -> 0.99 | J20: =I20 -> 0.99 | K20: =J20 -> 0.99 | L20: =K20 -> 0.99 | M20: =L20 -> 0.99 | N20: =M20 -> 0.99 | O20: =N20 -> 0.99 | P20: =O20 -> 0.99 | Q20: =P20 -> 0.99 | R20: 1 | T20: 5
A21: UC_GrowthOfNGAR1LO6 | B21: =TechData_R0!B14 -> MINNGAD6 | E21: CAP, GROWTH | G21: LO | H21: =1-TechData_R0!J14+1 -> 0.9 | I21: =1-TechData_R0!K14+1 -> 0.99 | J21: =I21 -> 0.99 | K21: =J21 -> 0.99 | L21: =K21 -> 0.99 | M21: =L21 -> 0.99 | N21: =M21 -> 0.99 | O21: =N21 -> 0.99 | P21: =O21 -> 0.99 | Q21: =P21 -> 0.99 | R21: 1 | T21: 5
A24: Maximum capacity technology growth:
A25: ~UC_Sets: R_E: R2
A26: ~UC_Sets: T_SUC:
G27: ~UC_T
A28: UC_N | B28: Pset_PN | C28: Pset_CI | D28: Pset_CO | E28: UC_ATTR | F28: Year | G28: LimType | H28: UC_CAP~2010 | I28: UC_CAP~2015 | J28: UC_CAP~2020 | K28: UC_CAP~2025 | L28: UC_CAP~2030 | M28: UC_CAP~2035 | N28: UC_CAP~2040 | O28: UC_CAP~2045 | P28: UC_CAP~2050 | Q28: UC_CAP~2055 | R28: UC_CAP~RHS | S28: UC_RHSRTS | T28: UC_RHSRTS~0 | U28: UC_Desc
A29: UC_GrowthOfNGAR2UP1 | B29: =TechData_R0!B16 -> MINNGAD1 | E29: CAP, GROWTH | G29: UP | H29: =TechData_R0!G16 -> 1.25 | I29: =TechData_R0!H16 -> 1.1 | J29: =I29 -> 1.1 | K29: =TechData_R0!I16 -> 1.1 | L29: =K29 -> 1.1 | M29: =L29 -> 1.1 | N29: =M29 -> 1.1 | O29: =N29 -> 1.1 | P29: =O29 -> 1.1 | Q29: =P29 -> 1.1 | R29: =MAX(1,TechData_R0!F16) -> 1 | T29: 5
A30: UC_GrowthOfNGAR2UP2 | B30: =TechData_R0!B17 -> MINNGAD2 | E30: CAP, GROWTH | G30: UP | H30: =TechData_R0!G17 -> 1.25 | I30: =TechData_R0!H17 -> 1.1 | J30: =I30 -> 1.1 | K30: =TechData_R0!I17 -> 1.1 | L30: =K30 -> 1.1 | M30: =L30 -> 1.1 | N30: =M30 -> 1.1 | O30: =N30 -> 1.1 | P30: =O30 -> 1.1 | Q30: =P30 -> 1.1 | R30: =MAX(1,TechData_R0!F17) -> 1 | T30: 5
A31: UC_GrowthOfNGAR2UP3 | B31: =TechData_R0!B18 -> MINNGAD3 | E31: CAP, GROWTH | G31: UP | H31: =TechData_R0!G18 -> 1.25 | I31: =TechData_R0!H18 -> 1.1 | J31: =I31 -> 1.1 | K31: =TechData_R0!I18 -> 1.1 | L31: =K31 -> 1.1 | M31: =L31 -> 1.1 | N31: =M31 -> 1.1 | O31: =N31 -> 1.1 | P31: =O31 -> 1.1 | Q31: =P31 -> 1.1 | R31: =MAX(1,TechData_R0!F18) -> 1 | T31: 5
A32: UC_GrowthOfNGAR2UP4 | B32: =TechData_R0!B19 -> MINNGAD4 | E32: CAP, GROWTH | G32: UP | H32: =TechData_R0!G19 -> 1.25 | I32: =TechData_R0!H19 -> 1.1 | J32: =I32 -> 1.1 | K32: =TechData_R0!I19 -> 1.1 | L32: =K32 -> 1.1 | M32: =L32 -> 1.1 | N32: =M32 -> 1.1 | O32: =N32 -> 1.1 | P32: =O32 -> 1.1 | Q32: =P32 -> 1.1 | R32: =MAX(1,TechData_R0!F19) -> 1 | T32: 5
A33: UC_GrowthOfNGAR2UP5 | B33: =TechData_R0!B20 -> MINNGAD5 | E33: CAP, GROWTH | G33: UP | H33: =TechData_R0!G20 -> 1.25 | I33: =TechData_R0!H20 -> 1.1 | J33: =I33 -> 1.1 | K33: =TechData_R0!I20 -> 1.1 | L33: =K33 -> 1.1 | M33: =L33 -> 1.1 | N33: =M33 -> 1.1 | O33: =N33 -> 1.1 | P33: =O33 -> 1.1 | Q33: =P33 -> 1.1 | R33: =MAX(1,TechData_R0!F20) -> 1 | T33: 5
A34: UC_GrowthOfNGAR2UP6 | B34: =TechData_R0!B21 -> MINNGAD6 | E34: CAP, GROWTH | G34: UP | H34: =TechData_R0!G21 -> 1.25 | I34: =TechData_R0!H21 -> 1.1 | J34: =I34 -> 1.1 | K34: =TechData_R0!I21 -> 1.1 | L34: =K34 -> 1.1 | M34: =L34 -> 1.1 | N34: =M34 -> 1.1 | O34: =N34 -> 1.1 | P34: =O34 -> 1.1 | Q34: =P34 -> 1.1 | R34: =MAX(1,TechData_R0!F21) -> 1 | T34: 5
G36: ~UC_T
A37: UC_N | B37: Pset_PN | C37: Pset_CI | D37: Pset_CO | E37: UC_ATTR | F37: Year | G37: LimType | H37: UC_CAP~2010 | I37: UC_CAP~2015 | J37: UC_CAP~2020 | K37: UC_CAP~2025 | L37: UC_CAP~2030 | M37: UC_CAP~2035 | N37: UC_CAP~2040 | O37: UC_CAP~2045 | P37: UC_CAP~2050 | Q37: UC_CAP~2055 | R37: UC_CAP~RHS | S37: UC_RHSRTS | T37: UC_RHSRTS~0 | U37: UC_Desc
A38: UC_GrowthOfNGAR2LO1 | B38: =TechData_R0!B16 -> MINNGAD1 | E38: CAP, GROWTH | G38: LO | H38: =1-TechData_R0!J16+1 -> 0.9 | I38: =1-TechData_R0!K16+1 -> 0.99 | J38: =I38 -> 0.99 | K38: =J38 -> 0.99 | L38: =K38 -> 0.99 | M38: =L38 -> 0.99 | N38: =M38 -> 0.99 | O38: =N38 -> 0.99 | P38: =O38 -> 0.99 | Q38: =P38 -> 0.99 | R38: 1 | T38: 5
A39: UC_GrowthOfNGAR2LO2 | B39: =TechData_R0!B17 -> MINNGAD2 | E39: CAP, GROWTH | G39: LO | H39: =1-TechData_R0!J17+1 -> 0.9 | I39: =1-TechData_R0!K17+1 -> 0.99 | J39: =I39 -> 0.99 | K39: =J39 -> 0.99 | L39: =K39 -> 0.99 | M39: =L39 -> 0.99 | N39: =M39 -> 0.99 | O39: =N39 -> 0.99 | P39: =O39 -> 0.99 | Q39: =P39 -> 0.99 | R39: 1 | T39: 5
A40: UC_GrowthOfNGAR2LO3 | B40: =TechData_R0!B18 -> MINNGAD3 | E40: CAP, GROWTH | G40: LO | H40: =1-TechData_R0!J18+1 -> 0.9 | I40: =1-TechData_R0!K18+1 -> 0.99 | J40: =I40 -> 0.99 | K40: =J40 -> 0.99 | L40: =K40 -> 0.99 | M40: =L40 -> 0.99 | N40: =M40 -> 0.99 | O40: =N40 -> 0.99 | P40: =O40 -> 0.99 | Q40: =P40 -> 0.99 | R40: 1 | T40: 5
A41: UC_GrowthOfNGAR2LO4 | B41: =TechData_R0!B19 -> MINNGAD4 | E41: CAP, GROWTH | G41: LO | H41: =1-TechData_R0!J19+1 -> 0.9 | I41: =1-TechData_R0!K19+1 -> 0.99 | J41: =I41 -> 0.99 | K41: =J41 -> 0.99 | L41: =K41 -> 0.99 | M41: =L41 -> 0.99 | N41: =M41 -> 0.99 | O41: =N41 -> 0.99 | P41: =O41 -> 0.99 | Q41: =P41 -> 0.99 | R41: 1 | T41: 5
A42: UC_GrowthOfNGAR2LO5 | B42: =TechData_R0!B20 -> MINNGAD5 | E42: CAP, GROWTH | G42: LO | H42: =1-TechData_R0!J20+1 -> 0.9 | I42: =1-TechData_R0!K20+1 -> 0.99 | J42: =I42 -> 0.99 | K42: =J42 -> 0.99 | L42: =K42 -> 0.99 | M42: =L42 -> 0.99 | N42: =M42 -> 0.99 | O42: =N42 -> 0.99 | P42: =O42 -> 0.99 | Q42: =P42 -> 0.99 | R42: 1 | T42: 5
A43: UC_GrowthOfNGAR2LO6 | B43: =TechData_R0!B21 -> MINNGAD6 | E43: CAP, GROWTH | G43: LO | H43: =1-TechData_R0!J21+1 -> 0.9 | I43: =1-TechData_R0!K21+1 -> 0.99 | J43: =I43 -> 0.99 | K43: =J43 -> 0.99 | L43: =K43 -> 0.99 | M43: =L43 -> 0.99 | N43: =M43 -> 0.99 | O43: =N43 -> 0.99 | P43: =O43 -> 0.99 | Q43: =P43 -> 0.99 | R43: 1 | T43: 5
A46: Maximum capacity technology growth:
A47: ~UC_Sets: R_E: R3
...

Sheet UC_NGAb
A4: ~UC_Sets: R_E: R0 | J4: 0.8
G6: ~UC_T:
A7: UC_N | B7: Pset_PN | C7: Pset_PD | D7: Pset_CI | E7: Pset_CO | F7: Cset_CN | G7: Year | H7: LimType | I7: UC_FLO~2010 | J7: UC_FLO~2055 | K7: UC_RHSRTS | L7: UC_RHSRTS~0
A8: UC_NGA_CAN | B8: SCNGAC* | F8: NGAC1 | G8: 2020 | H8: LO | I8: 1 | J8: 1 | K8: 0 | L8: 15
B9: SCIMPNGA* | D9: NGAC | F9: NGACX | G9: 2025 | I9: =-Exports!$G$55 -> -0.083594039 | J9: =I9*J4 -> -0.066875231

Sheet TechData_R0
A1: TechData | B1: _GLOBAL,R0,R1,R2,R3,R4,R5,R6 | BO1: *
A6: Region | B6: TechName | C6: TechDesc | D6: CommOUT | E6: *TID | F6: *GROWTH_TIDr | G6: *GROWTHr~2010 | H6: *GROWTHr~2015-2020 | I6: *GROWTHr~2025-2055 | J6: *DECAYr~2010 | K6: *DECAYr~2015-2055 | L6: COST~2010 | M6: COST~2015 | N6: COST~2020 | O6: COST~2025 | P6: COST~2030 | Q6: COST~2035 | R6: COST~2040 | S6: COST~2045 | T6: COST~2050 | U6: COST~2055 | V6: CUM | W6: ACT_BND~LO~2010 | X6: ACT_BND~UP~2010 | Y6: ACT_BND~UP~2015 | Z6: ACT_BND~UP~2020 | AA6: ACT_BND~UP~2055
A7: *Minning Natural gas
A8: * Price Shocks | M8: 1 | N8: 1 | O8: 1 | P8: 1 | Q8: 1 | R8: 1 | S8: 1 | T8: 1 | U8: 1
A9: R1 | B9: MINNGAD1 | C9: Domestic natural gas - step 1 | D9: =Commodities!C$11 -> NGAD0 | E9: 2010 | G9: 1.25 | H9: 1.1 | I9: 1.1 | J9: 1.1 | K9: 1.01 | L9: =L11*'Domestic NG Prices'!$N$19 -> #REF! | M9: =M11*'Domestic NG Prices'!$N$19 -> #REF! | N9: =N11*'Domestic NG Prices'!$N$19 -> #REF! | O9: =O11*'Domestic NG Prices'!$N$19 -> #REF! | P9: =P11*'Domestic NG Prices'!$N$19 -> #REF! | Q9: =Q11*'Domestic NG Prices'!$N$19 -> #REF! | R9: =R11*'Domestic NG Prices'!$N$19 -> #REF! | S9: =S11*'Domestic NG Prices'!$N$19 -> 6.6176 | ... U9: =U11*'Domestic NG Prices'!$N$19 -> 8.0872 | V9: =X9/SUM($X$9:$X$14)*#REF! -> #REF! | W9: =#REF! -> #REF! | X9: =#REF! -> #REF!
A10: R1 | B10: MINNGAD2 | C10: Domestic natural gas - step 2 | D10: =Commodities!C$11 -> NGAD0 | E10: 2010 | G10: 1.25 | H10: 1.1 | I10: 1.1 | J10: 1.1 | K10: 1.01 | L10: =L11*'Domestic NG Prices'!$N$20 -> #REF! | M10: =M11*'Domestic NG Prices'!$N$20 -> #REF! | N10: =N11*'Domestic NG Prices'!$N$20 -> #REF! | O10: =O11*'Domestic NG Prices'!$N$20 -> #REF! | P10: =P11*'Domestic NG Prices'!$N$20 -> #REF! | Q10: =Q11*'Domestic NG Prices'!$N$20 -> #REF! | R10: =R11*'Domestic NG Prices'!$N$20 -> #REF! | S10: =S11*'Domestic NG Prices'!$N$20 -> 7.144 | ... U10: =U11*'Domestic NG Prices'!$N$20 -> 8.7305 | V10: =X10/SUM($X$9:$X$14)*#REF! -> #REF! | W10: =#REF! -> #REF! | X10: =#REF! -> #REF!
A11: R1 | B11: MINNGAD3 | C11: Domestic natural gas - step 3 | D11: =Commodities!C$11 -> NGAD0 | E11: 2010 | G11: 1.25 | H11: 1.1 | I11: 1.1 | J11: 1.1 | K11: 1.01 | L11: ='Domestic NG Prices'!N42*'Domestic NG Prices'!$P$27*#REF! -> #REF! | M11: ='Domestic NG Prices'!O42*'Domestic NG Prices'!$P$27*#REF!*M8 -> #REF! | N11: ='Domestic NG Prices'!P42*'Domestic NG Prices'!$P$27*#REF!*N8 -> #REF! | O11: ='Domestic NG Prices'!Q42*'Domestic NG Prices'!$P$27*#REF!*O8 -> #REF! | P11: ='Domestic NG Prices'!R42*'Domestic NG Prices'!$P$27*#REF!*P8 -> #REF! | Q11: ='Domestic NG Prices'!S42*'Domestic NG Prices'!$P$27*#REF!*Q8 -> #REF! | R11: ='Domestic NG Prices'!T42*'Domestic NG Prices'!$P$27*#REF!*R8 -> #REF! | S11: =7.52*S8 -> 7.52 | T11: =8.32*T8 -> 8.32 | U11: =9.19*U8 -> 9.19 | V11: =X11/SUM($X$9:$X$14)*#REF! -> #REF! | W11: =#REF! -> #REF! | X11: =#REF! -> #REF!
A12: R1 | B12: MINNGAD4 | C12: Domestic natural gas - step 4 | D12: =Commodities!C$11 -> NGAD0 | E12: 2010 | G12: 1.25 | H12: 1.1 | I12: 1.1 | J12: 1.1 | K12: 1.01 | L12: =L11*'Domestic NG Prices'!$N$22 -> #REF! | M12: =M11*'Domestic NG Prices'!$N$22 -> #REF! | N12: =N11*'Domestic NG Prices'!$N$22 -> #REF! | O12: =O11*'Domestic NG Prices'!$N$22 -> #REF! | P12: =P11*'Domestic NG Prices'!$N$22 -> #REF! | Q12: =Q11*'Domestic NG Prices'!$N$22 -> #REF! | R12: =R11*'Domestic NG Prices'!$N$22 -> #REF! | S12: =S11*'Domestic NG Prices'!$N$22 -> 8.1216 | ... U12: =U11*'Domestic NG Prices'!$N$22 -> 9.9252 | V12: =X12/SUM($X$9:$X$14)*#REF! -> #REF! | W12: =#REF! -> #REF! | X12: =#REF! -> #REF!
A13: R1 | B13: MINNGAD5 | C13: Domestic natural gas - step 5 | D13: =Commodities!C$11 -> NGAD0 | E13: 2010 | F13: =X13 -> #REF! | G13: 1.25 | H13: 1.1 | I13: 1.1 | J13: 1.1 | K13: 1.01 | L13: =L11*'Domestic NG Prices'!$N$23 -> #REF! | M13: =M11*'Domestic NG Prices'!$N$23 -> #REF! | N13: =N11*'Domestic NG Prices'!$N$23 -> #REF! | O13: =O11*'Domestic NG Prices'!$N$23 -> #REF! | P13: =P11*'Domestic NG Prices'!$N$23 -> #REF! | Q13: =Q11*'Domestic NG Prices'!$N$23 -> #REF! | R13: =R11*'Domestic NG Prices'!$N$23 -> #REF! | S13: =S11*'Domestic NG Prices'!$N$23 -> 8.4224 | ... U13: =U11*'Domestic NG Prices'!$N$23 -> 10.2928 | V13: =X13/SUM($X$9:$X$14)*#REF! -> #REF! | X13: =#REF! -> #REF!
A14: R1 | B14: MINNGAD6 | C14: Domestic natural gas - step 6 | D14: =Commodities!C$11 -> NGAD0 | E14: 2010 | F14: =X14 -> #REF! | G14: 1.25 | H14: 1.1 | I14: 1.1 | J14: 1.1 | K14: 1.01 | L14: =L11*'Domestic NG Prices'!$N$24 -> #REF! | M14: =M11*'Domestic NG Prices'!$N$24 -> #REF! | N14: =N11*'Domestic NG Prices'!$N$24 -> #REF! | O14: =O11*'Domestic NG Prices'!$N$24 -> #REF! | P14: =P11*'Domestic NG Prices'!$N$24 -> #REF! | Q14: =Q11*'Domestic NG Prices'!$N$24 -> #REF! | R14: =R11*'Domestic NG Prices'!$N$24 -> #REF! | S14: =S11*'Domestic NG Prices'!$N$24 -> 11.5056 | ... U14: =U11*'Domestic NG Prices'!$N$24 -> 14.0607 | V14: =X14/SUM($X$9:$X$14)*#REF! -> #REF! | X14: =#REF! -> #REF!
A15: *
A16: R2 | B16: MINNGAD1 | C16: Domestic natural gas - step 1 | D16: =Commodities!C$11 -> NGAD0 | E16: 2010 | G16: 1.25 | H16: 1.1 | I16: 1.1 | J16: 1.1 | K16: 1.01 | L16: =L18*'Domestic NG Prices'!$N$19 -> #REF! | M16: =M18*'Domestic NG Prices'!$N$19 -> #REF! | N16: =N18*'Domestic NG Prices'!$N$19 -> #REF! | O16: =O18*'Domestic NG Prices'!$N$19 -> #REF! | P16: =P18*'Domestic NG Prices'!$N$19 -> #REF! | Q16: =Q18*'Domestic NG Prices'!$N$19 -> #REF! | R16: =R18*'Domestic NG Prices'!$N$19 -> #REF! | S16: =S18*'Domestic NG Prices'!$N$19 -> 6.5694775 | ... U16: =U18*'Domestic NG Prices'!$N$19 -> 8.0217982 | V16: 0 | W16: =X16*0.9 -> 0 | X16: 0 | Y16: 0 | Z16: 0 | AA16: =Z16 -> 0
A17: R2 | B17: MINNGAD2 | C17: Domestic natural gas - step 2 | D17: =Commodities!C$11 -> NGAD0 | E17: 2010 | G17: 1.25 | H17: 1.1 | I17: 1.1 | J17: 1.1 | K17: 1.01 | L17: =L18*'Domestic NG Prices'!$N$20 -> #REF! | M17: =M18*'Domestic NG Prices'!$N$20 -> #REF! | N17: =N18*'Domestic NG Prices'!$N$20 -> #REF! | O17: =O18*'Domestic NG Prices'!$N$20 -> #REF! | P17: =P18*'Domestic NG Prices'!$N$20 -> #REF! | Q17: =Q18*'Domestic NG Prices'!$N$20 -> #REF! | R17: =R18*'Domestic NG Prices'!$N$20 -> #REF! | S17: =S18*'Domestic NG Prices'!$N$20 -> 7.0920495 | ... U17: =U18*'Domestic NG Prices'!$N$20 -> 8.6598958 | V17: 0 | W17: =X17*0.9 -> 0 | X17: 0 | Y17: 0 | Z17: 0 | AA17: =Z17 -> 0
A18: R2 | B18: MINNGAD3 | C18: Domestic natural gas - step 3 | D18: =Commodities!C$11 -> NGAD0 | E18: 2010 | G18: 1.25 | H18: 1.1 | I18: 1.1 | J18: 1.1 | K18: 1.01 | L18: ='Domestic NG Prices'!N42*'Domestic NG Prices'!$P$27*#REF! -> #REF! | M18: ='Domestic NG Prices'!O42*'Domestic NG Prices'!$P$27*#REF!*M8 -> #REF! | N18: ='Domestic NG Prices'!P42*'Domestic NG Prices'!$P$27*#REF!*N8 -> #REF! | O18: ='Domestic NG Prices'!Q42*'Domestic NG Prices'!$P$27*#REF!*O8 -> #REF! | P18: ='Domestic NG Prices'!R42*'Domestic NG Prices'!$P$27*#REF!*P8 -> #REF! | Q18: ='Domestic NG Prices'!S42*'Domestic NG Prices'!$P$27*#REF!*Q8 -> #REF! | R18: ='Domestic NG Prices'!T42*'Domestic NG Prices'!$P$27*#REF!*R8 -> #REF! | S18: =7.46531529457816*S8 -> 7.4653153 | T18: =8.2493286895923*T8 -> 8.2493287 | U18: =9.11567979966692*U8 -> 9.1156798 | V18: 0 | W18: =X18*0.9 -> 0 | X18: 0 | Y18: 0 | Z18: 0 | AA18: =Z18 -> 0
A19: R2 | B19: MINNGAD4 | C19: Domestic natural gas - step 4 | D19: =Commodities!C$11 -> NGAD0 | E19: 2010 | G19: 1.25 | H19: 1.1 | I19: 1.1 | J19: 1.1 | K19: 1.01 | L19: =L18*'Domestic NG Prices'!$N$22 -> #REF! | M19: =M18*'Domestic NG Prices'!$N$22 -> #REF! | N19: =N18*'Domestic NG Prices'!$N$22 -> #REF! | O19: =O18*'Domestic NG Prices'!$N$22 -> #REF! | P19: =P18*'Domestic NG Prices'!$N$22 -> #REF! | Q19: =Q18*'Domestic NG Prices'!$N$22 -> #REF! | R19: =R18*'Domestic NG Prices'!$N$22 -> #REF! | S19: =S18*'Domestic NG Prices'!$N$22 -> 8.0625405 | ... U19: =U18*'Domestic NG Prices'!$N$22 -> 9.8449342 | V19: 0 | W19: =X19*0.9 -> 0 | X19: 0 | Y19: 0 | Z19: 0 | AA19: =Z19 -> 0
A20: R2 | B20: MINNGAD5 | C20: Domestic natural gas - step 5 | D20: =Commodities!C$11 -> NGAD0 | E20: 2010 | F20: =X20 -> 0 | G20: 1.25 | H20: 1.1 | I20: 1.1 | J20: 1.1 | K20: 1.01 | L20: =L18*'Domestic NG Prices'!$N$23 -> #REF! | M20: =M18*'Domestic NG Prices'!$N$23 -> #REF! | N20: =N18*'Domestic NG Prices'!$N$23 -> #REF! | O20: =O18*'Domestic NG Prices'!$N$23 -> #REF! | P20: =P18*'Domestic NG Prices'!$N$23 -> #REF! | Q20: =Q18*'Domestic NG Prices'!$N$23 -> #REF! | R20: =R18*'Domestic NG Prices'!$N$23 -> #REF! | S20: =S18*'Domestic NG Prices'!$N$23 -> 8.3611531 | ... U20: =U18*'Domestic NG Prices'!$N$23 -> 10.209561 | V20: 0 | W20: =X20*0.9 -> 0 | X20: 0 | Y20: 0 | Z20: 0 | AA20: =Z20 -> 0
A21: R2 | B21: MINNGAD6 | C21: Domestic natural gas - step 6 | D21: =Commodities!C$11 -> NGAD0 | E21: 2010 | F21: =X21 -> 0 | G21: 1.25 | H21: 1.1 | I21: 1.1 | J21: 1.1 | K21: 1.01 | L21: =L18*'Domestic NG Prices'!$N$24 -> #REF! | M21: =M18*'Domestic NG Prices'!$N$24 -> #REF! | N21: =N18*'Domestic NG Prices'!$N$24 -> #REF! | O21: =O18*'Domestic NG Prices'!$N$24 -> #REF! | P21: =P18*'Domestic NG Prices'!$N$24 -> #REF! | Q21: =Q18*'Domestic NG Prices'!$N$24 -> #REF! | R21: =R18*'Domestic NG Prices'!$N$24 -> #REF! | S21: =S18*'Domestic NG Prices'!$N$24 -> 11.421932 | ... U21: =U18*'Domestic NG Prices'!$N$24 -> 13.94699 | V21: 0 | W21: =X21*0.9 -> 0 | X21: 0 | Y21: 0 | Z21: 0 | AA21: =Z21 -> 0
A22: *
A23: R3 | B23: MINNGAD1 | C23: Domestic natural gas - step 1 | D23: =Commodities!C$11 -> NGAD0 | E23: 2010 | G23: 1.25 | H23: 1.1 | I23: 1.1 | J23: 1.1 | K23: 1.01 | L23: =L25*'Domestic NG Prices'!$N$19 -> #REF! | M23: =M25*'Domestic NG Prices'!$N$19 -> #REF! | N23: =N25*'Domestic NG Prices'!$N$19 -> #REF! | O23: =O25*'Domestic NG Prices'!$N$19 -> #REF! | P23: =P25*'Domestic NG Prices'!$N$19 -> #REF! | Q23: =Q25*'Domestic NG Prices'!$N$19 -> #REF! | R23: =R25*'Domestic NG Prices'!$N$19 -> #REF! | S23: =S25*'Domestic NG Prices'!$N$19 -> 6.0617197 | ... U23: =U25*'Domestic NG Prices'!$N$19 -> 7.40179 | V23: 0 | W23: =X23*0.9 -> 0 | X23: 0 | Y23: 0 | Z23: 0 | AA23: =Z23 -> 0
A24: R3 | B24: MINNGAD2 | C24: Domestic natural gas - step 2 | D24: =Commodities!C$11 -> NGAD0 | E24: 2010 | G24: 1.25 | H24: 1.1 | I24: 1.1 | J24: 1.1 | K24: 1.01 | L24: =L25*'Domestic NG Prices'!$N$20 -> #REF! | M24: =M25*'Domestic NG Prices'!$N$20 -> #REF! | N24: =N25*'Domestic NG Prices'!$N$20 -> #REF! | O24: =O25*'Domestic NG Prices'!$N$20 -> #REF! | P24: =P25*'Domestic NG Prices'!$N$20 -> #REF! | Q24: =Q25*'Domestic NG Prices'!$N$20 -> #REF! | R24: =R25*'Domestic NG Prices'!$N$20 -> #REF! | S24: =S25*'Domestic NG Prices'!$N$20 -> 6.543902 | ... U24: =U25*'Domestic NG Prices'!$N$20 -> 7.9905688 | V24: 0 | W24: =X24*0.9 -> 0 | X24: 0 | Y24: 0 | Z24: 0 | AA24: =Z24 -> 0
A25: R3 | B25: MINNGAD3 | C25: Domestic natural gas - step 3 | D25: =Commodities!C$11 -> NGAD0 | E25: 2010 | G25: 1.25 | H25: 1.1 | I25: 1.1 | J25: 1.1 | K25: 1.01 | L25: ='Domestic NG Prices'!N42*'Domestic NG Prices'!$P$27*#REF! -> #REF! | M25: ='Domestic NG Prices'!O42*'Domestic NG Prices'!$P$27*#REF!*M8 -> #REF! | N25: ='Domestic NG Prices'!P42*'Domestic NG Prices'!$P$27*#REF!*N8 -> #REF! | O25: ='Domestic NG Prices'!Q42*'Domestic NG Prices'!$P$27*#REF!*O8 -> #REF! | P25: ='Domestic NG Prices'!R42*'Domestic NG Prices'!$P$27*#REF!*P8 -> #REF! | Q25: ='Domestic NG Prices'!S42*'Domestic NG Prices'!$P$27*#REF!*Q8 -> #REF! | R25: ='Domestic NG Prices'!T42*'Domestic NG Prices'!$P$27*#REF!*R8 -> #REF! | S25: =6.88831787744587*S8 -> 6.8883179 | T25: =7.61173454130134*T8 -> 7.6117345 | U25: =8.41112500294819*U8 -> 8.411125 | V25: 0 | W25: =X25*0.9 -> 0 | X25: 0 | Y25: 0 | Z25: 0 | AA25: =Z25 -> 0
A26: R3 | B26: MINNGAD4 | C26: Domestic natural gas - step 4 | D26: =Commodities!C$11 -> NGAD0 | E26: 2010 | G26: 1.1 | H26: 1.1 | I26: 1.1 | J26: 1.1 | K26: 1.01 | L26: =L25*'Domestic NG Prices'!$N$22 -> #REF! | M26: =M25*'Domestic NG Prices'!$N$22 -> #REF! | N26: =N25*'Domestic NG Prices'!$N$22 -> #REF! | O26: =O25*'Domestic NG Prices'!$N$22 -> #REF! | P26: =P25*'Domestic NG Prices'!$N$22 -> #REF! | Q26: =Q25*'Domestic NG Prices'!$N$22 -> #REF! | R26: =R25*'Domestic NG Prices'!$N$22 -> #REF! | S26: =S25*'Domestic NG Prices'!$N$22 -> 7.4393833 | ... U26: =U25*'Domestic NG Prices'!$N$22 -> 9.084015 | V26: 0 | W26: =X26*0.9 -> 0 | X26: 0 | Y26: 0 | Z26: 0 | AA26: =Z26 -> 0
A27: R3 | B27: MINNGAD5 | C27: Domestic natural gas - step 5 | D27: =Commodities!C$11 -> NGAD0 | E27: 2010 | F27: =X27 -> 0 | G27: 1.01 | H27: 1.01 | I27: 1.01 | J27: 1.1 | K27: 1.01 | L27: =L25*'Domestic NG Prices'!$N$23 -> #REF! | M27: =M25*'Domestic NG Prices'!$N$23 -> #REF! | N27: =N25*'Domestic NG Prices'!$N$23 -> #REF! | O27: =O25*'Domestic NG Prices'!$N$23 -> #REF! | P27: =P25*'Domestic NG Prices'!$N$23 -> #REF! | Q27: =Q25*'Domestic NG Prices'!$N$23 -> #REF! | R27: =R25*'Domestic NG Prices'!$N$23 -> #REF! | S27: =S25*'Domestic NG Prices'!$N$23 -> 7.714916 | ... U27: =U25*'Domestic NG Prices'!$N$23 -> 9.42046 | V27: 0 | W27: =X27*0.9 -> 0 | X27: 0 | Y27: 0 | Z27: 0 | AA27: =Z27 -> 0
A28: R3 | B28: MINNGAD6 | C28: Domestic natural gas - step 6 | D28: =Commodities!C$11 -> NGAD0 | E28: 2010 | F28: =X28 -> 0 | G28: 1.01 | H28: 1.01 | I28: 1.01 | J28: 1.1 | K28: 1.01 | L28: =L25*'Domestic NG Prices'!$N$24 -> #REF! | M28: =M25*'Domestic NG Prices'!$N$24 -> #REF! | N28: =N25*'Domestic NG Prices'!$N$24 -> #REF! | O28: =O25*'Domestic NG Prices'!$N$24 -> #REF! | P28: =P25*'Domestic NG Prices'!$N$24 -> #REF! | Q28: =Q25*'Domestic NG Prices'!$N$24 -> #REF! | R28: =R25*'Domestic NG Prices'!$N$24 -> #REF! | S28: =S25*'Domestic NG Prices'!$N$24 -> 10.539126 | ... U28: =U25*'Domestic NG Prices'!$N$24 -> 12.869021 | V28: 0 | W28: =X28*0.9 -> 0 | X28: 0 | Y28: 0 | Z28: 0 | AA28: =Z28 -> 0
A29: *
A30: R4 | B30: MINNGAD1 | C30: Domestic natural gas - step 1 | D30: =Commodities!C$11 -> NGAD0 | E30: 2010 | G30: 1.1 | H30: 1.05 | I30: 1.01 | J30: 1.1 | K30: 1.01 | L30: =L32*'Domestic NG Prices'!$N$19 -> #REF! | M30: =M32*'Domestic NG Prices'!$N$19 -> #REF! | N30: =N32*'Domestic NG Prices'!$N$19 -> #REF! | O30: =O32*'Domestic NG Prices'!$N$19 -> #REF! | P30: =P32*'Domestic NG Prices'!$N$19 -> #REF! | Q30: =Q32*'Domestic NG Prices'!$N$19 -> #REF! | R30: =R32*'Domestic NG Prices'!$N$19 -> #REF! | S30: =S32*'Domestic NG Prices'!$N$19 -> 6.4965138 | ... U30: =U32*'Domestic NG Prices'!$N$19 -> 7.9327045 | V30: 0 | W30: =X30*0.9 -> 0 | X30: 0 | Y30: 0 | Z30: 0 | AA30: =Z30 -> 0
A31: R4 | B31: MINNGAD2 | C31: Domestic natural gas - step 2 | D31: =Commodities!C$11 -> NGAD0 | E31: 2010 | G31: 1.2 | H31: 1.1 | I31: 1.05 | J31: 1.1 | K31: 1.01 | L31: =L32*'Domestic NG Prices'!$N$20 -> #REF! | M31: =M32*'Domestic NG Prices'!$N$20 -> #REF! | N31: =N32*'Domestic NG Prices'!$N$20 -> #REF! | O31: =O32*'Domestic NG Prices'!$N$20 -> #REF! | P31: =P32*'Domestic NG Prices'!$N$20 -> #REF! | Q31: =Q32*'Domestic NG Prices'!$N$20 -> #REF! | R31: =R32*'Domestic NG Prices'!$N$20 -> #REF! | S31: =S32*'Domestic NG Prices'!$N$20 -> 7.013282 | ... U31: =U32*'Domestic NG Prices'!$N$20 -> 8.5637151 | V31: 0 | W31: =X31*0.9 -> 0 | X31: 0 | Y31: 0 | Z31: 0 | AA31: =Z31 -> 0
A32: R4 | B32: MINNGAD3 | C32: Domestic natural gas - step 3 | D32: =Commodities!C$11 -> NGAD0 | E32: 2010 | G32: 1.1 | H32: 1.1 | I32: 1.05 | J32: 1.1 | K32: 1.01 | L32: ='Domestic NG Prices'!N42*'Domestic NG Prices'!$P$27*#REF! -> #REF! | M32: ='Domestic NG Prices'!O42*'Domestic NG Prices'!$P$27*#REF!*M8 -> #REF! | N32: ='Domestic NG Prices'!P42*'Domestic NG Prices'!$P$27*#REF!*N8 -> #REF! | O32: ='Domestic NG Prices'!Q42*'Domestic NG Prices'!$P$27*#REF!*O8 -> #REF! | P32: ='Domestic NG Prices'!R42*'Domestic NG Prices'!$P$27*#REF!*P8 -> #REF! | Q32: ='Domestic NG Prices'!S42*'Domestic NG Prices'!$P$27*#REF!*Q8 -> #REF! | R32: ='Domestic NG Prices'!T42*'Domestic NG Prices'!$P$27*#REF!*R8 -> #REF! | S32: =7.38240209732537*S8 -> 7.3824021 | T32: =8.15770788191657*T8 -> 8.1577079 | U32: =9.01443690134327*U8 -> 9.0144369 | V32: 0 | W32: =X32*0.9 -> 0 | X32: 0 | Y32: 0 | Z32: 0 | AA32: =Z32 -> 0
A33: R4 | B33: MINNGAD4 | C33: Domestic natural gas - step 4 | D33: =Commodities!C$11 -> NGAD0 | E33: 2010 | G33: 1.1 | H33: 1.1 | I33: 1.1 | J33: 1.1 | K33: 1.01 | L33: =L32*'Domestic NG Prices'!$N$22 -> #REF! | M33: =M32*'Domestic NG Prices'!$N$22 -> #REF! | N33: =N32*'Domestic NG Prices'!$N$22 -> #REF! | O33: =O32*'Domestic NG Prices'!$N$22 -> #REF! | P33: =P32*'Domestic NG Prices'!$N$22 -> #REF! | Q33: =Q32*'Domestic NG Prices'!$N$22 -> #REF! | R33: =R32*'Domestic NG Prices'!$N$22 -> #REF! | S33: =S32*'Domestic NG Prices'!$N$22 -> 7.9729943 | ... U33: =U32*'Domestic NG Prices'!$N$22 -> 9.7355919 | V33: 0 | W33: =X33*0.9 -> 0 | X33: 0 | Y33: 0 | Z33: 0 | AA33: =Z33 -> 0
A34: R4 | B34: MINNGAD5 | C34: Domestic natural gas - step 5 | D34: =Commodities!C$11 -> NGAD0 | E34: 2010 | F34: =X34 -> 0 | G34: 1.01 | H34: 1.01 | I34: 1.01 | J34: 1.1 | K34: 1.01 | L34: =L32*'Domestic NG Prices'!$N$23 -> #REF! | M34: =M32*'Domestic NG Prices'!$N$23 -> #REF! | N34: =N32*'Domestic NG Prices'!$N$23 -> #REF! | O34: =O32*'Domestic NG Prices'!$N$23 -> #REF! | P34: =P32*'Domestic NG Prices'!$N$23 -> #REF! | Q34: =Q32*'Domestic NG Prices'!$N$23 -> #REF! | R34: =R32*'Domestic NG Prices'!$N$23 -> #REF! | S34: =S32*'Domestic NG Prices'!$N$23 -> 8.2682903 | ... U34: =U32*'Domestic NG Prices'!$N$23 -> 10.096169 | V34: 0 | W34: =X34*0.9 -> 0 | X34: 0 | Y34: 0 | Z34: 0 | AA34: =Z34 -> 0
A35: R4 | B35: MINNGAD6 | C35: Domestic natural gas - step 6 | D35: =Commodities!C$11 -> NGAD0 | E35: 2010 | F35: =X35 -> 0 | G35: 1.01 | H35: 1.01 | I35: 1.01 | J35: 1.1 | K35: 1.01 | L35: =L32*'Domestic NG Prices'!$N$24 -> #REF! | M35: =M32*'Domestic NG Prices'!$N$24 -> #REF! | N35: =N32*'Domestic NG Prices'!$N$24 -> #REF! | O35: =O32*'Domestic NG Prices'!$N$24 -> #REF! | P35: =P32*'Domestic NG Prices'!$N$24 -> #REF! | Q35: =Q32*'Domestic NG Prices'!$N$24 -> #REF! | R35: =R32*'Domestic NG Prices'!$N$24 -> #REF! | S35: =S32*'Domestic NG Prices'!$N$24 -> 11.295075 | ... U35: =U32*'Domestic NG Prices'!$N$24 -> 13.792088 | V35: 0 | W35: =X35*0.9 -> 0 | X35: 0 | Y35: 0 | Z35: 0 | AA35: =Z35 -> 0
A36: *
A37: R5 | B37: MINNGAD1 | C37: Domestic natural gas - step 1 | D37: =Commodities!C$11 -> NGAD0 | E37: 2010 | G37: 1.1 | H37: 1.05 | I37: 1.01 | J37: 1.1 | K37: 1.01 | L37: =L39*'Domestic NG Prices'!$N$19 -> #REF! | M37: =M39*'Domestic NG Prices'!$N$19 -> #REF! | N37: =N39*'Domestic NG Prices'!$N$19 -> #REF! | O37: =O39*'Domestic NG Prices'!$N$19 -> #REF! | P37: =P39*'Domestic NG Prices'!$N$19 -> #REF! | Q37: =Q39*'Domestic NG Prices'!$N$19 -> #REF! | R37: =R39*'Domestic NG Prices'!$N$19 -> #REF! | S37: =S39*'Domestic NG Prices'!$N$19 -> 6.286944 | ... U37: =U39*'Domestic NG Prices'!$N$19 -> 7.6768048 | V37: 0 | W37: =X37*0.9 -> 0 | X37: 0 | Y37: 0 | Z37: 0 | AA37: =Z37 -> 0
A38: R5 | B38: MINNGAD2 | C38: Domestic natural gas - step 2 | D38: =Commodities!C$11 -> NGAD0 | E38: 2010 | G38: 1.2 | H38: 1.1 | I38: 1.05 | J38: 1.1 | K38: 1.01 | L38: =L39*'Domestic NG Prices'!$N$20 -> #REF! | M38: =M39*'Domestic NG Prices'!$N$20 -> #REF! | N38: =N39*'Domestic NG Prices'!$N$20 -> #REF! | O38: =O39*'Domestic NG Prices'!$N$20 -> #REF! | P38: =P39*'Domestic NG Prices'!$N$20 -> #REF! | Q38: =Q39*'Domestic NG Prices'!$N$20 -> #REF! | R38: =R39*'Domestic NG Prices'!$N$20 -> #REF! | S38: =S39*'Domestic NG Prices'!$N$20 -> 6.7870418 | ... U38: =U39*'Domestic NG Prices'!$N$20 -> 8.2874597 | V38: 0 | W38: =X38*0.9 -> 0 | X38: 0 | Y38: 0 | Z38: 0 | AA38: =Z38 -> 0
A39: R5 | B39: MINNGAD3 | C39: Domestic natural gas - step 3 | D39: =Commodities!C$11 -> NGAD0 | E39: 2010 | G39: 1.1 | H39: 1.1 | I39: 1.05 | J39: 1.1 | K39: 1.01 | L39: ='Domestic NG Prices'!N42*'Domestic NG Prices'!$P$27*#REF! -> #REF! | M39: ='Domestic NG Prices'!O42*'Domestic NG Prices'!$P$27*#REF!*M8 -> #REF! | N39: ='Domestic NG Prices'!P42*'Domestic NG Prices'!$P$27*#REF!*N8 -> #REF! | O39: ='Domestic NG Prices'!Q42*'Domestic NG Prices'!$P$27*#REF!*O8 -> #REF! | P39: ='Domestic NG Prices'!R42*'Domestic NG Prices'!$P$27*#REF!*P8 -> #REF! | Q39: ='Domestic NG Prices'!S42*'Domestic NG Prices'!$P$27*#REF!*Q8 -> #REF! | R39: ='Domestic NG Prices'!T42*'Domestic NG Prices'!$P$27*#REF!*R8 -> #REF! | S39: =7.14425453277032*S8 -> 7.1442545 | T39: =7.89454986927814*T8 -> 7.8945499 | U39: =8.72364182332011*U8 -> 8.7236418 | V39: 0 | W39: =X39*0.9 -> 0 | X39: 0 | Y39: 0 | Z39: 0 | AA39: =Z39 -> 0
A40: R5 | B40: MINNGAD4 | C40: Domestic natural gas - step 4 | D40: =Commodities!C$11 -> NGAD0 | E40: 2010 | G40: 1.1 | H40: 1.1 | I40: 1.1 | J40: 1.1 | K40: 1.01 | L40: =L39*'Domestic NG Prices'!$N$22 -> #REF! | M40: =M39*'Domestic NG Prices'!$N$22 -> #REF! | N40: =N39*'Domestic NG Prices'!$N$22 -> #REF! | O40: =O39*'Domestic NG Prices'!$N$22 -> #REF! | P40: =P39*'Domestic NG Prices'!$N$22 -> #REF! | Q40: =Q39*'Domestic NG Prices'!$N$22 -> #REF! | R40: =R39*'Domestic NG Prices'!$N$22 -> #REF! | S40: =S39*'Domestic NG Prices'!$N$22 -> 7.7157949 | ... U40: =U39*'Domestic NG Prices'!$N$22 -> 9.4215332 | V40: 0 | W40: =X40*0.9 -> 0 | X40: 0 | Y40: 0 | Z40: 0 | AA40: =Z40 -> 0
A41: R5 | B41: MINNGAD5 | C41: Domestic natural gas - step 5 | D41: =Commodities!C$11 -> NGAD0 | E41: 2010 | F41: =X41 -> 0 | G41: 1.01 | H41: 1.01 | I41: 1.01 | J41: 1.1 | K41: 1.01 | L41: =L39*'Domestic NG Prices'!$N$23 -> #REF! | M41: =M39*'Domestic NG Prices'!$N$23 -> #REF! | N41: =N39*'Domestic NG Prices'!$N$23 -> #REF! | O41: =O39*'Domestic NG Prices'!$N$23 -> #REF! | P41: =P39*'Domestic NG Prices'!$N$23 -> #REF! | Q41: =Q39*'Domestic NG Prices'!$N$23 -> #REF! | R41: =R39*'Domestic NG Prices'!$N$23 -> #REF! | S41: =S39*'Domestic NG Prices'!$N$23 -> 8.0015651 | ... U41: =U39*'Domestic NG Prices'!$N$23 -> 9.7704788 | V41: 0 | W41: =X41*0.9 -> 0 | X41: 0 | Y41: 0 | Z41: 0 | AA41: =Z41 -> 0
A42: R5 | B42: MINNGAD6 | C42: Domestic natural gas - step 6 | D42: =Commodities!C$11 -> NGAD0 | E42: 2010 | F42: =X42 -> 0 | G42: 1.01 | H42: 1.01 | I42: 1.01 | J42: 1.1 | K42: 1.01 | L42: =L39*'Domestic NG Prices'!$N$24 -> #REF! | M42: =M39*'Domestic NG Prices'!$N$24 -> #REF! | N42: =N39*'Domestic NG Prices'!$N$24 -> #REF! | O42: =O39*'Domestic NG Prices'!$N$24 -> #REF! | P42: =P39*'Domestic NG Prices'!$N$24 -> #REF! | Q42: =Q39*'Domestic NG Prices'!$N$24 -> #REF! | R42: =R39*'Domestic NG Prices'!$N$24 -> #REF! | S42: =S39*'Domestic NG Prices'!$N$24 -> 10.930709 | ... U42: =U39*'Domestic NG Prices'!$N$24 -> 13.347172 | V42: 0 | W42: =X42*0.9 -> 0 | X42: 0 | Y42: 0 | Z42: 0 | AA42: =Z42 -> 0
A43: *
A44: *
...

Sheet >> Not used

Sheet Commodities
B1: Commodities | C1: _GLOBAL,R0,R1,R2,R3,R4,R5,R6
B7: Region | C7: CommName | D7: CommDesc | E7: Unit | F7: Csets | G7: LimType | H7: CTSLvl | I7: PeakTS | J7: Ctype | O7: Comment
B8: * Natural Gas Supply Commodities - Domestic and Imported
B9: R1,R2,R3,R4,R5,R6 | C9: NGA | D9: Natural Gas | E9: PJ | F9: NRG
B10: R1,R2,R3,R4,R5,R6 | C10: NGAD | D10: Domestic Natural Gas | E10: PJ
B11: R1,R2,R3,R4,R5,R6 | C11: NGAD0 | D11: Domestic Natural Gas - D0 | E11: PJ
B12: R1 | C12: NGAD1 | D12: Domestic Natural Gas - R1 | E12: PJ
B13: R2 | C13: NGAD2 | D13: Domestic Natural Gas - R2 | E13: PJ
B14: R3 | C14: NGAD3 | D14: Domestic Natural Gas - R3 | E14: PJ
B15: R4 | C15: NGAD4 | D15: Domestic Natural Gas - R4 | E15: PJ
B16: R5 | C16: NGAD5 | D16: Domestic Natural Gas - R5 | E16: PJ
B17: R6 | C17: NGAD6 | D17: Domestic Natural Gas - R6 | E17: PJ
B18: R1,R2,R3,R4,R5,R6 | C18: NGAR1 | D18: Natural Gas - R1 | E18: PJ
B19: R1,R2,R3,R4,R5,R6 | C19: NGAR2 | D19: Natural Gas - R2 | E19: PJ
B20: R1,R2,R3,R4,R5,R6 | C20: NGAR3 | D20: Natural Gas - R3 | E20: PJ
B21: R1,R2,R3,R4,R5,R6 | C21: NGAR4 | D21: Natural Gas - R4 | E21: PJ
... B43: R1,R2,R3,R4,R5,R6 | C43: NGLR6 | D43: Traded natural gas plant liquids from R6 | E43: PJ
B44: * Natural Gas End-Use Commodities
B45: R1,R2,R3,R4,R5,R6 | C45: RESNGA | D45: Natural gas to Residential sector | E45: PJ | F45: NRG
B46: R1,R2,R3,R4,R5,R6 | C46: COMNGA | D46: Natural gas to Commercial sector | E46: PJ
B47: R1,R2,R3,R4,R5,R6 | C47: INDNGA | D47: Natural gas to Industrial sector | E47: PJ
B48: R1,R2,R3,R4,R5,R6 | C48: ELCNGA | D48: Natural gas to Electricity generation | E48: PJ
B49: R1,R2,R3,R4,R5,R6 | C49: TRNNGA | D49: Natural gas to Transportation sector | E49: PJ
B50: *R1,R2,R3,R4,R5,R6 | C50: LPG | D50: LPG from NGL | E50: PJ
B51: *R1,R2,R3,R4,R5,R7 | C51: PFS | D51: PFS from NGL | E51: PJ
B52: *R1,R2,R3,R4,R5,R8 | C52: PENTS | D52: Pentanes from NGL | E52: PJ
B53: *R1,R2,R3,R4,R5,R9 | C53: GSR | D53: NGL Pentanes to gasoline | E53: PJ
B54: *R1,R2,R3,R4,R5,R10 | C54: DENAT | D54: NGL Pentanes to ethanol denaturant | E54: PJ
B55: *R1,R2,R3,R4,R5,R11 | C55: PFS_NGL | D55: Natural gas liquids to PFS (C2 & C4) | E55: PJ
B56: *R1,R2,R3,R4,R5,R12 | C56: LPG_NGL | D56: Natural gas liquids to LPG (C3) | E56: PJ
B57: *R1,R2,R3,R4,R5,R13 | C57: NGLPENT | D57: Natural gas liquids to pentanes (C5+) | E57: PJ
B74: * Emissions Commodities
B75: R1,R2,R3,R4,R5,R6 | C75: CO2 | D75: Carbon dioxide | E75: Mt | F75: ENV
B76: R1,R2,R3,R4,R5,R6 | C76: NOX | D76: Nitrogen oxide | E76: kt | F76: ENV
B77: R1,R2,R3,R4,R5,R6 | C77: PM10 | D77: Particulate matter | E77: kt | F77: ENV
B78: R1,R2,R3,R4,R5,R6 | C78: PM25 | D78: Fine particulate matter | E78: kt | F78: ENV
B79: R1,R2,R3,R4,R5,R6 | C79: VOC | D79: Volatile organic compounds | E79: kt | F79: ENV
B80: R1,R2,R3,R4,R5,R6 | C80: CO | D80: Carbon monoxide | E80: kt | F80: ENV
B81: R1,R2,R3,R4,R5,R6 | C81: CH4 | D81: Methane | E81: kt | F81: ENV
B82: R1,R2,R3,R4,R5,R6 | C82: N2O | D82: N2O | E82: kt | F82: ENV
...

Sheet ANSv6.1-Technologies
A1: ANSWER-Technologies
B7: TechName | C7: TechDesc | D7: TACTUnit | E7: TCAPUnit | F7: Set Memberships | G7: Comment

Sheet Technologies
B1: Technologies | C1: _GLOBAL,R0,R1,R2,R3,R4,R5,R6
B7: Region | C7: TechName | D7: TechDesc | E7: Tact | F7: Tcap | G7: Sets | H7: PrimaryCG | I7: Vintage | O7: Comment
B8: R1,R2,R3,R4,R5,R6 | C8: MINNGAD1 | D8: Domestic natural gas - step 1 | E8: PJ | F8: PJ/a | G8: MIN
B9: R1,R2,R3,R4,R5,R6 | C9: MINNGAD2 | D9: Domestic natural gas - step 2 | E9: PJ | F9: PJ/a
B10: R1,R2,R3,R4,R5,R6 | C10: MINNGAD3 | D10: Domestic natural gas - step 3 | E10: PJ | F10: PJ/a
B11: R1,R2,R3,R4,R5,R6 | C11: MINNGAD4 | D11: Domestic natural gas - step 4 | E11: PJ | F11: PJ/a
B12: R1,R2,R3,R4,R5,R6 | C12: MINNGAD5 | D12: Domestic natural gas - step 5 | E12: PJ | F12: PJ/a
B13: R1,R2,R3,R4,R5,R6 | C13: MINNGAD6 | D13: Domestic natural gas - step 6 | E13: PJ | F13: PJ/a
B14: R1,R2,R3,R4,R5,R6 | C14: SCMINNGAD | D14: Collector: MINNGAD | E14: PJ | F14: PJ/a | G14: PRE
B15: R1 | C15: MINNGLDMY | D15: Dummy NGL Resource Supply | E15: PJ | F15: PJ/a | G15: MIN
B16: R1 | C16: SCNGAR1 | D16: Collector: Natural Gas R1 | E16: PJ | F16: PJ/a | G16: PRE
B17: R2 | C17: SCNGAR2 | D17: Collector: Natural Gas R2 | E17: PJ | F17: PJ/a
B18: R3 | C18: SCNGAR3 | D18: Collector: Natural Gas R3 | E18: PJ | F18: PJ/a
B19: R4 | C19: SCNGAR4 | D19: Collector: Natural Gas R4 | E19: PJ | F19: PJ/a
B20: R5 | C20: SCNGAR5 | D20: Collector: Natural Gas R5 | E20: PJ | F20: PJ/a
B21: R6 | C21: SCNGAR6 | D21: Collector: Natural Gas R6 | E21: PJ | F21: PJ/a
B22: *
B23: R1 | C23: SCNGAD1 | D23: Domestic natural gas Existing infrastructure in R1 | E23: PJ | F23: PJ/a
B24: R2 | C24: SCNGAD2 | D24: Domestic natural gas Existing infrastructure in R2 | E24: PJ | F24: PJ/a
B25: R3 | C25: SCNGAD3 | D25: Domestic natural gas Existing infrastructure in R3 | E25: PJ | F25: PJ/a
B26: R4 | C26: SCNGAD4 | D26: Domestic natural gas Existing infrastructure in R4 | E26: PJ | F26: PJ/a
B27: R5 | C27: SCNGAD5 | D27: Domestic natural gas Existing infrastructure in R5 | E27: PJ | F27: PJ/a
B28: R6 | C28: SCNGAD6 | D28: Domestic natural gas Existing infrastructure in R6 | E28: PJ | F28: PJ/a
B29: *Imported natural gas supply and transport
B30: R0 | C30: IMPNGALA | D30: Imported LNG - Step A | E30: PJ | F30: PJ/a | G30: IMP
B31: R0 | C31: IMPNGALB | D31: Imported LNG - Step B | E31: PJ | F31: PJ/a
B32: R0 | C32: IMPNGALC | D32: Imported LNG - Step C | E32: PJ | F32: PJ/a
B33: R0 | C33: SCIMPNGAL | D33: Share of Imported LNG to Existing Terminals | E33: PJ | F33: PJ/a | G33: PRE
B34: R0 | C34: IMPNGAC1 | D34: Imported natural gas from Canada - Step 1 | E34: PJ | F34: PJ/a | G34: IMP
B35: R0 | C35: IMPNGAC2 | D35: Imported natural gas from Canada - Step 2 | E35: PJ | F35: PJ/a
B36: R0 | C36: IMPNGAC3 | D36: Imported natural gas from Canada - Step 3 | E36: PJ | F36: PJ/a
B37: R0 | C37: IMPNGAC4 | D37: Imported natural gas from Canada - Step 4 | E37: PJ | F37: PJ/a
B38: R0 | C38: IMPNGAC5 | D38: Imported natural gas from Canada - Step 5 | E38: PJ | F38: PJ/a
B39: R0 | C39: IMPNGAC6 | D39: Imported natural gas from Canada - Step 6 | E39: PJ | F39: PJ/a
B40: R0 | C40: SCIMPNGAC | D40: Canadian imported natural gas shares | E40: PJ | F40: PJ/a | G40: PRE
B41: R0 | C41: SCNGAC1 | D41: Canadian imported natural gas in R1 | E41: PJ | F41: PJ/a
B42: *R0 | C42: SCNGAC2 | D42: Canadian imported natural gas in R2 | E42: PJ | F42: PJ/a
B43: *R0 | C43: SCNGAC3 | D43: Canadian imported natural gas in R3 | E43: PJ | F43: PJ/a
B44: *R0 | C44: SCNGAC4 | D44: Canadian imported natural gas in R4 | E44: PJ | F44: PJ/a
B45: *R0 | C45: SCNGAC5 | D45: Canadian imported natural gas in R5 | E45: PJ | F45: PJ/a
...

Sheet ANSv6.1-Constraints
A1: ANSWER-Constraints
B7: ConstrName | C7: ConstrDesc | D7: Units | E7: Set Memberships | F7: Comment

Sheet ANSv6.1-CommData
A1: ANSWER-CommData
B7: CommName | C7: CommDesc | D7: Units

Sheet ANSv6.1-TechData
A1: ANSWER-TechData
B7: TechName | C7: TechDesc | D7: Units | E7: CommIN | F7: CommOUT

Sheet ANSv6.1-ConstrData
A1: ANSWER-ConstrData
B7: ConstrName | C7: ConstrDesc | D7: Units | E7: TechName

Sheet Domestic NG Prices
A1: Lower 48 Natural Gas Production and Wellhead Prices by Supply Region, Reference case
A3: Region | B3: 2005 in 2005$ | C3: 2010 in 2010$ | D3: 2015 | E3: 2020 | F3: 2025 | G3: 2030 | H3: 2035 | I3: 2040
A5: Dry Production (trillion cubic feet) 1/
A6: Lower 48 Total | B6: 17.772602 | C6: 21.22 | D6: 24.329756 | E6: 28.812149 | F6: 31.609116 | G6: 33.242813 | H6: 34.918686 | I6: 36.377583
A8: Lower 48 Onshore | C8: 18.66 | D8: 22.213337 | E8: 26.654739 | F8: 29.519766 | G8: 30.82295 | H8: 32.458858 | I8: 33.428997
A9: Northeast | B9: 1.0956695 | C9: 1.52 | D9: 4.255119 | E9: 5.287964 | F9: 6.526698 | G9: 6.571349 | H9: 7.722331 | I9: 8.083803
A10: Gulf Coast | B10: 4.651669 | C10: 4.85 | D10: 6.021707 | E10: 8.327435 | F10: 9.761693 | G10: 10.173032 | H10: 10.303289 | I10: 10.544703
A11: Midcontinent | B11: 2.4793184 | C11: 3.43 | D11: 3.387572 | E11: 3.736248 | F11: 3.707607 | G11: 3.486203 | H11: 3.278044 | I11: 2.976638
A12: Southwest | B12: 1.8143151 | C12: 3.59 | D12: 3.454635 | E12: 3.461408 | F12: 3.271382 | G12: 3.288815 | H12: 3.325309 | I12: 4.202095
A13: Rocky Mountain | B13: 4.0738535 | C13: 5.06 | D13: 4.943402 | E13: 5.698319 | F13: 6.122963 | G13: 7.191331 | H13: 7.722852 | I13: 7.498688
A14: West Coast | B14: 0.25004801 | C14: 0.21 | D14: 0.150902 | E14: 0.143363 | F14: 0.129423 | G14: 0.112223 | H14: 0.107034 | I14: 0.123074
A16: Lower 48 Offshore | C16: 2.56 | D16: 2.11642 | E16: 2.157413 | F16: 2.089348 | G16: 2.419865 | H16: 2.459829 | I16: 2.948587
A17: Gulf | B17: 3.3515694 | C17: 2.52 | D17: 2.08797 | E17: 2.136284 | F17: 2.072056 | G17: 2.313114 | H17: 2.297252 | I17: 2.485032 | N17: Supply Curve Steps
A18: Shallow | B18: 1.9836395 | C18: 0.94 | D18: 0.609703 | E18: 0.420437 | F18: 0.490367 | G18: 0.567648 | H18: 0.577533 | I18: 0.526555 | N18: Prices | O18: Quantity
A19: Deep | B19: 1.3679301 | C19: 1.58 | D19: 1.478266 | E19: 1.715847 | F19: 1.581689 | G19: 1.745466 | H19: 1.719719 | I19: 1.958477 | M19: 1 | N19: 0.88 | O19: 0.4
A20: Pacific | B20: 0.056159936 | C20: 0.04 | D20: 0.02845 | E20: 0.02113 | F20: 0.017292 | G20: 0.044993 | H20: 0.119662 | I20: 0.154505 | M20: 2 | N20: 0.95 | O20: 0.7
A21: Atlantic | B21: 0 | C21: 0 | D21: 0 | E21: 0 | F21: 0 | G21: 0.061758 | H21: 0.042915 | I21: 0.30905 | M21: 3 | N21: 1 | O21: 1
M22: 4 | N22: 1.08 | O22: 1.05
A23: Supply Prices | M23: 5 | N23: 1.12 | O23: 1.1 | R23: * Based on estimated state production in the U.S. Crude Oil, NG, and NGL Reserves report found on
A24: (2012 dollars per million Btu) | M24: 6 | N24: 1.53 | O24: 1.2 | R24: Domestic NG CUM worksheet, the following assumptions were made:
A25: Henry Hub Spot Price | B25: 8.6000004 | C25: 4.39 | D25: 3.743775 | E25: 4.376477 | F25: 5.233528 | G25: 6.034758 | H25: 6.924771 | I25: 7.652016 | S25: R4 prices allotted as 33% of Rocky Mountain and 67% of Midcontinent
A26: Lower 48 Average Price | B26: 7.2912626 | C26: 4.06 | D26: 3.451457 | E26: 4.244283 | F26: 4.905202 | G26: 5.631371 | H26: 6.350606 | I26: 7.263971 | J26: =1+(I26-H26)/H26 -> 1.1438233 | S26: R6 prices allotted as 26% of Northeast and 74% of Gulf Coast
B27: =B26/Conv!$J$5/1000000*Conv!$D$38 -> 6.9107826 | C27: =C26/Conv!$J$5/1000000*Conv!$D$43 -> 3.4975839 | D27: =D26/Conv!$J$5/1000000*Conv!$D$45 -> 2.8659904 | E27: =E26/Conv!$J$5/1000000*Conv!$D$45 -> 3.5243302 | F27: =F26/Conv!$J$5/1000000*Conv!$D$45 -> 4.0731383 | G27: =G26/Conv!$J$5/1000000*Conv!$D$45 -> 4.6761281 | H27: =H26/Conv!$J$5/1000000*Conv!$D$45 -> 5.2733601 | I27: =I26/Conv!$J$5/1000000*Conv!$D$45 -> 6.031792 | M27: Step 3 Price Starting Point: | P27: 1.1 | S27: R7 prices allotted as 25% of Southwest, 40% of Gulf Coast, 24% of Midcontinent, and 11% offshore
A28: (2012 dollars per thousand cubic feet) | P28: *10% above average price
A29: Lower 48 Average Price | B29: 7.5100002 | C29: 4.16 | D29: 3.527389 | E29: 4.337657 | F29: 5.013116 | G29: 5.755261 | H29: 6.490319 | I29: 7.423778
B30: =B29/Conv!$D$6/1000/Conv!$J$5/1000000*Conv!$D$38 -> 6.9648785 | C30: =C29/Conv!$D$6/1000/Conv!$J$5/1000000*Conv!$D$43 -> 3.5065864 | D30: =D29/Conv!$D$6/1000/Conv!$J$5/1000000*Conv!$D$45 -> 2.8659903 | E30: =E29/Conv!$D$6/1000/Conv!$J$5/1000000*Conv!$D$45 -> 3.52433 | F30: =F29/Conv!$D$6/1000/Conv!$J$5/1000000*Conv!$D$45 -> 4.0731379 | G30: =G29/Conv!$D$6/1000/Conv!$J$5/1000000*Conv!$D$45 -> 4.6761279 | H30: =H29/Conv!$D$6/1000/Conv!$J$5/1000000*Conv!$D$45 -> 5.2733598 | I30: =I29/Conv!$D$6/1000/Conv!$J$5/1000000*Conv!$D$45 -> 6.0317917
A31: Lower 48 Onshore Price | J31: Growth Rate: 2012-2040 | M31: 2005 | N31: 2010 | O31: 2015 | P31: 2020 | Q31: 2025 | R31: 2030 | S31: 2035 | T31: 2040 | U31: Growth 2040+
A32: Northeast | B32: 7.6983781 | C32: 4.59 | D32: 3.462149 | E32: 4.10648 | F32: 5.444122 | G32: 6.612253 | H32: 6.571887 | I32: 8.110544 | J32: 1.4 | L32: R1 | M32: =B32/Conv!$D$6/1000/Conv!$J$5/1000000*Conv!$D$38 -> 7.1395827 | N32: =C32/Conv!$D$6/1000/Conv!$J$5/1000000*Conv!$D$43 -> 3.8690461 | O32: =D32/Conv!$D$6/1000/Conv!$J$5/1000000*Conv!$D$45 -> 2.8129831 | P32: =E32/Conv!$D$6/1000/Conv!$J$5/1000000*Conv!$D$45 -> 3.3364996 | Q32: =F32/Conv!$D$6/1000/Conv!$J$5/1000000*Conv!$D$45 -> 4.4233287 | R32: =G32/Conv!$D$6/1000/Conv!$J$5/1000000*Conv!$D$45 -> 5.3724307 | S32: =H32/Conv!$D$6/1000/Conv!$J$5/1000000*Conv!$D$45 -> 5.3396335 | T32: =I32/Conv!$D$6/1000/Conv!$J$5/1000000*Conv!$D$45 -> 6.5897865 | U32: =1+(T32-S32)/S32 -> 1.2341271
A33: Gulf Coast | B33: 7.881938 | C33: 4.18 | D33: 3.516361 | E33: 4.144482 | F33: 4.981838 | G33: 5.780926 | H33: 6.654837 | I33: 7.406928 | J33: 1.4 | L33: R2 | M33: =B32/Conv!$D$6/1000/Conv!$J$5/1000000*Conv!$D$38 -> 7.1395827 | N33: =C32/Conv!$D$6/1000/Conv!$J$5/1000000*Conv!$D$43 -> 3.8690461 | O33: =D32/Conv!$D$6/1000/Conv!$J$5/1000000*Conv!$D$45 -> 2.8129831 | P33: =E32/Conv!$D$6/1000/Conv!$J$5/1000000*Conv!$D$45 -> 3.3364996 | Q33: =F32/Conv!$D$6/1000/Conv!$J$5/1000000*Conv!$D$45 -> 4.4233287 | R33: =G32/Conv!$D$6/1000/Conv!$J$5/1000000*Conv!$D$45 -> 5.3724307 | S33: =H32/Conv!$D$6/1000/Conv!$J$5/1000000*Conv!$D$45 -> 5.3396335 | T33: =I32/Conv!$D$6/1000/Conv!$J$5/1000000*Conv!$D$45 -> 6.5897865 | U33: =1+(T33-S33)/S33 -> 1.2341271
A34: Midcontinent | B34: 7.3497467 | C34: 3.85 | D34: 3.693374 | E34: 4.74555 | F34: 5.072756 | G34: 5.835664 | H34: 6.776257 | I34: 7.591363 | J34: 1.5 | L34: R3 | M34: =B32/Conv!$D$6/1000/Conv!$J$5/1000000*Conv!$D$38 -> 7.1395827 | N34: =C32/Conv!$D$6/1000/Conv!$J$5/1000000*Conv!$D$43 -> 3.8690461 | O34: =D32/Conv!$D$6/1000/Conv!$J$5/1000000*Conv!$D$45 -> 2.8129831 | P34: =E32/Conv!$D$6/1000/Conv!$J$5/1000000*Conv!$D$45 -> 3.3364996 | Q34: =F32/Conv!$D$6/1000/Conv!$J$5/1000000*Conv!$D$45 -> 4.4233287 | R34: =G32/Conv!$D$6/1000/Conv!$J$5/1000000*Conv!$D$45 -> 5.3724307 | S34: =H32/Conv!$D$6/1000/Conv!$J$5/1000000*Conv!$D$45 -> 5.3396335 | T34: =I32/Conv!$D$6/1000/Conv!$J$5/1000000*Conv!$D$45 -> 6.5897865 | U34: =1+(T34-S34)/S34 -> 1.2341271
A35: Southwest | B35: 7.4758234 | C35: 4.21 | D35: 3.797485 | E35: 4.900776 | F35: 5.25594 | G35: 5.816219 | H35: 6.761253 | I35: 7.014832 | J35: 1.5 | L35: R4 | M35: =(B34*0.67+B36*0.33)/Conv!$D$6/1000/Conv!$J$5/1000000*Conv!$D$38 -> 6.6324621 | N35: =(C34*0.67+C36*0.33)/Conv!$D$6/1000/Conv!$J$5/1000000*Conv!$D$43 -> 3.2285883 | O35: =(D34*0.67+D36*0.33)/Conv!$D$6/1000/Conv!$J$5/1000000*Conv!$D$45 -> 2.8317147 | P35: =(E34*0.67+E36*0.33)/Conv!$D$6/1000/Conv!$J$5/1000000*Conv!$D$45 -> 3.6307605 | Q35: =(F34*0.67+F36*0.33)/Conv!$D$6/1000/Conv!$J$5/1000000*Conv!$D$45 -> 3.9224538 | R35: =(G34*0.67+G36*0.33)/Conv!$D$6/1000/Conv!$J$5/1000000*Conv!$D$45 -> 4.4561491 | S35: =(H34*0.67+H36*0.33)/Conv!$D$6/1000/Conv!$J$5/1000000*Conv!$D$45 -> 5.2438224 | T35: =(I34*0.67+I36*0.33)/Conv!$D$6/1000/Conv!$J$5/1000000*Conv!$D$45 -> 5.9401603 | U35: =1+(T35-S35)/S35 -> 1.132792
A36: Rocky Mountain | B36: 6.7492008 | C36: 3.79 | D36: 3.062554 | E36: 3.906456 | F36: 4.330034 | G36: 4.771581 | H36: 5.799615 | I36: 6.741779 | J36: 1.6 | L36: R5 | M36: =B32/Conv!$D$6/1000/Conv!$J$5/1000000*Conv!$D$38 -> 7.1395827 | N36: =C32/Conv!$D$6/1000/Conv!$J$5/1000000*Conv!$D$43 -> 3.8690461 | O36: =D32/Conv!$D$6/1000/Conv!$J$5/1000000*Conv!$D$45 -> 2.8129831 | P36: =E32/Conv!$D$6/1000/Conv!$J$5/1000000*Conv!$D$45 -> 3.3364996 | Q36: =F32/Conv!$D$6/1000/Conv!$J$5/1000000*Conv!$D$45 -> 4.4233287 | R36: =G32/Conv!$D$6/1000/Conv!$J$5/1000000*Conv!$D$45 -> 5.3724307 | S36: =H32/Conv!$D$6/1000/Conv!$J$5/1000000*Conv!$D$45 -> 5.3396335 | T36: =I32/Conv!$D$6/1000/Conv!$J$5/1000000*Conv!$D$45 -> 6.5897865 | U36: =1+(T36-S36)/S36 -> 1.2341271
A37: West Coast | B37: 7.5527425 | C37: 4.33 | D37: 4.386786 | E37: 4.760738 | F37: 5.281815 | G37: 5.659292 | H37: 6.794529 | I37: 7.623652 | J37: 1 | L37: R6 | M37: =(B32*0.26+B33*0.74)/Conv!$D$6/1000/Conv!$J$5/1000000*Conv!$D$38 -> 7.2655573 | N37: =(C32*0.26+C33*0.74)/Conv!$D$6/1000/Conv!$J$5/1000000*Conv!$D$43 -> 3.6133013 | O37: =(D32*0.26+D33*0.74)/Conv!$D$6/1000/Conv!$J$5/1000000*Conv!$D$45 -> 2.8455779 | P37: =(E32*0.26+E33*0.74)/Conv!$D$6/1000/Conv!$J$5/1000000*Conv!$D$45 -> 3.3593482 | Q37: =(F32*0.26+F33*0.74)/Conv!$D$6/1000/Conv!$J$5/1000000*Conv!$D$45 -> 4.1453817 | R37: =(G32*0.26+G33*0.74)/Conv!$D$6/1000/Conv!$J$5/1000000*Conv!$D$45 -> 4.8725977 | S37: =(H32*0.26+H33*0.74)/Conv!$D$6/1000/Conv!$J$5/1000000*Conv!$D$45 -> 5.389507 | T37: =(I32*0.26+I33*0.74)/Conv!$D$6/1000/Conv!$J$5/1000000*Conv!$D$45 -> 6.1667394 | U37: =1+(T37-S37)/S37 -> 1.1442122
L38: R7 | M38: =(B33*0.4+B34*0.24+B35*0.25+B40*0.11)/Conv!$D$6/1000/Conv!$J$5/1000000*Conv!$D$38 -> 7.1082317 | N38: =(C33*0.4+C34*0.24+C35*0.25+C40*0.11)/Conv!$D$6/1000/Conv!$J$5/1000000*Conv!$D$43 -> 3.5325487 | O38: =(D33*0.4+D34*0.24+D35*0.25+D40*0.11)/Conv!$D$6/1000/Conv!$J$5/1000000*Conv!$D$45 -> 2.9916272 | P38: =(E33*0.4+E34*0.24+E35*0.25+E40*0.11)/Conv!$D$6/1000/Conv!$J$5/1000000*Conv!$D$45 -> 3.7279214 | Q38: =(F33*0.4+F34*0.24+F35*0.25+F40*0.11)/Conv!$D$6/1000/Conv!$J$5/1000000*Conv!$D$45 -> 4.1502662 | R38: =(G33*0.4+G34*0.24+G35*0.25+G40*0.11)/Conv!$D$6/1000/Conv!$J$5/1000000*Conv!$D$45 -> 4.733051 | S38: =(H33*0.4+H34*0.24+H35*0.25+H40*0.11)/Conv!$D$6/1000/Conv!$J$5/1000000*Conv!$D$45 -> 5.4771501 | T38: =(I33*0.4+I34*0.24+I35*0.25+I40*0.11)/Conv!$D$6/1000/Conv!$J$5/1000000*Conv!$D$45 -> 5.9943983 | U38: =1+(T38-S38)/S38 -> 1.0944375
A39: Lower 48 Offshore Price | L39: R8 | M39: =B36/Conv!$D$6/1000/Conv!$J$5/1000000*Conv!$D$38 -> 6.2593025 | N39: =C36/Conv!$D$6/1000/Conv!$J$5/1000000*Conv!$D$43 -> 3.1947025 | O39: =D36/Conv!$D$6/1000/Conv!$J$5/1000000*Conv!$D$45 -> 2.4883136 | P39: =E36/Conv!$D$6/1000/Conv!$J$5/1000000*Conv!$D$45 -> 3.1739808 | Q39: =F36/Conv!$D$6/1000/Conv!$J$5/1000000*Conv!$D$45 -> 3.5181364 | R39: =G36/Conv!$D$6/1000/Conv!$J$5/1000000*Conv!$D$45 -> 3.8768916 | S39: =H36/Conv!$D$6/1000/Conv!$J$5/1000000*Conv!$D$45 -> 4.7121654 | T39: =I36/Conv!$D$6/1000/Conv!$J$5/1000000*Conv!$D$45 -> 5.4776701 | U39: =1+(T39-S39)/S39 -> 1.1624529
A40: Gulf | B40: 7.9900274 | C40: 4.93 | D40: 3.997221 | E40: 5.148303 | F40: 5.307836 | G40: 5.984872 | H40: 6.93263 | I40: 7.630444 | L40: R9 | M40: =B37/Conv!$D$6/1000/Conv!$J$5/1000000*Conv!$D$38 -> 7.0045182 | N40: =C37/Conv!$D$6/1000/Conv!$J$5/1000000*Conv!$D$43 -> 3.6498844 | O40: =D37/Conv!$D$6/1000/Conv!$J$5/1000000*Conv!$D$45 -> 3.5642471 | P40: =E37/Conv!$D$6/1000/Conv!$J$5/1000000*Conv!$D$45 -> 3.8680817 | Q40: =F37/Conv!$D$6/1000/Conv!$J$5/1000000*Conv!$D$45 -> 4.2914548 | R40: =G37/Conv!$D$6/1000/Conv!$J$5/1000000*Conv!$D$45 -> 4.5981535 | S40: =H37/Conv!$D$6/1000/Conv!$J$5/1000000*Conv!$D$45 -> 5.5205293 | T40: =I37/Conv!$D$6/1000/Conv!$J$5/1000000*Conv!$D$45 -> 6.1941886 | U40: =1+(T40-S40)/S40 -> 1.122028
A41: Pacific | B41: 7.5570188 | C41: 4.52 | D41: 4.76031 | E41: 5.304164 | F41: 5.757464 | G41: 7.071461 | H41: 6.676446 | I41: 7.566227
A42: Atlantic | B42: 0 | C42: 4.25 | D42: 4.103883 | E42: 5.020764 | F42: 5.201926 | G42: 7.711931 | H42: 8.816 | I42: 8.718942 | L42: Henry Hub | M42: =B25/Conv!$D$6/1000/Conv!$J$5/1000000*Conv!$D$38 -> 7.9757597 | N42: =C25/Conv!$D$6/1000/Conv!$J$5/1000000*Conv!$D$43 -> 3.7004602 | O42: =D25/Conv!$D$6/1000/Conv!$J$5/1000000*Conv!$D$45 -> 3.0418031 | P42: =E25/Conv!$D$6/1000/Conv!$J$5/1000000*Conv!$D$45 -> 3.5558711 | Q42: =F25/Conv!$D$6/1000/Conv!$J$5/1000000*Conv!$D$45 -> 4.2522218 | R42: =G25/Conv!$D$6/1000/Conv!$J$5/1000000*Conv!$D$45 -> 4.9032182 | S42: =H25/Conv!$D$6/1000/Conv!$J$5/1000000*Conv!$D$45 -> 5.6263504 | T42: =I25/Conv!$D$6/1000/Conv!$J$5/1000000*Conv!$D$45 -> 6.2172342 | U42: =1+(T42-S42)/S42 -> 1.1050208
A44: 1/ Marketed production (wet) minus extraction losses.
A45: - - = Not applicable.
...

Sheet AEO NG Imports
A1: Natural Gas Imports and Exports, Reference case
A3: Volumes and Prices | B3: 2005 | C3: 2010 | D3: 2015 | E3: 2020 | F3: 2025 | G3: 2030 | H3: 2035 | I3: 2040
A5: Volumes (trillion cubic feet)
A6: Net Imports | B6: 3.5729237 | C6: 2.58 | D6: 1.084329 | E6: -1.926104 | F6: -3.410152 | G6: -4.937026 | H6: -5.531103 | I6: -5.798003
A7: Imports | B7: 4.3210435 | C7: 3.71 | D7: 3.108017 | E7: 2.335441 | F7: 1.988579 | G7: 1.964056 | H7: 2.004963 | I7: 2.22168
A8: Pipeline Imports from Canada | B8: 3.6804636 | C8: 3.25 | D8: 2.958251 | E8: 2.187141 | F8: 1.840279 | G8: 1.815756 | H8: 1.856663 | I8: 2.07338 | W8: 2005 | X8: 2010 | Y8: 2015 | AA8: 2005 | AB8: 2010 | AC8: 2015
A9: Pipeline Imports from Mexico | B9: 0.0093200002 | C9: 0.03 | D9: 0.002816 | E9: 0.0003 | F9: 0.0003 | G9: 0.0003 | H9: 0.0003 | I9: 0.0003 | U9: Canada | V9: Step 1 | W9: =W11*'Domestic NG Prices'!$O$19 -> 1424.2786 | X9: =X11*'Domestic NG Prices'!$O$19 -> 1082.5803 | AA9: =W9 -> 1424.2786 | AB9: =X9 -> 1082.5803
A10: Pipeline Imports from Bahamas | B10: 0 | C10: 0 | D10: 0 | E10: 0 | F10: 0 | G10: 0 | H10: 0 | I10: 0 | V10: Step 2 | W10: =W11*'Domestic NG Prices'!$O$20 -> 2492.4876 | X10: =X11*'Domestic NG Prices'!$O$20 -> 1894.5155 | AA10: =W10-W9 -> 1068.209 | AB10: =X10-X9 -> 811.93523
A11: Liquefied Natural Gas Imports 1/ | B11: 0.63126004 | C11: 0.43 | D11: 0.14695 | E11: 0.148 | F11: 0.148 | G11: 0.148 | H11: 0.148 | I11: 0.148 | V11: Step 3 | W11: =K17 -> 3560.6966 | X11: =L17 -> 2706.4508 | AA11: =W11-W10 -> 1068.209 | AB11: =X11-X10 -> 811.93523
A12: Exports | B12: 0.74812007 | C12: 1.14 | D12: 2.023689 | E12: 4.261545 | F12: 5.398732 | G12: 6.901082 | H12: 7.536067 | I12: 8.019683 | V12: Step 4 | W12: =W11*'Domestic NG Prices'!$O$22 -> 3738.7315 | X12: =X11*'Domestic NG Prices'!$O$22 -> 2841.7733 | AA12: =W12-W11 -> 178.03483 | AB12: =X12-X11 -> 135.32254
A13: Pipeline Exports to Canada | B13: 0.37822407 | C13: 0.74 | D13: 1.014307 | E13: 1.080964 | F13: 1.18302 | G13: 1.372742 | H13: 1.449109 | I13: 1.368091 | V13: Step 5 | W13: =W11*'Domestic NG Prices'!$O$23 -> 3916.7663 | X13: =X11*'Domestic NG Prices'!$O$23 -> 2977.0958 | AA13: =W13-W12 -> 178.03483 | AB13: =X13-X12 -> 135.32254
A14: Pipeline Exports to Mexico | B14: 0.30519602 | C14: 0.33 | D14: 0.901382 | E14: 1.102581 | F14: 1.497712 | G14: 2.01034 | H14: 2.568958 | I14: 3.133591 | V14: Step 6 | W14: =W11*'Domestic NG Prices'!$O$24 -> 4272.8359 | X14: =X11*'Domestic NG Prices'!$O$24 -> 3247.7409 | AA14: =W14-W13 -> 356.06966 | AB14: =X14-X13 -> 270.64508
A15: Liquefied Natural Gas Exports 2/ | B15: 0.0647 | C15: 0.06 | D15: 0.108 | E15: 2.078 | F15: 2.718 | G15: 3.518 | H15: 3.518 | I15: 3.518
A16: Net Imports | B16: =B7-B12 -> 3.5729234 | C16: 2.58 | D16: 1.084329 | E16: -1.926104 | F16: -3.410153 | G16: -4.937026 | H16: -5.531103 | I16: -5.798003 | K16: 2005 | L16: 2010 | M16: 2015 | N16: 2020 | O16: 2025 | P16: 2030 | Q16: 2035 | R16: 2040 | U16: LNG | V16: Step 1 | W16: =W18*'Domestic NG Prices'!$O$19 -> 244.36125 | X16: =X18*'Domestic NG Prices'!$O$19 -> 159.58355 | Y16: =Y18*'Domestic NG Prices'!$O$19 -> 16.799403 | AA16: =W16 -> 244.36125 | AB16: =X16 -> 159.58355 | AC16: =Y16 -> 16.799403
A17: Canada | B17: =B8-B13 -> 3.3022395 | C17: 2.51 | D17: 1.943944 | E17: 1.106177 | F17: 0.657259 | G17: 0.443014 | H17: 0.407555 | I17: 0.705289 | K17: =B17*1000000*Conv!$D$6*Conv!$J$5*1000000 -> 3560.6966 | L17: =C17*1000000*Conv!$D$6*Conv!$J$5*1000000 -> 2706.4508 | M17: =D17*1000000*Conv!$D$6*Conv!$J$5*1000000 -> 2096.0911 | N17: =E17*1000000*Conv!$D$6*Conv!$J$5*1000000 -> 1192.7544 | O17: =F17*1000000*Conv!$D$6*Conv!$J$5*1000000 -> 708.70084 | P17: =G17*1000000*Conv!$D$6*Conv!$J$5*1000000 -> 477.68748 | Q17: =H17*1000000*Conv!$D$6*Conv!$J$5*1000000 -> 439.4532 | R17: =I17*1000000*Conv!$D$6*Conv!$J$5*1000000 -> 760.49002 | V17: Step 2 | W17: =W18*'Domestic NG Prices'!$O$20 -> 427.63219 | X17: =X18*'Domestic NG Prices'!$O$20 -> 279.27121 | Y17: =Y18*'Domestic NG Prices'!$O$20 -> 29.398956 | AA17: =W17-W16 -> 183.27094 | AB17: =X17-X16 -> 119.68766 | AC17: =Y17-Y16 -> 12.599553
A18: Mexico | B18: =B9-B14 -> -0.29587602 | C18: -0.3 | D18: -0.898566 | E18: -1.102281 | F18: -1.497411 | G18: -2.01004 | H18: -2.568658 | I18: -3.133291 | K18: =B18*1000000*Conv!$D$6*Conv!$J$5*1000000 -> -319.03341 | L18: =C18*1000000*Conv!$D$6*Conv!$J$5*1000000 -> -323.48017 | M18: =D18*1000000*Conv!$D$6*Conv!$J$5*1000000 -> -968.89427 | N18: =E18*1000000*Conv!$D$6*Conv!$J$5*1000000 -> -1188.5535 | O18: =F18*1000000*Conv!$D$6*Conv!$J$5*1000000 -> -1614.6092 | P18: =G18*1000000*Conv!$D$6*Conv!$J$5*1000000 -> -2167.3603 | Q18: =H18*1000000*Conv!$D$6*Conv!$J$5*1000000 -> -2769.6998 | R18: =I18*1000000*Conv!$D$6*Conv!$J$5*1000000 -> -3378.525 | S18: =1+T18 -> 1.2198163 | T18: =AVERAGE((R18-Q18)/Q18) -> 0.21981634 | V18: Step 3 | W18: =K20 -> 610.90312 | X18: =L20 -> 398.95888 | Y18: =M20 -> 41.998509 | AA18: =W18-W17 -> 183.27094 | AB18: =X18-X17 -> 119.68766 | AC18: =Y18-Y17 -> 12.599553
A19: Bahamas | B19: 0 | C19: 0 | D19: 0 | E19: 0 | F19: 0 | G19: 0 | H19: 0 | I19: 0
A20: Liquefied Natural Gas | B20: =B11-B15 -> 0.56656004 | C20: 0.37 | D20: 0.03895 | E20: -1.93 | F20: -2.57 | G20: -3.37 | H20: -3.37 | I20: -3.37 | K20: =B20*1000000*Conv!$D$6*Conv!$J$5*1000000 -> 610.90312 | L20: =C20*1000000*Conv!$D$6*Conv!$J$5*1000000 -> 398.95888 | M20: =D20*1000000*Conv!$D$6*Conv!$J$5*1000000 -> 41.998509 | N20: =E20*1000000*Conv!$D$6*Conv!$J$5*1000000 -> -2081.0558 | O20: =F20*1000000*Conv!$D$6*Conv!$J$5*1000000 -> -2771.1468 | P20: =G20*1000000*Conv!$D$6*Conv!$J$5*1000000 -> -3633.7606 | Q20: =H20*1000000*Conv!$D$6*Conv!$J$5*1000000 -> -3633.7606 | R20: =I20*1000000*Conv!$D$6*Conv!$J$5*1000000 -> -3633.7606 | S20: =1+T20 -> 1 | T20: =AVERAGE((R20-Q20)/Q20) -> 0
A22: Border Prices
A23: (2012 dollars per thousand cubic feet)
A24: Average Import Price | B24: 7.7595983 | C24: 4.53 | D24: 4.023057 | E24: 5.404779 | F24: 5.894635 | G24: 6.625491 | H24: 7.327688 | I24: 7.948038
A25: Pipeline Import Prices | K25: 2005 | L25: 2010 | M25: 2015 | N25: 2020 | O25: 2025 | P25: 2030 | Q25: 2035 | R25: 2040 | S25: Growth 2040+
