Workbook
Name AnswerData: #REF!
Name AnswerData: #REF!
Name AnswerData: #REF!
Name AnswerData: #REF!
Name AnswerData: #REF!
Name BDSEFF: [1]TechInfo!$J$33
Name BFBEFF: [1]TechInfo!$J$32
Name BFCEFF: [1]TechInfo!$J$34
Name blah: #REF!
Name bprint: #REF!
Name bprint: #REF!
Name bprint: #REF!
Name bprint: #REF!
Name BSGEFF: [1]TechInfo!$J$35
Name BSOEFF: [1]TechInfo!$J$31
Name BST_AF: [1]CHPData!$B$40
Name BST2_INV: [1]CHPData!$C$66
Name BST3_INV: [1]CHPData!$D$66
Name CCT_AF: [1]CHPData!$B$81
Name CCT2_INV: [1]CHPData!$C$91
Name CCT3_INV: [1]CHPData!$D$91
Name CCT4_INV: [1]CHPData!$E$91
Name CCT5_INV: [1]CHPData!$F$91
Name CFBEFF: [1]TechInfo!$J$29
Name CMM_SUPPLY_CRV_TABLE: [2]cum2025curves!#REF!
Name CMM_SUPPLY_CRV_TABLE: [2]cum2025curves!#REF!
Name CMM_SUPPLY_CRV_TABLE: [2]cum2025curves!#REF!
Name CMM_SUPPLY_CRV_TABLE: [2]cum2025curves!#REF!
Name cprint: #REF!
Name cprint: #REF!
Name cprint: #REF!
Name cprint: #REF!
Name CPVEFF: [1]TechInfo!$J$27
Name CSOEFF: [1]TechInfo!$J$28
Name DSTEFF: [1]TechInfo!$J$37
Name exch_rate: #REF!
Name exch_rate: #REF!
Name exch_rate: #REF!
Name exch_rate: #REF!
Name exch_rate: #REF!
Name FCL_AF: [1]CHPData!$B$154
Name FCL2_INV: [1]CHPData!$C$163
Name FCL3_INV: [1]CHPData!$D$163
Name fitfile: [3]MODEL!$D$38
Name INF: [3]MODEL!$H$14
Name million_short_tons_to_short_ton: [4]Steps!$Y$5
Name MMBTU_to_PJ: [4]Steps!$Y$6
Name MT2_INV: [1]CHPData!$C$141
Name MT3_INV: [1]CHPData!$D$141
Name neb: #REF!
Name PPP: [3]MODEL!$D$12
Name PPPEX: [3]MODEL!$D$13
Name rail_coal: #REF!
Name rail_coal: #REF!
Name rail_coal: #REF!
Name rail_coal: #REF!
Name rail_coal: #REF!
Name REG1_AF: [1]CHPData!$B$107
Name REG1_INV: [1]CHPData!$B$117
Name REG2_AF: [1]CHPData!$C$107

Sheet UC_OIL
A3: Maximum trade of oil product
A4: ~UC_Sets: R_E: AllRegions
E5: ~UC_T: UC_RHSRTS~UP
A6: UC_N | B6: Pset_PN | C6: Pset_CI | D6: Cset_CN | E6: Year | F6: UC_FLO | G6: UC_RHSRTS~UP~0 | H6: R0 | I6: R1 | J6: R2 | K6: R3 | L6: R4 | M6: R5 | N6: R6 | O6: UC_Desc
A7: UC_TRADEOILR2 | B7: X* | C7: GSCR1,GSRR1,DSHR1,DSLR1,DSUR1,RFLR1 | D7: GSCR1,GSRR1,DSHR1,DSLR1,DSUR1,RFLR1 | E7: 2010 | F7: 1 | G7: 15 | J7: =#REF!*Conv!$C$46*Conv!$I$5*365*10^3 -> #REF! | K7: =#REF!*Conv!$C$46*Conv!$I$5*365*10^3 -> #REF! | L7: =#REF!*Conv!$C$46*Conv!$I$5*365*10^3 -> #REF! | M7: =#REF!*Conv!$C$46*Conv!$I$5*365*10^3 -> #REF! | N7: =#REF!*Conv!$C$46*Conv!$I$5*365*10^3 -> #REF!
B8: X* | C8: GSCR1,GSRR1,DSHR1,DSLR1,DSUR1,RFLR1 | D8: GSCR1,GSRR1,DSHR1,DSLR1,DSUR1,RFLR1 | E8: 2015 | F8: 1 | J8: =J7 -> #REF! | K8: =K7 -> #REF! | L8: =L7 -> #REF! | M8: =M7 -> #REF! | N8: =N7 -> #REF!
B9: X* | C9: GSCR1,GSRR1,DSHR1,DSLR1,DSUR1,RFLR1 | D9: GSCR1,GSRR1,DSHR1,DSLR1,DSUR1,RFLR1 | E9: 2020 | F9: 1 | J9: =J8 -> #REF! | K9: =K8 -> #REF! | L9: =L8 -> #REF! | M9: =M8 -> #REF! | N9: =N8 -> #REF!
B10: X* | C10: GSCR1,GSRR1,DSHR1,DSLR1,DSUR1,RFLR1 | D10: GSCR1,GSRR1,DSHR1,DSLR1,DSUR1,RFLR1 | E10: 2025 | F10: 1 | J10: =J9 -> #REF! | K10: =K9 -> #REF! | L10: =L9 -> #REF! | M10: =M9 -> #REF! | N10: =N9 -> #REF!
B11: X* | C11: GSCR1,GSRR1,DSHR1,DSLR1,DSUR1,RFLR1 | D11: GSCR1,GSRR1,DSHR1,DSLR1,DSUR1,RFLR1 | E11: 2030 | F11: 1 | J11: =J10 -> #REF! | K11: =K10 -> #REF! | L11: =L10 -> #REF! | M11: =M10 -> #REF! | N11: =N10 -> #REF!
B12: X* | C12: GSCR1,GSRR1,DSHR1,DSLR1,DSUR1,RFLR1 | D12: GSCR1,GSRR1,DSHR1,DSLR1,DSUR1,RFLR1 | E12: 2035 | F12: 1 | J12: =J11 -> #REF! | K12: =K11 -> #REF! | L12: =L11 -> #REF! | M12: =M11 -> #REF! | N12: =N11 -> #REF!
B13: X* | C13: GSCR1,GSRR1,DSHR1,DSLR1,DSUR1,RFLR1 | D13: GSCR1,GSRR1,DSHR1,DSLR1,DSUR1,RFLR1 | E13: 2040 | F13: 1 | J13: =J12 -> #REF! | K13: =K12 -> #REF! | L13: =L12 -> #REF! | M13: =M12 -> #REF! | N13: =N12 -> #REF!
B14: X* | C14: GSCR1,GSRR1,DSHR1,DSLR1,DSUR1,RFLR1 | D14: GSCR1,GSRR1,DSHR1,DSLR1,DSUR1,RFLR1 | E14: 2045 | F14: 1 | J14: =J13 -> #REF! | K14: =K13 -> #REF! | L14: =L13 -> #REF! | M14: =M13 -> #REF! | N14: =N13 -> #REF!
B15: X* | C15: GSCR1,GSRR1,DSHR1,DSLR1,DSUR1,RFLR1 | D15: GSCR1,GSRR1,DSHR1,DSLR1,DSUR1,RFLR1 | E15: 2050 | F15: 1 | J15: =J14 -> #REF! | K15: =K14 -> #REF! | L15: =L14 -> #REF! | M15: =M14 -> #REF! | N15: =N14 -> #REF!
B16: X* | C16: GSCR1,GSRR1,DSHR1,DSLR1,DSUR1,RFLR1 | D16: GSCR1,GSRR1,DSHR1,DSLR1,DSUR1,RFLR1 | E16: 2055 | F16: 1 | J16: =J15 -> #REF! | K16: =K15 -> #REF! | L16: =L15 -> #REF! | M16: =M15 -> #REF! | N16: =N15 -> #REF!

Sheet UC_OIL2
A2: Maximum capacity technology growth:
A3: ~UC_Sets: R_E: R1
A4: ~UC_Sets: T_SUC:
G5: ~UC_T
A6: UC_N | B6: Pset_PN | C6: Pset_CI | D6: Pset_CO | E6: UC_ATTR | F6: Year | G6: LimType | H6: UC_CAP~2010 | I6: UC_CAP~2015 | J6: UC_CAP~2020 | K6: UC_CAP~2025 | L6: UC_CAP~2030 | M6: UC_CAP~2035 | N6: UC_CAP~2040 | O6: UC_CAP~2045 | P6: UC_CAP~2050 | Q6: UC_CAP~2055 | R6: UC_CAP~RHS | S6: UC_RHSRTS | T6: UC_RHSRTS~0 | U6: UC_Desc
A7: UC_GrowthOfOILUP1 | B7: =TechData_R0!C9 -> MINOILD1 | E7: CAP, GROWTH | G7: UP | H7: =TechData_R0!J9 -> 1.005 | I7: =H7 -> 1.005 | J7: =I7 -> 1.005 | K7: =J7 -> 1.005 | L7: =K7 -> 1.005 | M7: =L7 -> 1.005 | N7: =M7 -> 1.005 | O7: =N7 -> 1.005 | P7: =O7 -> 1.005 | Q7: =P7 -> 1.005 | R7: =IF(TechData_R0!H9="",1,TechData_R0!H9) -> 1 | T7: 5
A8: UC_GrowthOfOILUP2 | B8: =TechData_R0!C10 -> MINOILD2 | E8: CAP, GROWTH | G8: UP | H8: =TechData_R0!J10 -> 1.005 | I8: =H8 -> 1.005 | J8: =I8 -> 1.005 | K8: =J8 -> 1.005 | L8: =K8 -> 1.005 | M8: =L8 -> 1.005 | N8: =M8 -> 1.005 | O8: =N8 -> 1.005 | P8: =O8 -> 1.005 | Q8: =P8 -> 1.005 | R8: =IF(TechData_R0!H10="",1,TechData_R0!H10) -> 1 | T8: 5
A9: UC_GrowthOfOILUP3 | B9: =TechData_R0!C11 -> MINOILD3 | E9: CAP, GROWTH | G9: UP | H9: =TechData_R0!J11 -> 1.005 | I9: =H9 -> 1.005 | J9: =I9 -> 1.005 | K9: =J9 -> 1.005 | L9: =K9 -> 1.005 | M9: =L9 -> 1.005 | N9: =M9 -> 1.005 | O9: =N9 -> 1.005 | P9: =O9 -> 1.005 | Q9: =P9 -> 1.005 | R9: =IF(TechData_R0!H11="",1,TechData_R0!H11) -> 1 | T9: 5
A10: UC_GrowthOfOILUP4 | B10: =TechData_R0!C12 -> MINOILD4 | E10: CAP, GROWTH | G10: UP | H10: =TechData_R0!J12 -> 1.005 | I10: =H10 -> 1.005 | J10: =I10 -> 1.005 | K10: =J10 -> 1.005 | L10: =K10 -> 1.005 | M10: =L10 -> 1.005 | N10: =M10 -> 1.005 | O10: =N10 -> 1.005 | P10: =O10 -> 1.005 | Q10: =P10 -> 1.005 | R10: =IF(TechData_R0!H12="",1,TechData_R0!H12) -> 0.50462412 | T10: 5
A11: UC_GrowthOfOILUP5 | B11: =TechData_R0!C13 -> MINOILD5 | E11: CAP, GROWTH | G11: UP | H11: =TechData_R0!J13 -> 1.005 | I11: =H11 -> 1.005 | J11: =I11 -> 1.005 | K11: =J11 -> 1.005 | L11: =K11 -> 1.005 | M11: =L11 -> 1.005 | N11: =M11 -> 1.005 | O11: =N11 -> 1.005 | P11: =O11 -> 1.005 | Q11: =P11 -> 1.005 | R11: =IF(TechData_R0!H13="",1,TechData_R0!H13) -> 0.75693618 | T11: 5
A12: UC_GrowthOfOILUP6 | B12: =TechData_R0!C32 -> IMPOILHH13 | E12: CAP, GROWTH | G12: UP | H12: =TechData_R0!J32 -> 1.005 | I12: =H12 -> 1.005 | J12: =I12 -> 1.005 | K12: =J12 -> 1.005 | L12: =K12 -> 1.005 | M12: =L12 -> 1.005 | N12: =M12 -> 1.005 | O12: =N12 -> 1.005 | P12: =O12 -> 1.005 | Q12: =P12 -> 1.005 | R12: =IF(TechData_R0!H32="",1,TechData_R0!H32) -> 1 | T12: 5
A13: UC_GrowthOfOILUP7 | B13: =TechData_R0!C33 -> IMPOILHH11 | E13: CAP, GROWTH | G13: UP | H13: =TechData_R0!J33 -> 1.005 | I13: =H13 -> 1.005 | J13: =I13 -> 1.005 | K13: =J13 -> 1.005 | L13: =K13 -> 1.005 | M13: =L13 -> 1.005 | N13: =M13 -> 1.005 | O13: =N13 -> 1.005 | P13: =O13 -> 1.005 | Q13: =P13 -> 1.005 | R13: =IF(TechData_R0!H33="",1,TechData_R0!H33) -> 1 | T13: 5
A14: UC_GrowthOfOILUP8 | B14: =TechData_R0!C34 -> IMPOILHH12 | E14: CAP, GROWTH | G14: UP | H14: =TechData_R0!J34 -> 1.005 | I14: =H14 -> 1.005 | J14: =I14 -> 1.005 | K14: =J14 -> 1.005 | L14: =K14 -> 1.005 | M14: =L14 -> 1.005 | N14: =M14 -> 1.005 | O14: =N14 -> 1.005 | P14: =O14 -> 1.005 | Q14: =P14 -> 1.005 | R14: =IF(TechData_R0!H34="",1,TechData_R0!H34) -> 1 | T14: 5
A15: UC_GrowthOfOILUP9 | B15: =TechData_R0!C35 -> IMPOILHH14 | E15: CAP, GROWTH | G15: UP | H15: =TechData_R0!J35 -> 1.005 | I15: =H15 -> 1.005 | J15: =I15 -> 1.005 | K15: =J15 -> 1.005 | L15: =K15 -> 1.005 | M15: =L15 -> 1.005 | N15: =M15 -> 1.005 | O15: =N15 -> 1.005 | P15: =O15 -> 1.005 | Q15: =P15 -> 1.005 | R15: =IF(TechData_R0!H35="",1,TechData_R0!H35) -> 1 | T15: 5
A16: UC_GrowthOfOILUP10 | B16: =TechData_R0!C36 -> IMPOILHH15 | E16: CAP, GROWTH | G16: UP | H16: =TechData_R0!J36 -> 1.005 | I16: =H16 -> 1.005 | J16: =I16 -> 1.005 | K16: =J16 -> 1.005 | L16: =K16 -> 1.005 | M16: =L16 -> 1.005 | N16: =M16 -> 1.005 | O16: =N16 -> 1.005 | P16: =O16 -> 1.005 | Q16: =P16 -> 1.005 | R16: =IF(TechData_R0!H36="",1,TechData_R0!H36) -> 1 | T16: 5
A17: UC_GrowthOfOILUP11 | B17: =TechData_R0!C37 -> IMPOILHL13 | E17: CAP, GROWTH | G17: UP | H17: =TechData_R0!J37 -> 1.005 | I17: =H17 -> 1.005 | J17: =I17 -> 1.005 | K17: =J17 -> 1.005 | L17: =K17 -> 1.005 | M17: =L17 -> 1.005 | N17: =M17 -> 1.005 | O17: =N17 -> 1.005 | P17: =O17 -> 1.005 | Q17: =P17 -> 1.005 | R17: =IF(TechData_R0!H37="",1,TechData_R0!H37) -> 1 | T17: 5
A18: UC_GrowthOfOILUP12 | B18: =TechData_R0!C38 -> IMPOILHL11 | E18: CAP, GROWTH | G18: UP | H18: =TechData_R0!J38 -> 1.005 | I18: =H18 -> 1.005 | J18: =I18 -> 1.005 | K18: =J18 -> 1.005 | L18: =K18 -> 1.005 | M18: =L18 -> 1.005 | N18: =M18 -> 1.005 | O18: =N18 -> 1.005 | P18: =O18 -> 1.005 | Q18: =P18 -> 1.005 | R18: =IF(TechData_R0!H38="",1,TechData_R0!H38) -> 1 | T18: 5
A19: UC_GrowthOfOILUP13 | B19: =TechData_R0!C39 -> IMPOILHL12 | E19: CAP, GROWTH | G19: UP | H19: =TechData_R0!J39 -> 1.005 | I19: =H19 -> 1.005 | J19: =I19 -> 1.005 | K19: =J19 -> 1.005 | L19: =K19 -> 1.005 | M19: =L19 -> 1.005 | N19: =M19 -> 1.005 | O19: =N19 -> 1.005 | P19: =O19 -> 1.005 | Q19: =P19 -> 1.005 | R19: =IF(TechData_R0!H39="",1,TechData_R0!H39) -> 1 | T19: 5
A20: UC_GrowthOfOILUP14 | B20: =TechData_R0!C40 -> IMPOILHL14 | E20: CAP, GROWTH | G20: UP | H20: =TechData_R0!J40 -> 1.005 | I20: =H20 -> 1.005 | J20: =I20 -> 1.005 | K20: =J20 -> 1.005 | L20: =K20 -> 1.005 | M20: =L20 -> 1.005 | N20: =M20 -> 1.005 | O20: =N20 -> 1.005 | P20: =O20 -> 1.005 | Q20: =P20 -> 1.005 | R20: =IF(TechData_R0!H40="",1,TechData_R0!H40) -> 1 | T20: 5
A21: UC_GrowthOfOILUP15 | B21: =TechData_R0!C41 -> IMPOILHL15 | E21: CAP, GROWTH | G21: UP | H21: =TechData_R0!J41 -> 1.005 | I21: =H21 -> 1.005 | J21: =I21 -> 1.005 | K21: =J21 -> 1.005 | L21: =K21 -> 1.005 | M21: =L21 -> 1.005 | N21: =M21 -> 1.005 | O21: =N21 -> 1.005 | P21: =O21 -> 1.005 | Q21: =P21 -> 1.005 | R21: =IF(TechData_R0!H41="",1,TechData_R0!H41) -> 1 | T21: 5
A22: UC_GrowthOfOILUP16 | B22: =TechData_R0!C42 -> IMPOILHV13 | E22: CAP, GROWTH | G22: UP | H22: =TechData_R0!J42 -> 1.005 | I22: =H22 -> 1.005 | J22: =I22 -> 1.005 | K22: =J22 -> 1.005 | L22: =K22 -> 1.005 | M22: =L22 -> 1.005 | N22: =M22 -> 1.005 | O22: =N22 -> 1.005 | P22: =O22 -> 1.005 | Q22: =P22 -> 1.005 | R22: =IF(TechData_R0!H42="",1,TechData_R0!H42) -> 1 | T22: 5
A23: UC_GrowthOfOILUP17 | B23: =TechData_R0!C43 -> IMPOILHV11 | E23: CAP, GROWTH | G23: UP | H23: =TechData_R0!J43 -> 1.005 | I23: =H23 -> 1.005 | J23: =I23 -> 1.005 | K23: =J23 -> 1.005 | L23: =K23 -> 1.005 | M23: =L23 -> 1.005 | N23: =M23 -> 1.005 | O23: =N23 -> 1.005 | P23: =O23 -> 1.005 | Q23: =P23 -> 1.005 | R23: =IF(TechData_R0!H43="",1,TechData_R0!H43) -> 1 | T23: 5
... A36: UC_GrowthOfOILUP30 | B36: =TechData_R0!C56 -> IMPOILMH15 | E36: CAP, GROWTH | G36: UP | H36: =TechData_R0!J56 -> 1.005 | I36: =H36 -> 1.005 | J36: =I36 -> 1.005 | K36: =J36 -> 1.005 | L36: =K36 -> 1.005 | M36: =L36 -> 1.005 | N36: =M36 -> 1.005 | O36: =N36 -> 1.005 | P36: =O36 -> 1.005 | Q36: =P36 -> 1.005 | R36: =IF(TechData_R0!H56="",1,TechData_R0!H56) -> 1 | T36: 5
A37: UC_GrowthOfOILUP31 | B37: =TechData_R0!C58 -> IMPOILHH23 | E37: CAP, GROWTH | G37: UP | H37: =TechData_R0!J58 -> 1.005 | I37: =H37 -> 1.005 | J37: =I37 -> 1.005 | K37: =J37 -> 1.005 | L37: =K37 -> 1.005 | M37: =L37 -> 1.005 | N37: =M37 -> 1.005 | O37: =N37 -> 1.005 | P37: =O37 -> 1.005 | Q37: =P37 -> 1.005 | R37: =IF(TechData_R0!H57="",1,TechData_R0!H57) -> 1 | T37: 5
A38: UC_GrowthOfOILUP32 | B38: =TechData_R0!C59 -> IMPOILHH21 | E38: CAP, GROWTH | G38: UP | H38: =TechData_R0!J59 -> 1.005 | I38: =H38 -> 1.005 | J38: =I38 -> 1.005 | K38: =J38 -> 1.005 | L38: =K38 -> 1.005 | M38: =L38 -> 1.005 | N38: =M38 -> 1.005 | O38: =N38 -> 1.005 | P38: =O38 -> 1.005 | Q38: =P38 -> 1.005 | R38: =IF(TechData_R0!H58="",1,TechData_R0!H58) -> 1 | T38: 5
A39: UC_GrowthOfOILUP33 | B39: =TechData_R0!C60 -> IMPOILHH22 | E39: CAP, GROWTH | G39: UP | H39: =TechData_R0!J60 -> 1.005 | I39: =H39 -> 1.005 | J39: =I39 -> 1.005 | K39: =J39 -> 1.005 | L39: =K39 -> 1.005 | M39: =L39 -> 1.005 | N39: =M39 -> 1.005 | O39: =N39 -> 1.005 | P39: =O39 -> 1.005 | Q39: =P39 -> 1.005 | R39: =IF(TechData_R0!H59="",1,TechData_R0!H59) -> 1 | T39: 5
A40: UC_GrowthOfOILUP34 | B40: =TechData_R0!C61 -> IMPOILHH24 | E40: CAP, GROWTH | G40: UP | H40: =TechData_R0!J61 -> 1.005 | I40: =H40 -> 1.005 | J40: =I40 -> 1.005 | K40: =J40 -> 1.005 | L40: =K40 -> 1.005 | M40: =L40 -> 1.005 | N40: =M40 -> 1.005 | O40: =N40 -> 1.005 | P40: =O40 -> 1.005 | Q40: =P40 -> 1.005 | R40: =IF(TechData_R0!H60="",1,TechData_R0!H60) -> 1 | T40: 5
A41: UC_GrowthOfOILUP35 | B41: =TechData_R0!C62 -> IMPOILHH25 | E41: CAP, GROWTH | G41: UP | H41: =TechData_R0!J62 -> 1.005 | I41: =H41 -> 1.005 | J41: =I41 -> 1.005 | K41: =J41 -> 1.005 | L41: =K41 -> 1.005 | M41: =L41 -> 1.005 | N41: =M41 -> 1.005 | O41: =N41 -> 1.005 | P41: =O41 -> 1.005 | Q41: =P41 -> 1.005 | R41: =IF(TechData_R0!H61="",1,TechData_R0!H61) -> 1 | T41: 5
A42: UC_GrowthOfOILUP36 | B42: =TechData_R0!C63 -> IMPOILHL23 | E42: CAP, GROWTH | G42: UP | H42: =TechData_R0!J63 -> 1.005 | I42: =H42 -> 1.005 | J42: =I42 -> 1.005 | K42: =J42 -> 1.005 | L42: =K42 -> 1.005 | M42: =L42 -> 1.005 | N42: =M42 -> 1.005 | O42: =N42 -> 1.005 | P42: =O42 -> 1.005 | Q42: =P42 -> 1.005 | R42: =IF(TechData_R0!H62="",1,TechData_R0!H62) -> 1 | T42: 5
A43: UC_GrowthOfOILUP37 | B43: =TechData_R0!C64 -> IMPOILHL21 | E43: CAP, GROWTH | G43: UP | H43: =TechData_R0!J64 -> 1.005 | I43: =H43 -> 1.005 | J43: =I43 -> 1.005 | K43: =J43 -> 1.005 | L43: =K43 -> 1.005 | M43: =L43 -> 1.005 | N43: =M43 -> 1.005 | O43: =N43 -> 1.005 | P43: =O43 -> 1.005 | Q43: =P43 -> 1.005 | R43: =IF(TechData_R0!H63="",1,TechData_R0!H63) -> 1 | T43: 5
A44: UC_GrowthOfOILUP38 | B44: =TechData_R0!C65 -> IMPOILHL22 | E44: CAP, GROWTH | G44: UP | H44: =TechData_R0!J65 -> 1.005 | I44: =H44 -> 1.005 | J44: =I44 -> 1.005 | K44: =J44 -> 1.005 | L44: =K44 -> 1.005 | M44: =L44 -> 1.005 | N44: =M44 -> 1.005 | O44: =N44 -> 1.005 | P44: =O44 -> 1.005 | Q44: =P44 -> 1.005 | R44: =IF(TechData_R0!H64="",1,TechData_R0!H64) -> 1 | T44: 5
A45: UC_GrowthOfOILUP39 | B45: =TechData_R0!C66 -> IMPOILHL24 | E45: CAP, GROWTH | G45: UP | H45: =TechData_R0!J66 -> 1.005 | I45: =H45 -> 1.005 | J45: =I45 -> 1.005 | K45: =J45 -> 1.005 | L45: =K45 -> 1.005 | M45: =L45 -> 1.005 | N45: =M45 -> 1.005 | O45: =N45 -> 1.005 | P45: =O45 -> 1.005 | Q45: =P45 -> 1.005 | R45: =IF(TechData_R0!H65="",1,TechData_R0!H65) -> 1 | T45: 5
A46: UC_GrowthOfOILUP40 | B46: =TechData_R0!C67 -> IMPOILHL25 | E46: CAP, GROWTH | G46: UP | H46: =TechData_R0!J67 -> 1.005 | I46: =H46 -> 1.005 | J46: =I46 -> 1.005 | K46: =J46 -> 1.005 | L46: =K46 -> 1.005 | M46: =L46 -> 1.005 | N46: =M46 -> 1.005 | O46: =N46 -> 1.005 | P46: =O46 -> 1.005 | Q46: =P46 -> 1.005 | R46: =IF(TechData_R0!H66="",1,TechData_R0!H66) -> 1 | T46: 5
A47: UC_GrowthOfOILUP41 | B47: =TechData_R0!C68 -> IMPOILHV23 | E47: CAP, GROWTH | G47: UP | H47: =TechData_R0!J68 -> 1.005 | I47: =H47 -> 1.005 | J47: =I47 -> 1.005 | K47: =J47 -> 1.005 | L47: =K47 -> 1.005 | M47: =L47 -> 1.005 | N47: =M47 -> 1.005 | O47: =N47 -> 1.005 | P47: =O47 -> 1.005 | Q47: =P47 -> 1.005 | R47: =IF(TechData_R0!H67="",1,TechData_R0!H67) -> 1 | T47: 5
A48: UC_GrowthOfOILUP42 | B48: =TechData_R0!C69 -> IMPOILHV21 | E48: CAP, GROWTH | G48: UP | H48: =TechData_R0!J69 -> 1.005 | I48: =H48 -> 1.005 | J48: =I48 -> 1.005 | K48: =J48 -> 1.005 | L48: =K48 -> 1.005 | M48: =L48 -> 1.005 | N48: =M48 -> 1.005 | O48: =N48 -> 1.005 | P48: =O48 -> 1.005 | Q48: =P48 -> 1.005 | R48: =IF(TechData_R0!H68="",1,TechData_R0!H68) -> 1 | T48: 5
... A61: UC_GrowthOfOILUP55 | B61: =TechData_R0!C82 -> IMPOILMH25 | E61: CAP, GROWTH | G61: UP | H61: =TechData_R0!J82 -> 1.005 | I61: =H61 -> 1.005 | J61: =I61 -> 1.005 | K61: =J61 -> 1.005 | L61: =K61 -> 1.005 | M61: =L61 -> 1.005 | N61: =M61 -> 1.005 | O61: =N61 -> 1.005 | P61: =O61 -> 1.005 | Q61: =P61 -> 1.005 | R61: =IF(TechData_R0!H81="",1,TechData_R0!H81) -> 1 | T61: 5
A62: UC_GrowthOfOILUP56 | B62: =TechData_R0!C84 -> IMPOILHH33 | E62: CAP, GROWTH | G62: UP | H62: =TechData_R0!J84 -> 1.005 | I62: =H62 -> 1.005 | J62: =I62 -> 1.005 | K62: =J62 -> 1.005 | L62: =K62 -> 1.005 | M62: =L62 -> 1.005 | N62: =M62 -> 1.005 | O62: =N62 -> 1.005 | P62: =O62 -> 1.005 | Q62: =P62 -> 1.005 | R62: =IF(TechData_R0!H82="",1,TechData_R0!H82) -> 1 | T62: 5
A63: UC_GrowthOfOILUP57 | B63: =TechData_R0!C85 -> IMPOILHH31 | E63: CAP, GROWTH | G63: UP | H63: =TechData_R0!J85 -> 1.005 | I63: =H63 -> 1.005 | J63: =I63 -> 1.005 | K63: =J63 -> 1.005 | L63: =K63 -> 1.005 | M63: =L63 -> 1.005 | N63: =M63 -> 1.005 | O63: =N63 -> 1.005 | P63: =O63 -> 1.005 | Q63: =P63 -> 1.005 | R63: =IF(TechData_R0!H83="",1,TechData_R0!H83) -> 1 | T63: 5
A64: UC_GrowthOfOILUP58 | B64: =TechData_R0!C86 -> IMPOILHH32 | E64: CAP, GROWTH | G64: UP | H64: =TechData_R0!J86 -> 1.005 | I64: =H64 -> 1.005 | J64: =I64 -> 1.005 | K64: =J64 -> 1.005 | L64: =K64 -> 1.005 | M64: =L64 -> 1.005 | N64: =M64 -> 1.005 | O64: =N64 -> 1.005 | P64: =O64 -> 1.005 | Q64: =P64 -> 1.005 | R64: =IF(TechData_R0!H84="",1,TechData_R0!H84) -> 1 | T64: 5
A65: UC_GrowthOfOILUP59 | B65: =TechData_R0!C87 -> IMPOILHH34 | E65: CAP, GROWTH | G65: UP | H65: =TechData_R0!J87 -> 1.005 | I65: =H65 -> 1.005 | J65: =I65 -> 1.005 | K65: =J65 -> 1.005 | L65: =K65 -> 1.005 | M65: =L65 -> 1.005 | N65: =M65 -> 1.005 | O65: =N65 -> 1.005 | P65: =O65 -> 1.005 | Q65: =P65 -> 1.005 | R65: =IF(TechData_R0!H85="",1,TechData_R0!H85) -> 1 | T65: 5
...

Sheet UC_OIL3
A2: Maximum import PADD
A3: ~UC_Sets: R_S: AllRegions
F4: ~UC_T:UC_RHST
A5: UC_N | B5: Pset_PN | C5: Pset_CI | D5: Cset_CN | E5: UC_ACT | F5: UC_RHST~UP~0 | G5: UC_RHST~UP~2010 | H5: UC_RHST~UP~2015 | I5: UC_RHST~UP~2020 | J5: UC_RHST~UP~2025 | K5: UC_RHST~UP~2030 | L5: UC_RHST~UP~2035 | M5: UC_RHST~UP~2040 | N5: UC_RHST~UP~2045 | O5: UC_RHST~UP~2050 | P5: UC_RHST~UP~2055 | Q5: UC_Desc
A6: UC_IMPPADDUP1 | B6: IMPJTFP13 | E6: 1 | F6: 1 | G6: =IF(TechData_R0!W198="","",TechData_R0!W198) -> 218348.9 | H6: =IF(TechData_R0!X198="","",TechData_R0!X198) -> 218348.9 | I6: =IF(TechData_R0!Y198="","",TechData_R0!Y198) -> 218348.9 | J6: =IF(TechData_R0!Z198="","",TechData_R0!Z198) | K6: =IF(TechData_R0!AA198="","",TechData_R0!AA198) | L6: =IF(TechData_R0!AB198="","",TechData_R0!AB198) | M6: =IF(TechData_R0!AC198="","",TechData_R0!AC198) | N6: =IF(TechData_R0!AD198="","",TechData_R0!AD198) | ... P6: =IF(TechData_R0!AF198="","",TechData_R0!AF198)
A7: UC_IMPPADDUP2 | B7: IMPJTFP11 | E7: 1 | F7: 1 | G7: =IF(TechData_R0!W199="","",TechData_R0!W199) -> 1746791.2 | H7: =IF(TechData_R0!X199="","",TechData_R0!X199) -> 1746791.2 | I7: =IF(TechData_R0!Y199="","",TechData_R0!Y199) -> 1746791.2 | J7: =IF(TechData_R0!Z199="","",TechData_R0!Z199) | K7: =IF(TechData_R0!AA199="","",TechData_R0!AA199) | L7: =IF(TechData_R0!AB199="","",TechData_R0!AB199) | M7: =IF(TechData_R0!AC199="","",TechData_R0!AC199) | N7: =IF(TechData_R0!AD199="","",TechData_R0!AD199) | ... P7: =IF(TechData_R0!AF199="","",TechData_R0!AF199)
A8: UC_IMPPADDUP3 | B8: IMPJTFP12 | E8: 1 | F8: 1 | G8: =IF(TechData_R0!W200="","",TechData_R0!W200) -> 218348.9 | H8: =IF(TechData_R0!X200="","",TechData_R0!X200) -> 218348.9 | I8: =IF(TechData_R0!Y200="","",TechData_R0!Y200) -> 218348.9 | J8: =IF(TechData_R0!Z200="","",TechData_R0!Z200) | K8: =IF(TechData_R0!AA200="","",TechData_R0!AA200) | L8: =IF(TechData_R0!AB200="","",TechData_R0!AB200) | M8: =IF(TechData_R0!AC200="","",TechData_R0!AC200) | N8: =IF(TechData_R0!AD200="","",TechData_R0!AD200) | ... P8: =IF(TechData_R0!AF200="","",TechData_R0!AF200)
A9: UC_IMPPADDUP4 | B9: IMPJTFP14 | E9: 1 | F9: 1 | G9: =IF(TechData_R0!W201="","",TechData_R0!W201) -> 436697.79 | H9: =IF(TechData_R0!X201="","",TechData_R0!X201) -> 436697.79 | I9: =IF(TechData_R0!Y201="","",TechData_R0!Y201) -> 436697.79 | J9: =IF(TechData_R0!Z201="","",TechData_R0!Z201) | K9: =IF(TechData_R0!AA201="","",TechData_R0!AA201) | L9: =IF(TechData_R0!AB201="","",TechData_R0!AB201) | M9: =IF(TechData_R0!AC201="","",TechData_R0!AC201) | N9: =IF(TechData_R0!AD201="","",TechData_R0!AD201) | ... P9: =IF(TechData_R0!AF201="","",TechData_R0!AF201)
A10: UC_IMPPADDUP5 | B10: IMPJTFP15 | E10: 1 | F10: 1 | G10: =IF(TechData_R0!W202="","",TechData_R0!W202) -> 1746791.2 | H10: =IF(TechData_R0!X202="","",TechData_R0!X202) -> 1746791.2 | I10: =IF(TechData_R0!Y202="","",TechData_R0!Y202) -> 1746791.2 | J10: =IF(TechData_R0!Z202="","",TechData_R0!Z202) | K10: =IF(TechData_R0!AA202="","",TechData_R0!AA202) | L10: =IF(TechData_R0!AB202="","",TechData_R0!AB202) | M10: =IF(TechData_R0!AC202="","",TechData_R0!AC202) | N10: =IF(TechData_R0!AD202="","",TechData_R0!AD202) | ... P10: =IF(TechData_R0!AF202="","",TechData_R0!AF202)
A11: UC_IMPPADDUP6 | B11: IMPDSHP13 | E11: 1 | F11: 1 | G11: =IF(TechData_R0!W203="","",TechData_R0!W203) -> 224317.87 | H11: =IF(TechData_R0!X203="","",TechData_R0!X203) -> 224317.87 | I11: =IF(TechData_R0!Y203="","",TechData_R0!Y203) -> 224317.87 | J11: =IF(TechData_R0!Z203="","",TechData_R0!Z203) | K11: =IF(TechData_R0!AA203="","",TechData_R0!AA203) | L11: =IF(TechData_R0!AB203="","",TechData_R0!AB203) | M11: =IF(TechData_R0!AC203="","",TechData_R0!AC203) | N11: =IF(TechData_R0!AD203="","",TechData_R0!AD203) | ... P11: =IF(TechData_R0!AF203="","",TechData_R0!AF203)
A12: UC_IMPPADDUP7 | B12: IMPDSHP11 | E12: 1 | F12: 1 | G12: =IF(TechData_R0!W204="","",TechData_R0!W204) -> 1794543 | H12: =IF(TechData_R0!X204="","",TechData_R0!X204) -> 1794543 | I12: =IF(TechData_R0!Y204="","",TechData_R0!Y204) -> 1794543 | J12: =IF(TechData_R0!Z204="","",TechData_R0!Z204) | K12: =IF(TechData_R0!AA204="","",TechData_R0!AA204) | L12: =IF(TechData_R0!AB204="","",TechData_R0!AB204) | M12: =IF(TechData_R0!AC204="","",TechData_R0!AC204) | N12: =IF(TechData_R0!AD204="","",TechData_R0!AD204) | ... P12: =IF(TechData_R0!AF204="","",TechData_R0!AF204)
A13: UC_IMPPADDUP8 | B13: IMPDSHP12 | E13: 1 | F13: 1 | G13: =IF(TechData_R0!W205="","",TechData_R0!W205) -> 224317.87 | H13: =IF(TechData_R0!X205="","",TechData_R0!X205) -> 224317.87 | I13: =IF(TechData_R0!Y205="","",TechData_R0!Y205) -> 224317.87 | J13: =IF(TechData_R0!Z205="","",TechData_R0!Z205) | K13: =IF(TechData_R0!AA205="","",TechData_R0!AA205) | L13: =IF(TechData_R0!AB205="","",TechData_R0!AB205) | M13: =IF(TechData_R0!AC205="","",TechData_R0!AC205) | N13: =IF(TechData_R0!AD205="","",TechData_R0!AD205) | ... P13: =IF(TechData_R0!AF205="","",TechData_R0!AF205)
A14: UC_IMPPADDUP9 | B14: IMPDSHP14 | E14: 1 | F14: 1 | G14: =IF(TechData_R0!W206="","",TechData_R0!W206) -> 448635.74 | H14: =IF(TechData_R0!X206="","",TechData_R0!X206) -> 448635.74 | I14: =IF(TechData_R0!Y206="","",TechData_R0!Y206) -> 448635.74 | J14: =IF(TechData_R0!Z206="","",TechData_R0!Z206) | K14: =IF(TechData_R0!AA206="","",TechData_R0!AA206) | L14: =IF(TechData_R0!AB206="","",TechData_R0!AB206) | M14: =IF(TechData_R0!AC206="","",TechData_R0!AC206) | N14: =IF(TechData_R0!AD206="","",TechData_R0!AD206) | ... P14: =IF(TechData_R0!AF206="","",TechData_R0!AF206)
A15: UC_IMPPADDUP10 | B15: IMPDSHP15 | E15: 1 | F15: 1 | G15: =IF(TechData_R0!W207="","",TechData_R0!W207) -> 1794543 | H15: =IF(TechData_R0!X207="","",TechData_R0!X207) -> 1794543 | I15: =IF(TechData_R0!Y207="","",TechData_R0!Y207) -> 1794543 | J15: =IF(TechData_R0!Z207="","",TechData_R0!Z207) | K15: =IF(TechData_R0!AA207="","",TechData_R0!AA207) | L15: =IF(TechData_R0!AB207="","",TechData_R0!AB207) | M15: =IF(TechData_R0!AC207="","",TechData_R0!AC207) | N15: =IF(TechData_R0!AD207="","",TechData_R0!AD207) | ... P15: =IF(TechData_R0!AF207="","",TechData_R0!AF207)
A16: UC_IMPPADDUP11 | B16: IMPJTFP23 | E16: 1 | F16: 1 | G16: =IF(TechData_R0!W208="","",TechData_R0!W208) -> 218348.9 | H16: =IF(TechData_R0!X208="","",TechData_R0!X208) -> 218348.9 | I16: =IF(TechData_R0!Y208="","",TechData_R0!Y208) -> 218348.9 | J16: =IF(TechData_R0!Z208="","",TechData_R0!Z208) -> 218348.9 | K16: =IF(TechData_R0!AA208="","",TechData_R0!AA208) -> 218348.9 | L16: =IF(TechData_R0!AB208="","",TechData_R0!AB208) -> 218348.9 | M16: =IF(TechData_R0!AC208="","",TechData_R0!AC208) -> 218348.9 | N16: =IF(TechData_R0!AD208="","",TechData_R0!AD208) -> 0 | ... P16: =IF(TechData_R0!AF208="","",TechData_R0!AF208) -> 0
A17: UC_IMPPADDUP12 | B17: IMPJTFP21 | E17: 1 | F17: 1 | G17: =IF(TechData_R0!W209="","",TechData_R0!W209) -> 1746791.2 | H17: =IF(TechData_R0!X209="","",TechData_R0!X209) -> 1746791.2 | I17: =IF(TechData_R0!Y209="","",TechData_R0!Y209) -> 1746791.2 | J17: =IF(TechData_R0!Z209="","",TechData_R0!Z209) -> 1746791.2 | K17: =IF(TechData_R0!AA209="","",TechData_R0!AA209) -> 1746791.2 | L17: =IF(TechData_R0!AB209="","",TechData_R0!AB209) -> 1746791.2 | M17: =IF(TechData_R0!AC209="","",TechData_R0!AC209) -> 1746791.2 | N17: =IF(TechData_R0!AD209="","",TechData_R0!AD209) -> 0 | ... P17: =IF(TechData_R0!AF209="","",TechData_R0!AF209) -> 0
... A35: UC_IMPPADDUP30 | B35: IMPDSHP35 | E35: 1 | F35: 1 | G35: =IF(TechData_R0!W227="","",TechData_R0!W227) -> 1794543 | H35: =IF(TechData_R0!X227="","",TechData_R0!X227) -> 1794543 | I35: =IF(TechData_R0!Y227="","",TechData_R0!Y227) -> 1794543 | J35: =IF(TechData_R0!Z227="","",TechData_R0!Z227) | K35: =IF(TechData_R0!AA227="","",TechData_R0!AA227) | L35: =IF(TechData_R0!AB227="","",TechData_R0!AB227) | M35: =IF(TechData_R0!AC227="","",TechData_R0!AC227) | N35: =IF(TechData_R0!AD227="","",TechData_R0!AD227) | ... P35: =IF(TechData_R0!AF227="","",TechData_R0!AF227)

Sheet TechData_R0
B1: TechData | C1: R0,R1,R2,R3,R4,R5,R6 | Z1: * | AA1: * | AB1: * | AC1: =$AB1 -> * | AD1: =$AB1 -> * | AE1: =$AB1 -> * | AF1: =$AB1 -> * | AG1: =$AB1 -> * | AH1: =$AB1 -> * | AI1: =$AB1 -> * | AJ1: =$AB1 -> * | AK1: =$AB1 -> *
B7: Region | C7: TechName | D7: TechDesc | E7: CommOUT | F7: EFF | G7: *GROWTHr | H7: *GROWTH_TIDr | I7: *DECAYr | J7: *GROWTHr~2010-2055 | K7: *DECAYr~2010-2055 | L7: COST~2010 | M7: COST~2015 | N7: COST~2020 | O7: COST~2025 | P7: COST~2030 | Q7: COST~2035 | R7: COST~2040 | S7: COST~2045 | T7: COST~2050 | U7: COST~2055 | V7: CUM | W7: ACT_BND~LO~2010 | X7: ACT_BND~UP~2005 | Y7: ACT_BND~UP~2010 | Z7: ACT_BND~UP~2015 | AA7: ACT_BND~UP~2020 | AB7: ACT_BND~UP~2025 | AC7: ACT_BND~UP~2030 | AD7: ACT_BND~UP~2035 | AE7: ACT_BND~UP~2040 | AF7: ACT_BND~UP~2045 | AG7: ACT_BND~UP~2050 | AH7: ACT_BND~UP~2055 | AI7: AFA
B8: *Oil mining
B9: =Technologies!B9 -> R1 | C9: =Technologies!C9 -> MINOILD1 | D9: Domestic crude oil - step 1 | E9: =Commodities!$C$10 -> OILD0 | F9: 1 | J9: 1.005 | K9: 1.01 | L9: =L11*'Imp Crude'!$C$5 -> 10.985033 | M9: =M11*'Imp Crude'!$C$5 -> 12.023779 | N9: =N11*'Imp Crude'!$C$5 -> 11.97627 | O9: =O11*'Imp Crude'!$C$5 -> 13.651597 | P9: =P11*'Imp Crude'!$C$5 -> 14.902155 | Q9: =Q11*'Imp Crude'!$C$5 -> 16.322528 | R9: =R11*'Imp Crude'!$C$5 -> 17.862997 | S9: =S11*'Imp Crude'!$C$5 -> 19.548851 | ... U9: =U11*'Imp Crude'!$C$5 -> 23.412892 | V9: =Y9/SUM($Y$9:$Y$13)*'Domestic Crude Oil CUM'!$J$7 -> 177.08864 | W9: =Y9*0.9 -> 2.2708085 | X9: ='Domestic Crude Oil Prod'!B47 -> 2.1943305 | Y9: ='Domestic Crude Oil Prod'!B62 -> 2.5231206
B10: =Technologies!B10 -> R1 | C10: =Technologies!C10 -> MINOILD2 | D10: Domestic crude oil - step 2 | E10: =Commodities!$C$10 -> OILD0 | F10: 1 | J10: 1.005 | K10: 1.01 | L10: =L11*'Imp Crude'!$C$6 -> 11.595313 | M10: =M11*'Imp Crude'!$C$6 -> 12.691766 | N10: =N11*'Imp Crude'!$C$6 -> 12.641618 | O10: =O11*'Imp Crude'!$C$6 -> 14.410019 | P10: =P11*'Imp Crude'!$C$6 -> 15.730053 | Q10: =Q11*'Imp Crude'!$C$6 -> 17.229335 | R10: =R11*'Imp Crude'!$C$6 -> 18.855386 | S10: =S11*'Imp Crude'!$C$6 -> 20.634898 | ... U10: =U11*'Imp Crude'!$C$6 -> 24.713608 | V10: =Y10/SUM($Y$9:$Y$13)*'Domestic Crude Oil CUM'!$J$7 -> 177.08864 | W10: =Y10*0.9 -> 2.2708085 | X10: ='Domestic Crude Oil Prod'!B48 -> 2.1943305 | Y10: ='Domestic Crude Oil Prod'!B63 -> 2.5231206
B11: =Technologies!B11 -> R1 | C11: =Technologies!C11 -> MINOILD3 | D11: Domestic crude oil - step 3 | E11: =Commodities!$C$10 -> OILD0 | F11: 1 | J11: 1.005 | K11: 1.01 | L11: ='Domestic Crude Oil Prices'!M31*'Imp Crude'!$J$5 -> 12.205592 | M11: ='Domestic Crude Oil Prices'!N31*'Imp Crude'!$J$5 -> 13.359754 | N11: ='Domestic Crude Oil Prices'!O31*'Imp Crude'!$J$5 -> 13.306966 | O11: ='Domestic Crude Oil Prices'!P31*'Imp Crude'!$J$5 -> 15.168441 | P11: ='Domestic Crude Oil Prices'!Q31*'Imp Crude'!$J$5 -> 16.55795 | Q11: ='Domestic Crude Oil Prices'!R31*'Imp Crude'!$J$5 -> 18.136142 | R11: ='Domestic Crude Oil Prices'!S31*'Imp Crude'!$J$5 -> 19.847774 | S11: =R11*'Domestic Crude Oil Prices'!$T$30 -> 21.720945 | T11: =S11*'Domestic Crude Oil Prices'!$T$30 -> 23.770901 | U11: =T11*'Domestic Crude Oil Prices'!$T$30 -> 26.014324 | V11: =Y11/SUM($Y$9:$Y$13)*'Domestic Crude Oil CUM'!$J$7 -> 1416.7091 | W11: =Y11*0.9 -> 18.166468 | X11: ='Domestic Crude Oil Prod'!B49 -> 17.554644 | Y11: ='Domestic Crude Oil Prod'!B64 -> 20.184965
B12: =Technologies!B12 -> R1 | C12: =Technologies!C12 -> MINOILD4 | D12: Domestic crude oil - step 4 | E12: =Commodities!$C$10 -> OILD0 | F12: 1 | H12: =Y12*0.1 -> 0.50462412 | J12: 1.005 | K12: 1.01 | L12: =L11*'Imp Crude'!$C$8 -> 12.815872 | M12: =M11*'Imp Crude'!$C$8 -> 14.027742 | N12: =N11*'Imp Crude'!$C$8 -> 13.972315 | O12: =O11*'Imp Crude'!$C$8 -> 15.926863 | P12: =P11*'Imp Crude'!$C$8 -> 17.385848 | Q12: =Q11*'Imp Crude'!$C$8 -> 19.042949 | R12: =R11*'Imp Crude'!$C$8 -> 20.840163 | S12: =S11*'Imp Crude'!$C$8 -> 22.806993 | ... U12: =U11*'Imp Crude'!$C$8 -> 27.31504 | V12: =Y12/SUM($Y$9:$Y$13)*'Domestic Crude Oil CUM'!$J$7 -> 354.17728 | X12: ='Domestic Crude Oil Prod'!B50 -> 4.3886609 | Y12: ='Domestic Crude Oil Prod'!B65 -> 5.0462412
B13: =Technologies!B13 -> R1 | C13: =Technologies!C13 -> MINOILD5 | D13: Domestic crude oil - step 5 | E13: =Commodities!$C$10 -> OILD0 | F13: 1 | H13: =Y13*0.1 -> 0.75693618 | J13: 1.005 | K13: 1.01 | L13: =L12*'Imp Crude'!$C$9 -> 16.660633 | M13: =M12*'Imp Crude'!$C$9 -> 18.236064 | N13: =N12*'Imp Crude'!$C$9 -> 18.164009 | O13: =O12*'Imp Crude'!$C$9 -> 20.704922 | P13: =P12*'Imp Crude'!$C$9 -> 22.601602 | Q13: =Q12*'Imp Crude'!$C$9 -> 24.755834 | R13: =R12*'Imp Crude'!$C$9 -> 27.092212 | S13: =S12*'Imp Crude'!$C$9 -> 29.649091 | ... U13: =U12*'Imp Crude'!$C$9 -> 35.509552 | V13: =Y13/SUM($Y$9:$Y$13)*'Domestic Crude Oil CUM'!$J$7 -> 531.26592 | X13: 0 | Y13: ='Domestic Crude Oil Prod'!B66 -> 7.5693618
B17: Region | C17: TechName | D17: TechDesc | E17: CommIN | F17: CommOUT | G17: EFF | H17: ACT_BND~LO~2010 | I17: ACT_BND~UP~2005 | J17: ACT_BND~UP~2010 | K17: ACT_BND~UP~2015 | L17: ACT_BND~UP~2020 | M17: ACT_BND~UP~2025 | N17: ACT_BND~UP~2030 | O17: ACT_BND~UP~2035 | P17: ACT_BND~UP~2040 | Q17: ACT_BND~UP~2045 | R17: ACT_BND~UP~2050 | S17: ACT_BND~UP~2055 | T17: AFA | X17: ENV_ACT~VOC | Y17: ENV_ACT~CO | Z17: ENV_ACT~NOX | AA17: ENV_ACT~PM10 | AB17: ENV_ACT~PM25 | AC17: ENV_ACT~SO2 | AD17: ENV_ACT~CH4 | AE17: ENV_ACT~N2O | AF17: ENV_ACT~CO2 | AG17: ENV_ACT~OC | AH17: ENV_ACT~BC
B18: * Oil extraction
B19: =Technologies!B$18 -> R1 | C19: =Technologies!C$18 -> SCMINOILD | D19: Collector: MINOILD | E19: =Commodities!$C$10 -> OILD0 | F19: =Commodities!C11 -> OILD1 | G19: 1
B20: * | C20: =Technologies!C$18 -> SCMINOILD | D20: Collector: MINOILD | E20: =Commodities!$C$10 -> OILD0 | F20: =Commodities!C12 -> OILD2 | G20: 1 | X20: =Emissions!D6 -> 0.0010994635 | Y20: =Emissions!E6 -> 0.0029382215 | Z20: =Emissions!F6 -> 0.0092506587 | AA20: =Emissions!G6 -> 0.0011184198 | AB20: =Emissions!H6 -> 0.00038860349 | AC20: =Emissions!I6 -> 0.0019524956 | AD20: =Emissions!C75 -> 0.080620207 | AE20: =Emissions!K6 -> 4.3599416e-05 | AF20: =Emissions!B75/1000 -> 0.0022133809 | AG20: =Emissions!M6 -> 3.1277842e-05 | AH20: =Emissions!N6 -> 1.2321574e-05
B21: * | C21: =Technologies!C$18 -> SCMINOILD | D21: Collector: MINOILD | E21: =Commodities!$C$10 -> OILD0 | F21: =Commodities!C13 -> OILD3 | G21: 1 | X21: =X20 -> 0.0010994635 | Y21: =Y20 -> 0.0029382215 | Z21: =Z20 -> 0.0092506587 | AA21: =AA20 -> 0.0011184198 | AB21: =AB20 -> 0.00038860349 | AC21: =AC20 -> 0.0019524956 | AD21: =AD20 -> 0.080620207 | AE21: =AE20 -> 4.3599416e-05 | ... AH21: =AH20 -> 1.2321574e-05
B22: * | C22: =Technologies!C$18 -> SCMINOILD | D22: Collector: MINOILD | E22: =Commodities!$C$10 -> OILD0 | F22: =Commodities!C14 -> OILD4 | G22: 1 | X22: =X21 -> 0.0010994635 | Y22: =Y21 -> 0.0029382215 | Z22: =Z21 -> 0.0092506587 | AA22: =AA21 -> 0.0011184198 | AB22: =AB21 -> 0.00038860349 | AC22: =AC21 -> 0.0019524956 | AD22: =AD21 -> 0.080620207 | AE22: =AE21 -> 4.3599416e-05 | ... AH22: =AH21 -> 1.2321574e-05
B23: * | C23: =Technologies!C$18 -> SCMINOILD | D23: Collector: MINOILD | E23: =Commodities!$C$10 -> OILD0 | F23: =Commodities!C15 -> OILD5 | G23: 1 | X23: =X22 -> 0.0010994635 | Y23: =Y22 -> 0.0029382215 | Z23: =Z22 -> 0.0092506587 | AA23: =AA22 -> 0.0011184198 | AB23: =AB22 -> 0.00038860349 | AC23: =AC22 -> 0.0019524956 | AD23: =AD22 -> 0.080620207 | AE23: =AE22 -> 4.3599416e-05 | ... AH23: =AH22 -> 1.2321574e-05
B24: * | C24: =Technologies!C$18 -> SCMINOILD | D24: Collector: MINOILD | E24: =Commodities!$C$10 -> OILD0 | F24: =Commodities!C16 -> OILD6 | G24: 1 | X24: =X23 -> 0.0010994635 | Y24: =Y23 -> 0.0029382215 | Z24: =Z23 -> 0.0092506587 | AA24: =AA23 -> 0.0011184198 | AB24: =AB23 -> 0.00038860349 | AC24: =AC23 -> 0.0019524956 | AD24: =AD23 -> 0.080620207 | AE24: =AE23 -> 4.3599416e-05 | ... AH24: =AH23 -> 1.2321574e-05
B25: *
B30: Region | C30: TechName | D30: TechDesc | E30: CommOUT | F30: EFF | G30: *GROWTHr | H30: *GROWTH_TIDr | I30: *DECAYr | J30: *GROWTHr~2010-2055 | K30: *DECAYr~2010-2055 | L30: COST~2010 | M30: COST~2015 | N30: COST~2020 | O30: COST~2025 | P30: COST~2030 | Q30: COST~2035 | R30: COST~2040 | S30: COST~2045 | T30: COST~2050 | U30: COST~2055 | V30: CUM | W30: ACT_BND~LO~2010 | X30: ACT_BND~UP~2005 | Y30: ACT_BND~UP~2010 | Z30: ACT_BND~UP~2015 | AA30: ACT_BND~UP~2020 | AB30: ACT_BND~UP~2025 | AC30: ACT_BND~UP~2030 | AD30: ACT_BND~UP~2035 | AE30: ACT_BND~UP~2040 | AF30: ACT_BND~UP~2045 | AG30: ACT_BND~UP~2050 | AH30: ACT_BND~UP~2055 | AI30: AFA | AJ30: NCAP_TLIFE
B31: *Imported crude supply
B32: =Technologies!B25 -> R1 | C32: ='Imp Crude'!B13 -> IMPOILHH13 | D32: ='Imp Crude'!C13 -> Imported Imported Oil-High Sulfur, Heavy G, PADD 1, Step 3 | E32: ='Imp Crude'!D13 -> OILHH1 | F32: 1 | J32: 1.005 | K32: 1.005 | L32: ='Imp Crude'!L13 -> 11.163537 | M32: ='Imp Crude'!M13 -> #REF! | N32: ='Imp Crude'!N13 -> #REF! | O32: ='Imp Crude'!O13 -> #REF! | P32: ='Imp Crude'!P13 -> #REF! | Q32: ='Imp Crude'!Q13 -> #REF! | R32: ='Imp Crude'!R13 -> #REF! | S32: ='Imp Crude'!S13 -> #REF! | ... U32: ='Imp Crude'!U13 -> #REF! | X32: ='Imp Crude'!AE13 -> 477.40444 | Y32: ='Imp Crude'!AF13 -> 239.79184
B33: =Technologies!B26 -> R1 | C33: ='Imp Crude'!B14 -> IMPOILHH11 | D33: ='Imp Crude'!C14 -> Imported Imported Oil-High Sulfur, Heavy G, PADD 1, Step 1 | E33: ='Imp Crude'!D14 -> OILHH1 | F33: 1 | J33: 1.005 | K33: 1.005 | L33: ='Imp Crude'!L14 -> 10.047183 | M33: ='Imp Crude'!M14 -> #REF! | N33: ='Imp Crude'!N14 -> #REF! | O33: ='Imp Crude'!O14 -> #REF! | P33: ='Imp Crude'!P14 -> #REF! | Q33: ='Imp Crude'!Q14 -> #REF! | R33: ='Imp Crude'!R14 -> #REF! | S33: ='Imp Crude'!S14 -> #REF! | ... U33: ='Imp Crude'!U14 -> #REF! | X33: ='Imp Crude'!AE14 -> 59.675555 | Y33: ='Imp Crude'!AF14 -> 29.973981
B34: =Technologies!B27 -> R1 | C34: ='Imp Crude'!B15 -> IMPOILHH12 | D34: ='Imp Crude'!C15 -> Imported Imported Oil-High Sulfur, Heavy G, PADD 1, Step 2 | E34: ='Imp Crude'!D15 -> OILHH1 | F34: 1 | J34: 1.005 | K34: 1.005 | L34: ='Imp Crude'!L15 -> 10.60536 | M34: ='Imp Crude'!M15 -> #REF! | N34: ='Imp Crude'!N15 -> #REF! | O34: ='Imp Crude'!O15 -> #REF! | P34: ='Imp Crude'!P15 -> #REF! | Q34: ='Imp Crude'!Q15 -> #REF! | R34: ='Imp Crude'!R15 -> #REF! | S34: ='Imp Crude'!S15 -> #REF! | ... U34: ='Imp Crude'!U15 -> #REF! | X34: ='Imp Crude'!AE15 -> 59.675555 | Y34: ='Imp Crude'!AF15 -> 29.973981
B35: =Technologies!B28 -> R1 | C35: ='Imp Crude'!B16 -> IMPOILHH14 | D35: ='Imp Crude'!C16 -> Imported Imported Oil-High Sulfur, Heavy G, PADD 1, Step 4 | E35: ='Imp Crude'!D16 -> OILHH1 | F35: 1 | J35: 1.005 | K35: 1.005 | L35: ='Imp Crude'!L16 -> 11.721714 | M35: ='Imp Crude'!M16 -> #REF! | N35: ='Imp Crude'!N16 -> #REF! | O35: ='Imp Crude'!O16 -> #REF! | P35: ='Imp Crude'!P16 -> #REF! | Q35: ='Imp Crude'!Q16 -> #REF! | R35: ='Imp Crude'!R16 -> #REF! | S35: ='Imp Crude'!S16 -> #REF! | ... U35: ='Imp Crude'!U16 -> #REF! | X35: ='Imp Crude'!AE16 -> 119.35111 | Y35: ='Imp Crude'!AF16 -> 59.947961
B36: =Technologies!B29 -> R1 | C36: ='Imp Crude'!B17 -> IMPOILHH15 | D36: ='Imp Crude'!C17 -> Imported Imported Oil-High Sulfur, Heavy G, PADD 1, Step 5 | E36: ='Imp Crude'!D17 -> OILHH1 | F36: 1 | J36: 1.005 | K36: 1.005 | L36: ='Imp Crude'!L17 -> 14.512598 | M36: ='Imp Crude'!M17 -> #REF! | N36: ='Imp Crude'!N17 -> #REF! | O36: ='Imp Crude'!O17 -> #REF! | P36: ='Imp Crude'!P17 -> #REF! | Q36: ='Imp Crude'!Q17 -> #REF! | R36: ='Imp Crude'!R17 -> #REF! | S36: ='Imp Crude'!S17 -> #REF! | ... U36: ='Imp Crude'!U17 -> #REF! | X36: ='Imp Crude'!AE17 -> 59.675555 | Y36: ='Imp Crude'!AF17 -> 29.973981
B37: =Technologies!B30 -> R1 | C37: ='Imp Crude'!B18 -> IMPOILHL13 | D37: ='Imp Crude'!C18 -> Imported Imported Oil-High Sulfur, Low G, PADD 1, Step 3 | E37: ='Imp Crude'!D18 -> OILHL1 | F37: 1 | J37: 1.005 | K37: 1.005 | L37: ='Imp Crude'!L18 -> 12.073159 | M37: ='Imp Crude'!M18 -> #REF! | N37: ='Imp Crude'!N18 -> #REF! | O37: ='Imp Crude'!O18 -> #REF! | P37: ='Imp Crude'!P18 -> #REF! | Q37: ='Imp Crude'!Q18 -> #REF! | R37: ='Imp Crude'!R18 -> #REF! | S37: ='Imp Crude'!S18 -> #REF! | ... U37: ='Imp Crude'!U18 -> #REF! | X37: ='Imp Crude'!AE18 -> 174.82416 | Y37: ='Imp Crude'!AF18 -> 148.71043
B38: =Technologies!B31 -> R1 | C38: ='Imp Crude'!B19 -> IMPOILHL11 | D38: ='Imp Crude'!C19 -> Imported Imported Oil-High Sulfur, Low G, PADD 1, Step 1 | E38: ='Imp Crude'!D19 -> OILHL1 | F38: 1 | J38: 1.005 | K38: 1.005 | L38: ='Imp Crude'!L19 -> 10.865843 | M38: ='Imp Crude'!M19 -> #REF! | N38: ='Imp Crude'!N19 -> #REF! | O38: ='Imp Crude'!O19 -> #REF! | P38: ='Imp Crude'!P19 -> #REF! | Q38: ='Imp Crude'!Q19 -> #REF! | R38: ='Imp Crude'!R19 -> #REF! | S38: ='Imp Crude'!S19 -> #REF! | ... U38: ='Imp Crude'!U19 -> #REF! | X38: ='Imp Crude'!AE19 -> 21.85302 | Y38: ='Imp Crude'!AF19 -> 18.588804
B39: =Technologies!B32 -> R1 | C39: ='Imp Crude'!B20 -> IMPOILHL12 | D39: ='Imp Crude'!C20 -> Imported Imported Oil-High Sulfur, Low G, PADD 1, Step 2 | E39: ='Imp Crude'!D20 -> OILHL1 | F39: 1 | J39: 1.005 | K39: 1.005 | L39: ='Imp Crude'!L20 -> 11.469501 | M39: ='Imp Crude'!M20 -> #REF! | N39: ='Imp Crude'!N20 -> #REF! | O39: ='Imp Crude'!O20 -> #REF! | P39: ='Imp Crude'!P20 -> #REF! | Q39: ='Imp Crude'!Q20 -> #REF! | R39: ='Imp Crude'!R20 -> #REF! | S39: ='Imp Crude'!S20 -> #REF! | ... U39: ='Imp Crude'!U20 -> #REF! | X39: ='Imp Crude'!AE20 -> 21.85302 | Y39: ='Imp Crude'!AF20 -> 18.588804
B40: =Technologies!B33 -> R1 | C40: ='Imp Crude'!B21 -> IMPOILHL14 | D40: ='Imp Crude'!C21 -> Imported Imported Oil-High Sulfur, Low G, PADD 1, Step 4 | E40: ='Imp Crude'!D21 -> OILHL1 | F40: 1 | J40: 1.005 | K40: 1.005 | L40: ='Imp Crude'!L21 -> 12.676817 | M40: ='Imp Crude'!M21 -> #REF! | N40: ='Imp Crude'!N21 -> #REF! | O40: ='Imp Crude'!O21 -> #REF! | P40: ='Imp Crude'!P21 -> #REF! | Q40: ='Imp Crude'!Q21 -> #REF! | R40: ='Imp Crude'!R21 -> #REF! | S40: ='Imp Crude'!S21 -> #REF! | ... U40: ='Imp Crude'!U21 -> #REF! | X40: ='Imp Crude'!AE21 -> 43.70604 | Y40: ='Imp Crude'!AF21 -> 37.177608
B41: =Technologies!B34 -> R1 | C41: ='Imp Crude'!B22 -> IMPOILHL15 | D41: ='Imp Crude'!C22 -> Imported Imported Oil-High Sulfur, Low G, PADD 1, Step 5 | E41: ='Imp Crude'!D22 -> OILHL1 | F41: 1 | J41: 1.005 | K41: 1.005 | L41: ='Imp Crude'!L22 -> 15.695106 | M41: ='Imp Crude'!M22 -> #REF! | N41: ='Imp Crude'!N22 -> #REF! | O41: ='Imp Crude'!O22 -> #REF! | P41: ='Imp Crude'!P22 -> #REF! | Q41: ='Imp Crude'!Q22 -> #REF! | R41: ='Imp Crude'!R22 -> #REF! | S41: ='Imp Crude'!S22 -> #REF! | ... U41: ='Imp Crude'!U22 -> #REF! | X41: ='Imp Crude'!AE22 -> 21.85302 | Y41: ='Imp Crude'!AF22 -> 18.588804
B42: =Technologies!B35 -> R1 | C42: ='Imp Crude'!B23 -> IMPOILHV13 | D42: ='Imp Crude'!C23 -> Imported Imported Oil-High Sulfur, Very HG, PADD 1, Step 3 | E42: ='Imp Crude'!D23 -> OILHV1 | F42: 1 | J42: 1.005 | K42: 1.005 | L42: ='Imp Crude'!L23 -> 11.064306 | M42: ='Imp Crude'!M23 -> #REF! | N42: ='Imp Crude'!N23 -> #REF! | O42: ='Imp Crude'!O23 -> #REF! | P42: ='Imp Crude'!P23 -> #REF! | Q42: ='Imp Crude'!Q23 -> #REF! | R42: ='Imp Crude'!R23 -> #REF! | S42: ='Imp Crude'!S23 -> #REF! | ... U42: ='Imp Crude'!U23 -> #REF! | X42: ='Imp Crude'!AE23 -> 229.6779 | Y42: ='Imp Crude'!AF23 -> 117.94019
B43: =Technologies!B36 -> R1 | C43: ='Imp Crude'!B24 -> IMPOILHV11 | D43: ='Imp Crude'!C24 -> Imported Imported Oil-High Sulfur, Very HG, PADD 1, Step 1 | E43: ='Imp Crude'!D24 -> OILHV1 | F43: 1 | J43: 1.005 | K43: 1.005 | L43: ='Imp Crude'!L24 -> 9.9578751 | M43: ='Imp Crude'!M24 -> #REF! | N43: ='Imp Crude'!N24 -> #REF! | O43: ='Imp Crude'!O24 -> #REF! | P43: ='Imp Crude'!P24 -> #REF! | Q43: ='Imp Crude'!Q24 -> #REF! | R43: ='Imp Crude'!R24 -> #REF! | S43: ='Imp Crude'!S24 -> #REF! | ... U43: ='Imp Crude'!U24 -> #REF! | X43: ='Imp Crude'!AE24 -> 28.709737 | Y43: ='Imp Crude'!AF24 -> 14.742523
... B56: =Technologies!B49 -> R1 | C56: ='Imp Crude'!B37 -> IMPOILMH15 | D56: ='Imp Crude'!C37 -> Imported Imported Oil-Medium Sulfur, HG, PADD 1, Step 5 | E56: ='Imp Crude'!D37 -> OILMH1 | F56: 1 | J56: 1.005 | K56: 1.005 | L56: ='Imp Crude'!L37 -> 15.669306 | M56: ='Imp Crude'!M37 -> #REF! | N56: ='Imp Crude'!N37 -> #REF! | O56: ='Imp Crude'!O37 -> #REF! | P56: ='Imp Crude'!P37 -> #REF! | Q56: ='Imp Crude'!Q37 -> #REF! | R56: ='Imp Crude'!R37 -> #REF! | S56: ='Imp Crude'!S37 -> #REF! | ... U56: ='Imp Crude'!U37 -> #REF! | X56: ='Imp Crude'!AE37 -> 12.281556 | Y56: ='Imp Crude'!AF37 -> 11.843843
B57: *
B58: =Technologies!B51 -> R1 | C58: ='Imp Crude'!B39 -> IMPOILHH23 | D58: ='Imp Crude'!C39 -> Imported Imported Oil-High Sulfur, Heavy G, PADD 2, Step 3 | E58: ='Imp Crude'!D39 -> OILHH2 | F58: 1 | J58: 1.005 | K58: 1.005 | L58: ='Imp Crude'!L39 -> 11.163537 | M58: ='Imp Crude'!M39 -> #REF! | N58: ='Imp Crude'!N39 -> #REF! | O58: ='Imp Crude'!O39 -> #REF! | P58: ='Imp Crude'!P39 -> #REF! | Q58: ='Imp Crude'!Q39 -> #REF! | R58: ='Imp Crude'!R39 -> #REF! | S58: ='Imp Crude'!S39 -> #REF! | ... U58: ='Imp Crude'!U39 -> #REF! | X58: ='Imp Crude'!AE39 -> 424.2643 | Y58: ='Imp Crude'!AF39 -> 454.15912
B59: =Technologies!B52 -> R1 | C59: ='Imp Crude'!B40 -> IMPOILHH21 | D59: ='Imp Crude'!C40 -> Imported Imported Oil-High Sulfur, Heavy G, PADD 2, Step 1 | E59: ='Imp Crude'!D40 -> OILHH2 | F59: 1 | J59: 1.005 | K59: 1.005 | L59: ='Imp Crude'!L40 -> 10.047183 | M59: ='Imp Crude'!M40 -> #REF! | N59: ='Imp Crude'!N40 -> #REF! | O59: ='Imp Crude'!O40 -> #REF! | P59: ='Imp Crude'!P40 -> #REF! | Q59: ='Imp Crude'!Q40 -> #REF! | R59: ='Imp Crude'!R40 -> #REF! | S59: ='Imp Crude'!S40 -> #REF! | ... U59: ='Imp Crude'!U40 -> #REF! | X59: ='Imp Crude'!AE40 -> 53.033038 | Y59: ='Imp Crude'!AF40 -> 56.76989
B60: =Technologies!B53 -> R1 | C60: ='Imp Crude'!B41 -> IMPOILHH22 | D60: ='Imp Crude'!C41 -> Imported Imported Oil-High Sulfur, Heavy G, PADD 2, Step 2 | E60: ='Imp Crude'!D41 -> OILHH2 | F60: 1 | J60: 1.005 | K60: 1.005 | L60: ='Imp Crude'!L41 -> 10.60536 | M60: ='Imp Crude'!M41 -> #REF! | N60: ='Imp Crude'!N41 -> #REF! | O60: ='Imp Crude'!O41 -> #REF! | P60: ='Imp Crude'!P41 -> #REF! | Q60: ='Imp Crude'!Q41 -> #REF! | R60: ='Imp Crude'!R41 -> #REF! | S60: ='Imp Crude'!S41 -> #REF! | ... U60: ='Imp Crude'!U41 -> #REF! | X60: ='Imp Crude'!AE41 -> 53.033038 | Y60: ='Imp Crude'!AF41 -> 56.76989
B61: =Technologies!B54 -> R1 | C61: ='Imp Crude'!B42 -> IMPOILHH24 | D61: ='Imp Crude'!C42 -> Imported Imported Oil-High Sulfur, Heavy G, PADD 2, Step 4 | E61: ='Imp Crude'!D42 -> OILHH2 | F61: 1 | J61: 1.005 | K61: 1.005 | L61: ='Imp Crude'!L42 -> 11.721714 | M61: ='Imp Crude'!M42 -> #REF! | N61: ='Imp Crude'!N42 -> #REF! | O61: ='Imp Crude'!O42 -> #REF! | P61: ='Imp Crude'!P42 -> #REF! | Q61: ='Imp Crude'!Q42 -> #REF! | R61: ='Imp Crude'!R42 -> #REF! | S61: ='Imp Crude'!S42 -> #REF! | ... U61: ='Imp Crude'!U42 -> #REF! | X61: ='Imp Crude'!AE42 -> 106.06608 | Y61: ='Imp Crude'!AF42 -> 113.53978
B62: =Technologies!B55 -> R1 | C62: ='Imp Crude'!B43 -> IMPOILHH25 | D62: ='Imp Crude'!C43 -> Imported Imported Oil-High Sulfur, Heavy G, PADD 2, Step 5 | E62: ='Imp Crude'!D43 -> OILHH2 | F62: 1 | J62: 1.005 | K62: 1.005 | L62: ='Imp Crude'!L43 -> 14.512598 | M62: ='Imp Crude'!M43 -> #REF! | N62: ='Imp Crude'!N43 -> #REF! | O62: ='Imp Crude'!O43 -> #REF! | P62: ='Imp Crude'!P43 -> #REF! | Q62: ='Imp Crude'!Q43 -> #REF! | R62: ='Imp Crude'!R43 -> #REF! | S62: ='Imp Crude'!S43 -> #REF! | ... U62: ='Imp Crude'!U43 -> #REF! | X62: ='Imp Crude'!AE43 -> 53.033038 | Y62: ='Imp Crude'!AF43 -> 56.76989
B63: =Technologies!B56 -> R1 | C63: ='Imp Crude'!B44 -> IMPOILHL23 | D63: ='Imp Crude'!C44 -> Imported Imported Oil-High Sulfur, Low G, PADD 2, Step 3 | E63: ='Imp Crude'!D44 -> OILHL2 | F63: 1 | J63: 1.005 | K63: 1.005 | L63: ='Imp Crude'!L44 -> 12.073159 | M63: ='Imp Crude'!M44 -> #REF! | N63: ='Imp Crude'!N44 -> #REF! | O63: ='Imp Crude'!O44 -> #REF! | P63: ='Imp Crude'!P44 -> #REF! | Q63: ='Imp Crude'!Q44 -> #REF! | R63: ='Imp Crude'!R44 -> #REF! | S63: ='Imp Crude'!S44 -> #REF! | ... U63: ='Imp Crude'!U44 -> #REF! | X63: ='Imp Crude'!AE44 -> 276.11265 | Y63: ='Imp Crude'!AF44 -> 221.25892
B64: =Technologies!B57 -> R1 | C64: ='Imp Crude'!B45 -> IMPOILHL21 | D64: ='Imp Crude'!C45 -> Imported Imported Oil-High Sulfur, Low G, PADD 2, Step 1 | E64: ='Imp Crude'!D45 -> OILHL2 | F64: 1 | J64: 1.005 | K64: 1.005 | L64: ='Imp Crude'!L45 -> 10.865843 | M64: ='Imp Crude'!M45 -> #REF! | N64: ='Imp Crude'!N45 -> #REF! | O64: ='Imp Crude'!O45 -> #REF! | P64: ='Imp Crude'!P45 -> #REF! | Q64: ='Imp Crude'!Q45 -> #REF! | R64: ='Imp Crude'!R45 -> #REF! | S64: ='Imp Crude'!S45 -> #REF! | ... U64: ='Imp Crude'!U45 -> #REF! | X64: ='Imp Crude'!AE45 -> 34.514082 | Y64: ='Imp Crude'!AF45 -> 27.657365
...

Sheet >> Not used

Sheet Commodities
B1: Commodities | C1: R0,R1,R2,R3,R4,R5,R6
B7: Region | C7: CommName | D7: CommDesc | E7: Unit | F7: Csets | G7: LimType | H7: CTSLvl | I7: PeakTS | J7: Ctype | O7: Comment
B8: * Crude Oil Supply Commodities - Domestic and Imported
B9: R0,R1 | C9: OIL | D9: Crude Oil-All Sources | E9: PJ | F9: NRG
B10: R1 | C10: OILD0 | D10: Domestic Crude Oil - 0 | E10: PJ
B11: R1 | C11: OILD1 | D11: Domestic Crude Oil - R1 | E11: PJ
B12: *R0,R1,R2,R3,R4,R5,R6 | C12: OILD2 | D12: Domestic Crude Oil - R2 | E12: PJ
B13: *R0,R1,R2,R3,R4,R5,R6 | C13: OILD3 | D13: Domestic Crude Oil - R3 | E13: PJ
B14: *R0,R1,R2,R3,R4,R5,R6 | C14: OILD4 | D14: Domestic Crude Oil - R4 | E14: PJ
B15: *R0,R1,R2,R3,R4,R5,R6 | C15: OILD5 | D15: Domestic Crude Oil - R5 | E15: PJ
B16: *R0,R1,R2,R3,R4,R5,R6 | C16: OILD6 | D16: Domestic Crude Oil - R6 | E16: PJ
B17: R1 | C17: OILIP1 | D17: =CONCATENATE("Imported Oil Supply - All types, ","PADD 1") -> Imported Oil Supply - All types, PADD 1 | E17: PJ
B18: R1 | C18: =SUBSTITUTE(C17,1,2) -> OILIP2 | D18: =SUBSTITUTE(D17,1,2) -> Imported Oil Supply - All types, PADD 2 | E18: PJ
B19: R1 | C19: =SUBSTITUTE(C18,2,3) -> OILIP3 | D19: =SUBSTITUTE(D18,2,3) -> Imported Oil Supply - All types, PADD 3 | E19: PJ
B20: *R0 | C20: =SUBSTITUTE(C19,3,4) -> OILIP4 | D20: =SUBSTITUTE(D19,3,4) -> Imported Oil Supply - All types, PADD 4 | E20: PJ
B21: *R0 | C21: =SUBSTITUTE(C20,4,5) -> OILIP5 | D21: =SUBSTITUTE(D20,4,5) -> Imported Oil Supply - All types, PADD 5 | E21: PJ
B22: R1 | C22: OILHH1 | D22: Imported Imported Oil-High Sulfur, Heavy G, PADD 1 | E22: PJ
B23: R1 | C23: OILHH2 | D23: Imported Imported Oil-High Sulfur, Heavy G, PADD 2 | E23: PJ
B24: R1 | C24: OILHH3 | D24: Imported Imported Oil-High Sulfur, Heavy G, PADD 3 | E24: PJ
B25: *R0 | C25: OILHH4 | D25: Imported Imported Oil-High Sulfur, Heavy G, PADD 4 | E25: PJ
B26: *R0 | C26: OILHH5 | D26: Imported Imported Oil-High Sulfur, Heavy G, PADD 5 | E26: PJ
B27: R1 | C27: OILHL1 | D27: Imported Imported Oil-High Sulfur, Low G, PADD 1 | E27: PJ
B28: R1 | C28: OILHL2 | D28: Imported Imported Oil-High Sulfur, Low G, PADD 2 | E28: PJ
B29: R1 | C29: OILHL3 | D29: Imported Imported Oil-High Sulfur, Low G, PADD 3 | E29: PJ
B30: *R0 | C30: OILHL4 | D30: Imported Imported Oil-High Sulfur, Low G, PADD 4 | E30: PJ
B31: *R0 | C31: OILHL5 | D31: Imported Imported Oil-High Sulfur, Low G, PADD 5 | E31: PJ
B32: R1 | C32: OILHV1 | D32: Imported Imported Oil-High Sulfur, Very HG, PADD 1 | E32: PJ
B33: R1 | C33: OILHV2 | D33: Imported Imported Oil-High Sulfur, Very HG, PADD 2 | E33: PJ
... B46: *R0 | C46: OILMH5 | D46: Imported Imported Oil-Medium Sulfur, HG, PADD 5 | E46: PJ
B47: * Refined Oil Product Commodities
B48: R0,R1,R2,R3,R4,R5,R6 | C48: GSC | D48: Conventional Gasoline | E48: PJ | F48: NRG
B49: R0,R1,R2,R3,R4,R5,R6 | C49: GSR | D49: Reformulated Gasoline | E49: PJ
B50: R1 | C50: DSH | D50: Distillate-Heating Oil No. 2 | E50: PJ
B51: R0,R1,R2,R3,R4,R5,R6 | C51: DSL | D51: Distillate-Low Sulfur Highway Diesel (500 ppm) | E51: PJ
B52: R0,R1,R2,R3,R4,R5,R6 | C52: DSU | D52: Distillate-Ultralow Sulfur Highway Diesel (15 ppm) | E52: PJ
B53: *R1,R2,R3,R4,R5,R6 | C53: JTF | D53: Jet Fuel | E53: PJ
B54: *R1,R2,R3,R4,R5,R6 | C54: KER | D54: Kerosene and Other Refined Products | E54: PJ
B55: *R1,R2,R3,R4,R5,R6 | C55: LPG | D55: LPG | E55: PJ
B56: *R1,R2,R3,R4,R5,R6 | C56: MTH | D56: Methanol | E56: PJ
B57: *R1,R2,R3,R4,R5,R6 | C57: PFS | D57: Petrochemical Feedstocks | E57: PJ
...

Sheet Technologies
B1: Technologies | C1: R0,R1,R2,R3,R4,R5,R6
B7: Region | C7: TechName | D7: TechDesc | E7: Tact | F7: Tcap | G7: Sets | H7: PrimaryCG | I7: Vintage | O7: Comment
B8: *Domestic oil supply and transport technologies
B9: =IF(LEFT(Commodities!B$10,1)="*","*R1","R1") -> R1 | C9: MINOILD1 | D9: Domestic crude oil - step 1 | E9: PJ | F9: PJ/a | G9: MIN
B10: =IF(LEFT(Commodities!B$10,1)="*","*R1","R1") -> R1 | C10: MINOILD2 | D10: Domestic crude oil - step 2 | E10: PJ | F10: PJ/a
B11: =IF(LEFT(Commodities!B$10,1)="*","*R1","R1") -> R1 | C11: MINOILD3 | D11: Domestic crude oil - step 3 | E11: PJ | F11: PJ/a
B12: =IF(LEFT(Commodities!B$10,1)="*","*R1","R1") -> R1 | C12: MINOILD4 | D12: Domestic crude oil - step 4 | E12: PJ | F12: PJ/a
B13: =IF(LEFT(Commodities!B$10,1)="*","*R1","R1") -> R1 | C13: MINOILD5 | D13: Domestic crude oil - step 5 | E13: PJ | F13: PJ/a
B14: * | C14: MINOILD6 | D14: Domestic crude oil - step 6 | E14: PJ | F14: PJ/a
B15: * | C15: MINOILD7 | D15: Domestic crude oil - step 7 | E15: PJ | F15: PJ/a
B16: * | C16: MINOILD8 | D16: Domestic crude oil - step 8 | E16: PJ | F16: PJ/a
B17: * | C17: MINOILD9 | D17: Domestic crude oil - step 9 | E17: PJ | F17: PJ/a
B18: =IF(LEFT(Commodities!B$10,1)="*","*R1","R1") -> R1 | C18: SCMINOILD | D18: Collector: MINOILD | E18: PJ | F18: PJ/a | G18: PRE
B19: =IF(LEFT(Commodities!B$10,1)="*","*R1","R1") -> R1 | C19: XOILD1 | D19: Domestic crude delivery charge from R1 | E19: PJ | F19: PJ/a
B20: *R3 | C20: XOILD3 | D20: Domestic crude delivery charge from R3 | E20: PJ | F20: PJ/a
B21: *R4 | C21: XOILD4 | D21: Domestic crude delivery charge from R4 | E21: PJ | F21: PJ/a
B22: *R5 | C22: XOILD5 | D22: Domestic crude delivery charge from R5 | E22: PJ | F22: PJ/a
B23: *R6 | C23: XOILD6 | D23: Domestic crude delivery charge from R6 | E23: PJ | F23: PJ/a
B24: *Imported crude supply from PADDs
B25: R1 | C25: =TechData_R0!C32 -> IMPOILHH13 | D25: =TechData_R0!D32 -> Imported Imported Oil-High Sulfur, Heavy G, PADD 1, Step 3 | E25: PJ | F25: PJ/a | G25: IMP
B26: R1 | C26: =TechData_R0!C33 -> IMPOILHH11 | D26: =TechData_R0!D33 -> Imported Imported Oil-High Sulfur, Heavy G, PADD 1, Step 1 | E26: PJ | F26: PJ/a
B27: R1 | C27: =TechData_R0!C34 -> IMPOILHH12 | D27: =TechData_R0!D34 -> Imported Imported Oil-High Sulfur, Heavy G, PADD 1, Step 2 | E27: PJ | F27: PJ/a
B28: R1 | C28: =TechData_R0!C35 -> IMPOILHH14 | D28: =TechData_R0!D35 -> Imported Imported Oil-High Sulfur, Heavy G, PADD 1, Step 4 | E28: PJ | F28: PJ/a
B29: R1 | C29: =TechData_R0!C36 -> IMPOILHH15 | D29: =TechData_R0!D36 -> Imported Imported Oil-High Sulfur, Heavy G, PADD 1, Step 5 | E29: PJ | F29: PJ/a
B30: R1 | C30: =TechData_R0!C37 -> IMPOILHL13 | D30: =TechData_R0!D37 -> Imported Imported Oil-High Sulfur, Low G, PADD 1, Step 3 | E30: PJ | F30: PJ/a
B31: R1 | C31: =TechData_R0!C38 -> IMPOILHL11 | D31: =TechData_R0!D38 -> Imported Imported Oil-High Sulfur, Low G, PADD 1, Step 1 | E31: PJ | F31: PJ/a
B32: R1 | C32: =TechData_R0!C39 -> IMPOILHL12 | D32: =TechData_R0!D39 -> Imported Imported Oil-High Sulfur, Low G, PADD 1, Step 2 | E32: PJ | F32: PJ/a
B33: R1 | C33: =TechData_R0!C40 -> IMPOILHL14 | D33: =TechData_R0!D40 -> Imported Imported Oil-High Sulfur, Low G, PADD 1, Step 4 | E33: PJ | F33: PJ/a
B34: R1 | C34: =TechData_R0!C41 -> IMPOILHL15 | D34: =TechData_R0!D41 -> Imported Imported Oil-High Sulfur, Low G, PADD 1, Step 5 | E34: PJ | F34: PJ/a
B35: R1 | C35: =TechData_R0!C42 -> IMPOILHV13 | D35: =TechData_R0!D42 -> Imported Imported Oil-High Sulfur, Very HG, PADD 1, Step 3 | E35: PJ | F35: PJ/a
B36: R1 | C36: =TechData_R0!C43 -> IMPOILHV11 | D36: =TechData_R0!D43 -> Imported Imported Oil-High Sulfur, Very HG, PADD 1, Step 1 | E36: PJ | F36: PJ/a
B37: R1 | C37: =TechData_R0!C44 -> IMPOILHV12 | D37: =TechData_R0!D44 -> Imported Imported Oil-High Sulfur, Very HG, PADD 1, Step 2 | E37: PJ | F37: PJ/a
... B49: R1 | C49: =TechData_R0!C56 -> IMPOILMH15 | D49: =TechData_R0!D56 -> Imported Imported Oil-Medium Sulfur, HG, PADD 1, Step 5 | E49: PJ | F49: PJ/a
B50: *
B51: R1 | C51: =TechData_R0!C58 -> IMPOILHH23 | D51: =TechData_R0!D58 -> Imported Imported Oil-High Sulfur, Heavy G, PADD 2, Step 3 | E51: PJ | F51: PJ/a
B52: R1 | C52: =TechData_R0!C59 -> IMPOILHH21 | D52: =TechData_R0!D59 -> Imported Imported Oil-High Sulfur, Heavy G, PADD 2, Step 1 | E52: PJ | F52: PJ/a
B53: R1 | C53: =TechData_R0!C60 -> IMPOILHH22 | D53: =TechData_R0!D60 -> Imported Imported Oil-High Sulfur, Heavy G, PADD 2, Step 2 | E53: PJ | F53: PJ/a
B54: R1 | C54: =TechData_R0!C61 -> IMPOILHH24 | D54: =TechData_R0!D61 -> Imported Imported Oil-High Sulfur, Heavy G, PADD 2, Step 4 | E54: PJ | F54: PJ/a
B55: R1 | C55: =TechData_R0!C62 -> IMPOILHH25 | D55: =TechData_R0!D62 -> Imported Imported Oil-High Sulfur, Heavy G, PADD 2, Step 5 | E55: PJ | F55: PJ/a
B56: R1 | C56: =TechData_R0!C63 -> IMPOILHL23 | D56: =TechData_R0!D63 -> Imported Imported Oil-High Sulfur, Low G, PADD 2, Step 3 | E56: PJ | F56: PJ/a
...

Sheet TechData_DelOILNYC
B1: TechData | C1: R0,R1,R2,R3,R4,R5,R6
B5: Region | C5: TechName | D5: TechDesc | E5: CommIN | F5: CommOUT | G5: EFF | H5: NCAP_FOM~2010 | I5: NCAP_FOM~2015 | J5: NCAP_FOM~2020 | K5: NCAP_FOM~2025 | L5: NCAP_FOM~2030 | M5: NCAP_FOM~2035 | N5: NCAP_FOM~2040 | O5: NCAP_FOM~2045 | P5: NCAP_FOM~2050 | Q5: NCAP_FOM~2055
B6: *Domestic crude delivery to refineries in PADD
B7: =Technologies!B19 -> R1 | C7: =Technologies!C19 -> XOILD1 | D7: =Technologies!D19 -> Domestic crude delivery charge from R1 | E7: =Commodities!C11 -> OILD1 | F7: =Commodities!$C$9 -> OIL | G7: 1 | H7: =#REF!*#REF!^5/(Conv!$I$5*Conv!$D$46)/10^6 -> #REF! | I7: =#REF!*#REF!^5/(Conv!$I$5*Conv!$D$46)/10^6 -> #REF! | J7: =#REF!*#REF!^5/(Conv!$I$5*Conv!$D$46)/10^6 -> #REF! | K7: =#REF!*#REF!^5/(Conv!$I$5*Conv!$D$46)/10^6 -> #REF! | L7: =#REF!*#REF!^5/(Conv!$I$5*Conv!$D$46)/10^6 -> #REF! | M7: =#REF!*#REF!^5/(Conv!$I$5*Conv!$D$46)/10^6 -> #REF! | N7: =#REF!*#REF!^5/(Conv!$I$5*Conv!$D$46)/10^6 -> #REF! | O7: =#REF!*#REF!^5/(Conv!$I$5*Conv!$D$46)/10^6 -> #REF! | ... Q7: =#REF!*#REF!^5/(Conv!$I$5*Conv!$D$46)/10^6 -> #REF!
B8: =Technologies!B20 -> *R3 | C8: =Technologies!C20 -> XOILD3 | D8: =Technologies!D20 -> Domestic crude delivery charge from R3 | E8: =Commodities!C13 -> OILD3 | F8: =Commodities!$C$9 -> OIL | G8: 1 | H8: =#REF!*#REF!^5/(Conv!$I$5*Conv!$D$46)/10^6 -> #REF! | I8: =#REF!*#REF!^5/(Conv!$I$5*Conv!$D$46)/10^6 -> #REF! | J8: =#REF!*#REF!^5/(Conv!$I$5*Conv!$D$46)/10^6 -> #REF! | K8: =#REF!*#REF!^5/(Conv!$I$5*Conv!$D$46)/10^6 -> #REF! | L8: =#REF!*#REF!^5/(Conv!$I$5*Conv!$D$46)/10^6 -> #REF! | M8: =#REF!*#REF!^5/(Conv!$I$5*Conv!$D$46)/10^6 -> #REF! | N8: =#REF!*#REF!^5/(Conv!$I$5*Conv!$D$46)/10^6 -> #REF! | O8: =#REF!*#REF!^5/(Conv!$I$5*Conv!$D$46)/10^6 -> #REF! | ... Q8: =#REF!*#REF!^5/(Conv!$I$5*Conv!$D$46)/10^6 -> #REF!
B9: =Technologies!B21 -> *R4 | C9: =Technologies!C21 -> XOILD4 | D9: =Technologies!D21 -> Domestic crude delivery charge from R4 | E9: =Commodities!C14 -> OILD4 | F9: =Commodities!$C$9 -> OIL | G9: 1 | H9: =H8 -> #REF! | I9: =I8 -> #REF! | J9: =J8 -> #REF! | K9: =K8 -> #REF! | L9: =L8 -> #REF! | M9: =M8 -> #REF! | N9: =N8 -> #REF! | O9: =O8 -> #REF! | ... Q9: =Q8 -> #REF!
B10: =Technologies!B22 -> *R5 | C10: =Technologies!C22 -> XOILD5 | D10: =Technologies!D22 -> Domestic crude delivery charge from R5 | E10: =Commodities!C15 -> OILD5 | F10: =Commodities!$C$9 -> OIL | G10: 1 | H10: =H7 -> #REF! | I10: =I7 -> #REF! | J10: =J7 -> #REF! | K10: =K7 -> #REF! | L10: =L7 -> #REF! | M10: =M7 -> #REF! | N10: =N7 -> #REF! | O10: =O7 -> #REF! | ... Q10: =Q7 -> #REF!
B11: =Technologies!B23 -> *R6 | C11: =Technologies!C23 -> XOILD6 | D11: =Technologies!D23 -> Domestic crude delivery charge from R6 | E11: =Commodities!C16 -> OILD6 | F11: =Commodities!$C$9 -> OIL | G11: 1 | H11: =#REF!*#REF!^5/(Conv!$I$5*Conv!$D$46)/10^6 -> #REF! | I11: =#REF!*#REF!^5/(Conv!$I$5*Conv!$D$46)/10^6 -> #REF! | J11: =#REF!*#REF!^5/(Conv!$I$5*Conv!$D$46)/10^6 -> #REF! | K11: =#REF!*#REF!^5/(Conv!$I$5*Conv!$D$46)/10^6 -> #REF! | L11: =#REF!*#REF!^5/(Conv!$I$5*Conv!$D$46)/10^6 -> #REF! | M11: =#REF!*#REF!^5/(Conv!$I$5*Conv!$D$46)/10^6 -> #REF! | N11: =#REF!*#REF!^5/(Conv!$I$5*Conv!$D$46)/10^6 -> #REF! | O11: =#REF!*#REF!^5/(Conv!$I$5*Conv!$D$46)/10^6 -> #REF! | ... Q11: =#REF!*#REF!^5/(Conv!$I$5*Conv!$D$46)/10^6 -> #REF!
B15: Region | C15: TechName | D15: TechDesc | E15: CommIN | F15: CommOUT | G15: EFF | H15: NCAP_FOM~2010 | I15: NCAP_FOM~2015 | J15: NCAP_FOM~2020 | K15: NCAP_FOM~2025 | L15: NCAP_FOM~2030 | M15: NCAP_FOM~2035 | N15: NCAP_FOM~2040 | O15: NCAP_FOM~2045 | P15: NCAP_FOM~2050 | Q15: NCAP_FOM~2055
B16: *Imported crude delivery to refineries in PADD
B17: =Technologies!$B181 -> R1 | C17: =Technologies!$C181 -> XOILIP1 | D17: =Technologies!$D181 -> Imported crude delivery charge from PADD 1 | E17: =Commodities!C17 -> OILIP1 | F17: =Commodities!$C$9 -> OIL | G17: 1 | H17: =H7+2.5 -> #REF! | I17: =I7+2.5 -> #REF! | J17: =J7+2.5 -> #REF! | K17: =K7+2.5 -> #REF! | L17: =L7+2.5 -> #REF! | M17: =M7+2.5 -> #REF! | N17: =N7+2.5 -> #REF! | O17: =O7+2.5 -> #REF! | ... Q17: =Q7+2.5 -> #REF!
B18: =Technologies!$B182 -> R1 | C18: =Technologies!$C182 -> XOILIP2 | D18: =Technologies!$D182 -> Imported crude delivery charge from PADD 2 | E18: =Commodities!C18 -> OILIP2 | F18: =Commodities!$C$9 -> OIL | G18: 1 | H18: =H8+2.5 -> #REF! | I18: =I8+2.5 -> #REF! | J18: =J8+2.5 -> #REF! | K18: =K8+2.5 -> #REF! | L18: =L8+2.5 -> #REF! | M18: =M8+2.5 -> #REF! | N18: =N8+2.5 -> #REF! | O18: =O8+2.5 -> #REF! | ... Q18: =Q8+2.5 -> #REF!
B19: =Technologies!$B183 -> R1 | C19: =Technologies!$C183 -> XOILIP3 | D19: =Technologies!$D183 -> Imported crude delivery charge from PADD 3 | E19: =Commodities!C19 -> OILIP3 | F19: =Commodities!$C$9 -> OIL | G19: 1 | H19: =H9+2.5 -> #REF! | I19: =I9+2.5 -> #REF! | J19: =J9+2.5 -> #REF! | K19: =K9+2.5 -> #REF! | L19: =L9+2.5 -> #REF! | M19: =M9+2.5 -> #REF! | N19: =N9+2.5 -> #REF! | O19: =O9+2.5 -> #REF! | ... Q19: =Q9+2.5 -> #REF!
