Workbook
Name AnswerData: #REF!
Name bprint: #REF!
Name cprint: #REF!
Name exch_rate: #REF!
Name fitfile: [1]MODEL!$D$38
Name INF: [1]MODEL!$H$14
Name PPP: [1]MODEL!$D$12
Name PPPEX: [1]MODEL!$D$13
Name rail_coal: #REF!

Sheet Commodities
B1: Commodities | C1: R0,R1,R2,R3,R4,R5,R6
B6: ~FI_Comm
B7: Region | C7: CommName | D7: CommDesc | E7: Unit | F7: Csets | G7: LimType | H7: CTSLvl | I7: PeakTS | J7: Ctype | O7: Comment
B8: *R1,R2,R3,R4,R5,R6 | C8: LPG | D8: LPG | E8: PJ | F8: NRG
B9: *R1,R2,R3,R4,R5,R6 | C9: JTF | D9: Jet Fuel | E9: PJ
B10: *R1,R2,R3,R4,R5,R6 | C10: RFH | D10: High Sulfur Residual Fuel Oil | E10: PJ
B11: *R1,R2,R3,R4,R5,R6 | C11: KER | D11: Kerosene and Other Refined Products | E11: PJ
B12: *R1,R2,R3,R4,R5,R6 | C12: PFS | D12: Petrochemical Feedstocks | E12: PJ
B13: *R1,R2,R3,R4,R5,R6 | C13: ASP | D13: Asphalt | E13: PJ
B14: *R1,R2,R3,R4,R5,R6 | C14: PTC | D14: Petroleum Coke | E14: PJ
B15: *R1,R2,R3,R4,R5,R6 | C15: DLG | D15: Dummy Liquid Fuel | E15: PJ
B16: * Refined Products in each Region | E16: PJ
B17: R1 | C17: DummyREF | D17: Refinery dummy commodities | E17: PJ
B18: *R1,R2,R3,R4,R5,R6 | C18: LPG_E | D18: LPG | E18: PJ
B19: R1 | C19: GSC_E | D19: Conventional Gasoline | E19: PJ
B20: R1 | C20: GSR_E | D20: Reformulated Gasoline | E20: PJ
B21: *R1,R2,R3,R4,R5,R6 | C21: JTF_E | D21: Jet Fuel | E21: PJ
B22: R1 | C22: DSH_E | D22: Distillate-Heating Oil No. 2 | E22: PJ
B23: R1 | C23: RFL_E | D23: Low Sulfur Residual Fuel Oil | E23: PJ
B24: *R1,R2,R3,R4,R5,R6 | C24: RFH_E | D24: High Sulfur Residual Fuel Oil | E24: PJ
B25: *R1,R2,R3,R4,R5,R6 | C25: KER_E | D25: Kerosene and Other Refined Products | E25: PJ
B26: *R1,R2,R3,R4,R5,R6 | C26: PFS_E | D26: Petrochemical Feedstocks | E26: PJ
B27: *R1,R2,R3,R4,R5,R6 | C27: ASP_E | D27: Asphalt | E27: PJ
B28: R1 | C28: DSL_E | D28: Distillate-Low Sulfur Highway Diesel (500 ppm) | E28: PJ
... B61: *R1,R2,R3,R4,R5,R6 | C61: ETH_L | D61: Ethanol | E61: PJ
B62: R1,R2,R3,R4,R5,R6 | C62: CO2I | D62: Industrial CO2 emissions | E62: kt | F62: ENV
B63: R1,R2,R3,R4,R5,R6 | C63: NOXI | D63: Industrial NOx emissions | E63: kt | F63: ENV
B64: R1,R2,R3,R4,R5,R6 | C64: SO2I | D64: Industrial SO2 emissions | E64: kt | F64: ENV
B65: R1,R2,R3,R4,R5,R6 | C65: PM10I | D65: Industrial PM emissions | E65: kt | F65: ENV
B66: R1,R2,R3,R4,R5,R6 | C66: NOXDIREF | D66: NOx from refineries | E66: kt | F66: ENV
B73: R1,R2,R3,R4,R5,R6 | C73: ELC | D73: Electricity to Industrial Sector | E73: PJ | F73: NRG
B74: R1 | C74: OIL | D74: Crude Oil-All Sources | E74: PJ | F74: ENT,ENC,EFS,LIQ
B75: R1,R2,R3,R4,R5,R6 | C75: NGA | D75: Natural Gas to Industrial Sector | E75: PJ | F75: ENT,ENC,EFS,GAZ
B76: R1 | C76: GSC | D76: Conventional Gasoline | E76: PJ | F76: ENT,ENC,EFS,LIQ
B77: R1 | C77: GSR | D77: Reformulated Gasoline | E77: PJ | F77: ENT,ENC,EFS,LIQ
B78: R1 | C78: DSH | D78: Distillate-Heating Oil No. 2 | E78: PJ | F78: ENT,ENC,EFS,LIQ
B79: R1 | C79: RFL | D79: Low Sulfur Residual Fuel Oil | E79: PJ | F79: ENT,ENC,EFS,LIQ
... B93: R1,R2,R3,R4,R5,R6 | C93: SO2 | D93: Sulfur dioxide emissions | E93: kt | F93: ENV
B94: =IF(LEFT(B8,1)="*","*R1","R1") -> *R1 | C94: =CONCATENATE(C8,B94) -> LPG*R1 | D94: =CONCATENATE(C8," Refined in ",B94) -> LPG Refined in *R1 | E94: PJ
B95: =IF(LEFT(B76,1)="*","*R1","R1") -> R1 | C95: =CONCATENATE(C76,B95) -> GSCR1 | D95: =CONCATENATE(C76," Refined in ",B95) -> GSC Refined in R1 | E95: PJ
...

Sheet Technologies
B1: Technologies | C1: R0,R1,R2,R3,R4,R5,R6
B6: ~FI_Process
B7: Region | C7: TechName | D7: TechDesc | E7: Tact | F7: Tcap | G7: Sets | H7: PrimaryCG | I7: Vintage | O7: Comment
B8: R1 | C8: PREFE | D8: Refinery-existing conversion | E8: PJ | F8: PJ/a | G8: PRE
B9: *R1,R2,R3,R4,R5,R6 | C9: MINNGL | D9: Mined Natural Gas Liquids | E9: PJ | F9: PJ/a | G9: MIN
B10: *R1 | C10: SCLPG_E | D10: Collector: LPG from REF_E | E10: PJ | F10: PJ/a | G10: PRE
B11: R1 | C11: SCGSC_E | D11: Collector: GSC from REF_E | E11: PJ | F11: PJ/a
B12: R1 | C12: SCGSR_E | D12: Collector: GSR from REF_E | E12: PJ | F12: PJ/a
B13: *R1 | C13: SCJTF_E | D13: Collector: JTF from REF_E | E13: PJ | F13: PJ/a
B14: R1 | C14: SCDSH_E | D14: Collector: DSH from REF_E | E14: PJ | F14: PJ/a
B15: R1 | C15: SCRFL_E | D15: Collector: RFL from REF_E | E15: PJ | F15: PJ/a
B16: *R1 | C16: SCRFH_E | D16: Collector: RFH from REF_E | E16: PJ | F16: PJ/a
B17: *R1 | C17: SCKER_E | D17: Collector: KER from REF_E | E17: PJ | F17: PJ/a
B18: *R1 | C18: SCPFS_E | D18: Collector: PFS from REF_E | E18: PJ | F18: PJ/a
B19: *R1 | C19: SCASP_E | D19: Collector: ASP from REF_E | E19: PJ | F19: PJ/a
B20: R1 | C20: SCDSL_E | D20: Collector: DSL from REF_E | E20: PJ | F20: PJ/a
B21: R1 | C21: SCDSU_E | D21: Collector: DSU from REF_E | E21: PJ | F21: PJ/a
B22: *R1 | C22: SCPTC_E | D22: Collector: PTC from REF_E | E22: PJ | F22: PJ/a
... B57: R1 | C57: PREFL | D57: Refinery-new limit | E57: PJ | F57: PJ/a

Sheet TechData_REFNYC
A1: TechData | B1: R0,R1,R2,R3,R4,R5,R6 | Z1: *
E4: ~FI_T
A5: Region | B5: TechName | C5: *TechDesc | D5: CommIN | E5: CommOUT | F5: EFF | G5: NCAP_COST | H5: NCAP_FOM~2010 | I5: NCAP_FOM~2015 | J5: NCAP_FOM~2020 | K5: NCAP_FOM~2025 | L5: NCAP_FOM~2030 | M5: NCAP_FOM~2055 | N5: PRC_RESID~2010 | O5: PRC_RESID~2055 | P5: ACT_BND~LO
A6: * Collectors
A7: =Technologies!B10 -> *R1 | B7: =Technologies!C10 -> SCLPG_E | C7: =Technologies!D10 -> Collector: LPG from REF_E | D7: LPG_E | E7: =Commodities!C8 -> LPG | F7: 1 | H7: 0.001 | I7: 0.001 | J7: 0.001 | K7: 0.001 | L7: 0.001 | M7: =L7 -> 0.001
A8: =Technologies!B11 -> R1 | B8: =Technologies!C11 -> SCGSC_E | C8: =Technologies!D11 -> Collector: GSC from REF_E | D8: GSC_E | E8: =Commodities!C76 -> GSC | F8: 1 | H8: 0.001 | I8: 0.001 | J8: 0.001 | K8: 0.001 | L8: 0.001 | M8: =L8 -> 0.001
A9: =Technologies!B12 -> R1 | B9: =Technologies!C12 -> SCGSR_E | C9: =Technologies!D12 -> Collector: GSR from REF_E | D9: GSR_E | E9: =Commodities!C77 -> GSR | F9: 1 | H9: 0.001 | I9: 0.001 | J9: 0.001 | K9: 0.001 | L9: 0.001 | M9: =L9 -> 0.001
A10: =Technologies!B13 -> *R1 | B10: =Technologies!C13 -> SCJTF_E | C10: =Technologies!D13 -> Collector: JTF from REF_E | D10: JTF_E | E10: =Commodities!C9 -> JTF | F10: 1 | H10: 0.001 | I10: 0.001 | J10: 0.001 | K10: 0.001 | L10: 0.001 | M10: =L10 -> 0.001
A11: =Technologies!B14 -> R1 | B11: =Technologies!C14 -> SCDSH_E | C11: =Technologies!D14 -> Collector: DSH from REF_E | D11: DSH_E | E11: =Commodities!C78 -> DSH | F11: 1 | H11: 0.001 | I11: 0.001 | J11: 0.001 | K11: 0.001 | L11: 0.001 | M11: =L11 -> 0.001
A12: =Technologies!B15 -> R1 | B12: =Technologies!C15 -> SCRFL_E | C12: =Technologies!D15 -> Collector: RFL from REF_E | D12: RFL_E | E12: =Commodities!C79 -> RFL | F12: 1 | H12: 0.001 | I12: 0.001 | J12: 0.001 | K12: 0.001 | L12: 0.001 | M12: =L12 -> 0.001
A13: =Technologies!B16 -> *R1 | B13: =Technologies!C16 -> SCRFH_E | C13: =Technologies!D16 -> Collector: RFH from REF_E | D13: RFH_E | E13: =Commodities!C10 -> RFH | F13: 1 | H13: 0.001 | I13: 0.001 | J13: 0.001 | K13: 0.001 | L13: 0.001 | M13: =L13 -> 0.001
A14: =Technologies!B17 -> *R1 | B14: =Technologies!C17 -> SCKER_E | C14: =Technologies!D17 -> Collector: KER from REF_E | D14: KER_E | E14: =Commodities!C11 -> KER | F14: 1 | H14: 0.001 | I14: 0.001 | J14: 0.001 | K14: 0.001 | L14: 0.001 | M14: =L14 -> 0.001
A15: =Technologies!B18 -> *R1 | B15: =Technologies!C18 -> SCPFS_E | C15: =Technologies!D18 -> Collector: PFS from REF_E | D15: PFS_E | E15: =Commodities!C12 -> PFS | F15: 1 | H15: 0.001 | I15: 0.001 | J15: 0.001 | K15: 0.001 | L15: 0.001 | M15: =L15 -> 0.001
A16: =Technologies!B19 -> *R1 | B16: =Technologies!C19 -> SCASP_E | C16: =Technologies!D19 -> Collector: ASP from REF_E | D16: ASP_E | E16: =Commodities!C13 -> ASP | F16: 1 | H16: 0.001 | I16: 0.001 | J16: 0.001 | K16: 0.001 | L16: 0.001 | M16: =L16 -> 0.001
A17: =Technologies!B20 -> R1 | B17: =Technologies!C20 -> SCDSL_E | C17: =Technologies!D20 -> Collector: DSL from REF_E | D17: DSL_E | E17: =Commodities!C80 -> DSL | F17: 1 | H17: 0.001 | I17: 0.001 | J17: 0.001 | K17: 0.001 | L17: 0.001 | M17: =L17 -> 0.001
A18: =Technologies!B21 -> R1 | B18: =Technologies!C21 -> SCDSU_E | C18: =Technologies!D21 -> Collector: DSU from REF_E | D18: DSU_E | E18: =Commodities!C81 -> DSU | F18: 1 | H18: 0.001 | I18: 0.001 | J18: 0.001 | K18: 0.001 | L18: 0.001 | M18: =L18 -> 0.001
A19: =Technologies!B22 -> *R1 | B19: =Technologies!C22 -> SCPTC_E | C19: =Technologies!D22 -> Collector: PTC from REF_E | D19: PTC_E | E19: =Commodities!C14 -> PTC | F19: 1 | H19: 0.001 | I19: 0.001 | J19: 0.001 | K19: 0.001 | L19: 0.001 | M19: =L19 -> 0.001
A20: =Technologies!B23 -> *R1 | B20: =Technologies!C23 -> SCDLG_E | C20: =Technologies!D23 -> Collector: DLG from REF_E | D20: DLG_E | E20: =Commodities!C15 -> DLG | F20: 1 | H20: 0.001 | I20: 0.001 | J20: 0.001 | K20: 0.001 | L20: 0.001 | M20: =L20 -> 0.001
A21: =Technologies!B24 -> *R1 | B21: =Technologies!C24 -> SCLPG_N | C21: =Technologies!D24 -> Collector: LPG from REF_N | D21: LPG_N | E21: =E7 -> LPG | F21: 1 | H21: 0.001 | I21: 0.001 | J21: 0.001 | K21: 0.001 | L21: 0.001 | M21: =L21 -> 0.001
A22: =Technologies!B25 -> R1 | B22: =Technologies!C25 -> SCGSC_N | C22: =Technologies!D25 -> Collector: GSC from REF_N | D22: GSC_N | E22: =E8 -> GSC | F22: 1 | H22: 0.001 | I22: 0.001 | J22: 0.001 | K22: 0.001 | L22: 0.001 | M22: =L22 -> 0.001
A23: =Technologies!B26 -> R1 | B23: =Technologies!C26 -> SCGSR_N | C23: =Technologies!D26 -> Collector: GSR from REF_N | D23: GSR_N | E23: =E9 -> GSR | F23: 1 | H23: 0.001 | I23: 0.001 | J23: 0.001 | K23: 0.001 | L23: 0.001 | M23: =L23 -> 0.001
A24: =Technologies!B27 -> *R1 | B24: =Technologies!C27 -> SCJTF_N | C24: =Technologies!D27 -> Collector: JTF from REF_N | D24: JTF_N | E24: =E10 -> JTF | F24: 1 | H24: 0.001 | I24: 0.001 | J24: 0.001 | K24: 0.001 | L24: 0.001 | M24: =L24 -> 0.001
A25: =Technologies!B28 -> R1 | B25: =Technologies!C28 -> SCDSH_N | C25: =Technologies!D28 -> Collector: DSH from REF_N | D25: DSH_N | E25: =E11 -> DSH | F25: 1 | H25: 0.001 | I25: 0.001 | J25: 0.001 | K25: 0.001 | L25: 0.001 | M25: =L25 -> 0.001
A26: =Technologies!B29 -> R1 | B26: =Technologies!C29 -> SCRFL_N | C26: =Technologies!D29 -> Collector: RFL from REF_N | D26: RFL_N | E26: =E12 -> RFL | F26: 1 | H26: 0.001 | I26: 0.001 | J26: 0.001 | K26: 0.001 | L26: 0.001 | M26: =L26 -> 0.001
A27: =Technologies!B30 -> *R1 | B27: =Technologies!C30 -> SCRFH_N | C27: =Technologies!D30 -> Collector: RFH from REF_N | D27: RFH_N | E27: =E13 -> RFH | F27: 1 | H27: 0.001 | I27: 0.001 | J27: 0.001 | K27: 0.001 | L27: 0.001 | M27: =L27 -> 0.001
A28: =Technologies!B31 -> *R1 | B28: =Technologies!C31 -> SCKER_N | C28: =Technologies!D31 -> Collector: KER from REF_N | D28: KER_N | E28: =E14 -> KER | F28: 1 | H28: 0.001 | I28: 0.001 | J28: 0.001 | K28: 0.001 | L28: 0.001 | M28: =L28 -> 0.001
A29: =Technologies!B32 -> *R1 | B29: =Technologies!C32 -> SCPFS_N | C29: =Technologies!D32 -> Collector: PFS from REF_N | D29: PFS_N | E29: =E15 -> PFS | F29: 1 | H29: 0.001 | I29: 0.001 | J29: 0.001 | K29: 0.001 | L29: 0.001 | M29: =L29 -> 0.001
A30: =Technologies!B33 -> *R1 | B30: =Technologies!C33 -> SCASP_N | C30: =Technologies!D33 -> Collector: ASP from REF_N | D30: ASP_N | E30: =E16 -> ASP | F30: 1 | H30: 0.001 | I30: 0.001 | J30: 0.001 | K30: 0.001 | L30: 0.001 | M30: =L30 -> 0.001
A31: =Technologies!B34 -> R1 | B31: =Technologies!C34 -> SCDSL_N | C31: =Technologies!D34 -> Collector: DSL from REF_N | D31: DSL_N | E31: =E17 -> DSL | F31: 1 | H31: 0.001 | I31: 0.001 | J31: 0.001 | K31: 0.001 | L31: 0.001 | M31: =L31 -> 0.001
A32: =Technologies!B35 -> R1 | B32: =Technologies!C35 -> SCDSU_N | C32: =Technologies!D35 -> Collector: DSU from REF_N | D32: DSU_N | E32: =E18 -> DSU | F32: 1 | H32: 0.001 | I32: 0.001 | J32: 0.001 | K32: 0.001 | L32: 0.001 | M32: =L32 -> 0.001
... A47: =Technologies!B50 -> *R1 | B47: =Technologies!C50 -> SCPTC_L | C47: =Technologies!D50 -> Collector: PTC from REF_L | D47: PTC_L | E47: =E33 -> PTC | F47: 1 | H47: 0.001 | I47: 0.001 | J47: 0.001 | K47: 0.001 | L47: 0.001 | M47: =L47 -> 0.001
E52: ~FI_T
A53: Region | B53: TechName | C53: *TechDesc | D53: CommIN | E53: CommOUT | F53: EFF | G53: Share~UP~2010 | H53: Share~UP~2055 | I53: Share~UP~2010 | J53: Share~UP~2055 | K53: *NCAP_START | L53: NCAP_TLIFE | M53: PRC_CAPACT | N53: NCAP_AFA | O53: NCAP_COST | P53: NCAP_FOM~2010 | Q53: NCAP_FOM~2015 | R53: NCAP_FOM~2020 | S53: NCAP_FOM~2025 | T53: NCAP_FOM~2030 | U53: NCAP_FOM~2055 | V53: PRC_RESID~2010 | W53: PRC_RESID~2055 | X53: ACT_BND~LO~2010 | Y53: ACT_BND~LO~2050 | AA53: Input | AB53: Output | AD53: IBOND(UP)
A54: R1 | B54: =Technologies!C8 -> PREFE | C54: =Technologies!D8 -> Refinery-existing conversion | D54: =Commodities!C74 -> OIL | F54: =SUM(AB58:AB64)/SUM(AA54:AA57) -> 0.92083406 | G54: =AA54/SUM(AA$54:AA$57) -> 0.95569214 | H54: =G54 -> 0.95569214 | K54: 2010 | L54: 40 | M54: 1 | N54: 1 | P54: 0.12898736 | Q54: 0.14403589 | R54: 0.1470456 | S54: 0.14833547 | T54: 0.14145614 | U54: =T54 -> 0.14145614 | V54: =RESID!K21 -> 2074.6655 | W54: =V54 -> 2074.6655 | X54: =0.1*V54 -> 207.46655 | Y54: =X54 -> 207.46655 | AA54: =EPAUS9RTechData!G50 -> 1.0378549 | AD54: 0
A55: =A54 -> R1 | D55: =Commodities!C75 -> NGA | G55: =AA55/SUM(AA$54:AA$57) -> 0.039891908 | H55: =G55 -> 0.039891908 | AA55: =EPAUS9RTechData!G51 -> 0.043321495
A56: =A55 -> R1 | D56: =Commodities!C73 -> ELC | G56: =AA56/SUM(AA$54:AA$57) -> 0.0044159568 | H56: =G56 -> 0.0044159568 | AA56: =EPAUS9RTechData!G52 -> 0.0047956054
A57: =A56 -> R1 | D57: =Commodities!$C$82 -> NGL | G57: =AA57/SUM(AA$54:AA$57) -> 0 | H57: =G57 -> 0 | AA57: =EPAUS9RTechData!G53 -> 0
A58: =A57 -> R1 | E58: DSH_E | I58: =AB58/SUM(AB$58:AB$64) -> 0.11618676 | J58: =I58*0.2 -> 0.023237353 | AB58: ='PADD Products'!I10/100 -> 0.11618676
A59: =A58 -> R1 | E59: RFL_E | I59: =AB59/SUM(AB$58:AB$64) -> 0.064152 | J59: =I59*0.8 -> 0.0513216 | AB59: ='PADD Products'!I11/100 -> 0.064152
A60: =A59 -> R1 | E60: =Commodities!$C$19 -> GSC_E | I60: =AB60/SUM(AB$58:AB$64) -> 0 | J60: =I60 -> 0 | AB60: =EPAUS9RTechData!H52 -> 0
...

Sheet RESID
A1: Table 1. Number and Capacity of Operable Petroleum Refineries by PAD District and State as of January 1, 2006
A2: From EIA Refinery Capacity Report
A3: http://www.eia.gov/pub/oil_gas/petroleum/data_publications/refinery_capacity_data/historical/2006/table1.pdf
A5: NYC
A7: PAD District | D7: NEMS Growth Rates
A8: and | D8: Start yr | E8: %/yr | G8: PJ/period
A9: State | B9: Barrels per Calender Day | C9: Region | I9: Region | J9: Capacity | K9: RESID (PJ/a)
A10: PAD District I................... 16 13 3 1,697,900 1,549,900 148,000 1,789,300 1,630,300 159,000 | B10: 1713100 | I10: R1
A11: Delaware ...................... 1 1 0 162,000 162,000 0 167,000 167,000 0 | B11: 181500 | C11: 5 | I11: R2 | J11: =SUM(B13,B14) -> 1425000 | K11: =J11*365*Conv!$C$47*10^-9*Conv!$I$6 -> 3248.4927 | L11: *In R2-R5, an IBOND is imposed corresponding to the fraction of the RESID retiring in each period. EIA projects no increase in capacity in these regions owing to siting difficulties.
A12: Georgia ........................ 2 1 1 33,400 5,400 28,000 40,000 8,000 32,000 | B12: 28000 | C12: 5 | I12: R3 | J12: =IF(A5="EPAUS9R",SUM(B18,B19,B22,B25,B28),0) -> 0 | K12: =J12*365*Conv!$C$47*10^-9*Conv!$I$6 -> 0
A13: New Jersey................... 6 4 2 667,000 547,000 120,000 696,000 569,000 127,000 | B13: 655000 | C13: 2 | I13: R4 | J13: =IF(A5="EPAUS9R",SUM(B23,B24,B20),0) -> 0 | K13: =J13*365*Conv!$C$47*10^-9*Conv!$I$6 -> 0
A14: Pennsylvania ................ 5 5 0 760,000 760,000 0 807,500 807,500 0 | B14: 770000 | C14: 2 | I14: R5 | J14: =IF(A5="EPAUS9R",SUM(B12,B15,B16,B11),0) -> 0 | K14: =J14*365*Conv!$C$47*10^-9*Conv!$I$6 -> 0
A15: Virginia ......................... 1 1 0 59,700 59,700 0 61,800 61,800 0 | B15: 58600 | C15: 5 | I15: R6 | J15: =IF(A5="EPAUS9R",SUM(B21,B27,B33,B30),0) -> 0 | K15: =J15*365*Conv!$C$47*10^-9*Conv!$I$6 -> 0
A16: West Virginia ................ 1 1 0 15,800 15,800 0 17,000 17,000 0 | B16: 20000 | C16: 5 | I16: R7 | J16: =IF(A5="EPAUS9R",SUM(B26,B31,B32,B35),0) -> 0 | K16: =J16*365*Conv!$C$47*10^-9*Conv!$I$6 -> 0
A17: PAD District II.................. 28 28 0 3,637,380 3,637,380 0 3,827,049 3,827,049 0 | B17: 3582640 | D17: 2025 | E17: =Capacity!E23/Capacity!E22 -> 0.027027027 | F17: =B17*E17 -> 96828.108 | G17: =F17*5*Conv!$C$47*10^-9*Conv!$I$6 -> 3.0237482 | I17: R8 | J17: =IF(A5="EPAUS9R",SUM(B37:B40,B45,B34),0) -> 0 | K17: =J17*365*Conv!$C$47*10^-9*Conv!$I$6 -> 0
A18: Illinois ........................... 6 6 0 1,017,885 1,017,885 0 1,069,000 1,069,000 0 | B18: 903500 | C18: 3 | I18: R9 | J18: =IF(A5="EPAUS9R",SUM(B42:B44,B47),0) -> 0 | K18: =J18*365*Conv!$C$47*10^-9*Conv!$I$6 -> 0
A19: Indiana ......................... 2 2 0 433,000 433,000 0 456,000 456,000 0 | B19: 433000 | C19: 3 | F19: R3 | G19: =G17*J24 -> 0 | I19: Total | J19: =SUM(J10:J18) -> 1425000 | K19: =SUM(K11:K18) -> 3248.4927 | M19: padd 1 | N19: padd 2 | O19: padd 3 | P19: R8 | Q19: R9
A20: Kansas ......................... 3 3 0 294,400 294,400 0 307,000 307,000 0 | B20: 299200 | C20: 4 | F20: R4 | G20: =G17*J25 -> 0 | M20: padd 1 | N20: padd 2 | O20: padd 3 | P20: padd 4 | Q20: padd 5
A21: Kentucky....................... 2 2 0 227,500 227,500 0 241,300 241,300 0 | B21: 227500 | C21: 6 | I21: R2 | J21: =J11/(J11+SUM(B12,B15,B16,B11)) -> 0.83182535 | K21: =J21*M21 -> 2074.6655 | M21: =Capacity!F3 -> 2494.1119 | N21: =Capacity!F4 -> 6901.1864 | O21: =Capacity!F5 -> 14663.505 | P21: =Capacity!F6 -> 1086.857 | Q21: =Capacity!F7 -> 4892.5752
A22: Michigan....................... 1 1 0 74,000 74,000 0 75,000 75,000 0 | B22: 100000 | C22: 3 | I22: R5 | J22: =J14/(J11+J14) -> 0 | K22: =J22*M21 -> 0
A23: Minnesota..................... 2 2 0 335,000 335,000 0 366,000 366,000 0 | B23: 349300 | C23: 4
A24: North Dakota ................ 1 1 0 58,000 58,000 0 60,000 60,000 0 | B24: 58000 | C24: 4 | I24: R3 | J24: =IF(A5="EPAUS9R",J12/(J12+J13),0) -> 0 | K24: =J24*N21 -> 0
A25: Ohio.............................. 4 4 0 525,500 525,500 0 539,000 539,000 0 | B25: 510900 | C25: 3 | I25: R4 | J25: =IF(A5="EPAUS9R",J13/(J12+J13),0) -> 0 | K25: =J25*N21 -> 0
A26: Oklahoma..................... 5 5 0 469,095 469,095 0 500,749 500,749 0 | B26: 486940 | C26: 7
A27: Tennessee.................... 1 1 0 170,000 170,000 0 175,000 175,000 0 | B27: 180000 | C27: 6 | I27: R6 | J27: =IF(A5="EPAUS9R",J15/(J15+J16),0) -> 0 | K27: =J27*O21 -> 0
A28: Wisconsin..................... 1 1 0 33,000 33,000 0 38,000 38,000 0 | B28: 34300 | C28: 3 | I28: R7 | J28: =IF(A5="EPAUS9R",J16/(J15+J16),0) -> 0 | K28: =J28*O21 -> 0
A29: PAD District III................. 56 55 1 7,586,485 7,559,485 27,000 8,036,012 8,007,012 29,000 | B29: 8274086 | D29: 2010 | E29: =Capacity!E29/Capacity!E28 -> 0.034883721 | F29: =B29*E29 -> 288630.91 | G29: =F29*5*Conv!$C$47*10^-9*Conv!$I$6 -> 9.013366 | I29: R8 | J29: =IF(A7="EPAUS9R",J17/(J17+J18),0) -> 0 | K29: =J29*O23 -> 0
A30: Alabama ....................... 3 3 0 130,000 130,000 0 138,000 138,000 0 | B30: 135300 | C30: 6 | I30: R9 | J30: =IF(A8="EPAUS9R",J18/(J18+J19),0) -> 0 | K30: =J30*O24 -> 0
A31: Arkansas ...................... 2 2 0 61,455 61,455 0 73,250 73,250 0 | B31: 77200 | C31: 7 | F31: R6 | G31: =G29*J27 -> 0
A32: Louisiana...................... 17 17 0 2,672,200 2,672,200 0 2,796,855 2,796,855 0 | B32: 2900883 | C32: 7 | F32: R7 | G32: =G29*J28 -> 0
A33: Mississippi .................... 4 4 0 334,800 334,800 0 393,300 393,300 0 | B33: 369800 | C33: 6
A34: New Mexico.................. 3 3 0 95,600 95,600 0 101,107 101,107 0 | B34: 112600 | C34: 8
A35: Texas ............................ 27 26 1 4,292,430 4,265,430 27,000 4,533,500 4,504,500 29,000 | B35: 4678303 | C35: 7
A36: PAD District IV ................ 16 15 1 554,476 543,476 11,000 585,600 573,100 12,500 | B36: 595550 | D36: 2010 | E36: 0 | F36: =B36*E36 -> 0 | G36: =F36*5*Conv!$C$47*10^-9*Conv!$I$6 -> 0
A37: Colorado....................... 2 2 0 84,500 84,500 0 92,000 92,000 0 | B37: 94000 | C37: 8
A38: Montana ....................... 4 4 0 166,590 166,590 0 174,800 174,800 0 | B38: 181200 | C38: 8
A39: Utah.............................. 5 4 1 163,000 152,000 11,000 172,500 160,000 12,500 | B39: 167350 | C39: 8
A40: Wyoming ...................... 5 5 0 140,386 140,386 0 146,300 146,300 0 | B40: 153000 | C40: 8
A41: PAD District V.................. 39 39 0 3,119,130 3,029,930 89,200 3,273,300 3,176,300 97,000 | B41: 3173438 | D41: 2020 | E41: 0 | F41: =B41*E41 -> 0 | G41: =F41*5*Conv!$C$47*10^-9*Conv!$I$6 -> 0
A42: Alaska........................... 6 6 0 358,400 358,400 0 390,200 390,200 0 | B42: 373500 | C42: 9
...

Sheet Capacity
A1: Residual Capacity
A2: (use year 2012) | B2: Capacity | C2: Capacity Used | D2: Process Loss | E2: Products not used in MARKAL | F2: RESIDS | H2: Barrels of Oil | I2: % of Capacity that is Crude Oil (98.7)
A3: PADD 1 | B3: =E19*Conv!$C$47*Conv!$I$6*365/1000 -> 3647.4304 | C3: =B3*Utilization!G4/100 -> 2622.6202 | D3: =C3*(1+(Yields!S31)/100) -> 2494.1119 | E3: =C3*(Yields!T31)/100 -> 0 | F3: =D3-E3 -> 2494.1119 | H3: =C3/F3 -> 1.0515247 | I3: =H3*0.987 -> 1.0378549
A4: PADD 2 | B4: =E25*Conv!$C$47*Conv!$I$6*365/1000 -> 8434.6828 | C4: =B4*Utilization!G7/100 -> 7712.9772 | D4: =C4*(1+(Yields!S48)/100) -> 7267.5528 | E4: =C4*(Yields!T48)/100 -> 366.36642 | F4: =D4-E4 -> 6901.1864 | H4: =C4/F4 -> 1.1176306 | I4: =H4*0.987 -> 1.1031014
A5: PADD 3 | B5: =E31*Conv!$C$47*Conv!$I$6*365/1000 -> 19604.938 | C5: =B5*Utilization!G10/100 -> 17225.85 | D5: =C5*(1+(Yields!S65)/100) -> 15938.218 | E5: =C5*(Yields!T65)/100 -> 1274.7129 | F5: =D5-E5 -> 14663.505 | H5: =C5/F5 -> 1.174743 | I5: =H5*0.987 -> 1.1594714
A6: PADD 4 | B6: =E37*Conv!$C$47*Conv!$I$6*365/1000 -> 1367.7864 | C6: =B6*Utilization!G13/100 -> 1199.9525 | D6: =C6*(1+(Yields!S82)/100) -> 1150.1545 | E6: =C6*(Yields!T82)/100 -> 63.297493 | F6: =D6-E6 -> 1086.857 | H6: =C6/F6 -> 1.1040574 | I6: =H6*0.987 -> 1.0897047
A7: PADD 5 | B7: =E43*Conv!$C$47*Conv!$I$6*365/1000 -> 7066.8964 | C7: =B7*Utilization!G16/100 -> 5672.5509 | D7: =C7*(1+(Yields!S99)/100) -> 5262.7091 | E7: =C7*(Yields!T99)/100 -> 370.13395 | F7: =D7-E7 -> 4892.5752 | H7: =C7/F7 -> 1.1594203 | I7: =H7*0.987 -> 1.1443478
A10: AEO 2012 Reference Case
A11: Domestic Refinery Distillation Base Capacity, Expansion, and Utilization, Reference case
A12: (million barrels per day)
A14: Region | B14: 2009 | C14: 2010 | D14: 2011 | E14: 2012 | F14: 2013 | G14: 2014 | H14: 2015 | I14: 2016 | J14: 2017 | K14: 2018 | L14: 2019 | M14: 2020 | N14: 2021 | O14: 2022 | P14: 2023 | Q14: 2024 | R14: 2025 | S14: 2026 | T14: 2027 | U14: 2028 | V14: 2029 | W14: 2030 | X14: 2031 | Y14: 2032 | Z14: 2033 | AA14: 2034 | AB14: 2035 | AC14: Growth Rate (2010-2035)
A15: PAD District I
A16: Base Capacity | B16: 1.7 | C16: 1.4 | D16: 1.6 | E16: 1.6 | F16: 1.6 | G16: 1.6 | H16: 1.6 | I16: 1.6 | J16: 1.6 | K16: 1.6 | L16: 1.6 | M16: 1.6 | N16: 1.6 | O16: 1.6 | P16: 1.6 | Q16: 1.6 | R16: 1.6 | S16: 1.6 | T16: 1.6 | U16: 1.6 | V16: 1.6 | W16: 1.6 | X16: 1.6 | Y16: 1.6 | Z16: 1.6 | AA16: 1.6 | AB16: 1.6 | AC16: 0.004
A17: Capacity Additions | B17: 0 | C17: 0 | D17: 0 | E17: 0 | F17: 0 | G17: 0 | H17: 0 | I17: 0 | J17: 0 | K17: 0 | L17: 0 | M17: 0 | N17: 0 | O17: 0 | P17: 0 | Q17: 0 | R17: 0 | S17: 0 | T17: 0 | U17: 0 | V17: 0 | W17: 0 | X17: 0 | Y17: 0 | Z17: 0 | AA17: 0 | AB17: 0 | AC17: - -
A18: Idled Capacity | B18: 0 | C18: 0 | D18: 0 | E18: 0.1 | F18: 0.1 | G18: 0.1 | H18: 0.1 | I18: 0.1 | J18: 0.3 | K18: 0.4 | L18: 0.5 | M18: 0.5 | N18: 0.5 | O18: 0.6 | P18: 0.6 | Q18: 0.6 | R18: 0.6 | S18: 0.6 | T18: 0.6 | U18: 0.6 | V18: 0.6 | W18: 0.6 | X18: 0.6 | Y18: 0.6 | Z18: 0.6 | AA18: 0.6 | AB18: 0.7 | AC18: - -
A19: Total Capacity | B19: 1.7 | C19: 1.4 | D19: 1.6 | E19: 1.6 | F19: 1.5 | G19: 1.5 | H19: 1.5 | I19: 1.5 | J19: 1.3 | K19: 1.2 | L19: 1.1 | M19: 1.1 | N19: 1 | O19: 1 | P19: 1 | Q19: 1 | R19: 1 | S19: 1 | T19: 1 | U19: 1 | V19: 1 | W19: 1 | X19: 1 | Y19: 1 | Z19: 1 | AA19: 1 | AB19: 0.9 | AC19: -0.018
A21: PAD District II
A22: Base Capacity | B22: 3.7 | C22: 3.7 | D22: 3.7 | E22: 3.7 | F22: 3.7 | G22: 3.7 | H22: 3.7 | I22: 3.7 | J22: 3.7 | K22: 3.7 | L22: 3.7 | M22: 3.7 | N22: 3.7 | O22: 3.7 | P22: 3.7 | Q22: 3.7 | R22: 3.7 | S22: 3.7 | T22: 3.7 | U22: 3.7 | V22: 3.7 | W22: 3.7 | X22: 3.7 | Y22: 3.7 | Z22: 3.7 | AA22: 3.7 | AB22: 3.7 | AC22: 0
A23: Capacity Additions | B23: 0 | C23: 0 | D23: 0 | E23: 0.1 | F23: 0.1 | G23: 0.1 | H23: 0.1 | I23: 0.1 | J23: 0.1 | K23: 0.1 | L23: 0.1 | M23: 0.1 | N23: 0.1 | O23: 0.1 | P23: 0.1 | Q23: 0.1 | R23: 0.1 | S23: 0.1 | T23: 0.1 | U23: 0.1 | V23: 0.1 | W23: 0.1 | X23: 0.1 | Y23: 0.1 | Z23: 0.1 | AA23: 0.1 | AB23: 0.1 | AC23: - -
A24: Idled Capacity | B24: 0 | C24: 0 | D24: 0.1 | E24: 0.1 | F24: 0.2 | G24: 0.2 | H24: 0.2 | I24: 0.3 | J24: 0.4 | K24: 0.5 | L24: 0.6 | M24: 0.8 | N24: 0.8 | O24: 0.8 | P24: 0.9 | Q24: 0.9 | R24: 0.9 | S24: 0.9 | T24: 0.9 | U24: 0.9 | V24: 0.9 | W24: 0.9 | X24: 0.9 | Y24: 0.9 | Z24: 0.9 | AA24: 0.9 | AB24: 0.9 | AC24: - -
A25: Total Capacity | B25: 3.7 | C25: 3.7 | D25: 3.7 | E25: 3.7 | F25: 3.7 | G25: 3.6 | H25: 3.6 | I25: 3.5 | J25: 3.4 | K25: 3.3 | L25: 3.2 | M25: 3 | N25: 3 | O25: 3 | P25: 3 | Q25: 2.9 | R25: 2.9 | S25: 2.9 | T25: 2.9 | U25: 2.9 | V25: 2.9 | W25: 2.9 | X25: 2.9 | Y25: 2.9 | Z25: 2.9 | AA25: 2.9 | AB25: 2.9 | AC25: -0.01
A27: PAD District III
A28: Base Capacity | B28: 8.4 | C28: 8.6 | D28: 8.6 | E28: 8.6 | F28: 8.6 | G28: 8.6 | H28: 8.6 | I28: 8.6 | J28: 8.6 | K28: 8.6 | L28: 8.6 | M28: 8.6 | N28: 8.6 | O28: 8.6 | P28: 8.6 | Q28: 8.6 | R28: 8.6 | S28: 8.6 | T28: 8.6 | U28: 8.6 | V28: 8.6 | W28: 8.6 | X28: 8.6 | Y28: 8.6 | Z28: 8.6 | AA28: 8.6 | AB28: 8.6 | AC28: 0
A29: Capacity Additions | B29: 0 | C29: 0 | D29: 0 | E29: 0.3 | F29: 0.3 | G29: 0.3 | H29: 0.3 | I29: 0.3 | J29: 0.3 | K29: 0.3 | L29: 0.3 | M29: 0.3 | N29: 0.3 | O29: 0.3 | P29: 0.3 | Q29: 0.3 | R29: 0.3 | S29: 0.3 | T29: 0.3 | U29: 0.3 | V29: 0.3 | W29: 0.3 | X29: 0.3 | Y29: 0.3 | Z29: 0.3 | AA29: 0.3 | AB29: 0.3 | AC29: - -
A30: Idled Capacity | B30: 0 | C30: 0 | D30: 0.1 | E30: 0.1 | F30: 0.2 | G30: 0.2 | H30: 0.2 | I30: 0.3 | J30: 0.4 | K30: 0.5 | L30: 0.5 | M30: 0.9 | N30: 0.9 | O30: 0.9 | P30: 0.9 | Q30: 0.9 | R30: 0.9 | S30: 0.9 | T30: 0.9 | U30: 1 | V30: 1 | W30: 1.1 | X30: 1.2 | Y30: 1.3 | Z30: 1.3 | AA30: 1.3 | AB30: 1.3 | AC30: - -
A31: Total Capacity | B31: 8.4 | C31: 8.6 | D31: 8.6 | E31: 8.6 | F31: 8.8 | G31: 8.8 | H31: 8.7 | I31: 8.7 | J31: 8.5 | K31: 8.4 | L31: 8.4 | M31: 8.1 | N31: 8.1 | O31: 8.1 | P31: 8.1 | Q31: 8.1 | R31: 8 | S31: 8 | T31: 8 | U31: 8 | V31: 7.9 | W31: 7.8 | X31: 7.8 | Y31: 7.7 | Z31: 7.7 | AA31: 7.7 | AB31: 7.7 | AC31: -0.005
A33: PAD District IV
A34: Base Capacity | B34: 0.6 | C34: 0.6 | D34: 0.6 | E34: 0.6 | F34: 0.6 | G34: 0.6 | H34: 0.6 | I34: 0.6 | J34: 0.6 | K34: 0.6 | L34: 0.6 | M34: 0.6 | N34: 0.6 | O34: 0.6 | P34: 0.6 | Q34: 0.6 | R34: 0.6 | S34: 0.6 | T34: 0.6 | U34: 0.6 | V34: 0.6 | W34: 0.6 | X34: 0.6 | Y34: 0.6 | Z34: 0.6 | AA34: 0.6 | AB34: 0.6 | AC34: 0
A35: Capacity Additions | B35: 0 | C35: 0 | D35: 0 | E35: 0 | F35: 0 | G35: 0 | H35: 0 | I35: 0 | J35: 0 | K35: 0 | L35: 0 | M35: 0 | N35: 0 | O35: 0 | P35: 0 | Q35: 0 | R35: 0 | S35: 0 | T35: 0 | U35: 0 | V35: 0 | W35: 0 | X35: 0 | Y35: 0 | Z35: 0 | AA35: 0 | AB35: 0 | AC35: - -
A36: Idled Capacity | B36: 0 | C36: 0 | D36: 0 | E36: 0 | F36: 0 | G36: 0 | H36: 0 | I36: 0 | J36: 0.1 | K36: 0.1 | L36: 0.1 | M36: 0.1 | N36: 0.1 | O36: 0.1 | P36: 0.1 | Q36: 0.1 | R36: 0.1 | S36: 0.1 | T36: 0.1 | U36: 0.1 | V36: 0.1 | W36: 0.1 | X36: 0.1 | Y36: 0.1 | Z36: 0.1 | AA36: 0.1 | AB36: 0.1 | AC36: - -
A37: Total Capacity | B37: 0.6 | C37: 0.6 | D37: 0.6 | E37: 0.6 | F37: 0.6 | G37: 0.6 | H37: 0.6 | I37: 0.6 | J37: 0.5 | K37: 0.5 | L37: 0.5 | M37: 0.5 | N37: 0.5 | O37: 0.5 | P37: 0.5 | Q37: 0.5 | R37: 0.5 | S37: 0.5 | T37: 0.5 | U37: 0.5 | V37: 0.5 | W37: 0.5 | X37: 0.5 | Y37: 0.5 | Z37: 0.5 | AA37: 0.5 | AB37: 0.5 | AC37: -0.01
A39: PAD District V
A40: Base Capacity | B40: 3.2 | C40: 3.2 | D40: 3.1 | E40: 3.1 | F40: 3.1 | G40: 3.1 | H40: 3.1 | I40: 3.1 | J40: 3.1 | K40: 3.1 | L40: 3.1 | M40: 3.1 | N40: 3.1 | O40: 3.1 | P40: 3.1 | Q40: 3.1 | R40: 3.1 | S40: 3.1 | T40: 3.1 | U40: 3.1 | V40: 3.1 | W40: 3.1 | X40: 3.1 | Y40: 3.1 | Z40: 3.1 | AA40: 3.1 | AB40: 3.1 | AC40: -0.001
A41: Capacity Additions | B41: 0 | C41: 0 | D41: 0 | E41: 0 | F41: 0 | G41: 0 | H41: 0 | I41: 0 | J41: 0 | K41: 0 | L41: 0 | M41: 0 | N41: 0 | O41: 0 | P41: 0 | Q41: 0 | R41: 0 | S41: 0 | T41: 0 | U41: 0 | V41: 0 | W41: 0.1 | X41: 0.1 | Y41: 0.1 | Z41: 0.1 | AA41: 0.1 | AB41: 0.2 | AC41: - -
A42: Idled Capacity | B42: 0 | C42: 0 | D42: 0 | E42: 0 | F42: 0 | G42: 0 | H42: 0 | I42: 0 | J42: 0 | K42: 0 | L42: 0 | M42: 0 | N42: 0 | O42: 0 | P42: 0 | Q42: 0 | R42: 0 | S42: 0 | T42: 0 | U42: 0 | V42: 0 | W42: 0 | X42: 0 | Y42: 0 | Z42: 0 | AA42: 0 | AB42: 0 | AC42: - -
A43: Total Capacity | B43: 3.2 | C43: 3.2 | D43: 3.1 | E43: 3.1 | F43: 3.1 | G43: 3.1 | H43: 3.1 | I43: 3.1 | J43: 3.1 | K43: 3.1 | L43: 3.1 | M43: 3.1 | N43: 3.1 | O43: 3.1 | P43: 3.1 | Q43: 3.1 | R43: 3.1 | S43: 3.1 | T43: 3.1 | U43: 3.1 | V43: 3.1 | W43: 3.2 | X43: 3.2 | Y43: 3.2 | Z43: 3.2 | AA43: 3.2 | AB43: 3.2 | AC43: 0
A45: United States
A46: Base Capacity | B46: 17.7 | C46: 17.6 | D46: 17.7 | E46: 17.7 | F46: 17.7 | G46: 17.7 | H46: 17.7 | I46: 17.7 | J46: 17.7 | K46: 17.7 | L46: 17.7 | M46: 17.7 | N46: 17.7 | O46: 17.7 | P46: 17.7 | Q46: 17.7 | R46: 17.7 | S46: 17.7 | T46: 17.7 | U46: 17.7 | V46: 17.7 | W46: 17.7 | X46: 17.7 | Y46: 17.7 | Z46: 17.7 | AA46: 17.7 | AB46: 17.7 | AC46: 0
A47: Capacity Additions | B47: 0 | C47: 0 | D47: 0 | E47: 0.4 | F47: 0.4 | G47: 0.4 | H47: 0.4 | I47: 0.4 | J47: 0.4 | K47: 0.4 | L47: 0.4 | M47: 0.4 | N47: 0.4 | O47: 0.4 | P47: 0.4 | Q47: 0.4 | R47: 0.4 | S47: 0.4 | T47: 0.4 | U47: 0.4 | V47: 0.5 | W47: 0.6 | X47: 0.6 | Y47: 0.6 | Z47: 0.5 | AA47: 0.6 | AB47: 0.6 | AC47: - -
A48: Idled Capacity | B48: 0 | C48: 0 | D48: 0.3 | E48: 0.4 | F48: 0.4 | G48: 0.5 | H48: 0.6 | I48: 0.8 | J48: 1.3 | K48: 1.6 | L48: 1.8 | M48: 2.3 | N48: 2.4 | O48: 2.4 | P48: 2.5 | Q48: 2.5 | R48: 2.6 | S48: 2.6 | T48: 2.6 | U48: 2.7 | V48: 2.7 | W48: 2.8 | X48: 2.9 | Y48: 2.9 | Z48: 2.9 | AA48: 2.9 | AB48: 3 | AC48: - -
...

Sheet PADD Products
B1: 1 | C1: 2 | D1: 3 | E1: 4 | F1: 5 | I1: 1 | J1: 2 | K1: 3 | L1: 4 | M1: 5
B2: PADD1 | C2: PADD2 | D2: PADD3 | E2: PADD4 | F2: PADD5 | I2: PADD1 | J2: PADD2 | K2: PADD3 | L2: PADD4 | M2: PADD5
A3: LPG_E | B3: {=SUM(IF(Yields!$A$4:$A$99=1,Yields!$C$4:$C$99,0))} -> 3.46 | C3: {=SUM(IF(Yields!$A$4:$A$99=2,Yields!$C$4:$C$99,0))} -> 3.375 | D3: {=SUM(IF(Yields!$A$4:$A$99=3,Yields!$C$4:$C$99,0))} -> 5.225 | E3: {=SUM(IF(Yields!$A$4:$A$99=4,Yields!$C$4:$C$99,0))} -> 1.75 | F3: {=SUM(IF(Yields!$A$4:$A$99=5,Yields!$C$4:$C$99,0))} -> 2.675 | H3: LPG_E | I3: =B3*1.08 -> 3.7368 | J3: =C3*1.08 -> 3.645 | K3: =D3*1.08 -> 5.643 | L3: =E3*1.08 -> 1.89 | M3: =F3*1.08 -> 2.889
A4: GSR_E | B4: {=SUM(IF(Yields!$A$4:$A$99=1,Yields!$D$4:$D$99,0))} -> 46.14 | C4: {=SUM(IF(Yields!$A$4:$A$99=2,Yields!$D$4:$D$99,0))} -> 50.325 | D4: {=SUM(IF(Yields!$A$4:$A$99=3,Yields!$D$4:$D$99,0))} -> 42.15 | E4: {=SUM(IF(Yields!$A$4:$A$99=4,Yields!$D$4:$D$99,0))} -> 47.825 | F4: {=SUM(IF(Yields!$A$4:$A$99=5,Yields!$D$4:$D$99,0))} -> 47.2 | H4: GSR_E | I4: =B4*1.18 -> 54.4452 | J4: =C4*1.18 -> 59.3835 | K4: =D4*1.18 -> 49.737 | L4: =E4*1.18 -> 56.4335 | M4: =F4*1.18 -> 55.696
A5: GSC_E | H5: GSC_E | I5: =B5*1.08 -> 0 | J5: =C5*1.08 -> 0 | K5: =D5*1.08 -> 0 | L5: =E5*1.08 -> 0 | M5: =F5*1.08 -> 0
A6: JTF_E | B6: {=SUM(IF(Yields!$A$4:$A$99=1,Yields!$F$4:$F$99,0))} -> 5.66 | C6: {=SUM(IF(Yields!$A$4:$A$99=2,Yields!$F$4:$F$99,0))} -> 6.55 | D6: {=SUM(IF(Yields!$A$4:$A$99=3,Yields!$F$4:$F$99,0))} -> 9.275 | E6: {=SUM(IF(Yields!$A$4:$A$99=4,Yields!$F$4:$F$99,0))} -> 4.925 | F6: {=SUM(IF(Yields!$A$4:$A$99=5,Yields!$F$4:$F$99,0))} -> 16.8 | H6: JTF_E | I6: =B6*1.08 -> 6.1128 | J6: =C6*1.08 -> 7.074 | K6: =D6*1.08 -> 10.017 | L6: =E6*1.08 -> 5.319 | M6: =F6*1.08 -> 18.144
A7: KER_E | B7: {=SUM(IF(Yields!$A$4:$A$99=1,Yields!$G$4:$G$99,0))} -> 0.38 | C7: {=SUM(IF(Yields!$A$4:$A$99=2,Yields!$G$4:$G$99,0))} -> 0.025 | D7: {=SUM(IF(Yields!$A$4:$A$99=3,Yields!$G$4:$G$99,0))} -> 0.075 | E7: {=SUM(IF(Yields!$A$4:$A$99=4,Yields!$G$4:$G$99,0))} -> 0.25 | F7: {=SUM(IF(Yields!$A$4:$A$99=5,Yields!$G$4:$G$99,0))} -> 0.025 | H7: KER_E | I7: =B7*1.08 -> 0.4104 | J7: =C7*1.08 -> 0.027 | K7: =D7*1.08 -> 0.081 | L7: =E7*1.08 -> 0.27 | M7: =F7*1.08 -> 0.027
A8: DSU_E | B8: {=SUM(IF(Yields!$A$4:$A$99=1,Yields!$H$4:$H$99,0))*(1-'DSH percent'!Q2)} -> 18.941966 | C8: {=SUM(IF(Yields!$A$4:$A$99=2,Yields!$H$4:$H$99,0))*(1-'DSH percent'!Q3)} -> 28.805417 | D8: {=SUM(IF(Yields!$A$4:$A$99=3,Yields!$H$4:$H$99,0))*(1-'DSH percent'!Q4)} -> 26.332062 | E8: {=SUM(IF(Yields!$A$4:$A$99=4,Yields!$H$4:$H$99,0))} -> 32.025 | F8: {=SUM(IF(Yields!$A$4:$A$99=5,Yields!$H$4:$H$99,0))*(1-'DSH percent'!Q6)} -> 19.606299 | H8: DSU_E | I8: =B8*1.15 -> 21.783261 | J8: =C8*1.15 -> 33.126229 | K8: =D8*1.15 -> 30.281872 | L8: =E8*1.15 -> 36.82875 | M8: =F8*1.15 -> 22.547244
A9: DSL_E | H9: DSL_E | I9: =B9*1.08 -> 0 | J9: =C9*1.08 -> 0 | K9: =D9*1.08 -> 0 | L9: =E9*1.08 -> 0 | M9: =F9*1.08 -> 0
A10: DSH_E | B10: {=SUM(IF(Yields!$A$4:$A$99=1,Yields!$H$4:$H$99,0))*'DSH percent'!Q2} -> 10.758034 | C10: {=SUM(IF(Yields!$A$4:$A$99=2,Yields!$H$4:$H$99,0))*'DSH percent'!Q3} -> 0.19458322 | D10: {=SUM(IF(Yields!$A$4:$A$99=3,Yields!$H$4:$H$99,0))*'DSH percent'!Q4} -> 2.4679377 | E10: 0 | F10: {=SUM(IF(Yields!$A$4:$A$99=5,Yields!$H$4:$H$99,0))*'DSH percent'!Q6} -> 1.6187012 | H10: DSH_E | I10: =B10*1.08 -> 11.618676 | J10: =C10*1.08 -> 0.21014988 | K10: =D10*1.08 -> 2.6653728 | L10: =E10*1.08 -> 0 | M10: =F10*1.08 -> 1.7481973
A11: RFL_E | B11: {=SUM(IF(Yields!$A$4:$A$99=1,Yields!$I$4:$I$99,0))} -> 5.94 | C11: {=SUM(IF(Yields!$A$4:$A$99=2,Yields!$I$4:$I$99,0))} -> 1.45 | D11: {=SUM(IF(Yields!$A$4:$A$99=3,Yields!$I$4:$I$99,0))} -> 4 | E11: {=SUM(IF(Yields!$A$4:$A$99=4,Yields!$I$4:$I$99,0))} -> 1.8 | F11: {=SUM(IF(Yields!$A$4:$A$99=5,Yields!$I$4:$I$99,0))} -> 5.325 | H11: RFL_E | I11: =B11*1.08 -> 6.4152 | J11: =C11*1.08 -> 1.566 | K11: =D11*1.08 -> 4.32 | L11: =E11*1.08 -> 1.944 | M11: =F11*1.08 -> 5.751
A12: RFH_E | H12: RFH_E | I12: =I11 -> 6.4152 | J12: =J11 -> 1.566 | K12: =K11 -> 4.32 | L12: =L11 -> 1.944 | M12: =M11 -> 5.751
A13: PFS_E | B13: {=SUM(IF(Yields!$A$4:$A$99=1,Yields!$J$4:$J$99,0))+SUM(IF(Yields!$A$4:$A$99=1,Yields!$K$4:$K$99,0))} -> 0.76 | C13: {=SUM(IF(Yields!$A$4:$A$99=2,Yields!$J$4:$J$99,0))+SUM(IF(Yields!$A$4:$A$99=2,Yields!$K$4:$K$99,0))} -> 1.025 | D13: {=SUM(IF(Yields!$A$4:$A$99=3,Yields!$J$4:$J$99,0))+SUM(IF(Yields!$A$4:$A$99=3,Yields!$K$4:$K$99,0))} -> 3.6 | E13: {=SUM(IF(Yields!$A$4:$A$99=4,Yields!$J$4:$J$99,0))+SUM(IF(Yields!$A$4:$A$99=4,Yields!$K$4:$K$99,0))} -> 0.15 | F13: {=SUM(IF(Yields!$A$4:$A$99=5,Yields!$J$4:$J$99,0))+SUM(IF(Yields!$A$4:$A$99=5,Yields!$K$4:$K$99,0))} -> 0.066666667 | H13: PFS_E | I13: =B13*1.08 -> 0.8208 | J13: =C13*1.08 -> 1.107 | K13: =D13*1.08 -> 3.888 | L13: =E13*1.08 -> 0.162 | M13: =F13*1.08 -> 0.072
A14: PTC_E | B14: {=SUM(IF(Yields!$A$4:$A$99=1,Yields!$O$4:$O$99,0))} -> 3.1 | C14: {=SUM(IF(Yields!$A$4:$A$99=2,Yields!$O$4:$O$99,0))} -> 4.35 | D14: {=SUM(IF(Yields!$A$4:$A$99=3,Yields!$O$4:$O$99,0))} -> 6 | E14: {=SUM(IF(Yields!$A$4:$A$99=4,Yields!$O$4:$O$99,0))} -> 4.375 | F14: {=SUM(IF(Yields!$A$4:$A$99=5,Yields!$O$4:$O$99,0))} -> 6.15 | H14: PTC_E | I14: =B14*1.08 -> 3.348 | J14: =C14*1.08 -> 4.698 | K14: =D14*1.08 -> 6.48 | L14: =E14*1.08 -> 4.725 | M14: =F14*1.08 -> 6.642
A15: ASP_E | B15: {=SUM(IF(Yields!$A$4:$A$99=1,Yields!$P$4:$P$99,0))} -> 4.98 | C15: {=SUM(IF(Yields!$A$4:$A$99=2,Yields!$P$4:$P$99,0))} -> 4.95 | D15: {=SUM(IF(Yields!$A$4:$A$99=3,Yields!$P$4:$P$99,0))} -> 1.125 | E15: {=SUM(IF(Yields!$A$4:$A$99=4,Yields!$P$4:$P$99,0))} -> 5.875 | F15: {=SUM(IF(Yields!$A$4:$A$99=5,Yields!$P$4:$P$99,0))} -> 1.275 | H15: ASP_E | I15: =B15*1.08 -> 5.3784 | J15: =C15*1.08 -> 5.346 | K15: =D15*1.08 -> 1.215 | L15: =E15*1.08 -> 6.345 | M15: =F15*1.08 -> 1.377
B16: =SUM(B3:B15) -> 100.12 | C16: =SUM(C3:C15) -> 101.05 | D16: =SUM(D3:D15) -> 100.25 | E16: =SUM(E3:E15) -> 98.975 | F16: =SUM(F3:F15) -> 100.74167 | I16: =SUM(I3:I15) -> 120.48474 | J16: =SUM(J3:J15) -> 117.74888 | K16: =SUM(K3:K15) -> 118.64824 | L16: =SUM(L3:L15) -> 115.86125 | M16: =SUM(M3:M15) -> 120.64444

Sheet Yields
B1: Back to Contents | C1: Data 1: PADD 1 Refinery Yield
B2: Sourcekey | C2: MLRRYP13 | D2: MGFRYP13 | E2: MGARYP13 | F2: MKJRYP13 | G2: MKERYP13 | H2: MDIRYP13 | I2: MRERYP13 | J2: MNFRYP13 | K2: MOTRYP13 | L2: MNSRYP13 | M2: MLURYP13 | N2: MWXRYP13 | O2: MCKRYP13 | P2: MAPRYP13 | Q2: MSGRYP13 | R2: MMSRYP13 | S2: MPGRYP13
A3: PADD | B3: Date | C3: East Coast (PADD 1) Refinery Yield of Liquified Petroleum Gases (Percent) | D3: East Coast (PADD 1) Refinery Yield of Finished Motor Gasoline (Percent) | E3: East Coast (PADD 1) Refinery Yield of Aviation Gasoline (Percent) | F3: East Coast (PADD 1) Refinery Yield of Kerosene-Type Jet Fuel (Percent) | G3: East Coast (PADD 1) Refinery Yield of Kerosene (Percent) | H3: East Coast (PADD 1) Refinery Yield of Distillate Fuel Oil (Percent) | I3: East Coast (PADD 1) Refinery Yield of Residual Fuel Oil (Percent) | J3: East Coast (PADD 1) Refinery Yield of Naphtha for Petrochemical Feedstock Use (Percent) | K3: East Coast (PADD 1) Refinery Yield of Other Oils for Petrochemical Feedstock Use (Percent) | L3: East Coast (PADD 1) Refinery Yield of Special Naphthas (Percent) | M3: East Coast (PADD 1) Refinery Yield of Lubricants (Percent) | N3: East Coast (PADD 1) Refinery Yield of Waxes (Percent) | O3: East Coast (PADD 1) Refinery Yield of Petroleum Coke (Percent) | P3: East Coast (PADD 1) Refinery Yield of Asphalt and Road Oil (Percent) | Q3: East Coast (PADD 1) Refinery Yield of Still Gas (Percent) | R3: East Coast (PADD 1) Refinery Yield of Miscellaneous Petroleum Products (Percent) | S3: East Coast (PADD 1) Refinery Processing Gain (Percent)
C4: LPG | D4: GSL | F4: JTF | G4: KER | H4: DSL | I4: RFL | J4: PFS | K4: PFS | O4: PTC | P4: ASP
B5: 37802 | C5: 3 | D5: 46.4 | E5: 0.2 | F5: 5.2 | G5: 0.8 | H5: 27.2 | I5: 7.8 | J5: 0.8 | L5: 0.1 | M5: 1 | N5: 0 | O5: 2.9 | P5: 5.7 | Q5: 3.8 | R5: 0.1 | S5: -5 | T5: =SUM(C5:R5) -> 105
B6: 38168 | C6: 2.6 | D6: 46.5 | E6: 0.4 | F6: 6.1 | G6: 0.7 | H6: 26.6 | I6: 6.9 | J6: 0.8 | L6: 0.1 | M6: 1.1 | N6: 0 | O6: 3.1 | P6: 6.2 | Q6: 3.9 | R6: 0.1 | S6: -5.3 | T6: =SUM(C6:R6) -> 105.1
B7: 38533 | C7: 2.4 | D7: 46.6 | E7: 0.3 | F7: 5.7 | G7: 0.7 | H7: 28.8 | I7: 6.2 | J7: 0.8 | L7: 0.1 | M7: 1 | N7: 0 | O7: 2.9 | P7: 5.7 | Q7: 3.8 | R7: 0.1 | S7: -5.1 | T7: =SUM(C7:R7) -> 105.1
B8: 38898 | C8: 2.6 | D8: 45.8 | F8: 5.1 | G8: 0.4 | H8: 29.2 | I8: 7.1 | J8: 1.1 | L8: 0.1 | M8: 1.1 | N8: 0 | O8: 3 | P8: 5.6 | Q8: 3.6 | R8: 0.2 | S8: -4.9 | T8: =SUM(C8:R8) -> 104.9
B9: 39263 | C9: 3.2 | D9: 45.5 | E9: 0.1 | F9: 5 | G9: 0.5 | H9: 29.4 | I9: 7.2 | J9: 1.1 | L9: 0 | M9: 1 | N9: 0 | O9: 3.2 | P9: 5 | Q9: 3.9 | R9: 0.2 | S9: -5.1 | T9: =SUM(C9:R9) -> 105.3
B10: 39629 | C10: 3.3 | D10: 44.6 | E10: 0.1 | F10: 5.7 | G10: 0.6 | H10: 29.6 | I10: 7.1 | J10: 1.1 | L10: 0 | M10: 1.1 | N10: 0.1 | O10: 3.3 | P10: 5.1 | Q10: 3.8 | R10: 0.2 | S10: -5.4 | T10: =SUM(C10:R10) -> 105.7
B11: 39994 | C11: 3.4 | D11: 47 | E11: 0.1 | F11: 5.3 | G11: 0.6 | H11: 27.7 | I11: 7.4 | J11: 0.9 | K11: 0 | L11: 0.1 | M11: 1 | N11: 0.1 | O11: 2.9 | P11: 4.8 | Q11: 3.2 | R11: 0.1 | S11: -4.3 | T11: =SUM(C11:R11) -> 104.6
B12: 40359 | C12: 3.3 | D12: 46.7 | E12: 0.1 | F12: 5.7 | G12: 0.4 | H12: 29.9 | I12: 5.4 | J12: 0.8 | K12: 0 | L12: 0.1 | M12: 1.1 | N12: 0 | O12: 2.8 | P12: 5.1 | Q12: 3.2 | R12: 0.1 | S12: -4.7 | T12: =SUM(C12:R12) -> 104.7
B13: 40724 | C13: 3.7 | D13: 46.2 | E13: 0.1 | F13: 6.8 | G13: 0.2 | H13: 30 | I13: 4.9 | J13: 0.6 | K13: 0 | L13: 0.1 | M13: 1.2 | N13: 0 | O13: 3.1 | P13: 4.8 | Q13: 3.3 | R13: 0.2 | S13: -5 | T13: =SUM(C13:R13) -> 105.2
B14: 41090 | C14: 3.6 | D14: 46.2 | E14: 0.1 | F14: 4.8 | G14: 0.1 | H14: 31.3 | I14: 4.9 | J14: 0.4 | K14: 0 | L14: 0.1 | M14: 1.3 | N14: 0 | O14: 3.4 | P14: 5.1 | Q14: 3.6 | R14: 0.3 | S14: -5.1
B15: 41455 | C15: 3.3 | D15: 45 | E15: 0.1 | F15: 6.4 | G15: 0.2 | H15: 31.3 | I15: 5.8 | J15: 0.3 | K15: 0 | L15: 0.1 | M15: 1.3 | N15: 0 | O15: 2.8 | P15: 4.5 | Q15: 3.4 | R15: 0.2 | S15: -4.5
B16: 41820 | C16: 3.5 | D16: 46.3 | E16: 0.1 | F16: 8 | G16: 0.5 | H16: 28.9 | I16: 4.8 | J16: 0.3 | K16: 0 | L16: 0.1 | M16: 1.1 | N16: 0 | O16: 2.8 | P16: 4.4 | Q16: 3.5 | R16: 0.3 | S16: -4.5
B17: 42185 | C17: 3.3 | D17: 46.7 | E17: 0.1 | F17: 8.1 | G17: 0.3 | H17: 28.8 | I17: 4.1 | J17: 0.4 | K17: 0 | L17: 0.1 | M17: 1 | N17: 0 | O17: 3 | P17: 4.7 | Q17: 3.6 | R17: 0.2 | S17: -4.3
B18: 42551 | C18: 2.6 | D18: 47.5 | E18: 0.1 | F18: 7.6 | G18: 0.2 | H18: 29 | I18: 4.1 | J18: 0.4 | K18: 0 | L18: 0.1 | M18: 1.1 | N18: 0 | O18: 3.1 | P18: 4.5 | Q18: 3.6 | R18: 0.2 | S18: -4
B19: 42916 | C19: 2.8 | D19: 48.6 | E19: 0.1 | F19: 8.1 | G19: 0.3 | H19: 28.7 | I19: 3.9 | J19: 0.3 | K19: 0 | L19: 0.1 | M19: 1.1 | N19: 0 | O19: 3.1 | P19: 3.4 | Q19: 3.7 | R19: 0.3 | S19: -4.3
B20: 43281 | C20: 3.3 | D20: 46.6 | E20: 0.1 | F20: 8.2 | G20: 0.4 | H20: 29.5 | I20: 4.4 | J20: 0.3 | K20: 0 | L20: 0.1 | M20: 1.2 | N20: 0.1 | O20: 3.1 | P20: 3.1 | Q20: 4 | R20: 0.3 | S20: -4.4
B21: 43646 | C21: 3.3 | D21: 47.2 | E21: 0.1 | F21: 10.3 | G21: 0.3 | H21: 27.7 | I21: 3.6 | J21: 0.1 | K21: 0 | L21: 0.1 | M21: 1.3 | N21: 0 | O21: 2.8 | P21: 3.7 | Q21: 4.1 | R21: 0.3 | S21: -4.8
B22: 44012 | C22: 2.8 | D22: 50.7 | E22: 0.1 | F22: 4.7 | G22: 0.4 | H22: 27.7 | I22: 4.6 | J22: 0 | K22: 0 | L22: 0.1 | M22: 1.6 | N22: -0.1 | O22: 3.2 | P22: 4.9 | Q22: 4.2 | R22: 0.4 | S22: -5.2
B23: 44377 | C23: 2.9 | D23: 51.2 | E23: 0.1 | F23: 7.8 | G23: 0.2 | H23: 24.9 | I23: 5.6 | J23: 0 | K23: 0 | L23: 0.1 | M23: 1.6 | N23: -0.1 | O23: 3 | P23: 4.3 | Q23: 3.9 | R23: 0.4 | S23: -5.8
B24: 44742 | C24: 2.7 | D24: 46.1 | E24: 0.1 | F24: 11.4 | G24: 0.3 | H24: 26.2 | I24: 5.4 | J24: 0 | K24: 0 | L24: 0 | M24: 1.6 | N24: 0 | O24: 2.9 | P24: 4.1 | Q24: 3.5 | R24: 0.4 | S24: -4.6
B30: 2005 | C30: =AVERAGE(C5:C9) -> 2.76 | D30: =AVERAGE(D5:D9) -> 46.16 | E30: =AVERAGE(E5:E9) -> 0.25 | F30: =AVERAGE(F5:F9) -> 5.42 | G30: =AVERAGE(G5:G9) -> 0.62 | H30: =AVERAGE(H5:H9) -> 28.24 | I30: =AVERAGE(I5:I9) -> 7.04 | J30: =AVERAGE(J5:J9) -> 0.92 | L30: =AVERAGE(L5:L9) -> 0.08 | M30: =AVERAGE(M5:M9) -> 1.04 | N30: =AVERAGE(N5:N9) -> 0 | O30: =AVERAGE(O5:O9) -> 3.02 | P30: =AVERAGE(P5:P9) -> 5.64 | Q30: =AVERAGE(Q5:Q9) -> 3.8 | R30: =AVERAGE(R5:R9) -> 0.14 | S30: =AVERAGE(S5:S9) -> -5.08 | T30: =E30+L30+M30+N30+Q30+R30 -> 5.31
A31: 1 | B31: 2010 | C31: =AVERAGE(C10:C14) -> 3.46 | D31: =AVERAGE(D10:D14) -> 46.14 | E31: =AVERAGE(E10:E14) -> 0.1 | F31: =AVERAGE(F10:F14) -> 5.66 | G31: =AVERAGE(G10:G14) -> 0.38 | H31: =AVERAGE(H10:H14) -> 29.7 | I31: =AVERAGE(I10:I14) -> 5.94 | J31: =AVERAGE(J10:J14) -> 0.76 | ... S31: =AVERAGE(S10:S14) -> -4.9
B32: 2015 | C32: =AVERAGE(C15:C19) -> 3.1 | D32: =AVERAGE(D15:D19) -> 46.82 | E32: =AVERAGE(E15:E19) -> 0.1 | F32: =AVERAGE(F15:F19) -> 7.64 | G32: =AVERAGE(G15:G19) -> 0.3 | H32: =AVERAGE(H15:H19) -> 29.34 | I32: =AVERAGE(I15:I19) -> 4.54 | J32: =AVERAGE(J15:J19) -> 0.34 | ... S32: =AVERAGE(S15:S19) -> -4.32
B33: 2020 | C33: =AVERAGE(C20:C24) -> 3 | D33: =AVERAGE(D20:D24) -> 48.36 | E33: =AVERAGE(E20:E24) -> 0.1 | F33: =AVERAGE(F20:F24) -> 8.48 | G33: =AVERAGE(G20:G24) -> 0.32 | H33: =AVERAGE(H20:H24) -> 27.2 | I33: =AVERAGE(I20:I24) -> 4.72 | J33: =AVERAGE(J20:J24) -> 0.08 | ... S33: =AVERAGE(S20:S24) -> -4.96
B34: Back to Contents | C34: Data 1: PADD 2 Refinery Yield
B35: Sourcekey | C35: MLRRYP23 | D35: MGFRYP23 | E35: MGARYP23 | F35: MKJRYP23 | G35: MKERYP23 | H35: MDIRYP23 | I35: MRERYP23 | J35: MNFRYP23 | K35: MOTRYP23 | L35: MNSRYP23 | M35: MLURYP23 | N35: MWXRYP23 | O35: MCKRYP23 | P35: MAPRYP23 | Q35: MSGRYP23 | R35: MMSRYP23 | S35: MPGRYP23
B36: 37437 | C36: 3.5 | D36: 52 | E36: 0.1 | F36: 6.7 | G36: 0.3 | H36: 25.4 | I36: 1.8 | J36: 0.6 | K36: 0 | L36: 0.5 | M36: 0.5 | N36: 0.1 | O36: 4.1 | P36: 5.3 | Q36: 4 | R36: 0.4 | S36: -5.2
B37: 37802 | C37: 3.3 | D37: 51.5 | E37: 0.1 | F37: 6.2 | G37: 0.3 | H37: 26 | I37: 1.7 | J37: 0.5 | K37: 0 | L37: 0.6 | M37: 0.5 | N37: 0.1 | O37: 4.2 | P37: 5.6 | Q37: 4.1 | R37: 0.4 | S37: -5.1
B38: 38168 | C38: 3.3 | D38: 51.6 | E38: 0.1 | F38: 6.4 | G38: 0.3 | H38: 25.7 | I38: 1.8 | J38: 0.8 | K38: 0.3 | L38: 0.1 | M38: 0.4 | N38: 0.1 | O38: 4.3 | P38: 5.7 | Q38: 4.1 | R38: 0.4 | S38: -5.4
B39: 38533 | C39: 3.1 | D39: 50.4 | E39: 0.1 | F39: 6.5 | G39: 0.3 | H39: 27.1 | I39: 1.6 | J39: 0.8 | K39: 0.3 | L39: 0.2 | M39: 0.4 | N39: 0.1 | O39: 4.5 | P39: 5.7 | Q39: 4.1 | R39: 0.5 | S39: -5.8
B40: 38898 | C40: 4 | D40: 49.4 | E40: 0.1 | F40: 6.2 | G40: 0.3 | H40: 27.3 | I40: 1.7 | J40: 0.9 | K40: 0.2 | L40: 0.2 | M40: 0.5 | N40: 0.1 | O40: 4.4 | P40: 6.1 | Q40: 4.1 | R40: 0.5 | S40: -5.9
B41: 39263 | C41: 3.9 | D41: 49.8 | E41: 0.1 | F41: 6.1 | G41: 0.1 | H41: 28.2 | I41: 1.7 | J41: 0.9 | K41: 0.2 | L41: 0.1 | M41: 0.4 | N41: 0.1 | O41: 4.3 | P41: 5.3 | Q41: 4.2 | R41: 0.4 | S41: -5.8
B42: 39629 | C42: 3.5 | D42: 48.5 | E42: 0.1 | F42: 6.3 | G42: 0 | H42: 30 | I42: 1.6 | J42: 0.8 | K42: 0.2 | L42: 0.1 | M42: 0.4 | N42: 0.1 | O42: 4.3 | P42: 5.3 | Q42: 4 | R42: 0.4 | S42: -5.6
B43: 39994 | C43: 3.3 | D43: 51.6 | E43: 0.1 | F43: 6.5 | G43: 0 | H43: 28.1 | I43: 1.5 | J43: 0.7 | K43: 0.2 | L43: 0 | M43: 0.2 | N43: 0 | O43: 4.4 | P43: 4.6 | Q43: 4.1 | R43: 0.4 | S43: -5.7
B44: 40359 | C44: 3.4 | D44: 50.6 | E44: 0.1 | F44: 6.6 | G44: 0 | H44: 28.9 | I44: 1.3 | J44: 0.8 | K44: 0.3 | L44: 0 | M44: 0.2 | N44: 0.1 | O44: 4.3 | P44: 5 | Q44: 3.8 | R44: 0.4 | S44: -5.9
B45: 40724 | C45: 3.3 | D45: 50.6 | E45: 0.1 | F45: 6.8 | G45: 0.1 | H45: 29 | I45: 1.4 | J45: 0.8 | K45: 0.3 | L45: 0 | M45: 0.2 | N45: 0 | O45: 4.4 | P45: 4.9 | Q45: 3.8 | R45: 0.4 | S45: -5.9
...

Sheet Utilization
A1: Utilization
F2: Average | J2: Crude Oil Input
A3: PADD 1 | B3: 2010-2011 | C3: =AVERAGE(B22:B73) -> 1045.1923 | D3: =AVERAGE(E22:E73) -> 73.042308
B4: 2011-2012 | C4: =AVERAGE(C74:C126) -> 1061.8868 | D4: =AVERAGE(E74:E126) -> 70.764151 | F4: =AVERAGE(C3:C4) -> 1053.5396 | G4: =AVERAGE(D3:D4) -> 71.903229 | J4: =F4*365*Conv!$C$47*Conv!$I$6*10^-6 -> 2401.6951
A6: PADD 2 | B6: 2010-2011 | C6: =AVERAGE(B139:B190) -> 3299.6346 | D6: =AVERAGE(E139:E190) -> 89.621154
B7: 2011-2012 | C7: =AVERAGE(B191:B243) -> 3440.4151 | D7: =AVERAGE(E191:E243) -> 93.266038 | F7: =AVERAGE(C6:C7) -> 3370.0249 | G7: =AVERAGE(D6:D7) -> 91.443596 | J7: =F7*365*Conv!$C$47*Conv!$I$6*10^-6 -> 7682.4569
A9: PADD 3 | B9: 2010-2011 | C9: =AVERAGE(B255:B306) -> 7342.8846 | D9: =AVERAGE(E255:E306) -> 87.751923
B10: 2011-2012 | C10: =AVERAGE(B307:B360) -> 7487 | D10: =AVERAGE(E307:E360) -> 87.977778 | F10: =AVERAGE(C9:C10) -> 7414.9423 | G10: =AVERAGE(D9:D10) -> 87.86485 | J10: =F10*365*Conv!$C$47*Conv!$I$6*10^-6 -> 16903.429
A12: PADD 4 | B12: 2010-2011 | C12: =AVERAGE(B372:B423) -> 536.84615 | D12: =AVERAGE(E372:E423) -> 86.544231
B13: 2011-2012 | C13: =AVERAGE(B424:B477) -> 551.07407 | D13: =AVERAGE(E424:E477) -> 88.914815 | F13: =AVERAGE(C12:C13) -> 543.96011 | G13: =AVERAGE(D12:D13) -> 87.729523 | J13: =F13*365*Conv!$C$47*Conv!$I$6*10^-6 -> 1240.0354
A15: PADD 5 | B15: 2010-2011 | C15: =AVERAGE(B488:B539) -> 2342.3269 | D15: =AVERAGE(E488:E539) -> 79.594231
B16: 2011-2012 | C16: =AVERAGE(B540:B593) -> 2376.3704 | D16: =AVERAGE(E540:E593) -> 80.944444 | F16: =AVERAGE(C15:C16) -> 2359.3486 | G16: =AVERAGE(D15:D16) -> 80.269338 | J16: =F16*365*Conv!$C$47*Conv!$I$6*10^-6 -> 5378.475
J18: =SUM(J4:J17) -> 33606.091
A19: Back to Contents | B19: Data 1: Refiner Inputs and Utilization
A20: Sourcekey | B20: WCRRIP12 | C20: WGIRIP12 | D20: W_NA_YRL_R10_MBBLD | E20: W_NA_YUP_R10_PER
A21: Date | B21: 4-Week Avg East Coast (PADD 1) Refiner Net Input of Crude Oil (Thousand Barrels per Day) | C21: 4-Week Avg East Coast (PADD 1) Gross Inputs into Refineries (Thousand Barrels per Day) | D21: 4-Week Avg East Coast (PADD 1) Operable Crude Oil Distillation Capacity (Thousand Barrels per Calendar Day) | E21: 4-Week Avg East Coast (PADD 1) Percent Utilization of Refinery Operable Capacity (Percent)
A22: 40354 | B22: 1207 | C22: 1212 | D22: 1397 | E22: 86.8
A23: 40361 | B23: 1211 | C23: 1219 | D23: 1397 | E23: 87.3
A24: 40368 | B24: 1224 | C24: 1234 | D24: 1397 | E24: 88.3
A25: 40375 | B25: 1243 | C25: 1255 | D25: 1397 | E25: 89.8
A26: 40382 | B26: 1256 | C26: 1273 | D26: 1397 | E26: 91.1
A27: 40389 | B27: 1258 | C27: 1273 | D27: 1397 | E27: 91.1
A28: 40396 | B28: 1230 | C28: 1247 | D28: 1397 | E28: 89.3
A29: 40403 | B29: 1213 | C29: 1229 | D29: 1397 | E29: 88
A30: 40410 | B30: 1199 | C30: 1213 | D30: 1397 | E30: 86.8
A31: 40417 | B31: 1175 | C31: 1190 | D31: 1397 | E31: 85.2
A32: 40424 | B32: 1189 | C32: 1200 | D32: 1397 | E32: 85.9
A33: 40431 | B33: 1164 | C33: 1168 | D33: 1397 | E33: 83.6
... A132: 41124 | B132: 994 | C132: 1002 | D132: 1188 | E132: 84.3
A136: Back to Contents | B136: Data 1: Refiner Inputs and Utilization
A137: Sourcekey | B137: WCRRIP22 | C137: WGIRIP22 | D137: W_NA_YRL_R20_MBBLD | E137: W_NA_YUP_R20_PER
A138: Date | B138: 4-Week Avg Midwest (PADD 2) Refiner Net Input of Crude Oil (Thousand Barrels per Day) | C138: 4-Week Avg Midwest (PADD 2) Gross Inputs into Refineries (Thousand Barrels per Day) | D138: 4-Week Avg Midwest (PADD 2) Operable Crude Oil Distillation Capacity (Thousand Barrels per Calendar Day) | E138: 4-Week Avg Midwest (PADD 2) Percent Utilization of Refinery Operable Capacity (Percent)
A139: 40354 | B139: 3403 | C139: 3434 | D139: 3723 | E139: 92.3
A140: 40361 | B140: 3411 | C140: 3447 | D140: 3723 | E140: 92.6
A141: 40368 | B141: 3444 | C141: 3487 | D141: 3723 | E141: 93.7
A142: 40375 | B142: 3440 | C142: 3485 | D142: 3723 | E142: 93.6
A143: 40382 | B143: 3442 | C143: 3485 | D143: 3723 | E143: 93.6
A144: 40389 | B144: 3451 | C144: 3489 | D144: 3723 | E144: 93.7
A145: 40396 | B145: 3431 | C145: 3472 | D145: 3723 | E145: 93.3
A146: 40403 | B146: 3449 | C146: 3492 | D146: 3723 | E146: 93.8
...

Sheet DSH percent
A1: DSH Percent of DSL Total
A2: Back to Contents | B2: Data 1: East Coast (PADD 1) Weekly Refiner & Blender Net Production | P2: PADD 1 | Q2: =SUM(Q11:Q122)/SUM(N11:N122) -> 0.36222335
P3: PADD 2 | Q3: =SUM(Q129:Q240)/SUM(N129:N240) -> 0.0067097663
P4: PADD 3 | Q4: =SUM(Q246:Q357)/SUM(N246:N357) -> 0.085692282
P5: PADD 4 | Q5: =SUM(Q363:Q474)/SUM(N364:N474) -> -0.0021292399
P6: PADD 5 | Q6: =SUM(Q480:Q591)/SUM(N480:N591) -> 0.076263895
N8: Total | Q8: DSH
A9: Sourcekey | B9: WGFRPP12 | C9: WGRRPP12 | D9: WG1TP_R10_2 | E9: W_EPM0RO_YPT_R10_MBBLD | F9: WG4TP_R10_2 | G9: WG5TP_R10_2 | H9: W_EPM0CAL55_YPT_R10_MBBLD | I9: W_EPM0CAG55_YPT_R10_MBBLD | J9: WG6TP_R10_2 | K9: WKJRPP12 | L9: WKCRPP12 | M9: WKMRPP12 | N9: WDIRPP12 | O9: WD0TP_R10_2 | P9: WD1TP_R10_2 | Q9: WDGRPP12 | R9: WRERPP12 | S9: WPRNPP12
A10: Date | B10: Weekly East Coast (PADD 1) Refiner and Blender Net Production of Finished Motor Gasoline (Thousand Barrels per Day) | C10: Weekly East Coast (PADD 1) Refiner and Blender Net Production of Reformulated Motor Gasoline (Thousand Barrels per Day) | D10: Weekly East Coast (PADD 1) Refiner and Blender Net Production of Finished Reformulated Motor Gasoline with Ethanol (Thousand Barrels per Day) | E10: Weekly East Coast (PADD 1) Refiner and Blender Net Production of Other Finished Reformulated Motor Gasoline (Thousand Barrels per Day) | F10: Weekly East Coast (PADD 1) Refiner and Blender Net Production of Conventional Motor Gasoline (Thousand Barrels per Day) | G10: Weekly East Coast (PADD 1) Refiner and Blender Net Production of Finished Conventional Motor Gasoline with Ethanol (Thousand Barrels per Day) | H10: Weekly East Coast (PADD 1) Refiner and Blender Net Production of Finished Conventional Motor Gasoline, Ed 55 and Lower (Thousand Barrels per Day) | I10: Weekly East Coast (PADD 1) Refiner and Blender Net Production of Finished Conventional Motor Gasoline, Greater than Ed 55 (Thousand Barrels per Day) | J10: Weekly East Coast (PADD 1) Refiner and Blender Net Production of Other Finished Conventional Motor Gasoline (Thousand Barrels per Day) | K10: Weekly East Coast (PADD 1) Refiner and Blender Net Production of Kerosene-Type Jet Fuel (Thousand Barrels per Day) | L10: Weekly East Coast (PADD 1) Refiner and Blender Net Production of Commercial Kerosene-Type Jet Fuel (Thousand Barrels per Day) | M10: Weekly East Coast (PADD 1) Refiner and Blender Net Production of Military Kerosene-Type Jet Fuel (Thousand Barrels per Day) | N10: Weekly East Coast (PADD 1) Refiner and Blender Net Production of Distillate Fuel Oil (Thousand Barrels per Day) | O10: Weekly East Coast (PADD 1) Refiner and Blender Net Production of Distillate Fuel Oil, 0 to 15 ppm Sulfur (Thousand Barrels per Day) | P10: Weekly East Coast (PADD 1) Refiner and Blender Net Production of Distillate Fuel Oil, Greater than 15 to 500 ppm Sulfur (Thousand Barrels per Day) | Q10: Weekly East Coast (PADD 1) Refiner and Blender Net Production of Distillate Fuel Oil Greater than 500 ppm Sulfur (Thousand Barrels per Day) | R10: Weekly East Coast (PADD 1) Refiner and Blender Net Production of Residual Fuel Oil (Thousand Barrels per Day) | S10: Weekly East Coast (PADD 1) Refiner, Blender, and Gas Plant Net Production of Propane and Propylene (Thousand Barrels per Day)
A11: 40354 | B11: 2838 | C11: 1276 | D11: 1276 | E11: 0 | F11: 1562 | G11: 1811 | H11: 1811 | I11: 0 | J11: -249 | K11: 80 | L11: 80 | M11: 0 | N11: 375 | O11: 276 | P11: 4 | Q11: 95 | R11: 67 | S11: 45
A12: 40361 | B12: 2923 | C12: 1317 | D12: 1317 | E12: 0 | F12: 1606 | G12: 1913 | H12: 1913 | I12: 0 | J12: -307 | K12: 83 | L12: 83 | M12: 0 | N12: 353 | O12: 275 | P12: -13 | Q12: 91 | R12: 81 | S12: 44
A13: 40368 | B13: 2881 | C13: 1237 | D13: 1237 | E13: 0 | F13: 1643 | G13: 1824 | H13: 1824 | I13: 0 | J13: -181 | K13: 61 | L13: 61 | M13: 0 | N13: 398 | O13: 261 | P13: -19 | Q13: 156 | R13: 67 | S13: 41
A14: 40375 | B14: 2792 | C14: 1251 | D14: 1251 | E14: 0 | F14: 1541 | G14: 1821 | H14: 1821 | I14: 0 | J14: -280 | K14: 86 | L14: 86 | M14: 0 | N14: 384 | O14: 274 | P14: -24 | Q14: 134 | R14: 65 | S14: 42
A15: 40382 | B15: 2897 | C15: 1290 | D15: 1290 | E15: 0 | F15: 1608 | G15: 1856 | H15: 1856 | I15: 0 | J15: -249 | K15: 70 | L15: 70 | M15: 0 | N15: 388 | O15: 278 | P15: 17 | Q15: 93 | R15: 62 | S15: 45
A16: 40389 | B16: 2849 | C16: 1296 | D16: 1296 | E16: 0 | F16: 1553 | G16: 1824 | H16: 1824 | I16: 0 | J16: -271 | K16: 78 | L16: 78 | M16: 0 | N16: 374 | O16: 274 | P16: -7 | Q16: 107 | R16: 66 | S16: 45
A17: 40396 | B17: 2772 | C17: 1239 | D17: 1239 | E17: 0 | F17: 1533 | G17: 1822 | H17: 1822 | I17: 0 | J17: -289 | K17: 66 | L17: 66 | M17: 0 | N17: 396 | O17: 261 | P17: -2 | Q17: 137 | R17: 53 | S17: 40
A18: 40403 | B18: 2802 | C18: 1252 | D18: 1252 | E18: 0 | F18: 1550 | G18: 1849 | H18: 1849 | I18: 0 | J18: -299 | K18: 81 | L18: 81 | M18: 0 | N18: 398 | O18: 278 | P18: -16 | Q18: 136 | R18: 59 | S18: 45
A19: 40410 | B19: 2844 | C19: 1262 | D19: 1262 | E19: 0 | F19: 1582 | G19: 1885 | H19: 1885 | I19: 0 | J19: -303 | K19: 71 | L19: 71 | M19: 0 | N19: 404 | O19: 291 | P19: 1 | Q19: 112 | R19: 50 | S19: 44
A20: 40417 | B20: 2792 | C20: 1220 | D20: 1220 | E20: 0 | F20: 1573 | G20: 1869 | H20: 1869 | I20: 0 | J20: -297 | K20: 72 | L20: 72 | M20: 0 | N20: 423 | O20: 285 | P20: -34 | Q20: 172 | R20: 64 | S20: 47
A21: 40424 | B21: 2835 | C21: 1279 | D21: 1279 | E21: 0 | F21: 1556 | G21: 1856 | H21: 1856 | I21: 0 | J21: -300 | K21: 83 | L21: 83 | M21: 0 | N21: 403 | O21: 243 | P21: 35 | Q21: 125 | R21: 62 | S21: 49
A22: 40431 | B22: 2727 | C22: 1239 | D22: 1239 | E22: 0 | F22: 1489 | G22: 1793 | H22: 1793 | I22: 0 | J22: -304 | K22: 77 | L22: 77 | M22: 0 | N22: 379 | O22: 232 | P22: -14 | Q22: 162 | R22: 62 | S22: 42
... A122: 41131 | B122: 2975 | C122: 1225 | D122: 1225 | E122: 0 | F122: 1750 | G122: 1938 | H122: 1938 | I122: 0 | J122: -188 | K122: 48 | L122: 48 | M122: 0 | N122: 376 | O122: 241 | P122: 45 | Q122: 90 | R122: 33 | S122: 51
A126: Back to Contents | B126: Data 1: PADD 2 Weekly Refiner & Blender Net Production
A127: Sourcekey | B127: WGFRPP22 | C127: WGRRPP22 | D127: WG1TP_R20_2 | E127: W_EPM0RO_YPT_R20_MBBLD | F127: WG4TP_R20_2 | G127: WG5TP_R20_2 | H127: W_EPM0CAL55_YPT_R20_MBBLD | I127: W_EPM0CAG55_YPT_R20_MBBLD | J127: WG6TP_R20_2 | K127: WKJRPP22 | L127: WKCRPP22 | M127: WKMRPP22 | N127: WDIRPP22 | O127: WD0TP_R20_2 | P127: WD1TP_R20_2 | Q127: WDGRPP22 | R127: WRERPP22 | S127: WPRNPP22
A128: Date | B128: 4-Week Avg Midwest (PADD 2) Refiner and Blender Net Production of Finished Motor Gasoline (Thousand Barrels per Day) | C128: 4-Week Avg Midwest (PADD 2) Refiner and Blender Net Production of Reformulated Motor Gasoline (Thousand Barrels per Day) | D128: 4-Week Avg Midwest (PADD 2) Refiner and Blender Net Production of Finished Reformulated Motor Gasoline with Ethanol (Thousand Barrels per Day) | E128: 4-Week Avg Midwest (PADD 2) Refiner and Blender Net Production of Other Finished Reformulated Motor Gasoline (Thousand Barrels per Day) | F128: 4-Week Avg Midwest (PADD 2) Refiner and Blender Net Production of Conventional Motor Gasoline (Thousand Barrels per Day) | G128: 4-Week Avg Midwest (PADD 2) Refiner and Blender Net Production of Finished Conventional Motor Gasoline with Ethanol (Thousand Barrels per Day) | H128: 4-Week Avg Midwest (PADD 2) Refiner and Blender Net Production of Finished Conventional Motor Gasoline, Ed 55 and Lower (Thousand Barrels per Day) | I128: 4-Week Avg Midwest (PADD 2) Refiner and Blender Net Production of Finished Conventional Motor Gasoline, Greater than Ed 55 (Thousand Barrels per Day) | J128: 4-Week Avg Midwest (PADD 2) Refiner and Blender Net Production of Other Finished Conventional Motor Gasoline (Thousand Barrels per Day) | K128: 4-Week Avg Midwest (PADD 2) Refiner and Blender Net Production of Kerosene-Type Jet Fuel (Thousand Barrels per Day) | L128: 4-Week Avg Midwest (PADD 2) Refiner and Blender Net Production of Commercial Kerosene-Type Jet Fuel (Thousand Barrels per Day) | M128: 4-Week Avg Midwest (PADD 2) Refiner and Blender Net Production of Military Kerosene-Type Jet Fuel (Thousand Barrels per Day) | N128: 4-Week Avg Midwest (PADD 2) Refiner and Blender Net Production of Distillate Fuel Oil (Thousand Barrels per Day) | O128: 4-Week Avg Midwest (PADD 2) Refiner and Blender Net Production of Distillate Fuel Oil, 0 to 15 ppm Sulfur (Thousand Barrels per Day) | P128: 4-Week Avg Midwest (PADD 2)Refiner and Blender Net Production of Distillate Fuel Oil, Greater than 15 to 500 ppm Sulfur (Thousand Barrels per Day) | Q128: 4-Week Avg Midwest (PADD 2) Refiner and Blender Net Production of Distillate Fuel Oil Greater than 500 ppm Sulfur (Thousand Barrels per Day) | R128: 4-Week Avg Midwest (PADD 2) Refiner and Blender Net Production of Residual Fuel Oil (Thousand Barrels per Day) | S128: 4-Week Avg Midwest (PADD 2) Refiner, Blender, and Gas Plant Net Production of Propane and Propylene (Thousand Barrels per Day)
A129: 40354 | B129: 2201 | C129: 356 | D129: 354 | E129: 2 | F129: 1845 | G129: 1812 | H129: 1811 | I129: 1 | J129: 33 | K129: 224 | L129: 211 | M129: 13 | N129: 1007 | O129: 955 | P129: 40 | Q129: 11 | R129: 52 | S129: 262
A130: 40361 | B130: 2227 | C130: 362 | D130: 360 | E130: 2 | F130: 1865 | G130: 1841 | H130: 1840 | I130: 1 | J130: 23 | K130: 231 | L130: 217 | M130: 14 | N130: 998 | O130: 952 | P130: 37 | Q130: 9 | R130: 52 | S130: 264
A131: 40368 | B131: 2252 | C131: 366 | D131: 365 | E131: 1 | F131: 1886 | G131: 1862 | H131: 1861 | I131: 1 | J131: 25 | K131: 241 | L131: 225 | M131: 16 | N131: 993 | O131: 949 | P131: 34 | Q131: 10 | R131: 50 | S131: 263
A132: 40375 | B132: 2262 | C132: 364 | D132: 364 | E132: 0 | F132: 1897 | G132: 1859 | H132: 1858 | I132: 1 | J132: 38 | K132: 248 | L132: 233 | M132: 15 | N132: 1019 | O132: 974 | P132: 32 | Q132: 13 | R132: 48 | S132: 263
