Workbook
Name AnswerData: #REF!
Name AnswerData: #REF!
Name bprint: #REF!
Name btu_per_watthr: '[1]Conversion Factors'!$B$5
Name CMM_SUPPLY_CRV_TABLE: [2]cum2025curves!#REF!
Name cprint: #REF!
Name days_per_year: '[1]Conversion Factors'!$B$3
Name dollar____per__m: '[1]Conversion Factors'!$B$7
Name exch_rate: #REF!
Name exch_rate: #REF!
Name fitfile: [3]MODEL!$D$38
Name hours_per_day: '[1]Conversion Factors'!$B$2
Name INF: [3]MODEL!$H$14
Name j_per_btu: '[1]Conversion Factors'!$B$4
Name j_per_pj: '[1]Conversion Factors'!$B$6
Name lumens_per_billion_lumens: '[1]Conversion Factors'!$B$9
Name MAXREC: #REF!
Name million_short_tons_to_short_ton: [4]Steps!$Y$5
Name MMBTU_to_PJ: [4]Steps!$Y$6
Name PPP: [3]MODEL!$D$12
Name PPPEX: [3]MODEL!$D$13
Name rail_coal: #REF!
Name rail_coal: #REF!
Name region1: [5]Regions!$B$3:$C$61
Name TECHNAME: #REF!
Name TRNDTYPE: #REF!

Sheet ANSv6.1-Commodities
A1: ANSWER-Commodities
B7: CommName | C7: CommDesc | D7: CommUnit | E7: Set Memberships | F7: Comment

Sheet Commodities
B1: Commodities | C1: _GLOBAL,R0,R1,R2,R3,R4,R5,R6
B6: ~FI_Comm
B7: Region | C7: CommName | D7: CommDesc | E7: Unit | F7: Csets | G7: LimType | H7: CTSLvl | I7: PeakTS | J7: Ctype | O7: Comment
B8: * Natural Gas Supply Commodities - Domestic and Imported
B9: R1,R2,R3,R4,R5,R6 | C9: NGA | D9: Natural Gas | E9: PJ | F9: NRG
B10: R1,R2,R3,R4,R5,R6 | C10: NGAD | D10: Domestic Natural Gas | E10: PJ
B11: R1,R2,R3,R4,R5,R6 | C11: NGAD0 | D11: Domestic Natural Gas - D0 | E11: PJ
B12: R1 | C12: NGAD1 | D12: Domestic Natural Gas - R1 | E12: PJ
B13: R2 | C13: NGAD2 | D13: Domestic Natural Gas - R2 | E13: PJ
B14: R3 | C14: NGAD3 | D14: Domestic Natural Gas - R3 | E14: PJ
B15: R4 | C15: NGAD4 | D15: Domestic Natural Gas - R4 | E15: PJ
B16: R5 | C16: NGAD5 | D16: Domestic Natural Gas - R5 | E16: PJ
B17: R6 | C17: NGAD6 | D17: Domestic Natural Gas - R6 | E17: PJ
B18: R1,R2,R3,R4,R5,R6 | C18: NGAR1 | D18: Natural Gas - R1 | E18: PJ
B19: R1,R2,R3,R4,R5,R6 | C19: NGAR2 | D19: Natural Gas - R2 | E19: PJ
B20: R1,R2,R3,R4,R5,R6 | C20: NGAR3 | D20: Natural Gas - R3 | E20: PJ
B21: R1,R2,R3,R4,R5,R6 | C21: NGAR4 | D21: Natural Gas - R4 | E21: PJ
... B43: R1,R2,R3,R4,R5,R6 | C43: NGLR6 | D43: Traded natural gas plant liquids from R6 | E43: PJ
B44: * Natural Gas End-Use Commodities
B45: R1,R2,R3,R4,R5,R6 | C45: RESNGA | D45: Natural gas to Residential sector | E45: PJ | F45: NRG
B46: R1,R2,R3,R4,R5,R6 | C46: COMNGA | D46: Natural gas to Commercial sector | E46: PJ
B47: R1,R2,R3,R4,R5,R6 | C47: INDNGA | D47: Natural gas to Industrial sector | E47: PJ
B48: R1,R2,R3,R4,R5,R6 | C48: ELCNGA | D48: Natural gas to Electricity generation | E48: PJ
B49: R1,R2,R3,R4,R5,R6 | C49: TRNNGA | D49: Natural gas to Transportation sector | E49: PJ
B50: *R1,R2,R3,R4,R5,R6 | C50: LPG | D50: LPG from NGL | E50: PJ
B51: *R1,R2,R3,R4,R5,R7 | C51: PFS | D51: PFS from NGL | E51: PJ
B52: *R1,R2,R3,R4,R5,R8 | C52: PENTS | D52: Pentanes from NGL | E52: PJ
B53: *R1,R2,R3,R4,R5,R9 | C53: GSR | D53: NGL Pentanes to gasoline | E53: PJ
B54: *R1,R2,R3,R4,R5,R10 | C54: DENAT | D54: NGL Pentanes to ethanol denaturant | E54: PJ
B55: *R1,R2,R3,R4,R5,R11 | C55: PFS_NGL | D55: Natural gas liquids to PFS (C2 & C4) | E55: PJ
B56: *R1,R2,R3,R4,R5,R12 | C56: LPG_NGL | D56: Natural gas liquids to LPG (C3) | E56: PJ
B57: *R1,R2,R3,R4,R5,R13 | C57: NGLPENT | D57: Natural gas liquids to pentanes (C5+) | E57: PJ
B74: * Emissions Commodities
B75: R1,R2,R3,R4,R5,R6 | C75: CO2 | D75: Carbon dioxide | E75: Mt | F75: ENV
B76: R1,R2,R3,R4,R5,R6 | C76: NOX | D76: Nitrogen oxide | E76: kt | F76: ENV
B77: R1,R2,R3,R4,R5,R6 | C77: PM10 | D77: Particulate matter | E77: kt | F77: ENV
B78: R1,R2,R3,R4,R5,R6 | C78: PM25 | D78: Fine particulate matter | E78: kt | F78: ENV
B79: R1,R2,R3,R4,R5,R6 | C79: VOC | D79: Volatile organic compounds | E79: kt | F79: ENV
B80: R1,R2,R3,R4,R5,R6 | C80: CO | D80: Carbon monoxide | E80: kt | F80: ENV
B81: R1,R2,R3,R4,R5,R6 | C81: CH4 | D81: Methane | E81: kt | F81: ENV
...

Sheet ANSv6.1-Technologies
A1: ANSWER-Technologies
B7: TechName | C7: TechDesc | D7: TACTUnit | E7: TCAPUnit | F7: Set Memberships | G7: Comment

Sheet Technologies
B1: Technologies | C1: _GLOBAL,R0,R1,R2,R3,R4,R5,R6
B6: ~FI_Process
B7: Region | C7: TechName | D7: TechDesc | E7: Tact | F7: Tcap | G7: Sets | H7: PrimaryCG | I7: Vintage | O7: Comment
B8: R1,R2,R3,R4,R5,R6 | C8: MINNGAD1 | D8: Domestic natural gas - step 1 | E8: PJ | F8: PJ/a | G8: MIN
B9: R1,R2,R3,R4,R5,R6 | C9: MINNGAD2 | D9: Domestic natural gas - step 2 | E9: PJ | F9: PJ/a
B10: R1,R2,R3,R4,R5,R6 | C10: MINNGAD3 | D10: Domestic natural gas - step 3 | E10: PJ | F10: PJ/a
B11: R1,R2,R3,R4,R5,R6 | C11: MINNGAD4 | D11: Domestic natural gas - step 4 | E11: PJ | F11: PJ/a
B12: R1,R2,R3,R4,R5,R6 | C12: MINNGAD5 | D12: Domestic natural gas - step 5 | E12: PJ | F12: PJ/a
B13: R1,R2,R3,R4,R5,R6 | C13: MINNGAD6 | D13: Domestic natural gas - step 6 | E13: PJ | F13: PJ/a
B14: R1,R2,R3,R4,R5,R6 | C14: SCMINNGAD | D14: Collector: MINNGAD | E14: PJ | F14: PJ/a | G14: PRE
B15: R1 | C15: MINNGLDMY | D15: Dummy NGL Resource Supply | E15: PJ | F15: PJ/a | G15: MIN
B16: R1 | C16: SCNGAR1 | D16: Collector: Natural Gas R1 | E16: PJ | F16: PJ/a | G16: PRE
B17: R2 | C17: SCNGAR2 | D17: Collector: Natural Gas R2 | E17: PJ | F17: PJ/a
B18: R3 | C18: SCNGAR3 | D18: Collector: Natural Gas R3 | E18: PJ | F18: PJ/a
B19: R4 | C19: SCNGAR4 | D19: Collector: Natural Gas R4 | E19: PJ | F19: PJ/a
B20: R5 | C20: SCNGAR5 | D20: Collector: Natural Gas R5 | E20: PJ | F20: PJ/a
B21: R6 | C21: SCNGAR6 | D21: Collector: Natural Gas R6 | E21: PJ | F21: PJ/a
B22: *
B23: R1 | C23: SCNGAD1 | D23: Domestic natural gas Existing infrastructure in R1 | E23: PJ | F23: PJ/a
B24: R2 | C24: SCNGAD2 | D24: Domestic natural gas Existing infrastructure in R2 | E24: PJ | F24: PJ/a
B25: R3 | C25: SCNGAD3 | D25: Domestic natural gas Existing infrastructure in R3 | E25: PJ | F25: PJ/a
B26: R4 | C26: SCNGAD4 | D26: Domestic natural gas Existing infrastructure in R4 | E26: PJ | F26: PJ/a
B27: R5 | C27: SCNGAD5 | D27: Domestic natural gas Existing infrastructure in R5 | E27: PJ | F27: PJ/a
B28: R6 | C28: SCNGAD6 | D28: Domestic natural gas Existing infrastructure in R6 | E28: PJ | F28: PJ/a
B29: *Imported natural gas supply and transport
B30: R0 | C30: IMPNGALA | D30: Imported LNG - Step A | E30: PJ | F30: PJ/a | G30: IMP
B31: R0 | C31: IMPNGALB | D31: Imported LNG - Step B | E31: PJ | F31: PJ/a
B32: R0 | C32: IMPNGALC | D32: Imported LNG - Step C | E32: PJ | F32: PJ/a
B33: R0 | C33: SCIMPNGAL | D33: Share of Imported LNG to Existing Terminals | E33: PJ | F33: PJ/a | G33: PRE
B34: R0 | C34: IMPNGAC1 | D34: Imported natural gas from Canada - Step 1 | E34: PJ | F34: PJ/a | G34: IMP
B35: R0 | C35: IMPNGAC2 | D35: Imported natural gas from Canada - Step 2 | E35: PJ | F35: PJ/a
B36: R0 | C36: IMPNGAC3 | D36: Imported natural gas from Canada - Step 3 | E36: PJ | F36: PJ/a
B37: R0 | C37: IMPNGAC4 | D37: Imported natural gas from Canada - Step 4 | E37: PJ | F37: PJ/a
B38: R0 | C38: IMPNGAC5 | D38: Imported natural gas from Canada - Step 5 | E38: PJ | F38: PJ/a
B39: R0 | C39: IMPNGAC6 | D39: Imported natural gas from Canada - Step 6 | E39: PJ | F39: PJ/a
B40: R0 | C40: SCIMPNGAC | D40: Canadian imported natural gas shares | E40: PJ | F40: PJ/a | G40: PRE
B41: R0 | C41: SCNGAC1 | D41: Canadian imported natural gas in R1 | E41: PJ | F41: PJ/a
B42: *R0 | C42: SCNGAC2 | D42: Canadian imported natural gas in R2 | E42: PJ | F42: PJ/a
B43: *R0 | C43: SCNGAC3 | D43: Canadian imported natural gas in R3 | E43: PJ | F43: PJ/a
B44: *R0 | C44: SCNGAC4 | D44: Canadian imported natural gas in R4 | E44: PJ | F44: PJ/a
...

Sheet ANSv6.1-Constraints
A1: ANSWER-Constraints
B7: ConstrName | C7: ConstrDesc | D7: Units | E7: Set Memberships | F7: Comment

Sheet ANSv6.1-CommData
A1: ANSWER-CommData
B7: CommName | C7: CommDesc | D7: Units

Sheet ANSv6.1-TechData
A1: ANSWER-TechData
B7: TechName | C7: TechDesc | D7: Units | E7: CommIN | F7: CommOUT

Sheet TechData_R0
A1: TechData | B1: _GLOBAL,R0,R1,R2,R3,R4,R5,R6 | BO1: *
D5: ~FI_T
A6: Region | B6: TechName | C6: TechDesc | D6: CommOUT | E6: *NCAP_START | F6: COST~2010 | G6: COST~2015 | H6: COST~2020 | I6: COST~2025 | J6: COST~2030 | K6: COST~2035 | L6: COST~2040 | M6: COST~2045 | N6: COST~2050 | O6: COST~2055 | P6: CUM | Q6: ACT_BND~LO~2010 | R6: ACT_BND~UP~2010 | S6: ACT_BND~UP~2015 | T6: ACT_BND~UP~2020 | U6: ACT_BND~UP~2055 | W6: *GROWTH_TIDr | X6: *GROWTHr~2010 | Y6: *GROWTHr~2015-2020 | Z6: *GROWTHr~2025-2055 | AA6: *DECAYr~2010 | AB6: *DECAYr~2015-2055
A7: *Minning Natural gas
A8: * Price Shocks | G8: 1 | H8: 1 | I8: 1 | J8: 1 | K8: 1 | L8: 1 | M8: 1 | N8: 1 | O8: 1
A9: R1 | B9: MINNGAD1 | C9: Domestic natural gas - step 1 | D9: =Commodities!C$11 -> NGAD0 | E9: 2010 | F9: =F11*'Domestic NG Prices'!$N$19 -> 3.5667714 | G9: =G11*'Domestic NG Prices'!$N$19 -> 2.93191 | H9: =H11*'Domestic NG Prices'!$N$19 -> 3.427406 | I9: =I11*'Domestic NG Prices'!$N$19 -> 4.0985992 | J9: =J11*'Domestic NG Prices'!$N$19 -> 4.7260766 | K9: =K11*'Domestic NG Prices'!$N$19 -> 5.4230838 | L9: =L11*'Domestic NG Prices'!$N$19 -> 5.9926204 | M9: =M11*'Domestic NG Prices'!$N$19 -> 6.6176 | ... O9: =O11*'Domestic NG Prices'!$N$19 -> 8.0872 | P9: =R9/SUM($R$9:$R$14)*'Domestic NG CUM'!$T$6 -> 3637.3548 | Q9: ='Domestic NG Production'!B94 -> 14.464222 | R9: ='Domestic NG Production'!B79 -> 326.2332 | X9: 1.25 | Y9: 1.1 | Z9: 1.1 | AA9: 1.1 | AB9: 1.01
A10: R1 | B10: MINNGAD2 | C10: Domestic natural gas - step 2 | D10: =Commodities!C$11 -> NGAD0 | E10: 2010 | F10: =F11*'Domestic NG Prices'!$N$20 -> 3.8504918 | G10: =G11*'Domestic NG Prices'!$N$20 -> 3.1651301 | H10: =H11*'Domestic NG Prices'!$N$20 -> 3.7000405 | I10: =I11*'Domestic NG Prices'!$N$20 -> 4.4246241 | J10: =J11*'Domestic NG Prices'!$N$20 -> 5.1020145 | K10: =K11*'Domestic NG Prices'!$N$20 -> 5.8544654 | L10: =L11*'Domestic NG Prices'!$N$20 -> 6.4693061 | M10: =M11*'Domestic NG Prices'!$N$20 -> 7.144 | ... O10: =O11*'Domestic NG Prices'!$N$20 -> 8.7305 | P10: =R10/SUM($R$9:$R$14)*'Domestic NG CUM'!$T$6 -> 2728.0161 | Q10: ='Domestic NG Production'!B95 -> 10.848166 | R10: ='Domestic NG Production'!B80 -> 244.6749 | X10: 1.25 | Y10: 1.1 | Z10: 1.1 | AA10: 1.1 | AB10: 1.01
A11: R1 | B11: MINNGAD3 | C11: Domestic natural gas - step 3 | D11: =Commodities!C$11 -> NGAD0 | E11: 2010 | F11: ='Domestic NG Prices'!N42*'Domestic NG Prices'!$P$27*TechData_DelNGA!$I$8 -> 4.0531493 | G11: ='Domestic NG Prices'!O42*'Domestic NG Prices'!$P$27*TechData_DelNGA!$I$8*G8 -> 3.3317159 | H11: ='Domestic NG Prices'!P42*'Domestic NG Prices'!$P$27*TechData_DelNGA!$I$8*H8 -> 3.8947795 | I11: ='Domestic NG Prices'!Q42*'Domestic NG Prices'!$P$27*TechData_DelNGA!$I$8*I8 -> 4.6574991 | J11: ='Domestic NG Prices'!R42*'Domestic NG Prices'!$P$27*TechData_DelNGA!$I$8*J8 -> 5.3705416 | K11: ='Domestic NG Prices'!S42*'Domestic NG Prices'!$P$27*TechData_DelNGA!$I$8*K8 -> 6.1625952 | L11: ='Domestic NG Prices'!T42*'Domestic NG Prices'!$P$27*TechData_DelNGA!$I$8*L8 -> 6.8097959 | M11: =7.52*M8 -> 7.52 | N11: =8.32*N8 -> 8.32 | O11: =9.19*O8 -> 9.19 | P11: =R11/SUM($R$9:$R$14)*'Domestic NG CUM'!$T$6 -> 2728.0161 | Q11: ='Domestic NG Production'!B96 -> 10.848166 | R11: ='Domestic NG Production'!B81 -> 244.6749 | X11: 1.25 | Y11: 1.1 | Z11: 1.1 | AA11: 1.1 | AB11: 1.01
A12: R1 | B12: MINNGAD4 | C12: Domestic natural gas - step 4 | D12: =Commodities!C$11 -> NGAD0 | E12: 2010 | F12: =F11*'Domestic NG Prices'!$N$22 -> 4.3774012 | G12: =G11*'Domestic NG Prices'!$N$22 -> 3.5982532 | H12: =H11*'Domestic NG Prices'!$N$22 -> 4.2063619 | I12: =I11*'Domestic NG Prices'!$N$22 -> 5.030099 | J12: =J11*'Domestic NG Prices'!$N$22 -> 5.8001849 | K12: =K11*'Domestic NG Prices'!$N$22 -> 6.6556028 | L12: =L11*'Domestic NG Prices'!$N$22 -> 7.3545796 | M12: =M11*'Domestic NG Prices'!$N$22 -> 8.1216 | ... O12: =O11*'Domestic NG Prices'!$N$22 -> 9.9252 | P12: =R12/SUM($R$9:$R$14)*'Domestic NG CUM'!$T$6 -> 454.66935 | Q12: ='Domestic NG Production'!B97 -> 1.8080277 | R12: ='Domestic NG Production'!B82 -> 40.77915 | X12: 1.25 | Y12: 1.1 | Z12: 1.1 | AA12: 1.1 | AB12: 1.01
A13: R1 | B13: MINNGAD5 | C13: Domestic natural gas - step 5 | D13: =Commodities!C$11 -> NGAD0 | E13: 2010 | F13: =F11*'Domestic NG Prices'!$N$23 -> 4.5395272 | G13: =G11*'Domestic NG Prices'!$N$23 -> 3.7315218 | H13: =H11*'Domestic NG Prices'!$N$23 -> 4.362153 | I13: =I11*'Domestic NG Prices'!$N$23 -> 5.216399 | J13: =J11*'Domestic NG Prices'!$N$23 -> 6.0150066 | K13: =K11*'Domestic NG Prices'!$N$23 -> 6.9021066 | L13: =L11*'Domestic NG Prices'!$N$23 -> 7.6269714 | M13: =M11*'Domestic NG Prices'!$N$23 -> 8.4224 | ... O13: =O11*'Domestic NG Prices'!$N$23 -> 10.2928 | P13: =R13/SUM($R$9:$R$14)*'Domestic NG CUM'!$T$6 -> 454.66935 | R13: ='Domestic NG Production'!B83 -> 40.77915 | W13: =R13 -> 40.77915 | X13: 1.25 | Y13: 1.1 | Z13: 1.1 | AA13: 1.1 | AB13: 1.01
A14: R1 | B14: MINNGAD6 | C14: Domestic natural gas - step 6 | D14: =Commodities!C$11 -> NGAD0 | E14: 2010 | F14: =F11*'Domestic NG Prices'!$N$24 -> 6.2013184 | G14: =G11*'Domestic NG Prices'!$N$24 -> 5.0975254 | H14: =H11*'Domestic NG Prices'!$N$24 -> 5.9590126 | I14: =I11*'Domestic NG Prices'!$N$24 -> 7.1259736 | J14: =J11*'Domestic NG Prices'!$N$24 -> 8.2169286 | K14: =K11*'Domestic NG Prices'!$N$24 -> 9.4287707 | L14: =L11*'Domestic NG Prices'!$N$24 -> 10.418988 | M14: =M11*'Domestic NG Prices'!$N$24 -> 11.5056 | ... O14: =O11*'Domestic NG Prices'!$N$24 -> 14.0607 | P14: =R14/SUM($R$9:$R$14)*'Domestic NG CUM'!$T$6 -> 909.3387 | R14: ='Domestic NG Production'!B84 -> 81.5583 | W14: =R14 -> 81.5583 | X14: 1.25 | Y14: 1.1 | Z14: 1.1 | AA14: 1.1 | AB14: 1.01
A15: *
A16: R2 | B16: MINNGAD1 | C16: Domestic natural gas - step 1 | D16: =Commodities!C$11 -> NGAD0 | E16: 2010 | F16: =F18*'Domestic NG Prices'!$N$19 -> 3.5667714 | G16: =G18*'Domestic NG Prices'!$N$19 -> 2.93191 | H16: =H18*'Domestic NG Prices'!$N$19 -> 3.427406 | I16: =I18*'Domestic NG Prices'!$N$19 -> 4.0985992 | J16: =J18*'Domestic NG Prices'!$N$19 -> 4.7260766 | K16: =K18*'Domestic NG Prices'!$N$19 -> 5.4230838 | L16: =L18*'Domestic NG Prices'!$N$19 -> 5.9926204 | M16: =M18*'Domestic NG Prices'!$N$19 -> 6.5694775 | ... O16: =O18*'Domestic NG Prices'!$N$19 -> 8.0217982 | P16: 0 | Q16: =R16*0.9 -> 0 | R16: 0 | S16: 0 | T16: 0 | U16: =T16 -> 0 | X16: 1.25 | Y16: 1.1 | Z16: 1.1 | AA16: 1.1 | AB16: 1.01
A17: R2 | B17: MINNGAD2 | C17: Domestic natural gas - step 2 | D17: =Commodities!C$11 -> NGAD0 | E17: 2010 | F17: =F18*'Domestic NG Prices'!$N$20 -> 3.8504918 | G17: =G18*'Domestic NG Prices'!$N$20 -> 3.1651301 | H17: =H18*'Domestic NG Prices'!$N$20 -> 3.7000405 | I17: =I18*'Domestic NG Prices'!$N$20 -> 4.4246241 | J17: =J18*'Domestic NG Prices'!$N$20 -> 5.1020145 | K17: =K18*'Domestic NG Prices'!$N$20 -> 5.8544654 | L17: =L18*'Domestic NG Prices'!$N$20 -> 6.4693061 | M17: =M18*'Domestic NG Prices'!$N$20 -> 7.0920495 | ... O17: =O18*'Domestic NG Prices'!$N$20 -> 8.6598958 | P17: 0 | Q17: =R17*0.9 -> 0 | R17: 0 | S17: 0 | T17: 0 | U17: =T17 -> 0 | X17: 1.25 | Y17: 1.1 | Z17: 1.1 | AA17: 1.1 | AB17: 1.01
A18: R2 | B18: MINNGAD3 | C18: Domestic natural gas - step 3 | D18: =Commodities!C$11 -> NGAD0 | E18: 2010 | F18: ='Domestic NG Prices'!N42*'Domestic NG Prices'!$P$27*TechData_DelNGA!$I$11 -> 4.0531493 | G18: ='Domestic NG Prices'!O42*'Domestic NG Prices'!$P$27*TechData_DelNGA!$I$11*G8 -> 3.3317159 | H18: ='Domestic NG Prices'!P42*'Domestic NG Prices'!$P$27*TechData_DelNGA!$I$11*H8 -> 3.8947795 | I18: ='Domestic NG Prices'!Q42*'Domestic NG Prices'!$P$27*TechData_DelNGA!$I$11*I8 -> 4.6574991 | J18: ='Domestic NG Prices'!R42*'Domestic NG Prices'!$P$27*TechData_DelNGA!$I$11*J8 -> 5.3705416 | K18: ='Domestic NG Prices'!S42*'Domestic NG Prices'!$P$27*TechData_DelNGA!$I$11*K8 -> 6.1625952 | L18: ='Domestic NG Prices'!T42*'Domestic NG Prices'!$P$27*TechData_DelNGA!$I$11*L8 -> 6.8097959 | M18: =7.46531529457816*M8 -> 7.4653153 | N18: =8.2493286895923*N8 -> 8.2493287 | O18: =9.11567979966692*O8 -> 9.1156798 | P18: 0 | Q18: =R18*0.9 -> 0 | R18: 0 | S18: 0 | T18: 0 | U18: =T18 -> 0 | X18: 1.25 | Y18: 1.1 | Z18: 1.1 | AA18: 1.1 | AB18: 1.01
A19: R2 | B19: MINNGAD4 | C19: Domestic natural gas - step 4 | D19: =Commodities!C$11 -> NGAD0 | E19: 2010 | F19: =F18*'Domestic NG Prices'!$N$22 -> 4.3774012 | G19: =G18*'Domestic NG Prices'!$N$22 -> 3.5982532 | H19: =H18*'Domestic NG Prices'!$N$22 -> 4.2063619 | I19: =I18*'Domestic NG Prices'!$N$22 -> 5.030099 | J19: =J18*'Domestic NG Prices'!$N$22 -> 5.8001849 | K19: =K18*'Domestic NG Prices'!$N$22 -> 6.6556028 | L19: =L18*'Domestic NG Prices'!$N$22 -> 7.3545796 | M19: =M18*'Domestic NG Prices'!$N$22 -> 8.0625405 | ... O19: =O18*'Domestic NG Prices'!$N$22 -> 9.8449342 | P19: 0 | Q19: =R19*0.9 -> 0 | R19: 0 | S19: 0 | T19: 0 | U19: =T19 -> 0 | X19: 1.25 | Y19: 1.1 | Z19: 1.1 | AA19: 1.1 | AB19: 1.01
A20: R2 | B20: MINNGAD5 | C20: Domestic natural gas - step 5 | D20: =Commodities!C$11 -> NGAD0 | E20: 2010 | F20: =F18*'Domestic NG Prices'!$N$23 -> 4.5395272 | G20: =G18*'Domestic NG Prices'!$N$23 -> 3.7315218 | H20: =H18*'Domestic NG Prices'!$N$23 -> 4.362153 | I20: =I18*'Domestic NG Prices'!$N$23 -> 5.216399 | J20: =J18*'Domestic NG Prices'!$N$23 -> 6.0150066 | K20: =K18*'Domestic NG Prices'!$N$23 -> 6.9021066 | L20: =L18*'Domestic NG Prices'!$N$23 -> 7.6269714 | M20: =M18*'Domestic NG Prices'!$N$23 -> 8.3611531 | ... O20: =O18*'Domestic NG Prices'!$N$23 -> 10.209561 | P20: 0 | Q20: =R20*0.9 -> 0 | R20: 0 | S20: 0 | T20: 0 | U20: =T20 -> 0 | W20: =R20 -> 0 | X20: 1.25 | Y20: 1.1 | Z20: 1.1 | AA20: 1.1 | AB20: 1.01
A21: R2 | B21: MINNGAD6 | C21: Domestic natural gas - step 6 | D21: =Commodities!C$11 -> NGAD0 | E21: 2010 | F21: =F18*'Domestic NG Prices'!$N$24 -> 6.2013184 | G21: =G18*'Domestic NG Prices'!$N$24 -> 5.0975254 | H21: =H18*'Domestic NG Prices'!$N$24 -> 5.9590126 | I21: =I18*'Domestic NG Prices'!$N$24 -> 7.1259736 | J21: =J18*'Domestic NG Prices'!$N$24 -> 8.2169286 | K21: =K18*'Domestic NG Prices'!$N$24 -> 9.4287707 | L21: =L18*'Domestic NG Prices'!$N$24 -> 10.418988 | M21: =M18*'Domestic NG Prices'!$N$24 -> 11.421932 | ... O21: =O18*'Domestic NG Prices'!$N$24 -> 13.94699 | P21: 0 | Q21: =R21*0.9 -> 0 | R21: 0 | S21: 0 | T21: 0 | U21: =T21 -> 0 | W21: =R21 -> 0 | X21: 1.25 | Y21: 1.1 | Z21: 1.1 | AA21: 1.1 | AB21: 1.01
A22: *
A23: R3 | B23: MINNGAD1 | C23: Domestic natural gas - step 1 | D23: =Commodities!C$11 -> NGAD0 | E23: 2010 | F23: =F25*'Domestic NG Prices'!$N$19 -> 3.5667714 | G23: =G25*'Domestic NG Prices'!$N$19 -> 2.93191 | H23: =H25*'Domestic NG Prices'!$N$19 -> 3.427406 | I23: =I25*'Domestic NG Prices'!$N$19 -> 4.0985992 | J23: =J25*'Domestic NG Prices'!$N$19 -> 4.7260766 | K23: =K25*'Domestic NG Prices'!$N$19 -> 5.4230838 | L23: =L25*'Domestic NG Prices'!$N$19 -> 5.9926204 | M23: =M25*'Domestic NG Prices'!$N$19 -> 6.0617197 | ... O23: =O25*'Domestic NG Prices'!$N$19 -> 7.40179 | P23: 0 | Q23: =R23*0.9 -> 0 | R23: 0 | S23: 0 | T23: 0 | U23: =T23 -> 0 | X23: 1.25 | Y23: 1.1 | Z23: 1.1 | AA23: 1.1 | AB23: 1.01
A24: R3 | B24: MINNGAD2 | C24: Domestic natural gas - step 2 | D24: =Commodities!C$11 -> NGAD0 | E24: 2010 | F24: =F25*'Domestic NG Prices'!$N$20 -> 3.8504918 | G24: =G25*'Domestic NG Prices'!$N$20 -> 3.1651301 | H24: =H25*'Domestic NG Prices'!$N$20 -> 3.7000405 | I24: =I25*'Domestic NG Prices'!$N$20 -> 4.4246241 | J24: =J25*'Domestic NG Prices'!$N$20 -> 5.1020145 | K24: =K25*'Domestic NG Prices'!$N$20 -> 5.8544654 | L24: =L25*'Domestic NG Prices'!$N$20 -> 6.4693061 | M24: =M25*'Domestic NG Prices'!$N$20 -> 6.543902 | ... O24: =O25*'Domestic NG Prices'!$N$20 -> 7.9905688 | P24: 0 | Q24: =R24*0.9 -> 0 | R24: 0 | S24: 0 | T24: 0 | U24: =T24 -> 0 | X24: 1.25 | Y24: 1.1 | Z24: 1.1 | AA24: 1.1 | AB24: 1.01
A25: R3 | B25: MINNGAD3 | C25: Domestic natural gas - step 3 | D25: =Commodities!C$11 -> NGAD0 | E25: 2010 | F25: ='Domestic NG Prices'!N42*'Domestic NG Prices'!$P$27*TechData_DelNGA!$I$14 -> 4.0531493 | G25: ='Domestic NG Prices'!O42*'Domestic NG Prices'!$P$27*TechData_DelNGA!$I$14*G8 -> 3.3317159 | H25: ='Domestic NG Prices'!P42*'Domestic NG Prices'!$P$27*TechData_DelNGA!$I$14*H8 -> 3.8947795 | I25: ='Domestic NG Prices'!Q42*'Domestic NG Prices'!$P$27*TechData_DelNGA!$I$14*I8 -> 4.6574991 | J25: ='Domestic NG Prices'!R42*'Domestic NG Prices'!$P$27*TechData_DelNGA!$I$14*J8 -> 5.3705416 | K25: ='Domestic NG Prices'!S42*'Domestic NG Prices'!$P$27*TechData_DelNGA!$I$14*K8 -> 6.1625952 | L25: ='Domestic NG Prices'!T42*'Domestic NG Prices'!$P$27*TechData_DelNGA!$I$14*L8 -> 6.8097959 | M25: =6.88831787744587*M8 -> 6.8883179 | N25: =7.61173454130134*N8 -> 7.6117345 | O25: =8.41112500294819*O8 -> 8.411125 | P25: 0 | Q25: =R25*0.9 -> 0 | R25: 0 | S25: 0 | T25: 0 | U25: =T25 -> 0 | X25: 1.25 | Y25: 1.1 | Z25: 1.1 | AA25: 1.1 | AB25: 1.01
A26: R3 | B26: MINNGAD4 | C26: Domestic natural gas - step 4 | D26: =Commodities!C$11 -> NGAD0 | E26: 2010 | F26: =F25*'Domestic NG Prices'!$N$22 -> 4.3774012 | G26: =G25*'Domestic NG Prices'!$N$22 -> 3.5982532 | H26: =H25*'Domestic NG Prices'!$N$22 -> 4.2063619 | I26: =I25*'Domestic NG Prices'!$N$22 -> 5.030099 | J26: =J25*'Domestic NG Prices'!$N$22 -> 5.8001849 | K26: =K25*'Domestic NG Prices'!$N$22 -> 6.6556028 | L26: =L25*'Domestic NG Prices'!$N$22 -> 7.3545796 | M26: =M25*'Domestic NG Prices'!$N$22 -> 7.4393833 | ... O26: =O25*'Domestic NG Prices'!$N$22 -> 9.084015 | P26: 0 | Q26: =R26*0.9 -> 0 | R26: 0 | S26: 0 | T26: 0 | U26: =T26 -> 0 | X26: 1.1 | Y26: 1.1 | Z26: 1.1 | AA26: 1.1 | AB26: 1.01
A27: R3 | B27: MINNGAD5 | C27: Domestic natural gas - step 5 | D27: =Commodities!C$11 -> NGAD0 | E27: 2010 | F27: =F25*'Domestic NG Prices'!$N$23 -> 4.5395272 | G27: =G25*'Domestic NG Prices'!$N$23 -> 3.7315218 | H27: =H25*'Domestic NG Prices'!$N$23 -> 4.362153 | I27: =I25*'Domestic NG Prices'!$N$23 -> 5.216399 | J27: =J25*'Domestic NG Prices'!$N$23 -> 6.0150066 | K27: =K25*'Domestic NG Prices'!$N$23 -> 6.9021066 | L27: =L25*'Domestic NG Prices'!$N$23 -> 7.6269714 | M27: =M25*'Domestic NG Prices'!$N$23 -> 7.714916 | ... O27: =O25*'Domestic NG Prices'!$N$23 -> 9.42046 | P27: 0 | Q27: =R27*0.9 -> 0 | R27: 0 | S27: 0 | T27: 0 | U27: =T27 -> 0 | W27: =R27 -> 0 | X27: 1.01 | Y27: 1.01 | Z27: 1.01 | AA27: 1.1 | AB27: 1.01
A28: R3 | B28: MINNGAD6 | C28: Domestic natural gas - step 6 | D28: =Commodities!C$11 -> NGAD0 | E28: 2010 | F28: =F25*'Domestic NG Prices'!$N$24 -> 6.2013184 | G28: =G25*'Domestic NG Prices'!$N$24 -> 5.0975254 | H28: =H25*'Domestic NG Prices'!$N$24 -> 5.9590126 | I28: =I25*'Domestic NG Prices'!$N$24 -> 7.1259736 | J28: =J25*'Domestic NG Prices'!$N$24 -> 8.2169286 | K28: =K25*'Domestic NG Prices'!$N$24 -> 9.4287707 | L28: =L25*'Domestic NG Prices'!$N$24 -> 10.418988 | M28: =M25*'Domestic NG Prices'!$N$24 -> 10.539126 | ... O28: =O25*'Domestic NG Prices'!$N$24 -> 12.869021 | P28: 0 | Q28: =R28*0.9 -> 0 | R28: 0 | S28: 0 | T28: 0 | U28: =T28 -> 0 | W28: =R28 -> 0 | X28: 1.01 | Y28: 1.01 | Z28: 1.01 | AA28: 1.1 | AB28: 1.01
A29: *
A30: R4 | B30: MINNGAD1 | C30: Domestic natural gas - step 1 | D30: =Commodities!C$11 -> NGAD0 | E30: 2010 | F30: =F32*'Domestic NG Prices'!$N$19 -> 3.5667714 | G30: =G32*'Domestic NG Prices'!$N$19 -> 2.93191 | H30: =H32*'Domestic NG Prices'!$N$19 -> 3.427406 | I30: =I32*'Domestic NG Prices'!$N$19 -> 4.0985992 | J30: =J32*'Domestic NG Prices'!$N$19 -> 4.7260766 | K30: =K32*'Domestic NG Prices'!$N$19 -> 5.4230838 | L30: =L32*'Domestic NG Prices'!$N$19 -> 5.9926204 | M30: =M32*'Domestic NG Prices'!$N$19 -> 6.4965138 | ... O30: =O32*'Domestic NG Prices'!$N$19 -> 7.9327045 | P30: 0 | Q30: =R30*0.9 -> 0 | R30: 0 | S30: 0 | T30: 0 | U30: =T30 -> 0 | X30: 1.1 | Y30: 1.05 | Z30: 1.01 | AA30: 1.1 | AB30: 1.01
A31: R4 | B31: MINNGAD2 | C31: Domestic natural gas - step 2 | D31: =Commodities!C$11 -> NGAD0 | E31: 2010 | F31: =F32*'Domestic NG Prices'!$N$20 -> 3.8504918 | G31: =G32*'Domestic NG Prices'!$N$20 -> 3.1651301 | H31: =H32*'Domestic NG Prices'!$N$20 -> 3.7000405 | I31: =I32*'Domestic NG Prices'!$N$20 -> 4.4246241 | J31: =J32*'Domestic NG Prices'!$N$20 -> 5.1020145 | K31: =K32*'Domestic NG Prices'!$N$20 -> 5.8544654 | L31: =L32*'Domestic NG Prices'!$N$20 -> 6.4693061 | M31: =M32*'Domestic NG Prices'!$N$20 -> 7.013282 | ... O31: =O32*'Domestic NG Prices'!$N$20 -> 8.5637151 | P31: 0 | Q31: =R31*0.9 -> 0 | R31: 0 | S31: 0 | T31: 0 | U31: =T31 -> 0 | X31: 1.2 | Y31: 1.1 | Z31: 1.05 | AA31: 1.1 | AB31: 1.01
A32: R4 | B32: MINNGAD3 | C32: Domestic natural gas - step 3 | D32: =Commodities!C$11 -> NGAD0 | E32: 2010 | F32: ='Domestic NG Prices'!N42*'Domestic NG Prices'!$P$27*TechData_DelNGA!$I$17 -> 4.0531493 | G32: ='Domestic NG Prices'!O42*'Domestic NG Prices'!$P$27*TechData_DelNGA!$I$17*G8 -> 3.3317159 | H32: ='Domestic NG Prices'!P42*'Domestic NG Prices'!$P$27*TechData_DelNGA!$I$17*H8 -> 3.8947795 | I32: ='Domestic NG Prices'!Q42*'Domestic NG Prices'!$P$27*TechData_DelNGA!$I$17*I8 -> 4.6574991 | J32: ='Domestic NG Prices'!R42*'Domestic NG Prices'!$P$27*TechData_DelNGA!$I$17*J8 -> 5.3705416 | K32: ='Domestic NG Prices'!S42*'Domestic NG Prices'!$P$27*TechData_DelNGA!$I$17*K8 -> 6.1625952 | L32: ='Domestic NG Prices'!T42*'Domestic NG Prices'!$P$27*TechData_DelNGA!$I$17*L8 -> 6.8097959 | M32: =7.38240209732537*M8 -> 7.3824021 | N32: =8.15770788191657*N8 -> 8.1577079 | O32: =9.01443690134327*O8 -> 9.0144369 | P32: 0 | Q32: =R32*0.9 -> 0 | R32: 0 | S32: 0 | T32: 0 | U32: =T32 -> 0 | X32: 1.1 | Y32: 1.1 | Z32: 1.05 | AA32: 1.1 | AB32: 1.01
A33: R4 | B33: MINNGAD4 | C33: Domestic natural gas - step 4 | D33: =Commodities!C$11 -> NGAD0 | E33: 2010 | F33: =F32*'Domestic NG Prices'!$N$22 -> 4.3774012 | G33: =G32*'Domestic NG Prices'!$N$22 -> 3.5982532 | H33: =H32*'Domestic NG Prices'!$N$22 -> 4.2063619 | I33: =I32*'Domestic NG Prices'!$N$22 -> 5.030099 | J33: =J32*'Domestic NG Prices'!$N$22 -> 5.8001849 | K33: =K32*'Domestic NG Prices'!$N$22 -> 6.6556028 | L33: =L32*'Domestic NG Prices'!$N$22 -> 7.3545796 | M33: =M32*'Domestic NG Prices'!$N$22 -> 7.9729943 | ... O33: =O32*'Domestic NG Prices'!$N$22 -> 9.7355919 | P33: 0 | Q33: =R33*0.9 -> 0 | R33: 0 | S33: 0 | T33: 0 | U33: =T33 -> 0 | X33: 1.1 | Y33: 1.1 | Z33: 1.1 | AA33: 1.1 | AB33: 1.01
A34: R4 | B34: MINNGAD5 | C34: Domestic natural gas - step 5 | D34: =Commodities!C$11 -> NGAD0 | E34: 2010 | F34: =F32*'Domestic NG Prices'!$N$23 -> 4.5395272 | G34: =G32*'Domestic NG Prices'!$N$23 -> 3.7315218 | H34: =H32*'Domestic NG Prices'!$N$23 -> 4.362153 | I34: =I32*'Domestic NG Prices'!$N$23 -> 5.216399 | J34: =J32*'Domestic NG Prices'!$N$23 -> 6.0150066 | K34: =K32*'Domestic NG Prices'!$N$23 -> 6.9021066 | L34: =L32*'Domestic NG Prices'!$N$23 -> 7.6269714 | M34: =M32*'Domestic NG Prices'!$N$23 -> 8.2682903 | ... O34: =O32*'Domestic NG Prices'!$N$23 -> 10.096169 | P34: 0 | Q34: =R34*0.9 -> 0 | R34: 0 | S34: 0 | T34: 0 | U34: =T34 -> 0 | W34: =R34 -> 0 | X34: 1.01 | Y34: 1.01 | Z34: 1.01 | AA34: 1.1 | AB34: 1.01
A35: R4 | B35: MINNGAD6 | C35: Domestic natural gas - step 6 | D35: =Commodities!C$11 -> NGAD0 | E35: 2010 | F35: =F32*'Domestic NG Prices'!$N$24 -> 6.2013184 | G35: =G32*'Domestic NG Prices'!$N$24 -> 5.0975254 | H35: =H32*'Domestic NG Prices'!$N$24 -> 5.9590126 | I35: =I32*'Domestic NG Prices'!$N$24 -> 7.1259736 | J35: =J32*'Domestic NG Prices'!$N$24 -> 8.2169286 | K35: =K32*'Domestic NG Prices'!$N$24 -> 9.4287707 | L35: =L32*'Domestic NG Prices'!$N$24 -> 10.418988 | M35: =M32*'Domestic NG Prices'!$N$24 -> 11.295075 | ... O35: =O32*'Domestic NG Prices'!$N$24 -> 13.792088 | P35: 0 | Q35: =R35*0.9 -> 0 | R35: 0 | S35: 0 | T35: 0 | U35: =T35 -> 0 | W35: =R35 -> 0 | X35: 1.01 | Y35: 1.01 | Z35: 1.01 | AA35: 1.1 | AB35: 1.01
A36: *
A37: R5 | B37: MINNGAD1 | C37: Domestic natural gas - step 1 | D37: =Commodities!C$11 -> NGAD0 | E37: 2010 | F37: =F39*'Domestic NG Prices'!$N$19 -> 3.5667714 | G37: =G39*'Domestic NG Prices'!$N$19 -> 2.93191 | H37: =H39*'Domestic NG Prices'!$N$19 -> 3.427406 | I37: =I39*'Domestic NG Prices'!$N$19 -> 4.0985992 | J37: =J39*'Domestic NG Prices'!$N$19 -> 4.7260766 | K37: =K39*'Domestic NG Prices'!$N$19 -> 5.4230838 | L37: =L39*'Domestic NG Prices'!$N$19 -> 5.9926204 | M37: =M39*'Domestic NG Prices'!$N$19 -> 6.286944 | ... O37: =O39*'Domestic NG Prices'!$N$19 -> 7.6768048 | P37: 0 | Q37: =R37*0.9 -> 0 | R37: 0 | S37: 0 | T37: 0 | U37: =T37 -> 0 | X37: 1.1 | Y37: 1.05 | Z37: 1.01 | AA37: 1.1 | AB37: 1.01
A38: R5 | B38: MINNGAD2 | C38: Domestic natural gas - step 2 | D38: =Commodities!C$11 -> NGAD0 | E38: 2010 | F38: =F39*'Domestic NG Prices'!$N$20 -> 3.8504918 | G38: =G39*'Domestic NG Prices'!$N$20 -> 3.1651301 | H38: =H39*'Domestic NG Prices'!$N$20 -> 3.7000405 | I38: =I39*'Domestic NG Prices'!$N$20 -> 4.4246241 | J38: =J39*'Domestic NG Prices'!$N$20 -> 5.1020145 | K38: =K39*'Domestic NG Prices'!$N$20 -> 5.8544654 | L38: =L39*'Domestic NG Prices'!$N$20 -> 6.4693061 | M38: =M39*'Domestic NG Prices'!$N$20 -> 6.7870418 | ... O38: =O39*'Domestic NG Prices'!$N$20 -> 8.2874597 | P38: 0 | Q38: =R38*0.9 -> 0 | R38: 0 | S38: 0 | T38: 0 | U38: =T38 -> 0 | X38: 1.2 | Y38: 1.1 | Z38: 1.05 | AA38: 1.1 | AB38: 1.01
A39: R5 | B39: MINNGAD3 | C39: Domestic natural gas - step 3 | D39: =Commodities!C$11 -> NGAD0 | E39: 2010 | F39: ='Domestic NG Prices'!N42*'Domestic NG Prices'!$P$27*TechData_DelNGA!$I$20 -> 4.0531493 | G39: ='Domestic NG Prices'!O42*'Domestic NG Prices'!$P$27*TechData_DelNGA!$I$20*G8 -> 3.3317159 | H39: ='Domestic NG Prices'!P42*'Domestic NG Prices'!$P$27*TechData_DelNGA!$I$20*H8 -> 3.8947795 | I39: ='Domestic NG Prices'!Q42*'Domestic NG Prices'!$P$27*TechData_DelNGA!$I$20*I8 -> 4.6574991 | J39: ='Domestic NG Prices'!R42*'Domestic NG Prices'!$P$27*TechData_DelNGA!$I$20*J8 -> 5.3705416 | K39: ='Domestic NG Prices'!S42*'Domestic NG Prices'!$P$27*TechData_DelNGA!$I$20*K8 -> 6.1625952 | L39: ='Domestic NG Prices'!T42*'Domestic NG Prices'!$P$27*TechData_DelNGA!$I$20*L8 -> 6.8097959 | M39: =7.14425453277032*M8 -> 7.1442545 | N39: =7.89454986927814*N8 -> 7.8945499 | O39: =8.72364182332011*O8 -> 8.7236418 | P39: 0 | Q39: =R39*0.9 -> 0 | R39: 0 | S39: 0 | T39: 0 | U39: =T39 -> 0 | X39: 1.1 | Y39: 1.1 | Z39: 1.05 | AA39: 1.1 | AB39: 1.01
A40: R5 | B40: MINNGAD4 | C40: Domestic natural gas - step 4 | D40: =Commodities!C$11 -> NGAD0 | E40: 2010 | F40: =F39*'Domestic NG Prices'!$N$22 -> 4.3774012 | G40: =G39*'Domestic NG Prices'!$N$22 -> 3.5982532 | H40: =H39*'Domestic NG Prices'!$N$22 -> 4.2063619 | I40: =I39*'Domestic NG Prices'!$N$22 -> 5.030099 | J40: =J39*'Domestic NG Prices'!$N$22 -> 5.8001849 | K40: =K39*'Domestic NG Prices'!$N$22 -> 6.6556028 | L40: =L39*'Domestic NG Prices'!$N$22 -> 7.3545796 | M40: =M39*'Domestic NG Prices'!$N$22 -> 7.7157949 | ... O40: =O39*'Domestic NG Prices'!$N$22 -> 9.4215332 | P40: 0 | Q40: =R40*0.9 -> 0 | R40: 0 | S40: 0 | T40: 0 | U40: =T40 -> 0 | X40: 1.1 | Y40: 1.1 | Z40: 1.1 | AA40: 1.1 | AB40: 1.01
A41: R5 | B41: MINNGAD5 | C41: Domestic natural gas - step 5 | D41: =Commodities!C$11 -> NGAD0 | E41: 2010 | F41: =F39*'Domestic NG Prices'!$N$23 -> 4.5395272 | G41: =G39*'Domestic NG Prices'!$N$23 -> 3.7315218 | H41: =H39*'Domestic NG Prices'!$N$23 -> 4.362153 | I41: =I39*'Domestic NG Prices'!$N$23 -> 5.216399 | J41: =J39*'Domestic NG Prices'!$N$23 -> 6.0150066 | K41: =K39*'Domestic NG Prices'!$N$23 -> 6.9021066 | L41: =L39*'Domestic NG Prices'!$N$23 -> 7.6269714 | M41: =M39*'Domestic NG Prices'!$N$23 -> 8.0015651 | ... O41: =O39*'Domestic NG Prices'!$N$23 -> 9.7704788 | P41: 0 | Q41: =R41*0.9 -> 0 | R41: 0 | S41: 0 | T41: 0 | U41: =T41 -> 0 | W41: =R41 -> 0 | X41: 1.01 | Y41: 1.01 | Z41: 1.01 | AA41: 1.1 | AB41: 1.01
A42: R5 | B42: MINNGAD6 | C42: Domestic natural gas - step 6 | D42: =Commodities!C$11 -> NGAD0 | E42: 2010 | F42: =F39*'Domestic NG Prices'!$N$24 -> 6.2013184 | G42: =G39*'Domestic NG Prices'!$N$24 -> 5.0975254 | H42: =H39*'Domestic NG Prices'!$N$24 -> 5.9590126 | I42: =I39*'Domestic NG Prices'!$N$24 -> 7.1259736 | J42: =J39*'Domestic NG Prices'!$N$24 -> 8.2169286 | K42: =K39*'Domestic NG Prices'!$N$24 -> 9.4287707 | L42: =L39*'Domestic NG Prices'!$N$24 -> 10.418988 | M42: =M39*'Domestic NG Prices'!$N$24 -> 10.930709 | ... O42: =O39*'Domestic NG Prices'!$N$24 -> 13.347172 | P42: 0 | Q42: =R42*0.9 -> 0 | R42: 0 | S42: 0 | T42: 0 | U42: =T42 -> 0 | W42: =R42 -> 0 | X42: 1.01 | Y42: 1.01 | Z42: 1.01 | AA42: 1.1 | AB42: 1.01
A43: *
...

Sheet TechData_DelNGA
B1: TechData | C1: _GLOBAL,R0,R1,R2,R3,R4,R5,R6
F4: ~FI_T
B5: Region | C5: TechName | D5: TechDesc | E5: CommIN | F5: CommOUT | G5: NCAP_TLIFE | H5: EFF | I5: Share~UP
B6: *Domestic natural gas infrastructure
B7: R1 | C7: =Technologies!C$23 -> SCNGAD1 | D7: =Technologies!D$23 -> Domestic natural gas Existing infrastructure in R1 | E7: =Commodities!C$12 -> NGAD1 | G7: 55 | H7: 1
B8: =B7 -> R1 | F8: =Commodities!$C$9 -> NGA | I8: ='Domestic NG Production'!M59 -> 0.99573593
B9: =B8 -> R1 | F9: NGL | I9: ='Domestic NG Production'!M60 -> 0.0042640693
B10: R2 | C10: =Technologies!C$24 -> SCNGAD2 | D10: =Technologies!D$24 -> Domestic natural gas Existing infrastructure in R2 | E10: =Commodities!C$13 -> NGAD2 | G10: 55 | H10: 1
B11: =B10 -> R2 | F11: =Commodities!$C$9 -> NGA | I11: =I8 -> 0.99573593
B12: =B11 -> R2 | F12: NGL | I12: =I9 -> 0.0042640693
B13: R3 | C13: =Technologies!C$25 -> SCNGAD3 | D13: =Technologies!D$25 -> Domestic natural gas Existing infrastructure in R3 | E13: =Commodities!C$14 -> NGAD3 | G13: 55 | H13: 1
B14: =B13 -> R3 | F14: =Commodities!$C$9 -> NGA | I14: =I11 -> 0.99573593
B15: =B14 -> R3 | F15: NGL | I15: =I12 -> 0.0042640693
B16: R4 | C16: =Technologies!C$26 -> SCNGAD4 | D16: =Technologies!D$26 -> Domestic natural gas Existing infrastructure in R4 | E16: =Commodities!C$15 -> NGAD4 | G16: 55 | H16: 1
B17: =B16 -> R4 | F17: =Commodities!$C$9 -> NGA | I17: =I14 -> 0.99573593
B18: =B17 -> R4 | F18: NGL | I18: =I15 -> 0.0042640693
B19: R5 | C19: =Technologies!C$27 -> SCNGAD5 | D19: =Technologies!D$27 -> Domestic natural gas Existing infrastructure in R5 | E19: =Commodities!C$16 -> NGAD5 | G19: 55 | H19: 1
B20: =B19 -> R5 | F20: =Commodities!$C$9 -> NGA | I20: =I17 -> 0.99573593
B21: =B20 -> R5 | F21: NGL | I21: =I18 -> 0.0042640693
B22: R6 | C22: =Technologies!C$28 -> SCNGAD6 | D22: =Technologies!D$28 -> Domestic natural gas Existing infrastructure in R6 | E22: =Commodities!C$17 -> NGAD6 | G22: 55 | H22: 1
B23: =B22 -> R6 | F23: =Commodities!$C$9 -> NGA | I23: =I20 -> 0.99573593
B24: =B23 -> R6 | F24: NGL | I24: =I21 -> 0.0042640693
F27: ~FI_T
B28: Region | C28: TechName | D28: TechDesc | E28: CommIN | F28: CommOUT | G28: NCAP_TLIFE | H28: EFF | I28: ACT_BND~UP | J28: NCAP_COST
B29: * Imported natural gas Pipeline technologies
B30: =Technologies!$B$50 -> R1 | C30: =Technologies!$C$50 -> XNGAC1E | D30: =Technologies!$D$50 -> Existing Pipeline for Import Canadian natural gas to R1 | E30: =Commodities!C29 -> NGAC1 | F30: =Commodities!$C$9 -> NGA | G30: 55 | H30: 1 | I30: =NGACap!B17*Conv!$D$6*Conv!$J$5*10^9 -> 1412.2711
B31: =Technologies!$B$51 -> *R2 | C31: =Technologies!$C$51 -> XNGAC2E | D31: =Technologies!$D$51 -> Existing Pipeline for Import Canadian natural gas to R2 | E31: =Commodities!C30 -> NGAC2 | F31: =Commodities!$C$9 -> NGA | G31: 55 | H31: 1 | I31: 9999
B32: =Technologies!$B$52 -> *R3 | C32: =Technologies!$C$52 -> XNGAC3E | D32: =Technologies!$D$52 -> Existing Pipeline for Import Canadian natural gas to R3 | E32: =Commodities!C31 -> NGAC3 | F32: =Commodities!$C$9 -> NGA | G32: 55 | H32: 1 | I32: 9999
B33: =Technologies!$B$53 -> *R4 | C33: =Technologies!$C$53 -> XNGAC4E | D33: =Technologies!$D$53 -> Existing Pipeline for Import Canadian natural gas to R4 | E33: =Commodities!C32 -> NGAC4 | F33: =Commodities!$C$9 -> NGA | G33: 55 | H33: 1 | I33: 9999
B34: =Technologies!$B$54 -> *R5 | C34: =Technologies!$C$54 -> XNGAC5E | D34: =Technologies!$D$54 -> Existing Pipeline for Import Canadian natural gas to R5 | E34: =Commodities!C33 -> NGAC5 | F34: =Commodities!$C$9 -> NGA | G34: 55 | H34: 1 | I34: 9999
B35: =Technologies!$B$55 -> *R6 | C35: =Technologies!$C$55 -> XNGAC6E | D35: =Technologies!$D$55 -> Existing Pipeline for Import Canadian natural gas to R6 | E35: =Commodities!C34 -> NGAC6 | F35: =Commodities!$C$9 -> NGA | G35: 55 | H35: 1 | I35: 9999
B36: *LNG Terminals
B37: =Technologies!$B$57 -> R1 | C37: =Technologies!$C$57 -> XNGALE1E | D37: =Technologies!$D$57 -> Infrastructure for Import LNG to Existing terminal in R1 | E37: =Commodities!C35 -> NGALE1 | F37: =Commodities!$C$9 -> NGA | G37: 55 | H37: 1 | I37: 0
B38: =Technologies!$B$58 -> R4 | C38: =Technologies!$C$58 -> XNGALE4E | D38: =Technologies!$D$58 -> Infrastructure for Import LNG to Existing terminal in R4 - Manhattan | E38: =Commodities!C36 -> NGALE4 | F38: =Commodities!$C$9 -> NGA | G38: 55 | H38: 1 | I38: 0
B39: =Technologies!$B$59 -> R5 | C39: =Technologies!$C$59 -> XNGALE5E | D39: =Technologies!$D$59 -> Infrastructure for Import LNG to Existing terminal in R5 - Staten Island | E39: =Commodities!C37 -> NGALE5 | F39: =Commodities!$C$9 -> NGA | G39: 55 | H39: 1 | I39: 0
B42: Region | C42: TechName | D42: TechDesc | E42: CommIN | F42: CommOUT | G42: NCAP_START | H42: NCAP_TLIFE | I42: EFF | J42: ACT_BND~UP | K42: NCAP_COST
B43: * Imported natural gas Pipeline technologies
B44: =Technologies!$B$123 -> R1 | C44: =Technologies!$C$123 -> XNGAC1N | D44: =Technologies!$D$123 -> New Pipeline for Import Canadian natural gas to R1 | E44: =Commodities!C29 -> NGAC1 | F44: =Commodities!$C$9 -> NGA | G44: 2010 | H44: 55 | I44: 1 | K44: =NGExpansion!M72 -> 4.2380354
B45: =Technologies!$B$124 -> *R2 | C45: =Technologies!$C$124 -> XNGAC2N | D45: =Technologies!$D$124 -> New Pipeline for Import Canadian natural gas to R2 | E45: =Commodities!C30 -> NGAC2 | F45: =Commodities!$C$9 -> NGA | G45: 2010 | H45: 55 | I45: 1 | K45: =NGExpansion!M73 -> 2.62137
B46: =Technologies!$B$125 -> *R3 | C46: =Technologies!$C$125 -> XNGAC3N | D46: =Technologies!$D$125 -> New Pipeline for Import Canadian natural gas to R3 | E46: =Commodities!C31 -> NGAC3 | F46: =Commodities!$C$9 -> NGA | G46: 2010 | H46: 55 | I46: 1 | K46: =(NGExpansion!M75+NGExpansion!M76)/2 -> 8.5091105
...

Sheet TechData_ExIm
B1: TechData | C1: _GLOBAL,R0,R1,R2,R3,R4,R5,R6
F5: ~FI_T
B6: Region | C6: TechName | D6: TechDesc | E6: CommIN | F6: CommOUT | G6: *TID | H6: EFF | I6: NCAP_COST | J6: NCAP_FOM | K6: ACT_COST | L6: AFA
B7: *Natural gas change names
B8: =Technologies!B16 -> R1 | C8: =Technologies!C16 -> SCNGAR1 | D8: =Technologies!D16 -> Collector: Natural Gas R1 | E8: =Commodities!C$9 -> NGA | F8: =Commodities!C18 -> NGAR1 | G8: 2010 | H8: 1
B9: =Technologies!B17 -> R2 | C9: =Technologies!C17 -> SCNGAR2 | D9: =Technologies!D17 -> Collector: Natural Gas R2 | E9: =Commodities!C$9 -> NGA | F9: =Commodities!C19 -> NGAR2 | G9: 2010 | H9: 1
B10: R3 | C10: SCNGAR3 | D10: Collector: Natural Gas R3 | E10: =Commodities!C$9 -> NGA | F10: =Commodities!C20 -> NGAR3 | G10: 2010 | H10: 1
B11: R4 | C11: SCNGAR4 | D11: Collector: Natural Gas R4 | E11: =Commodities!C$9 -> NGA | F11: =Commodities!C21 -> NGAR4 | G11: 2010 | H11: 1
B12: R5 | C12: SCNGAR5 | D12: Collector: Natural Gas R5 | E12: =Commodities!C$9 -> NGA | F12: =Commodities!C22 -> NGAR5 | G12: 2010 | H12: 1
B13: R6 | C13: SCNGAR6 | D13: Collector: Natural Gas R6 | E13: =Commodities!C$9 -> NGA | F13: =Commodities!C23 -> NGAR6 | G13: 2010 | H13: 1

Sheet Domestic NG CUM
A1: EIA Report: U.S. Crude Oil, Natural Gas, and Natural Gas Liquids Proved Reserves, 2011
A2: http://www.eia.gov/naturalgas/crudeoilreserves/
A3: Table 10: Total natural gas proved reserves, reserves changes, and production, wet after lease separation, 2011
A4: billion cubic feet
C5: Changes in reserves during 2011 | Q5: Region | R5: Reserves by Region | S5: % Total | T5: Reserves PJ
B6: Published | J6: New Reservoir | Q6: R2 | R6: =L33 -> 253 | S6: =R6/$R$14 -> 0.00072532532 | T6: =R6*1000000000*Conv!$D$6*Conv!$J$5*40 -> 10912.064
B7: Proved | D7: Revision | E7: Revision | I7: New Field | J7: Discoveries | K7: Estimated | L7: Proved | Q7: R3 | R7: =L27+L35 -> 3307 | S7: =R7/$R$14 -> 0.0094808334 | T7: =R7*1000000000*Conv!$D$6*Conv!$J$5*20 -> 71316.595
B8: Reserves | C8: Adjustments | D8: Increases | E8: Decreases | F8: Sales | G8: Acquisitions | H8: Extensions | I8: Discoveries | J8: in Old Fields | K8: Production | L8: Reserves | N8: MARKAL REGION | Q8: R4 | R8: =L21+L34 -> 6399 | S8: =R8/$R$14 -> 0.018345284 | T8: =R8*1000000000*Conv!$D$6*Conv!$J$5*20 -> 137996.64
A9: State and subdivision | B9: 40543 | C9: (+,-) | D9: (+) | E9: (-) | F9: (-) | G9: (+) | H9: (+) | I9: (+) | J9: (+) | K9: (-) | L9: 40908 | Q9: R5 | R9: =L20+L53+L54 -> 13370 | S9: =R9/$R$14 -> 0.038330433 | T9: =R9*1000000000*Conv!$D$6*Conv!$J$5*20 -> 288328.66
A10: Alaska | B10: 8917 | C10: -2 | D10: 938 | E10: 207 | F10: 36 | G10: 222 | H10: 4 | I10: 0 | J10: 3 | K10: 328 | L10: 9511 | N10: 9 | Q10: R6 | R10: =L12+L22+L28 -> 5566 | S10: =R10/$R$14 -> 0.015957157 | T10: =R10*1000000000*Conv!$D$6*Conv!$J$5*20 -> 120032.71
A11: Lower 48 States | B11: 308730 | C11: 2717 | D11: 55077 | E11: 55920 | F11: 44539 | G11: 47651 | H11: 47631 | I11: 987 | J11: 1257 | K11: 24293 | L11: 339298 | Q11: R7 | R11: =L13+L23+L36+L38+L58+L59 -> 191419 | S11: =R11/$R$14 -> 0.54877884 | T11: =R11*1000000000*Conv!$D$6*Conv!$J$5*20 -> 4128016.7
A12: Alabama | B12: 2724 | C12: -45 | D12: 472 | E12: 163 | F12: 595 | G12: 398 | H12: 3 | I12: 2 | J12: 0 | K12: 226 | L12: 2570 | N12: 6 | Q12: R8 | R12: =L19+L29+L30+L52+L55 -> 88119 | S12: =R12/$R$14 -> 0.25262823 | T12: =R12*1000000000*Conv!$D$6*Conv!$J$5*20 -> 1900316.6
A13: Arkansas | B13: 14181 | C13: 729 | D13: 631 | E13: 324 | F13: 6762 | G13: 6882 | H13: 2094 | I13: 0 | J13: 23 | K13: 1080 | L13: 16374 | N13: 7 | Q13: R9 | R13: =L10+L14+L57 -> 13264 | S13: =R13/$R$14 -> 0.038026542 | T13: =R13*1000000000*Conv!$D$6*Conv!$J$5*20 -> 286042.73
A14: California | B14: 2785 | C14: 917 | D14: 1542 | E14: 1959 | F14: 49 | G14: 55 | H14: 75 | I14: 0 | J14: 0 | K14: 324 | L14: 3042 | N14: 9 | Q14: Total | R14: =SUM(R6:R13)+L60+L37 -> 348809 | S14: =SUM(S6:S13) -> 0.92227265 | T14: =SUM(T6:T13) -> 6942962.7
A15: Coastal Region Onshore | B15: 180 | C15: 15 | D15: 21 | E15: 32 | F15: 0 | G15: 0 | H15: 1 | I15: 0 | J15: 0 | K15: 12 | L15: 173
A16: Los Angeles Basin Onshore | B16: 92 | C16: 6 | D16: 12 | E16: 4 | F16: 0 | G16: 3 | H16: 0 | I16: 0 | J16: 0 | K16: 7 | L16: 102
A17: San Joaquin Basin Onshore | B17: 2447 | C17: 895 | D17: 1498 | E17: 1923 | F17: 47 | G17: 44 | H17: 71 | I17: 0 | J17: 0 | K17: 300 | L17: 2685
A18: State Offshore | B18: 66 | C18: 1 | D18: 11 | E18: 0 | F18: 2 | G18: 8 | H18: 3 | I18: 0 | J18: 0 | K18: 5 | L18: 82
A19: Colorado | B19: 25372 | C19: 883 | D19: 2644 | E19: 3077 | F19: 1311 | G19: 1283 | H19: 2123 | I19: 19 | J19: 0 | K19: 1785 | L19: 26151 | N19: 8
A20: Florida | B20: 56 | C20: -54 | D20: 13 | E20: 9 | F20: 0 | G20: 0 | H20: 0 | I20: 0 | J20: 0 | K20: 0 | L20: 6 | N20: 5
A21: Kansas | B21: 3937 | C21: 145 | D21: 164 | E21: 258 | F21: 133 | G21: 131 | H21: 66 | I21: 0 | J21: 1 | K21: 306 | L21: 3747 | N21: 4
A22: Kentucky | B22: 2785 | C22: -48 | D22: 188 | E22: 678 | F22: 106 | G22: 89 | H22: 4 | I22: 2 | J22: 0 | K22: 108 | L22: 2128 | N22: 6
A23: Louisiana | B23: 29517 | C23: 126 | D23: 3789 | E23: 5877 | F23: 5618 | G23: 5585 | H23: 5813 | I23: 49 | J23: 169 | K23: 3008 | L23: 30545 | N23: 7
A24: North | B24: 26136 | C24: 177 | D24: 3105 | E24: 5335 | F24: 4999 | G24: 5060 | H24: 5693 | I24: 0 | J24: 144 | K24: 2570 | L24: 27411
A25: South Onshore | B25: 2995 | C25: -48 | D25: 627 | E25: 523 | F25: 608 | G25: 381 | H25: 104 | I25: 49 | J25: 25 | K25: 387 | L25: 2615
A26: State Offshore | B26: 386 | C26: -3 | D26: 57 | E26: 19 | F26: 11 | G26: 144 | H26: 16 | I26: 0 | J26: 0 | K26: 51 | L26: 519
A27: Michigan | B27: 2975 | C27: 5 | D27: 213 | E27: 272 | F27: 654 | G27: 410 | H27: 0 | I27: 14 | J27: 0 | K27: 142 | L27: 2549 | N27: 3
A28: Mississippi | B28: 858 | C28: 112 | D28: 106 | E28: 157 | F28: 11 | G28: 10 | H28: 24 | I28: 1 | J28: 0 | K28: 75 | L28: 868 | N28: 6
A29: Montana | B29: 959 | C29: -58 | D29: 44 | E29: 99 | F29: 45 | G29: 45 | H29: 14 | I29: 7 | J29: 1 | K29: 76 | L29: 792 | N29: 8
A30: New Mexico | B30: 16529 | C30: 107 | D30: 2267 | E30: 2386 | F30: 1088 | G30: 1155 | H30: 802 | I30: 3 | J30: 9 | K30: 1260 | L30: 16138 | N30: 8
A31: East | B31: 4720 | C31: -143 | D31: 560 | E31: 481 | F31: 222 | G31: 286 | H31: 579 | I31: 3 | J31: 2 | K31: 420 | L31: 4884
A32: West | B32: 11809 | C32: 250 | D32: 1707 | E32: 1905 | F32: 866 | G32: 869 | H32: 223 | I32: 0 | J32: 7 | K32: 840 | L32: 11254
A33: New York | B33: 281 | C33: -22 | D33: 48 | E33: 50 | F33: 0 | G33: 0 | H33: 0 | I33: 0 | J33: 27 | K33: 31 | L33: 253 | N33: 2
A34: North Dakota | B34: 1869 | C34: -15 | D34: 635 | E34: 417 | F34: 126 | G34: 188 | H34: 638 | I34: 11 | J34: 18 | K34: 149 | L34: 2652 | N34: 4
A35: Ohio | B35: 832 | C35: -99 | D35: 17 | E35: 38 | F35: 0 | G35: 4 | H35: 118 | I35: 0 | J35: 0 | K35: 76 | L35: 758 | N35: 3
A36: Oklahoma | B36: 28182 | C36: -238 | D36: 5531 | E36: 7375 | F36: 3222 | G36: 2645 | H36: 6170 | I36: 50 | J36: 19 | K36: 1825 | L36: 29937 | N36: 7
A37: Pennsylvania | B37: 14068 | C37: -231 | D37: 7127 | E37: 4907 | F37: 805 | G37: 1897 | H37: 10337 | I37: 166 | J37: 324 | K37: 1257 | L37: 26719 | N37: 2
A38: Texas | B38: 94287 | C38: 676 | D38: 21098 | E38: 20135 | F38: 21329 | G38: 23629 | H38: 13321 | I38: 72 | J38: 446 | K38: 7611 | L38: 104454 | N38: 7
A39: RRC District 1 | B39: 2599 | C39: -57 | D39: 2303 | E39: 180 | F39: 1237 | G39: 1181 | H39: 1718 | I39: 24 | J39: 2 | K39: 226 | L39: 6127
A40: RRC District 2 Onshore | B40: 2235 | C40: 210 | D40: 458 | E40: 593 | F40: 175 | G40: 684 | H40: 1079 | I40: 0 | J40: 122 | K40: 330 | L40: 3690
...

Sheet NGACap
A1: Trade Links
B2: 2005 Capacity (billion cubic feet per year) | C2: 2010 | D2: 2015 | E2: 2020 | F2: 2025 | G2: 2030
A3: R2 to R1 | B3: =B29*T29 -> 841.51091 | C3: =C29*U29 -> 931.00691 | D3: =D29*V29 -> 997.0439 | E3: =E29*W29 -> 1089.6932 | F3: =F29*X29 -> 1161.4342 | G3: =G29*Y29 -> 1090.645
A4: R3 to R2 | B4: =B30*N77*T30 -> 711.53892 | C4: =C30*O77*U30 -> 740.76291 | D4: =D30*P77*V30 -> 588.95718 | E4: =E30*Q77*W30 -> 1127.4329 | F4: =F30*R77*X30 -> 1672.5097 | G4: =G30*S77*Y30 -> 1650.0836
A5: R3 to R5 | B5: =B35*N95*T35 -> 738.8962 | C5: =C35*O95*U35 -> 675.84918 | D5: =D35*P95*V35 -> 569.7805 | E5: =E35*Q95*W35 -> 474.1315 | F5: =F35*R95*X35 -> 431.72837 | G5: =G35*S95*Y35 -> 496.12024
A6: R4 to R3 | B6: =B33*N83*T33 -> 3980.2715 | C6: =C33*O83*U33 -> 3879.6746 | D6: =D33*P83*V33 -> 3479.9697 | E6: =E33*Q83*W33 -> 3130.7141 | F6: =F33*R83*X33 -> 2867.0799 | G6: =G33*S83*Y33 -> 2649.7341
A7: R5 to R2 | B7: =B30*N78*T30 -> 2370.5572 | C7: =C30*O78*U30 -> 2382.1156 | D7: =D30*P78*V30 -> 2721.9842 | E7: =E30*Q78*W30 -> 2256.1001 | F7: =F30*R78*X30 -> 1640.5264 | G7: =G30*S78*Y30 -> 1544.3135
A8: R6 to R3 | B8: =B33*N84*T33 -> 1773.1273 | C8: =C33*O84*U33 -> 2289.265 | D8: =D33*P84*V33 -> 2944.4108 | E8: =E33*Q84*W33 -> 3324.3184 | F8: =F33*R84*X33 -> 3587.8594 | G8: =G33*S84*Y33 -> 3665.113
A9: R6 to R5 | B9: =B35*N96*T35 -> 2906.9313 | C9: =C35*O96*U35 -> 2912.2119 | D9: =D35*P96*V35 -> 3495.0084 | E9: =E35*Q96*W35 -> 3360.2108 | F9: =F35*R96*X35 -> 3267.1702 | G9: =G35*S96*Y35 -> 3050.4881
A10: R7 to R4 | B10: =B34*N87*T34 -> 2921.7356 | C10: =C34*O87*U34 -> 2053.023 | D10: =D34*P87*V34 -> 3033.7256 | E10: =E34*Q87*W34 -> 3118.3711 | F10: =F34*R87*X34 -> 3206.3104 | G10: =G34*S87*Y34 -> 2906.3653
A11: R7 to R6 | B11: =B36*T36 -> 5576.4599 | C11: =C36*U36 -> 6099.0257 | D11: =D36*V36 -> 7138.2818 | E11: =E36*W36 -> 7094.0284 | F11: =F36*X36 -> 6684.2628 | G11: =G36*Y36 -> 6576.5555
A12: R8 to R4 | B12: =B34*N88*T34 -> 1950.4105 | C12: =C34*O88*U34 -> 3120.4368 | D12: =D34*P88*V34 -> 2060.4607 | E12: =E34*Q88*W34 -> 2050.3612 | F12: =F34*R88*X34 -> 1955.9731 | G12: =G34*S88*Y34 -> 2161.9355
A13: R8 to R7 | B13: =B37*T37 -> 804.90139 | C13: =C37*U37 -> 745.47851 | D13: =D37*V37 -> 606.87026 | E13: =E37*W37 -> 712.04625 | F13: =F37*X37 -> 721.60296 | G13: =G37*Y37 -> 689.48573 | V13: * Taken from the AEO2007
A14: R8 to R9 | B14: =B39*T39 -> 2785.1306 | C14: =C39*U39 -> 2904.4028 | D14: =D39*V39 -> 3130.4791 | E14: =E39*W39 -> 3104.6554 | F14: =F39*X39 -> 3205.0279 | G14: =G39*Y39 -> 3297.0241
A16: Canada to R1 | B16: =B41*N71 -> 314.14553 | C16: =C41*O71 -> 269.64204 | D16: =D41*P71 -> 337.47455 | E16: =E41*Q71 -> 328.83673 | F16: =F41*R71 -> 222.48607 | G16: =G41*S71 -> 180.89989 | V16: * For more information on capacity use see
A17: Canada to R2 | B17: =B41*N79 -> 1309.7599 | C17: =C41*O79 -> 902.0752 | D17: =D41*P79 -> 751.79975 | E17: =E41*Q79 -> 610.69679 | F17: =F41*R79 -> 374.27563 | G17: =G41*S79 -> 305.65843 | V17: http://www.eia.gov/pub/oil_gas/natural_gas/analysis_publications/ngpipeline/usage.html
A18: Canada to R4 | B18: =B41*N89 -> 3318.1196 | C18: =C41*O89 -> 3422.0027 | D18: =D41*P89 -> 3991.2213 | E18: =E41*Q89 -> 4450.5295 | F18: =F41*R89 -> 3983.9561 | G18: =G41*S89 -> 4038.0182
A19: Canada to R8 | B19: =B41*N106 -> 73.271147 | C19: =C41*O106 -> 23.667128 | D19: =D41*P106 -> 51.364972 | E19: =E41*Q106 -> 69.4675 | F19: =F41*R106 -> 78.2614 | G19: =G41*S106 -> 90.173499
A20: Canada to R9 | B20: =B41*N110 -> 1486.5539 | C20: =C41*O110 -> 1527.9716 | D20: =D41*P110 -> 1506.9408 | E20: =E41*Q110 -> 1958.7232 | F20: =F41*R110 -> 2035.6435 | G20: =G41*S110 -> 2229.0193
A24: Table 109. Natural Gas Pipeline Capacity By Census Division | F24: * Taken from the AEO2007 | M24: Table 110. Natural Gas Pipeline Capacity Utilization 1/ by Census Division
A25: (design capacity in billion cubic feet per year) | M25: (fraction)
T26: Utilization
B27: 2005 | C27: 2010 | D27: 2015 | E27: 2020 | F27: 2025 | G27: 2030 | N27: 2005 | O27: 2010 | P27: 2015 | Q27: 2020 | R27: 2025 | S27: 2030 | T27: 2005 | U27: 2010 | V27: 2015 | W27: 2020 | X27: 2025 | Y27: 2030
A28: Capacity Entering Region 1/ | M28: Utilization Entering Region
A29: New England | B29: 1457.46 | C29: 1807.6101 | D29: 1962.6101 | E29: 1962.6101 | F29: 1962.6101 | G29: 1962.6101 | M29: New England | N29: 0.52738184 | O29: 0.46504852 | P29: 0.45801935 | Q29: 0.50522655 | R29: 0.54178041 | S29: 0.5057115 | T29: =N29+0.05 -> 0.57738184 | U29: =O29+0.05 -> 0.51504852 | V29: =P29+0.05 -> 0.50801935 | W29: =Q29+0.05 -> 0.55522655 | X29: =R29+0.05 -> 0.59178041 | Y29: =S29+0.05 -> 0.5557115
A30: Middle Atlantic | B30: 4835.2114 | C30: 4894.7065 | D30: 4894.7065 | E30: 4894.7065 | F30: 4894.7065 | G30: 4894.7065 | M30: Middle Atlantic | N30: 0.58742738 | O30: 0.58801138 | P30: 0.62643307 | Q30: 0.64126372 | R30: 0.62686104 | S30: 0.60262281 | T30: =N30+0.05 -> 0.63742738 | U30: =O30+0.05 -> 0.63801138 | V30: =P30+0.05 -> 0.67643307 | W30: =Q30+0.05 -> 0.69126372 | X30: =R30+0.05 -> 0.67686104 | Y30: =S30+0.05 -> 0.65262281
A31: NYS | C31: =#REF!+#REF!+#REF!+#REF!+#REF!+#REF!+#REF!+#REF!+#REF!+#REF!+#REF!+#REF!+#REF!+#REF!+#REF!+#REF!+#REF!+#REF!+#REF!+#REF!+#REF!+#REF!+#REF!+#REF! -> #REF! | D31: =SUM(#REF!) -> #REF!
A32: (%) | C32: =C31/C30 -> #REF! | D32: =D31/D30 -> #REF!
A33: East North Central | B33: 9278.541 | C33: 9717.5576 | D33: 10323.524 | E33: 10380.955 | F33: 10426.616 | G33: 10426.616 | M33: East North Central | N33: 0.57007581 | O33: 0.58482409 | P33: 0.57230496 | Q33: 0.57181489 | R33: 0.56908286 | S33: 0.55564684 | T33: =N33+0.05 -> 0.62007581 | U33: =O33+0.05 -> 0.63482409 | V33: =P33+0.05 -> 0.62230496 | W33: =Q33+0.05 -> 0.62181489 | X33: =R33+0.05 -> 0.61908286 | Y33: =S33+0.05 -> 0.60564684
A34: West North Central | B34: 7584.0049 | C34: 8211.8047 | D34: 8441.9521 | E34: 9374.9512 | F34: 9467.4111 | G34: 9467.4111 | M34: West North Central | N34: 0.59242392 | O34: 0.58000278 | P34: 0.55343699 | Q34: 0.50133431 | R34: 0.49526876 | S34: 0.48534179 | T34: =N34+0.05 -> 0.64242392 | U34: =O34+0.05 -> 0.63000278 | V34: =P34+0.05 -> 0.60343699 | W34: =Q34+0.05 -> 0.55133431 | X34: =R34+0.05 -> 0.54526876 | Y34: =S34+0.05 -> 0.53534179
A35: South Atlantic | B35: 7253.3164 | C35: 7594.7383 | D35: 7594.7383 | E35: 7594.7383 | F35: 7594.7383 | G35: 7594.7383 | M35: South Atlantic | N35: 0.45264283 | O35: 0.42244038 | P35: 0.48521119 | Q35: 0.45486826 | R35: 0.43703437 | S35: 0.41698229 | T35: =N35+0.05 -> 0.50264283 | U35: =O35+0.05 -> 0.47244038 | V35: =P35+0.05 -> 0.53521119 | W35: =Q35+0.05 -> 0.50486826 | X35: =R35+0.05 -> 0.48703437 | Y35: =S35+0.05 -> 0.46698229
A36: East South Central | B36: 9910.8145 | C36: 12035.144 | D36: 12035.144 | E36: 12035.144 | F36: 12035.144 | G36: 12035.144 | M36: East South Central | N36: 0.51266414 | O36: 0.45676801 | P36: 0.54311979 | Q36: 0.53944278 | R36: 0.50539535 | S36: 0.49644595 | T36: =N36+0.05 -> 0.56266414 | U36: =O36+0.05 -> 0.50676801 | V36: =P36+0.05 -> 0.59311979 | W36: =Q36+0.05 -> 0.58944278 | X36: =R36+0.05 -> 0.55539535 | Y36: =S36+0.05 -> 0.54644595
A37: West South Central | B37: 2155.0769 | C37: 2180.51 | D37: 2180.51 | E37: 2180.51 | F37: 2180.51 | G37: 2180.51 | M37: West South Central | N37: 0.3234908 | O37: 0.29188263 | P37: 0.22831574 | Q37: 0.27655032 | R37: 0.28093311 | S37: 0.26620388 | T37: =N37+0.05 -> 0.3734908 | U37: =O37+0.05 -> 0.34188263 | V37: =P37+0.05 -> 0.27831574 | W37: =Q37+0.05 -> 0.32655032 | X37: =R37+0.05 -> 0.33093311 | Y37: =S37+0.05 -> 0.31620388
A38: Mountain | B38: 2821.46 | C38: 2821.46 | D38: 2821.46 | E38: 2841.8293 | F38: 2843.8479 | G38: 2843.8479 | M38: Mountain | N38: 0.12451178 | O38: 0.13006356 | P38: 0.13062556 | Q38: 0.12941578 | R38: 0.13097328 | S38: 0.13185398 | T38: =N38+0.05 -> 0.17451178 | U38: =O38+0.05 -> 0.18006356 | V38: =P38+0.05 -> 0.18062556 | W38: =Q38+0.05 -> 0.17941578 | X38: =R38+0.05 -> 0.18097328 | Y38: =S38+0.05 -> 0.18185398
A39: Pacific | B39: 4559.9697 | C39: 4603.77 | D39: 4603.77 | E39: 5232.583 | F39: 5294.6895 | G39: 5294.6895 | M39: Pacific | N39: 0.56077832 | O39: 0.58087486 | P39: 0.62998164 | Q39: 0.54333133 | R39: 0.55532879 | S39: 0.57270396 | T39: =N39+0.05 -> 0.61077832 | U39: =O39+0.05 -> 0.63087486 | V39: =P39+0.05 -> 0.67998164 | W39: =Q39+0.05 -> 0.59333133 | X39: =R39+0.05 -> 0.60532879 | Y39: =S39+0.05 -> 0.62270396
A40: Total | B40: 49855.855 | C40: 53867.301 | D40: 54858.418 | E40: 56498.027 | F40: 56700.277 | G40: 56700.277 | M40: Average 2/ | N40: 0.50868762 | O40: 0.4928394 | P40: 0.52013314 | Q40: 0.5049209 | R40: 0.49525565 | S40: 0.48430136 | T40: =N40+0.05 -> 0.55868762 | U40: =O40+0.05 -> 0.5428394 | V40: =P40+0.05 -> 0.57013314 | W40: =Q40+0.05 -> 0.5549209 | X40: =R40+0.05 -> 0.54525565 | Y40: =S40+0.05 -> 0.53430136
A41: United States (Pipeline Imports) | B41: 6501.8501 | C41: 6945.0752 | D41: 7100.0752 | E41: 8680.1602 | F41: 8836.7451 | G41: 8836.7451 | M41: United States (Pipeline Imports) | N41: 0.64688349 | O41: 0.56445765 | P41: 0.53024685 | Q41: 0.50292164 | R41: 0.47014397 | S41: 0.44361678 | T41: =N41+0.05 -> 0.69688349 | U41: =O41+0.05 -> 0.61445765 | V41: =P41+0.05 -> 0.58024685 | W41: =Q41+0.05 -> 0.55292164 | X41: =R41+0.05 -> 0.52014397 | Y41: =S41+0.05 -> 0.49361678
A43: Capacity Exiting Region 2/ | M43: Utilization Exiting Region
A44: New England | B44: 132.86 | C44: 132.86 | D44: 132.86 | E44: 132.86 | F44: 132.86 | G44: 132.86 | M44: New England | N44: 0.79432482 | O44: 0.79432482 | P44: 0.79432482 | Q44: 0.79432482 | R44: 0.79432482 | S44: 0.79432482
A45: Middle Atlantic | B45: 2280.4526 | C45: 2598.9807 | D45: 2598.9807 | E45: 2598.9807 | F45: 2598.9807 | G45: 2598.9807 | M45: Middle Atlantic | N45: 0.28399223 | O45: 0.26432943 | P45: 0.27671316 | Q45: 0.29788712 | R45: 0.30035669 | S45: 0.27832127
...

Sheet Domestic NG Production
A1: Workbook Source (EIA)
A2: Natural Gas Gross Withdrawals and Production | F2: * Volume in million cubic feet
A4: Click worksheet name or tab at bottom for data
A5: Worksheet Name | B5: Description | C5: # Of Series | D5: Frequency | E5: Latest Data for
A6: Data 1 | C6: 10 | D6: Annual | E6: 2011 | F6: 6/30/1967
A8: Release Date: | B8: 8/31/2012
A9: Next Release Date: | B9: 9/28/2012
A11: Excel File Name: | B11: ng_prod_sum_dcu_nus_a.xls
A12: Available from Web Page: | B12: http://www.eia.gov/dnav/ng/ng_prod_sum_dcu_nus_a.htm
A13: Source: | B13: Energy Information Administration
A14: For Help, Contact: | B14: infoctr@eia.gov
B15: (202) 586-8800 | E15: 8/30/2012 2:29:48 PM
F17: *6.1% to R6 based on Reserves
B18: 9 | F18: 7,6 | J18: 7 | N18: 8 | R18: 7 | V18: 7 | Z18: 8 | AD18: 6 | AH18: 8 | AL18: 7 | AP18: 9 | AT18: 8 | AX18: 5 | BB18: 3 | BF18: 3 | BJ18: 4 | BN18: 6 | BR18: 5 | BV18: 3 | BZ18: 6 | CD18: 8 | CH18: 4 | CL18: 8 | CP18: 2 | CT18: 4 | CX18: 3 | DB18: 9 | DF18: 2 | DJ18: 4 | DN18: 6 | DR18: 8 | DV18: 5 | DZ18: 5
