Workbook
Name __HDV50: #REF!
Name __LDV50: #REF!
Name _1995_Implicit_GDP_Deflator: #REF!
Name _1995_Implicit_GDP_Deflator: #REF!
Name _1995_Implicit_GDP_Deflator: #REF!
Name _1995_Implicit_GDP_Deflator: #REF!
Name _2001_Implicit_GDP_Deflator: #REF!
Name _2001_Implicit_GDP_Deflator: #REF!
Name _2001_Implicit_GDP_Deflator: #REF!
Name _2001_Implicit_GDP_Deflator: #REF!
Name _HDV50: #REF!
Name _HDV50: #REF!
Name _HDV50: #REF!
Name _HDV50: #REF!
Name _LDV50: #REF!
Name _LDV50: #REF!
Name _LDV50: #REF!
Name _LDV50: #REF!
Name Age_of_car: #REF!
Name Age_of_car: #REF!
Name Age_of_car: #REF!
Name Age_of_car: #REF!
Name avg_water_heater_PJ: '[1]AEO HW'!$B$33
Name avg_water_heater_PJ: '[2]AEO HW'!$B$33
Name btu_per_watthr: #REF!
Name btu_per_watthr: #REF!
Name btu_per_watthr: #REF!
Name btu_per_watthr: #REF!
Name conv: #REF!
Name conv: #REF!
Name conv: #REF!
Name conv: #REF!
Name days_per_year: #REF!
Name days_per_year: #REF!
Name days_per_year: #REF!
Name days_per_year: #REF!
Name Diesel_Car_CO: #REF!
Name Diesel_Car_CO: #REF!
Name Diesel_Car_CO: #REF!
Name Diesel_Car_CO: #REF!
Name Diesel_Car_Nox: #REF!
Name Diesel_Car_Nox: #REF!
Name Diesel_Car_Nox: #REF!
Name Diesel_Car_Nox: #REF!
Name Diesel_Car_PM: #REF!
Name Diesel_Car_PM: #REF!
Name Diesel_Car_PM: #REF!
Name Diesel_Car_PM: #REF!
Name Diesel_Car_VOCs: #REF!
Name Diesel_Car_VOCs: #REF!
Name Diesel_Car_VOCs: #REF!
Name Diesel_Car_VOCs: #REF!
Name Diesel_HDT_CO: #REF!
Name Diesel_HDT_CO: #REF!
Name Diesel_HDT_CO: #REF!
Name Diesel_HDT_CO: #REF!
Name Diesel_HDT_NOx: #REF!
Name Diesel_HDT_NOx: #REF!
Name Diesel_HDT_NOx: #REF!
Name Diesel_HDT_NOx: #REF!

Sheet ANSv6.0-Commodities
A1: ANSWER-Commodities
B7: CommName | C7: CommDesc | D7: CommUnit | E7: Set Memberships | F7: Comment

Sheet Readme
B1: Readme - 05-12-2022
B3: For questions contact: Ozge Kaplan, kaplan.ozge@epa.gov, 919-541-5069
B4: Contributors:
B5: Mine Isik, Former ORISE
B6: Andrew Zalesak, ORISE
B8: General Notes
B9: Tabs for pages that consist primarily of input data are colored blue
B10: Tabs for pages that consist primarily of calculations are white
B11: Tabs for pages that are read into Answer are colored yellow
B12: The tabs generally should be navigated from right to left, e.g., the
B13: pages with input data tables are the right-most. Calculations
B14: come next (with each subsequent page typically building on the
... B20: Population Data ("Population")
C21: '- U.S. Census Bureau projections
C22: '- U.S. EPA ORD Integrated Land Use Scenarios model projections
C23: - NYC Population Estimates
B24: Vehicle Miles Traveled Breakdown by Region ("Demands")
C25: '- EIA Household Transportation Energy Use Survey, 2001
B27: Price Deflators to Convert Costs to $2000 ("GDPdeflator")
C28: '- Bureau of Economic Analysis NIPA Table 1.1.9
B30: Vehicle Sales Data by Class ("Sales Data")
C31: '- EIA Annual Energy Outlook 2008, Table 51
B33: Technology Cost and Efficiency Estimates ("AEO08 T59","AEO08 T60","OTAQ-Car","OTAQ-Truck","QM2002")
C34: '- EIA Annual Energy Outlook 2008, Tables 59 and 60
C35: '- OTAQ vehicle assumptions for SGM provided by Simon Mui
C36: '- Vehicle maintenance estimates from DOE's Quality Metrics Report 2002
B38: Emissions (ICF WA on County Level MOVES runs)
C39: -county simulated MOVES runs
B41: Existing Fleet Info
C42: '- Transportation Energy Data book, Edition 21
C43: - NYC.GOV
B46: General Flow of Operations for Preparing Data for Input to ANSWER
B47: Demand Calculation:
C48: '- Regional VMT demands are calculated in "VMT by Region"
B50: Vehicle Characterization:
C51: '- Vehicle efficiency and cost calculations for vehicles described in AEO are provided in the "Costs" and "Efficiencies" pages
C52: - Additional vehicle types are characterized in "AdditionalVehs"
C53: '- The AEO and additional vehicle data are consolidated in "ConsolidatedVehData"
B55: Emissions Characterization:
C56: - Emission factors from MOVES are consolidated in "NewEmisData"
...

Sheet Commodities
B1: Commodities | C1: R1,R2,R3,R4,R5,R6
B6: ~FI_Comm
B7: Region | C7: CommName | D7: CommDesc | E7: Unit | F7: Csets | G7: LimType | H7: CTSLvl | I7: PeakTS | J7: Ctype | O7: Comment
B8: *Demands
B9: R1,R2,R3,R4,R5,R6 | C9: TA | D9: TRN.AIR | E9: bn-pass-miles | F9: DEM
B10: R2,R3,R4,R5,R6 | C10: TB | D10: TRN.BUS | E10: bn-vmt | F10: DEM
B11: R2,R3,R4,R5,R6 | C11: TM | D11: TRN.Medium Duty Trucks | E11: bn-vmt | F11: DEM
B12: R2,R3,R4,R5,R6 | C12: THS | D12: TRN.HDV Short Haul | E12: bn-vmt | F12: DEM
B13: *R1,R2,R3,R4,R5,R6 | C13: THL | D13: TRN.HDV Long Haul | E13: bn-vmt | F13: DEM
B14: R1,R2,R3,R4,R5,R6 | C14: TS | D14: TRN.SHIP | E14: bn-t-m | F14: DEM
B15: *R2,R3,R4,R5,R6 | C15: TRF | D15: TRN.RAIL.FREIGHT | E15: bn-t-m | F15: DEM
B16: *R2,R3,R4,R5,R6 | C16: TSW | D16: TRN.MSW | E16: bn-vmt | F16: DEM
B17: R2,R3,R4,R5,R6 | C17: TRP | D17: TRN.RAIL.PASS | E17: bn-pass-miles | F17: DEM
B18: *R2,R3,R4,R5,R6 | C18: TC | D18: TRN.TRUCK.COMMERCIAL | E18: bn-vmt | F18: DEM
B26: *Energy Carriers
B27: R1,R2,R3,R4,R5,R6 | C27: TRNELC | D27: ELC to TRN | E27: PJ | F27: NRG
B28: *R1,R2,R3,R4,R5,R6 | C28: TRNDSL | D28: DSL to rail emissions collector | E28: PJ | F28: NRG
B29: *R1,R2,R3,R4,R5,R6 | C29: TRNLPG1 | D29: LPG to TRN after Collection | E29: PJ | F29: NRG
B30: *R1,R2,R3,R4,R5,R6 | C30: TRNLPG | D30: LPG after collection | E30: PJ | F30: NRG
B31: R1,R2,R3,R4,R5,R6 | C31: TRNJTF1 | D31: JTF to TRN after Collection | E31: PJ | F31: NRG
B32: R1,R2,R3,R4,R5,R6 | C32: TRNJTF | D32: JTF after collection | E32: PJ | F32: NRG
B33: *R1,R2,R3,R4,R5,R6 | C33: TRNRFH | D33: High Sulfur Residual Fuel Oil to Transportation Sector | E33: PJ | F33: NRG
B34: R1,R2,R3,R4,R5,R6 | C34: TRNRFH1 | D34: RFH to TRN after collector | E34: PJ | F34: NRG
B35: R1,R2,R3,R4,R5,R6 | C35: TRNGSL | D35: GSL to TRN | E35: PJ | F35: NRG
B36: R1,R2,R3,R4,R5,R6 | C36: TRNGSLB | D36: GSLB to TRN | E36: PJ | F36: NRG
B37: R1,R2,R3,R4,R5,R6 | C37: TBGSL | D37: GSL to TB | E37: PJ | F37: NRG
B38: R1,R2,R3,R4,R5,R6 | C38: TCGSL | D38: GSL to TC | E38: PJ | F38: NRG
... B65: *R1,R2,R3,R4,R5,R6 | C65: TSB20X | D65: B20X to TS | E65: PJ | F65: NRG
B66: *Emissions Commodities
B67: * | C67: CARBON | D67: Carbon Emissions | E67: Mt | F67: ENV
B68: R2,R3,R4,R5,R6 | C68: SULFUR | D68: Sulfur Emissions | E68: kt | F68: ENV
B69: R2,R3,R4,R5,R6 | C69: SO2T | D69: Sulfur Emissions -Transportation | E69: kt | F69: ENV
B70: R2,R3,R4,R5,R6 | C70: NOXT | D70: NOX Emissions -Transportation | E70: kt | F70: ENV
B71: R2,R3,R4,R5,R6 | C71: PM10T | D71: PM10 Emissions -Transportation | E71: kt | F71: ENV
B72: R2,R3,R4,R5,R6 | C72: VOCT | D72: VOC Emissions - Transportation | E72: kt | F72: ENV
B73: R2,R3,R4,R5,R6 | C73: PM25T | D73: PM25 Emissions - Trasportation | E73: kt | F73: ENV
B74: R2,R3,R4,R5,R6 | C74: CO2 | D74: Carbon dioxide emissions | E74: Mt | F74: ENV
B75: R2,R3,R4,R5,R6 | C75: SO2 | D75: Sulfur emissions | E75: kt | F75: ENV
B76: R2,R3,R4,R5,R6 | C76: NOX | D76: NOX Emissions | E76: kt | F76: ENV
B77: R2,R3,R4,R5,R6 | C77: PM10 | D77: PM10 Emissions | E77: kt | F77: ENV
...

Sheet ANSv6.0-Technologies
A1: ANSWER-Technologies
B7: TechName | C7: TechDesc | D7: TACTUnit | E7: TCAPUnit | F7: Set Memberships | G7: Comment

Sheet ANSv6.0-Constraints
A1: ANSWER-Constraints
B7: ConstrName | C7: ConstrDesc | D7: Units | E7: Set Memberships | F7: Comment

Sheet ANSv6.0-CommData
A1: ANSWER-CommData
B7: CommName | C7: CommDesc | D7: Units

Sheet ANSv6.0-TechData
A1: ANSWER-TechData
B7: TechName | C7: TechDesc | D7: Units | E7: CommIN | F7: CommOUT

Sheet ANSv6.0-ConstrData
A1: ANSWER-ConstrData
B7: ConstrName | C7: ConstrDesc | D7: Units | E7: TechName

Sheet Technologies
B1: Technologies | C1: R1,R2,R3,R4,R5,R6
B6: ~FI_Process
B7: Region | C7: TechName | D7: TechDesc | E7: Tact | F7: Tcap | G7: Sets | H7: PrimaryCG | I7: Vintage
B8: * Existing Technologies
B9: =TechData!A8 -> R2,R3,R4,R5,R6 | C9: =TechData!B8 -> TAJE | D9: =TechData!C8 -> Air Jet, Passenger Existing | E9: bn-pass-miles | F9: bn-pmt/a | G9: DMD
B10: =TechData!A9 -> * | C10: =TechData!B9 -> TAPE | D10: =TechData!C9 -> Airplane, General Aviation, exisiting | E10: bn-pass-miles | F10: bn-pmt/a | G10: DMD
B11: =TechData!A11 -> R2,R3,R4,R5,R6 | C11: =TechData!B11 -> TBDSLE | D11: =TechData!C11 -> Bus, Exisiting Diesel | E11: bn-vmt | F11: bn-vmt/a | G11: DMD
B12: =TechData!A12 -> * | C12: =TechData!B12 -> TBGSLE | D12: =TechData!C12 -> Bus, Exisiting Gasoline | E12: bn-vmt | F12: bn-vmt/a | G12: DMD
B13: =TechData!A13 -> R2,R3,R4,R5,R6 | C13: =TechData!B13 -> TBCNGE | D13: =TechData!C13 -> Bus, Exisiting CNG | E13: bn-vmt | F13: bn-vmt/a | G13: DMD
B14: =TechData!A15 -> * | C14: =TechData!B15 -> TCGSLE | D14: =TechData!C15 -> Truck, Commerical, Exisiting Gasoline | E14: bn-vmt | F14: bn-vmt/a | G14: DMD
B15: =TechData!A16 -> * | C15: =TechData!B16 -> TCDSLE | D15: =TechData!C16 -> Truck, Commerical, Existing Diesel | E15: bn-vmt | F15: bn-vmt/a | G15: DMD
B16: =TechData!A18 -> R2,R3,R4,R5,R6 | C16: =TechData!B18 -> TMGSLE | D16: =TechData!C18 -> Medium Duty Truck, Existing Gasoline | E16: bn-vmt | F16: bn-vmt/a | G16: DMD
B17: =TechData!A19 -> R2,R3,R4,R5,R6 | C17: =TechData!B19 -> TMDSLE | D17: =TechData!C19 -> Medium Duty Truck, Existing Diesel | E17: bn-vmt | F17: bn-vmt/a | G17: DMD
B18: =TechData!A20 -> R2,R3,R4,R5,R6 | C18: =TechData!B20 -> TMCNGE | D18: =TechData!C20 -> Medium Duty Truck, Existing CNG | E18: bn-vmt | F18: bn-vmt/a | G18: DMD
B19: =TechData!A21 -> * | C19: =TechData!B21 -> TMLPGE | D19: =TechData!C21 -> Medium Duty Truck, Existing LPG | E19: bn-vmt | F19: bn-vmt/a | G19: DMD
B20: =TechData!A23 -> R2,R3,R4,R5,R6 | C20: =TechData!B23 -> THSGSLE | D20: =TechData!C23 -> Heavy Truck, Short Haul, Gasoline exisiting | E20: bn-vmt | F20: bn-vmt/a | G20: DMD
B21: =TechData!A24 -> R2,R3,R4,R5,R6 | C21: =TechData!B24 -> THSDSLE | D21: =TechData!C24 -> Heavy Truck, Short Haul, Diesel exisiting | E21: bn-vmt | F21: bn-vmt/a | G21: DMD
B22: =TechData!A25 -> * | C22: =TechData!B25 -> THSDSLE2 | D22: =TechData!C25 -> Heavy Truck, Short Haul, Diesel exisiting MSW | E22: bn-vmt | F22: bn-vmt/a | G22: DMD
B23: =TechData!A26 -> * | C23: =TechData!B26 -> THSCNGE2 | D23: =TechData!C26 -> Heavy Truck, Short Haul, CNG exisiting MSW | E23: bn-vmt | F23: bn-vmt/a | G23: DMD
B24: =TechData!A28 -> R2,R3,R4,R5,R6 | C24: =TechData!B28 -> TPDSLCR | D24: =TechData!C28 -> Commuter Rail, Diesel | E24: bn-pass-miles | F24: bn-pmt/a | G24: DMD
B25: =TechData!A29 -> R2,R3,R4,R5,R6 | C25: =TechData!B29 -> TPELCSUB | D25: =TechData!C29 -> Subways and Streetcars, Electricity | E25: bn-pass-miles | F25: bn-pmt/a | G25: DMD
B26: =TechData!A31 -> * | C26: =TechData!B31 -> TRFDSLE | D26: =TechData!C31 -> Rail Freight, Diesel Existing | E26: bn-t-m | F26: bn-ton-m/a | G26: DMD
B27: =TechData!A32 -> * | C27: =TechData!B32 -> TRFDSLE2 | D27: =TechData!C32 -> Rail Freight, Diesel Existing-MSW | E27: bn-vmt | F27: bn-vmt/a | G27: DMD
B28: =TechData!A33 -> R2,R3,R4,R5,R6 | C28: =TechData!B33 -> TSDSLE | D28: =TechData!C33 -> Water Shipping, Diesel exisiting | E28: bn-t-m | F28: bn-ton-m/a | G28: DMD
B33: =#REF! -> #REF! | C33: =#REF! -> #REF! | E33: PJ | F33: Pja | G33: PRE
B34: =#REF! -> #REF! | C34: =#REF! -> #REF! | E34: PJ | F34: Pja | G34: PRE
B35: =#REF! -> #REF! | C35: =#REF! -> #REF! | E35: PJ | F35: Pja | G35: PRE
B36: =#REF! -> #REF! | C36: =#REF! -> #REF! | E36: PJ | F36: Pja | G36: PRE
B37: =#REF! -> #REF! | C37: =#REF! -> #REF! | E37: PJ | F37: Pja | G37: PRE
B38: =#REF! -> #REF! | C38: =#REF! -> #REF! | E38: PJ | F38: Pja | G38: PRE
B39: =#REF! -> #REF! | C39: =#REF! -> #REF! | E39: PJ | F39: Pja | G39: PRE
B40: =#REF! -> #REF! | C40: =#REF! -> #REF! | E40: PJ | F40: Pja | G40: PRE
B41: =#REF! -> #REF! | C41: =#REF! -> #REF! | E41: PJ | F41: Pja | G41: PRE
B42: =#REF! -> #REF! | C42: =#REF! -> #REF! | E42: PJ | F42: Pja | G42: PRE
B47: R2,R3,R4,R5,R6 | C47: TAJE | D47: ='Air&Marine'!B6 -> Air Jet, Passenger Existing | E47: bn-pass-miles | F47: bn-pmt/a | G47: DMD
B48: *R2,R3,R4,R5,R6 | C48: TAPE | D48: Airplane, General Aviation, exisiting | E48: bn-pass-miles | F48: bn-pmt/a | G48: DMD
B49: R2,R3,R4,R5,R6 | C49: TAJ10 | D49: ='Air&Marine'!B7 -> Air Jet, Passenger 2010 | E49: bn-pass-miles | F49: bn-pmt/a | G49: DMD
B50: R2,R3,R4,R5,R6 | C50: TAJSYN10 | D50: ='Air&Marine'!B8 -> Air Jet, Passenger, Syn fuel, 2010 | E50: bn-pass-miles | F50: bn-pmt/a | G50: DMD
B51: R2,R3,R4,R5,R6 | C51: TAJWT10 | D51: ='Air&Marine'!B9 -> Air Jet, Passenger (Wing tips),2010 | E51: bn-pass-miles | F51: bn-pmt/a | G51: DMD
B52: R2,R3,R4,R5,R6 | C52: TAJAPU15 | D52: ='Air&Marine'!B11 -> Air Jet Passeneger (APU) 2015 | E52: bn-pass-miles | F52: bn-pmt/a | G52: DMD
...

Sheet CommData
A1: CommData | B1: R1,R2,R3,R4,R5,R6
E3: ~FI_T
A4: Region | B4: CommName | C4: *CommDesc | D4: *Units | E4: *COM_PROJ~2005 | F4: COM_PROJ~2010 | G4: COM_PROJ~2015 | H4: COM_PROJ~2020 | I4: COM_PROJ~2025 | J4: COM_PROJ~2030 | K4: COM_PROJ~2035 | L4: COM_PROJ~2040 | M4: COM_PROJ~2045 | N4: COM_PROJ~2050 | O4: COM_PROJ~2055
A5: *Energy Demands by End Use
A6: * | B6: =B16 -> TA | C6: =C16 -> TRN.AIR | D6: =D16 -> bn-pass-miles | E6: =E16+E26+E37+E48+E59+E70 -> 0.01747708 | F6: =F16+F26+F37+F48+F59+F70 -> 0.014855518 | G6: =G16+G26+G37+G48+G59+G70 -> 0.019044073 | H6: =H16+H26+H37+H48+H59+H70 -> 0.019869506 | I6: =I16+I26+I37+I48+I59+I70 -> 0.020959275 | J6: =J16+J26+J37+J48+J59+J70 -> 0.021741127 | K6: =K16+K26+K37+K48+K59+K70 -> 0.022804962 | L6: =L16+L26+L37+L48+L59+L70 -> 0.024131694 | ... O6: =O16+O26+O37+O48+O59+O70 -> 0.02860129
A7: * | B7: =B17 -> TB | C7: =C17 -> TRN.BUS | D7: =D17 -> bn-vmt | E7: =E17+E27+E38+E49+E60+E71 -> 0.44094656 | F7: =F17+F27+F38+F49+F60+F71 -> 0.44094656 | G7: =G17+G27+G38+G49+G60+G71 -> 0.42448077 | H7: =H17+H27+H38+H49+H60+H71 -> 0.4420327 | I7: =I17+I27+I38+I49+I60+I71 -> 0.46037993 | J7: =J17+J27+J38+J49+J60+J71 -> 0.47882279 | K7: =K17+K27+K38+K49+K60+K71 -> 0.4968582 | L7: =L17+L27+L38+L49+L60+L71 -> 0.51425279 | ... O7: =O17+O27+O38+O49+O60+O71 -> 0.59327237
A8: * | B8: TM | C8: TRN.MDV | D8: bn-vmt | E8: =E18+E28+E39+E50+E61+E72 -> 0.49815344 | F8: =F18+F28+F39+F50+F61+F72 -> 0.49815344 | G8: =G18+G28+G39+G50+G61+G72 -> 0.50909164 | H8: =H18+H28+H39+H50+H61+H72 -> 0.50912534 | I8: =I18+I28+I39+I50+I61+I72 -> 0.51716492 | J8: =J18+J28+J39+J50+J61+J72 -> 0.52520449 | K8: =K18+K28+K39+K50+K61+K72 -> 0.53128109 | L8: =L18+L28+L39+L50+L61+L72 -> 0.53735769 | ... O8: =O18+O28+O39+O50+O61+O72 -> 0.57156693
A9: * | B9: =B19 -> THS | C9: =C19 -> TRN.HDV Short Haul | D9: =D19 -> bn-vmt | E9: =E19+E29+E40+E51+E62+E73 -> 0.91154638 | F9: =F19+F29+F40+F51+F62+F73 -> 0.91154638 | G9: =G19+G29+G40+G51+G62+G73 -> 0.94339499 | H9: =H19+H29+H40+H51+H62+H73 -> 0.98428483 | I9: =I19+I29+I40+I51+I62+I73 -> 1.0382692 | J9: =J19+J29+J40+J51+J62+J73 -> 1.0770002 | K9: =K19+K29+K40+K51+K62+K73 -> 1.1296999 | L9: =L19+L29+L40+L51+L62+L73 -> 1.1954228 | ... O9: =O19+O29+O40+O51+O62+O73 -> 1.4168352
A10: * | B10: =B20 -> THL | C10: =C20 -> TRN.HDV Long Haul | D10: =D9 -> bn-vmt | E10: =E20+E30+E41+E52+E63+E74 -> 0 | F10: =F20+F30+F41+F52+F63+F74 -> 0 | G10: =G20+G30+G41+G52+G63+G74 -> 0 | H10: =H20+H30+H41+H52+H63+H74 -> 0 | I10: =I20+I30+I41+I52+I63+I74 -> 0 | J10: =J20+J30+J41+J52+J63+J74 -> 0 | K10: =K20+K30+K41+K52+K63+K74 -> 0 | L10: =L20+L30+L41+L52+L63+L74 -> 0 | ... O10: =O20+O30+O41+O52+O63+O74 -> 0
A11: * | B11: =B21 -> TRF | C11: =C21 -> TRN.RAIL.FREIGHT | D11: =D21 -> bn-t-m | E11: =E21+E31+E42+E53+E64+E75 -> 0 | F11: =F21+F31+F42+F53+F64+F75 -> 0 | G11: =G21+G31+G42+G53+G64+G75 -> 0 | H11: =H21+H31+H42+H53+H64+H75 -> 0 | I11: =I21+I31+I42+I53+I64+I75 -> 0 | J11: =J21+J31+J42+J53+J64+J75 -> 0 | K11: =K21+K31+K42+K53+K64+K75 -> 0 | L11: =L21+L31+L42+L53+L64+L75 -> 0 | ... O11: =O21+O31+O42+O53+O64+O75 -> 0
A12: * | B12: =B22 -> TRP | C12: =C22 -> TRN.RAIL.PASS | D12: =D22 -> bn-pass-miles | E12: =E22+E32+E43+E54+E65+E76 -> 28.027525 | F12: =F22+F32+F43+F54+F65+F76 -> 28.027525 | G12: =G22+G32+G43+G54+G65+G76 -> 29.38391 | H12: =H22+H32+H43+H54+H65+H76 -> 30.881758 | I12: =I22+I32+I43+I54+I65+I76 -> 32.723301 | J12: =J22+J32+J43+J54+J65+J76 -> 34.380043 | K12: =K22+K32+K43+K54+K65+K76 -> 35.920869 | L12: =L22+L32+L43+L54+L65+L76 -> 38.097929 | ... O12: =O22+O32+O43+O54+O65+O76 -> 45.084512
A13: * | B13: =B23 -> TS | C13: =C23 -> TRN.SHIP | D13: =D23 -> bn-t-m | E13: =E23+E33+E44+E55+E66+E77 -> 1.6792504 | F13: =F23+F33+F44+F55+F66+F77 -> 1.6792504 | G13: =G23+G33+G44+G55+G66+G77 -> 1.8745064 | H13: =H23+H33+H44+H55+H66+H77 -> 1.7615035 | I13: =I23+I33+I44+I55+I66+I77 -> 1.6458124 | J13: =J23+J33+J44+J55+J66+J77 -> 1.5707945 | K13: =K23+K33+K44+K55+K66+K77 -> 1.5633757 | L13: =L23+L33+L44+L55+L66+L77 -> 1.5833336 | ... O13: =O23+O33+O44+O55+O66+O77 -> 1.5833336
A14: * | B14: =B24 -> TC | C14: =C24 -> TRN.TRUCK.COMMERCIAL | D14: =D24 -> bn-vmt | E14: =E24+E34+E45+E56+E67+E78 -> 0 | F14: =F24+F34+F45+F56+F67+F78 -> 0 | G14: =G24+G34+G45+G56+G67+G78 -> 0 | H14: =H24+H34+H45+H56+H67+H78 -> 0 | I14: =I24+I34+I45+I56+I67+I78 -> 0 | J14: =J24+J34+J45+J56+J67+J78 -> 0 | K14: =K24+K34+K45+K56+K67+K78 -> 0 | L14: =L24+L34+L45+L56+L67+L78 -> 0 | ... O14: =O24+O34+O45+O56+O67+O78 -> 0
A15: *
A16: *R1 | B16: TA | C16: TRN.AIR | D16: bn-pass-miles | E16: =RegionalDMDNYC!C4 -> 0 | F16: =RegionalDMDNYC!D4 -> 0 | G16: =RegionalDMDNYC!E4 -> 0 | H16: =RegionalDMDNYC!F4 -> 0 | I16: =RegionalDMDNYC!G4 -> 0 | J16: =RegionalDMDNYC!H4 -> 0 | K16: =RegionalDMDNYC!I4 -> 0 | L16: =RegionalDMDNYC!J4 -> 0 | ... O16: =RegionalDMDNYC!M4 -> 0
A17: *R1 | B17: TB | C17: TRN.BUS | D17: bn-vmt | E17: =RegionalDMDNYC!C5 -> 0.081762147 | F17: =RegionalDMDNYC!D5 -> 0.081762147 | G17: =RegionalDMDNYC!E5 -> 0.078708991 | H17: =RegionalDMDNYC!F5 -> 0.081963543 | I17: =RegionalDMDNYC!G5 -> 0.085365562 | J17: =RegionalDMDNYC!H5 -> 0.088785316 | K17: =RegionalDMDNYC!I5 -> 0.092129516 | L17: =RegionalDMDNYC!J5 -> 0.095354894 | ... O17: =RegionalDMDNYC!M5 -> 0.11000703
A18: *R1 | B18: TM | C18: TRN.MDV | D18: bn-vmt | E18: =RegionalDMDNYC!C6 -> 0 | F18: =RegionalDMDNYC!D6 -> 0 | G18: =RegionalDMDNYC!E6 -> 0 | H18: =RegionalDMDNYC!F6 -> 0 | I18: =RegionalDMDNYC!G6 -> 0 | J18: =RegionalDMDNYC!H6 -> 0 | K18: =RegionalDMDNYC!I6 -> 0 | L18: =RegionalDMDNYC!J6 -> 0 | ... O18: =RegionalDMDNYC!M6 -> 0
A19: *R1 | B19: =Commodities!$C$12 -> THS | C19: =Commodities!$D$12 -> TRN.HDV Short Haul | D19: bn-vmt | E19: =RegionalDMDNYC!C7 -> 0.26756986 | F19: =RegionalDMDNYC!D7 -> 0.26756986 | G19: =RegionalDMDNYC!E7 -> 0.287736 | H19: =RegionalDMDNYC!F7 -> 0.30020743 | I19: =RegionalDMDNYC!G7 -> 0.31667271 | J19: =RegionalDMDNYC!H7 -> 0.32848566 | K19: =RegionalDMDNYC!I7 -> 0.34455911 | L19: =RegionalDMDNYC!J7 -> 0.36460463 | ... O19: =RegionalDMDNYC!M7 -> 0.43213555
A20: *R1 | B20: =Commodities!$C$13 -> THL | C20: =Commodities!$D$13 -> TRN.HDV Long Haul | D20: bn-vmt | E20: =RegionalDMDNYC!C8 -> 0 | F20: =RegionalDMDNYC!D8 -> 0 | G20: =RegionalDMDNYC!E8 -> 0 | H20: =RegionalDMDNYC!F8 -> 0 | I20: =RegionalDMDNYC!G8 -> 0 | J20: =RegionalDMDNYC!H8 -> 0 | K20: =RegionalDMDNYC!I8 -> 0 | L20: =RegionalDMDNYC!J8 -> 0 | ... O20: =RegionalDMDNYC!M8 -> 0
A21: *R1 | B21: TRF | C21: TRN.RAIL.FREIGHT | D21: bn-t-m | E21: =RegionalDMDNYC!C9 -> 0 | F21: =RegionalDMDNYC!D9 -> 0 | G21: =RegionalDMDNYC!E9 -> 0 | H21: =RegionalDMDNYC!F9 -> 0 | I21: =RegionalDMDNYC!G9 -> 0 | J21: =RegionalDMDNYC!H9 -> 0 | K21: =RegionalDMDNYC!I9 -> 0 | L21: =RegionalDMDNYC!J9 -> 0 | ... O21: =RegionalDMDNYC!M9 -> 0
A22: *R1 | B22: TRP | C22: TRN.RAIL.PASS | D22: bn-pass-miles | E22: =RegionalDMDNYC!C10 -> 18.739064 | F22: =RegionalDMDNYC!D10 -> 18.739064 | G22: =RegionalDMDNYC!E10 -> 19.650375 | H22: =RegionalDMDNYC!F10 -> 20.64739 | I22: =RegionalDMDNYC!G10 -> 21.878636 | J22: =RegionalDMDNYC!H10 -> 22.986326 | K22: =RegionalDMDNYC!I10 -> 24.016515 | L22: =RegionalDMDNYC!J10 -> 25.472087 | ... O22: =RegionalDMDNYC!M10 -> 30.143281
A23: *R1 | B23: TS | C23: TRN.SHIP | D23: bn-t-m | E23: =RegionalDMDNYC!C11 -> 0 | F23: =RegionalDMDNYC!D11 -> 0 | G23: =RegionalDMDNYC!E11 -> 0 | H23: =RegionalDMDNYC!F11 -> 0 | I23: =RegionalDMDNYC!G11 -> 0 | J23: =RegionalDMDNYC!H11 -> 0 | K23: =RegionalDMDNYC!I11 -> 0 | L23: =RegionalDMDNYC!J11 -> 0 | ... O23: =RegionalDMDNYC!M11 -> 0
A24: *R1 | B24: TC | C24: =Commodities!D18 -> TRN.TRUCK.COMMERCIAL | D24: bn-vmt | E24: =RegionalDMDNYC!C12 -> 0 | F24: =RegionalDMDNYC!D12 -> 0 | G24: =RegionalDMDNYC!E12 -> 0 | H24: =RegionalDMDNYC!F12 -> 0 | I24: =RegionalDMDNYC!G12 -> 0 | J24: =RegionalDMDNYC!H12 -> 0 | K24: =RegionalDMDNYC!I12 -> 0 | L24: =RegionalDMDNYC!J12 -> 0 | ... O24: =RegionalDMDNYC!M12 -> 0
A25: *R2
A26: *R2 | B26: =Commodities!C$9 -> TA | C26: =Commodities!D$9 -> TRN.AIR | D26: bn-pass-miles | E26: =RegionalDMDNYC!C16 -> 0 | F26: =RegionalDMDNYC!D16 -> 0 | G26: =RegionalDMDNYC!E16 -> 0 | H26: =RegionalDMDNYC!F16 -> 0 | I26: =RegionalDMDNYC!G16 -> 0 | J26: =RegionalDMDNYC!H16 -> 0 | K26: =RegionalDMDNYC!I16 -> 0 | L26: =RegionalDMDNYC!J16 -> 0 | ... O26: =RegionalDMDNYC!M16 -> 0
A27: =IF(LEFT(Commodities!B$10,1)="*",A$25,RIGHT(A$25,2)) -> R2 | B27: =Commodities!C$10 -> TB | C27: =Commodities!D$10 -> TRN.BUS | D27: bn-vmt | E27: =RegionalDMDNYC!C17 -> 0.11124684 | F27: =RegionalDMDNYC!D17 -> 0.11124684 | G27: =RegionalDMDNYC!E17 -> 0.10662753 | H27: =RegionalDMDNYC!F17 -> 0.11152253 | I27: =RegionalDMDNYC!G17 -> 0.11662449 | J27: =RegionalDMDNYC!H17 -> 0.12177343 | K27: =RegionalDMDNYC!I17 -> 0.12687698 | L27: =RegionalDMDNYC!J17 -> 0.13184164 | ... O27: =RegionalDMDNYC!M17 -> 0.15156288
A28: R2 | B28: =Commodities!C$11 -> TM | C28: =Commodities!D$11 -> TRN.Medium Duty Trucks | D28: bn-vmt | E28: =RegionalDMDNYC!C18 -> 0.15428842 | F28: =RegionalDMDNYC!D18 -> 0.15428842 | G28: =RegionalDMDNYC!E18 -> 0.15699136 | H28: =RegionalDMDNYC!F18 -> 0.157689 | I28: =RegionalDMDNYC!G18 -> 0.16083143 | J28: =RegionalDMDNYC!H18 -> 0.16397387 | K28: =RegionalDMDNYC!I18 -> 0.16654945 | L28: =RegionalDMDNYC!J18 -> 0.16912503 | ... O28: =RegionalDMDNYC!M18 -> 0.17925624
A29: =IF(LEFT(Commodities!B$12,1)="*",A$25,RIGHT(A$25,2)) -> R2 | B29: =Commodities!C$12 -> THS | C29: =Commodities!$D$12 -> TRN.HDV Short Haul | D29: bn-vmt | E29: =RegionalDMDNYC!C19 -> 0.19945284 | F29: =RegionalDMDNYC!D19 -> 0.19945284 | G29: =RegionalDMDNYC!E19 -> 0.20218913 | H29: =RegionalDMDNYC!F19 -> 0.21187607 | I29: =RegionalDMDNYC!G19 -> 0.22440695 | J29: =RegionalDMDNYC!H19 -> 0.23369339 | K29: =RegionalDMDNYC!I19 -> 0.24613104 | L29: =RegionalDMDNYC!J19 -> 0.26148719 | ... O29: =RegionalDMDNYC!M19 -> 0.30882397
A30: =IF(LEFT(Commodities!B$13,1)="*",A$25,RIGHT(A$25,2)) -> *R2 | B30: =Commodities!C$13 -> THL | C30: =Commodities!$D$13 -> TRN.HDV Long Haul | D30: bn-vmt | E30: =RegionalDMDNYC!C20 -> 0 | F30: =RegionalDMDNYC!D20 -> 0 | G30: =RegionalDMDNYC!E20 -> 0 | H30: =RegionalDMDNYC!F20 -> 0 | I30: =RegionalDMDNYC!G20 -> 0 | J30: =RegionalDMDNYC!H20 -> 0 | K30: =RegionalDMDNYC!I20 -> 0 | L30: =RegionalDMDNYC!J20 -> 0 | ... O30: =RegionalDMDNYC!M20 -> 0
A31: =IF(LEFT(Commodities!B$15,1)="*",A$25,RIGHT(A$25,2)) -> *R2 | B31: =Commodities!C$15 -> TRF | C31: =Commodities!D$15 -> TRN.RAIL.FREIGHT | D31: bn-t-m | E31: =RegionalDMDNYC!C21 -> 0 | F31: =RegionalDMDNYC!D21 -> 0 | G31: =RegionalDMDNYC!E21 -> 0 | H31: =RegionalDMDNYC!F21 -> 0 | I31: =RegionalDMDNYC!G21 -> 0 | J31: =RegionalDMDNYC!H21 -> 0 | K31: =RegionalDMDNYC!I21 -> 0 | L31: =RegionalDMDNYC!J21 -> 0 | ... O31: =RegionalDMDNYC!M21 -> 0
A32: =IF(LEFT(Commodities!B$17,1)="*",A$25,RIGHT(A$25,2)) -> R2 | B32: =Commodities!C$17 -> TRP | C32: =Commodities!D$17 -> TRN.RAIL.PASS | D32: bn-pass-miles | E32: =RegionalDMDNYC!C22 -> 2.8768283 | F32: =RegionalDMDNYC!D22 -> 2.8768283 | G32: =RegionalDMDNYC!E22 -> 3.0036305 | H32: =RegionalDMDNYC!F22 -> 3.1698426 | I32: =RegionalDMDNYC!G22 -> 3.3725467 | J32: =RegionalDMDNYC!H22 -> 3.5572274 | K32: =RegionalDMDNYC!I22 -> 3.7318543 | L32: =RegionalDMDNYC!J22 -> 3.973789 | ... O32: =RegionalDMDNYC!M22 -> 4.685906
A33: =IF(LEFT(Commodities!B$14,1)="*",A$25,RIGHT(A$25,2)) -> R2 | B33: =Commodities!C$14 -> TS | C33: =Commodities!D$14 -> TRN.SHIP | D33: bn-t-m | E33: =RegionalDMDNYC!C23 -> 1.6792504 | F33: =RegionalDMDNYC!D23 -> 1.6792504 | G33: =RegionalDMDNYC!E23 -> 1.8745064 | H33: =RegionalDMDNYC!F23 -> 1.7615035 | I33: =RegionalDMDNYC!G23 -> 1.6458124 | J33: =RegionalDMDNYC!H23 -> 1.5707945 | K33: =RegionalDMDNYC!I23 -> 1.5633757 | L33: =RegionalDMDNYC!J23 -> 1.5833336 | ... O33: =RegionalDMDNYC!M23 -> 1.5833336
A34: =IF(LEFT(Commodities!B$18,1)="*",A$25,RIGHT(A$25,2)) -> *R2 | B34: =Commodities!C$18 -> TC | C34: =Commodities!D$18 -> TRN.TRUCK.COMMERCIAL | D34: bn-vmt | E34: =RegionalDMDNYC!C24 -> 0 | F34: =RegionalDMDNYC!D24 -> 0 | G34: =RegionalDMDNYC!E24 -> 0 | H34: =RegionalDMDNYC!F24 -> 0 | I34: =RegionalDMDNYC!G24 -> 0 | J34: =RegionalDMDNYC!H24 -> 0 | K34: =RegionalDMDNYC!I24 -> 0 | L34: =RegionalDMDNYC!J24 -> 0 | ... O34: =RegionalDMDNYC!M24 -> 0
A35: =IF(LEFT(Commodities!B16,1)="*",A$25,RIGHT(A$25,2)) -> *R2 | B35: =Commodities!C16 -> TSW | C35: =Commodities!D16 -> TRN.MSW | D35: =Commodities!E16 -> bn-vmt
A36: *R3
A37: *R3 | B37: =Commodities!C$9 -> TA | C37: =Commodities!D$9 -> TRN.AIR | D37: bn-pass-miles | E37: =RegionalDMDNYC!C28 -> 0 | F37: =RegionalDMDNYC!D28 -> 0 | G37: =RegionalDMDNYC!E28 -> 0 | H37: =RegionalDMDNYC!F28 -> 0 | I37: =RegionalDMDNYC!G28 -> 0 | J37: =RegionalDMDNYC!H28 -> 0 | K37: =RegionalDMDNYC!I28 -> 0 | L37: =RegionalDMDNYC!J28 -> 0 | ... O37: =RegionalDMDNYC!M28 -> 0
A38: =IF(LEFT(Commodities!B$10,1)="*",A$36,RIGHT(A$36,2)) -> R3 | B38: =Commodities!C$10 -> TB | C38: =Commodities!D$10 -> TRN.BUS | D38: bn-vmt | E38: =RegionalDMDNYC!C29 -> 0.06035811 | F38: =RegionalDMDNYC!D29 -> 0.06035811 | G38: =RegionalDMDNYC!E29 -> 0.058857032 | H38: =RegionalDMDNYC!F29 -> 0.060922173 | I38: =RegionalDMDNYC!G29 -> 0.064023283 | J38: =RegionalDMDNYC!H29 -> 0.067165212 | K38: =RegionalDMDNYC!I29 -> 0.070264245 | L38: =RegionalDMDNYC!J29 -> 0.07329992 | ... O38: =RegionalDMDNYC!M29 -> 0.08534026
A39: R3 | B39: =Commodities!C$11 -> TM | C39: =Commodities!D$11 -> TRN.Medium Duty Trucks | D39: bn-vmt | E39: =RegionalDMDNYC!C30 -> 0.083710759 | F39: =RegionalDMDNYC!D30 -> 0.083710759 | G39: =RegionalDMDNYC!E30 -> 0.086657226 | H39: =RegionalDMDNYC!F30 -> 0.086141847 | I39: =RegionalDMDNYC!G30 -> 0.088291541 | J39: =RegionalDMDNYC!H30 -> 0.090441235 | K39: =RegionalDMDNYC!I30 -> 0.09223479 | L39: =RegionalDMDNYC!J30 -> 0.094028345 | ... O39: =RegionalDMDNYC!M30 -> 0.10093352
A40: =IF(LEFT(Commodities!B$12,1)="*",A$36,RIGHT(A$36,2)) -> R3 | B40: =Commodities!C$12 -> THS | C40: =Commodities!$D$12 -> TRN.HDV Short Haul | D40: bn-vmt | E40: =RegionalDMDNYC!C31 -> 0.10821518 | F40: =RegionalDMDNYC!D31 -> 0.10821518 | G40: =RegionalDMDNYC!E31 -> 0.11160582 | H40: =RegionalDMDNYC!F31 -> 0.11574299 | I40: =RegionalDMDNYC!G31 -> 0.12319256 | J40: =RegionalDMDNYC!H31 -> 0.12889566 | K40: =RegionalDMDNYC!I31 -> 0.13630693 | L40: =RegionalDMDNYC!J31 -> 0.14537888 | ... O40: =RegionalDMDNYC!M31 -> 0.173889
A41: =IF(LEFT(Commodities!B$13,1)="*",A$36,RIGHT(A$36,2)) -> *R3 | B41: =Commodities!C$13 -> THL | C41: =Commodities!$D$13 -> TRN.HDV Long Haul | D41: bn-vmt | E41: =RegionalDMDNYC!C32 -> 0 | F41: =RegionalDMDNYC!D32 -> 0 | G41: =RegionalDMDNYC!E32 -> 0 | H41: =RegionalDMDNYC!F32 -> 0 | I41: =RegionalDMDNYC!G32 -> 0 | J41: =RegionalDMDNYC!H32 -> 0 | K41: =RegionalDMDNYC!I32 -> 0 | L41: =RegionalDMDNYC!J32 -> 0 | ... O41: =RegionalDMDNYC!M32 -> 0
...

Sheet TechData
A1: TechData | B1: R1,R2,R3,R4,R5,R6
F5: ~FI_T
A6: Region | B6: TechName | C6: *TechDesc | D6: *Units | E6: CommIN | F6: CommOUT | G6: Share~UP | H6: NCAP_START | I6: NCAP_TLIFE | J6: NCAP_DRATE | K6: EFF | L6: EFF~2010 | M6: EFF~2015 | N6: EFF~2020 | O6: EFF~2025 | P6: EFF~2030 | Q6: EFF~2035 | R6: EFF~2040 | S6: EFF~2045 | T6: EFF~2050 | U6: EFF~2055 | V6: NCAP_COST~2010 | W6: NCAP_COST~2015 | X6: NCAP_COST~2020 | Y6: NCAP_COST~2025 | Z6: NCAP_COST~2030 | AA6: NCAP_COST~2035 | AB6: NCAP_COST~2040 | AC6: NCAP_COST~2045 | AD6: NCAP_COST~2050 | AE6: NCAP_COST~2055 | AF6: NCAP_FOM | AG6: PRC_RESID~R2~2010 | AH6: PRC_RESID~R3~2010 | AI6: PRC_RESID~R4~2010 | AJ6: PRC_RESID~R5~2010 | AK6: PRC_RESID~R6~2010 | AL6: PRC_RESID~R6~2015 | AM6: NCAP_AFA | AO6: NCAP_BND~2010 | AP6: NCAP_BND~2015 | AQ6: NCAP_BND~2020 | AR6: NCAP_BND~2025 | AS6: NCAP_BND~2030 | AT6: NCAP_BND~2035 | AU6: NCAP_BND~2040 | AV6: NCAP_BND~2045 | AW6: NCAP_BND~2050 | AX6: NCAP_BND~2055 | BA6: NCAP_TLIFE
A7: *Aviation
A8: =Technologies!B47 -> R2,R3,R4,R5,R6 | B8: =Technologies!C47 -> TAJE | C8: =Technologies!D47 -> Air Jet, Passenger Existing | D8: bn-pass-miles, bn-pmt/a | E8: =Commodities!$C$31 -> TRNJTF1 | F8: TA | G8: 1 | H8: 2010 | I8: =BA8+5 -> 17.5 | K8: ='Air&Marine'!J6 -> 0.43762303 | AF8: ='Air&Marine'!I6 -> 7.462576 | AK8: =CommData!F70*1.1 -> 0.01634107 | AL8: =AK8 -> 0.01634107 | AM8: 1 | AQ8: 0 | AR8: 0 | AS8: 0 | AT8: 0 | AU8: 0 | AV8: 0 | AW8: 0 | AX8: 0 | BA8: ='Air&Marine'!G6 -> 12.5
A9: * | B9: =Technologies!C48 -> TAPE | C9: =Technologies!D48 -> Airplane, General Aviation, exisiting | D9: bn-pass-miles, bn-pmt/a | E9: TRGSLB | F9: TA | G9: 1 | H9: 2010 | I9: =BA9+5 -> 25 | AF9: ='Air&Marine'!I17 -> 1.7511 | AM9: 1 | AO9: 0 | AP9: 0 | AQ9: 0 | AR9: 0 | AS9: 0 | AT9: 0 | AU9: 0 | AV9: 0 | AW9: 0 | AX9: 0 | BA9: 20
A10: *BUSES
A11: =Technologies!B57 -> R2,R3,R4,R5,R6 | B11: =Technologies!C57 -> TBDSLE | C11: ='Rail&Bus2'!B7 -> Bus, Exisiting Diesel | D11: bn-vmt, bn-vmt/a | E11: TBDSL | F11: TB | G11: 1 | H11: 2010 | I11: =BA11+5 -> 17 | K11: ='Rail&Bus2'!I7 -> 0.034970963 | AF11: ='Rail&Bus2'!H7 -> 555.05381 | AG11: =TB!B32 -> 0.098160718 | AH11: =TB!B31 -> 0.053258103 | AI11: =TB!B33 -> 0.060977618 | AJ11: =TB!B35 -> 0.018022905 | AK11: =TB!B34 -> 0.086513714 | AM11: 1 | AO11: 0 | AP11: 0 | AQ11: 0 | AR11: 0 | AS11: 0 | AT11: 0 | AU11: 0 | AV11: 0 | AW11: 0 | AX11: 0 | BA11: ='Rail&Bus2'!F7 -> 12
A12: * | B12: =Technologies!C58 -> TBGSLE | C12: ='Rail&Bus2'!B8 -> Bus, Exisiting Gasoline | D12: bn-vmt, bn-vmt/a | E12: TBGSL | F12: TB | G12: 1 | H12: 2010 | I12: =BA12+5 -> 17 | J12: 0.18 | K12: ='Rail&Bus2'!I8 -> 0.03776864 | V12: ='Rail&Bus2'!G8 -> 10426.657 | W12: =V12 -> 10426.657 | X12: =W12 -> 10426.657 | Y12: =X12 -> 10426.657 | Z12: =Y12 -> 10426.657 | AA12: =Z12 -> 10426.657 | AB12: =AA12 -> 10426.657 | AC12: =AB12 -> 10426.657 | AD12: =AC12 -> 10426.657 | AE12: =AD12 -> 10426.657 | AF12: ='Rail&Bus2'!H8 -> 555.05381 | AM12: 1 | BA12: ='Rail&Bus2'!F8 -> 12
A13: =Technologies!B59 -> R2,R3,R4,R5,R6 | B13: =Technologies!C59 -> TBCNGE | C13: Bus, Exisiting CNG | D13: bn-vmt, bn-vmt/a | E13: TBCNG | F13: TB | G13: 1 | H13: 2010 | I13: =BA13+5 -> 17 | K13: ='Rail&Bus2'!I9 -> 0.029733766 | AF13: ='Rail&Bus2'!H9 -> 639.72304 | AG13: =TB!D32 -> 0.013086117 | AH13: =TB!D31 -> 0.007100007 | AI13: =TB!D33 -> 0.0081291202 | AJ13: =TB!D35 -> 0.0024026908 | AK13: =TB!D34 -> 0.011533418 | AM13: 1 | AP13: 0 | AQ13: 0 | AR13: 0 | AS13: 0 | AT13: 0 | AU13: 0 | AV13: 0 | AW13: 0 | AX13: 0 | BA13: 12
A14: *Commercial Trucks | AO14: 0
A15: * | B15: =Technologies!C79 -> TCGSLE | C15: =Technologies!D79 -> Truck, Commerical, Exisiting Gasoline | D15: bn-vmt, bn-vmt/a | E15: TCGSL | F15: =Commodities!C$18 -> TC | G15: 1 | H15: 2010 | I15: =BA15+5 -> 20.5 | K15: =Trucks!H66 -> 0.0971537 | AF15: =Trucks!G66 -> 55.312878 | AM15: 1 | AO15: 0 | AP15: 0 | AQ15: 0 | AR15: 0 | AS15: 0 | AT15: 0 | AU15: 0 | AV15: 0 | AW15: 0 | AX15: 0 | BA15: =Trucks!E66 -> 15.5
A16: * | B16: =Technologies!C80 -> TCDSLE | C16: =Technologies!D80 -> Truck, Commerical, Existing Diesel | D16: bn-vmt, bn-vmt/a | E16: TCDSL | F16: =Commodities!C$18 -> TC | G16: 1 | H16: 2010 | I16: =BA16+5 -> 20.5 | K16: =Trucks!H67 -> 0.11740134 | AF16: =Trucks!G67 -> 55.312878 | AM16: 1 | AO16: 0 | AP16: 0 | AQ16: 0 | AR16: 0 | AS16: 0 | AT16: 0 | AU16: 0 | AV16: 0 | AW16: 0 | AX16: 0 | BA16: =Trucks!E67 -> 15.5
A17: *Medium Duty Trucks
A18: =Technologies!B110 -> R2,R3,R4,R5,R6 | B18: =Technologies!C110 -> TMGSLE | C18: =Technologies!D110 -> Medium Duty Truck, Existing Gasoline | D18: bn-vmt, bn-vmt/a | E18: =Commodities!C39 -> TMGSL | F18: =Commodities!C$11 -> TM | G18: 1 | H18: 2010 | I18: =BA18+5 -> 24 | K18: =Trucks!H119*TM!$L$7 -> 0.081247596 | AF18: =Trucks!G119 -> 248.8047 | AG18: =TM!B48 -> 0.11532313 | AH18: =TM!B47 -> 0.062569744 | AI18: =TM!B49 -> 0.071638939 | AJ18: =TM!B51 -> 0.021174028 | AK18: =TM!B50 -> 0.10163976 | AM18: 1 | AO18: 0 | AP18: 0 | AQ18: 0 | AR18: 0 | AS18: 0 | AT18: 0 | AU18: 0 | AV18: 0 | AW18: 0 | AX18: 0 | BA18: =Trucks!E119 -> 19
A19: =Technologies!B111 -> R2,R3,R4,R5,R6 | B19: =Technologies!C111 -> TMDSLE | C19: =Technologies!D111 -> Medium Duty Truck, Existing Diesel | D19: bn-vmt, bn-vmt/a | E19: =Commodities!C42 -> TMDSL | F19: =Commodities!C$11 -> TM | G19: 1 | H19: 2010 | I19: =BA19+5 -> 24 | K19: =Trucks!H120*TM!$L$7 -> 0.083040936 | AF19: =Trucks!G120 -> 136.84259 | AG19: =TM!B41 -> 0.05411575 | AH19: =TM!B40 -> 0.029361054 | AI19: =TM!B42 -> 0.033616803 | AJ19: =TM!B44 -> 0.009935981 | AK19: =TM!B43 -> 0.047694786 | AM19: 1 | AO19: 0 | AP19: 0 | AQ19: 0 | AR19: 0 | AS19: 0 | AT19: 0 | AU19: 0 | AV19: 0 | AW19: 0 | AX19: 0 | BA19: =Trucks!E120 -> 19
A20: =Technologies!B112 -> R2,R3,R4,R5,R6 | B20: =Technologies!C112 -> TMCNGE | C20: =Technologies!D112 -> Medium Duty Truck, Existing CNG | D20: bn-vmt, bn-vmt/a | E20: =Commodities!C57 -> TMCNG | F20: =Commodities!C$11 -> TM | G20: 1 | H20: 2010 | I20: =BA20+5 -> 24 | K20: =Trucks!H122*TM!$L$7 -> 0.066470533 | AF20: =Trucks!G122 -> 248.8047 | AG20: =TM!B34 -> 0.00027837838 | AH20: =TM!B33 -> 0.00015103704 | AI20: =TM!B35 -> 0.00017292916 | AJ20: =TM!B37 -> 5.1111965e-05 | AK20: =TM!B36 -> 0.00024534812 | AM20: 1 | AO20: 0 | AP20: 0 | AQ20: 0 | AR20: 0 | AS20: 0 | AT20: 0 | AU20: 0 | AV20: 0 | AW20: 0 | AX20: 0 | BA20: =Trucks!E122 -> 19
A21: * | B21: =Technologies!C113 -> TMLPGE | C21: =Technologies!D113 -> Medium Duty Truck, Existing LPG | D21: bn-vmt, bn-vmt/a | E21: =Commodities!C29 -> TRNLPG1 | F21: =Commodities!C$11 -> TM | G21: 1 | H21: 2010 | I21: =BA21+5 -> 24 | K21: =Trucks!H121 -> 0.053551661 | AF21: =Trucks!G121 -> 248.8047 | AM21: 1 | AO21: 0 | AP21: 0 | AQ21: 0 | AR21: 0 | AS21: 0 | AT21: 0 | AU21: 0 | AV21: 0 | AW21: 0 | AX21: 0 | BA21: =Trucks!E121 -> 19
A22: *Heavy Duty Trucks
A23: =Technologies!B136 -> R2,R3,R4,R5,R6 | B23: =Technologies!C136 -> THSGSLE | C23: =Technologies!D136 -> Heavy Truck, Short Haul, Gasoline exisiting | D23: bn-vmt, bn-vmt/a | E23: =Commodities!C47 -> THGSL | F23: =Commodities!C$12 -> THS | G23: 1 | H23: 2010 | I23: =BA23+5 -> 24 | K23: =Trucks!H162 -> 0.029418718 | AF23: =Trucks!G162 -> 301.42015 | AG23: 0 | AH23: 0 | AI23: 0 | AJ23: 0 | AK23: 0 | AM23: 1 | AO23: 0 | AP23: 0 | AQ23: 0 | AR23: 0 | AS23: 0 | AT23: 0 | AU23: 0 | AV23: 0 | AW23: 0 | AX23: 0 | BA23: =Trucks!E162 -> 19
A24: =Technologies!B137 -> R2,R3,R4,R5,R6 | B24: =Technologies!C137 -> THSDSLE | C24: =Technologies!D137 -> Heavy Truck, Short Haul, Diesel exisiting | D24: bn-vmt, bn-vmt/a | E24: =Commodities!$C$44 -> THDSL | F24: =Commodities!C$12 -> THS | G24: 1 | H24: 2010 | I24: =BA24+5 -> 24 | K24: =THS!G5 -> 0.030387433 | AF24: =Trucks!G163 -> 165.78108 | AG24: =THS!B23 -> 0.19945284 | AH24: =THS!B22 -> 0.10821518 | AI24: =THS!B24 -> 0.12390047 | AJ24: =THS!B26 -> 0.036620755 | AK24: =THS!B25 -> 0.17578728 | AM24: 1 | AP24: 0 | AQ24: 0 | AR24: 0 | AS24: 0 | AT24: 0 | AU24: 0 | AV24: 0 | AW24: 0 | AX24: 0 | BA24: =Trucks!E163 -> 19
A25: * | B25: =Technologies!C138 -> THSDSLE2 | C25: =Technologies!D138 -> Heavy Truck, Short Haul, Diesel exisiting MSW | D25: bn-vmt, bn-vmt/a | E25: =Commodities!$C$46 -> TWDSL | F25: =Commodities!$C$16 -> TSW | G25: 1 | H25: 2010 | I25: 24 | K25: 0.039439301 | AF25: 165.78108 | AG25: =TSW!C62 -> 0.013386394 | AH25: =TSW!C61 -> 0.0070042362 | AI25: =TSW!C63 -> 0.0086552157 | AJ25: =TSW!C65 -> 0.0022050745 | AK25: =TSW!C64 -> 0.011355357 | AM25: 1 | BA25: 19
A26: * | B26: =Technologies!C140 -> THSCNGE2 | C26: =Technologies!D140 -> Heavy Truck, Short Haul, CNG exisiting MSW | D26: bn-vmt, bn-vmt/a | E26: =Commodities!$C$46 -> TWDSL | F26: =Commodities!$C$16 -> TSW | G26: 1 | H26: 2010 | I26: 24 | K26: 0.039547347 | AF26: 248.8047 | AM26: 1 | AO26: 0 | AP26: 0 | AQ26: 0 | AR26: 0 | AS26: 0 | AT26: 0 | AU26: 0 | AV26: 0 | AW26: 0 | AX26: 0 | BA26: 19
A27: *Passenger Rail
A28: =Technologies!B191 -> R2,R3,R4,R5,R6 | B28: =Technologies!C191 -> TPDSLCR | C28: =Technologies!D191 -> Commuter Rail, Diesel | D28: bn-pass-miles, bn-pmt/a | E28: TRNDSL | F28: TRP | G28: 1 | H28: 2010 | I28: 20 | L28: ='Rail&Bus2'!H61 -> 0.63495882 | M28: =L28 -> 0.63495882 | N28: =L28 -> 0.63495882 | O28: =N28 -> 0.63495882 | P28: =O28 -> 0.63495882 | Q28: =P28 -> 0.63495882 | R28: =Q28 -> 0.63495882 | S28: =R28 -> 0.63495882 | T28: =S28 -> 0.63495882 | U28: =T28 -> 0.63495882 | V28: ='Rail&Bus2'!F61 -> 1284.7941 | W28: =V28 -> 1284.7941 | X28: =W28 -> 1284.7941 | Y28: =X28 -> 1284.7941 | Z28: =Y28 -> 1284.7941 | AA28: =Z28 -> 1284.7941 | AB28: =AA28 -> 1284.7941 | AC28: =AB28 -> 1284.7941 | AD28: =AC28 -> 1284.7941 | AE28: =AD28 -> 1284.7941 | AF28: ='Rail&Bus2'!G61 -> 128.47941 | AG28: =TRP!C31 -> 0.038496366 | AH28: =TRP!C30 -> 0.020886597 | AI28: =TRP!C32 -> 0.023914013 | AJ28: =TRP!C34 -> 0.0070681671 | AK28: =TRP!C33 -> 0.03392868 | AM28: 1 | AO28: 0 | BA28: 20
A29: =Technologies!B193 -> R2,R3,R4,R5,R6 | B29: =Technologies!C193 -> TPELCSUB | C29: =Technologies!D193 -> Subways and Streetcars, Electricity | D29: bn-pass-miles, bn-pmt/a | E29: TRNELC | F29: TRP | G29: 1 | H29: 2010 | I29: 20 | L29: ='Rail&Bus2'!H59 -> 1.1472366 | M29: =L29 -> 1.1472366 | N29: =M29 -> 1.1472366 | O29: =N29 -> 1.1472366 | P29: =O29 -> 1.1472366 | Q29: =P29 -> 1.1472366 | R29: =Q29 -> 1.1472366 | S29: =R29 -> 1.1472366 | T29: =S29 -> 1.1472366 | U29: =T29 -> 1.1472366 | V29: ='Rail&Bus2'!F59 -> 216.106 | W29: =V29 -> 216.106 | X29: =W29 -> 216.106 | Y29: =X29 -> 216.106 | Z29: =Y29 -> 216.106 | AA29: =Z29 -> 216.106 | AB29: =AA29 -> 216.106 | AC29: =AB29 -> 216.106 | AD29: =AC29 -> 216.106 | AE29: =AD29 -> 216.106 | AF29: ='Rail&Bus2'!G59 -> 10.805 | AG29: =TRP!C39 -> 2.8383319 | AH29: =TRP!C38 -> 1.539966 | AI29: =TRP!C40 -> 1.763177 | AJ29: =TRP!C42 -> 0.52113501 | AK29: =TRP!C41 -> 2.501557 | AM29: 1 | AO29: 0 | BA29: 20
A30: *Freight Rail
A31: * | B31: =Technologies!C195 -> TRFDSLE | C31: =Technologies!D195 -> Rail Freight, Diesel Existing | D31: bn-t-m, bn-ton-m/a | E31: TRNDSL | F31: TRF | G31: 1 | H31: 2010 | I31: 30 | K31: =Freight!H5 -> 2.7635669 | AF31: =Freight!G5 -> 1.4305792 | AM31: 1 | BA31: =Freight!E5 -> 30
A32: * | B32: =Technologies!C196 -> TRFDSLE2 | C32: =Technologies!D196 -> Rail Freight, Diesel Existing-MSW | D32: bn-vmt, bn-vmt/a | E32: =Commodities!$C$46 -> TWDSL | F32: =Commodities!$C$16 -> TSW | G32: =G31 -> 1 | H32: =H31 -> 2010 | I32: =I31 -> 30 | K32: =K31 -> 2.7635669 | AF32: =AF31 -> 1.4305792 | AG32: =TSW!C47 -> 0.19037656 | AH32: =TSW!C46 -> 0.099611766 | AI32: =TSW!C48 -> 0.12309141 | AJ32: =TSW!C50 -> 0.031359788 | AK32: =TSW!C49 -> 0.16149186 | AM32: 1 | BA32: =BA31 -> 30
A33: =Technologies!B210 -> R2,R3,R4,R5,R6 | B33: =Technologies!C210 -> TSDSLE | C33: =Technologies!D210 -> Water Shipping, Diesel exisiting | D33: bn-t-m, bn-ton-m/a | E33: =Commodities!C43 -> TSDSL | F33: TS | G33: 1 | H33: 2010 | I33: 30 | J33: 0.18 | K33: ='Air&Marine'!J32 -> 1.9172147 | V33: ='Air&Marine'!H32 -> 20.108903 | W33: =V33 -> 20.108903 | X33: =W33 -> 20.108903 | Y33: =X33 -> 20.108903 | Z33: =Y33 -> 20.108903 | AA33: =Z33 -> 20.108903 | AB33: =AA33 -> 20.108903 | AC33: =AB33 -> 20.108903 | AD33: =AC33 -> 20.108903 | AE33: =AD33 -> 20.108903 | AF33: ='Air&Marine'!I32 -> 1.0054451 | AG33: =CommData!E13 -> 1.6792504 | AM33: 1 | AP33: 0 | AQ33: 0 | AR33: 0 | AS33: 0 | AT33: 0 | AU33: 0 | AV33: 0 | AW33: 0 | AX33: 0 | BA33: ='Air&Marine'!G32 -> 30
F38: ~FI_T
A39: Region | B39: TechName | C39: TechDesc | D39: Units | E39: CommIN | F39: CommOUT | G39: NCAP_START | H39: NCAP_TLIFE | I39: NCAP_DRATE | J39: EFF | N39: NCAP_TLIFE
A40: *Emissions Collectors
A41: * | B41: =Technologies!C216 -> SETRB20 | C41: =Technologies!D216 -> Emissions: B20 Rail fuel to TRB20X | D41: PJ, PJ/a | E41: TRB20 | F41: =Commodities!C$64 -> TRB20X | G41: 2010 | H41: 50 | J41: 1 | N41: 50
A42: =Technologies!B215 -> R2,R3,R4,R5,R6 | B42: =Technologies!C215 -> SETRDSL | C42: =Technologies!D215 -> Emissions: DSL Rail fuel to TRDSL | D42: PJ, PJ/a | E42: TRNDSL | F42: TRDSL | G42: 2010 | H42: 50 | J42: 1 | N42: 50
F45: FI_T
A46: Region | B46: TechName | C46: TechDesc | D46: Units | E46: CommIN | F46: CommOUT | G46: EFF | H46: NCAP_FOM
A47: * ZZ (DMD) Backstop Technologies
A48: =Technologies!B218 -> R2,R3,R4,R5,R6 | B48: =Technologies!C218 -> ZZTB | C48: =Technologies!D218 -> Transportation Buses - ZZINFES backstop | D48: bn-vmt, bn-vmt/a | E48: ZZDMY | F48: TB | G48: 1 | H48: 9999
A49: =Technologies!B219 -> *R2,R3,R4,R5,R6 | B49: =Technologies!C219 -> ZZTC | C49: =Technologies!D219 -> Transportation Commercial Trucks - ZZINFES backstop | D49: bn-vmt, bn-vmt/a | E49: ZZDMY | F49: TC | G49: 1 | H49: 9999
...

Sheet NewTech
A1: TechData | B1: R1,R2,R3,R4,R5,R6
A6: Region | B6: TechName | C6: *TechDesc | D6: *Units | E6: CommIN | F6: CommOUT | G6: Share~UP | H6: NCAP_START | I6: NCAP_TLIFE | J6: NCAP_DRATE | K6: EFF | L6: EFF~2010 | M6: EFF~2015 | N6: EFF~2020 | O6: EFF~2025 | P6: EFF~2030 | Q6: EFF~2035 | R6: EFF~2040 | S6: EFF~2045 | T6: EFF~2050 | U6: EFF~2055 | V6: NCAP_COST~2010 | W6: NCAP_COST~2015 | X6: NCAP_COST~2020 | Y6: NCAP_COST~2025 | Z6: NCAP_COST~2030 | AA6: NCAP_COST~2035 | AB6: NCAP_COST~2040 | AC6: NCAP_COST~2045 | AD6: NCAP_COST~2050 | AE6: NCAP_COST~2055 | AF6: NCAP_FOM | AG6: PRC_RESID~R2~2010 | AH6: PRC_RESID~R3~2010 | AI6: PRC_RESID~R4~2010 | AJ6: PRC_RESID~R5~2010 | AK6: PRC_RESID~R6~2010 | AL6: NACP_AFA | AM6: NCAP_BND~2010 | AN6: NCAP_BND~2015 | AO6: NCAP_BND~2020 | AP6: NCAP_BND~2025 | AQ6: NCAP_BND~2030 | AR6: NCAP_BND~2035 | AS6: NCAP_BND~2040 | AT6: NCAP_BND~2045 | AU6: NCAP_BND~2050 | AV6: NCAP_BND~2055 | AZ6: NCAP_TLIFE
A7: *Aviation
A8: =Technologies!B49 -> R2,R3,R4,R5,R6 | B8: =Technologies!C49 -> TAJ10 | C8: =Technologies!D49 -> Air Jet, Passenger 2010 | D8: bn-pass-miles, bn-pmt/a | E8: =Commodities!C31 -> TRNJTF1 | F8: TA | G8: 1 | H8: ='Air&Marine'!F7 -> 2010 | I8: =AZ8+5 -> 30 | J8: 0.18 | K8: ='Air&Marine'!J7 -> 0.45147637 | V8: ='Air&Marine'!H7 -> 814.53239 | W8: =V8 -> 814.53239 | X8: =W8 -> 814.53239 | Y8: =X8 -> 814.53239 | Z8: =Y8 -> 814.53239 | AA8: =Z8 -> 814.53239 | AB8: =AA8 -> 814.53239 | AC8: =AB8 -> 814.53239 | AD8: =AC8 -> 814.53239 | AE8: =AD8 -> 814.53239 | AF8: ='Air&Marine'!I7 -> 7.462576 | AL8: 1 | AM8: 0 | AN8: 0 | AZ8: ='Air&Marine'!G7 -> 25
A9: =Technologies!B50 -> R2,R3,R4,R5,R6 | B9: =Technologies!C50 -> TAJSYN10 | C9: =Technologies!D50 -> Air Jet, Passenger, Syn fuel, 2010 | D9: bn-pass-miles, bn-pmt/a | E9: =Commodities!C31 -> TRNJTF1 | F9: TA | G9: 1 | H9: ='Air&Marine'!F8 -> 2010 | I9: =AZ9+5 -> 30 | K9: ='Air&Marine'!J8 -> 0.42712996 | V9: ='Air&Marine'!H8 -> 814.53239 | W9: =V9 -> 814.53239 | X9: =W9 -> 814.53239 | Y9: =X9 -> 814.53239 | Z9: =Y9 -> 814.53239 | AA9: =Z9 -> 814.53239 | AB9: =AA9 -> 814.53239 | AC9: =AB9 -> 814.53239 | AD9: =AC9 -> 814.53239 | AE9: =AD9 -> 814.53239 | AF9: ='Air&Marine'!I8 -> 7.462576 | AL9: 1 | AM9: 0 | AN9: 0 | AZ9: ='Air&Marine'!G8 -> 25
A10: =Technologies!B51 -> R2,R3,R4,R5,R6 | B10: =Technologies!C51 -> TAJWT10 | C10: =Technologies!D51 -> Air Jet, Passenger (Wing tips),2010 | D10: bn-pass-miles, bn-pmt/a | E10: =Commodities!C$31 -> TRNJTF1 | F10: TA | G10: 1 | H10: ='Air&Marine'!F9 -> 2010 | I10: =AZ10+5 -> 30 | J10: 0.2 | K10: ='Air&Marine'!J9 -> 0.47275012 | V10: ='Air&Marine'!H9 -> 820.68444 | W10: =V10 -> 820.68444 | X10: =W10 -> 820.68444 | Y10: =X10 -> 820.68444 | Z10: =Y10 -> 820.68444 | AA10: =Z10 -> 820.68444 | AB10: =AA10 -> 820.68444 | AC10: =AB10 -> 820.68444 | AD10: =AC10 -> 820.68444 | AE10: =AD10 -> 820.68444 | AF10: ='Air&Marine'!I9 -> 7.462576 | AL10: 1 | AM10: 0 | AN10: 0 | AZ10: ='Air&Marine'!G9 -> 25
A11: =Technologies!B52 -> R2,R3,R4,R5,R6 | B11: =Technologies!C52 -> TAJAPU15 | C11: =Technologies!D52 -> Air Jet Passeneger (APU) 2015 | D11: bn-pass-miles, bn-pmt/a | E11: =Commodities!C$31 -> TRNJTF1 | F11: TA | G11: 1 | H11: ='Air&Marine'!F11 -> 2015 | I11: =AZ11+5 -> 30 | J11: 0.2 | K11: ='Air&Marine'!J11 -> 0.45358554 | V11: ='Air&Marine'!H11 -> 815.46191 | W11: =V11 -> 815.46191 | X11: =W11 -> 815.46191 | Y11: =X11 -> 815.46191 | Z11: =Y11 -> 815.46191 | AA11: =Z11 -> 815.46191 | AB11: =AA11 -> 815.46191 | AC11: =AB11 -> 815.46191 | AD11: =AC11 -> 815.46191 | AE11: =AD11 -> 815.46191 | AF11: ='Air&Marine'!I11 -> 7.5083155 | AL11: 1 | AM11: 0 | AN11: 0 | AZ11: ='Air&Marine'!G10 -> 25
A12: =Technologies!B53 -> R2,R3,R4,R5,R6 | B12: =Technologies!C53 -> TAJBW30 | C12: =Technologies!D53 -> Air Jet, Passenger(blended wing), 2030 | D12: bn-pass-miles, bn-pmt/a | E12: =Commodities!C$31 -> TRNJTF1 | F12: TA | G12: 1 | H12: ='Air&Marine'!F12 -> 2030 | I12: =AZ12+5 -> 30 | J12: 0.24 | K12: ='Air&Marine'!J12 -> 0.64496624 | V12: ='Air&Marine'!H12 -> 1127.6931 | W12: =V12 -> 1127.6931 | X12: =W12 -> 1127.6931 | Y12: =X12 -> 1127.6931 | Z12: =Y12 -> 1127.6931 | AA12: =Z12 -> 1127.6931 | AB12: =AA12 -> 1127.6931 | AC12: =AB12 -> 1127.6931 | AD12: =AC12 -> 1127.6931 | AE12: =AD12 -> 1127.6931 | AF12: ='Air&Marine'!I12 -> 7.462576 | AL12: 1 | AM12: 0 | AN12: 0 | AZ12: ='Air&Marine'!G12 -> 25
A13: =Technologies!B54 -> R2,R3,R4,R5,R6 | B13: =Technologies!C54 -> TAJAE30 | C13: =Technologies!D54 -> Air Jet, Passenger (improved aero), 2030 | D13: bn-pass-miles, bn-pmt/a | E13: =Commodities!C$31 -> TRNJTF1 | F13: TA | G13: 1 | H13: ='Air&Marine'!F13 -> 2030 | I13: =AZ13+5 -> 30 | J13: 0.24 | K13: ='Air&Marine'!J13 -> 0.50164041 | V13: ='Air&Marine'!H13 -> 895.98562 | W13: =V13 -> 895.98562 | X13: =W13 -> 895.98562 | Y13: =X13 -> 895.98562 | Z13: =Y13 -> 895.98562 | AA13: =Z13 -> 895.98562 | AB13: =AA13 -> 895.98562 | AC13: =AB13 -> 895.98562 | AD13: =AC13 -> 895.98562 | AE13: =AD13 -> 895.98562 | AF13: ='Air&Marine'!I13 -> 7.462576 | AL13: 1 | AM13: 0 | AN13: 0 | AZ13: ='Air&Marine'!G13 -> 25
A14: =Technologies!B55 -> R2,R3,R4,R5,R6 | B14: =Technologies!C55 -> TAJGE15 | C14: =Technologies!D55 -> Air Jet Passenger, (geared engine), 2015 | D14: bn-pass-miles, bn-pmt/a | E14: =Commodities!C$31 -> TRNJTF1 | F14: TA | G14: 1 | H14: ='Air&Marine'!F15 -> 2015 | I14: =AZ14+5 -> 30 | J14: 0.2 | K14: ='Air&Marine'!J15 -> 0.51597299 | V14: ='Air&Marine'!H15 -> 929.6172 | W14: =V14 -> 929.6172 | X14: =W14 -> 929.6172 | Y14: =X14 -> 929.6172 | Z14: =Y14 -> 929.6172 | AA14: =Z14 -> 929.6172 | AB14: =AA14 -> 929.6172 | AC14: =AB14 -> 929.6172 | AD14: =AC14 -> 929.6172 | AE14: =AD14 -> 929.6172 | AF14: ='Air&Marine'!I15 -> 8.5169591 | AL14: 1 | AM14: 0 | AN14: 0 | AZ14: ='Air&Marine'!G15 -> 25
A15: * | B15: =Technologies!C56 -> TAP10 | C15: =Technologies!D56 -> Airplane, General Aviation - 2010 | D15: bn-pass-miles, bn-pmt/a | E15: TRGSLB | F15: TA | G15: 1 | H15: 2010 | I15: =AZ15+5 -> 25 | J15: 0.18 | V15: ='Air&Marine'!H18 -> 17.511 | W15: =V15 -> 17.511 | X15: =W15 -> 17.511 | Y15: =X15 -> 17.511 | Z15: =Y15 -> 17.511 | AA15: =Z15 -> 17.511 | AB15: =AA15 -> 17.511 | AC15: =AB15 -> 17.511 | AD15: =AC15 -> 17.511 | AE15: =AD15 -> 17.511 | AF15: ='Air&Marine'!I18 -> 1.7511 | AL15: 1 | AZ15: 20
A16: *BUSES
A17: =Technologies!B60 -> R2,R3,R4,R5,R6 | B17: =Technologies!C60 -> TBDSLC10 | C17: =Technologies!D60 -> Bus, Conventional Diesel, 2010 | D17: bn-vmt, bn-vmt/a | E17: =Commodities!C$41 -> TBDSL | F17: TB | G17: 1 | H17: 2010 | I17: =AZ17+5 -> 17 | J17: 0.18 | K17: ='Rail&Bus2'!$L7 -> 0.031791784 | V17: ='Rail&Bus2'!T7 -> 10426.657 | AF17: ='Rail&Bus2'!H11 -> 555.05381 | AL17: 1 | AM17: 0 | AN17: 0 | AO17: 0 | AP17: 0 | AQ17: 0 | AR17: 0 | AS17: 0 | AT17: 0 | AU17: 0 | AV17: 0 | AZ17: 12
A18: =Technologies!B61 -> R2,R3,R4,R5,R6 | B18: =Technologies!C61 -> TBDSLC | C18: ='Rail&Bus2'!B11 -> Bus, Conventional Diesel | D18: bn-vmt, bn-vmt/a | E18: =Commodities!C$41 -> TBDSL | F18: TB | G18: 1 | H18: 2015 | I18: =AZ18+5 -> 17 | J18: 0.18 | M18: ='Rail&Bus2'!$I11 -> 0.033488882 | N18: ='Rail&Bus2'!$I12 -> 0.034986321 | O18: =N18 -> 0.034986321 | P18: =O18 -> 0.034986321 | Q18: =P18 -> 0.034986321 | R18: =Q18 -> 0.034986321 | S18: =R18 -> 0.034986321 | T18: =S18 -> 0.034986321 | U18: =T18 -> 0.034986321 | W18: ='Rail&Bus2'!G11 -> 10488.439 | X18: ='Rail&Bus2'!G12 -> 10598.81 | Y18: =X18 -> 10598.81 | Z18: =Y18 -> 10598.81 | AA18: =Z18 -> 10598.81 | AB18: =AA18 -> 10598.81 | AC18: =AB18 -> 10598.81 | AD18: =AC18 -> 10598.81 | AE18: =AD18 -> 10598.81 | AF18: ='Rail&Bus2'!H11 -> 555.05381 | AL18: 1 | AM18: 0 | AZ18: ='Rail&Bus2'!F11 -> 12
A19: =Technologies!B62 -> R2,R3,R4,R5,R6 | B19: =Technologies!C62 -> TBDSLIM | C19: =Technologies!D62 -> Bus, Improved Diesel | D19: bn-vmt, bn-vmt/a | E19: =Commodities!C$41 -> TBDSL | F19: TB | G19: 1 | H19: 2025 | I19: =AZ19+5 -> 17 | J19: 0.24 | K19: ='Rail&Bus2'!I13 -> 0.03909468 | W19: =X19 -> 10598.81 | X19: =Y19 -> 10598.81 | Y19: ='Rail&Bus2'!V7 -> 10598.81 | Z19: =Y19 -> 10598.81 | AA19: =Z19 -> 10598.81 | AB19: =AA19 -> 10598.81 | AC19: =AB19 -> 10598.81 | AD19: =AC19 -> 10598.81 | AE19: =AD19 -> 10598.81 | AF19: ='Rail&Bus2'!H12 -> 555.05381 | AL19: 1 | AM19: 0 | AZ19: 12
A20: =Technologies!B63 -> R2,R3,R4,R5,R6 | B20: =Technologies!C63 -> TBDSLADV | C20: ='Rail&Bus2'!B14 -> Bus, Advanced Tech Diesel | D20: bn-vmt, bn-vmt/a | E20: =Commodities!C$41 -> TBDSL | F20: TB | G20: 1 | H20: ='Rail&Bus2'!E14 -> 2015 | I20: =AZ20+5 -> 17 | J20: 0.28 | M20: ='Rail&Bus2'!I14 -> 0.037727787 | N20: =M20 -> 0.037727787 | O20: ='Rail&Bus2'!$I15 -> 0.03909468 | P20: =O20 -> 0.03909468 | Q20: =P20 -> 0.03909468 | R20: ='Rail&Bus2'!I16 -> 0.039355772 | S20: =R20 -> 0.039355772 | T20: =S20 -> 0.039355772 | U20: =T20 -> 0.039355772 | W20: ='Rail&Bus2'!G14 -> 10807.968 | X20: =W20 -> 10807.968 | Y20: ='Rail&Bus2'!G15 -> 10912.547 | Z20: =Y20 -> 10912.547 | AA20: =Z20 -> 10912.547 | AB20: ='Rail&Bus2'!G16 -> 11236.002 | AC20: =AB20 -> 11236.002 | AD20: =AC20 -> 11236.002 | AE20: =AD20 -> 11236.002 | AF20: ='Rail&Bus2'!H14 -> 555.05381 | AL20: 1 | AM20: 0 | AZ20: ='Rail&Bus2'!F14 -> 12
A21: =Technologies!B64 -> R2,R3,R4,R5,R6 | B21: =Technologies!C64 -> TBDSLAH | C21: ='Rail&Bus2'!B17 -> Bus, Advanced Hybrid Diesel | D21: bn-vmt, bn-vmt/a | E21: =Commodities!C$41 -> TBDSL | F21: TB | G21: 1 | H21: ='Rail&Bus2'!$E$17 -> 2015 | I21: =AZ21+5 -> 17 | J21: 0.28 | M21: ='Rail&Bus2'!I17 -> 0.05389245 | N21: =M21 -> 0.05389245 | O21: ='Rail&Bus2'!$I18 -> 0.05585064 | P21: =O21 -> 0.05585064 | Q21: =P21 -> 0.05585064 | R21: ='Rail&Bus2'!I19 -> 0.056557124 | S21: =R21 -> 0.056557124 | T21: =S21 -> 0.056557124 | U21: =T21 -> 0.056557124 | W21: ='Rail&Bus2'!G17 -> 17887.168 | X21: =W21 -> 17887.168 | Y21: ='Rail&Bus2'!G18 -> 15563.582 | Z21: =Y21 -> 15563.582 | AA21: =Z21 -> 15563.582 | AB21: ='Rail&Bus2'!G19 -> 15887.037 | AC21: =AB21 -> 15887.037 | AD21: =AC21 -> 15887.037 | AE21: =AD21 -> 15887.037 | AF21: ='Rail&Bus2'!H17 -> 564.4615 | AL21: 1 | AM21: 0 | AZ21: ='Rail&Bus2'!F17 -> 12
A22: * | B22: =Technologies!C65 -> TBB20C10 | C22: =Technologies!D65 -> Bus, Conventional Biodiesel, 2010 | D22: bn-vmt, bn-vmt/a | E22: TBB20X | F22: TB | G22: 1 | H22: 2010 | I22: =AZ22+5 -> 17 | J22: 0.18 | K22: ='Rail&Bus2'!$L9 -> 0.031770687 | V22: ='Rail&Bus2'!T9 -> 10426.657 | AF22: ='Rail&Bus2'!H20 -> 524.22213 | AL22: 1 | AN22: 0 | AO22: 0 | AP22: 0 | AQ22: 0 | AR22: 0 | AS22: 0 | AT22: 0 | AU22: 0 | AV22: 0 | AZ22: 12
A23: * | B23: =Technologies!C66 -> TBB20C | C23: ='Rail&Bus2'!B21 -> Bus, Conventional B20 | D23: bn-vmt, bn-vmt/a | E23: TBB20X | F23: TB | G23: 1 | H23: 2015 | I23: =AZ23+5 -> 17 | J23: 0.18 | M23: ='Rail&Bus2'!I11 -> 0.033488882 | N23: ='Rail&Bus2'!$I22 -> 0.034963103 | O23: =N23 -> 0.034963103 | P23: =O23 -> 0.034963103 | Q23: =P23 -> 0.034963103 | R23: =Q23 -> 0.034963103 | S23: =R23 -> 0.034963103 | T23: =S23 -> 0.034963103 | U23: =T23 -> 0.034963103 | W23: ='Rail&Bus2'!G21 -> 10488.439 | X23: ='Rail&Bus2'!G22 -> 10749.404 | Y23: =X23 -> 10749.404 | Z23: =Y23 -> 10749.404 | AA23: =Z23 -> 10749.404 | AB23: =AA23 -> 10749.404 | AC23: =AB23 -> 10749.404 | AD23: =AC23 -> 10749.404 | AE23: =AD23 -> 10749.404 | AF23: ='Rail&Bus2'!H21 -> 524.22213 | AL23: 1 | AZ23: ='Rail&Bus2'!F21 -> 12
A24: * | B24: =Technologies!C67 -> TBB20IM | C24: =Technologies!D67 -> Bus, B20, Improved Biodiesel | D24: bn-vmt, bn-vmt/a | E24: TBB20X | F24: TB | G24: 1 | H24: 2025 | I24: =AZ24+5 -> 17 | J24: 0.24 | K24: ='Rail&Bus2'!I23 -> 0.039068736 | Y24: ='Rail&Bus2'!G23 -> 11404.873 | Z24: =Y24 -> 11404.873 | AA24: =Z24 -> 11404.873 | AB24: =AA24 -> 11404.873 | AC24: =AB24 -> 11404.873 | AD24: =AC24 -> 11404.873 | AE24: =AD24 -> 11404.873 | AF24: ='Rail&Bus2'!H22 -> 524.22213 | AL24: 1 | AZ24: 12
A25: * | B25: =Technologies!C68 -> TBB20ADV | C25: ='Rail&Bus2'!B24 -> Bus, Advanced Tech B20 | D25: bn-vmt, bn-vmt/a | E25: TBB20X | F25: TB | G25: 1 | H25: 2015 | I25: =AZ25+5 -> 17 | J25: 0.28 | M25: ='Rail&Bus2'!I24 -> 0.037700577 | N25: =M25 -> 0.037700577 | O25: ='Rail&Bus2'!I25 -> 0.039067956 | P25: =O25 -> 0.039067956 | Q25: =P25 -> 0.039067956 | R25: ='Rail&Bus2'!I26 -> 0.039562487 | S25: =R25 -> 0.039562487 | T25: =S25 -> 0.039562487 | U25: =T25 -> 0.039562487 | W25: ='Rail&Bus2'!G24 -> 10807.968 | X25: =W25 -> 10807.968 | Y25: ='Rail&Bus2'!G25 -> 10912.547 | Z25: =Y25 -> 10912.547 | AA25: =Z25 -> 10912.547 | AB25: ='Rail&Bus2'!G26 -> 11236.005 | AC25: =AB25 -> 11236.005 | AD25: =AC25 -> 11236.005 | AE25: =AD25 -> 11236.005 | AF25: ='Rail&Bus2'!H23 -> 524.22213 | AL25: 1 | AZ25: 12
A26: * | B26: =Technologies!C69 -> TBB20AH | C26: ='Rail&Bus2'!B27 -> Bus, Advanced Hybrid B20 | D26: bn-vmt, bn-vmt/a | E26: TBB20X | F26: TB | G26: 1 | H26: 2015 | I26: =AZ26+5 -> 17 | J26: 0.28 | M26: ='Rail&Bus2'!I27 -> 0.053857967 | N26: =M26 -> 0.053857967 | O26: ='Rail&Bus2'!I28 -> 0.055811365 | P26: =O26 -> 0.055811365 | Q26: =P26 -> 0.055811365 | R26: ='Rail&Bus2'!I29 -> 0.056517838 | S26: =R26 -> 0.056517838 | T26: =S26 -> 0.056517838 | U26: =T26 -> 0.056517838 | W26: ='Rail&Bus2'!G27 -> 17887.168 | X26: =W26 -> 17887.168 | Y26: ='Rail&Bus2'!G28 -> 15563.582 | Z26: =Y26 -> 15563.582 | AA26: =Z26 -> 15563.582 | AB26: ='Rail&Bus2'!G29 -> 15887.04 | AC26: =AB26 -> 15887.04 | AD26: =AC26 -> 15887.04 | AE26: =AD26 -> 15887.04 | AF26: ='Rail&Bus2'!H27 -> 564.4615 | AL26: 1 | AZ26: 12
A27: =Technologies!B70 -> R2,R3,R4,R5,R6 | B27: =Technologies!C70 -> TBCNGC10 | C27: =Technologies!D70 -> Bus, Conventional CNG, 2010 | D27: bn-vmt, bn-vmt/a | E27: =Commodities!C$55 -> TBCNG | F27: TB | G27: 1 | H27: 2010 | I27: =AZ27+5 -> 17 | J27: 0.18 | K27: ='Rail&Bus2'!$L10 -> 0.027030696 | V27: ='Rail&Bus2'!T10 -> 12020.947 | AF27: ='Rail&Bus2'!H30 -> 639.72304 | AL27: 1 | AM27: 0 | AN27: 0 | AO27: 0 | AP27: 0 | AQ27: 0 | AR27: 0 | AS27: 0 | AT27: 0 | AU27: 0 | AV27: 0 | AZ27: 12
A28: =Technologies!B71 -> R2,R3,R4,R5,R6 | B28: =Technologies!C71 -> TBCNGC | C28: ='Rail&Bus2'!B31 -> Bus, Conventional CNG | D28: bn-vmt, bn-vmt/a | E28: =Commodities!C$55 -> TBCNG | F28: TB | G28: 1 | H28: 2015 | I28: =AZ28+5 -> 17 | J28: 0.18 | M28: ='Rail&Bus2'!$I31 -> 0.028412947 | N28: ='Rail&Bus2'!$I32 -> 0.029718407 | O28: =N28 -> 0.029718407 | P28: =O28 -> 0.029718407 | Q28: =P28 -> 0.029718407 | R28: =Q28 -> 0.029718407 | S28: =R28 -> 0.029718407 | T28: =S28 -> 0.029718407 | U28: =T28 -> 0.029718407 | W28: ='Rail&Bus2'!G31 -> 12033.046 | X28: ='Rail&Bus2'!G32 -> 12046.85 | Y28: =X28 -> 12046.85 | Z28: =Y28 -> 12046.85 | AA28: =Z28 -> 12046.85 | AB28: =AA28 -> 12046.85 | AC28: =AB28 -> 12046.85 | AD28: =AC28 -> 12046.85 | AE28: =AD28 -> 12046.85 | AF28: ='Rail&Bus2'!H31 -> 639.72304 | AL28: 1 | AM28: 0 | AZ28: ='Rail&Bus2'!F31 -> 12
A29: =Technologies!B72 -> R2,R3,R4,R5,R6 | B29: =Technologies!C72 -> TBCNGIM | C29: =Technologies!D72 -> Bus, Improved CNG | D29: bn-vmt, bn-vmt/a | E29: =Commodities!C$55 -> TBCNG | F29: TB | G29: 1 | H29: 2025 | I29: =AZ29+5 -> 17 | J29: 0.24 | K29: ='Rail&Bus2'!I33 -> 0.031231205 | Y29: ='Rail&Bus2'!G33 -> 12573.414 | Z29: =Y29 -> 12573.414 | AA29: =Z29 -> 12573.414 | AB29: =AA29 -> 12573.414 | AC29: =AB29 -> 12573.414 | AD29: =AC29 -> 12573.414 | AE29: =AD29 -> 12573.414 | AF29: ='Rail&Bus2'!H32 -> 639.72304 | AL29: 1 | AM29: 0 | AZ29: 12
A30: =Technologies!B73 -> R2,R3,R4,R5,R6 | B30: =Technologies!C73 -> TBCNGADV | C30: ='Rail&Bus2'!B34 -> Bus, Advanced Tech CNG | D30: bn-vmt, bn-vmt/a | E30: =Commodities!C$55 -> TBCNG | F30: TB | G30: 1 | H30: ='Rail&Bus2'!E34 -> 2015 | I30: =AZ30+5 -> 17 | J30: 0.28 | M30: ='Rail&Bus2'!I34 -> 0.030225233 | N30: =M30 -> 0.030225233 | O30: ='Rail&Bus2'!$I35 -> 0.030839567 | P30: =O30 -> 0.030839567 | Q30: =P30 -> 0.030839567 | R30: ='Rail&Bus2'!$I36 -> 0.031231205 | S30: =R30 -> 0.031231205 | T30: =S30 -> 0.031231205 | U30: =T30 -> 0.031231205 | W30: ='Rail&Bus2'!G34 -> 12097.885 | X30: =W30 -> 12097.885 | Y30: ='Rail&Bus2'!G35 -> 12081.088 | Z30: =Y30 -> 12081.088 | AA30: =Z30 -> 12081.088 | AB30: ='Rail&Bus2'!G36 -> 12404.543 | AC30: =AB30 -> 12404.543 | AD30: =AC30 -> 12404.543 | AE30: =AD30 -> 12404.543 | AF30: ='Rail&Bus2'!H34 -> 639.72304 | AL30: 1 | AM30: 0 | AZ30: ='Rail&Bus2'!F34 -> 12
A31: =Technologies!B74 -> R2,R3,R4,R5,R6 | B31: =Technologies!C74 -> TBCNGAH | C31: ='Rail&Bus2'!B37 -> Bus, Advanced Hybird CNG | D31: bn-vmt, bn-vmt/a | E31: =Commodities!C$55 -> TBCNG | F31: TB | G31: 1 | H31: 2015 | I31: =AZ31+5 -> 17 | J31: 0.28 | M31: ='Rail&Bus2'!I37 -> 0.04030031 | N31: =M31 -> 0.04030031 | O31: ='Rail&Bus2'!$I38 -> 0.041121982 | P31: =O31 -> 0.041121982 | Q31: =P31 -> 0.041121982 | R31: ='Rail&Bus2'!$I39 -> 0.041644166 | S31: =R31 -> 0.041644166 | T31: =S31 -> 0.041644166 | U31: =T31 -> 0.041644166 | W31: ='Rail&Bus2'!G37 -> 18533.521 | X31: =W31 -> 18533.521 | Y31: ='Rail&Bus2'!G38 -> 16309.301 | Z31: =Y31 -> 16309.301 | AA31: =Z31 -> 16309.301 | AB31: ='Rail&Bus2'!G39 -> 16632.756 | AC31: =AB31 -> 16632.756 | AD31: =AC31 -> 16632.756 | AE31: =AD31 -> 16632.756 | AF31: ='Rail&Bus2'!H37 -> 649.13073 | AL31: 1 | AM31: 0 | AZ31: ='Rail&Bus2'!F35 -> 12
A32: =Technologies!B75 -> R2,R3,R4,R5,R6 | B32: =Technologies!C75 -> TBH2FC | C32: ='Rail&Bus2'!B40 -> Bus, Hydrogen Fuel Cell | D32: bn-vmt, bn-vmt/a | E32: =Commodities!C$53 -> TRNH2 | F32: TB | G32: 1 | H32: ='Rail&Bus2'!E40 -> 2010 | I32: =AZ32+5 -> 17 | J32: 0.24 | K32: ='Rail&Bus2'!I40 -> 0.027477594 | V32: ='Rail&Bus2'!T12 -> 63771.6 | W32: ='Rail&Bus2'!U12 -> 51017.28 | X32: =W32 -> 51017.28 | Y32: ='Rail&Bus2'!V12 -> 31885.8 | Z32: =Y32 -> 31885.8 | AA32: =Z32 -> 31885.8 | AB32: ='Rail&Bus2'!W12 -> 19131.48 | AC32: =AB32 -> 19131.48 | AD32: =AC32 -> 19131.48 | AE32: =AD32 -> 19131.48 | AF32: ='Rail&Bus2'!H43 -> 1317.0768 | AL32: 1 | AM32: 0 | AZ32: ='Rail&Bus2'!F40 -> 12
A33: =Technologies!B76 -> R2,R3,R4,R5,R6 | B33: =Technologies!C76 -> TBH2HYB | C33: ='Rail&Bus2'!B44 -> Bus, Hydrogen Fuel Cell Hybrid | D33: bn-vmt, bn-vmt/a | E33: =Commodities!C$53 -> TRNH2 | F33: TB | G33: 1 | H33: ='Rail&Bus2'!E44 -> 2010 | I33: =AZ33+5 -> 17 | J33: 0.24 | K33: ='Rail&Bus2'!I44 -> 0.049930713 | V33: =V32 -> 63771.6 | W33: ='Rail&Bus2'!U13 -> 51017.28 | X33: =W33 -> 51017.28 | Y33: ='Rail&Bus2'!V13 -> 31885.8 | Z33: =Y33 -> 31885.8 | AA33: =Z33 -> 31885.8 | AB33: ='Rail&Bus2'!W13 -> 19131.48 | AC33: =AB33 -> 19131.48 | AD33: =AC33 -> 19131.48 | AE33: =AD33 -> 19131.48 | AF33: ='Rail&Bus2'!H44 -> 1317.0768 | AL33: 1 | AZ33: ='Rail&Bus2'!F44 -> 12
A34: =Technologies!B77 -> R2,R3,R4,R5,R6 | B34: =Technologies!C77 -> TBELC | C34: =Technologies!D77 -> Bus, Conventional ELC | D34: bn-vmt, bn-vmt/a | E34: TRNELC | F34: TB | G34: 1 | H34: 2020 | I34: 17 | J34: 0.28 | K34: 0.0811 | W34: 16379.979 | X34: 16379.979 | Y34: 16379.979 | Z34: 16379.979 | AA34: 16379.979 | AB34: 16379.979 | AC34: 16379.979 | AD34: 16379.979 | AE34: 16379.979 | AF34: 333.0323 | AL34: 1 | AZ34: 12
