Workbook
Name AnswerData: #REF!
Name AnswerData: #REF!
Name AnswerData: #REF!
Name AnswerData: #REF!
Name AnswerData: #REF!
Name BDSEFF: [1]TechInfo!$J$33
Name BFBEFF: [1]TechInfo!$J$32
Name BFCEFF: [1]TechInfo!$J$34
Name blah: #REF!
Name bprint: #REF!
Name bprint: #REF!
Name bprint: #REF!
Name bprint: #REF!
Name BSGEFF: [1]TechInfo!$J$35
Name BSOEFF: [1]TechInfo!$J$31
Name BST_AF: [1]CHPData!$B$40
Name BST2_INV: [1]CHPData!$C$66
Name BST3_INV: [1]CHPData!$D$66
Name CCT_AF: [1]CHPData!$B$81
Name CCT2_INV: [1]CHPData!$C$91
Name CCT3_INV: [1]CHPData!$D$91
Name CCT4_INV: [1]CHPData!$E$91
Name CCT5_INV: [1]CHPData!$F$91
Name CFBEFF: [1]TechInfo!$J$29
Name CMM_SUPPLY_CRV_TABLE: [2]cum2025curves!#REF!
Name CMM_SUPPLY_CRV_TABLE: [2]cum2025curves!#REF!
Name CMM_SUPPLY_CRV_TABLE: [2]cum2025curves!#REF!
Name CMM_SUPPLY_CRV_TABLE: [2]cum2025curves!#REF!
Name cprint: #REF!
Name cprint: #REF!
Name cprint: #REF!
Name cprint: #REF!
Name CPVEFF: [1]TechInfo!$J$27
Name CSOEFF: [1]TechInfo!$J$28
Name DSTEFF: [1]TechInfo!$J$37
Name exch_rate: #REF!
Name exch_rate: #REF!
Name exch_rate: #REF!
Name exch_rate: #REF!
Name exch_rate: #REF!
Name FCL_AF: [1]CHPData!$B$154
Name FCL2_INV: [1]CHPData!$C$163
Name FCL3_INV: [1]CHPData!$D$163
Name fitfile: [3]MODEL!$D$38
Name INF: [3]MODEL!$H$14
Name million_short_tons_to_short_ton: [4]Steps!$Y$5
Name MMBTU_to_PJ: [4]Steps!$Y$6
Name MT2_INV: [1]CHPData!$C$141
Name MT3_INV: [1]CHPData!$D$141
Name neb: #REF!
Name PPP: [3]MODEL!$D$12
Name PPPEX: [3]MODEL!$D$13
Name rail_coal: #REF!
Name rail_coal: #REF!
Name rail_coal: #REF!
Name rail_coal: #REF!
Name rail_coal: #REF!
Name REG1_AF: [1]CHPData!$B$107
Name REG1_INV: [1]CHPData!$B$117
Name REG2_AF: [1]CHPData!$C$107

Sheet Fractions10
C1: Back to home page | J1: 29 | K1: 30 | L1: 31 | M1: 32 | N1: 33 | O1: 34 | P1: 35 | Q1: 36 | R1: 37 | S1: 40 | T1: 41 | U1: 42 | V1: 43 | W1: 44 | X1: 45 | Y1: 46 | Z1: 47 | AA1: 48 | BO1: R1 | BP1: R2 | BQ1: R3 | BR1: R4 | BS1: R5 | BT1: R6 | BU1: R7 | BV1: R8 | BW1: R9 | DG1: R1 | DH1: R2 | DI1: R3 | DJ1: R4 | DK1: R5 | DL1: R6 | DM1: R7 | DN1: R8 | DO1: R9
A3: This sheet contains the calculations and analysis needed for determining key fractions that will be used in order to help steer projections in the right direction. Fractions include end use shares for each sub-sector and region, output shares for each sub-sector, fuel, end-use and region, and regional breakdowns of demand.
A5: Table 90. 2010 Output for each technology | AW5: Table P65. 2010 Regional Output for each sub-sector and end use combination | BJ5: Table 91. 2010 End use fractions for each sub-sector | CH5: Table P66. Table 91 in pivot form | CS5: Table P67. 2010 Regional output for each sub-sector, fuel, and end-use combination | DE5: Table 92. 2010 Output shares relative to each sub-sector and end-use combination | DZ5: Table P68. Table 93 in pivot form | EK5: Table 93. Fuel Relaxation Percentages | EO5: Table 94. 2010 Regional breakdown of demand for each sub-sector | ET5: Table P69. Table 94 in pivot form | EW5: Table 95. 2010 demand adjustments | FI5: Table P70. Table 95 in pivot form
J6: Capacity (CHP - GW, Other - PJ/a) | S6: Availability Factor | AB6: Output | AL6: CHP Electricity Output | AX6: Values | BO6: Output (PJ/a) | BX6: Fraction | CI6: Values | CT6: Values | DG6: Output (PJ/a) | DP6: Output fraction relative to end-use | EA6: Values | FI6: Sum of Demand Adjustment | FJ6: Column Labels
A7: Sub-Sector | B7: End-Use | C7: AEO Fuel Type | D7: MARKAL Fuel Type | E7: Technology | F7: Constraint Identifier | G7: Sheet | H7: % Steam Output (CHP) | I7: % Electricity Output (CHP) | J7: R1 (Cap) | K7: R2 (Cap) | L7: R3 (Cap) | M7: R4 (Cap) | N7: R5 (Cap) | O7: R6 (Cap) | P7: R7 (Cap) | Q7: R8 (Cap) | R7: R9 (Cap) | S7: R1 (AF) | T7: R2 (AF) | U7: R3 (AF) | V7: R4 (AF) | W7: R5 (AF) | X7: R6 (AF) | Y7: R7 (AF) | Z7: R8 (AF) | AA7: R9 (AF) | AB7: R1 (Out) | AC7: R2 (Out) | AD7: R3 (Out) | AE7: R4 (Out) | AF7: R5 (Out) | AG7: R6 (Out) | AH7: R7 (Out) | AI7: R8 (Out) | AJ7: R9 (Out) | AK7: U.S. (Out) | AL7: R1 (ELC) | AM7: R2 (ELC) | AN7: R3 (ELC) | AO7: R4 (ELC) | AP7: R5 (ELC) | AQ7: R6 (ELC) | AR7: R7 (ELC) | AS7: R8 (ELC) | AT7: R9 (ELC) | AU7: U.S. (ELC) | AW7: Row Labels | AX7: Sum of R1 (Out) | AY7: Sum of R2 (Out) | AZ7: Sum of R3 (Out) | BA7: Sum of R4 (Out) | BB7: Sum of R5 (Out) | BC7: Sum of R6 (Out) | BD7: Sum of R7 (Out) | BE7: Sum of R8 (Out) | BF7: Sum of R9 (Out) | BG7: Sum of U.S. (Out) | BH7: Sum of U.S. (ELC) | BJ7: Sub-Sector | BK7: MARKAL Sub-Sector Identifier | BL7: End-Use | BM7: MARKAL End-Use Identifier | BN7: End-Use Commodity | BO7: R1 (Out) | BP7: R2 (Out) | BQ7: R3 (Out) | BR7: R4 (Out) | BS7: R5 (Out) | BT7: R6 (Out) | BU7: R7 (Out) | BV7: R8 (Out) | BW7: R9 (Out) | BX7: R1 (%) | BY7: R2 (%) | BZ7: R3 (%) | CA7: R4 (%) | CB7: R5 (%) | CC7: R6 (%) | CD7: R7 (%) | CE7: R8 (%) | CF7: R9 (%) | CH7: Row Labels | CI7: Sum of R1 (%) | CJ7: Sum of R2 (%) | CK7: Sum of R3 (%) | CL7: Sum of R4 (%) | CM7: Sum of R5 (%) | CN7: Sum of R6 (%) | CO7: Sum of R7 (%) | CP7: Sum of R8 (%) | CQ7: Sum of R9 (%) | CS7: Row Labels | CT7: Sum of R1 (Out) | CU7: Sum of R2 (Out) | CV7: Sum of R3 (Out) | CW7: Sum of R4 (Out) | CX7: Sum of R5 (Out) | CY7: Sum of R6 (Out) | CZ7: Sum of R7 (Out) | DA7: Sum of R8 (Out) | DB7: Sum of R9 (Out) | DC7: Sum of U.S. (Out) | DE7: Constraint identifier | DF7: Sub-sector and End Use Identifier | DG7: =DG1&" (Fuel)" -> R1 (Fuel) | DH7: =DH1&" (Fuel)" -> R2 (Fuel) | DI7: =DI1&" (Fuel)" -> R3 (Fuel) | DJ7: =DJ1&" (Fuel)" -> R4 (Fuel) | DK7: =DK1&" (Fuel)" -> R5 (Fuel) | DL7: =DL1&" (Fuel)" -> R6 (Fuel) | DM7: =DM1&" (Fuel)" -> R7 (Fuel) | DN7: =DN1&" (Fuel)" -> R8 (Fuel) | DO7: =DO1&" (Fuel)" -> R9 (Fuel) | DP7: =DG1&" (Frac)" -> R1 (Frac) | DQ7: =DH1&" (Frac)" -> R2 (Frac) | DR7: =DI1&" (Frac)" -> R3 (Frac) | DS7: =DJ1&" (Frac)" -> R4 (Frac) | DT7: =DK1&" (Frac)" -> R5 (Frac) | DU7: =DL1&" (Frac)" -> R6 (Frac) | DV7: =DM1&" (Frac)" -> R7 (Frac) | DW7: =DN1&" (Frac)" -> R8 (Frac) | DX7: =DO1&" (Frac)" -> R9 (Frac) | DZ7: Row Labels | EA7: Sum of R1 (Frac) | EB7: Sum of R2 (Frac) | EC7: Sum of R3 (Frac) | ED7: Sum of R4 (Frac) | EE7: Sum of R5 (Frac) | EF7: Sum of R6 (Frac) | EG7: Sum of R7 (Frac) | EH7: Sum of R8 (Frac) | EI7: Sum of R9 (Frac) | EK7: General Industry Category | EL7: Natural Gas | EM7: Coal | EO7: Sub-sector | EP7: Region | EQ7: Output (PJ/a) | ER7: Output (%) | ET7: Row Labels | EU7: Sum of Output (%) | EW7: Sub-sector | EX7: MARKAL Sub-Sector Identifier | EY7: Minimum End Use | EZ7: MARKAL End Use Identifier | FA7: End Use | FB7: Region | FC7: Original Demand | FD7: End Use Demand | FE7: End Use Fraction | FF7: End Use Adjustment | FG7: Demand Adjustment | FI7: Row Labels | FJ7: R1 | FK7: R2 | FL7: R3 | FM7: R4 | FN7: R5 | FO7: R6 | FP7: R7 | FQ7: R8 | FR7: R9 | FS7: Grand Total
A8: Agricultural Chemicals | B8: Facilities | C8: Distillate Oil | D8: Distillate Oil | E8: ICAEFACDST | F8: =EndUse(A8,B8,C8,G8) -> #NAME? | G8: TechData_OTR | H8: 1 | I8: 0 | J8: 0 | K8: 2.6967092 | S8: 1 | T8: 1 | U8: 1 | V8: 1 | W8: 1 | X8: 1 | Y8: 1 | Z8: 1 | AA8: 1 | AB8: =J8*$H8*S8 -> 0 | AC8: =K8*$H8*T8 -> 2.6967092 | AD8: =L8*$H8*U8 -> 0 | AE8: =M8*$H8*V8 -> 0 | AF8: =N8*$H8*W8 -> 0 | AG8: =O8*$H8*X8 -> 0 | AH8: =P8*$H8*Y8 -> 0 | AI8: =Q8*$H8*Z8 -> 0 | AJ8: =R8*$H8*AA8 -> 0 | AK8: =SUM(AB8:AJ8) -> 2.6967092 | AL8: 0 | AM8: 0 | AN8: 0 | AO8: 0 | AP8: 0 | AQ8: 0 | AR8: 0 | AS8: 0 | AT8: 0 | AU8: 0 | AW8: Agricultural Chemicals | AX8: 0 | AY8: 0 | AZ8: 45.432757 | BA8: 39.801248 | BB8: 61.795009 | BC8: 59.992423 | BD8: 194.70981 | BE8: 4.2262309 | BF8: 1.8615012 | BG8: 407.81898 | BH8: 1.823728 | BJ8: Agricultural Chemicals | BK8: ICA | BL8: Electrochemical | BM8: ETC | BN8: =BK8&BM8 -> ICAETC | BO8: =IF(ISERROR(GETPIVOTDATA("Sum of "&BO$1&" (Out)",$AW$6,"Sub-Sector",$BJ8,"End-Use",$BL8)),0,GETPIVOTDATA("Sum of "&BO$1&" (Out)",$AW$6,"Sub-Sector",$BJ8,"End-Use",$BL8)) -> 0 | BP8: =IF(ISERROR(GETPIVOTDATA("Sum of "&BP$1&" (Out)",$AW$6,"Sub-Sector",$BJ8,"End-Use",$BL8)),0,GETPIVOTDATA("Sum of "&BP$1&" (Out)",$AW$6,"Sub-Sector",$BJ8,"End-Use",$BL8)) -> 0 | BQ8: =IF(ISERROR(GETPIVOTDATA("Sum of "&BQ$1&" (Out)",$AW$6,"Sub-Sector",$BJ8,"End-Use",$BL8)),0,GETPIVOTDATA("Sum of "&BQ$1&" (Out)",$AW$6,"Sub-Sector",$BJ8,"End-Use",$BL8)) -> 0 | BR8: =IF(ISERROR(GETPIVOTDATA("Sum of "&BR$1&" (Out)",$AW$6,"Sub-Sector",$BJ8,"End-Use",$BL8)),0,GETPIVOTDATA("Sum of "&BR$1&" (Out)",$AW$6,"Sub-Sector",$BJ8,"End-Use",$BL8)) -> 0 | BS8: =IF(ISERROR(GETPIVOTDATA("Sum of "&BS$1&" (Out)",$AW$6,"Sub-Sector",$BJ8,"End-Use",$BL8)),0,GETPIVOTDATA("Sum of "&BS$1&" (Out)",$AW$6,"Sub-Sector",$BJ8,"End-Use",$BL8)) -> 0 | BT8: =IF(ISERROR(GETPIVOTDATA("Sum of "&BT$1&" (Out)",$AW$6,"Sub-Sector",$BJ8,"End-Use",$BL8)),0,GETPIVOTDATA("Sum of "&BT$1&" (Out)",$AW$6,"Sub-Sector",$BJ8,"End-Use",$BL8)) -> 0 | BU8: =IF(ISERROR(GETPIVOTDATA("Sum of "&BU$1&" (Out)",$AW$6,"Sub-Sector",$BJ8,"End-Use",$BL8)),0,GETPIVOTDATA("Sum of "&BU$1&" (Out)",$AW$6,"Sub-Sector",$BJ8,"End-Use",$BL8)) -> 0 | BV8: =IF(ISERROR(GETPIVOTDATA("Sum of "&BV$1&" (Out)",$AW$6,"Sub-Sector",$BJ8,"End-Use",$BL8)),0,GETPIVOTDATA("Sum of "&BV$1&" (Out)",$AW$6,"Sub-Sector",$BJ8,"End-Use",$BL8)) -> 0 | BW8: =IF(ISERROR(GETPIVOTDATA("Sum of "&BW$1&" (Out)",$AW$6,"Sub-Sector",$BJ8,"End-Use",$BL8)),0,GETPIVOTDATA("Sum of "&BW$1&" (Out)",$AW$6,"Sub-Sector",$BJ8,"End-Use",$BL8)) -> 0 | BX8: 0 | BY8: 0 | BZ8: =BQ8/BQ15 -> 0 | CA8: =BR8/BR15 -> 0 | CB8: =BS8/BS15 -> 0 | CC8: =BT8/BT15 -> 0 | CD8: =BU8/BU15 -> 0 | CE8: =BV8/BV15 -> 0 | CF8: =BW8/BW15 -> 0 | CH8: ICAETC | CI8: 0 | CJ8: 0 | CK8: 0 | CL8: 0 | CM8: 0 | CN8: 0 | CO8: 0 | CP8: 0 | CQ8: 0 | CS8: ICAFA_DST | CT8: 0 | CU8: 0 | CV8: 0 | CW8: 0 | CX8: 2.6967092 | CY8: 2.3505749 | CZ8: 8.1659027 | DA8: 0 | DB8: 0 | DC8: 13.213187 | DE8: ICAOH_OTP | DF8: =LEFT(DE8,5) -> ICAOH | DG8: =GETPIVOTDATA("Sum of "&DG$1&" (Out)",$CS$6,"Constraint Identifier",$DE8) -> 0 | DH8: =GETPIVOTDATA("Sum of "&DH$1&" (Out)",$CS$6,"Constraint Identifier",$DE8) -> 0 | DI8: =GETPIVOTDATA("Sum of "&DI$1&" (Out)",$CS$6,"Constraint Identifier",$DE8) -> 0.36588093 | DJ8: =GETPIVOTDATA("Sum of "&DJ$1&" (Out)",$CS$6,"Constraint Identifier",$DE8) -> 0.24781986 | DK8: =GETPIVOTDATA("Sum of "&DK$1&" (Out)",$CS$6,"Constraint Identifier",$DE8) -> 0 | DL8: =GETPIVOTDATA("Sum of "&DL$1&" (Out)",$CS$6,"Constraint Identifier",$DE8) -> 0 | DM8: =GETPIVOTDATA("Sum of "&DM$1&" (Out)",$CS$6,"Constraint Identifier",$DE8) -> 0 | DN8: =GETPIVOTDATA("Sum of "&DN$1&" (Out)",$CS$6,"Constraint Identifier",$DE8) -> 0 | DO8: =GETPIVOTDATA("Sum of "&DO$1&" (Out)",$CS$6,"Constraint Identifier",$DE8) -> 0 | DP8: =IF(SUMIF($DF$8:$DF$380,"="&$DF8,DG$8:DG$380)=0,0,DG8/SUMIF($DF$8:$DF$380,"="&$DF8,DG$8:DG$380)) -> 0 | DQ8: =IF(SUMIF($DF$8:$DF$380,"="&$DF8,DH$8:DH$380)=0,0,DH8/SUMIF($DF$8:$DF$380,"="&$DF8,DH$8:DH$380)) -> 0 | DR8: =IF(SUMIF($DF$8:$DF$380,"="&$DF8,DI$8:DI$380)=0,0,DI8/SUMIF($DF$8:$DF$380,"="&$DF8,DI$8:DI$380)) -> 1 | DS8: =IF(SUMIF($DF$8:$DF$380,"="&$DF8,DJ$8:DJ$380)=0,0,DJ8/SUMIF($DF$8:$DF$380,"="&$DF8,DJ$8:DJ$380)) -> 1 | DT8: =IF(SUMIF($DF$8:$DF$380,"="&$DF8,DK$8:DK$380)=0,0,DK8/SUMIF($DF$8:$DF$380,"="&$DF8,DK$8:DK$380)) -> 0 | DU8: =IF(SUMIF($DF$8:$DF$380,"="&$DF8,DL$8:DL$380)=0,0,DL8/SUMIF($DF$8:$DF$380,"="&$DF8,DL$8:DL$380)) -> 0 | DV8: =IF(SUMIF($DF$8:$DF$380,"="&$DF8,DM$8:DM$380)=0,0,DM8/SUMIF($DF$8:$DF$380,"="&$DF8,DM$8:DM$380)) -> 0 | DW8: =IF(SUMIF($DF$8:$DF$380,"="&$DF8,DN$8:DN$380)=0,0,DN8/SUMIF($DF$8:$DF$380,"="&$DF8,DN$8:DN$380)) -> 0 | DX8: =IF(SUMIF($DF$8:$DF$380,"="&$DF8,DO$8:DO$380)=0,0,DO8/SUMIF($DF$8:$DF$380,"="&$DF8,DO$8:DO$380)) -> 0 | DZ8: ICAFA_DST | EA8: 0 | EB8: 0 | EC8: 0 | ED8: 0 | EE8: 0.90292324 | EF8: 0.90292324 | EG8: 0.90292324 | EH8: 0 | EI8: 0 | EK8: Feedstocks | EL8: 0.9 | EO8: Agricultural Chemicals | EP8: R1 | EQ8: =GETPIVOTDATA("Sum of "&EP8&" (Out)",$AW$6,"Sub-Sector",EO8) -> 0 | ER8: =EQ8/SUM(EQ8:EQ16) -> 0 | ET8: Agricultural Chemicals | EU8: 1 | EW8: Agricultural Chemicals | EX8: ICA | EY8: Facilities | EZ8: FAC | FA8: =EX8&EZ8 -> ICAFAC | FB8: R3 | FC8: =GETPIVOTDATA("Sum of "&FB8&" (Out)",$AW$6,"Sub-Sector",EW8) -> 45.432757 | FD8: =GETPIVOTDATA("Sum of "&FB8&" (Out)",$AW$6,"Sub-Sector",EW8,"End-Use",EY8) -> 0.28316891 | FE8: =GETPIVOTDATA("Sum of "&FB8&" (%)",$CH$6,"End-Use Commodity",FA8) -> 0.0062327035 | FF8: 0 | FG8: =FC8-((FD8-FF8)/FE8) -> 0 | FI8: ICA | FL8: 0 | FM8: 0 | FN8: 0 | FO8: 0 | FP8: 0.43059052 | FQ8: 0 | FR8: 0 | FS8: 0.43059052
A9: Agricultural Chemicals | B9: Facilities | C9: Electricity | D9: Electricity | E9: ICAEFACELC | F9: =EndUse(A9,B9,C9,G9) -> #NAME? | G9: TechData_OTR | H9: 1 | I9: 0 | J9: 0.12902151 | K9: 0.16302314 | S9: 1 | T9: 1 | U9: 1 | V9: 1 | W9: 1 | X9: 1 | Y9: 1 | Z9: 1 | AA9: 1 | AB9: =J9*$H9*S9 -> 0.12902151 | AC9: =K9*$H9*T9 -> 0.16302314 | AD9: =L9*$H9*U9 -> 0 | AE9: =M9*$H9*V9 -> 0 | AF9: =N9*$H9*W9 -> 0 | AG9: =O9*$H9*X9 -> 0 | AH9: =P9*$H9*Y9 -> 0 | AI9: =Q9*$H9*Z9 -> 0 | AJ9: =R9*$H9*AA9 -> 0 | AK9: =SUM(AB9:AJ9) -> 0.29204465 | AL9: 0 | AM9: 0 | AN9: 0 | AO9: 0 | AP9: 0 | AQ9: 0 | AR9: 0 | AS9: 0 | AT9: 0 | AU9: 0 | AW9: Facilities | AX9: 0 | AY9: 0 | AZ9: 0.28316891 | BA9: 0.19179703 | BB9: 2.9866428 | BC9: 2.6032943 | BD9: 9.0438504 | BE9: 0.10910629 | BF9: 0.06841461 | BG9: 15.286274 | BH9: 0 | BJ9: Agricultural Chemicals | BK9: ICA | BL9: Facilities | BM9: FAC | BN9: =BK9&BM9 -> ICAFAC | BO9: =IF(ISERROR(GETPIVOTDATA("Sum of "&BO$1&" (Out)",$AW$6,"Sub-Sector",$BJ9,"End-Use",$BL9)),0,GETPIVOTDATA("Sum of "&BO$1&" (Out)",$AW$6,"Sub-Sector",$BJ9,"End-Use",$BL9)) -> 0 | BP9: =IF(ISERROR(GETPIVOTDATA("Sum of "&BP$1&" (Out)",$AW$6,"Sub-Sector",$BJ9,"End-Use",$BL9)),0,GETPIVOTDATA("Sum of "&BP$1&" (Out)",$AW$6,"Sub-Sector",$BJ9,"End-Use",$BL9)) -> 0 | BQ9: =IF(ISERROR(GETPIVOTDATA("Sum of "&BQ$1&" (Out)",$AW$6,"Sub-Sector",$BJ9,"End-Use",$BL9)),0,GETPIVOTDATA("Sum of "&BQ$1&" (Out)",$AW$6,"Sub-Sector",$BJ9,"End-Use",$BL9)) -> 0.28316891 | BR9: =IF(ISERROR(GETPIVOTDATA("Sum of "&BR$1&" (Out)",$AW$6,"Sub-Sector",$BJ9,"End-Use",$BL9)),0,GETPIVOTDATA("Sum of "&BR$1&" (Out)",$AW$6,"Sub-Sector",$BJ9,"End-Use",$BL9)) -> 0.19179703 | BS9: =IF(ISERROR(GETPIVOTDATA("Sum of "&BS$1&" (Out)",$AW$6,"Sub-Sector",$BJ9,"End-Use",$BL9)),0,GETPIVOTDATA("Sum of "&BS$1&" (Out)",$AW$6,"Sub-Sector",$BJ9,"End-Use",$BL9)) -> 2.9866428 | BT9: =IF(ISERROR(GETPIVOTDATA("Sum of "&BT$1&" (Out)",$AW$6,"Sub-Sector",$BJ9,"End-Use",$BL9)),0,GETPIVOTDATA("Sum of "&BT$1&" (Out)",$AW$6,"Sub-Sector",$BJ9,"End-Use",$BL9)) -> 2.6032943 | BU9: =IF(ISERROR(GETPIVOTDATA("Sum of "&BU$1&" (Out)",$AW$6,"Sub-Sector",$BJ9,"End-Use",$BL9)),0,GETPIVOTDATA("Sum of "&BU$1&" (Out)",$AW$6,"Sub-Sector",$BJ9,"End-Use",$BL9)) -> 9.0438504 | BV9: =IF(ISERROR(GETPIVOTDATA("Sum of "&BV$1&" (Out)",$AW$6,"Sub-Sector",$BJ9,"End-Use",$BL9)),0,GETPIVOTDATA("Sum of "&BV$1&" (Out)",$AW$6,"Sub-Sector",$BJ9,"End-Use",$BL9)) -> 0.10910629 | BW9: =IF(ISERROR(GETPIVOTDATA("Sum of "&BW$1&" (Out)",$AW$6,"Sub-Sector",$BJ9,"End-Use",$BL9)),0,GETPIVOTDATA("Sum of "&BW$1&" (Out)",$AW$6,"Sub-Sector",$BJ9,"End-Use",$BL9)) -> 0.06841461 | BX9: 0 | BY9: 0 | BZ9: =BQ9/BQ15 -> 0.0062327035 | CA9: =BR9/BR15 -> 0.0048188698 | CB9: =BS9/BS15 -> 0.048331457 | CC9: =BT9/BT15 -> 0.043393717 | CD9: =BU9/BU15 -> 0.046447841 | CE9: =BV9/BV15 -> 0.025816452 | CF9: =BW9/BW15 -> 0.036752386 | CH9: ICAFAC | CI9: 0 | CJ9: 0 | CK9: 0.0062327035 | CL9: 0.0048188698 | CM9: 0.048331457 | CN9: 0.043393717 | CO9: 0.046447841 | CP9: 0.025816452 | CQ9: 0.036752386 | CS9: ICAFA_ELC | CT9: 0 | CU9: 0 | CV9: 0.1904872 | CW9: 0.12902151 | CX9: 0.16302314 | CY9: 0.14209841 | CZ9: 0.49365022 | DA9: 0.098186775 | DB9: 0.06156758 | DC9: 1.2780348 | DE9: INCOH_OTP | DF9: =LEFT(DE9,5) -> INCOH | DG9: =GETPIVOTDATA("Sum of "&DG$1&" (Out)",$CS$6,"Constraint Identifier",$DE9) -> 0.16085723 | DH9: =GETPIVOTDATA("Sum of "&DH$1&" (Out)",$CS$6,"Constraint Identifier",$DE9) -> 0.44278584 | DI9: =GETPIVOTDATA("Sum of "&DI$1&" (Out)",$CS$6,"Constraint Identifier",$DE9) -> 2.1593079 | DJ9: =GETPIVOTDATA("Sum of "&DJ$1&" (Out)",$CS$6,"Constraint Identifier",$DE9) -> 1.4625506 | DK9: =GETPIVOTDATA("Sum of "&DK$1&" (Out)",$CS$6,"Constraint Identifier",$DE9) -> 0.44351597 | DL9: =GETPIVOTDATA("Sum of "&DL$1&" (Out)",$CS$6,"Constraint Identifier",$DE9) -> 0.38658877 | DM9: =GETPIVOTDATA("Sum of "&DM$1&" (Out)",$CS$6,"Constraint Identifier",$DE9) -> 1.3430103 | DN9: =GETPIVOTDATA("Sum of "&DN$1&" (Out)",$CS$6,"Constraint Identifier",$DE9) -> 0.44520677 | DO9: =GETPIVOTDATA("Sum of "&DO$1&" (Out)",$CS$6,"Constraint Identifier",$DE9) -> 0.27916492 | DP9: =IF(SUMIF($DF$8:$DF$380,"="&$DF9,DG$8:DG$380)=0,0,DG9/SUMIF($DF$8:$DF$380,"="&$DF9,DG$8:DG$380)) -> 1 | DQ9: =IF(SUMIF($DF$8:$DF$380,"="&$DF9,DH$8:DH$380)=0,0,DH9/SUMIF($DF$8:$DF$380,"="&$DF9,DH$8:DH$380)) -> 0.077581754 | DR9: =IF(SUMIF($DF$8:$DF$380,"="&$DF9,DI$8:DI$380)=0,0,DI9/SUMIF($DF$8:$DF$380,"="&$DF9,DI$8:DI$380)) -> 0.10286678 | DS9: =IF(SUMIF($DF$8:$DF$380,"="&$DF9,DJ$8:DJ$380)=0,0,DJ9/SUMIF($DF$8:$DF$380,"="&$DF9,DJ$8:DJ$380)) -> 0.10286678 | DT9: =IF(SUMIF($DF$8:$DF$380,"="&$DF9,DK$8:DK$380)=0,0,DK9/SUMIF($DF$8:$DF$380,"="&$DF9,DK$8:DK$380)) -> 0.10286678 | DU9: =IF(SUMIF($DF$8:$DF$380,"="&$DF9,DL$8:DL$380)=0,0,DL9/SUMIF($DF$8:$DF$380,"="&$DF9,DL$8:DL$380)) -> 0.10286678 | DV9: =IF(SUMIF($DF$8:$DF$380,"="&$DF9,DM$8:DM$380)=0,0,DM9/SUMIF($DF$8:$DF$380,"="&$DF9,DM$8:DM$380)) -> 0.10286678 | DW9: =IF(SUMIF($DF$8:$DF$380,"="&$DF9,DN$8:DN$380)=0,0,DN9/SUMIF($DF$8:$DF$380,"="&$DF9,DN$8:DN$380)) -> 0.10286678 | DX9: =IF(SUMIF($DF$8:$DF$380,"="&$DF9,DO$8:DO$380)=0,0,DO9/SUMIF($DF$8:$DF$380,"="&$DF9,DO$8:DO$380)) -> 0.10286678 | DZ9: ICAFA_ELC | EA9: 0 | EB9: 0 | EC9: 0.67269815 | ED9: 0.67269815 | EE9: 0.054584076 | EF9: 0.054584076 | EG9: 0.054584076 | EH9: 0.89991859 | EI9: 0.89991859 | EK9: Food | EL9: 28 | EM9: 20 | EO9: Agricultural Chemicals | EP9: R2 | EQ9: =GETPIVOTDATA("Sum of "&EP9&" (Out)",$AW$6,"Sub-Sector",EO9) -> 0 | ER9: =EQ9/SUM(EQ8:EQ16) -> 0 | ET9: R1 | EU9: 0 | EW9: Agricultural Chemicals | EX9: ICA | EY9: Facilities | EZ9: FAC | FA9: =EX9&EZ9 -> ICAFAC | FB9: R4 | FC9: =GETPIVOTDATA("Sum of "&FB9&" (Out)",$AW$6,"Sub-Sector",EW9) -> 39.801248 | FD9: =GETPIVOTDATA("Sum of "&FB9&" (Out)",$AW$6,"Sub-Sector",EW9,"End-Use",EY9) -> 0.19179703 | FE9: =GETPIVOTDATA("Sum of "&FB9&" (%)",$CH$6,"End-Use Commodity",FA9) -> 0.0048188698 | FF9: 0 | FG9: =FC9-((FD9-FF9)/FE9) -> 0 | FI9: ICI | FJ9: 0 | FK9: 0 | FL9: 0 | FM9: 0 | FN9: 0.064592122 | FO9: 0.6505523 | FP9: 0.062730209 | FQ9: 0.079818174 | FR9: 0.077045684 | FS9: 0.93473849
A10: Agricultural Chemicals | B10: Facilities | C10: Natural Gas | D10: Natural Gas | E10: ICAEFACNGA | F10: =EndUse(A10,B10,C10,G10) -> #NAME? | G10: TechData_OTR | H10: 1 | I10: 0 | J10: 0.062775525 | K10: 0.12691048 | S10: 1 | T10: 1 | U10: 1 | V10: 1 | W10: 1 | X10: 1 | Y10: 1 | Z10: 1 | AA10: 1 | AB10: =J10*$H10*S10 -> 0.062775525 | AC10: =K10*$H10*T10 -> 0.12691048 | AD10: =L10*$H10*U10 -> 0 | AE10: =M10*$H10*V10 -> 0 | AF10: =N10*$H10*W10 -> 0 | AG10: =O10*$H10*X10 -> 0 | AH10: =P10*$H10*Y10 -> 0 | AI10: =Q10*$H10*Z10 -> 0 | AJ10: =R10*$H10*AA10 -> 0 | AK10: =SUM(AB10:AJ10) -> 0.189686 | AL10: 0 | AM10: 0 | AN10: 0 | AO10: 0 | AP10: 0 | AQ10: 0 | AR10: 0 | AS10: 0 | AT10: 0 | AU10: 0 | AW10: Feedstock | AX10: 0 | AY10: 0 | AZ10: 29.234538 | BA10: 19.801248 | BB10: 39.003975 | BC10: 33.997645 | BD10: 118.1079 | BE10: 0 | BF10: 0 | BG10: 240.14531 | BH10: 0 | BJ10: Agricultural Chemicals | BK10: ICA | BL10: Feedstock | BM10: FEED | BN10: =BK10&BM10 -> ICAFEED | BO10: =IF(ISERROR(GETPIVOTDATA("Sum of "&BO$1&" (Out)",$AW$6,"Sub-Sector",$BJ10,"End-Use",$BL10)),0,GETPIVOTDATA("Sum of "&BO$1&" (Out)",$AW$6,"Sub-Sector",$BJ10,"End-Use",$BL10)) -> 0 | BP10: =IF(ISERROR(GETPIVOTDATA("Sum of "&BP$1&" (Out)",$AW$6,"Sub-Sector",$BJ10,"End-Use",$BL10)),0,GETPIVOTDATA("Sum of "&BP$1&" (Out)",$AW$6,"Sub-Sector",$BJ10,"End-Use",$BL10)) -> 0 | BQ10: =IF(ISERROR(GETPIVOTDATA("Sum of "&BQ$1&" (Out)",$AW$6,"Sub-Sector",$BJ10,"End-Use",$BL10)),0,GETPIVOTDATA("Sum of "&BQ$1&" (Out)",$AW$6,"Sub-Sector",$BJ10,"End-Use",$BL10)) -> 29.234538 | BR10: =IF(ISERROR(GETPIVOTDATA("Sum of "&BR$1&" (Out)",$AW$6,"Sub-Sector",$BJ10,"End-Use",$BL10)),0,GETPIVOTDATA("Sum of "&BR$1&" (Out)",$AW$6,"Sub-Sector",$BJ10,"End-Use",$BL10)) -> 19.801248 | BS10: =IF(ISERROR(GETPIVOTDATA("Sum of "&BS$1&" (Out)",$AW$6,"Sub-Sector",$BJ10,"End-Use",$BL10)),0,GETPIVOTDATA("Sum of "&BS$1&" (Out)",$AW$6,"Sub-Sector",$BJ10,"End-Use",$BL10)) -> 39.003975 | BT10: =IF(ISERROR(GETPIVOTDATA("Sum of "&BT$1&" (Out)",$AW$6,"Sub-Sector",$BJ10,"End-Use",$BL10)),0,GETPIVOTDATA("Sum of "&BT$1&" (Out)",$AW$6,"Sub-Sector",$BJ10,"End-Use",$BL10)) -> 33.997645 | BU10: =IF(ISERROR(GETPIVOTDATA("Sum of "&BU$1&" (Out)",$AW$6,"Sub-Sector",$BJ10,"End-Use",$BL10)),0,GETPIVOTDATA("Sum of "&BU$1&" (Out)",$AW$6,"Sub-Sector",$BJ10,"End-Use",$BL10)) -> 118.1079 | BV10: =IF(ISERROR(GETPIVOTDATA("Sum of "&BV$1&" (Out)",$AW$6,"Sub-Sector",$BJ10,"End-Use",$BL10)),0,GETPIVOTDATA("Sum of "&BV$1&" (Out)",$AW$6,"Sub-Sector",$BJ10,"End-Use",$BL10)) -> 0 | BW10: =IF(ISERROR(GETPIVOTDATA("Sum of "&BW$1&" (Out)",$AW$6,"Sub-Sector",$BJ10,"End-Use",$BL10)),0,GETPIVOTDATA("Sum of "&BW$1&" (Out)",$AW$6,"Sub-Sector",$BJ10,"End-Use",$BL10)) -> 0 | BX10: 0 | BY10: 0 | BZ10: =BQ10/BQ15 -> 0.64346828 | CA10: =BR10/BR15 -> 0.49750319 | CB10: =BS10/BS15 -> 0.63118325 | CC10: =BT10/BT15 -> 0.56669899 | CD10: =BU10/BU15 -> 0.60658422 | CE10: =BV10/BV15 -> 0 | CF10: =BW10/BW15 -> 0 | CH10: ICAFEED | CI10: 0 | CJ10: 0 | CK10: 0.64346828 | CL10: 0.49750319 | CM10: 0.63118325 | CN10: 0.56669899 | CO10: 0.60658422 | CP10: 0 | CQ10: 0 | CS10: ICAFA_NGA | CT10: 0 | CU10: 0 | CV10: 0.092681708 | CW10: 0.062775525 | CX10: 0.12691048 | CY10: 0.11062096 | CZ10: 0.38429749 | DA10: 0.010919511 | DB10: 0.0068470304 | DC10: 0.79505271 | DE10: INCOH_PTC | DF10: =LEFT(DE10,5) -> INCOH | DG10: =GETPIVOTDATA("Sum of "&DG$1&" (Out)",$CS$6,"Constraint Identifier",$DE10) -> 0 | DH10: =GETPIVOTDATA("Sum of "&DH$1&" (Out)",$CS$6,"Constraint Identifier",$DE10) -> 5.2645593 | DI10: =GETPIVOTDATA("Sum of "&DI$1&" (Out)",$CS$6,"Constraint Identifier",$DE10) -> 18.831997 | DJ10: =GETPIVOTDATA("Sum of "&DJ$1&" (Out)",$CS$6,"Constraint Identifier",$DE10) -> 12.755359 | DK10: =GETPIVOTDATA("Sum of "&DK$1&" (Out)",$CS$6,"Constraint Identifier",$DE10) -> 3.868041 | DL10: =GETPIVOTDATA("Sum of "&DL$1&" (Out)",$CS$6,"Constraint Identifier",$DE10) -> 3.3715611 | DM10: =GETPIVOTDATA("Sum of "&DM$1&" (Out)",$CS$6,"Constraint Identifier",$DE10) -> 11.712811 | DN10: =GETPIVOTDATA("Sum of "&DN$1&" (Out)",$CS$6,"Constraint Identifier",$DE10) -> 3.8827869 | DO10: =GETPIVOTDATA("Sum of "&DO$1&" (Out)",$CS$6,"Constraint Identifier",$DE10) -> 2.4346842 | DP10: =IF(SUMIF($DF$8:$DF$380,"="&$DF10,DG$8:DG$380)=0,0,DG10/SUMIF($DF$8:$DF$380,"="&$DF10,DG$8:DG$380)) -> 0 | DQ10: =IF(SUMIF($DF$8:$DF$380,"="&$DF10,DH$8:DH$380)=0,0,DH10/SUMIF($DF$8:$DF$380,"="&$DF10,DH$8:DH$380)) -> 0.92241825 | DR10: =IF(SUMIF($DF$8:$DF$380,"="&$DF10,DI$8:DI$380)=0,0,DI10/SUMIF($DF$8:$DF$380,"="&$DF10,DI$8:DI$380)) -> 0.89713322 | DS10: =IF(SUMIF($DF$8:$DF$380,"="&$DF10,DJ$8:DJ$380)=0,0,DJ10/SUMIF($DF$8:$DF$380,"="&$DF10,DJ$8:DJ$380)) -> 0.89713322 | DT10: =IF(SUMIF($DF$8:$DF$380,"="&$DF10,DK$8:DK$380)=0,0,DK10/SUMIF($DF$8:$DF$380,"="&$DF10,DK$8:DK$380)) -> 0.89713322 | DU10: =IF(SUMIF($DF$8:$DF$380,"="&$DF10,DL$8:DL$380)=0,0,DL10/SUMIF($DF$8:$DF$380,"="&$DF10,DL$8:DL$380)) -> 0.89713322 | DV10: =IF(SUMIF($DF$8:$DF$380,"="&$DF10,DM$8:DM$380)=0,0,DM10/SUMIF($DF$8:$DF$380,"="&$DF10,DM$8:DM$380)) -> 0.89713322 | DW10: =IF(SUMIF($DF$8:$DF$380,"="&$DF10,DN$8:DN$380)=0,0,DN10/SUMIF($DF$8:$DF$380,"="&$DF10,DN$8:DN$380)) -> 0.89713322 | DX10: =IF(SUMIF($DF$8:$DF$380,"="&$DF10,DO$8:DO$380)=0,0,DO10/SUMIF($DF$8:$DF$380,"="&$DF10,DO$8:DO$380)) -> 0.89713322 | DZ10: ICAFA_NGA | EA10: 0 | EB10: 0 | EC10: 0.32730185 | ED10: 0.32730185 | EE10: 0.042492686 | EF10: 0.042492686 | EG10: 0.042492686 | EH10: 0.10008141 | EI10: 0.10008141 | EK10: Paper | EL10: 32 | EM10: 23 | EO10: Agricultural Chemicals | EP10: R3 | EQ10: =GETPIVOTDATA("Sum of "&EP10&" (Out)",$AW$6,"Sub-Sector",EO10) -> 45.432757 | ER10: =EQ10/SUM(EQ8:EQ16) -> 0.11140422 | ET10: R2 | EU10: 0 | EW10: Agricultural Chemicals | EX10: ICA | EY10: Steam | EZ10: STM | FA10: =EX10&EZ10 -> ICASTM | FB10: R5 | FC10: =GETPIVOTDATA("Sum of "&FB10&" (Out)",$AW$6,"Sub-Sector",EW10) -> 61.795009 | FD10: =GETPIVOTDATA("Sum of "&FB10&" (Out)",$AW$6,"Sub-Sector",EW10,"End-Use",EY10) -> 0.91713298 | FE10: =GETPIVOTDATA("Sum of "&FB10&" (%)",$CH$6,"End-Use Commodity",FA10) -> 0.014841538 | FF10: 0 | FG10: =FC10-((FD10-FF10)/FE10) -> 0 | FI10: ICO | FJ10: 0 | FK10: 0 | FL10: 0.55714857 | FM10: 0 | FN10: 0.80380033 | FO10: 0.80056719 | FP10: 4.8401814 | FQ10: 0 | FR10: 0 | FS10: 7.0016975
A11: Agricultural Chemicals | B11: Feedstock | C11: Natural Gas | D11: Natural Gas | E11: ICAEFEDNGA | F11: =EndUse(A11,B11,C11,G11) -> #NAME? | G11: TechData_OTR | H11: 1 | I11: 0 | J11: 18.722287 | K11: 39.003975 | S11: 1 | T11: 1 | U11: 1 | V11: 1 | W11: 1 | X11: 1 | Y11: 1 | Z11: 1 | AA11: 1 | AB11: =J11*$H11*S11 -> 18.722287 | AC11: =K11*$H11*T11 -> 39.003975 | AD11: =L11*$H11*U11 -> 0 | AE11: =M11*$H11*V11 -> 0 | AF11: =N11*$H11*W11 -> 0 | AG11: =O11*$H11*X11 -> 0 | AH11: =P11*$H11*Y11 -> 0 | AI11: =Q11*$H11*Z11 -> 0 | AJ11: =R11*$H11*AA11 -> 0 | AK11: =SUM(AB11:AJ11) -> 57.726262 | AL11: 0 | AM11: 0 | AN11: 0 | AO11: 0 | AP11: 0 | AQ11: 0 | AR11: 0 | AS11: 0 | AT11: 0 | AU11: 0 | AW11: Machine Drive | AX11: 0 | AY11: 0 | AZ11: 2.9448659 | BA11: 1.9946277 | BB11: 2.6630554 | BC11: 2.3212407 | BD11: 8.0639956 | BE11: 1.4073734 | BF11: 0.88248721 | BG11: 20.277646 | BH11: 0 | BJ11: Agricultural Chemicals | BK11: ICA | BL11: Machine Drive | BM11: MDR | BN11: =BK11&BM11 -> ICAMDR | BO11: =IF(ISERROR(GETPIVOTDATA("Sum of "&BO$1&" (Out)",$AW$6,"Sub-Sector",$BJ11,"End-Use",$BL11)),0,GETPIVOTDATA("Sum of "&BO$1&" (Out)",$AW$6,"Sub-Sector",$BJ11,"End-Use",$BL11)) -> 0 | BP11: =IF(ISERROR(GETPIVOTDATA("Sum of "&BP$1&" (Out)",$AW$6,"Sub-Sector",$BJ11,"End-Use",$BL11)),0,GETPIVOTDATA("Sum of "&BP$1&" (Out)",$AW$6,"Sub-Sector",$BJ11,"End-Use",$BL11)) -> 0 | BQ11: =IF(ISERROR(GETPIVOTDATA("Sum of "&BQ$1&" (Out)",$AW$6,"Sub-Sector",$BJ11,"End-Use",$BL11)),0,GETPIVOTDATA("Sum of "&BQ$1&" (Out)",$AW$6,"Sub-Sector",$BJ11,"End-Use",$BL11)) -> 2.9448659 | BR11: =IF(ISERROR(GETPIVOTDATA("Sum of "&BR$1&" (Out)",$AW$6,"Sub-Sector",$BJ11,"End-Use",$BL11)),0,GETPIVOTDATA("Sum of "&BR$1&" (Out)",$AW$6,"Sub-Sector",$BJ11,"End-Use",$BL11)) -> 1.9946277 | BS11: =IF(ISERROR(GETPIVOTDATA("Sum of "&BS$1&" (Out)",$AW$6,"Sub-Sector",$BJ11,"End-Use",$BL11)),0,GETPIVOTDATA("Sum of "&BS$1&" (Out)",$AW$6,"Sub-Sector",$BJ11,"End-Use",$BL11)) -> 2.6630554 | BT11: =IF(ISERROR(GETPIVOTDATA("Sum of "&BT$1&" (Out)",$AW$6,"Sub-Sector",$BJ11,"End-Use",$BL11)),0,GETPIVOTDATA("Sum of "&BT$1&" (Out)",$AW$6,"Sub-Sector",$BJ11,"End-Use",$BL11)) -> 2.3212407 | BU11: =IF(ISERROR(GETPIVOTDATA("Sum of "&BU$1&" (Out)",$AW$6,"Sub-Sector",$BJ11,"End-Use",$BL11)),0,GETPIVOTDATA("Sum of "&BU$1&" (Out)",$AW$6,"Sub-Sector",$BJ11,"End-Use",$BL11)) -> 8.0639956 | BV11: =IF(ISERROR(GETPIVOTDATA("Sum of "&BV$1&" (Out)",$AW$6,"Sub-Sector",$BJ11,"End-Use",$BL11)),0,GETPIVOTDATA("Sum of "&BV$1&" (Out)",$AW$6,"Sub-Sector",$BJ11,"End-Use",$BL11)) -> 1.4073734 | BW11: =IF(ISERROR(GETPIVOTDATA("Sum of "&BW$1&" (Out)",$AW$6,"Sub-Sector",$BJ11,"End-Use",$BL11)),0,GETPIVOTDATA("Sum of "&BW$1&" (Out)",$AW$6,"Sub-Sector",$BJ11,"End-Use",$BL11)) -> 0.88248721 | BX11: 0 | BY11: 0 | BZ11: =BQ11/BQ15 -> 0.06481812 | CA11: =BR11/BR15 -> 0.050114702 | CB11: =BS11/BS15 -> 0.043094991 | CC11: =BT11/BT15 -> 0.03869223 | CD11: =BU11/BU15 -> 0.041415455 | CE11: =BV11/BV15 -> 0.33300911 | CF11: =BW11/BW15 -> 0.47407287 | CH11: ICAMDR | CI11: 0 | CJ11: 0 | CK11: 0.06481812 | CL11: 0.050114702 | CM11: 0.043094991 | CN11: 0.03869223 | CO11: 0.041415455 | CP11: 0.33300911 | CQ11: 0.47407287 | CS11: ICAFS_NGA | CT11: 0 | CU11: 0 | CV11: 27.641561 | CW11: 18.722287 | CX11: 39.003975 | CY11: 33.997645 | CZ11: 118.1079 | DA11: 0 | DB11: 0 | DC11: 237.47337 | DE11: IFDOH_DST | DF11: =LEFT(DE11,5) -> IFDOH | DG11: =GETPIVOTDATA("Sum of "&DG$1&" (Out)",$CS$6,"Constraint Identifier",$DE11) -> 0.069456426 | DH11: =GETPIVOTDATA("Sum of "&DH$1&" (Out)",$CS$6,"Constraint Identifier",$DE11) -> 0.19119017 | DI11: =GETPIVOTDATA("Sum of "&DI$1&" (Out)",$CS$6,"Constraint Identifier",$DE11) -> 0.15539433 | DJ11: =GETPIVOTDATA("Sum of "&DJ$1&" (Out)",$CS$6,"Constraint Identifier",$DE11) -> 0.10525227 | DK11: =GETPIVOTDATA("Sum of "&DK$1&" (Out)",$CS$6,"Constraint Identifier",$DE11) -> 0.10639191 | DL11: =GETPIVOTDATA("Sum of "&DL$1&" (Out)",$CS$6,"Constraint Identifier",$DE11) -> 0.092736046 | DM11: =GETPIVOTDATA("Sum of "&DM$1&" (Out)",$CS$6,"Constraint Identifier",$DE11) -> 0.32216524 | DN11: =GETPIVOTDATA("Sum of "&DN$1&" (Out)",$CS$6,"Constraint Identifier",$DE11) -> 0.58738626 | DO11: =GETPIVOTDATA("Sum of "&DO$1&" (Out)",$CS$6,"Constraint Identifier",$DE11) -> 0.36831794 | DP11: =IF(SUMIF($DF$8:$DF$380,"="&$DF11,DG$8:DG$380)=0,0,DG11/SUMIF($DF$8:$DF$380,"="&$DF11,DG$8:DG$380)) -> 0.11882275 | DQ11: =IF(SUMIF($DF$8:$DF$380,"="&$DF11,DH$8:DH$380)=0,0,DH11/SUMIF($DF$8:$DF$380,"="&$DF11,DH$8:DH$380)) -> 0.13148637 | DR11: =IF(SUMIF($DF$8:$DF$380,"="&$DF11,DI$8:DI$380)=0,0,DI11/SUMIF($DF$8:$DF$380,"="&$DF11,DI$8:DI$380)) -> 0.012023188 | DS11: =IF(SUMIF($DF$8:$DF$380,"="&$DF11,DJ$8:DJ$380)=0,0,DJ11/SUMIF($DF$8:$DF$380,"="&$DF11,DJ$8:DJ$380)) -> 0.013751338 | DT11: =IF(SUMIF($DF$8:$DF$380,"="&$DF11,DK$8:DK$380)=0,0,DK11/SUMIF($DF$8:$DF$380,"="&$DF11,DK$8:DK$380)) -> 0.0307272 | DU11: =IF(SUMIF($DF$8:$DF$380,"="&$DF11,DL$8:DL$380)=0,0,DL11/SUMIF($DF$8:$DF$380,"="&$DF11,DL$8:DL$380)) -> 0.037954893 | DV11: =IF(SUMIF($DF$8:$DF$380,"="&$DF11,DM$8:DM$380)=0,0,DM11/SUMIF($DF$8:$DF$380,"="&$DF11,DM$8:DM$380)) -> 0.031419424 | DW11: =IF(SUMIF($DF$8:$DF$380,"="&$DF11,DN$8:DN$380)=0,0,DN11/SUMIF($DF$8:$DF$380,"="&$DF11,DN$8:DN$380)) -> 0.11307213 | DX11: =IF(SUMIF($DF$8:$DF$380,"="&$DF11,DO$8:DO$380)=0,0,DO11/SUMIF($DF$8:$DF$380,"="&$DF11,DO$8:DO$380)) -> 0.14882417 | DZ11: ICAFS_NGA | EA11: 0 | EB11: 0 | EC11: 0.94551045 | ED11: 0.94551045 | EE11: 1 | EF11: 1 | EG11: 1 | EH11: 0 | EI11: 0 | EK11: Chemicals | EL11: 10 | EM11: 36 | EO11: Agricultural Chemicals | EP11: R4 | EQ11: =GETPIVOTDATA("Sum of "&EP11&" (Out)",$AW$6,"Sub-Sector",EO11) -> 39.801248 | ER11: =EQ11/SUM(EQ8:EQ16) -> 0.097595379 | ET11: R3 | EU11: 0.11140422 | EW11: Agricultural Chemicals | EX11: ICA | EY11: Machine Drive | EZ11: MDR | FA11: =EX11&EZ11 -> ICAMDR | FB11: R6 | FC11: =GETPIVOTDATA("Sum of "&FB11&" (Out)",$AW$6,"Sub-Sector",EW11) -> 59.992423 | FD11: =GETPIVOTDATA("Sum of "&FB11&" (Out)",$AW$6,"Sub-Sector",EW11,"End-Use",EY11) -> 2.3212407 | FE11: =GETPIVOTDATA("Sum of "&FB11&" (%)",$CH$6,"End-Use Commodity",FA11) -> 0.03869223 | FF11: 0 | FG11: =FC11-((FD11-FF11)/FE11) -> 0 | FI11: ICP | FJ11: 0 | FK11: 0 | FL11: 0 | FM11: 0 | FN11: 0.025857733 | FO11: 0.026692934 | FP11: 0.025785168 | FQ11: 0 | FR11: 0 | FS11: 0.078335835
A12: Agricultural Chemicals | B12: Feedstock | C12: Petrochemical Feedstock | D12: Petrochemical Feedstock | E12: ICAEFEDPFS | F12: =EndUse(A12,B12,C12,G12) -> #NAME? | G12: TechData_OTR | H12: 1 | I12: 0 | J12: 1.0789611 | K12: 0 | S12: 1 | T12: 1 | U12: 1 | V12: 1 | W12: 1 | X12: 1 | Y12: 1 | Z12: 1 | AA12: 1 | AB12: =J12*$H12*S12 -> 1.0789611 | AC12: =K12*$H12*T12 -> 0 | AD12: =L12*$H12*U12 -> 0 | AE12: =M12*$H12*V12 -> 0 | AF12: =N12*$H12*W12 -> 0 | AG12: =O12*$H12*X12 -> 0 | AH12: =P12*$H12*Y12 -> 0 | AI12: =Q12*$H12*Z12 -> 0 | AJ12: =R12*$H12*AA12 -> 0 | AK12: =SUM(AB12:AJ12) -> 1.0789611 | AL12: 0 | AM12: 0 | AN12: 0 | AO12: 0 | AP12: 0 | AQ12: 0 | AR12: 0 | AS12: 0 | AT12: 0 | AU12: 0 | AW12: Other Heat | AX12: 0 | AY12: 0 | AZ12: 0.36588093 | BA12: 0.24781986 | BB12: 0 | BC12: 0 | BD12: 0 | BE12: 0 | BF12: 0 | BG12: 0.61370079 | BH12: 0 | BJ12: Agricultural Chemicals | BK12: ICA | BL12: Other Heat | BM12: OHT | BN12: =BK12&BM12 -> ICAOHT | BO12: =IF(ISERROR(GETPIVOTDATA("Sum of "&BO$1&" (Out)",$AW$6,"Sub-Sector",$BJ12,"End-Use",$BL12)),0,GETPIVOTDATA("Sum of "&BO$1&" (Out)",$AW$6,"Sub-Sector",$BJ12,"End-Use",$BL12)) -> 0 | BP12: =IF(ISERROR(GETPIVOTDATA("Sum of "&BP$1&" (Out)",$AW$6,"Sub-Sector",$BJ12,"End-Use",$BL12)),0,GETPIVOTDATA("Sum of "&BP$1&" (Out)",$AW$6,"Sub-Sector",$BJ12,"End-Use",$BL12)) -> 0 | BQ12: =IF(ISERROR(GETPIVOTDATA("Sum of "&BQ$1&" (Out)",$AW$6,"Sub-Sector",$BJ12,"End-Use",$BL12)),0,GETPIVOTDATA("Sum of "&BQ$1&" (Out)",$AW$6,"Sub-Sector",$BJ12,"End-Use",$BL12)) -> 0.36588093 | BR12: =IF(ISERROR(GETPIVOTDATA("Sum of "&BR$1&" (Out)",$AW$6,"Sub-Sector",$BJ12,"End-Use",$BL12)),0,GETPIVOTDATA("Sum of "&BR$1&" (Out)",$AW$6,"Sub-Sector",$BJ12,"End-Use",$BL12)) -> 0.24781986 | BS12: =IF(ISERROR(GETPIVOTDATA("Sum of "&BS$1&" (Out)",$AW$6,"Sub-Sector",$BJ12,"End-Use",$BL12)),0,GETPIVOTDATA("Sum of "&BS$1&" (Out)",$AW$6,"Sub-Sector",$BJ12,"End-Use",$BL12)) -> 0 | BT12: =IF(ISERROR(GETPIVOTDATA("Sum of "&BT$1&" (Out)",$AW$6,"Sub-Sector",$BJ12,"End-Use",$BL12)),0,GETPIVOTDATA("Sum of "&BT$1&" (Out)",$AW$6,"Sub-Sector",$BJ12,"End-Use",$BL12)) -> 0 | BU12: =IF(ISERROR(GETPIVOTDATA("Sum of "&BU$1&" (Out)",$AW$6,"Sub-Sector",$BJ12,"End-Use",$BL12)),0,GETPIVOTDATA("Sum of "&BU$1&" (Out)",$AW$6,"Sub-Sector",$BJ12,"End-Use",$BL12)) -> 0 | BV12: =IF(ISERROR(GETPIVOTDATA("Sum of "&BV$1&" (Out)",$AW$6,"Sub-Sector",$BJ12,"End-Use",$BL12)),0,GETPIVOTDATA("Sum of "&BV$1&" (Out)",$AW$6,"Sub-Sector",$BJ12,"End-Use",$BL12)) -> 0 | BW12: =IF(ISERROR(GETPIVOTDATA("Sum of "&BW$1&" (Out)",$AW$6,"Sub-Sector",$BJ12,"End-Use",$BL12)),0,GETPIVOTDATA("Sum of "&BW$1&" (Out)",$AW$6,"Sub-Sector",$BJ12,"End-Use",$BL12)) -> 0 | BX12: 0 | BY12: 0 | BZ12: =BQ12/BQ15 -> 0.0080532408 | CA12: =BR12/BR15 -> 0.0062264343 | CB12: =BS12/BS15 -> 0 | CC12: =BT12/BT15 -> 0 | CD12: =BU12/BU15 -> 0 | CE12: =BV12/BV15 -> 0 | CF12: =BW12/BW15 -> 0 | CH12: ICAOHT | CI12: 0 | CJ12: 0 | CK12: 0.0080532408 | CL12: 0.0062264343 | CM12: 0 | CN12: 0 | CO12: 0 | CP12: 0 | CQ12: 0 | CS12: ICAFS_PFS | CT12: 0 | CU12: 0 | CV12: 1.5929769 | CW12: 1.0789611 | CX12: 0 | CY12: 0 | CZ12: 0 | DA12: 0 | DB12: 0 | DC12: 2.671938 | DE12: IFDOH_ELC | DF12: =LEFT(DE12,5) -> IFDOH | DG12: =GETPIVOTDATA("Sum of "&DG$1&" (Out)",$CS$6,"Constraint Identifier",$DE12) -> 0.13106152 | DH12: =GETPIVOTDATA("Sum of "&DH$1&" (Out)",$CS$6,"Constraint Identifier",$DE12) -> 0.36076827 | DI12: =GETPIVOTDATA("Sum of "&DI$1&" (Out)",$CS$6,"Constraint Identifier",$DE12) -> 1.3805913 | DJ12: =GETPIVOTDATA("Sum of "&DJ$1&" (Out)",$CS$6,"Constraint Identifier",$DE12) -> 0.93510732 | DK12: =GETPIVOTDATA("Sum of "&DK$1&" (Out)",$CS$6,"Constraint Identifier",$DE12) -> 0.33041308 | DL12: =GETPIVOTDATA("Sum of "&DL$1&" (Out)",$CS$6,"Constraint Identifier",$DE12) -> 0.28800313 | DM12: =GETPIVOTDATA("Sum of "&DM$1&" (Out)",$CS$6,"Constraint Identifier",$DE12) -> 1.0005235 | DN12: =GETPIVOTDATA("Sum of "&DN$1&" (Out)",$CS$6,"Constraint Identifier",$DE12) -> 0.51640179 | DO12: =GETPIVOTDATA("Sum of "&DO$1&" (Out)",$CS$6,"Constraint Identifier",$DE12) -> 0.32380744 | DP12: =IF(SUMIF($DF$8:$DF$380,"="&$DF12,DG$8:DG$380)=0,0,DG12/SUMIF($DF$8:$DF$380,"="&$DF12,DG$8:DG$380)) -> 0.22421382 | DQ12: =IF(SUMIF($DF$8:$DF$380,"="&$DF12,DH$8:DH$380)=0,0,DH12/SUMIF($DF$8:$DF$380,"="&$DF12,DH$8:DH$380)) -> 0.24810957 | DR12: =IF(SUMIF($DF$8:$DF$380,"="&$DF12,DI$8:DI$380)=0,0,DI12/SUMIF($DF$8:$DF$380,"="&$DF12,DI$8:DI$380)) -> 0.10681927 | DS12: =IF(SUMIF($DF$8:$DF$380,"="&$DF12,DJ$8:DJ$380)=0,0,DJ12/SUMIF($DF$8:$DF$380,"="&$DF12,DJ$8:DJ$380)) -> 0.12217292 | DT12: =IF(SUMIF($DF$8:$DF$380,"="&$DF12,DK$8:DK$380)=0,0,DK12/SUMIF($DF$8:$DF$380,"="&$DF12,DK$8:DK$380)) -> 0.095427076 | DU12: =IF(SUMIF($DF$8:$DF$380,"="&$DF12,DL$8:DL$380)=0,0,DL12/SUMIF($DF$8:$DF$380,"="&$DF12,DL$8:DL$380)) -> 0.11787356 | DV12: =IF(SUMIF($DF$8:$DF$380,"="&$DF12,DM$8:DM$380)=0,0,DM12/SUMIF($DF$8:$DF$380,"="&$DF12,DM$8:DM$380)) -> 0.097576861 | DW12: =IF(SUMIF($DF$8:$DF$380,"="&$DF12,DN$8:DN$380)=0,0,DN12/SUMIF($DF$8:$DF$380,"="&$DF12,DN$8:DN$380)) -> 0.099407587 | DX12: =IF(SUMIF($DF$8:$DF$380,"="&$DF12,DO$8:DO$380)=0,0,DO12/SUMIF($DF$8:$DF$380,"="&$DF12,DO$8:DO$380)) -> 0.13083906 | DZ12: ICAFS_PFS | EA12: 0 | EB12: 0 | EC12: 0.054489552 | ED12: 0.054489552 | EE12: 0 | EF12: 0 | EG12: 0 | EH12: 0 | EI12: 0 | EK12: Nonmetallic Mineral Products | EL12: 29 | EM12: 51 | EO12: Agricultural Chemicals | EP12: R5 | EQ12: =GETPIVOTDATA("Sum of "&EP12&" (Out)",$AW$6,"Sub-Sector",EO12) -> 61.795009 | ER12: =EQ12/SUM(EQ8:EQ16) -> 0.15152558 | ET12: R4 | EU12: 0.097595379 | EW12: Agricultural Chemicals | EX12: ICA | EY12: Facilities | EZ12: FAC | FA12: =EX12&EZ12 -> ICAFAC | FB12: R7 | FC12: =GETPIVOTDATA("Sum of "&FB12&" (Out)",$AW$6,"Sub-Sector",EW12) -> 194.70981 | FD12: =GETPIVOTDATA("Sum of "&FB12&" (Out)",$AW$6,"Sub-Sector",EW12,"End-Use",EY12) -> 9.0438504 | FE12: =GETPIVOTDATA("Sum of "&FB12&" (%)",$CH$6,"End-Use Commodity",FA12) -> 0.046447841 | FF12: 0.02 | FG12: =FC12-((FD12-FF12)/FE12) -> 0.43059052 | FI12: ICT | FJ12: 0 | FK12: 0.062709394 | FL12: 0 | FM12: 0 | FN12: 0.10979158 | FO12: 0.06234656 | FP12: 0.059490288 | FQ12: 0 | FR12: 0 | FS12: 0.29433782
A13: Agricultural Chemicals | B13: Machine Drive | C13: Electricity | D13: Electricity | E13: ICAEMDRELC | F13: =EndUse(A13,B13,C13,G13) -> #NAME? | G13: TechData_OTR | H13: 1 | I13: 0 | J13: 1.8063011 | K13: 2.282324 | S13: 1 | T13: 1 | U13: 1 | V13: 1 | W13: 1 | X13: 1 | Y13: 1 | Z13: 1 | AA13: 1 | AB13: =J13*$H13*S13 -> 1.8063011 | AC13: =K13*$H13*T13 -> 2.282324 | AD13: =L13*$H13*U13 -> 0 | AE13: =M13*$H13*V13 -> 0 | AF13: =N13*$H13*W13 -> 0 | AG13: =O13*$H13*X13 -> 0 | AH13: =P13*$H13*Y13 -> 0 | AI13: =Q13*$H13*Z13 -> 0 | AJ13: =R13*$H13*AA13 -> 0 | AK13: =SUM(AB13:AJ13) -> 4.0886251 | AL13: 0 | AM13: 0 | AN13: 0 | AO13: 0 | AP13: 0 | AQ13: 0 | AR13: 0 | AS13: 0 | AT13: 0 | AU13: 0 | AW13: Process Heat | AX13: 0 | AY13: 0 | AZ13: 11.683019 | BA13: 7.9131866 | BB13: 16.224203 | BC13: 14.141756 | BD13: 49.128495 | BE13: 1.4522061 | BF13: 0.91059935 | BG13: 101.45347 | BH13: 0 | BJ13: Agricultural Chemicals | BK13: ICA | BL13: Process Heat | BM13: PRH | BN13: =BK13&BM13 -> ICAPRH | BO13: =IF(ISERROR(GETPIVOTDATA("Sum of "&BO$1&" (Out)",$AW$6,"Sub-Sector",$BJ13,"End-Use",$BL13)),0,GETPIVOTDATA("Sum of "&BO$1&" (Out)",$AW$6,"Sub-Sector",$BJ13,"End-Use",$BL13)) -> 0 | BP13: =IF(ISERROR(GETPIVOTDATA("Sum of "&BP$1&" (Out)",$AW$6,"Sub-Sector",$BJ13,"End-Use",$BL13)),0,GETPIVOTDATA("Sum of "&BP$1&" (Out)",$AW$6,"Sub-Sector",$BJ13,"End-Use",$BL13)) -> 0 | BQ13: =IF(ISERROR(GETPIVOTDATA("Sum of "&BQ$1&" (Out)",$AW$6,"Sub-Sector",$BJ13,"End-Use",$BL13)),0,GETPIVOTDATA("Sum of "&BQ$1&" (Out)",$AW$6,"Sub-Sector",$BJ13,"End-Use",$BL13)) -> 11.683019 | BR13: =IF(ISERROR(GETPIVOTDATA("Sum of "&BR$1&" (Out)",$AW$6,"Sub-Sector",$BJ13,"End-Use",$BL13)),0,GETPIVOTDATA("Sum of "&BR$1&" (Out)",$AW$6,"Sub-Sector",$BJ13,"End-Use",$BL13)) -> 7.9131866 | BS13: =IF(ISERROR(GETPIVOTDATA("Sum of "&BS$1&" (Out)",$AW$6,"Sub-Sector",$BJ13,"End-Use",$BL13)),0,GETPIVOTDATA("Sum of "&BS$1&" (Out)",$AW$6,"Sub-Sector",$BJ13,"End-Use",$BL13)) -> 16.224203 | BT13: =IF(ISERROR(GETPIVOTDATA("Sum of "&BT$1&" (Out)",$AW$6,"Sub-Sector",$BJ13,"End-Use",$BL13)),0,GETPIVOTDATA("Sum of "&BT$1&" (Out)",$AW$6,"Sub-Sector",$BJ13,"End-Use",$BL13)) -> 14.141756 | BU13: =IF(ISERROR(GETPIVOTDATA("Sum of "&BU$1&" (Out)",$AW$6,"Sub-Sector",$BJ13,"End-Use",$BL13)),0,GETPIVOTDATA("Sum of "&BU$1&" (Out)",$AW$6,"Sub-Sector",$BJ13,"End-Use",$BL13)) -> 49.128495 | BV13: =IF(ISERROR(GETPIVOTDATA("Sum of "&BV$1&" (Out)",$AW$6,"Sub-Sector",$BJ13,"End-Use",$BL13)),0,GETPIVOTDATA("Sum of "&BV$1&" (Out)",$AW$6,"Sub-Sector",$BJ13,"End-Use",$BL13)) -> 1.4522061 | BW13: =IF(ISERROR(GETPIVOTDATA("Sum of "&BW$1&" (Out)",$AW$6,"Sub-Sector",$BJ13,"End-Use",$BL13)),0,GETPIVOTDATA("Sum of "&BW$1&" (Out)",$AW$6,"Sub-Sector",$BJ13,"End-Use",$BL13)) -> 0.91059935 | BX13: 0 | BY13: 0 | BZ13: =BQ13/BQ15 -> 0.25714968 | CA13: =BR13/BR15 -> 0.19881755 | CB13: =BS13/BS15 -> 0.26254876 | CC13: =BT13/BT15 -> 0.23572571 | CD13: =BU13/BU15 -> 0.25231648 | CE13: =BV13/BV15 -> 0.34361731 | CF13: =BW13/BW15 -> 0.48917474 | CH13: ICAPRH | CI13: 0 | CJ13: 0 | CK13: 0.25714968 | CL13: 0.19881755 | CM13: 0.26254876 | CN13: 0.23572571 | CO13: 0.25231648 | CP13: 0.34361731 | CQ13: 0.48917474 | CS13: ICAMD_ELC | CT13: 0 | CU13: 0 | CV13: 2.6668208 | CW13: 1.8063011 | CX13: 2.282324 | CY13: 1.9893778 | CZ13: 6.9111031 | DA13: 1.3746148 | DB13: 0.86194612 | DC13: 17.892488 | DE13: IFDOH_NGA | DF13: =LEFT(DE13,5) -> IFDOH | DG13: =GETPIVOTDATA("Sum of "&DG$1&" (Out)",$CS$6,"Constraint Identifier",$DE13) -> 0.22391973 | DH13: =GETPIVOTDATA("Sum of "&DH$1&" (Out)",$CS$6,"Constraint Identifier",$DE13) -> 0.61637567 | DI13: =GETPIVOTDATA("Sum of "&DI$1&" (Out)",$CS$6,"Constraint Identifier",$DE13) -> 2.2454365 | DJ13: =GETPIVOTDATA("Sum of "&DJ$1&" (Out)",$CS$6,"Constraint Identifier",$DE13) -> 1.5208875 | DK13: =GETPIVOTDATA("Sum of "&DK$1&" (Out)",$CS$6,"Constraint Identifier",$DE13) -> 0.4501817 | DL13: =GETPIVOTDATA("Sum of "&DL$1&" (Out)",$CS$6,"Constraint Identifier",$DE13) -> 0.39239893 | DM13: =GETPIVOTDATA("Sum of "&DM$1&" (Out)",$CS$6,"Constraint Identifier",$DE13) -> 1.3631948 | DN13: =GETPIVOTDATA("Sum of "&DN$1&" (Out)",$CS$6,"Constraint Identifier",$DE13) -> 1.1620232 | DO13: =GETPIVOTDATA("Sum of "&DO$1&" (Out)",$CS$6,"Constraint Identifier",$DE13) -> 0.72864146 | DP13: =IF(SUMIF($DF$8:$DF$380,"="&$DF13,DG$8:DG$380)=0,0,DG13/SUMIF($DF$8:$DF$380,"="&$DF13,DG$8:DG$380)) -> 0.38307123 | DQ13: =IF(SUMIF($DF$8:$DF$380,"="&$DF13,DH$8:DH$380)=0,0,DH13/SUMIF($DF$8:$DF$380,"="&$DF13,DH$8:DH$380)) -> 0.42389731 | DR13: =IF(SUMIF($DF$8:$DF$380,"="&$DF13,DI$8:DI$380)=0,0,DI13/SUMIF($DF$8:$DF$380,"="&$DF13,DI$8:DI$380)) -> 0.17373417 | DS13: =IF(SUMIF($DF$8:$DF$380,"="&$DF13,DJ$8:DJ$380)=0,0,DJ13/SUMIF($DF$8:$DF$380,"="&$DF13,DJ$8:DJ$380)) -> 0.19870582 | DT13: =IF(SUMIF($DF$8:$DF$380,"="&$DF13,DK$8:DK$380)=0,0,DK13/SUMIF($DF$8:$DF$380,"="&$DF13,DK$8:DK$380)) -> 0.13001762 | DU13: =IF(SUMIF($DF$8:$DF$380,"="&$DF13,DL$8:DL$380)=0,0,DL13/SUMIF($DF$8:$DF$380,"="&$DF13,DL$8:DL$380)) -> 0.16060054 | DV13: =IF(SUMIF($DF$8:$DF$380,"="&$DF13,DM$8:DM$380)=0,0,DM13/SUMIF($DF$8:$DF$380,"="&$DF13,DM$8:DM$380)) -> 0.13294667 | DW13: =IF(SUMIF($DF$8:$DF$380,"="&$DF13,DN$8:DN$380)=0,0,DN13/SUMIF($DF$8:$DF$380,"="&$DF13,DN$8:DN$380)) -> 0.22369001 | DX13: =IF(SUMIF($DF$8:$DF$380,"="&$DF13,DO$8:DO$380)=0,0,DO13/SUMIF($DF$8:$DF$380,"="&$DF13,DO$8:DO$380)) -> 0.29441808 | DZ13: ICAMD_ELC | EA13: 0 | EB13: 0 | EC13: 0.9055831 | ED13: 0.9055831 | EE13: 0.8570321 | EF13: 0.8570321 | EG13: 0.8570321 | EH13: 0.97672364 | EI13: 0.97672364 | EK13: Primary Metals | EL13: 12 | EM13: 3 | EO13: Agricultural Chemicals | EP13: R6 | EQ13: =GETPIVOTDATA("Sum of "&EP13&" (Out)",$AW$6,"Sub-Sector",EO13) -> 59.992423 | ER13: =EQ13/SUM(EQ8:EQ16) -> 0.14710552 | ET13: R5 | EU13: 0.15152558 | EW13: Agricultural Chemicals | EX13: ICA | EY13: Facilities | EZ13: FAC | FA13: =EX13&EZ13 -> ICAFAC | FB13: R8 | FC13: =GETPIVOTDATA("Sum of "&FB13&" (Out)",$AW$6,"Sub-Sector",EW13) -> 4.2262309 | FD13: =GETPIVOTDATA("Sum of "&FB13&" (Out)",$AW$6,"Sub-Sector",EW13,"End-Use",EY13) -> 0.10910629 | FE13: =GETPIVOTDATA("Sum of "&FB13&" (%)",$CH$6,"End-Use Commodity",FA13) -> 0.025816452 | FF13: 0 | FG13: =FC13-((FD13-FF13)/FE13) -> 0 | FI13: IFD | FJ13: 0 | FK13: 0 | FL13: 0.40226525 | FM13: 0.65868011 | FN13: 0 | FO13: 0 | FP13: 0 | FQ13: 0 | FR13: 0 | FS13: 1.0609454
A14: Agricultural Chemicals | B14: Machine Drive | C14: Natural Gas | D14: Natural Gas | E14: ICAEMDRNGA | F14: =EndUse(A14,B14,C14,G14) -> #NAME? | G14: TechData_OTR | H14: 1 | I14: 0 | J14: 0.18832657 | K14: 0.38073143 | S14: 1 | T14: 1 | U14: 1 | V14: 1 | W14: 1 | X14: 1 | Y14: 1 | Z14: 1 | AA14: 1 | AB14: =J14*$H14*S14 -> 0.18832657 | AC14: =K14*$H14*T14 -> 0.38073143 | AD14: =L14*$H14*U14 -> 0 | AE14: =M14*$H14*V14 -> 0 | AF14: =N14*$H14*W14 -> 0 | AG14: =O14*$H14*X14 -> 0 | AH14: =P14*$H14*Y14 -> 0 | AI14: =Q14*$H14*Z14 -> 0 | AJ14: =R14*$H14*AA14 -> 0 | AK14: =SUM(AB14:AJ14) -> 0.569058 | AL14: 0 | AM14: 0 | AN14: 0 | AO14: 0 | AP14: 0 | AQ14: 0 | AR14: 0 | AS14: 0 | AT14: 0 | AU14: 0 | AW14: Steam | AX14: 0 | AY14: 0 | AZ14: 0.92128435 | BA14: 9.6525691 | BB14: 0.91713298 | BC14: 6.9284866 | BD14: 10.365573 | BE14: 1.2575452 | BF14: 0 | BG14: 30.042591 | BH14: 1.823728 | BJ14: Agricultural Chemicals | BK14: ICA | BL14: Steam | BM14: STM | BN14: =BK14&BM14 -> ICASTM | BO14: =IF(ISERROR(GETPIVOTDATA("Sum of "&BO$1&" (Out)",$AW$6,"Sub-Sector",$BJ14,"End-Use",$BL14)),0,GETPIVOTDATA("Sum of "&BO$1&" (Out)",$AW$6,"Sub-Sector",$BJ14,"End-Use",$BL14)) -> 0 | BP14: =IF(ISERROR(GETPIVOTDATA("Sum of "&BP$1&" (Out)",$AW$6,"Sub-Sector",$BJ14,"End-Use",$BL14)),0,GETPIVOTDATA("Sum of "&BP$1&" (Out)",$AW$6,"Sub-Sector",$BJ14,"End-Use",$BL14)) -> 0 | BQ14: =IF(ISERROR(GETPIVOTDATA("Sum of "&BQ$1&" (Out)",$AW$6,"Sub-Sector",$BJ14,"End-Use",$BL14)),0,GETPIVOTDATA("Sum of "&BQ$1&" (Out)",$AW$6,"Sub-Sector",$BJ14,"End-Use",$BL14)) -> 0.92128435 | BR14: =IF(ISERROR(GETPIVOTDATA("Sum of "&BR$1&" (Out)",$AW$6,"Sub-Sector",$BJ14,"End-Use",$BL14)),0,GETPIVOTDATA("Sum of "&BR$1&" (Out)",$AW$6,"Sub-Sector",$BJ14,"End-Use",$BL14)) -> 9.6525691 | BS14: =IF(ISERROR(GETPIVOTDATA("Sum of "&BS$1&" (Out)",$AW$6,"Sub-Sector",$BJ14,"End-Use",$BL14)),0,GETPIVOTDATA("Sum of "&BS$1&" (Out)",$AW$6,"Sub-Sector",$BJ14,"End-Use",$BL14)) -> 0.91713298 | BT14: =IF(ISERROR(GETPIVOTDATA("Sum of "&BT$1&" (Out)",$AW$6,"Sub-Sector",$BJ14,"End-Use",$BL14)),0,GETPIVOTDATA("Sum of "&BT$1&" (Out)",$AW$6,"Sub-Sector",$BJ14,"End-Use",$BL14)) -> 6.9284866 | BU14: =IF(ISERROR(GETPIVOTDATA("Sum of "&BU$1&" (Out)",$AW$6,"Sub-Sector",$BJ14,"End-Use",$BL14)),0,GETPIVOTDATA("Sum of "&BU$1&" (Out)",$AW$6,"Sub-Sector",$BJ14,"End-Use",$BL14)) -> 10.365573 | BV14: =IF(ISERROR(GETPIVOTDATA("Sum of "&BV$1&" (Out)",$AW$6,"Sub-Sector",$BJ14,"End-Use",$BL14)),0,GETPIVOTDATA("Sum of "&BV$1&" (Out)",$AW$6,"Sub-Sector",$BJ14,"End-Use",$BL14)) -> 1.2575452 | BW14: =IF(ISERROR(GETPIVOTDATA("Sum of "&BW$1&" (Out)",$AW$6,"Sub-Sector",$BJ14,"End-Use",$BL14)),0,GETPIVOTDATA("Sum of "&BW$1&" (Out)",$AW$6,"Sub-Sector",$BJ14,"End-Use",$BL14)) -> 0 | BX14: 0 | BY14: 0 | BZ14: =BQ14/BQ15 -> 0.020277976 | CA14: =BR14/BR15 -> 0.24251926 | CB14: =BS14/BS15 -> 0.014841538 | CC14: =BT14/BT15 -> 0.11548936 | CD14: =BU14/BU15 -> 0.053236008 | CE14: =BV14/BV15 -> 0.29755713 | CF14: =BW14/BW15 -> 0 | CH14: ICASTM | CI14: 0 | CJ14: 0 | CK14: 0.020277976 | CL14: 0.24251926 | CM14: 0.014841538 | CN14: 0.11548936 | CO14: 0.053236008 | CP14: 0.29755713 | CQ14: 0 | CS14: ICAMD_NGA | CT14: 0 | CU14: 0 | CV14: 0.27804513 | CW14: 0.18832657 | CX14: 0.38073143 | CY14: 0.33186289 | CZ14: 1.1528925 | DA14: 0.032758532 | DB14: 0.020541091 | DC14: 2.3851581 | DE14: IFDOH_CHP | DF14: =LEFT(DE14,5) -> IFDOH | DG14: =GETPIVOTDATA("Sum of "&DG$1&" (Out)",$CS$6,"Constraint Identifier",$DE14) -> 0.0020921173 | DH14: =GETPIVOTDATA("Sum of "&DH$1&" (Out)",$CS$6,"Constraint Identifier",$DE14) -> 0.20752189 | DI14: =GETPIVOTDATA("Sum of "&DI$1&" (Out)",$CS$6,"Constraint Identifier",$DE14) -> 4.3775166 | DJ14: =GETPIVOTDATA("Sum of "&DJ$1&" (Out)",$CS$6,"Constraint Identifier",$DE14) -> 4.552543 | DK14: =GETPIVOTDATA("Sum of "&DK$1&" (Out)",$CS$6,"Constraint Identifier",$DE14) -> 0.88852272 | DL14: =GETPIVOTDATA("Sum of "&DL$1&" (Out)",$CS$6,"Constraint Identifier",$DE14) -> 1.5967659 | DM14: =GETPIVOTDATA("Sum of "&DM$1&" (Out)",$CS$6,"Constraint Identifier",$DE14) -> 7.3899107 | DN14: =GETPIVOTDATA("Sum of "&DN$1&" (Out)",$CS$6,"Constraint Identifier",$DE14) -> 0.13993091 | DO14: =GETPIVOTDATA("Sum of "&DO$1&" (Out)",$CS$6,"Constraint Identifier",$DE14) -> 1.0130085 | DP14: =IF(SUMIF($DF$8:$DF$380,"="&$DF14,DG$8:DG$380)=0,0,DG14/SUMIF($DF$8:$DF$380,"="&$DF14,DG$8:DG$380)) -> 0.0035790948 | DQ14: =IF(SUMIF($DF$8:$DF$380,"="&$DF14,DH$8:DH$380)=0,0,DH14/SUMIF($DF$8:$DF$380,"="&$DF14,DH$8:DH$380)) -> 0.14271811 | DR14: =IF(SUMIF($DF$8:$DF$380,"="&$DF14,DI$8:DI$380)=0,0,DI14/SUMIF($DF$8:$DF$380,"="&$DF14,DI$8:DI$380)) -> 0.33869772 | DS14: =IF(SUMIF($DF$8:$DF$380,"="&$DF14,DJ$8:DJ$380)=0,0,DJ14/SUMIF($DF$8:$DF$380,"="&$DF14,DJ$8:DJ$380)) -> 0.59479532 | DT14: =IF(SUMIF($DF$8:$DF$380,"="&$DF14,DK$8:DK$380)=0,0,DK14/SUMIF($DF$8:$DF$380,"="&$DF14,DK$8:DK$380)) -> 0.25661552 | DU14: =IF(SUMIF($DF$8:$DF$380,"="&$DF14,DL$8:DL$380)=0,0,DL14/SUMIF($DF$8:$DF$380,"="&$DF14,DL$8:DL$380)) -> 0.65352235 | DV14: =IF(SUMIF($DF$8:$DF$380,"="&$DF14,DM$8:DM$380)=0,0,DM14/SUMIF($DF$8:$DF$380,"="&$DF14,DM$8:DM$380)) -> 0.72070697 | DW14: =IF(SUMIF($DF$8:$DF$380,"="&$DF14,DN$8:DN$380)=0,0,DN14/SUMIF($DF$8:$DF$380,"="&$DF14,DN$8:DN$380)) -> 0.026936767 | DX14: =IF(SUMIF($DF$8:$DF$380,"="&$DF14,DO$8:DO$380)=0,0,DO14/SUMIF($DF$8:$DF$380,"="&$DF14,DO$8:DO$380)) -> 0.40932067 | DZ14: ICAMD_NGA | EA14: 0 | EB14: 0 | EC14: 0.094416905 | ED14: 0.094416905 | EE14: 0.1429679 | EF14: 0.1429679 | EG14: 0.1429679 | EH14: 0.023276362 | EI14: 0.023276362 | EK14: Other | EL14: 20 | EM14: 20 | EO14: Agricultural Chemicals | EP14: R7 | EQ14: =GETPIVOTDATA("Sum of "&EP14&" (Out)",$AW$6,"Sub-Sector",EO14) -> 194.70981 | ER14: =EQ14/SUM(EQ8:EQ16) -> 0.47744176 | ET14: R6 | EU14: 0.14710552 | EW14: Agricultural Chemicals | EX14: ICA | EY14: Facilities | EZ14: FAC | FA14: =EX14&EZ14 -> ICAFAC | FB14: R9 | FC14: =GETPIVOTDATA("Sum of "&FB14&" (Out)",$AW$6,"Sub-Sector",EW14) -> 1.8615012 | FD14: =GETPIVOTDATA("Sum of "&FB14&" (Out)",$AW$6,"Sub-Sector",EW14,"End-Use",EY14) -> 0.06841461 | FE14: =GETPIVOTDATA("Sum of "&FB14&" (%)",$CH$6,"End-Use Commodity",FA14) -> 0.036752386 | FF14: 0 | FG14: =FC14-((FD14-FF14)/FE14) -> 0 | FI14: IMA | FJ14: 0 | FK14: 0 | FL14: 0 | FM14: 0 | FN14: 0 | FO14: 0 | FP14: 0.44107409 | FQ14: 0 | FR14: 0 | FS14: 0.44107409
A15: Agricultural Chemicals | B15: Other Heat | C15: Other Petroleum | D15: Other Petroleum | E15: ICAEOHTOTP | F15: =EndUse(A15,B15,C15,G15) -> #NAME? | G15: TechData_OTR | H15: 1 | I15: 0 | J15: 0.24781986 | K15: 0 | S15: 1 | T15: 1 | U15: 1 | V15: 1 | W15: 1 | X15: 1 | Y15: 1 | Z15: 1 | AA15: 1 | AB15: =J15*$H15*S15 -> 0.24781986 | AC15: =K15*$H15*T15 -> 0 | AD15: =L15*$H15*U15 -> 0 | AE15: =M15*$H15*V15 -> 0 | AF15: =N15*$H15*W15 -> 0 | AG15: =O15*$H15*X15 -> 0 | AH15: =P15*$H15*Y15 -> 0 | AI15: =Q15*$H15*Z15 -> 0 | AJ15: =R15*$H15*AA15 -> 0 | AK15: =SUM(AB15:AJ15) -> 0.24781986 | AL15: 0 | AM15: 0 | AN15: 0 | AO15: 0 | AP15: 0 | AQ15: 0 | AR15: 0 | AS15: 0 | AT15: 0 | AU15: 0 | AW15: Cement | AX15: 5.1174965 | AY15: 19.351306 | AZ15: 43.505092 | BA15: 29.467033 | BB15: 18.144209 | BC15: 15.815321 | BD15: 54.942462 | BE15: 25.763156 | BF15: 16.154672 | BG15: 228.26075 | BH15: 2.2933893e-17 | BJ15: Agricultural Chemicals | BK15: ICA | BL15: Total | BO15: =GETPIVOTDATA("Sum of "&BO$1&" (Out)",$AW$6,"Sub-Sector",$BJ15) -> 0 | BP15: =GETPIVOTDATA("Sum of "&BP$1&" (Out)",$AW$6,"Sub-Sector",$BJ15) -> 0 | BQ15: =GETPIVOTDATA("Sum of "&BQ$1&" (Out)",$AW$6,"Sub-Sector",$BJ15) -> 45.432757 | BR15: =GETPIVOTDATA("Sum of "&BR$1&" (Out)",$AW$6,"Sub-Sector",$BJ15) -> 39.801248 | BS15: =GETPIVOTDATA("Sum of "&BS$1&" (Out)",$AW$6,"Sub-Sector",$BJ15) -> 61.795009 | BT15: =GETPIVOTDATA("Sum of "&BT$1&" (Out)",$AW$6,"Sub-Sector",$BJ15) -> 59.992423 | BU15: =GETPIVOTDATA("Sum of "&BU$1&" (Out)",$AW$6,"Sub-Sector",$BJ15) -> 194.70981 | BV15: =GETPIVOTDATA("Sum of "&BV$1&" (Out)",$AW$6,"Sub-Sector",$BJ15) -> 4.2262309 | BW15: =GETPIVOTDATA("Sum of "&BW$1&" (Out)",$AW$6,"Sub-Sector",$BJ15) -> 1.8615012 | CH15: ICIETC | CI15: 0.20343255 | CJ15: 0.21920853 | CK15: 0.2031139 | CL15: 0.2014114 | CM15: 0.11501976 | CN15: 0.13420263 | CO15: 0.11843369 | CP15: 0.1502062 | CQ15: 0.15561138 | CS15: ICAOH_OTP | CT15: 0 | CU15: 0 | CV15: 0.36588093 | CW15: 0.24781986 | CX15: 0 | CY15: 0 | CZ15: 0 | DA15: 0 | DB15: 0 | DC15: 0.61370079 | DE15: IFDOH_BIO | DF15: =LEFT(DE15,5) -> IFDOH | DG15: =GETPIVOTDATA("Sum of "&DG$1&" (Out)",$CS$6,"Constraint Identifier",$DE15) -> 0.12959496 | DH15: =GETPIVOTDATA("Sum of "&DH$1&" (Out)",$CS$6,"Constraint Identifier",$DE15) -> 0 | DI15: =GETPIVOTDATA("Sum of "&DI$1&" (Out)",$CS$6,"Constraint Identifier",$DE15) -> 4.244513 | DJ15: =GETPIVOTDATA("Sum of "&DJ$1&" (Out)",$CS$6,"Constraint Identifier",$DE15) -> 0.1872213 | DK15: =GETPIVOTDATA("Sum of "&DK$1&" (Out)",$CS$6,"Constraint Identifier",$DE15) -> 1.6282068 | DL15: =GETPIVOTDATA("Sum of "&DL$1&" (Out)",$CS$6,"Constraint Identifier",$DE15) -> 0.022208913 | DM15: =GETPIVOTDATA("Sum of "&DM$1&" (Out)",$CS$6,"Constraint Identifier",$DE15) -> 0 | DN15: =GETPIVOTDATA("Sum of "&DN$1&" (Out)",$CS$6,"Constraint Identifier",$DE15) -> 2.7235405 | DO15: =GETPIVOTDATA("Sum of "&DO$1&" (Out)",$CS$6,"Constraint Identifier",$DE15) -> 0 | DP15: =IF(SUMIF($DF$8:$DF$380,"="&$DF15,DG$8:DG$380)=0,0,DG15/SUMIF($DF$8:$DF$380,"="&$DF15,DG$8:DG$380)) -> 0.2217049 | DQ15: =IF(SUMIF($DF$8:$DF$380,"="&$DF15,DH$8:DH$380)=0,0,DH15/SUMIF($DF$8:$DF$380,"="&$DF15,DH$8:DH$380)) -> 0 | DR15: =IF(SUMIF($DF$8:$DF$380,"="&$DF15,DI$8:DI$380)=0,0,DI15/SUMIF($DF$8:$DF$380,"="&$DF15,DI$8:DI$380)) -> 0.32840695 | DS15: =IF(SUMIF($DF$8:$DF$380,"="&$DF15,DJ$8:DJ$380)=0,0,DJ15/SUMIF($DF$8:$DF$380,"="&$DF15,DJ$8:DJ$380)) -> 0.024460693 | DT15: =IF(SUMIF($DF$8:$DF$380,"="&$DF15,DK$8:DK$380)=0,0,DK15/SUMIF($DF$8:$DF$380,"="&$DF15,DK$8:DK$380)) -> 0.47024475 | DU15: =IF(SUMIF($DF$8:$DF$380,"="&$DF15,DL$8:DL$380)=0,0,DL15/SUMIF($DF$8:$DF$380,"="&$DF15,DL$8:DL$380)) -> 0.0090896361 | DV15: =IF(SUMIF($DF$8:$DF$380,"="&$DF15,DM$8:DM$380)=0,0,DM15/SUMIF($DF$8:$DF$380,"="&$DF15,DM$8:DM$380)) -> 0 | DW15: =IF(SUMIF($DF$8:$DF$380,"="&$DF15,DN$8:DN$380)=0,0,DN15/SUMIF($DF$8:$DF$380,"="&$DF15,DN$8:DN$380)) -> 0.52428283 | DX15: =IF(SUMIF($DF$8:$DF$380,"="&$DF15,DO$8:DO$380)=0,0,DO15/SUMIF($DF$8:$DF$380,"="&$DF15,DO$8:DO$380)) -> 0 | DZ15: ICAOH_OTP | EA15: 0 | EB15: 0 | EC15: 1 | ED15: 1 | EE15: 0 | EF15: 0 | EG15: 0 | EH15: 0 | EI15: 0 | EK15: Source: 2007 OPEI Report | EO15: Agricultural Chemicals | EP15: R8 | EQ15: =GETPIVOTDATA("Sum of "&EP15&" (Out)",$AW$6,"Sub-Sector",EO15) -> 4.2262309 | ER15: =EQ15/SUM(EQ8:EQ16) -> 0.010363007 | ET15: R7 | EU15: 0.47744176 | EW15: Cement | EX15: INC | EY15: Other Heat | EZ15: OHT | FA15: =EX15&EZ15 -> INCOHT | FB15: R1 | FC15: =GETPIVOTDATA("Sum of "&FB15&" (Out)",$AW$6,"Sub-Sector",EW15) -> 5.1174965 | FD15: =GETPIVOTDATA("Sum of "&FB15&" (Out)",$AW$6,"Sub-Sector",EW15,"End-Use",EY15) -> 0.16085723 | FE15: =GETPIVOTDATA("Sum of "&FB15&" (%)",$CH$6,"End-Use Commodity",FA15) -> 0.031432797 | FF15: 0 | FG15: =FC15-((FD15-FF15)/FE15) -> 0 | FI15: IML | FJ15: 0 | FK15: 0 | FL15: 0 | FM15: 0 | FN15: 0 | FO15: 0 | FP15: 0 | FQ15: 0 | FR15: 0 | FS15: 0
