Workbook
Name FO2_l_to_gj: Conversions!$C$23
Name FO4_l_to_gj: Conversions!$C$24
Name FO6_l_to_gj: Conversions!$C$25
Name gal_to_liter: Conversions!$C$20
Name GJ_to_PJ: Conversions!$C$18
Name kgs_to_gj: Conversions!$C$26
Name kwh_to_gj: Conversions!$C$21
Name MMBtu_to_PJ: Conversions!$C$14
Name scf_to_gj: Conversions!$C$22
Name trilBtu_to_PJ: Conversions!$C$28
Name var_derate: Tech_Data!$D$3
Name var_derate2: Tech_Data!$E$3
Name var_inflate: Tech_Data!$D$4
Name var_inflate2: Tech_Data!$E$4

Sheet Commodities
B3: ~FI_Comm
B4: Region | C4: Csets | D4: CommName | E4: CommDesc | F4: Unit | G4: LimType | H4: CTSLvl | I4: PeakTS | J4: Ctype
B5: *End Use demand
B6: R2,R3,R4,R5,R6 | C6: DEM | D6: ISH | E6: Industrial Heating | F6: PJ
B7: R2,R3,R4,R5,R6 | C7: DEM | D7: ISC | E7: Industrial Cooling | F7: PJ
B8: R2,R3,R4,R5,R6 | C8: DEM | D8: IWH | E8: Industrial Water Heating | F8: PJ
B9: R2,R3,R4,R5,R6 | C9: DEM | D9: ILT | E9: Industrial Lighting | F9: PJ
B10: R2,R3,R4,R5,R6 | C10: DEM | D10: IOTE | E10: Industrial Process Loads + Other, Electric | F10: PJ
B11: R2,R3,R4,R5,R6 | C11: DEM | D11: IOTF | E11: Industrial Process Loads + Other, Fossil | F11: PJ
B12: * Energy Carriers
B13: R2,R3,R4,R5,R6 | C13: NRG | D13: INDELC | E13: Electricity to Industrial Sector | F13: PJ | H13: DAYNITE | I13: ANNUAL | J13: ELC
B14: R2,R3,R4,R5,R6 | C14: NRG | D14: INDNGA | E14: Natural Gas to Industrial Sector | F14: PJ
B15: R2,R3,R4,R5,R6 | C15: NRG | D15: INDDSL | E15: Diesel to Industrial Sector | F15: PJ
B16: *CHP Energy Carriers
B17: R1,R2,R3,R4,R5,R6 | C17: NRG | D17: INDSTNUC | E17: STM from Industrial NGA Utility-scale CHP | F17: PJ
B18: R1,R2,R3,R4,R5,R6 | C18: NRG | D18: INDSTBUC | E18: STM from Industrial DST Utility-scale CHP | F18: PJ
B19: R2,R3,R4,R5,R6 | C19: NRG | D19: INDSTNB | E19: STM from Industrial NGA Boilers | F19: PJ
B20: R2,R3,R4,R5,R6 | C20: NRG | D20: INDSTNOC | E20: STM from Industrial NGA other CHP | F20: PJ
B21: *Industrial sector energy carriers after emissions accounting
B22: R2,R3,R4,R5,R6 | C22: NRG | D22: INDNGAEA | E22: Natural Gas to Industrial Sector after Emissions Accounting | F22: PJ
B23: R2,R3,R4,R5,R6 | C23: NRG | D23: INDDSLEA | E23: Diesel to Industrial Sector after Emissions Accounting | F23: PJ
B24: *Emissions Commodities
B25: R1,R2,R3,R4,R5,R6 | C25: ENV | D25: CO2 | E25: Carbon dioxide | F25: Mt
B26: R1,R2,R3,R4,R5,R6 | C26: ENV | D26: NOX | E26: Nitrogen oxide | F26: kt
B27: R1,R2,R3,R4,R5,R6 | C27: ENV | D27: PM10 | E27: Particulate matter | F27: kt
B28: R1,R2,R3,R4,R5,R6 | C28: ENV | D28: PM25 | E28: Fine particulate matter | F28: kt
B29: R1,R2,R3,R4,R5,R6 | C29: ENV | D29: VOC | E29: Volatile organic compounds | F29: kt
B30: R1,R2,R3,R4,R5,R6 | C30: ENV | D30: CO | E30: Carbon monoxide | F30: kt
B31: R1,R2,R3,R4,R5,R6 | C31: ENV | D31: CH4 | E31: Methane | F31: kt
B32: R1,R2,R3,R4,R5,R6 | C32: ENV | D32: N2O | E32: N2O | F32: kt
B33: R1,R2,R3,R4,R5,R6 | C33: ENV | D33: BC | E33: Black carbon | F33: kt
B34: R1,R2,R3,R4,R5,R6 | C34: ENV | D34: OC | E34: Organic carbon | F34: kt
B35: R1,R2,R3,R4,R5,R6 | C35: ENV | D35: SO2 | E35: Sulfur dioxide | F35: kt
B36: *IND_DEM_FI_Comm

Sheet Technologies
B2: *IND_DEM_FI_Process
B3: ~FI_Process
B4: Region | C4: Sets | D4: TechName | E4: *TechDesc | F4: Tact | G4: Tcap | H4: PrimaryCG | I4: Vintage | J4: Tslvl
B5: *Emissions Accounting Collectors
B6: R2,R3,R4,R5,R6 | C6: PRE | D6: SEINDNGA | E6: Emissions: NGA to IND | F6: PJ | G6: Pja
B7: R2,R3,R4,R5,R6 | C7: PRE | D7: SEINDDSL | E7: Emissions: DSL to IND | F7: PJ | G7: Pja
B8: R2,R3,R4,R5,R6 | C8: PRE | D8: SCINDELC | E8: Collector: ELC to IND | F8: PJ | G8: Pja
B9: *Energy Transfer
B10: R2,R3,R4,R5,R6 | C10: DMD | D10: ETINDNGA | E10: Energy Transfer: NGA to INDNGA | F10: PJ | G10: Pja
B11: R2,R3,R4,R5,R6 | C11: DMD | D11: ETINDDSL | E11: Energy Transfer: DSL to INDDSL | F11: PJ | G11: Pja
B12: R2,R3,R4,R5,R6 | C12: DMD | D12: ETINDELC | E12: Energy Transfer: ELC to INDELC | F12: PJ | G12: Pja
B13: *Dummy Backstops
B14: R2,R3,R4,R5,R6 | C14: DMD | D14: ZZDMYISH | E14: Industrial Heating - ZZ dummy backstop | F14: PJ | G14: Pja
B15: R2,R3,R4,R5,R6 | C15: DMD | D15: ZZDMYISC | E15: Industrial Cooling - ZZ dummy backstop | F15: PJ | G15: Pja
B16: R2,R3,R4,R5,R6 | C16: DMD | D16: ZZDMYIWH | E16: Industrial Water Heating - ZZ dummy backstop | F16: PJ | G16: Pja
B17: R2,R3,R4,R5,R6 | C17: DMD | D17: ZZDMYILT | E17: Industrial Lighting - ZZ dummy backstop | F17: PJ | G17: Pja
B18: R2,R3,R4,R5,R6 | C18: DMD | D18: ZZDMYIOT | E18: Industrial Process Loads + Other - ZZ dummy backstop | F18: PJ | G18: Pja
B19: *SPACE HEATING
B20: *Commercial Rooftop Air-source Heat Pumps
B21: R2,R3,R4,R5,R6 | C21: DMD | D21: ISHAHPST10 | E21: ISH.ELC.AHP.Ver1.10 | F21: PJ | G21: Pja
B22: *Commercial Ground Source Heat Pumps
B23: R2,R3,R4,R5,R6 | C23: DMD | D23: ISHGHPST10 | E23: ISH.ELC.GHP.Ver1.10 | F23: PJ | G23: Pja
B24: * Natural Gas Heat Pump
B25: R2,R3,R4,R5,R6 | C25: DMD | D25: ISHNHPST10 | E25: ISH.NG.HEATPUMP.ST.10 | F25: PJ | G25: Pja
B26: * Space Heating Commercial Electric Resistance Unit Heaters
B27: R2,R3,R4,R5,R6 | C27: DMD | D27: ISHERUST10 | E27: ISH.ELC.RSU.STANDARD.SMALL.12 | F27: PJ | G27: Pja
B28: R2,R3,R4,R5,R6 | C28: DMD | D28: ISHERUSTL10 | E28: ISH.ELC.RSU.STANDARD.LARGE.12 | F28: PJ | G28: Pja
B29: *Commercial Gas-Fired Furnaces
B30: R2,R3,R4,R5,R6 | C30: DMD | D30: ISHNGFST10 | E30: ISH.NG.FURNACE.Ver1.10 | F30: PJ | G30: Pja
B31: *Commercial Gas-fired Boilers
B32: R2,R3,R4,R5,R6 | C32: DMD | D32: ISHNGBST10 | E32: ISH.NG.BOILER | F32: PJ | G32: Pja
B33: *Commercial Oil-fired Furnaces
B34: R2,R3,R4,R5,R6 | C34: DMD | D34: ISHDSFST10 | E34: ISH.DSL.FURNACE.ST.10 | F34: PJ | G34: Pja
B35: *Commercial Oil-fired Boilers
B36: R2,R3,R4,R5,R6 | C36: DMD | D36: ISHDSBST10 | E36: ISH.DSL.BOILER.BS.10 | F36: PJ | G36: Pja
B37: *UTILITY SCALE CHP - SH
B38: R4 | C38: DMD | D38: ISHNUTIBOI10 | E38: ISH.NG.UTILITY.BOILER | F38: PJ | G38: Pja
B39: R4 | C39: DMD | D39: ISHNUTICHP10 | E39: ISH.NG.UTILITY.CHP | F39: PJ | G39: Pja
B40: R4 | C40: DMD | D40: ISHBUTICHP10 | E40: ISH.DSL.UTILITY.CHP | F40: PJ | G40: Pja
B41: * Space Cooling
...

Sheet CommDemand
B2: *IND_DEM_COM | F2: *Year Match | G2: =_xlfn.NUMBERVALUE(RIGHT(G5,4)) -> 2010 | H2: =_xlfn.NUMBERVALUE(RIGHT(H5,4)) -> 2015 | I2: =_xlfn.NUMBERVALUE(RIGHT(I5,4)) -> 2020 | J2: =_xlfn.NUMBERVALUE(RIGHT(J5,4)) -> 2023 | K2: =_xlfn.NUMBERVALUE(RIGHT(K5,4)) -> 2025 | L2: =_xlfn.NUMBERVALUE(RIGHT(L5,4)) -> 2030 | M2: =_xlfn.NUMBERVALUE(RIGHT(M5,4)) -> 2035 | N2: =_xlfn.NUMBERVALUE(RIGHT(N5,4)) -> 2040 | ... Q2: =_xlfn.NUMBERVALUE(RIGHT(Q5,4)) -> 2055
B3: *Source: DemandCalc | S3: Source: Time Slice File from EPA
G4: ~FI_T
B5: Region | C5: CommName | D5: *Comm Match | E5: *CommDesc | F5: *Units | G5: COM_PROJ~2010 | H5: COM_PROJ~2015 | I5: COM_PROJ~2020 | J5: COM_PROJ~2023 | K5: COM_PROJ~2025 | L5: COM_PROJ~2030 | M5: COM_PROJ~2035 | N5: COM_PROJ~2040 | O5: COM_PROJ~2045 | P5: COM_PROJ~2050 | Q5: COM_PROJ~2055 | R5: *TIME SLICES | S5: COM_FR~IDAM | T5: COM_FR~IDPM | U5: COM_FR~IN | V5: COM_FR~IP | W5: COM_FR~SDAM | X5: COM_FR~SDPM | Y5: COM_FR~SN | Z5: COM_FR~SP | AA5: COM_FR~WDAM | AB5: COM_FR~WDPM | AC5: COM_FR~WN | AD5: COM_FR~WP
B6: R2,R3,R4,R5,R6 | C6: ISH | D6: Space Heating | E6: Industrial Heating | F6: PJ | G6: =IF(G$2<YEAR(TODAY()),SUMIF(DemandPJ_historic[Year],CommDemand!G$2,_xlfn.XLOOKUP(CommDemand!$D6,DemandPJ_historic[#Headers],DemandPJ_historic[])), SUMIF(DemandPJ_projection[Year],CommDemand!G$2,_xlfn.XLOOKUP(CommDemand!$D6,DemandPJ_projection[#Headers],DemandPJ_projection[])))/5 -> 6.0169066 | H6: =IF(H$2<YEAR(TODAY()),SUMIF(DemandPJ_historic[Year],CommDemand!H$2,_xlfn.XLOOKUP(CommDemand!$D6,DemandPJ_historic[#Headers],DemandPJ_historic[])), SUMIF(DemandPJ_projection[Year],CommDemand!H$2,_xlfn.XLOOKUP(CommDemand!$D6,DemandPJ_projection[#Headers],DemandPJ_projection[])))/5 -> 6.761468 | I6: =IF(I$2<YEAR(TODAY()),SUMIF(DemandPJ_historic[Year],CommDemand!I$2,_xlfn.XLOOKUP(CommDemand!$D6,DemandPJ_historic[#Headers],DemandPJ_historic[])), SUMIF(DemandPJ_projection[Year],CommDemand!I$2,_xlfn.XLOOKUP(CommDemand!$D6,DemandPJ_projection[#Headers],DemandPJ_projection[])))/5 -> 6.4221479 | J6: =IF(J$2<YEAR(TODAY()),SUMIF(DemandPJ_historic[Year],CommDemand!J$2,_xlfn.XLOOKUP(CommDemand!$D6,DemandPJ_historic[#Headers],DemandPJ_historic[])), SUMIF(DemandPJ_projection[Year],CommDemand!J$2,_xlfn.XLOOKUP(CommDemand!$D6,DemandPJ_projection[#Headers],DemandPJ_projection[])))/5 -> 4.0412745 | K6: =IF(K$2<YEAR(TODAY()),SUMIF(DemandPJ_historic[Year],CommDemand!K$2,_xlfn.XLOOKUP(CommDemand!$D6,DemandPJ_historic[#Headers],DemandPJ_historic[])), SUMIF(DemandPJ_projection[Year],CommDemand!K$2,_xlfn.XLOOKUP(CommDemand!$D6,DemandPJ_projection[#Headers],DemandPJ_projection[])))/5 -> 3.885552 | L6: =IF(L$2<YEAR(TODAY()),SUMIF(DemandPJ_historic[Year],CommDemand!L$2,_xlfn.XLOOKUP(CommDemand!$D6,DemandPJ_historic[#Headers],DemandPJ_historic[])), SUMIF(DemandPJ_projection[Year],CommDemand!L$2,_xlfn.XLOOKUP(CommDemand!$D6,DemandPJ_projection[#Headers],DemandPJ_projection[])))/5 -> 3.7208848 | M6: =IF(M$2<YEAR(TODAY()),SUMIF(DemandPJ_historic[Year],CommDemand!M$2,_xlfn.XLOOKUP(CommDemand!$D6,DemandPJ_historic[#Headers],DemandPJ_historic[])), SUMIF(DemandPJ_projection[Year],CommDemand!M$2,_xlfn.XLOOKUP(CommDemand!$D6,DemandPJ_projection[#Headers],DemandPJ_projection[])))/5 -> 3.5446772 | N6: =IF(N$2<YEAR(TODAY()),SUMIF(DemandPJ_historic[Year],CommDemand!N$2,_xlfn.XLOOKUP(CommDemand!$D6,DemandPJ_historic[#Headers],DemandPJ_historic[])), SUMIF(DemandPJ_projection[Year],CommDemand!N$2,_xlfn.XLOOKUP(CommDemand!$D6,DemandPJ_projection[#Headers],DemandPJ_projection[])))/5 -> 3.4468983 | ... Q6: =IF(Q$2<YEAR(TODAY()),SUMIF(DemandPJ_historic[Year],CommDemand!Q$2,_xlfn.XLOOKUP(CommDemand!$D6,DemandPJ_historic[#Headers],DemandPJ_historic[])), SUMIF(DemandPJ_projection[Year],CommDemand!Q$2,_xlfn.XLOOKUP(CommDemand!$D6,DemandPJ_projection[#Headers],DemandPJ_projection[])))/5 -> 3.7208848 | R6: INDSHXXX | S6: 0.09583747 | T6: 0.10546803 | U6: 0.12880173 | V6: 0.00422628 | W6: 0.10930424 | X6: 0.11723673 | Y6: 0.10392567 | Z6: 0.0038677 | AA6: 0.09489002 | AB6: 0.11774265 | AC6: 0.11453188 | AD6: 0.0041676
B7: R2,R3,R4,R5,R6 | C7: ISC | D7: Space Cooling | E7: Industrial Cooling | F7: PJ | G7: =IF(G$2<YEAR(TODAY()),SUMIF(DemandPJ_historic[Year],CommDemand!G$2,_xlfn.XLOOKUP(CommDemand!$D7,DemandPJ_historic[#Headers],DemandPJ_historic[])), SUMIF(DemandPJ_projection[Year],CommDemand!G$2,_xlfn.XLOOKUP(CommDemand!$D7,DemandPJ_projection[#Headers],DemandPJ_projection[])))/5 -> 0.82556489 | H7: =IF(H$2<YEAR(TODAY()),SUMIF(DemandPJ_historic[Year],CommDemand!H$2,_xlfn.XLOOKUP(CommDemand!$D7,DemandPJ_historic[#Headers],DemandPJ_historic[])), SUMIF(DemandPJ_projection[Year],CommDemand!H$2,_xlfn.XLOOKUP(CommDemand!$D7,DemandPJ_projection[#Headers],DemandPJ_projection[])))/5 -> 0.83968448 | I7: =IF(I$2<YEAR(TODAY()),SUMIF(DemandPJ_historic[Year],CommDemand!I$2,_xlfn.XLOOKUP(CommDemand!$D7,DemandPJ_historic[#Headers],DemandPJ_historic[])), SUMIF(DemandPJ_projection[Year],CommDemand!I$2,_xlfn.XLOOKUP(CommDemand!$D7,DemandPJ_projection[#Headers],DemandPJ_projection[])))/5 -> 0.6845701 | J7: =IF(J$2<YEAR(TODAY()),SUMIF(DemandPJ_historic[Year],CommDemand!J$2,_xlfn.XLOOKUP(CommDemand!$D7,DemandPJ_historic[#Headers],DemandPJ_historic[])), SUMIF(DemandPJ_projection[Year],CommDemand!J$2,_xlfn.XLOOKUP(CommDemand!$D7,DemandPJ_projection[#Headers],DemandPJ_projection[])))/5 -> 0.74225732 | K7: =IF(K$2<YEAR(TODAY()),SUMIF(DemandPJ_historic[Year],CommDemand!K$2,_xlfn.XLOOKUP(CommDemand!$D7,DemandPJ_historic[#Headers],DemandPJ_historic[])), SUMIF(DemandPJ_projection[Year],CommDemand!K$2,_xlfn.XLOOKUP(CommDemand!$D7,DemandPJ_projection[#Headers],DemandPJ_projection[])))/5 -> 0.72605622 | L7: =IF(L$2<YEAR(TODAY()),SUMIF(DemandPJ_historic[Year],CommDemand!L$2,_xlfn.XLOOKUP(CommDemand!$D7,DemandPJ_historic[#Headers],DemandPJ_historic[])), SUMIF(DemandPJ_projection[Year],CommDemand!L$2,_xlfn.XLOOKUP(CommDemand!$D7,DemandPJ_projection[#Headers],DemandPJ_projection[])))/5 -> 0.73787665 | M7: =IF(M$2<YEAR(TODAY()),SUMIF(DemandPJ_historic[Year],CommDemand!M$2,_xlfn.XLOOKUP(CommDemand!$D7,DemandPJ_historic[#Headers],DemandPJ_historic[])), SUMIF(DemandPJ_projection[Year],CommDemand!M$2,_xlfn.XLOOKUP(CommDemand!$D7,DemandPJ_projection[#Headers],DemandPJ_projection[])))/5 -> 0.75251792 | N7: =IF(N$2<YEAR(TODAY()),SUMIF(DemandPJ_historic[Year],CommDemand!N$2,_xlfn.XLOOKUP(CommDemand!$D7,DemandPJ_historic[#Headers],DemandPJ_historic[])), SUMIF(DemandPJ_projection[Year],CommDemand!N$2,_xlfn.XLOOKUP(CommDemand!$D7,DemandPJ_projection[#Headers],DemandPJ_projection[])))/5 -> 0.77250658 | ... Q7: =IF(Q$2<YEAR(TODAY()),SUMIF(DemandPJ_historic[Year],CommDemand!Q$2,_xlfn.XLOOKUP(CommDemand!$D7,DemandPJ_historic[#Headers],DemandPJ_historic[])), SUMIF(DemandPJ_projection[Year],CommDemand!Q$2,_xlfn.XLOOKUP(CommDemand!$D7,DemandPJ_projection[#Headers],DemandPJ_projection[])))/5 -> 0.73787665 | R7: COMSCN01 | S7: 0.023994 | T7: 0.051143 | U7: 0.024568 | V7: 0.001637 | W7: 0.253683 | X7: 0.430038 | Y7: 0.187488 | Z7: 0.017988 | AA7: 0.001904 | AB7: 0.005149 | AC7: 0.002233 | AD7: 0.000175
B8: R2,R3,R4,R5,R6 | C8: IWH | D8: DHW | E8: Industrial Water Heating | F8: PJ | G8: =IF(G$2<YEAR(TODAY()),SUMIF(DemandPJ_historic[Year],CommDemand!G$2,_xlfn.XLOOKUP(CommDemand!$D8,DemandPJ_historic[#Headers],DemandPJ_historic[])), SUMIF(DemandPJ_projection[Year],CommDemand!G$2,_xlfn.XLOOKUP(CommDemand!$D8,DemandPJ_projection[#Headers],DemandPJ_projection[])))/5 -> 0.56345289 | H8: =IF(H$2<YEAR(TODAY()),SUMIF(DemandPJ_historic[Year],CommDemand!H$2,_xlfn.XLOOKUP(CommDemand!$D8,DemandPJ_historic[#Headers],DemandPJ_historic[])), SUMIF(DemandPJ_projection[Year],CommDemand!H$2,_xlfn.XLOOKUP(CommDemand!$D8,DemandPJ_projection[#Headers],DemandPJ_projection[])))/5 -> 0.5676364 | I8: =IF(I$2<YEAR(TODAY()),SUMIF(DemandPJ_historic[Year],CommDemand!I$2,_xlfn.XLOOKUP(CommDemand!$D8,DemandPJ_historic[#Headers],DemandPJ_historic[])), SUMIF(DemandPJ_projection[Year],CommDemand!I$2,_xlfn.XLOOKUP(CommDemand!$D8,DemandPJ_projection[#Headers],DemandPJ_projection[])))/5 -> 0.46820617 | J8: =IF(J$2<YEAR(TODAY()),SUMIF(DemandPJ_historic[Year],CommDemand!J$2,_xlfn.XLOOKUP(CommDemand!$D8,DemandPJ_historic[#Headers],DemandPJ_historic[])), SUMIF(DemandPJ_projection[Year],CommDemand!J$2,_xlfn.XLOOKUP(CommDemand!$D8,DemandPJ_projection[#Headers],DemandPJ_projection[])))/5 -> 0.38960223 | K8: =IF(K$2<YEAR(TODAY()),SUMIF(DemandPJ_historic[Year],CommDemand!K$2,_xlfn.XLOOKUP(CommDemand!$D8,DemandPJ_historic[#Headers],DemandPJ_historic[])), SUMIF(DemandPJ_projection[Year],CommDemand!K$2,_xlfn.XLOOKUP(CommDemand!$D8,DemandPJ_projection[#Headers],DemandPJ_projection[])))/5 -> 0.36767921 | L8: =IF(L$2<YEAR(TODAY()),SUMIF(DemandPJ_historic[Year],CommDemand!L$2,_xlfn.XLOOKUP(CommDemand!$D8,DemandPJ_historic[#Headers],DemandPJ_historic[])), SUMIF(DemandPJ_projection[Year],CommDemand!L$2,_xlfn.XLOOKUP(CommDemand!$D8,DemandPJ_projection[#Headers],DemandPJ_projection[])))/5 -> 0.35032438 | M8: =IF(M$2<YEAR(TODAY()),SUMIF(DemandPJ_historic[Year],CommDemand!M$2,_xlfn.XLOOKUP(CommDemand!$D8,DemandPJ_historic[#Headers],DemandPJ_historic[])), SUMIF(DemandPJ_projection[Year],CommDemand!M$2,_xlfn.XLOOKUP(CommDemand!$D8,DemandPJ_projection[#Headers],DemandPJ_projection[])))/5 -> 0.33639626 | N8: =IF(N$2<YEAR(TODAY()),SUMIF(DemandPJ_historic[Year],CommDemand!N$2,_xlfn.XLOOKUP(CommDemand!$D8,DemandPJ_historic[#Headers],DemandPJ_historic[])), SUMIF(DemandPJ_projection[Year],CommDemand!N$2,_xlfn.XLOOKUP(CommDemand!$D8,DemandPJ_projection[#Headers],DemandPJ_projection[])))/5 -> 0.32582419 | ... Q8: =IF(Q$2<YEAR(TODAY()),SUMIF(DemandPJ_historic[Year],CommDemand!Q$2,_xlfn.XLOOKUP(CommDemand!$D8,DemandPJ_historic[#Headers],DemandPJ_historic[])), SUMIF(DemandPJ_projection[Year],CommDemand!Q$2,_xlfn.XLOOKUP(CommDemand!$D8,DemandPJ_projection[#Headers],DemandPJ_projection[])))/5 -> 0.35032438 | R8: COMWHXXX | S8: 0.084433 | T8: 0.186457 | U8: 0.071359 | V8: 0.004134 | W8: 0.069288 | X8: 0.146371 | Y8: 0.042195 | Z8: 0.004794 | AA8: 0.096436 | AB8: 0.227751 | AC8: 0.062395 | AD8: 0.004387
B9: R2,R3,R4,R5,R6 | C9: ILT | D9: Lighting | E9: Industrial Lighting | F9: PJ | G9: =IF(G$2<YEAR(TODAY()),SUMIF(DemandPJ_historic[Year],CommDemand!G$2,_xlfn.XLOOKUP(CommDemand!$D9,DemandPJ_historic[#Headers],DemandPJ_historic[])), SUMIF(DemandPJ_projection[Year],CommDemand!G$2,_xlfn.XLOOKUP(CommDemand!$D9,DemandPJ_projection[#Headers],DemandPJ_projection[])))/5 -> 2.5771532 | H9: =IF(H$2<YEAR(TODAY()),SUMIF(DemandPJ_historic[Year],CommDemand!H$2,_xlfn.XLOOKUP(CommDemand!$D9,DemandPJ_historic[#Headers],DemandPJ_historic[])), SUMIF(DemandPJ_projection[Year],CommDemand!H$2,_xlfn.XLOOKUP(CommDemand!$D9,DemandPJ_projection[#Headers],DemandPJ_projection[])))/5 -> 2.6212301 | I9: =IF(I$2<YEAR(TODAY()),SUMIF(DemandPJ_historic[Year],CommDemand!I$2,_xlfn.XLOOKUP(CommDemand!$D9,DemandPJ_historic[#Headers],DemandPJ_historic[])), SUMIF(DemandPJ_projection[Year],CommDemand!I$2,_xlfn.XLOOKUP(CommDemand!$D9,DemandPJ_projection[#Headers],DemandPJ_projection[])))/5 -> 2.137012 | J9: =IF(J$2<YEAR(TODAY()),SUMIF(DemandPJ_historic[Year],CommDemand!J$2,_xlfn.XLOOKUP(CommDemand!$D9,DemandPJ_historic[#Headers],DemandPJ_historic[])), SUMIF(DemandPJ_projection[Year],CommDemand!J$2,_xlfn.XLOOKUP(CommDemand!$D9,DemandPJ_projection[#Headers],DemandPJ_projection[])))/5 -> 2.3170933 | K9: =IF(K$2<YEAR(TODAY()),SUMIF(DemandPJ_historic[Year],CommDemand!K$2,_xlfn.XLOOKUP(CommDemand!$D9,DemandPJ_historic[#Headers],DemandPJ_historic[])), SUMIF(DemandPJ_projection[Year],CommDemand!K$2,_xlfn.XLOOKUP(CommDemand!$D9,DemandPJ_projection[#Headers],DemandPJ_projection[])))/5 -> 2.2665186 | L9: =IF(L$2<YEAR(TODAY()),SUMIF(DemandPJ_historic[Year],CommDemand!L$2,_xlfn.XLOOKUP(CommDemand!$D9,DemandPJ_historic[#Headers],DemandPJ_historic[])), SUMIF(DemandPJ_projection[Year],CommDemand!L$2,_xlfn.XLOOKUP(CommDemand!$D9,DemandPJ_projection[#Headers],DemandPJ_projection[])))/5 -> 2.3034182 | M9: =IF(M$2<YEAR(TODAY()),SUMIF(DemandPJ_historic[Year],CommDemand!M$2,_xlfn.XLOOKUP(CommDemand!$D9,DemandPJ_historic[#Headers],DemandPJ_historic[])), SUMIF(DemandPJ_projection[Year],CommDemand!M$2,_xlfn.XLOOKUP(CommDemand!$D9,DemandPJ_projection[#Headers],DemandPJ_projection[])))/5 -> 2.3491236 | N9: =IF(N$2<YEAR(TODAY()),SUMIF(DemandPJ_historic[Year],CommDemand!N$2,_xlfn.XLOOKUP(CommDemand!$D9,DemandPJ_historic[#Headers],DemandPJ_historic[])), SUMIF(DemandPJ_projection[Year],CommDemand!N$2,_xlfn.XLOOKUP(CommDemand!$D9,DemandPJ_projection[#Headers],DemandPJ_projection[])))/5 -> 2.4115219 | ... Q9: =IF(Q$2<YEAR(TODAY()),SUMIF(DemandPJ_historic[Year],CommDemand!Q$2,_xlfn.XLOOKUP(CommDemand!$D9,DemandPJ_historic[#Headers],DemandPJ_historic[])), SUMIF(DemandPJ_projection[Year],CommDemand!Q$2,_xlfn.XLOOKUP(CommDemand!$D9,DemandPJ_projection[#Headers],DemandPJ_projection[])))/5 -> 2.3034182 | R9: COMLTXXX | S9: 0.099018 | T9: 0.144386 | U9: 0.092335 | V9: 0.004213 | W9: 0.099233 | X9: 0.1494 | Y9: 0.071368 | Z9: 0.004574 | AA9: 0.096951 | AB9: 0.156721 | AC9: 0.07783 | AD9: 0.003971
B10: *R2,R3,R4,R5,R6 | C10: IVTE | D10: Ventilation | E10: Industrial Ventilation, E | F10: PJ | G10: =IF(G$2<YEAR(TODAY()),SUMIFS(_xlfn.XLOOKUP(CommDemand!$D10,DemandPJ_historic[#Headers],DemandPJ_historic[]),DemandPJ_historic[Year],CommDemand!G$2,DemandPJ_historic[Fuel],"ELC"), SUMIFS(_xlfn.XLOOKUP(CommDemand!$D10,DemandPJ_projection[#Headers],DemandPJ_projection[]),DemandPJ_projection[Year],CommDemand!G$2,DemandPJ_projection[Fuel],"ELC"))/5 -> 0.54680551 | H10: =IF(H$2<YEAR(TODAY()),SUMIFS(_xlfn.XLOOKUP(CommDemand!$D10,DemandPJ_historic[#Headers],DemandPJ_historic[]),DemandPJ_historic[Year],CommDemand!H$2,DemandPJ_historic[Fuel],"ELC"), SUMIFS(_xlfn.XLOOKUP(CommDemand!$D10,DemandPJ_projection[#Headers],DemandPJ_projection[]),DemandPJ_projection[Year],CommDemand!H$2,DemandPJ_projection[Fuel],"ELC"))/5 -> 0.5561575 | I10: =IF(I$2<YEAR(TODAY()),SUMIFS(_xlfn.XLOOKUP(CommDemand!$D10,DemandPJ_historic[#Headers],DemandPJ_historic[]),DemandPJ_historic[Year],CommDemand!I$2,DemandPJ_historic[Fuel],"ELC"), SUMIFS(_xlfn.XLOOKUP(CommDemand!$D10,DemandPJ_projection[#Headers],DemandPJ_projection[]),DemandPJ_projection[Year],CommDemand!I$2,DemandPJ_projection[Fuel],"ELC"))/5 -> 0.45341888 | J10: =IF(J$2<YEAR(TODAY()),SUMIFS(_xlfn.XLOOKUP(CommDemand!$D10,DemandPJ_historic[#Headers],DemandPJ_historic[]),DemandPJ_historic[Year],CommDemand!J$2,DemandPJ_historic[Fuel],"ELC"), SUMIFS(_xlfn.XLOOKUP(CommDemand!$D10,DemandPJ_projection[#Headers],DemandPJ_projection[]),DemandPJ_projection[Year],CommDemand!J$2,DemandPJ_projection[Fuel],"ELC"))/5 -> 0.49162749 | K10: =IF(K$2<YEAR(TODAY()),SUMIFS(_xlfn.XLOOKUP(CommDemand!$D10,DemandPJ_historic[#Headers],DemandPJ_historic[]),DemandPJ_historic[Year],CommDemand!K$2,DemandPJ_historic[Fuel],"ELC"), SUMIFS(_xlfn.XLOOKUP(CommDemand!$D10,DemandPJ_projection[#Headers],DemandPJ_projection[]),DemandPJ_projection[Year],CommDemand!K$2,DemandPJ_projection[Fuel],"ELC"))/5 -> 0.48089684 | L10: =IF(L$2<YEAR(TODAY()),SUMIFS(_xlfn.XLOOKUP(CommDemand!$D10,DemandPJ_historic[#Headers],DemandPJ_historic[]),DemandPJ_historic[Year],CommDemand!L$2,DemandPJ_historic[Fuel],"ELC"), SUMIFS(_xlfn.XLOOKUP(CommDemand!$D10,DemandPJ_projection[#Headers],DemandPJ_projection[]),DemandPJ_projection[Year],CommDemand!L$2,DemandPJ_projection[Fuel],"ELC"))/5 -> 0.48872599 | M10: =IF(M$2<YEAR(TODAY()),SUMIFS(_xlfn.XLOOKUP(CommDemand!$D10,DemandPJ_historic[#Headers],DemandPJ_historic[]),DemandPJ_historic[Year],CommDemand!M$2,DemandPJ_historic[Fuel],"ELC"), SUMIFS(_xlfn.XLOOKUP(CommDemand!$D10,DemandPJ_projection[#Headers],DemandPJ_projection[]),DemandPJ_projection[Year],CommDemand!M$2,DemandPJ_projection[Fuel],"ELC"))/5 -> 0.49842351 | N10: =IF(N$2<YEAR(TODAY()),SUMIFS(_xlfn.XLOOKUP(CommDemand!$D10,DemandPJ_historic[#Headers],DemandPJ_historic[]),DemandPJ_historic[Year],CommDemand!N$2,DemandPJ_historic[Fuel],"ELC"), SUMIFS(_xlfn.XLOOKUP(CommDemand!$D10,DemandPJ_projection[#Headers],DemandPJ_projection[]),DemandPJ_projection[Year],CommDemand!N$2,DemandPJ_projection[Fuel],"ELC"))/5 -> 0.51166282 | ... Q10: =IF(Q$2<YEAR(TODAY()),SUMIFS(_xlfn.XLOOKUP(CommDemand!$D10,DemandPJ_historic[#Headers],DemandPJ_historic[]),DemandPJ_historic[Year],CommDemand!Q$2,DemandPJ_historic[Fuel],"ELC"), SUMIFS(_xlfn.XLOOKUP(CommDemand!$D10,DemandPJ_projection[#Headers],DemandPJ_projection[]),DemandPJ_projection[Year],CommDemand!Q$2,DemandPJ_projection[Fuel],"ELC"))/5 -> 0.48872599 | R10: COMVTXXX | S10: 0.08349393 | T10: 0.103057 | U10: 0.15240839 | V10: 0.00346679 | W10: 0.10221035 | X10: 0.11540133 | Y10: 0.12991177 | Z10: 0.00289949 | AA10: 0.07424331 | AB10: 0.10591607 | AC10: 0.12385355 | AD10: 0.00313802
B11: *R2,R3,R4,R5,R6 | C11: IVTF | D11: Ventilation | E11: Industrial Ventilation, F | F11: PJ | G11: =(IF(G$2<YEAR(TODAY()),SUMIF(DemandPJ_historic[Year],CommDemand!G$2,_xlfn.XLOOKUP(CommDemand!$D11,DemandPJ_historic[#Headers],DemandPJ_historic[])), SUMIF(DemandPJ_projection[Year],CommDemand!G$2,_xlfn.XLOOKUP(CommDemand!$D11,DemandPJ_projection[#Headers],DemandPJ_projection[])))/5)-G10 -> 0 | H11: =(IF(H$2<YEAR(TODAY()),SUMIF(DemandPJ_historic[Year],CommDemand!H$2,_xlfn.XLOOKUP(CommDemand!$D11,DemandPJ_historic[#Headers],DemandPJ_historic[])), SUMIF(DemandPJ_projection[Year],CommDemand!H$2,_xlfn.XLOOKUP(CommDemand!$D11,DemandPJ_projection[#Headers],DemandPJ_projection[])))/5)-H10 -> 0 | I11: =(IF(I$2<YEAR(TODAY()),SUMIF(DemandPJ_historic[Year],CommDemand!I$2,_xlfn.XLOOKUP(CommDemand!$D11,DemandPJ_historic[#Headers],DemandPJ_historic[])), SUMIF(DemandPJ_projection[Year],CommDemand!I$2,_xlfn.XLOOKUP(CommDemand!$D11,DemandPJ_projection[#Headers],DemandPJ_projection[])))/5)-I10 -> 0 | J11: =(IF(J$2<YEAR(TODAY()),SUMIF(DemandPJ_historic[Year],CommDemand!J$2,_xlfn.XLOOKUP(CommDemand!$D11,DemandPJ_historic[#Headers],DemandPJ_historic[])), SUMIF(DemandPJ_projection[Year],CommDemand!J$2,_xlfn.XLOOKUP(CommDemand!$D11,DemandPJ_projection[#Headers],DemandPJ_projection[])))/5)-J10 -> 0 | K11: =(IF(K$2<YEAR(TODAY()),SUMIF(DemandPJ_historic[Year],CommDemand!K$2,_xlfn.XLOOKUP(CommDemand!$D11,DemandPJ_historic[#Headers],DemandPJ_historic[])), SUMIF(DemandPJ_projection[Year],CommDemand!K$2,_xlfn.XLOOKUP(CommDemand!$D11,DemandPJ_projection[#Headers],DemandPJ_projection[])))/5)-K10 -> 0 | L11: =(IF(L$2<YEAR(TODAY()),SUMIF(DemandPJ_historic[Year],CommDemand!L$2,_xlfn.XLOOKUP(CommDemand!$D11,DemandPJ_historic[#Headers],DemandPJ_historic[])), SUMIF(DemandPJ_projection[Year],CommDemand!L$2,_xlfn.XLOOKUP(CommDemand!$D11,DemandPJ_projection[#Headers],DemandPJ_projection[])))/5)-L10 -> 0 | M11: =(IF(M$2<YEAR(TODAY()),SUMIF(DemandPJ_historic[Year],CommDemand!M$2,_xlfn.XLOOKUP(CommDemand!$D11,DemandPJ_historic[#Headers],DemandPJ_historic[])), SUMIF(DemandPJ_projection[Year],CommDemand!M$2,_xlfn.XLOOKUP(CommDemand!$D11,DemandPJ_projection[#Headers],DemandPJ_projection[])))/5)-M10 -> 0 | N11: =(IF(N$2<YEAR(TODAY()),SUMIF(DemandPJ_historic[Year],CommDemand!N$2,_xlfn.XLOOKUP(CommDemand!$D11,DemandPJ_historic[#Headers],DemandPJ_historic[])), SUMIF(DemandPJ_projection[Year],CommDemand!N$2,_xlfn.XLOOKUP(CommDemand!$D11,DemandPJ_projection[#Headers],DemandPJ_projection[])))/5)-N10 -> 0 | ... Q11: =(IF(Q$2<YEAR(TODAY()),SUMIF(DemandPJ_historic[Year],CommDemand!Q$2,_xlfn.XLOOKUP(CommDemand!$D11,DemandPJ_historic[#Headers],DemandPJ_historic[])), SUMIF(DemandPJ_projection[Year],CommDemand!Q$2,_xlfn.XLOOKUP(CommDemand!$D11,DemandPJ_projection[#Headers],DemandPJ_projection[])))/5)-Q10 -> 0 | R11: COMVTXXX | S11: 0.08349393 | T11: 0.103057 | U11: 0.15240839 | V11: 0.00346679 | W11: 0.10221035 | X11: 0.11540133 | Y11: 0.12991177 | Z11: 0.00289949 | AA11: 0.07424331 | AB11: 0.10591607 | AC11: 0.12385355 | AD11: 0.00313802
B12: *R2,R3,R4,R5,R6 | C12: ICOE | D12: Conveyance | E12: Industrial Conveyance, E | F12: PJ | G12: =IF(G$2<YEAR(TODAY()),SUMIFS(_xlfn.XLOOKUP(CommDemand!$D12,DemandPJ_historic[#Headers],DemandPJ_historic[]),DemandPJ_historic[Year],CommDemand!G$2,DemandPJ_historic[Fuel],"ELC"), SUMIFS(_xlfn.XLOOKUP(CommDemand!$D12,DemandPJ_projection[#Headers],DemandPJ_projection[]),DemandPJ_projection[Year],CommDemand!G$2,DemandPJ_projection[Fuel],"ELC"))/5 -> 0.38878958 | H12: =IF(H$2<YEAR(TODAY()),SUMIFS(_xlfn.XLOOKUP(CommDemand!$D12,DemandPJ_historic[#Headers],DemandPJ_historic[]),DemandPJ_historic[Year],CommDemand!H$2,DemandPJ_historic[Fuel],"ELC"), SUMIFS(_xlfn.XLOOKUP(CommDemand!$D12,DemandPJ_projection[#Headers],DemandPJ_projection[]),DemandPJ_projection[Year],CommDemand!H$2,DemandPJ_projection[Fuel],"ELC"))/5 -> 0.39543903 | I12: =IF(I$2<YEAR(TODAY()),SUMIFS(_xlfn.XLOOKUP(CommDemand!$D12,DemandPJ_historic[#Headers],DemandPJ_historic[]),DemandPJ_historic[Year],CommDemand!I$2,DemandPJ_historic[Fuel],"ELC"), SUMIFS(_xlfn.XLOOKUP(CommDemand!$D12,DemandPJ_projection[#Headers],DemandPJ_projection[]),DemandPJ_projection[Year],CommDemand!I$2,DemandPJ_projection[Fuel],"ELC"))/5 -> 0.32238983 | J12: =IF(J$2<YEAR(TODAY()),SUMIFS(_xlfn.XLOOKUP(CommDemand!$D12,DemandPJ_historic[#Headers],DemandPJ_historic[]),DemandPJ_historic[Year],CommDemand!J$2,DemandPJ_historic[Fuel],"ELC"), SUMIFS(_xlfn.XLOOKUP(CommDemand!$D12,DemandPJ_projection[#Headers],DemandPJ_projection[]),DemandPJ_projection[Year],CommDemand!J$2,DemandPJ_projection[Fuel],"ELC"))/5 -> 0.34955691 | K12: =IF(K$2<YEAR(TODAY()),SUMIFS(_xlfn.XLOOKUP(CommDemand!$D12,DemandPJ_historic[#Headers],DemandPJ_historic[]),DemandPJ_historic[Year],CommDemand!K$2,DemandPJ_historic[Fuel],"ELC"), SUMIFS(_xlfn.XLOOKUP(CommDemand!$D12,DemandPJ_projection[#Headers],DemandPJ_projection[]),DemandPJ_projection[Year],CommDemand!K$2,DemandPJ_projection[Fuel],"ELC"))/5 -> 0.34192721 | L12: =IF(L$2<YEAR(TODAY()),SUMIFS(_xlfn.XLOOKUP(CommDemand!$D12,DemandPJ_historic[#Headers],DemandPJ_historic[]),DemandPJ_historic[Year],CommDemand!L$2,DemandPJ_historic[Fuel],"ELC"), SUMIFS(_xlfn.XLOOKUP(CommDemand!$D12,DemandPJ_projection[#Headers],DemandPJ_projection[]),DemandPJ_projection[Year],CommDemand!L$2,DemandPJ_projection[Fuel],"ELC"))/5 -> 0.34749389 | M12: =IF(M$2<YEAR(TODAY()),SUMIFS(_xlfn.XLOOKUP(CommDemand!$D12,DemandPJ_historic[#Headers],DemandPJ_historic[]),DemandPJ_historic[Year],CommDemand!M$2,DemandPJ_historic[Fuel],"ELC"), SUMIFS(_xlfn.XLOOKUP(CommDemand!$D12,DemandPJ_projection[#Headers],DemandPJ_projection[]),DemandPJ_projection[Year],CommDemand!M$2,DemandPJ_projection[Fuel],"ELC"))/5 -> 0.35438902 | N12: =IF(N$2<YEAR(TODAY()),SUMIFS(_xlfn.XLOOKUP(CommDemand!$D12,DemandPJ_historic[#Headers],DemandPJ_historic[]),DemandPJ_historic[Year],CommDemand!N$2,DemandPJ_historic[Fuel],"ELC"), SUMIFS(_xlfn.XLOOKUP(CommDemand!$D12,DemandPJ_projection[#Headers],DemandPJ_projection[]),DemandPJ_projection[Year],CommDemand!N$2,DemandPJ_projection[Fuel],"ELC"))/5 -> 0.36380243 | ... Q12: =IF(Q$2<YEAR(TODAY()),SUMIFS(_xlfn.XLOOKUP(CommDemand!$D12,DemandPJ_historic[#Headers],DemandPJ_historic[]),DemandPJ_historic[Year],CommDemand!Q$2,DemandPJ_historic[Fuel],"ELC"), SUMIFS(_xlfn.XLOOKUP(CommDemand!$D12,DemandPJ_projection[#Headers],DemandPJ_projection[]),DemandPJ_projection[Year],CommDemand!Q$2,DemandPJ_projection[Fuel],"ELC"))/5 -> 0.34749389 | R12: COMCOXXX | S12: 0.095411 | T12: 0.17413 | U12: 0.067175 | V12: 0.003466 | W12: 0.089708 | X12: 0.185882 | Y12: 0.042992 | Z12: 0.004953 | AA12: 0.093811 | AB12: 0.194873 | AC12: 0.043932 | AD12: 0.003667
C13: ICOE | D13: Conveyance | E13: Industrial Conveyance, F | F13: PJ | G13: =(IF(G$2<YEAR(TODAY()),SUMIF(DemandPJ_historic[Year],CommDemand!G$2,_xlfn.XLOOKUP(CommDemand!$D13,DemandPJ_historic[#Headers],DemandPJ_historic[])), SUMIF(DemandPJ_projection[Year],CommDemand!G$2,_xlfn.XLOOKUP(CommDemand!$D13,DemandPJ_projection[#Headers],DemandPJ_projection[])))/5)-G12 -> 0 | H13: =(IF(H$2<YEAR(TODAY()),SUMIF(DemandPJ_historic[Year],CommDemand!H$2,_xlfn.XLOOKUP(CommDemand!$D13,DemandPJ_historic[#Headers],DemandPJ_historic[])), SUMIF(DemandPJ_projection[Year],CommDemand!H$2,_xlfn.XLOOKUP(CommDemand!$D13,DemandPJ_projection[#Headers],DemandPJ_projection[])))/5)-H12 -> 0 | I13: =(IF(I$2<YEAR(TODAY()),SUMIF(DemandPJ_historic[Year],CommDemand!I$2,_xlfn.XLOOKUP(CommDemand!$D13,DemandPJ_historic[#Headers],DemandPJ_historic[])), SUMIF(DemandPJ_projection[Year],CommDemand!I$2,_xlfn.XLOOKUP(CommDemand!$D13,DemandPJ_projection[#Headers],DemandPJ_projection[])))/5)-I12 -> 0 | J13: =(IF(J$2<YEAR(TODAY()),SUMIF(DemandPJ_historic[Year],CommDemand!J$2,_xlfn.XLOOKUP(CommDemand!$D13,DemandPJ_historic[#Headers],DemandPJ_historic[])), SUMIF(DemandPJ_projection[Year],CommDemand!J$2,_xlfn.XLOOKUP(CommDemand!$D13,DemandPJ_projection[#Headers],DemandPJ_projection[])))/5)-J12 -> 0 | K13: =(IF(K$2<YEAR(TODAY()),SUMIF(DemandPJ_historic[Year],CommDemand!K$2,_xlfn.XLOOKUP(CommDemand!$D13,DemandPJ_historic[#Headers],DemandPJ_historic[])), SUMIF(DemandPJ_projection[Year],CommDemand!K$2,_xlfn.XLOOKUP(CommDemand!$D13,DemandPJ_projection[#Headers],DemandPJ_projection[])))/5)-K12 -> 0 | L13: =(IF(L$2<YEAR(TODAY()),SUMIF(DemandPJ_historic[Year],CommDemand!L$2,_xlfn.XLOOKUP(CommDemand!$D13,DemandPJ_historic[#Headers],DemandPJ_historic[])), SUMIF(DemandPJ_projection[Year],CommDemand!L$2,_xlfn.XLOOKUP(CommDemand!$D13,DemandPJ_projection[#Headers],DemandPJ_projection[])))/5)-L12 -> 0 | M13: =(IF(M$2<YEAR(TODAY()),SUMIF(DemandPJ_historic[Year],CommDemand!M$2,_xlfn.XLOOKUP(CommDemand!$D13,DemandPJ_historic[#Headers],DemandPJ_historic[])), SUMIF(DemandPJ_projection[Year],CommDemand!M$2,_xlfn.XLOOKUP(CommDemand!$D13,DemandPJ_projection[#Headers],DemandPJ_projection[])))/5)-M12 -> 0 | N13: =(IF(N$2<YEAR(TODAY()),SUMIF(DemandPJ_historic[Year],CommDemand!N$2,_xlfn.XLOOKUP(CommDemand!$D13,DemandPJ_historic[#Headers],DemandPJ_historic[])), SUMIF(DemandPJ_projection[Year],CommDemand!N$2,_xlfn.XLOOKUP(CommDemand!$D13,DemandPJ_projection[#Headers],DemandPJ_projection[])))/5)-N12 -> 0 | ... Q13: =(IF(Q$2<YEAR(TODAY()),SUMIF(DemandPJ_historic[Year],CommDemand!Q$2,_xlfn.XLOOKUP(CommDemand!$D13,DemandPJ_historic[#Headers],DemandPJ_historic[])), SUMIF(DemandPJ_projection[Year],CommDemand!Q$2,_xlfn.XLOOKUP(CommDemand!$D13,DemandPJ_projection[#Headers],DemandPJ_projection[])))/5)-Q12 -> 0 | R13: COMCOXXX | S13: 0.095411 | T13: 0.17413 | U13: 0.067175 | V13: 0.003466 | W13: 0.089708 | X13: 0.185882 | Y13: 0.042992 | Z13: 0.004953 | AA13: 0.093811 | AB13: 0.194873 | AC13: 0.043932 | AD13: 0.003667
B14: *R2,R3,R4,R5,R6 | C14: IPLE | D14: Process Loads | E14: Industrial Process Loads, E | F14: PJ | G14: =IF(G$2<YEAR(TODAY()),SUMIFS(_xlfn.XLOOKUP(CommDemand!$D14,DemandPJ_historic[#Headers],DemandPJ_historic[]),DemandPJ_historic[Year],CommDemand!G$2,DemandPJ_historic[Fuel],"ELC"), SUMIFS(_xlfn.XLOOKUP(CommDemand!$D14,DemandPJ_projection[#Headers],DemandPJ_projection[]),DemandPJ_projection[Year],CommDemand!G$2,DemandPJ_projection[Fuel],"ELC"))/5 -> 0.85331797 | H14: =IF(H$2<YEAR(TODAY()),SUMIFS(_xlfn.XLOOKUP(CommDemand!$D14,DemandPJ_historic[#Headers],DemandPJ_historic[]),DemandPJ_historic[Year],CommDemand!H$2,DemandPJ_historic[Fuel],"ELC"), SUMIFS(_xlfn.XLOOKUP(CommDemand!$D14,DemandPJ_projection[#Headers],DemandPJ_projection[]),DemandPJ_projection[Year],CommDemand!H$2,DemandPJ_projection[Fuel],"ELC"))/5 -> 0.86791222 | I14: =IF(I$2<YEAR(TODAY()),SUMIFS(_xlfn.XLOOKUP(CommDemand!$D14,DemandPJ_historic[#Headers],DemandPJ_historic[]),DemandPJ_historic[Year],CommDemand!I$2,DemandPJ_historic[Fuel],"ELC"), SUMIFS(_xlfn.XLOOKUP(CommDemand!$D14,DemandPJ_projection[#Headers],DemandPJ_projection[]),DemandPJ_projection[Year],CommDemand!I$2,DemandPJ_projection[Fuel],"ELC"))/5 -> 0.70758335 | J14: =IF(J$2<YEAR(TODAY()),SUMIFS(_xlfn.XLOOKUP(CommDemand!$D14,DemandPJ_historic[#Headers],DemandPJ_historic[]),DemandPJ_historic[Year],CommDemand!J$2,DemandPJ_historic[Fuel],"ELC"), SUMIFS(_xlfn.XLOOKUP(CommDemand!$D14,DemandPJ_projection[#Headers],DemandPJ_projection[]),DemandPJ_projection[Year],CommDemand!J$2,DemandPJ_projection[Fuel],"ELC"))/5 -> 0.76720984 | K14: =IF(K$2<YEAR(TODAY()),SUMIFS(_xlfn.XLOOKUP(CommDemand!$D14,DemandPJ_historic[#Headers],DemandPJ_historic[]),DemandPJ_historic[Year],CommDemand!K$2,DemandPJ_historic[Fuel],"ELC"), SUMIFS(_xlfn.XLOOKUP(CommDemand!$D14,DemandPJ_projection[#Headers],DemandPJ_projection[]),DemandPJ_projection[Year],CommDemand!K$2,DemandPJ_projection[Fuel],"ELC"))/5 -> 0.75046411 | L14: =IF(L$2<YEAR(TODAY()),SUMIFS(_xlfn.XLOOKUP(CommDemand!$D14,DemandPJ_historic[#Headers],DemandPJ_historic[]),DemandPJ_historic[Year],CommDemand!L$2,DemandPJ_historic[Fuel],"ELC"), SUMIFS(_xlfn.XLOOKUP(CommDemand!$D14,DemandPJ_projection[#Headers],DemandPJ_projection[]),DemandPJ_projection[Year],CommDemand!L$2,DemandPJ_projection[Fuel],"ELC"))/5 -> 0.76268191 | M14: =IF(M$2<YEAR(TODAY()),SUMIFS(_xlfn.XLOOKUP(CommDemand!$D14,DemandPJ_historic[#Headers],DemandPJ_historic[]),DemandPJ_historic[Year],CommDemand!M$2,DemandPJ_historic[Fuel],"ELC"), SUMIFS(_xlfn.XLOOKUP(CommDemand!$D14,DemandPJ_projection[#Headers],DemandPJ_projection[]),DemandPJ_projection[Year],CommDemand!M$2,DemandPJ_projection[Fuel],"ELC"))/5 -> 0.77781538 | N14: =IF(N$2<YEAR(TODAY()),SUMIFS(_xlfn.XLOOKUP(CommDemand!$D14,DemandPJ_historic[#Headers],DemandPJ_historic[]),DemandPJ_historic[Year],CommDemand!N$2,DemandPJ_historic[Fuel],"ELC"), SUMIFS(_xlfn.XLOOKUP(CommDemand!$D14,DemandPJ_projection[#Headers],DemandPJ_projection[]),DemandPJ_projection[Year],CommDemand!N$2,DemandPJ_projection[Fuel],"ELC"))/5 -> 0.798476 | ... Q14: =IF(Q$2<YEAR(TODAY()),SUMIFS(_xlfn.XLOOKUP(CommDemand!$D14,DemandPJ_historic[#Headers],DemandPJ_historic[]),DemandPJ_historic[Year],CommDemand!Q$2,DemandPJ_historic[Fuel],"ELC"), SUMIFS(_xlfn.XLOOKUP(CommDemand!$D14,DemandPJ_projection[#Headers],DemandPJ_projection[]),DemandPJ_projection[Year],CommDemand!Q$2,DemandPJ_projection[Fuel],"ELC"))/5 -> 0.76268191 | R14: INDMSXXX | S14: 0.08840918 | T14: 0.10056911 | U14: 0.14146522 | V14: 0.00389066 | W14: 0.10269188 | X14: 0.11269183 | Y14: 0.11543107 | Z14: 0.00351943 | AA14: 0.08756231 | AB14: 0.11300045 | AC14: 0.12691579 | AD14: 0.00385307
C15: IPLF | D15: Process Loads | E15: Industrial Process Loads, F | F15: PJ | G15: =(IF(G$2<YEAR(TODAY()),SUMIF(DemandPJ_historic[Year],CommDemand!G$2,_xlfn.XLOOKUP(CommDemand!$D15,DemandPJ_historic[#Headers],DemandPJ_historic[])), SUMIF(DemandPJ_projection[Year],CommDemand!G$2,_xlfn.XLOOKUP(CommDemand!$D15,DemandPJ_projection[#Headers],DemandPJ_projection[])))/5)-G14 -> 0.07351398 | H15: =(IF(H$2<YEAR(TODAY()),SUMIF(DemandPJ_historic[Year],CommDemand!H$2,_xlfn.XLOOKUP(CommDemand!$D15,DemandPJ_historic[#Headers],DemandPJ_historic[])), SUMIF(DemandPJ_projection[Year],CommDemand!H$2,_xlfn.XLOOKUP(CommDemand!$D15,DemandPJ_projection[#Headers],DemandPJ_projection[])))/5)-H14 -> 0.084690622 | I15: =(IF(I$2<YEAR(TODAY()),SUMIF(DemandPJ_historic[Year],CommDemand!I$2,_xlfn.XLOOKUP(CommDemand!$D15,DemandPJ_historic[#Headers],DemandPJ_historic[])), SUMIF(DemandPJ_projection[Year],CommDemand!I$2,_xlfn.XLOOKUP(CommDemand!$D15,DemandPJ_projection[#Headers],DemandPJ_projection[])))/5)-I14 -> 0.077758159 | J15: =(IF(J$2<YEAR(TODAY()),SUMIF(DemandPJ_historic[Year],CommDemand!J$2,_xlfn.XLOOKUP(CommDemand!$D15,DemandPJ_historic[#Headers],DemandPJ_historic[])), SUMIF(DemandPJ_projection[Year],CommDemand!J$2,_xlfn.XLOOKUP(CommDemand!$D15,DemandPJ_projection[#Headers],DemandPJ_projection[])))/5)-J14 -> 0.04781816 | K15: =(IF(K$2<YEAR(TODAY()),SUMIF(DemandPJ_historic[Year],CommDemand!K$2,_xlfn.XLOOKUP(CommDemand!$D15,DemandPJ_historic[#Headers],DemandPJ_historic[])), SUMIF(DemandPJ_projection[Year],CommDemand!K$2,_xlfn.XLOOKUP(CommDemand!$D15,DemandPJ_projection[#Headers],DemandPJ_projection[])))/5)-K14 -> 0.046104528 | L15: =(IF(L$2<YEAR(TODAY()),SUMIF(DemandPJ_historic[Year],CommDemand!L$2,_xlfn.XLOOKUP(CommDemand!$D15,DemandPJ_historic[#Headers],DemandPJ_historic[])), SUMIF(DemandPJ_projection[Year],CommDemand!L$2,_xlfn.XLOOKUP(CommDemand!$D15,DemandPJ_projection[#Headers],DemandPJ_projection[])))/5)-L14 -> 0.04453291 | M15: =(IF(M$2<YEAR(TODAY()),SUMIF(DemandPJ_historic[Year],CommDemand!M$2,_xlfn.XLOOKUP(CommDemand!$D15,DemandPJ_historic[#Headers],DemandPJ_historic[])), SUMIF(DemandPJ_projection[Year],CommDemand!M$2,_xlfn.XLOOKUP(CommDemand!$D15,DemandPJ_projection[#Headers],DemandPJ_projection[])))/5)-M14 -> 0.042641031 | N15: =(IF(N$2<YEAR(TODAY()),SUMIF(DemandPJ_historic[Year],CommDemand!N$2,_xlfn.XLOOKUP(CommDemand!$D15,DemandPJ_historic[#Headers],DemandPJ_historic[])), SUMIF(DemandPJ_projection[Year],CommDemand!N$2,_xlfn.XLOOKUP(CommDemand!$D15,DemandPJ_projection[#Headers],DemandPJ_projection[])))/5)-N14 -> 0.042143205 | ... Q15: =(IF(Q$2<YEAR(TODAY()),SUMIF(DemandPJ_historic[Year],CommDemand!Q$2,_xlfn.XLOOKUP(CommDemand!$D15,DemandPJ_historic[#Headers],DemandPJ_historic[])), SUMIF(DemandPJ_projection[Year],CommDemand!Q$2,_xlfn.XLOOKUP(CommDemand!$D15,DemandPJ_projection[#Headers],DemandPJ_projection[])))/5)-Q14 -> 0.04453291 | R15: INDMSXXX | S15: 0.08840918 | T15: 0.10056911 | U15: 0.14146522 | V15: 0.00389066 | W15: 0.10269188 | X15: 0.11269183 | Y15: 0.11543107 | Z15: 0.00351943 | AA15: 0.08756231 | AB15: 0.11300045 | AC15: 0.12691579 | AD15: 0.00385307
B16: *R2,R3,R4,R5,R6 | C16: IPME | D16: Plug Loads/Misc | E16: Industrial Plug Loads / Misc, E | F16: PJ | G16: =IF(G$2<YEAR(TODAY()),SUMIFS(_xlfn.XLOOKUP(CommDemand!$D16,DemandPJ_historic[#Headers],DemandPJ_historic[]),DemandPJ_historic[Year],CommDemand!G$2,DemandPJ_historic[Fuel],"ELC"), SUMIFS(_xlfn.XLOOKUP(CommDemand!$D16,DemandPJ_projection[#Headers],DemandPJ_projection[]),DemandPJ_projection[Year],CommDemand!G$2,DemandPJ_projection[Fuel],"ELC"))/5 -> 0.80485748 | H16: =IF(H$2<YEAR(TODAY()),SUMIFS(_xlfn.XLOOKUP(CommDemand!$D16,DemandPJ_historic[#Headers],DemandPJ_historic[]),DemandPJ_historic[Year],CommDemand!H$2,DemandPJ_historic[Fuel],"ELC"), SUMIFS(_xlfn.XLOOKUP(CommDemand!$D16,DemandPJ_projection[#Headers],DemandPJ_projection[]),DemandPJ_projection[Year],CommDemand!H$2,DemandPJ_projection[Fuel],"ELC"))/5 -> 0.81862291 | I16: =IF(I$2<YEAR(TODAY()),SUMIFS(_xlfn.XLOOKUP(CommDemand!$D16,DemandPJ_historic[#Headers],DemandPJ_historic[]),DemandPJ_historic[Year],CommDemand!I$2,DemandPJ_historic[Fuel],"ELC"), SUMIFS(_xlfn.XLOOKUP(CommDemand!$D16,DemandPJ_projection[#Headers],DemandPJ_projection[]),DemandPJ_projection[Year],CommDemand!I$2,DemandPJ_projection[Fuel],"ELC"))/5 -> 0.66739922 | J16: =IF(J$2<YEAR(TODAY()),SUMIFS(_xlfn.XLOOKUP(CommDemand!$D16,DemandPJ_historic[#Headers],DemandPJ_historic[]),DemandPJ_historic[Year],CommDemand!J$2,DemandPJ_historic[Fuel],"ELC"), SUMIFS(_xlfn.XLOOKUP(CommDemand!$D16,DemandPJ_projection[#Headers],DemandPJ_projection[]),DemandPJ_projection[Year],CommDemand!J$2,DemandPJ_projection[Fuel],"ELC"))/5 -> 0.72363949 | K16: =IF(K$2<YEAR(TODAY()),SUMIFS(_xlfn.XLOOKUP(CommDemand!$D16,DemandPJ_historic[#Headers],DemandPJ_historic[]),DemandPJ_historic[Year],CommDemand!K$2,DemandPJ_historic[Fuel],"ELC"), SUMIFS(_xlfn.XLOOKUP(CommDemand!$D16,DemandPJ_projection[#Headers],DemandPJ_projection[]),DemandPJ_projection[Year],CommDemand!K$2,DemandPJ_projection[Fuel],"ELC"))/5 -> 0.70784476 | L16: =IF(L$2<YEAR(TODAY()),SUMIFS(_xlfn.XLOOKUP(CommDemand!$D16,DemandPJ_historic[#Headers],DemandPJ_historic[]),DemandPJ_historic[Year],CommDemand!L$2,DemandPJ_historic[Fuel],"ELC"), SUMIFS(_xlfn.XLOOKUP(CommDemand!$D16,DemandPJ_projection[#Headers],DemandPJ_projection[]),DemandPJ_projection[Year],CommDemand!L$2,DemandPJ_projection[Fuel],"ELC"))/5 -> 0.71936869 | M16: =IF(M$2<YEAR(TODAY()),SUMIFS(_xlfn.XLOOKUP(CommDemand!$D16,DemandPJ_historic[#Headers],DemandPJ_historic[]),DemandPJ_historic[Year],CommDemand!M$2,DemandPJ_historic[Fuel],"ELC"), SUMIFS(_xlfn.XLOOKUP(CommDemand!$D16,DemandPJ_projection[#Headers],DemandPJ_projection[]),DemandPJ_projection[Year],CommDemand!M$2,DemandPJ_projection[Fuel],"ELC"))/5 -> 0.73364273 | N16: =IF(N$2<YEAR(TODAY()),SUMIFS(_xlfn.XLOOKUP(CommDemand!$D16,DemandPJ_historic[#Headers],DemandPJ_historic[]),DemandPJ_historic[Year],CommDemand!N$2,DemandPJ_historic[Fuel],"ELC"), SUMIFS(_xlfn.XLOOKUP(CommDemand!$D16,DemandPJ_projection[#Headers],DemandPJ_projection[]),DemandPJ_projection[Year],CommDemand!N$2,DemandPJ_projection[Fuel],"ELC"))/5 -> 0.75313002 | ... Q16: =IF(Q$2<YEAR(TODAY()),SUMIFS(_xlfn.XLOOKUP(CommDemand!$D16,DemandPJ_historic[#Headers],DemandPJ_historic[]),DemandPJ_historic[Year],CommDemand!Q$2,DemandPJ_historic[Fuel],"ELC"), SUMIFS(_xlfn.XLOOKUP(CommDemand!$D16,DemandPJ_projection[#Headers],DemandPJ_projection[]),DemandPJ_projection[Year],CommDemand!Q$2,DemandPJ_projection[Fuel],"ELC"))/5 -> 0.71936869 | R16: INDPMXXX | S16: 0.08409339 | T16: 0.09768158 | U16: 0.14881921 | V16: 0.00361859 | W16: 0.09910395 | X16: 0.11041002 | Y16: 0.12152309 | Z16: 0.00317655 | AA16: 0.08339323 | AB16: 0.11061763 | AC16: 0.13394508 | AD16: 0.00361768
C17: IPMF | D17: Plug Loads/Misc | E17: Industrial Plug Loads / Misc, F | F17: PJ | G17: =(IF(G$2<YEAR(TODAY()),SUMIF(DemandPJ_historic[Year],CommDemand!G$2,_xlfn.XLOOKUP(CommDemand!$D17,DemandPJ_historic[#Headers],DemandPJ_historic[])), SUMIF(DemandPJ_projection[Year],CommDemand!G$2,_xlfn.XLOOKUP(CommDemand!$D17,DemandPJ_projection[#Headers],DemandPJ_projection[])))/5)-G16 -> 0.015180916 | H17: =(IF(H$2<YEAR(TODAY()),SUMIF(DemandPJ_historic[Year],CommDemand!H$2,_xlfn.XLOOKUP(CommDemand!$D17,DemandPJ_historic[#Headers],DemandPJ_historic[])), SUMIF(DemandPJ_projection[Year],CommDemand!H$2,_xlfn.XLOOKUP(CommDemand!$D17,DemandPJ_projection[#Headers],DemandPJ_projection[])))/5)-H16 -> 0.017937931 | I17: =(IF(I$2<YEAR(TODAY()),SUMIF(DemandPJ_historic[Year],CommDemand!I$2,_xlfn.XLOOKUP(CommDemand!$D17,DemandPJ_historic[#Headers],DemandPJ_historic[])), SUMIF(DemandPJ_projection[Year],CommDemand!I$2,_xlfn.XLOOKUP(CommDemand!$D17,DemandPJ_projection[#Headers],DemandPJ_projection[])))/5)-I16 -> 0.018510636 | J17: =(IF(J$2<YEAR(TODAY()),SUMIF(DemandPJ_historic[Year],CommDemand!J$2,_xlfn.XLOOKUP(CommDemand!$D17,DemandPJ_historic[#Headers],DemandPJ_historic[])), SUMIF(DemandPJ_projection[Year],CommDemand!J$2,_xlfn.XLOOKUP(CommDemand!$D17,DemandPJ_projection[#Headers],DemandPJ_projection[])))/5)-J16 -> 0.01031893 | K17: =(IF(K$2<YEAR(TODAY()),SUMIF(DemandPJ_historic[Year],CommDemand!K$2,_xlfn.XLOOKUP(CommDemand!$D17,DemandPJ_historic[#Headers],DemandPJ_historic[])), SUMIF(DemandPJ_projection[Year],CommDemand!K$2,_xlfn.XLOOKUP(CommDemand!$D17,DemandPJ_projection[#Headers],DemandPJ_projection[])))/5)-K16 -> 0.010041484 | L17: =(IF(L$2<YEAR(TODAY()),SUMIF(DemandPJ_historic[Year],CommDemand!L$2,_xlfn.XLOOKUP(CommDemand!$D17,DemandPJ_historic[#Headers],DemandPJ_historic[])), SUMIF(DemandPJ_projection[Year],CommDemand!L$2,_xlfn.XLOOKUP(CommDemand!$D17,DemandPJ_projection[#Headers],DemandPJ_projection[])))/5)-L16 -> 0.0096410102 | M17: =(IF(M$2<YEAR(TODAY()),SUMIF(DemandPJ_historic[Year],CommDemand!M$2,_xlfn.XLOOKUP(CommDemand!$D17,DemandPJ_historic[#Headers],DemandPJ_historic[])), SUMIF(DemandPJ_projection[Year],CommDemand!M$2,_xlfn.XLOOKUP(CommDemand!$D17,DemandPJ_projection[#Headers],DemandPJ_projection[])))/5)-M16 -> 0.0091535977 | N17: =(IF(N$2<YEAR(TODAY()),SUMIF(DemandPJ_historic[Year],CommDemand!N$2,_xlfn.XLOOKUP(CommDemand!$D17,DemandPJ_historic[#Headers],DemandPJ_historic[])), SUMIF(DemandPJ_projection[Year],CommDemand!N$2,_xlfn.XLOOKUP(CommDemand!$D17,DemandPJ_projection[#Headers],DemandPJ_projection[])))/5)-N16 -> 0.0088838436 | ... Q17: =(IF(Q$2<YEAR(TODAY()),SUMIF(DemandPJ_historic[Year],CommDemand!Q$2,_xlfn.XLOOKUP(CommDemand!$D17,DemandPJ_historic[#Headers],DemandPJ_historic[])), SUMIF(DemandPJ_projection[Year],CommDemand!Q$2,_xlfn.XLOOKUP(CommDemand!$D17,DemandPJ_projection[#Headers],DemandPJ_projection[])))/5)-Q16 -> 0.0096410102 | R17: INDPMXXX | S17: 0.08409339 | T17: 0.09768158 | U17: 0.14881921 | V17: 0.00361859 | W17: 0.09910395 | X17: 0.11041002 | Y17: 0.12152309 | Z17: 0.00317655 | AA17: 0.08339323 | AB17: 0.11061763 | AC17: 0.13394508 | AD17: 0.00361768
B18: R2,R3,R4,R5,R6 | C18: IOTE | D18: Plug Loads/Misc + Other | E18: Industrial Process Loads + Other | F18: PJ | G18: =SUM(G10,G12,G14,G16) -> 2.5937705 | H18: =SUM(H10,H12,H14,H16) -> 2.6381317 | I18: =SUM(I10,I12,I14,I16) -> 2.1507913 | J18: =SUM(J10,J12,J14,J16) -> 2.3320337 | K18: =SUM(K10,K12,K14,K16) -> 2.2811329 | L18: =SUM(L10,L12,L14,L16) -> 2.3182705 | M18: =SUM(M10,M12,M14,M16) -> 2.3642706 | N18: =SUM(N10,N12,N14,N16) -> 2.4270713 | ... Q18: =SUM(Q10,Q12,Q14,Q16) -> 2.3182705 | R18: INDMSXXX | S18: 0.08840918 | T18: 0.10056911 | U18: 0.14146522 | V18: 0.00389066 | W18: 0.10269188 | X18: 0.11269183 | Y18: 0.11543107 | Z18: 0.00351943 | AA18: 0.08756231 | AB18: 0.11300045 | AC18: 0.12691579 | AD18: 0.00385307
B19: R2,R3,R4,R5,R6 | C19: IOTF | D19: Plug Loads/Misc + Other | E19: Industrial Process Loads + Other | F19: PJ | G19: =SUM(G11,G13,G15,G17) -> 0.088694896 | H19: =SUM(H11,H13,H15,H17) -> 0.10262855 | I19: =SUM(I11,I13,I15,I17) -> 0.096268795 | J19: =SUM(J11,J13,J15,J17) -> 0.058137091 | K19: =SUM(K11,K13,K15,K17) -> 0.056146012 | L19: =SUM(L11,L13,L15,L17) -> 0.05417392 | M19: =SUM(M11,M13,M15,M17) -> 0.051794628 | N19: =SUM(N11,N13,N15,N17) -> 0.051027048 | ... Q19: =SUM(Q11,Q13,Q15,Q17) -> 0.05417392 | R19: INDMSXXX | S19: 0.08840918 | T19: 0.10056911 | U19: 0.14146522 | V19: 0.00389066 | W19: 0.10269188 | X19: 0.11269183 | Y19: 0.11543107 | Z19: 0.00351943 | AA19: 0.08756231 | AB19: 0.11300045 | AC19: 0.12691579 | AD19: 0.00385307

Sheet CommData_DMD_dep
B3: Region | C3: CommName | D3: *CommDesc | E3: *Units | F3: COM_PROJ~2010 | G3: COM_PROJ~2015 | H3: COM_PROJ~2020 | I3: COM_PROJ~2025 | J3: COM_PROJ~2030 | K3: COM_PROJ~2035 | L3: COM_PROJ~2040 | M3: COM_PROJ~2045 | N3: COM_PROJ~2050 | O3: COM_PROJ~2055
B4: *Other
B5: R2 | C5: IOT | D5: Other Industry End Demand | E5: PJ | F5: =NYCIND_DMD!D53 -> 8.30918 | G5: =NYCIND_DMD!E53 -> 9.3622424 | H5: =NYCIND_DMD!F53 -> 10.402576 | I5: =NYCIND_DMD!G53 -> 11.132577 | J5: =NYCIND_DMD!H53 -> 12.024885 | K5: =NYCIND_DMD!I53 -> 11.425521 | L5: =NYCIND_DMD!J53 -> 11.314906 | M5: =NYCIND_DMD!K53 -> 12.034575 | ... O5: =NYCIND_DMD!M53 -> 12.379512
B6: R3 | C6: IOT | D6: Other Industry End Demand | E6: PJ | F6: =NYCIND_DMD!D54 -> 23.925625 | G6: =NYCIND_DMD!E54 -> 24.506902 | H6: =NYCIND_DMD!F54 -> 25.069199 | I6: =NYCIND_DMD!G54 -> 25.475584 | J6: =NYCIND_DMD!H54 -> 25.975055 | K6: =NYCIND_DMD!I54 -> 25.651449 | L6: =NYCIND_DMD!J54 -> 25.596716 | M6: =NYCIND_DMD!K54 -> 26.008436 | ... O6: =NYCIND_DMD!M54 -> 26.2175
B7: R4 | C7: IOT | D7: Other Industry End Demand | E7: PJ | F7: =NYCIND_DMD!D55 -> 8.9383948 | G7: =NYCIND_DMD!E55 -> 9.5951843 | H7: =NYCIND_DMD!F55 -> 10.233329 | I7: =NYCIND_DMD!G55 -> 10.670858 | J7: =NYCIND_DMD!H55 -> 11.200623 | K7: =NYCIND_DMD!I55 -> 10.81467 | L7: =NYCIND_DMD!J55 -> 10.728394 | M7: =NYCIND_DMD!K55 -> 11.158541 | ... O7: =NYCIND_DMD!M55 -> 11.336043
B8: R5 | C8: IOT | D8: Other Industry End Demand | E8: PJ | F8: =NYCIND_DMD!D56 -> 20.115576 | G8: =NYCIND_DMD!E56 -> 21.049788 | H8: =NYCIND_DMD!F56 -> 21.957493 | I8: =NYCIND_DMD!G56 -> 22.573867 | J8: =NYCIND_DMD!H56 -> 23.317968 | K8: =NYCIND_DMD!I56 -> 22.781647 | L8: =NYCIND_DMD!J56 -> 22.668541 | M8: =NYCIND_DMD!K56 -> 23.313585 | ... O8: =NYCIND_DMD!M56 -> 23.591192
B9: R6 | C9: IOT | D9: Other Industry End Demand | E9: PJ | F9: =NYCIND_DMD!D57 -> 2.128264 | G9: =NYCIND_DMD!E57 -> 2.3177935 | H9: =NYCIND_DMD!F57 -> 2.5133223 | I9: =NYCIND_DMD!G57 -> 2.6429877 | J9: =NYCIND_DMD!H57 -> 2.7998263 | K9: =NYCIND_DMD!I57 -> 2.6846609 | L9: =NYCIND_DMD!J57 -> 2.6585167 | M9: =NYCIND_DMD!K57 -> 2.8058186 | ... O9: =NYCIND_DMD!M57 -> 2.8712364

Sheet Technologies_dep
B3: *~FI_Process
B4: Region | C4: Sets | D4: TechName | E4: TechDesc | F4: Tact | G4: Tcap | H4: PrimaryCG | I4: Vintage | J4: Tslvl
B5: *Other
B6: =TechData_OTR_dep!B5 -> R2,R3,R4,R5,R6 | C6: PRE | D6: =TechData_OTR_dep!C5 -> INDELC000 | E6: =TechData_OTR_dep!D5 -> Electricity Going to the Industrial Sector | F6: PJ | G6: Pja | J6: DAYNITE
B7: =TechData_OTR_dep!B11 -> * | C7: PRE | D7: =TechData_OTR_dep!C11 -> IOTEMETCOK | E7: =TechData_OTR_dep!D11 -> Other Industry Metallurgical Coal Plant | F7: PJ | G7: Pja
B8: =TechData_OTR_dep!B12 -> * | C8: PRE | D8: =TechData_OTR_dep!C12 -> IOTEFEDRFL | E8: =TechData_OTR_dep!D12 -> Other Industry Residual Oil Feedstock | F8: PJ | G8: Pja
B9: =TechData_OTR_dep!B13 -> * | C9: PRE | D9: =TechData_OTR_dep!C13 -> IOTEFEDDST | E9: =TechData_OTR_dep!D13 -> Other Industry Distillate Oil Feedstock | F9: PJ | G9: Pja
B10: =TechData_OTR_dep!B14 -> * | C10: PRE | D10: =TechData_OTR_dep!C14 -> IOTEFEDNGA | E10: =TechData_OTR_dep!D14 -> Other Industry Natural Gas Feedstock | F10: PJ | G10: Pja
B11: =TechData_OTR_dep!B15 -> * | C11: PRE | D11: =TechData_OTR_dep!C15 -> IOTEFEDLPG | E11: =TechData_OTR_dep!D15 -> Other Industry LPG Feedstock | F11: PJ | G11: Pja
B12: =TechData_OTR_dep!B16 -> * | C12: PRE | D12: =TechData_OTR_dep!C16 -> IOTEFEDCOK | E12: =TechData_OTR_dep!D16 -> Other Industry Coke Feedstock | F12: PJ | G12: Pja
B13: =TechData_OTR_dep!B17 -> * | C13: PRE | D13: =TechData_OTR_dep!C17 -> IOTEFEDBIO | E13: =TechData_OTR_dep!D17 -> Other Industry Renewables Feedstock | F13: PJ | G13: Pja
B14: =TechData_OTR_dep!B18 -> * | C14: PRE | D14: =TechData_OTR_dep!C18 -> IOTEFEDPTC | E14: =TechData_OTR_dep!D18 -> Other Industry Petroleum Coke Feedstock | F14: PJ | G14: Pja
B15: =TechData_OTR_dep!B19 -> * | C15: PRE | D15: =TechData_OTR_dep!C19 -> IOTEFEDOTP | E15: =TechData_OTR_dep!D19 -> Other Industry Other Petroleum Feedstock | F15: PJ | G15: Pja
B16: =TechData_OTR_dep!B20 -> * | C16: PRE | D16: =TechData_OTR_dep!C20 -> IOTEETCELC | E16: =TechData_OTR_dep!D20 -> Other Industry Electrochemical | F16: PJ | G16: Pja
B17: =TechData_OTR_dep!B21 -> * | C17: PRE | D17: =TechData_OTR_dep!C21 -> IOTEPRHELC | E17: =TechData_OTR_dep!D21 -> Other Industry Electricity Process Heat | F17: PJ | G17: Pja
B18: =TechData_OTR_dep!B22 -> * | C18: PRE | D18: =TechData_OTR_dep!C22 -> IOTEPRHRFL | E18: =TechData_OTR_dep!D22 -> Other Industry Residual Oil Process Heat | F18: PJ | G18: Pja
... B42: =TechData_OTR_dep!B46 -> R2,R3,R4,R5,R6 | C42: DMD | D42: =TechData_OTR_dep!C46 -> IOTTECHEXT | E42: =TechData_OTR_dep!D46 -> Existing Other Industry Technologies | F42: PJ | G42: Pja
B43: *Collector
B44: R2,R3,R4,R5,R6 | C44: PRE | D44: IOTELC00 | E44: Other Industry Electricity collector | F44: PJ | G44: Pja | I44: DAYNITE
B45: R2,R3,R4,R5,R6 | C45: PRE | D45: SEINDNGA | E45: Emissions: NGA to IND | F45: PJ | G45: Pja
B46: R2,R3,R4,R5,R6 | C46: PRE | D46: SEINDRFL | E46: Emissions: RFL to IND | F46: PJ | G46: Pja
B47: R2,R3,R4,R5,R6 | C47: PRE | D47: SEINDDSL | E47: Emissions: DSL to IND | F47: PJ | G47: Pja
B48: * | C48: PRE | D48: SEINDDST | E48: Emissions: DST to IND | F48: PJ | G48: Pja
B49: * | C49: PRE | D49: SEINDBIO | E49: Emissions: Biomass combustion | F49: PJ | G49: Pja
B50: * | C50: PRE | D50: SEINDCOA | E50: Emissions: COA to IND | F50: PJ | G50: Pja
B51: * | C51: PRE | D51: SEINDRFL | E51: Emissions: RFL to IND | F51: PJ | G51: Pja
B52: * | C52: PRE | D52: SEINDLPG | E52: Emissions: LPG to IND | F52: PJ | G52: Pja
B53: * | C53: PRE | D53: SEINDMET | E53: Emissions: MET to IND | F53: PJ | G53: Pja

Sheet TechData_OTR_dep
G3: *~FI_T
B4: Region | C4: TechName | D4: *TechDesc | E4: *Units | F4: CommIN | G4: CommOUT | H4: NCAP_START | I4: PRC_CAPACT | J4: NCAP_AF | K4: EFF | N4: Input | O4: Output
B5: R2,R3,R4,R5,R6 | C5: INDELC000 | D5: Electricity Going to the Industrial Sector | E5: PJ, PJ/a | F5: ELC | G5: INDELC | H5: 2010 | I5: 1 | J5: 1 | K5: 1 | N5: 1 | O5: 1
G8: *~FI_T
B9: Region | C9: TechName | D9: *TechDesc | E9: *Units | F9: CommIN | G9: CommOUT | H9: NCAP_START | I9: NCAP_TLIFE | J9: PRC_CAPACT | K9: NCAP_DRATE | L9: NCAP_COST | M9: NCAP_FOM | N9: *NCAP_BND~FX~2010 | O9: *NCAP_BND~FX~2015 | P9: *NCAP_BND~FX~2055 | Q9: PRC_RESID~R2~2010 | R9: PRC_RESID~R3~2010 | S9: PRC_RESID~R4~2010 | T9: PRC_RESID~R5~2010 | U9: PRC_RESID~R6~2010 | V9: PRC_RESID~R2~2015 | W9: PRC_RESID~R3~2015 | X9: PRC_RESID~R4~2015 | Y9: PRC_RESID~R5~2015 | Z9: PRC_RESID~R6~2015 | AA9: PRC_RESID~R2~2055 | AB9: PRC_RESID~R3~2055 | AC9: PRC_RESID~R4~2055 | AD9: PRC_RESID~R5~2055 | AE9: PRC_RESID~R6~2055 | AF9: NCAP_AF | AG9: NCAP_AF | AH9: EFF~2010 | AI9: EFF~2015 | AJ9: EFF~2020 | AK9: EFF~2025 | AL9: EFF~2030 | AM9: EFF~2035 | AN9: EFF~2040 | AO9: EFF~2045 | AP9: EFF~2050 | AQ9: EFF~2055 | AR9: Share~UP~R2~2010 | AS9: Share~UP~R3~2010 | AT9: Share~UP~R4~2010 | AU9: Share~UP~R5~2010 | AV9: Share~UP~R6~2010 | AW9: Share~UP~R2~2015 | AX9: Share~UP~R3~2015 | AY9: Share~UP~R4~2015 | AZ9: Share~UP~R5~2015 | BA9: Share~UP~R6~2015 | BB9: Share~UP~R2~2055 | BC9: Share~UP~R3~2055 | BD9: Share~UP~R4~2055 | BE9: Share~UP~R5~2055 | BF9: Share~UP~R6~2055 | BG9: Peak | BI9: Input~2010 | BJ9: Input~2015 | BK9: Input~2020 | BL9: Input~2025 | BM9: Input~2030 | BN9: Input~2035 | BO9: Input~2040 | BP9: Input~2045 | BQ9: Input~2050 | BR9: Input~2055 | BS9: Output | BT9: Output | BU9: Input | BV9: Output
B10: * Other | BB10: =IF(AW10="","",AW10) | BC10: =IF(AX10="","",AX10) | BD10: =IF(AY10="","",AY10) | BE10: =IF(AZ10="","",AZ10) | BF10: =IF(BA10="","",BA10) | BJ10: =IF(BI10="","",BI10)
B11: * | C11: IOTEMETCOK | D11: Other Industry Metallurgical Coal Plant | E11: PJ, PJ/a | F11: INDMETEA | G11: COKE | H11: 2010 | I11: 30 | J11: 1 | K11: 0.15 | L11: =IFERROR(IF(_xlfn.XLOOKUP(D11,tbl_tech[TECHNOLOGY - Other],tbl_tech[NCAP_COST])=0,"",_xlfn.XLOOKUP(D11,tbl_tech[TECHNOLOGY - Other],tbl_tech[NCAP_COST])),"") -> 19.887216 | M11: =IFERROR(IF(_xlfn.XLOOKUP(D11,tbl_tech[TECHNOLOGY - Other],tbl_tech[NCAP_FOM])=0,"",_xlfn.XLOOKUP(D11,tbl_tech[TECHNOLOGY - Other],tbl_tech[NCAP_FOM])),"") -> 3.173022 | N11: 0 | Q11: 0.37987591 | R11: 0.91455766 | S11: 0.4127475 | T11: 0.37097101 | U11: 0.27476452 | V11: 0 | W11: 0.87277037 | X11: 0.59114812 | Y11: 0.29877444 | Z11: 0.26042544 | AF11: 1 | AH11: =IF(BI11="","",$BS11/BI11) -> 0.76923077 | AI11: =IF(BJ11="","",$BS11/BJ11) -> 0.76923077 | AJ11: =IF(BK11="","",$BS11/BK11) -> 0.76923077 | AK11: =IF(BL11="","",$BS11/BL11) -> 0.76923077 | AL11: =IF(BM11="","",$BS11/BM11) -> 0.76923077 | AM11: =IF(BN11="","",$BS11/BN11) -> 0.76923077 | AN11: =IF(BO11="","",$BS11/BO11) -> 0.76923077 | AO11: =IF(BP11="","",$BS11/BP11) -> 0.76923077 | ... AQ11: =IF(BR11="","",$BS11/BR11) -> 0.76923077 | BB11: =IF(AW11="","",AW11) | BC11: =IF(AX11="","",AX11) | BD11: =IF(AY11="","",AY11) | BE11: =IF(AZ11="","",AZ11) | BF11: =IF(BA11="","",BA11) | BI11: 1.3 | BJ11: =IF(BI11="","",BI11) -> 1.3 | BK11: 1.3 | BL11: 1.3 | BM11: 1.3 | BN11: 1.3 | BO11: 1.3 | BP11: 1.3 | BQ11: 1.3 | BR11: 1.3 | BS11: 1
B12: * | C12: IOTEFEDRFL | D12: Other Industry Residual Oil Feedstock | E12: PJ, PJ/a | F12: INDRFLEA | G12: IOTFEED | H12: 2010 | I12: 30 | J12: 1 | K12: 0.15 | L12: =IFERROR(IF(_xlfn.XLOOKUP(D12,tbl_tech[TECHNOLOGY - Other],tbl_tech[NCAP_COST])=0,"",_xlfn.XLOOKUP(D12,tbl_tech[TECHNOLOGY - Other],tbl_tech[NCAP_COST])),"") | M12: =IFERROR(IF(_xlfn.XLOOKUP(D12,tbl_tech[TECHNOLOGY - Other],tbl_tech[NCAP_FOM])=0,"",_xlfn.XLOOKUP(D12,tbl_tech[TECHNOLOGY - Other],tbl_tech[NCAP_FOM])),"") | N12: 0 | V12: 0 | W12: 0 | X12: 0 | Y12: 0.14511207 | Z12: 0.1264863 | AF12: 1 | AH12: =IF(BI12="","",$BS12/BI12) -> 1 | AI12: =IF(BJ12="","",$BS12/BJ12) -> 1 | AJ12: =IF(BK12="","",$BS12/BK12) -> 1.0050251 | AK12: =IF(BL12="","",$BS12/BL12) -> 1.010101 | AL12: =IF(BM12="","",$BS12/BM12) -> 1.0152284 | AM12: =IF(BN12="","",$BS12/BN12) -> 1.0204082 | AN12: =IF(BO12="","",$BS12/BO12) -> 1.025641 | AO12: =IF(BP12="","",$BS12/BP12) -> 1.0309278 | ... AQ12: =IF(BR12="","",$BS12/BR12) -> 1.0416667 | BB12: =IF(AW12="","",AW12) | BC12: =IF(AX12="","",AX12) | BD12: =IF(AY12="","",AY12) | BE12: =IF(AZ12="","",AZ12) | BF12: =IF(BA12="","",BA12) | BI12: 1 | BJ12: =IF(BI12="","",BI12) -> 1 | BK12: 0.995 | BL12: 0.99 | BM12: 0.985 | BN12: 0.98 | BO12: 0.975 | BP12: 0.97 | BQ12: 0.965 | BR12: 0.96 | BS12: 1
B13: * | C13: IOTEFEDDST | D13: Other Industry Distillate Oil Feedstock | E13: PJ, PJ/a | F13: INDDSTEA | G13: IOTFEED | H13: 2010 | I13: 30 | J13: 1 | K13: 0.15 | L13: =IFERROR(IF(_xlfn.XLOOKUP(D13,tbl_tech[TECHNOLOGY - Other],tbl_tech[NCAP_COST])=0,"",_xlfn.XLOOKUP(D13,tbl_tech[TECHNOLOGY - Other],tbl_tech[NCAP_COST])),"") | M13: =IFERROR(IF(_xlfn.XLOOKUP(D13,tbl_tech[TECHNOLOGY - Other],tbl_tech[NCAP_FOM])=0,"",_xlfn.XLOOKUP(D13,tbl_tech[TECHNOLOGY - Other],tbl_tech[NCAP_FOM])),"") | N13: 0 | Q13: 0 | R13: 1.2765939 | S13: 0.5761375 | T13: 0.61199828 | U13: 0.45328451 | V13: 0.59133783 | W13: 0.48062378 | X13: 0.32553791 | Y13: 0.32906273 | Z13: 0.2868261 | AF13: 1 | AH13: =IF(BI13="","",$BS13/BI13) -> 1 | AI13: =IF(BJ13="","",$BS13/BJ13) -> 1 | AJ13: =IF(BK13="","",$BS13/BK13) -> 1.0050251 | AK13: =IF(BL13="","",$BS13/BL13) -> 1.010101 | AL13: =IF(BM13="","",$BS13/BM13) -> 1.0152284 | AM13: =IF(BN13="","",$BS13/BN13) -> 1.0204082 | AN13: =IF(BO13="","",$BS13/BO13) -> 1.025641 | AO13: =IF(BP13="","",$BS13/BP13) -> 1.0309278 | ... AQ13: =IF(BR13="","",$BS13/BR13) -> 1.0416667 | BB13: =IF(AW13="","",AW13) | BC13: =IF(AX13="","",AX13) | BD13: =IF(AY13="","",AY13) | BE13: =IF(AZ13="","",AZ13) | BF13: =IF(BA13="","",BA13) | BI13: 1 | BJ13: =IF(BI13="","",BI13) -> 1 | BK13: 0.995 | BL13: 0.99 | BM13: 0.985 | BN13: 0.98 | BO13: 0.975 | BP13: 0.97 | BQ13: 0.965 | BR13: 0.96 | BS13: 1
