Workbook
Name _1995_Implicit_GDP_Deflator: Lighting!#REF!
Name _2001_Implicit_GDP_Deflator: Lighting!#REF!
Name act_foundp: #REF!
Name act_foundp: '[1]WithReg-Coke'!$N$120
Name act_furnp: #REF!
Name act_furnp: '[1]WithReg-Coke'!$M$120
Name AnswerData: #REF!
Name AnswerData: #REF!
Name avg_water_heater_PJ: #REF!
Name avg_water_heater_PJ: #REF!
Name avg_water_heater_PJ: #REF!
Name avg_water_heater_PJ: #REF!
Name avg_water_heater_PJ: #REF!
Name avg_water_heater_PJ: #REF!
Name base_foundp: #REF!
Name base_foundp: #REF!
Name base_furnp: #REF!
Name base_furnp: #REF!
Name base_steelp: #REF!
Name base_steelp: '[1]Baseline-Steel Mill Products'!$K$39
Name bprint: #REF!
Name bprint: #REF!
Name btu_per_mmbtu: 'Conv Factors'!$C$13
Name btu_per_watthr: #REF!
Name btu_per_watthr: 'Conv Factors'!$C$6
Name BTUtoPJ: 'conversion factors'!$B$7
Name cfm_hrs_per_trillion_cfm_hrs: 'Conv Factors'!$C$9
Name CMM_SUPPLY_CRV_TABLE: #REF!
Name CMM_SUPPLY_CRV_TABLE: [2]cum2025curves!#REF!
Name cprint: #REF!
Name cprint: #REF!
Name days_per_year: #REF!
Name Days_per_year: 'Conv Factors'!$C$4
Name DCF: #REF!
Name DCF: [3]ReadMe!$D$49
Name DenatEthPJperGal: 'conversion factors'!$B$17
Name dollar____per__m: #REF!
Name dollar____per__m: 'Conv Factors'!$C$8
Name dolomite_conv: #REF!
Name dolomite_conv: #REF!
Name dolomite_conv_13: #REF!
Name dolomite_conv_13: #REF!
Name Domestic: #REF!
Name Domestic: '[4]Dom Calcs'!$P$22
Name Domestic_12: #REF!
Name Domestic_12: '[5]Dom Calcs'!$P$22
Name Domestic_13: #REF!
Name Domestic_13: '[6]Dom Calcs'!$P$22
Name EthanolPJperGal: 'conversion factors'!$B$16
Name Excel_BuiltIn__FilterDatabase_2: #REF!
Name Excel_BuiltIn__FilterDatabase_2: '[7]CRF Reporter'!$A$1:$AA$55
Name exch_rate: #REF!
Name exch_rate: #REF!
Name FID_1: #REF!
Name FID_1: [8]AGR_Fuels!$A$2
Name fitfile: #REF!
Name fitfile: [9]MODEL!$D$38
Name FO2_l_to_gj: 'Conv Factors'!$C$23
Name FO4_l_to_gj: 'Conv Factors'!$C$24
Name FO6_l_to_gj: 'Conv Factors'!$C$25

Sheet ANSv6.1-Commodities
A1: ANSWER-Commodities
B7: CommName | C7: CommDesc | D7: CommUnit | E7: Set Memberships | F7: Comment

Sheet ANSv6.1-Technologies
A1: ANSWER-Technologies
B7: TechName | C7: TechDesc | D7: TACTUnit | E7: TCAPUnit | F7: Set Memberships | G7: Comment

Sheet Commodities
B1: Commodities | D1: _GLOBAL,R0,R1,R2,R3,R4,R5,R6
B6: ~FI_Comm
B7: Region | C7: Csets | D7: CommName | E7: CommDesc | F7: Unit | G7: LimType | H7: CTSLvl | I7: PeakTS | J7: Ctype
B8: *Demands
B9: R2,R3,R4,R5,R6 | C9: DEM | D9: RSC | E9: Residential Cooling | F9: PJ
B10: * | C10: DEM | D10: RFZ | E10: Residential Freezing | F10: PJ
B11: R2,R3,R4,R5,R6 | C11: DEM | D11: RSH | E11: Residential Heating | F11: PJ
B12: R2,R3,R4,R5,R6 | C12: DEM | D12: RLT | E12: Residential Lighting | F12: bn-lum-yr
B13: R2,R3,R4,R5,R6 | C13: DEM | D13: ROE | E13: Residential Other Appliances - ELC | F13: PJ
B14: R2,R3,R4,R5,R6 | C14: DEM | D14: ROG | E14: Residential Other Appliances - NGA | F14: PJ
B15: * | C15: DEM | D15: ROL | E15: Residential Other Appliances - LPG | F15: PJ
B16: * | C16: DEM | D16: RRF | E16: Residential Refrigeration | F16: PJ
B17: R2,R3,R4,R5,R6 | C17: DEM | D17: RWH | E17: Residential Water Heating | F17: PJ
B18: *Energy Carriers
B19: R2,R3,R4,R5,R6 | C19: NRG | D19: RESELC | E19: Electricity to Residential Sector | F19: PJ | H19: DAYNITE | I19: ANNUAL | J19: ELC
B20: R2,R3,R4,R5,R6 | C20: NRG | D20: RESNGAEA | E20: Natural Gas to Residential Sector | F20: PJ
B21: R2,R3,R4,R5,R6 | C21: NRG | D21: RESCOAEA | E21: Coal to Residential Sector | F21: PJ
B22: R2,R3,R4,R5,R6 | C22: NRG | D22: RESDSLEA | E22: Diesel to Residential Sector | F22: PJ
B23: *R2,R3,R4,R5,R6 | C23: NRG | D23: RESKEREA | E23: Kerosene to Residential Sector | F23: PJ
B24: *R2,R3,R4,R5,R6 | C24: NRG | D24: RESLPGEA | E24: LPG to Residential Sector | F24: PJ
B25: *R2,R3,R4,R5,R6 | C25: NRG | D25: RESBIOEA | E25: Biomass-wood to Residential Sector after emissions | F25: PJ
B26: *CHP Energy Carriers
B27: R1,R2,R3,R4,R5,R6 | C27: NRG | D27: RESSTNUC | E27: STM from Residential NGA Utility-scale CHP | F27: PJ
B28: R1,R2,R3,R4,R5,R6 | C28: NRG | D28: RESSTBUC | E28: STM from Residential DST Utility-scale CHP | F28: PJ
B29: R2,R3,R4,R5,R6 | C29: NRG | D29: RESSTNB | E29: STM from Commercial NGA Boilers | F29: PJ
B30: R2,R3,R4,R5,R6 | C30: NRG | D30: RESSTDB | E30: STM from Commercial DST Boilers | F30: PJ
B31: *Residential End Use Water Commodities for Demand Pass Through Technologies
B32: R2,R3,R4,R5,R6 | C32: MAT | D32: RBLDLEDMY | E32: Dummy water commodity for low eff buildings | F32: Mt
B33: *R2,R3,R4,R5,R6 | C33: MAT | D33: RBLDMEDMY | E33: Dummy water commodity for medium eff buildings | F33: Mt
B34: R2,R3,R4,R5,R6 | C34: MAT | D34: RBLDHEDMY | E34: Dummy water commodity for high eff buildings | F34: Mt
B35: R2,R3,R4,R5,R6 | C35: MAT | D35: RBROOFDMY | E35: Dummy water commodity for black roofs | F35: Mt
B36: R2,R3,R4,R5,R6 | C36: MAT | D36: RWTROOFDMY | E36: Dummy water commodity for white roofs | F36: Mt
B37: R2,R3,R4,R5,R6 | C37: MAT | D37: RGRF6DMY | E37: Dummy water commodity for green roofs | F37: Mt
B38: R2,R3,R4,R5,R6 | C38: MAT | D38: RGRF12DMY | E38: Dummy water commodity for green roofs | F38: Mt
B39: *Roof/GI Heating & Cooling Commodities
B40: *R2,R3,R4,R5,R6 | C40: NRG | D40: RHCRFBLK | E40: Heating/cooling from black roofs | F40: PJ
B41: *R2,R3,R4,R5,R6 | C41: NRG | D41: RHCRFWT | E41: Heating/cooling from white roofs | F41: PJ
B42: *R2,R3,R4,R5,R6 | C42: NRG | D42: RHCRFG6 | E42: Heating/cooling from 6 inch green roof | F42: PJ
B43: *R2,R3,R4,R5,R6 | C43: NRG | D43: RHCRFG12 | E43: Heating/cooling from 12 inch green roof | F43: PJ
B44: *Demand Commodities for NYC Population
...

Sheet Technologies
B1: Technologies | D1: _GLOBAL,R0,R1,R2,R3,R4,R5,R6
B6: ~FI_Process
B7: Region | C7: Sets | D7: TechName | E7: TechDesc | F7: Tact | G7: Tcap | H7: PrimaryCG | I7: Vintage | J7: Tslvl
B8: *Space Heating
B9: *Electric Radiant
B10: =TechData_DMD!A10 -> R2,R3,R4,R5,R6 | C10: DMD | D10: =TechData_DMD!B10 -> RSHERDV110 | E10: =TechData_DMD!C10 -> Electric Radiant Ver1.RSH.ELC.10 | F10: PJ | G10: PJ/a
B11: *Electric Resistance Furnaces
B12: *Electric Heat Pump
B13: =TechData_DMD!A13 -> R2,R3,R4,R5,R6 | C13: DMD | D13: =TechData_DMD!B13 -> RSHEHPV110 | E13: =TechData_DMD!C13 -> Electric Heat Pump Ver1.RSH.ELC.10 | F13: PJ | G13: PJ/a
B14: *Natural Gas Furnace
B15: =TechData_DMD!A15 -> R2,R3,R4,R5,R6 | C15: DMD | D15: =TechData_DMD!B15 -> RSHNFRV110 | E15: =TechData_DMD!C15 -> Natural Gas Furnace Ver1.RSH.NGA.10 | F15: PJ | G15: PJ/a
B16: *Natural Gas Radiant
B17: =TechData_DMD!A17 -> R2,R3,R4,R5,R6 | C17: DMD | D17: =TechData_DMD!B17 -> RSHNRDV110 | E17: =TechData_DMD!C17 -> Natural Gas Radiant Ver1.RSH.NGA.10 | F17: PJ | G17: PJ/a
B18: *Kerosene Furnace
B19: *Liquid Gas Furnace
B20: *Distillate Furnace
B21: =TechData_DMD!A21 -> R2,R3,R4,R5,R6 | C21: DMD | D21: =TechData_DMD!B21 -> RSHDFRV110 | E21: =TechData_DMD!C21 -> Distillate Furnace Ver1.RSH.DST.10 | F21: PJ | G21: PJ/a
B22: *Distillate Radiant
B23: =TechData_DMD!A23 -> R2,R3,R4,R5,R6 | C23: DMD | D23: =TechData_DMD!B23 -> RSHDRDV110 | E23: =TechData_DMD!C23 -> Distillate Radiant Ver1.RSH.DST.10 | F23: PJ | G23: PJ/a
B24: *Boiler district energy
B25: R4 | C25: DMD | D25: =TechData_CHP!B7 -> RESBLDBS05 | E25: =TechData_CHP!C7 -> RES.DSL.BOILER.DISTRICTHEAT.BS | F25: PJ | G25: PJ/a
B26: R4 | C26: DMD | D26: =TechData_CHP!B8 -> RESBLNG10 | E26: =TechData_CHP!C8 -> RES.NG.BOILER.DISTRICTHEAT.10 | F26: PJ | G26: PJ/a
B27: *UTILITY SCALE CHP - SH
B28: R4 | C28: DMD | D28: =TechData_DMD!B25 -> RSHNUTIBOI | E28: =TechData_DMD!C25 -> RSH.NG.UTILITY.BOILER | F28: PJ | G28: PJa
B29: R4 | C29: DMD | D29: =TechData_DMD!B26 -> RSHNUTICHP | E29: =TechData_DMD!C26 -> RSH.NG.UTILITY.CHP | F29: PJ | G29: PJa
B30: R4 | C30: DMD | D30: =TechData_DMD!B27 -> RSHBUTICHP | E30: =TechData_DMD!C27 -> RSH.DSL.UTILITY.CHP | F30: PJ | G30: PJa
B31: *Wood
B32: *Geothermal Heat Pump
B33: *Natural Gas Heat Pump
B34: *Space Cooling
B35: *Room AC
B36: =TechData_DMD!A33 -> R2,R3,R4,R5,R6 | C36: DMD | D36: =TechData_DMD!B33 -> RSCRACV110 | E36: =TechData_DMD!C33 -> Room AC Ver1.RSC.ELC.10 | F36: PJ | G36: PJ/a
B37: *Central AC
B38: =TechData_DMD!A35 -> R2,R3,R4,R5,R6 | C38: DMD | D38: =TechData_DMD!B35 -> RSCCACV110 | E38: =TechData_DMD!C35 -> Central AC Ver1.RSC.ELC.10 | F38: PJ | G38: PJ/a
B39: *Portable AC
B40: *Electric Heat Pump
B41: =TechData_DMD!A38 -> R2,R3,R4,R5,R6 | C41: DMD | D41: =TechData_DMD!B38 -> RSCEHPV110 | E41: =TechData_DMD!C38 -> Electric Heat Pump Ver1.RSC.ELC.10 | F41: PJ | G41: PJ/a
B42: *Geothermal Heat Pump
B43: *Natural Gas Heat Pump
B44: *Water Heating
...

Sheet CommData_DMD
A1: CommData | B1: _GLOBAL,R0,R1,R2,R3,R4,R5,R6
E4: ~FI_T
A5: Region | B5: CommName | C5: *CommDesc | D5: *Units | E5: COM_PROJ~2010 | F5: COM_PROJ~2015 | G5: COM_PROJ~2020 | H5: COM_PROJ~2025 | I5: COM_PROJ~2030 | J5: COM_PROJ~2035 | K5: COM_PROJ~2040 | L5: COM_PROJ~2045 | M5: COM_PROJ~2050 | N5: COM_PROJ~2055 | O5: COM_FR~IDAM | P5: COM_FR~IDPM | Q5: COM_FR~IN | R5: COM_FR~IP | S5: COM_FR~SDAM | T5: COM_FR~SDPM | U5: COM_FR~SN | V5: COM_FR~SP | W5: COM_FR~WDAM | X5: COM_FR~WDPM | Y5: COM_FR~WN | Z5: COM_FR~WP
A6: *Brooklyn
A7: R2 | B7: =Commodities!$D$9 -> RSC | C7: Residential Cooling | D7: PJ | E7: =(1-DmdCalc!R$6)*Pop!D103*Pop!D$49*Pop!D24*Pop!D113/PJ_to_BTU -> 9.427232 | F7: =(1-DmdCalc!S$6)*Pop!E103*Pop!E$49*Pop!E24*Pop!E113/PJ_to_BTU -> 9.2041854 | G7: =(1-DmdCalc!T$6)*Pop!F103*Pop!F$49*Pop!F24*Pop!F113/PJ_to_BTU -> 9.6137311 | H7: =(1-DmdCalc!U$6)*Pop!G103*Pop!G$49*Pop!G24*Pop!G113/PJ_to_BTU -> 9.3917216 | I7: =(1-DmdCalc!V$6)*Pop!H103*Pop!H$49*Pop!H24*Pop!H113/PJ_to_BTU -> 9.2792535 | J7: =(1-DmdCalc!W$6)*Pop!I103*Pop!I$49*Pop!I24*Pop!I113/PJ_to_BTU -> 9.3555513 | K7: =(1-DmdCalc!X$6)*Pop!J103*Pop!J$49*Pop!J24*Pop!J113/PJ_to_BTU -> 10.173151 | L7: =(1-DmdCalc!Y$6)*Pop!K103*Pop!K$49*Pop!K24*Pop!K113/PJ_to_BTU -> 10.180276 | ... N7: =(1-DmdCalc!AA$6)*Pop!M103*Pop!M$49*Pop!M24*Pop!M113/PJ_to_BTU -> 10.837579 | O7: 0.0166 | P7: 0.0577 | Q7: 0.0254 | R7: 0.0022 | S7: 0.1552 | T7: 0.5033 | U7: 0.2118 | V7: 0.0192 | W7: 0.0026 | X7: 0.0026 | Y7: 0.0033 | Z7: 0.0001
A8: *R2 | B8: =Commodities!$D$10 -> RFZ | C8: Residential Freezing | D8: PJ | O8: 0.0795 | P8: 0.1018 | Q8: 0.1482 | R8: 0.0034 | S8: 0.1033 | T8: 0.1284 | U8: 0.1341 | V8: 0.0034 | W8: 0.0715 | X8: 0.1017 | Y8: 0.1217 | Z8: 0.003
A9: R2 | B9: =Commodities!$D$11 -> RSH | C9: Residential Heating | D9: PJ | E9: =Pop!D95*Pop!D$49*Pop!D24*Pop!D121/PJ_to_BTU -> 44.265367 | F9: =Pop!E95*Pop!E$49*Pop!E24*Pop!E121/PJ_to_BTU -> 44.376666 | G9: =Pop!F95*Pop!F$49*Pop!F24*Pop!F121/PJ_to_BTU -> 37.391626 | H9: =Pop!G95*Pop!G$49*Pop!G24*Pop!G121/PJ_to_BTU -> 43.801347 | I9: =Pop!H95*Pop!H$49*Pop!H24*Pop!H121/PJ_to_BTU -> 42.122428 | J9: =Pop!I95*Pop!I$49*Pop!I24*Pop!I121/PJ_to_BTU -> 39.97184 | K9: =Pop!J95*Pop!J$49*Pop!J24*Pop!J121/PJ_to_BTU -> 36.665712 | L9: =Pop!K95*Pop!K$49*Pop!K24*Pop!K121/PJ_to_BTU -> 35.166738 | ... N9: =Pop!M95*Pop!M$49*Pop!M24*Pop!M121/PJ_to_BTU -> 31.255487 | O9: 0.0824 | P9: 0.0706 | Q9: 0.1213 | R9: 0.004 | S9: 0.0103 | T9: 0.0059 | U9: 0.0074 | V9: 0.0002 | W9: 0.1947 | X9: 0.1751 | Y9: 0.3194 | Z9: 0.0087
A10: R2 | B10: =Commodities!$D$12 -> RLT | C10: Residential Lighting | D10: =Commodities!$F$12 -> bn-lum-yr | E10: =DmdCalc!E$7*Pop!D24/Pop!D$28 -> 2.841194 | F10: =DmdCalc!F$7*Pop!E24/Pop!E$28 -> 2.7230091 | G10: =DmdCalc!G$7*Pop!F24/Pop!F$28 -> 2.5743822 | H10: =DmdCalc!H$7*Pop!G24/Pop!G$28 -> 0.89649269 | I10: =DmdCalc!I$7*Pop!H24/Pop!H$28 -> 0.91090786 | J10: =DmdCalc!J$7*Pop!I24/Pop!I$28 -> 0.912049 | K10: =DmdCalc!K$7*Pop!J24/Pop!J$28 -> 0.9103326 | L10: =DmdCalc!L$7*Pop!K24/Pop!K$28 -> 0.87873969 | ... N10: =DmdCalc!N$7*Pop!M24/Pop!M$28 -> 0.89278797 | O10: 0.0627 | P10: 0.09 | Q10: 0.1773 | R10: 0.0033 | S10: 0.0591 | T10: 0.0914 | U10: 0.1315 | V10: 0.0014 | W10: 0.0742 | X10: 0.1447 | Y10: 0.1595 | Z10: 0.0049
A11: R2 | B11: =Commodities!$D$13 -> ROE | C11: Residential Other Appliances - ELC | D11: PJ | E11: =DmdCalc!E$8*Pop!D24/Pop!D$28 -> 8.9321044 | F11: =DmdCalc!F$8*Pop!E24/Pop!E$28 -> 8.5605564 | G11: =DmdCalc!G$8*Pop!F24/Pop!F$28 -> 8.0933054 | H11: =DmdCalc!H$8*Pop!G24/Pop!G$28 -> 10.02788 | I11: =DmdCalc!I$8*Pop!H24/Pop!H$28 -> 10.558734 | J11: =DmdCalc!J$8*Pop!I24/Pop!I$28 -> 11.109995 | K11: =DmdCalc!K$8*Pop!J24/Pop!J$28 -> 11.816972 | L11: =DmdCalc!L$8*Pop!K24/Pop!K$28 -> 12.652415 | ... N11: =DmdCalc!N$8*Pop!M24/Pop!M$28 -> 14.89615 | O11: 0.0892 | P11: 0.1211 | Q11: 0.1084 | R11: 0.0044 | S11: 0.0865 | T11: 0.1257 | U11: 0.0674 | V11: 0.0031 | W11: 0.1079 | X11: 0.1718 | Y11: 0.1091 | Z11: 0.0054
A12: R2 | B12: =Commodities!$D$14 -> ROG | C12: Residential Other Appliances - NGA | D12: PJ | E12: =DmdCalc!E$10*Pop!D24/Pop!D$28 -> 0.80672192 | F12: =DmdCalc!F$10*Pop!E24/Pop!E$28 -> 0.90430384 | G12: =DmdCalc!G$10*Pop!F24/Pop!F$28 -> 0.93116314 | H12: =DmdCalc!H$10*Pop!G24/Pop!G$28 -> 1.1069888 | I12: =DmdCalc!I$10*Pop!H24/Pop!H$28 -> 1.1309661 | J12: =DmdCalc!J$10*Pop!I24/Pop!I$28 -> 1.1469159 | K12: =DmdCalc!K$10*Pop!J24/Pop!J$28 -> 1.1681423 | L12: =DmdCalc!L$10*Pop!K24/Pop!K$28 -> 1.1886465 | ... N12: =DmdCalc!N$10*Pop!M24/Pop!M$28 -> 1.2282187
A13: *R2 | B13: =Commodities!$D$15 -> ROL | C13: Residential Other Appliances - LPG | D13: PJ
A14: *R2 | B14: =Commodities!$D$16 -> RRF | C14: Residential Refrigeration | D14: PJ | O14: 0.0788 | P14: 0.1045 | Q14: 0.1505 | R14: 0.0035 | S14: 0.1018 | T14: 0.1286 | U14: 0.1329 | V14: 0.0034 | W14: 0.0696 | X14: 0.1051 | Y14: 0.1181 | Z14: 0.0032
A15: R2 | B15: =Commodities!$D$17 -> RWH | C15: Residential Water Heating | D15: PJ | E15: =DmdCalc!E$5*Pop!D24/Pop!D$28 -> 11.919112 | F15: =DmdCalc!F$5*Pop!E24/Pop!E$28 -> 12.146867 | G15: =DmdCalc!G$5*Pop!F24/Pop!F$28 -> 11.708389 | H15: =DmdCalc!H$5*Pop!G24/Pop!G$28 -> 12.736536 | I15: =DmdCalc!I$5*Pop!H24/Pop!H$28 -> 11.953859 | J15: =DmdCalc!J$5*Pop!I24/Pop!I$28 -> 11.840225 | K15: =DmdCalc!K$5*Pop!J24/Pop!J$28 -> 11.793674 | L15: =DmdCalc!L$5*Pop!K24/Pop!K$28 -> 11.604949 | ... N15: =DmdCalc!N$5*Pop!M24/Pop!M$28 -> 11.115908 | O15: 0.1215 | P15: 0.1114 | Q15: 0.1279 | R15: 0.0053 | S15: 0.0868 | T15: 0.0892 | U15: 0.0653 | V15: 0.002 | W15: 0.1324 | X15: 0.1486 | Y15: 0.1042 | Z15: 0.0054
A16: *Bronx
A17: R3 | B17: =Commodities!$D$9 -> RSC | C17: Residential Cooling | D17: PJ | E17: =(1-DmdCalc!R$6)*Pop!D102*Pop!D$49*Pop!D23*Pop!D112/PJ_to_BTU -> 4.7126374 | F17: =(1-DmdCalc!S$6)*Pop!E102*Pop!E$49*Pop!E23*Pop!E112/PJ_to_BTU -> 4.6812323 | G17: =(1-DmdCalc!T$6)*Pop!F102*Pop!F$49*Pop!F23*Pop!F112/PJ_to_BTU -> 4.9571109 | H17: =(1-DmdCalc!U$6)*Pop!G102*Pop!G$49*Pop!G23*Pop!G112/PJ_to_BTU -> 4.9322943 | I17: =(1-DmdCalc!V$6)*Pop!H102*Pop!H$49*Pop!H23*Pop!H112/PJ_to_BTU -> 4.8372334 | J17: =(1-DmdCalc!W$6)*Pop!I102*Pop!I$49*Pop!I23*Pop!I112/PJ_to_BTU -> 4.8988356 | K17: =(1-DmdCalc!X$6)*Pop!J102*Pop!J$49*Pop!J23*Pop!J112/PJ_to_BTU -> 5.3499581 | L17: =(1-DmdCalc!Y$6)*Pop!K102*Pop!K$49*Pop!K23*Pop!K112/PJ_to_BTU -> 5.3024708 | ... N17: =(1-DmdCalc!AA$6)*Pop!M102*Pop!M$49*Pop!M23*Pop!M112/PJ_to_BTU -> 5.6205815 | O17: 0.0194 | P17: 0.0671 | Q17: 0.0298 | R17: 0.0026 | S17: 0.152 | T17: 0.493 | U17: 0.2074 | V17: 0.0188 | W17: 0.003 | X17: 0.003 | Y17: 0.0037 | Z17: 0.0002
A18: *R3 | B18: =Commodities!$D$10 -> RFZ | C18: Residential Freezing | D18: PJ | O18: 0.0795 | P18: 0.1018 | Q18: 0.1482 | R18: 0.0034 | S18: 0.1033 | T18: 0.1284 | U18: 0.1341 | V18: 0.0034 | W18: 0.0715 | X18: 0.1017 | Y18: 0.1217 | Z18: 0.003
A19: R3 | B19: =Commodities!$D$11 -> RSH | C19: Residential Heating | D19: PJ | E19: =Pop!D94*Pop!D$49*Pop!D23*Pop!D120/PJ_to_BTU -> 21.043435 | F19: =Pop!E94*Pop!E$49*Pop!E23*Pop!E120/PJ_to_BTU -> 21.513374 | G19: =Pop!F94*Pop!F$49*Pop!F23*Pop!F120/PJ_to_BTU -> 18.251944 | H19: =Pop!G94*Pop!G$49*Pop!G23*Pop!G120/PJ_to_BTU -> 21.213828 | I19: =Pop!H94*Pop!H$49*Pop!H23*Pop!H120/PJ_to_BTU -> 20.250009 | J19: =Pop!I94*Pop!I$49*Pop!I23*Pop!I120/PJ_to_BTU -> 19.302139 | K19: =Pop!J94*Pop!J$49*Pop!J23*Pop!J120/PJ_to_BTU -> 17.782092 | L19: =Pop!K94*Pop!K$49*Pop!K23*Pop!K120/PJ_to_BTU -> 16.891905 | ... N19: =Pop!M94*Pop!M$49*Pop!M23*Pop!M120/PJ_to_BTU -> 14.948687 | O19: 0.0779 | P19: 0.0668 | Q19: 0.1147 | R19: 0.0038 | S19: 0.0105 | T19: 0.006 | U19: 0.0075 | V19: 0.0002 | W19: 0.1989 | X19: 0.1787 | Y19: 0.3262 | Z19: 0.0088
A20: R3 | B20: =Commodities!$D$12 -> RLT | C20: Residential Lighting | D20: =Commodities!$F$12 -> bn-lum-yr | E20: =DmdCalc!E$7*Pop!D23/Pop!D$28 -> 1.4807422 | F20: =DmdCalc!F$7*Pop!E23/Pop!E$28 -> 1.4314466 | G20: =DmdCalc!G$7*Pop!F23/Pop!F$28 -> 1.3626364 | H20: =DmdCalc!H$7*Pop!G23/Pop!G$28 -> 0.47081526 | I20: =DmdCalc!I$7*Pop!H23/Pop!H$28 -> 0.4748522 | J20: =DmdCalc!J$7*Pop!I23/Pop!I$28 -> 0.47757508 | K20: =DmdCalc!K$7*Pop!J23/Pop!J$28 -> 0.47873481 | L20: =DmdCalc!L$7*Pop!K23/Pop!K$28 -> 0.45769797 | ... N20: =DmdCalc!N$7*Pop!M23/Pop!M$28 -> 0.46301739 | O20: 0.0627 | P20: 0.09 | Q20: 0.1773 | R20: 0.0033 | S20: 0.0591 | T20: 0.0914 | U20: 0.1315 | V20: 0.0014 | W20: 0.0742 | X20: 0.1447 | Y20: 0.1595 | Z20: 0.0049
A21: R3 | B21: =Commodities!$D$13 -> ROE | C21: Residential Other Appliances - ELC | D21: PJ | E21: =DmdCalc!E$8*Pop!D23/Pop!D$28 -> 4.6551357 | F21: =DmdCalc!F$8*Pop!E23/Pop!E$28 -> 4.5001609 | G21: =DmdCalc!G$8*Pop!F23/Pop!F$28 -> 4.2838366 | H21: =DmdCalc!H$8*Pop!G23/Pop!G$28 -> 5.2663888 | I21: =DmdCalc!I$8*Pop!H23/Pop!H$28 -> 5.5042207 | J21: =DmdCalc!J$8*Pop!I23/Pop!I$28 -> 5.8175126 | K21: =DmdCalc!K$8*Pop!J23/Pop!J$28 -> 6.2144276 | L21: =DmdCalc!L$8*Pop!K23/Pop!K$28 -> 6.5901023 | ... N21: =DmdCalc!N$8*Pop!M23/Pop!M$28 -> 7.7254362 | O21: 0.0892 | P21: 0.1211 | Q21: 0.1084 | R21: 0.0044 | S21: 0.0865 | T21: 0.1257 | U21: 0.0674 | V21: 0.0031 | W21: 0.1079 | X21: 0.1718 | Y21: 0.1091 | Z21: 0.0054
A22: R3 | B22: =Commodities!$D$14 -> ROG | C22: Residential Other Appliances - NGA | D22: PJ | E22: =DmdCalc!E$10*Pop!D23/Pop!D$28 -> 0.42043844 | F22: =DmdCalc!F$10*Pop!E23/Pop!E$28 -> 0.47537947 | G22: =DmdCalc!G$10*Pop!F23/Pop!F$28 -> 0.49287041 | H22: =DmdCalc!H$10*Pop!G23/Pop!G$28 -> 0.58136247 | I22: =DmdCalc!I$10*Pop!H23/Pop!H$28 -> 0.58956755 | J22: =DmdCalc!J$10*Pop!I23/Pop!I$28 -> 0.60055815 | K22: =DmdCalc!K$10*Pop!J23/Pop!J$28 -> 0.61431435 | L22: =DmdCalc!L$10*Pop!K23/Pop!K$28 -> 0.61911517 | ... N22: =DmdCalc!N$10*Pop!M23/Pop!M$28 -> 0.63697834
A23: *R3 | B23: =Commodities!$D$15 -> ROL | C23: Residential Other Appliances - LPG | D23: PJ
A24: *R3 | B24: =Commodities!$D$16 -> RRF | C24: Residential Refrigeration | D24: PJ | O24: 0.0788 | P24: 0.1045 | Q24: 0.1505 | R24: 0.0035 | S24: 0.1018 | T24: 0.1286 | U24: 0.1329 | V24: 0.0034 | W24: 0.0696 | X24: 0.1051 | Y24: 0.1181 | Z24: 0.0032
A25: R3 | B25: =Commodities!$D$17 -> RWH | C25: Residential Water Heating | D25: PJ | E25: =DmdCalc!E$5*Pop!D23/Pop!D$28 -> 6.2118713 | F25: =DmdCalc!F$5*Pop!E23/Pop!E$28 -> 6.3854327 | G25: =DmdCalc!G$5*Pop!F23/Pop!F$28 -> 6.1973228 | H25: =DmdCalc!H$5*Pop!G23/Pop!G$28 -> 6.6889062 | I25: =DmdCalc!I$5*Pop!H23/Pop!H$28 -> 6.2314932 | J25: =DmdCalc!J$5*Pop!I23/Pop!I$28 -> 6.1998822 | K25: =DmdCalc!K$5*Pop!J23/Pop!J$28 -> 6.2021754 | L25: =DmdCalc!L$5*Pop!K23/Pop!K$28 -> 6.0445222 | ... N25: =DmdCalc!N$5*Pop!M23/Pop!M$28 -> 5.7649281 | O25: 0.1215 | P25: 0.1114 | Q25: 0.1279 | R25: 0.0053 | S25: 0.0868 | T25: 0.0892 | U25: 0.0653 | V25: 0.002 | W25: 0.1324 | X25: 0.1486 | Y25: 0.1042 | Z25: 0.0054
A26: *Manhattan
A27: R4 | B27: =Commodities!$D$9 -> RSC | C27: Residential Cooling | D27: PJ | E27: =(1-DmdCalc!R$6)*Pop!D104*Pop!D$49*Pop!D25*Pop!D114/PJ_to_BTU -> 7.2268707 | F27: =(1-DmdCalc!S$6)*Pop!E104*Pop!E$49*Pop!E25*Pop!E114/PJ_to_BTU -> 7.6093011 | G27: =(1-DmdCalc!T$6)*Pop!F104*Pop!F$49*Pop!F25*Pop!F114/PJ_to_BTU -> 7.336496 | H27: =(1-DmdCalc!U$6)*Pop!G104*Pop!G$49*Pop!G25*Pop!G114/PJ_to_BTU -> 7.6402481 | I27: =(1-DmdCalc!V$6)*Pop!H104*Pop!H$49*Pop!H25*Pop!H114/PJ_to_BTU -> 7.7120931 | J27: =(1-DmdCalc!W$6)*Pop!I104*Pop!I$49*Pop!I25*Pop!I114/PJ_to_BTU -> 7.6891359 | K27: =(1-DmdCalc!X$6)*Pop!J104*Pop!J$49*Pop!J25*Pop!J114/PJ_to_BTU -> 8.2700836 | L27: =(1-DmdCalc!Y$6)*Pop!K104*Pop!K$49*Pop!K25*Pop!K114/PJ_to_BTU -> 8.3333903 | ... N27: =(1-DmdCalc!AA$6)*Pop!M104*Pop!M$49*Pop!M25*Pop!M114/PJ_to_BTU -> 8.8828218 | O27: 0.0311 | P27: 0.102 | Q27: 0.0493 | R27: 0.004 | S27: 0.133 | T27: 0.4322 | U27: 0.1813 | V27: 0.0165 | W27: 0.0151 | X27: 0.0155 | Y27: 0.0192 | Z27: 0.0008
A28: *R4 | B28: =Commodities!$D$10 -> RFZ | C28: Residential Freezing | D28: PJ | O28: 0.0795 | P28: 0.1018 | Q28: 0.1482 | R28: 0.0034 | S28: 0.1033 | T28: 0.1284 | U28: 0.1341 | V28: 0.0034 | W28: 0.0715 | X28: 0.1017 | Y28: 0.1217 | Z28: 0.003
A29: R4 | B29: =Commodities!$D$11 -> RSH | C29: Residential Heating | D29: PJ | E29: =Pop!D96*Pop!D$49*Pop!D25*Pop!D122/PJ_to_BTU -> 37.294841 | F29: =Pop!E96*Pop!E$49*Pop!E25*Pop!E122/PJ_to_BTU -> 39.427265 | G29: =Pop!F96*Pop!F$49*Pop!F25*Pop!F122/PJ_to_BTU -> 31.917949 | H29: =Pop!G96*Pop!G$49*Pop!G25*Pop!G122/PJ_to_BTU -> 38.271352 | I29: =Pop!H96*Pop!H$49*Pop!H25*Pop!H122/PJ_to_BTU -> 37.600767 | J29: =Pop!I96*Pop!I$49*Pop!I25*Pop!I122/PJ_to_BTU -> 35.284696 | K29: =Pop!J96*Pop!J$49*Pop!J25*Pop!J122/PJ_to_BTU -> 32.013904 | L29: =Pop!K96*Pop!K$49*Pop!K25*Pop!K122/PJ_to_BTU -> 30.918495 | ... N29: =Pop!M96*Pop!M$49*Pop!M25*Pop!M122/PJ_to_BTU -> 27.514968 | O29: 0.0732 | P29: 0.0627 | Q29: 0.1077 | R29: 0.0036 | S29: 0.0043 | T29: 0.0025 | U29: 0.0031 | V29: 0.0001 | W29: 0.2073 | X29: 0.1863 | Y29: 0.34 | Z29: 0.0092
A30: R4 | B30: =Commodities!$D$12 -> RLT | C30: Residential Lighting | D30: =Commodities!$F$12 -> bn-lum-yr | E30: =DmdCalc!E$7*Pop!D25/Pop!D$28 -> 2.2631958 | F30: =DmdCalc!F$7*Pop!E25/Pop!E$28 -> 2.2525114 | G30: =DmdCalc!G$7*Pop!F25/Pop!F$28 -> 2.0460186 | H30: =DmdCalc!H$7*Pop!G25/Pop!G$28 -> 0.72930468 | I30: =DmdCalc!I$7*Pop!H25/Pop!H$28 -> 0.75706588 | J30: =DmdCalc!J$7*Pop!I25/Pop!I$28 -> 0.74959439 | K30: =DmdCalc!K$7*Pop!J25/Pop!J$28 -> 0.74003886 | L30: =DmdCalc!L$7*Pop!K25/Pop!K$28 -> 0.71932047 | ... N30: =DmdCalc!N$7*Pop!M25/Pop!M$28 -> 0.73175719 | O30: 0.0627 | P30: 0.09 | Q30: 0.1773 | R30: 0.0033 | S30: 0.0591 | T30: 0.0914 | U30: 0.1315 | V30: 0.0014 | W30: 0.0742 | X30: 0.1447 | Y30: 0.1595 | Z30: 0.0049
A31: R4 | B31: =Commodities!$D$13 -> ROE | C31: Residential Other Appliances - ELC | D31: PJ | E31: =DmdCalc!E$8*Pop!D25/Pop!D$28 -> 7.1150021 | F31: =DmdCalc!F$8*Pop!E25/Pop!E$28 -> 7.0814124 | G31: =DmdCalc!G$8*Pop!F25/Pop!F$28 -> 6.4322435 | H31: =DmdCalc!H$8*Pop!G25/Pop!G$28 -> 8.1577688 | I31: =DmdCalc!I$8*Pop!H25/Pop!H$28 -> 8.7754836 | J31: =DmdCalc!J$8*Pop!I25/Pop!I$28 -> 9.131077 | K31: =DmdCalc!K$8*Pop!J25/Pop!J$28 -> 9.6063997 | L31: =DmdCalc!L$8*Pop!K25/Pop!K$28 -> 10.357039 | ... N31: =DmdCalc!N$8*Pop!M25/Pop!M$28 -> 12.209355 | O31: 0.0892 | P31: 0.1211 | Q31: 0.1084 | R31: 0.0044 | S31: 0.0865 | T31: 0.1257 | U31: 0.0674 | V31: 0.0031 | W31: 0.1079 | X31: 0.1718 | Y31: 0.1091 | Z31: 0.0054
A32: R4 | B32: =Commodities!$D$14 -> ROG | C32: Residential Other Appliances - NGA | D32: PJ | E32: =DmdCalc!E$10*Pop!D25/Pop!D$28 -> 0.64260648 | F32: =DmdCalc!F$10*Pop!E25/Pop!E$28 -> 0.74805283 | G32: =DmdCalc!G$10*Pop!F25/Pop!F$28 -> 0.74005215 | H32: =DmdCalc!H$10*Pop!G25/Pop!G$28 -> 0.9005451 | I32: =DmdCalc!I$10*Pop!H25/Pop!H$28 -> 0.93995875 | J32: =DmdCalc!J$10*Pop!I25/Pop!I$28 -> 0.9426267 | K32: =DmdCalc!K$10*Pop!J25/Pop!J$28 -> 0.94962071 | L32: =DmdCalc!L$10*Pop!K25/Pop!K$28 -> 0.97300458 | ... N32: =DmdCalc!N$10*Pop!M25/Pop!M$28 -> 1.0066868
A33: *R4 | B33: =Commodities!$D$15 -> ROL | C33: Residential Other Appliances - LPG | D33: PJ
A34: *R4 | B34: =Commodities!$D$16 -> RRF | C34: Residential Refrigeration | D34: PJ | O34: 0.0788 | P34: 0.1045 | Q34: 0.1505 | R34: 0.0035 | S34: 0.1018 | T34: 0.1286 | U34: 0.1329 | V34: 0.0034 | W34: 0.0696 | X34: 0.1051 | Y34: 0.1181 | Z34: 0.0032
A35: R4 | B35: =Commodities!$D$17 -> RWH | C35: Residential Water Heating | D35: PJ | E35: =DmdCalc!E$5*Pop!D25/Pop!D$28 -> 9.4943477 | F35: =DmdCalc!F$5*Pop!E25/Pop!E$28 -> 10.048059 | G35: =DmdCalc!G$5*Pop!F25/Pop!F$28 -> 9.3053712 | H35: =DmdCalc!H$5*Pop!G25/Pop!G$28 -> 10.361284 | I35: =DmdCalc!I$5*Pop!H25/Pop!H$28 -> 9.934988 | J35: =DmdCalc!J$5*Pop!I25/Pop!I$28 -> 9.7312384 | K35: =DmdCalc!K$5*Pop!J25/Pop!J$28 -> 9.5874599 | L35: =DmdCalc!L$5*Pop!K25/Pop!K$28 -> 9.4996021 | ... N35: =DmdCalc!N$5*Pop!M25/Pop!M$28 -> 9.1109486 | O35: 0.1215 | P35: 0.1114 | Q35: 0.1279 | R35: 0.0053 | S35: 0.0868 | T35: 0.0892 | U35: 0.0653 | V35: 0.002 | W35: 0.1324 | X35: 0.1486 | Y35: 0.1042 | Z35: 0.0054
A36: *Staten Island
A37: R5 | B37: =Commodities!$D$9 -> RSC | C37: Residential Cooling | D37: PJ | E37: =(1-DmdCalc!R$6)*Pop!D106*Pop!D$49*Pop!D27*Pop!D116/PJ_to_BTU -> 1.7162587 | F37: =(1-DmdCalc!S$6)*Pop!E106*Pop!E$49*Pop!E27*Pop!E116/PJ_to_BTU -> 1.6990831 | G37: =(1-DmdCalc!T$6)*Pop!F106*Pop!F$49*Pop!F27*Pop!F116/PJ_to_BTU -> 1.5939977 | H37: =(1-DmdCalc!U$6)*Pop!G106*Pop!G$49*Pop!G27*Pop!G116/PJ_to_BTU -> 1.6158227 | I37: =(1-DmdCalc!V$6)*Pop!H106*Pop!H$49*Pop!H27*Pop!H116/PJ_to_BTU -> 1.6130755 | J37: =(1-DmdCalc!W$6)*Pop!I106*Pop!I$49*Pop!I27*Pop!I116/PJ_to_BTU -> 1.6063549 | K37: =(1-DmdCalc!X$6)*Pop!J106*Pop!J$49*Pop!J27*Pop!J116/PJ_to_BTU -> 1.7256772 | L37: =(1-DmdCalc!Y$6)*Pop!K106*Pop!K$49*Pop!K27*Pop!K116/PJ_to_BTU -> 1.7267736 | ... N37: =(1-DmdCalc!AA$6)*Pop!M106*Pop!M$49*Pop!M27*Pop!M116/PJ_to_BTU -> 1.8221133 | O37: 0.0292 | P37: 0.0972 | Q37: 0.0462 | R37: 0.0038 | S37: 0.1364 | T37: 0.4432 | U37: 0.186 | V37: 0.017 | W37: 0.0122 | X37: 0.0125 | Y37: 0.0156 | Z37: 0.0007
A38: *R5 | B38: =Commodities!$D$10 -> RFZ | C38: Residential Freezing | D38: PJ | O38: 0.0795 | P38: 0.1018 | Q38: 0.1482 | R38: 0.0034 | S38: 0.1033 | T38: 0.1284 | U38: 0.1341 | V38: 0.0034 | W38: 0.0715 | X38: 0.1017 | Y38: 0.1217 | Z38: 0.003
A39: R5 | B39: =Commodities!$D$11 -> RSH | C39: Residential Heating | D39: PJ | E39: =Pop!D98*Pop!D$49*Pop!D27*Pop!D124/PJ_to_BTU -> 10.042388 | F39: =Pop!E98*Pop!E$49*Pop!E27*Pop!E124/PJ_to_BTU -> 9.4413972 | G39: =Pop!F98*Pop!F$49*Pop!F27*Pop!F124/PJ_to_BTU -> 7.5394413 | H39: =Pop!G98*Pop!G$49*Pop!G27*Pop!G124/PJ_to_BTU -> 8.9307806 | I39: =Pop!H98*Pop!H$49*Pop!H27*Pop!H124/PJ_to_BTU -> 8.6777771 | J39: =Pop!I98*Pop!I$49*Pop!I27*Pop!I124/PJ_to_BTU -> 8.133542 | K39: =Pop!J98*Pop!J$49*Pop!J27*Pop!J124/PJ_to_BTU -> 7.3708516 | L39: =Pop!K98*Pop!K$49*Pop!K27*Pop!K124/PJ_to_BTU -> 7.0690553 | ... N39: =Pop!M98*Pop!M$49*Pop!M27*Pop!M124/PJ_to_BTU -> 6.22763 | O39: 0.0728 | P39: 0.0625 | Q39: 0.1074 | R39: 0.0036 | S39: 0.0047 | T39: 0.0027 | U39: 0.0033 | V39: 0.0001 | W39: 0.2074 | X39: 0.1863 | Y39: 0.34 | Z39: 0.0092
A40: R5 | B40: =Commodities!$D$12 -> RLT | C40: Residential Lighting | D40: =Commodities!$F$12 -> bn-lum-yr | E40: =DmdCalc!E$7*Pop!D27/Pop!D$28 -> 0.50653993 | F40: =DmdCalc!F$7*Pop!E27/Pop!E$28 -> 0.48885183 | G40: =DmdCalc!G$7*Pop!F27/Pop!F$28 -> 0.43801038 | H40: =DmdCalc!H$7*Pop!G27/Pop!G$28 -> 0.15423938 | I40: =DmdCalc!I$7*Pop!H27/Pop!H$28 -> 0.15834928 | J40: =DmdCalc!J$7*Pop!I27/Pop!I$28 -> 0.15659947 | K40: =DmdCalc!K$7*Pop!J27/Pop!J$28 -> 0.15442023 | L40: =DmdCalc!L$7*Pop!K27/Pop!K$28 -> 0.14905141 | ... N40: =DmdCalc!N$7*Pop!M27/Pop!M$28 -> 0.15010371 | O40: 0.0627 | P40: 0.09 | Q40: 0.1773 | R40: 0.0033 | S40: 0.0591 | T40: 0.0914 | U40: 0.1315 | V40: 0.0014 | W40: 0.0742 | X40: 0.1447 | Y40: 0.1595 | Z40: 0.0049
A41: R5 | B41: =Commodities!$D$13 -> ROE | C41: Residential Other Appliances - ELC | D41: PJ | E41: =DmdCalc!E$8*Pop!D27/Pop!D$28 -> 1.5924528 | F41: =DmdCalc!F$8*Pop!E27/Pop!E$28 -> 1.5368453 | G41: =DmdCalc!G$8*Pop!F27/Pop!F$28 -> 1.3770106 | H41: =DmdCalc!H$8*Pop!G27/Pop!G$28 -> 1.7252723 | I41: =DmdCalc!I$8*Pop!H27/Pop!H$28 -> 1.8354961 | J41: =DmdCalc!J$8*Pop!I27/Pop!I$28 -> 1.9075941 | K41: =DmdCalc!K$8*Pop!J27/Pop!J$28 -> 2.0045197 | L41: =DmdCalc!L$8*Pop!K27/Pop!K$28 -> 2.1460966 | ... N41: =DmdCalc!N$8*Pop!M27/Pop!M$28 -> 2.5044775 | O41: 0.0892 | P41: 0.1211 | Q41: 0.1084 | R41: 0.0044 | S41: 0.0865 | T41: 0.1257 | U41: 0.0674 | V41: 0.0031 | W41: 0.1079 | X41: 0.1718 | Y41: 0.1091 | Z41: 0.0054
A42: R5 | B42: =Commodities!$D$14 -> ROG | C42: Residential Other Appliances - NGA | D42: PJ | E42: =DmdCalc!E$10*Pop!D27/Pop!D$28 -> 0.14382575 | F42: =DmdCalc!F$10*Pop!E27/Pop!E$28 -> 0.16234635 | G42: =DmdCalc!G$10*Pop!F27/Pop!F$28 -> 0.1584299 | H42: =DmdCalc!H$10*Pop!G27/Pop!G$28 -> 0.19045471 | I42: =DmdCalc!I$10*Pop!H27/Pop!H$28 -> 0.19660349 | J42: =DmdCalc!J$10*Pop!I27/Pop!I$28 -> 0.19692629 | K42: =DmdCalc!K$10*Pop!J27/Pop!J$28 -> 0.19815263 | L42: =DmdCalc!L$10*Pop!K27/Pop!K$28 -> 0.20161765 | ... N42: =DmdCalc!N$10*Pop!M27/Pop!M$28 -> 0.2064994
...

Sheet TechData_DMD
A1: TechData | B1: _GLOBAL,R0,R1,R2,R3,R4,R5,R6 | L1: R2 | M1: R3 | N1: R4 | O1: R5 | P1: R6 | S1: R2 | T1: R3 | U1: R4 | V1: R5 | W1: R6 | X1: R2 | Y1: R3 | Z1: R4 | AA1: R5 | AB1: R6 | AC1: R2 | AD1: R3 | AE1: R4 | AF1: R5 | AG1: R6
F6: ~FI_T
A7: Region | B7: TechName | C7: *TechDesc | D7: *Units | E7: CommIN | F7: CommOUT | G7: NCAP_START | H7: NCAP_TLIFE | I7: NCAP_COST | J7: EFF | K7: Share~UP | L7: NCAP_AF~R2 | M7: NCAP_AF~R3 | N7: NCAP_AF~R4 | O7: NCAP_AF~R5 | P7: NCAP_AF~R6 | Q7: NCAP_FOM | R7: NCAP_DRATE | S7: PRC_RESID~R2~2010 | T7: PRC_RESID~R3~2010 | U7: PRC_RESID~R4~2010 | V7: PRC_RESID~R5~2010 | W7: PRC_RESID~R6~2010 | X7: PRC_RESID~R2~2015 | Y7: PRC_RESID~R3~2015 | Z7: PRC_RESID~R4~2015 | AA7: PRC_RESID~R5~2015 | AB7: PRC_RESID~R6~2015 | AC7: PRC_RESID~R2~2020 | AD7: PRC_RESID~R3~2020 | AE7: PRC_RESID~R4~2020 | AF7: PRC_RESID~R5~2020 | AG7: PRC_RESID~R6~2020 | AH7: PRC_RESID~R4~2055 | AI7: NCAP_BND~2010 | AJ7: NCAP_BND~2015 | AK7: NCAP_BND~2020 | AL7: NCAP_BND~2025 | AM7: NCAP_BND~2030 | AN7: NCAP_BND~2035 | AO7: NCAP_BND~2040 | AP7: NCAP_BND~2045 | AQ7: NCAP_BND~2050 | AR7: NCAP_BND~2055
A8: *Space Heating
A9: *Electric Radiant Heating
A10: R2,R3,R4,R5,R6 | B10: RSHERDV110 | C10: Electric Radiant Ver1.RSH.ELC.10 | D10: PJ | E10: RESELC | F10: =Commodities!$D$11 -> RSH | G10: 2010 | H10: 20 | I10: 3.7369871 | J10: 1 | K10: 1 | L10: 0.16 | M10: 0.16 | N10: 0.16 | O10: 0.16 | P10: 0.16 | R10: 0.18 | S10: =Resid!U9 -> 4.6902592 | T10: =Resid!V9 -> 2.2297152 | U10: =Resid!W9 -> 3.9516778 | V10: =Resid!X9 -> 1.064069 | W10: =Resid!Y9 -> 4.0851125 | X10: =Resid!AJ9 -> 3.4695111 | Y10: =Resid!AK9 -> 1.6819851 | Z10: =Resid!AL9 -> 3.0825509 | AA10: =Resid!AM9 -> 0.73815893 | AB10: =Resid!AN9 -> 2.9316531 | AC10: =Resid!AY9 -> 2.4158177 | AD10: =Resid!AZ9 -> 1.1792311 | AE10: =Resid!BA9 -> 2.0621716 | AF10: =Resid!BB9 -> 0.48711217 | AG10: =Resid!BC9 -> 1.9844322 | AI10: 0 | AJ10: 0 | AK10: 0 | AL10: 0 | AM10: 0 | AN10: 0 | AO10: 0 | AP10: 0 | AQ10: 0 | AR10: 0
A11: *Electric Resistance Furnaces
A12: *Electric Heat Pumps
A13: R2,R3,R4,R5,R6 | B13: RSHEHPV110 | C13: Electric Heat Pump Ver1.RSH.ELC.10 | D13: PJ | E13: RESELC | F13: =Commodities!$D$11 -> RSH | G13: 2010 | H13: 15 | I13: 4.0729892 | J13: 2.26 | K13: 1 | L13: 0.16 | M13: 0.16 | N13: 0.16 | O13: 0.16 | P13: 0.16 | R13: 0.18 | S13: =Resid!U12 -> 2.3993521 | T13: =Resid!V12 -> 1.1406346 | U13: =Resid!W12 -> 2.0215229 | V13: =Resid!X12 -> 0.54433582 | W13: =Resid!Y12 -> 2.0897828 | X13: =Resid!AJ12 -> 4.7975571 | Y13: =Resid!AK12 -> 2.3258088 | Z13: =Resid!AL12 -> 4.2624779 | AA13: =Resid!AM12 -> 1.0207086 | AB13: =Resid!AN12 -> 4.05382 | AC13: =Resid!AY12 -> 5.2807679 | AD13: =Resid!AZ12 -> 2.5776969 | AE13: =Resid!BA12 -> 4.5077281 | AF13: =Resid!BB12 -> 1.0647849 | AG13: =Resid!BC12 -> 4.3377966 | AI13: 0 | AJ13: 0 | AK13: 0 | AL13: 0 | AM13: 0 | AN13: 0 | AO13: 0 | AP13: 0 | AQ13: 0 | AR13: 0
A14: *Natural Gas Furnaces
A15: R2,R3,R4,R5,R6 | B15: RSHNFRV110 | C15: Natural Gas Furnace Ver1.RSH.NGA.10 | D15: PJ | E15: RESNGAEA | F15: =Commodities!$D$11 -> RSH | G15: 2010 | H15: 15 | I15: 3.5376821 | J15: 0.78 | K15: 1 | L15: 0.16 | M15: 0.16 | N15: 0.16 | O15: 0.16 | P15: 0.16 | R15: 0.15 | S15: =Resid!U27 -> 105.29643 | T15: =Resid!V27 -> 50.057159 | U15: =Resid!W27 -> 88.715259 | V15: =Resid!X27 -> 23.888373 | W15: =Resid!Y27 -> 91.710871 | X15: =Resid!AJ27 -> 121.48624 | Y15: =Resid!AK27 -> 58.895341 | Z15: =Resid!AL27 -> 107.93668 | AA15: =Resid!AM27 -> 25.846913 | AB15: =Resid!AN27 -> 102.65294 | AC15: =Resid!AY27 -> 114.02275 | AD15: =Resid!AZ27 -> 55.657834 | AE15: =Resid!BA27 -> 97.331217 | AF15: =Resid!BB27 -> 22.990919 | AG15: =Resid!BC27 -> 93.662044 | AI15: 0 | AJ15: 0 | AK15: 0
A16: *Natural Gas Radiant Heating
A17: R2,R3,R4,R5,R6 | B17: RSHNRDV110 | C17: Natural Gas Radiant Ver1.RSH.NGA.10 | D17: PJ | E17: RESNGAEA | F17: =Commodities!$D$11 -> RSH | G17: 2010 | H17: 20 | I17: 8.2856238 | J17: 0.8 | K17: 1 | L17: 0.16 | M17: 0.16 | N17: 0.16 | O17: 0.16 | P17: 0.16 | R17: 0.15 | S17: =Resid!U34 -> 64.152367 | T17: =Resid!V34 -> 30.49757 | U17: =Resid!W34 -> 54.050208 | V17: =Resid!X34 -> 14.554109 | W17: =Resid!Y34 -> 55.875298 | X17: =Resid!AJ34 -> 71.204274 | Y17: =Resid!AK34 -> 34.519137 | Z17: =Resid!AL34 -> 63.262747 | AA17: =Resid!AM34 -> 15.149129 | AB17: =Resid!AN34 -> 60.165894 | AC17: =Resid!AY34 -> 64.326862 | AD17: =Resid!AZ34 -> 31.399819 | AE17: =Resid!BA34 -> 54.910197 | AF17: =Resid!BB34 -> 12.970514 | AG17: =Resid!BC34 -> 52.840203 | AI17: 0 | AJ17: 0 | AK17: 0 | AL17: 0 | AM17: 0 | AN17: 0 | AO17: 0 | AP17: 0 | AQ17: 0 | AR17: 0
A18: *Kerosene Furnaces
A19: *LPG Furnaces
A20: *Fuel Oil (DSL) Furnaces
A21: R2,R3,R4,R5,R6 | B21: RSHDFRV110 | C21: Distillate Furnace Ver1.RSH.DST.10 | D21: PJ | E21: RESDSLEA | F21: =Commodities!$D$11 -> RSH | G21: 2010 | H21: 20 | I21: 6.3922148 | J21: 0.8 | K21: 1 | L21: 0.16 | M21: 0.16 | N21: 0.16 | O21: 0.16 | P21: 0.16 | R21: 0.18 | S21: =Resid!U45 -> 20.966428 | T21: =Resid!V45 -> 9.9672877 | U21: =Resid!W45 -> 17.664816 | V21: =Resid!X45 -> 4.7566081 | W21: =Resid!Y45 -> 18.261297 | X21: =Resid!AJ45 -> 19.39449 | Y21: =Resid!AK45 -> 9.4022592 | Z21: =Resid!AL45 -> 17.231391 | AA21: =Resid!AM45 -> 4.126292 | AB21: =Resid!AN45 -> 16.387876 | AC21: =Resid!AY45 -> 13.868938 | AD21: =Resid!AZ45 -> 6.7698336 | AE21: =Resid!BA45 -> 11.838696 | AF21: =Resid!BB45 -> 2.7964563 | AG21: =Resid!BC45 -> 11.392403 | AI21: 0 | AJ21: 0 | AK21: 0 | AL21: 0 | AM21: 0 | AN21: 0 | AO21: 0 | AP21: 0 | AQ21: 0 | AR21: 0
A22: *Dfuel Oil (DSL) Radiant Space Heating
A23: R2,R3,R4,R5,R6 | B23: RSHDRDV110 | C23: Distillate Radiant Ver1.RSH.DST.10 | D23: PJ | E23: RESDSLEA | F23: =Commodities!$D$11 -> RSH | G23: 2010 | H23: 20 | I23: 11.507811 | J23: 0.85 | K23: 1 | L23: 0.16 | M23: 0.16 | N23: 0.16 | O23: 0.16 | P23: 0.16 | R23: 0.18 | S23: =Resid!U51 -> 48.65557 | T23: =Resid!V51 -> 23.130505 | U23: =Resid!W51 -> 40.993712 | V23: =Resid!X51 -> 11.038384 | W23: =Resid!Y51 -> 42.377929 | X23: =Resid!AJ51 -> 26.475951 | Y23: =Resid!AK51 -> 12.835282 | Z23: =Resid!AL51 -> 23.523046 | AA23: =Resid!AM51 -> 5.6329146 | AB23: =Resid!AN51 -> 22.37154 | AC23: =Resid!AY51 -> 8.6205856 | AD23: =Resid!AZ51 -> 4.2079594 | AE23: =Resid!BA51 -> 7.3586374 | AF23: =Resid!BB51 -> 1.7382074 | AG23: =Resid!BC51 -> 7.0812329 | AI23: 0 | AJ23: 0 | AK23: 0 | AL23: 0 | AM23: 0 | AN23: 0 | AO23: 0 | AP23: 0 | AQ23: 0 | AR23: 0
A24: *UTILITY SCALE CHP - SH | L24: =IF(K24="","",K24)
A25: R4 | B25: RSHNUTIBOI | C25: RSH.NG.UTILITY.BOILER | D25: PJ | E25: RESSTNB | F25: =Commodities!$D$11 -> RSH | G25: 2010 | H25: 30 | I25: 2.5215838 | J25: 0.78 | L25: 0.16 | M25: 0.16 | N25: 0.16 | O25: 0.16 | P25: 0.16 | Q25: 0.070919543 | R25: 0.18 | S25: =Resid!U56 -> 0 | T25: =Resid!V56 -> 0 | U25: =Resid!W56 -> 18.013416 | V25: =Resid!X56 -> 0 | W25: =Resid!Y56 -> 0 | X25: =Resid!AJ56 -> 0 | Y25: =Resid!AK56 -> 0 | Z25: =Resid!AL56 -> 17.927436 | AA25: =Resid!AM56 -> 0 | AB25: =Resid!AN56 -> 0 | AC25: =Resid!AY56 -> 0 | AD25: =Resid!AZ56 -> 0 | AE25: =Resid!BA56 -> 16.139476 | AF25: =Resid!BB56 -> 0 | AG25: =Resid!BC56 -> 0 | AH25: =AE25 -> 16.139476 | AI25: 0 | AJ25: 0 | AK25: 0 | AL25: 0 | AM25: 0 | AN25: 0 | AO25: 0 | AP25: 0 | AQ25: 0 | AR25: 0
A26: R4 | B26: RSHNUTICHP | C26: RSH.NG.UTILITY.CHP | D26: PJ | E26: RESSTNUC | F26: =Commodities!$D$11 -> RSH | G26: 2010 | H26: 30 | I26: 2.5215838 | J26: 0.78 | L26: 0.16 | M26: 0.16 | N26: 0.16 | O26: 0.16 | P26: 0.16 | Q26: 0.070919543 | R26: 0.18 | S26: =Resid!U57 -> 0 | T26: =Resid!V57 -> 0 | U26: =Resid!W57 -> 23.899633 | V26: =Resid!X57 -> 0 | W26: =Resid!Y57 -> 0 | X26: =Resid!AJ57 -> 0 | Y26: =Resid!AK57 -> 0 | Z26: =Resid!AL57 -> 23.785557 | AA26: =Resid!AM57 -> 0 | AB26: =Resid!AN57 -> 0 | AC26: =Resid!AY57 -> 0 | AD26: =Resid!AZ57 -> 0 | AE26: =Resid!BA57 -> 21.413349 | AF26: =Resid!BB57 -> 0 | AG26: =Resid!BC57 -> 0 | AH26: =AE26 -> 21.413349 | AI26: 0 | AJ26: 0 | AK26: 0 | AL26: 0 | AM26: 0 | AN26: 0 | AO26: 0 | AP26: 0 | AQ26: 0 | AR26: 0
A27: R4 | B27: RSHBUTICHP | C27: RSH.DSL.UTILITY.CHP | D27: PJ | E27: RESSTBUC | F27: =Commodities!$D$11 -> RSH | G27: 2010 | H27: 30 | I27: 2.5215838 | J27: 0.78 | L27: 0.16 | M27: 0.16 | N27: 0.16 | O27: 0.16 | P27: 0.16 | Q27: 0.070919543 | R27: 0.18 | S27: =Resid!U58 -> 0 | T27: =Resid!V58 -> 0 | U27: =Resid!W58 -> 0.021080538 | V27: =Resid!X58 -> 0 | W27: =Resid!Y58 -> 0 | X27: =Resid!AJ58 -> 0 | Y27: =Resid!AK58 -> 0 | Z27: =Resid!AL58 -> 0.020979917 | AA27: =Resid!AM58 -> 0 | AB27: =Resid!AN58 -> 0 | AC27: =Resid!AY58 -> 0 | AD27: =Resid!AZ58 -> 0 | AE27: =Resid!BA58 -> 0.031044583 | AF27: =Resid!BB58 -> 0 | AG27: =Resid!BC58 -> 0 | AH27: =AE27 -> 0.031044583 | AI27: 0 | AJ27: 0 | AK27: 0 | AL27: 0 | AM27: 0 | AN27: 0 | AO27: 0 | AP27: 0 | AQ27: 0 | AR27: 0
A28: *Wood Fired Furnaces
A29: *Geothermal Heat Pumps
A30: *Natural Gas Heat Pumps
A31: *Space Cooling
A32: *Room/Window AC
A33: R2,R3,R4,R5,R6 | B33: RSCRACV110 | C33: Room AC Ver1.RSC.ELC.10 | D33: PJ | E33: RESELC | F33: RSC | G33: 2010 | H33: 10 | I33: 3.5842305 | J33: 2.74 | K33: 1 | L33: 0.15 | M33: 0.15 | N33: 0.15 | O33: 0.15 | P33: 0.15 | R33: 0.6 | S33: =Resid!U63 -> 20.209281 | T33: =Resid!V63 -> 10.102543 | U33: =Resid!W63 -> 15.492338 | V33: =Resid!X63 -> 3.6791663 | W33: =Resid!Y63 -> 17.637348 | X33: =Resid!AJ63 -> 24.096392 | Y33: =Resid!AK63 -> 12.255382 | Z33: =Resid!AL63 -> 19.921013 | AA33: =Resid!AM63 -> 4.448169 | AB33: =Resid!AN63 -> 20.659393 | AC33: =Resid!AY63 -> 28.26642 | AD33: =Resid!AZ63 -> 14.574963 | AE33: =Resid!BA63 -> 21.570863 | AF33: =Resid!BB63 -> 4.686693 | AG33: =Resid!BC63 -> 22.902978 | AI33: 0 | AJ33: 0 | AK33: 0 | AL33: 0 | AM33: 0 | AN33: 0 | AO33: 0 | AP33: 0 | AQ33: 0 | AR33: 0
A34: *Central AC Units
A35: R2,R3,R4,R5,R6 | B35: RSCCACV110 | C35: Central AC Ver1.RSC.ELC.10 | D35: PJ | E35: RESELC | F35: RSC | G35: 2010 | H35: 11 | I35: 5.4306523 | J35: 2.92 | K35: 1 | L35: 0.15 | M35: 0.15 | N35: 0.15 | O35: 0.15 | P35: 0.15 | R35: 0.18 | S35: =Resid!U71 -> 40.770302 | T35: =Resid!V71 -> 20.380919 | U35: =Resid!W71 -> 31.254318 | V35: =Resid!X71 -> 7.4223679 | W35: =Resid!Y71 -> 35.581671 | X35: =Resid!AJ71 -> 32.810172 | Y35: =Resid!AK71 -> 16.687195 | Z35: =Resid!AL71 -> 27.124885 | AA35: =Resid!AM71 -> 6.0567238 | AB35: =Resid!AN71 -> 28.130279 | AC35: =Resid!AY71 -> 29.305651 | AD35: =Resid!AZ71 -> 15.11082 | AE35: =Resid!BA71 -> 22.363928 | AF35: =Resid!BB71 -> 4.859002 | AG35: =Resid!BC71 -> 23.745019 | AI35: 0 | AJ35: 0 | AK35: 0 | AL35: 0 | AM35: 0 | AN35: 0 | AO35: 0 | AP35: 0 | AQ35: 0 | AR35: 0
A36: *Portable AC Units
A37: *Electric Heat Pumps
A38: R2,R3,R4,R5,R6 | B38: RSCEHPV110 | C38: Electric Heat Pump Ver1.RSC.ELC.10 | D38: PJ | E38: RESELC | F38: RSC | G38: 2010 | H38: 15 | I38: 4.0729892 | J38: 3 | K38: 1 | L38: 0.15 | M38: 0.15 | N38: 0.15 | O38: 0.15 | P38: 0.15 | R38: 0.45 | S38: =Resid!U81 -> 1.8686296 | T38: =Resid!V81 -> 0.93412086 | U38: =Resid!W81 -> 1.4324825 | V38: =Resid!X81 -> 0.34019019 | W38: =Resid!Y81 -> 1.6308186 | X38: =Resid!AJ81 -> 4.4546727 | Y38: =Resid!AK81 -> 2.2656386 | Z38: =Resid!AL81 -> 3.6827752 | AA38: =Resid!AM81 -> 0.82232799 | AB38: =Resid!AN81 -> 3.8192787 | AC38: =Resid!AY81 -> 6.5194698 | AD38: =Resid!AZ81 -> 3.3616225 | AE38: =Resid!BA81 -> 4.9751823 | AF38: =Resid!BB81 -> 1.0809559 | AG38: =Resid!BC81 -> 5.2824261 | AI38: 0 | AJ38: 0 | AK38: 0 | AL38: 0 | AM38: 0 | AN38: 0 | AO38: 0 | AP38: 0 | AQ38: 0 | AR38: 0
A39: *Geothermal Heat Pumps
A40: *Natural Gas Heat Pumps
A41: *Water Heating
A42: *Natural Gas
A43: R2,R3,R4,R5,R6 | B43: RWHNWHV110 | C43: Natural Gas Ver1.RWH.NGA.10 | D43: PJ | E43: RESNGAEA | F43: RWH | G43: 2010 | H43: 8 | I43: 7.9209267 | J43: 0.59 | K43: 1 | L43: 0.1 | M43: 0.1 | N43: 0.1 | O43: 0.1 | P43: 0.1 | R43: 0.18 | S43: =Resid!U101 -> 90.94865 | T43: =Resid!V101 -> 47.399615 | U43: =Resid!W101 -> 72.446515 | V43: =Resid!X101 -> 16.214705 | W43: =Resid!Y101 -> 76.449027 | X43: =Resid!AJ101 -> 101.94989 | Y43: =Resid!AK101 -> 53.593587 | Z43: =Resid!AL101 -> 84.334383 | AA43: =Resid!AM101 -> 18.30269 | AB43: =Resid!AN101 -> 84.938394 | AC43: =Resid!AY101 -> 104.97797 | AD43: =Resid!AZ101 -> 55.565489 | AE43: =Resid!BA101 -> 83.432397 | AF43: =Resid!BB101 -> 17.861155 | AG43: =Resid!BC101 -> 85.024335 | AI43: 0 | AJ43: 0 | AK43: 0 | AL43: 0 | AM43: 0 | AN43: 0 | AO43: 0 | AP43: 0 | AQ43: 0 | AR43: 0
A44: *Electric Water Heaters
...

Sheet TechData_SolarPV
A1: TechData | B1: _GLOBAL,R0,R1,R2,R3,R4,R5,R6
F4: ~FI_T
A5: Region | B5: TechName | C5: *TechDesc | D5: *Units | E5: CommIN | F5: CommOUT | G5: NCAP_START | H5: NCAP_TLIFE | I5: PRC_CAPACT | J5: EFF | K5: Peak | L5: PRC_RESID~2010 | M5: NCAP_COST~2010 | N5: NCAP_COST~2015 | O5: NCAP_COST~2020 | P5: NCAP_COST~2025 | Q5: NCAP_COST~2030 | R5: NCAP_COST~2035 | S5: NCAP_COST~2040 | T5: NCAP_COST~2045 | U5: NCAP_COST~2050 | V5: NCAP_COST~2055 | W5: NCAP_FOM | X5: NCAP_AF~IDAM | Y5: NCAP_AF~IDPM | Z5: *NCAP_AF~IP | AA5: NCAP_AF~IP | AB5: NCAP_AF~IN | AC5: NCAP_AF~SDAM | AD5: NCAP_AF~SDPM | AE5: *NCAP_AF~SP | AF5: NCAP_AF~SP | AG5: NCAP_AF~SN | AH5: NCAP_AF~WDAM | AI5: NCAP_AF~WDPM | AJ5: *NCAP_AF~WP | AK5: NCAP_AF~WP | AL5: NCAP_AF~WN | AM5: NCAP_DRATE | AO5: Input | AP5: Output | AR5: ACT_BND~FX~2010 | AS5: ACT_BND~FX~2015 | AT5: ACT_BND~LO~2020 | AU5: ACT_BND~LO~2025 | AV5: ACT_BND~LO~2030 | AW5: ACT_BND~LO~2035 | AX5: ACT_BND~LO~2040 | AY5: ACT_BND~LO~2045 | AZ5: ACT_BND~LO~2050 | BA5: ACT_BND~LO~2055 | BB5: ACT_BND~UP~2020 | BC5: ACT_BND~UP~2025 | BD5: ACT_BND~UP~2030 | BE5: ACT_BND~UP~2035 | BF5: ACT_BND~UP~2040 | BG5: ACT_BND~UP~2045 | BH5: ACT_BND~UP~2050 | BI5: ACT_BND~UP~2055
A6: * Solar PV Technologies
A7: *R1 | B7: ESOLPVRES | C7: Solar PV Distributed Residential Generation | E7: SOLRES | F7: RESELC | G7: 2010 | H7: 30 | I7: 31.536 | J7: =AP7/AO7 -> 0.34965035 | K7: 0.1 | L7: 0 | M7: 6546.9995 | N7: 3903.1781 | O7: 3453.8021 | P7: 3004.4261 | Q7: 2839.3022 | R7: 2674.1784 | S7: 2596.418 | T7: 2558.6683 | U7: 2540.0679 | V7: 2530.8353 | W7: 10 | X7: 0 | Y7: 0.31357247 | Z7: 0.31357247 | AA7: =Z7*0.2 -> 0.062714494 | AB7: 0 | AC7: 0.3060734 | AD7: 0.3060734 | AE7: 0.3060734 | AF7: =AE7*0.2 -> 0.061214679 | AG7: 0 | AH7: 0.3020009 | AI7: 0.3020009 | AJ7: 0.3020009 | AK7: =AJ7*0.2 -> 0.06040018 | AL7: 0 | AM7: 0.15 | AO7: 2.86 | AP7: 1
A8: R2 | B8: ESOLPVRES | C8: Solar PV Distributed Residential Generation | E8: SOLRES | F8: RESELC | G8: 2010 | H8: 30 | I8: 31.536 | J8: =AP8/AO8 -> 0.34965035 | K8: 0.1 | L8: 0.002 | M8: 6546.9995 | N8: 3903.1781 | O8: 3453.8021 | P8: 3004.4261 | Q8: 2839.3022 | R8: 2674.1784 | S8: 2596.418 | T8: 2558.6683 | U8: 2540.0679 | V8: 2530.8353 | W8: 10 | X8: 0 | Y8: 0.317351 | Z8: 0.317351 | AA8: =Z8*0.2 -> 0.0634702 | AB8: 0 | AC8: 0.30541737 | AD8: 0.30541737 | AE8: 0.30541737 | AF8: =AE8*0.2 -> 0.061083474 | AG8: 0 | AH8: 0.29271621 | AI8: 0.29271621 | AJ8: 0.29271621 | AK8: =AJ8*0.2 -> 0.058543242 | AL8: 0 | AM8: 0.15 | AO8: 2.86 | AP8: 1 | AR8: ='Rooftop Calc'!M70 -> 0.0071942858 | AS8: ='Rooftop Calc'!M76 -> 0.10932348 | AT8: ='Rooftop Calc'!M82 -> 0.2449548 | AU8: ='Rooftop Calc'!M89 -> 0.43038221 | AV8: ='Rooftop Calc'!M96 -> 0.61580962 | AW8: ='Rooftop Calc'!M103 -> 0.80123703 | AX8: ='Rooftop Calc'!M110 -> 0.98666444 | AY8: ='Rooftop Calc'!M117 -> 1.1648976 | AZ8: ='Rooftop Calc'!M124 -> 1.2410015 | BA8: ='Rooftop Calc'!M131 -> 1.3072234 | BB8: ='Rooftop Calc'!U82 -> 0.37638511 | BC8: ='Rooftop Calc'!U89 -> 0.64266587 | BD8: ='Rooftop Calc'!U96 -> 0.90972751 | BE8: ='Rooftop Calc'!U103 -> 1.1760083 | BF8: ='Rooftop Calc'!U110 -> 1.4430699 | BG8: ='Rooftop Calc'!U117 -> 1.7093507 | BH8: ='Rooftop Calc'!U124 -> 1.9764123 | BI8: ='Rooftop Calc'!U131 -> 2.242693
A9: R3 | B9: ESOLPVRES | C9: Solar PV Distributed Residential Generation | E9: SOLRES | F9: RESELC | G9: 2010 | H9: 30 | I9: 31.536 | J9: =AP9/AO9 -> 0.34965035 | K9: 0.1 | L9: 0.002 | M9: 6546.9995 | N9: 3903.1781 | O9: 3453.8021 | P9: 3004.4261 | Q9: 2839.3022 | R9: 2674.1784 | S9: 2596.418 | T9: 2558.6683 | U9: 2540.0679 | V9: 2530.8353 | W9: 10 | X9: 0 | Y9: 0.29713464 | Z9: 0.29713464 | AA9: =Z9*0.2 -> 0.059426928 | AB9: 0 | AC9: 0.30672516 | AD9: 0.30672516 | AE9: 0.30672516 | AF9: =AE9*0.2 -> 0.061345033 | AG9: 0 | AH9: 0.26137287 | AI9: 0.26137287 | AJ9: 0.26137287 | AK9: =AJ9*0.2 -> 0.052274574 | AL9: 0 | AM9: 0.15 | AO9: 2.86 | AP9: 1 | AR9: ='Rooftop Calc'!N70 -> 0.0037521802 | AS9: ='Rooftop Calc'!N76 -> 0.073445454 | AT9: ='Rooftop Calc'!N82 -> 0.13819492 | AU9: ='Rooftop Calc'!N89 -> 0.20768262 | AV9: ='Rooftop Calc'!N96 -> 0.27717031 | AW9: ='Rooftop Calc'!N103 -> 0.34665801 | AX9: ='Rooftop Calc'!N110 -> 0.4161457 | AY9: ='Rooftop Calc'!N117 -> 0.48188122 | AZ9: ='Rooftop Calc'!N124 -> 0.47792346 | BA9: ='Rooftop Calc'!N131 -> 0.46631308 | BB9: ='Rooftop Calc'!V82 -> 0.25286221 | BC9: ='Rooftop Calc'!V89 -> 0.43175435 | BD9: ='Rooftop Calc'!V96 -> 0.6111711 | BE9: ='Rooftop Calc'!V103 -> 0.79006324 | BF9: ='Rooftop Calc'!V110 -> 0.96947999 | BG9: ='Rooftop Calc'!V117 -> 1.1483721 | BH9: ='Rooftop Calc'!V124 -> 1.3277889 | BI9: ='Rooftop Calc'!V131 -> 1.506681
A10: R4 | B10: ESOLPVRES | C10: Solar PV Distributed Residential Generation | E10: SOLRES | F10: RESELC | G10: 2010 | H10: 30 | I10: 31.536 | J10: =AP10/AO10 -> 0.34965035 | K10: 0.1 | L10: 0.0004 | M10: 6546.9995 | N10: 3903.1781 | O10: 3453.8021 | P10: 3004.4261 | Q10: 2839.3022 | R10: 2674.1784 | S10: 2596.418 | T10: 2558.6683 | U10: 2540.0679 | V10: 2530.8353 | W10: 10 | X10: 0 | Y10: 0.33039362 | Z10: 0.33039362 | AA10: =Z10*0.2 -> 0.066078724 | AB10: 0 | AC10: 0.32440092 | AD10: 0.32440092 | AE10: 0.32440092 | AF10: =AE10*0.2 -> 0.064880183 | AG10: 0 | AH10: 0.34679382 | AI10: 0.34679382 | AJ10: 0.34679382 | AK10: =AJ10*0.2 -> 0.069358764 | AL10: 0 | AM10: 0.15 | AO10: 2.86 | AP10: 1 | AR10: ='Rooftop Calc'!O70 -> 0.0011971758 | AS10: ='Rooftop Calc'!O76 -> 0.0093113675 | AT10: ='Rooftop Calc'!O82 -> 0.017876875 | AU10: ='Rooftop Calc'!O89 -> 0.024528127 | AV10: ='Rooftop Calc'!O96 -> 0.03117938 | AW10: ='Rooftop Calc'!O103 -> 0.037830632 | AX10: ='Rooftop Calc'!O110 -> 0.044481884 | AY10: ='Rooftop Calc'!O117 -> 0.04993596 | AZ10: ='Rooftop Calc'!O124 -> 0.047275844 | BA10: ='Rooftop Calc'!O131 -> 0.042167344 | BB10: ='Rooftop Calc'!W82 -> 0.032057708 | BC10: ='Rooftop Calc'!W89 -> 0.054737539 | BD10: ='Rooftop Calc'!W96 -> 0.07748388 | BE10: ='Rooftop Calc'!W103 -> 0.10016371 | BF10: ='Rooftop Calc'!W110 -> 0.12291005 | BG10: ='Rooftop Calc'!W117 -> 0.14558988 | BH10: ='Rooftop Calc'!W124 -> 0.16833622 | BI10: ='Rooftop Calc'!W131 -> 0.19101605
A11: R5 | B11: ESOLPVRES | C11: Solar PV Distributed Residential Generation | E11: SOLRES | F11: RESELC | G11: 2010 | H11: 30 | I11: 31.536 | J11: =AP11/AO11 -> 0.34965035 | K11: 0.1 | L11: 0.0006 | M11: 6546.9995 | N11: 3903.1781 | O11: 3453.8021 | P11: 3004.4261 | Q11: 2839.3022 | R11: 2674.1784 | S11: 2596.418 | T11: 2558.6683 | U11: 2540.0679 | V11: 2530.8353 | W11: 10 | X11: 0 | Y11: 0.34379748 | Z11: 0.34379748 | AA11: =Z11*0.2 -> 0.068759495 | AB11: 0 | AC11: 0.29466039 | AD11: 0.29466039 | AE11: 0.29466039 | AF11: =AE11*0.2 -> 0.058932078 | AG11: 0 | AH11: 0.36077416 | AI11: 0.36077416 | AJ11: 0.36077416 | AK11: =AJ11*0.2 -> 0.072154833 | AL11: 0 | AM11: 0.15 | AO11: 2.86 | AP11: 1 | AR11: ='Rooftop Calc'!P70 -> 0.0017437235 | AS11: ='Rooftop Calc'!P76 -> 0.32033226 | AT11: ='Rooftop Calc'!P82 -> 0.57040473 | AU11: ='Rooftop Calc'!P89 -> 1.0832858 | AV11: ='Rooftop Calc'!P96 -> 1.5961669 | AW11: ='Rooftop Calc'!P103 -> 2.1090479 | AX11: ='Rooftop Calc'!P110 -> 2.621929 | AY11: ='Rooftop Calc'!P117 -> 3.1330663 | AZ11: ='Rooftop Calc'!P124 -> 3.3256151 | BA11: ='Rooftop Calc'!P131 -> 3.7957364 | BB11: ='Rooftop Calc'!X82 -> 1.1028582 | BC11: ='Rooftop Calc'!X89 -> 1.8830961 | BD11: ='Rooftop Calc'!X96 -> 2.665622 | BE11: ='Rooftop Calc'!X103 -> 3.4458599 | BF11: ='Rooftop Calc'!X110 -> 4.2283858 | BG11: ='Rooftop Calc'!X117 -> 5.0086237 | BH11: ='Rooftop Calc'!X124 -> 5.7911496 | BI11: ='Rooftop Calc'!X131 -> 6.5713875
A12: R6 | B12: ESOLPVRES | C12: Solar PV Distributed Residential Generation | E12: SOLRES | F12: RESELC | G12: 2010 | H12: 30 | I12: 31.536 | J12: =AP12/AO12 -> 0.34965035 | K12: 0.1 | L12: 0.004 | M12: 6546.9995 | N12: 3903.1781 | O12: 3453.8021 | P12: 3004.4261 | Q12: 2839.3022 | R12: 2674.1784 | S12: 2596.418 | T12: 2558.6683 | U12: 2540.0679 | V12: 2530.8353 | W12: 10 | X12: 0 | Y12: 0.34054374 | Z12: 0.34054374 | AA12: =Z12*0.2 -> 0.068108748 | AB12: 0 | AC12: 0.30737101 | AD12: 0.30737101 | AE12: 0.30737101 | AF12: =AE12*0.2 -> 0.061474202 | AG12: 0 | AH12: 0.32128124 | AI12: 0.32128124 | AJ12: 0.32128124 | AK12: =AJ12*0.2 -> 0.064256247 | AL12: 0 | AM12: 0.15 | AO12: 2.86 | AP12: 1 | AR12: ='Rooftop Calc'!Q70 -> 0.012992495 | AS12: ='Rooftop Calc'!Q76 -> 0.17522773 | AT12: ='Rooftop Calc'!Q82 -> 0.47192793 | AU12: ='Rooftop Calc'!Q89 -> 0.89933033 | AV12: ='Rooftop Calc'!Q96 -> 1.3267327 | AW12: ='Rooftop Calc'!Q103 -> 1.7541351 | AX12: ='Rooftop Calc'!Q110 -> 2.1815375 | AY12: ='Rooftop Calc'!Q117 -> 2.5959474 | AZ12: ='Rooftop Calc'!Q124 -> 2.8481221 | BA12: ='Rooftop Calc'!Q131 -> 3.1386879 | BB12: ='Rooftop Calc'!Y82 -> 0.60328405 | BC12: ='Rooftop Calc'!Y89 -> 1.0300887 | BD12: ='Rooftop Calc'!Y96 -> 1.4581451 | BE12: ='Rooftop Calc'!Y103 -> 1.8849497 | BF12: ='Rooftop Calc'!Y110 -> 2.3130061 | BG12: ='Rooftop Calc'!Y117 -> 2.7398108 | BH12: ='Rooftop Calc'!Y124 -> 3.1678671 | BI12: ='Rooftop Calc'!Y131 -> 3.5946718
A13: * | AR13: =SUM(AR8:AR12) -> 0.026879861 | AS13: =SUM(AS8:AS12) -> 0.68764029 | AT13: =SUM(AT8:AT12) -> 1.4433592 | AU13: =SUM(AU8:AU12) -> 2.6452091 | AV13: =SUM(AV8:AV12) -> 3.8470589 | AW13: =SUM(AW8:AW12) -> 5.0489087 | AX13: =SUM(AX8:AX12) -> 6.2507585 | AY13: =SUM(AY8:AY12) -> 7.4257285 | ... BI13: =SUM(BI8:BI12) -> 14.106449
A14: *
G22: S

Sheet TechData_SESC
A1: TechData | B1: _GLOBAL,R0,R1,R2,R3,R4,R5,R6
F4: ~FI_T
A5: Region | B5: TechName | C5: *TechDesc | D5: *Units | E5: CommIN | F5: CommOUT | G5: NCAP_START | H5: NCAP_TLIFE | I5: EFF | J5: ACT_COST | K5: Share~UP | L5: Share~UP | M5: Peak | N5: NCAP_AF | O5: PRC_CAPACT | P5: NCAP_COST | V5: Input | W5: Output | X5: Input | Y5: Output
A6: * Collectors
A7: R2,R3,R4,R5,R6 | B7: SCRESELC | C7: Collector: ELC to RES | D7: PJ | E7: ELC | F7: RESELC | G7: 2010 | I7: =Y7/X7 -> 1 | J7: 48.826391 | M7: 1 | N7: 1 | O7: 1 | X7: 1 | Y7: 1
A15: * Building Retrofit Collectors
A16: R2,R3,R4,R5,R6 | B16: XELCRBLD | C16: Collects ELC for use in buildings | D16: PJ | E16: RESELC | F16: RESELCBLD | G16: 2010 | I16: =Y16/X16 -> 1 | M16: 1 | N16: 1 | O16: 1 | P16: 0 | X16: 1 | Y16: 1
A17: R2,R3,R4,R5,R6 | B17: XNGARBLD | C17: Collects NGA for use in buildings | D17: PJ | E17: RESNGAEA | F17: RESNGABLD | G17: 2010 | N17: 1 | O17: 1 | P17: 0 | V17: 1 | W17: 1
A18: *R2,R3,R4,R5,R6 | B18: XRFLRBLD | C18: Collects RFL for use in buildings | D18: PJ | E18: RESRFLEA | F18: RESRFLBLD | G18: 2010 | N18: 1 | O18: 1 | P18: 0 | V18: 1 | W18: 1
A19: R2,R3,R4,R5,R6 | B19: XDSLRBLD | C19: Collects DSL for use in buildings | D19: PJ | E19: RESDSLEA | F19: RESDSLBLD | G19: 2010 | N19: 1 | O19: 1 | P19: 0 | V19: 1 | W19: 1
A20: R2,R3,R4,R5,R6 | B20: RELCHE | C20: High efficiency building ELC without retrofits | D20: PJ | E20: RESELCBLD | F20: RESELCRB | G20: 2010 | I20: =Y20/X20 -> 1 | M20: 1 | N20: 1 | O20: 1 | P20: 0 | X20: 1 | Y20: 1
A21: R2,R3,R4,R5,R6 | B21: RBLDBAUHE | C21: High efficiency building energy without retrofits | D21: PJ | E21: RESNGABLD | G21: 2010 | I21: =SUM(W24,W25,W26)/SUM(V21,V22,V23) -> 1 | K21: =V21/SUM(V21,V22,V23) -> 0.33333333 | N21: 1 | O21: 1 | P21: 0 | V21: 1
E22: RESDSLBLD | K22: =V22/SUM(V21,V22,V23) -> 0.33333333 | V22: 1
A23: * | E23: RESRFLBLD | K23: =V23/SUM(V21,V22,V23) -> 0.33333333 | V23: 1
F24: RESNGARB | L24: =W24/SUM(W24,W25,W26) -> 0.33333333 | W24: 1
F25: RESDSLRB | L25: =W25/SUM(W24,W25,W26) -> 0.33333333 | W25: 1
A26: * | F26: RESRFLRB | L26: =W26/SUM(W24,W25,W26) -> 0.33333333 | W26: 1
A27: R2,R3,R4,R5,R6 | B27: RELCBAU | C27: Building ELC without retrofits | D27: PJ | E27: RESELCBLD | F27: RESELCRM | G27: 2010 | I27: =Y27/X27 -> 1 | M27: 1 | N27: 1 | O27: 1 | P27: 0 | X27: 1 | Y27: 1
A28: R2,R3,R4,R5,R6 | B28: RBLDBAU | C28: Building energy without retrofits | D28: PJ | E28: RESNGABLD | G28: 2010 | I28: =SUM(W31,W32,W33)/SUM(V28,V29,V30) -> 1 | K28: =V28/SUM(V28,V29,V30) -> 0.33333333 | N28: 1 | O28: 1 | P28: 0 | V28: 1
E29: RESDSLBLD | K29: =V29/SUM(V28,V29,V30) -> 0.33333333 | V29: 1
A30: * | E30: RESRFLBLD | K30: =V30/SUM(V28,V29,V30) -> 0.33333333 | V30: 1
F31: RESNGARM | L31: =W31/SUM(W31,W32,W33) -> 0.33333333 | W31: 1
F32: RESDSLRM | L32: =W32/SUM(W31,W32,W33) -> 0.33333333 | W32: 1
A33: * | F33: RESRFLRM | L33: =W33/SUM(W31,W32,W33) -> 0.33333333 | W33: 1
A34: R2,R3,R4,R5,R6 | B34: RELCR10 | C34: Building ELC retrofit for 10% energy reduction | D34: PJ | E34: RESELCBLD | F34: RESELCRB | G34: 2015 | I34: =Y34/X34 -> 1 | M34: 1 | N34: 1 | O34: 1 | P34: 0.25 | X34: 1 | Y34: 1
A35: R2,R3,R4,R5,R6 | B35: RBLDR10 | C35: Building retrofit for 10% energy reduction | D35: PJ | E35: RESNGABLD | G35: 2015 | I35: =SUM(W38,W39,W40)/SUM(V35,V36,V37) -> 1.1 | K35: =V35/SUM(V35,V36,V37) -> 0.33333333 | N35: 1 | O35: 1 | P35: 0.25 | V35: 1
E36: RESDSLBLD | K36: =V36/SUM(V35,V36,V37) -> 0.33333333 | V36: 1
A37: * | E37: RESRFLBLD | K37: =V37/SUM(V35,V36,V37) -> 0.33333333 | V37: 1
F38: RESNGARB | L38: =W38/SUM(W38,W39,W40) -> 0.33333333 | W38: 1.1
F39: RESDSLRB | L39: =W39/SUM(W38,W39,W40) -> 0.33333333 | W39: 1.1
A40: * | F40: RESRFLRB | L40: =W40/SUM(W38,W39,W40) -> 0.33333333 | W40: 1.1
A41: R2,R3,R4,R5,R6 | B41: RELCR25 | C41: Building ELC retrofit for 25% energy reduction | D41: PJ | E41: RESELCBLD | F41: RESELCRM | G41: 2020 | I41: =Y41/X41 -> 1 | M41: 1 | N41: 1 | O41: 1 | P41: 0.5 | X41: 1 | Y41: 1
A42: R2,R3,R4,R5,R6 | B42: RBLDR25 | C42: Building retrofit for 25% energy reduction | D42: PJ | E42: RESNGABLD | G42: 2020 | I42: =SUM(W45,W46,W47)/SUM(V42,V43,V44) -> 1.25 | K42: =V42/SUM(V42,V43,V44) -> 0.33333333 | N42: 1 | O42: 1 | P42: 0.5 | V42: 1
E43: RESDSLBLD | K43: =V43/SUM(V42,V43,V44) -> 0.33333333 | V43: 1
A44: * | E44: RESRFLBLD | K44: =V44/SUM(V42,V43,V44) -> 0.33333333 | V44: 1
F45: RESNGARM | L45: =W45/SUM(W45,W46,W47) -> 0.33333333 | W45: 1.25
F46: RESDSLRM | L46: =W46/SUM(W45,W46,W47) -> 0.33333333 | W46: 1.25
A47: * | F47: RESRFLRM | L47: =W47/SUM(W45,W46,W47) -> 0.33333333 | W47: 1.25
A48: R2,R3,R4,R5,R6 | B48: RELCR50 | C48: Building ELC retrofit for 50% energy reduction | D48: PJ | E48: RESELCBLD | F48: RESELCRM | G48: 2025 | I48: =Y48/X48 -> 1 | M48: 1 | N48: 1 | O48: 1 | P48: 1 | X48: 1 | Y48: 1
A49: R2,R3,R4,R5,R6 | B49: RBLDR50 | C49: Building retrofit for 50% energy reduction | D49: PJ | E49: RESNGABLD | G49: 2025 | I49: =SUM(W52,W53,W54)/SUM(V49,V50,V51) -> 1.5 | K49: =V49/SUM(V49,V50,V51) -> 0.33333333 | N49: 1 | O49: 1 | P49: 1 | V49: 1
...

Sheet TechData-Emis
A1: TechData | B1: _GLOBAL,R0,R1,R2,R3,R4,R5,R6
F4: ~FI_T
A5: Region | B5: TechName | C5: *TechDesc | D5: *Units | E5: CommIN | F5: CommOUT | G5: NCAP_START | H5: NCAP_TLIFE | I5: EFF | J5: ENV_ACT~CO2~2010 | K5: ENV_ACT~CO2~2055 | L5: ENV_ACT~NOX~2010 | M5: ENV_ACT~NOX~2055 | N5: ENV_ACT~PM10~2010 | O5: ENV_ACT~PM10~2055 | P5: ENV_ACT~PM25~2010 | Q5: ENV_ACT~PM25~2055 | R5: ENV_ACT~VOC~2010 | S5: ENV_ACT~VOC~2055 | T5: ENV_ACT~CO~2010 | U5: ENV_ACT~CO~2055 | V5: ENV_ACT~CH4~2010 | W5: ENV_ACT~CH4~2055 | X5: ENV_ACT~N2O~2010 | Y5: ENV_ACT~N2O~2055 | Z5: ENV_ACT~BC~2010 | AA5: ENV_ACT~BC~2055 | AB5: ENV_ACT~OC~2010 | AC5: ENV_ACT~OC~2055 | AD5: ENV_ACT~SO2~2010 | AE5: ENV_ACT~SO2~2055 | AF5: ENV_ACT~CO2R | AG5: ENV_ACT~NOXR | AH5: ENV_ACT~PM10R | AI5: ENV_ACT~SO2R | AJ5: ENV_ACT~NOX2CR
A6: * Residential
A7: * | B7: SERESCOA | C7: Emissions: COA to RES | D7: PJ | E7: RESCOA | F7: RESCOAEA | G7: 2010 | H7: 55 | I7: 1 | J7: =EmisRes!D18 -> 0.10059959 | K7: =J7 -> 0.10059959
A8: R2,R3,R4,R5,R6 | B8: SERESNGA | C8: Emissions: NGA to RES | D8: PJ | E8: RESNGA | F8: RESNGAEA | G8: 2010 | H8: 55 | I8: 1 | J8: =EmisRes!D9 -> 0.077177346 | K8: =J8 -> 0.077177346 | L8: =EmisRes!I28 -> 0.039275865 | M8: =L8 -> 0.039275865 | N8: =EmisRes!J28 -> 0.00021727074 | O8: =N8 -> 0.00021727074 | P8: =EmisRes!K28 -> 0.00017966619 | Q8: =P8 -> 0.00017966619 | R8: =EmisRes!L28 -> 0.0022980559 | S8: =R8 -> 0.0022980559 | T8: =EmisRes!M28 -> 0.016713134 | U8: =T8 -> 0.016713134 | V8: =EmisRes!N28 -> 0.0047390856 | W8: =V8 -> 0.0047390856 | X8: =EmisRes!O28 -> 9.4781712e-05 | Y8: =X8 -> 9.4781712e-05 | Z8: =P8*EmisRes!K177 -> 1.0779971e-05 | AA8: =Z8 -> 1.0779971e-05 | AB8: =R8*EmisRes!K101 -> 0.001149028 | AC8: =AB8 -> 0.001149028 | AD8: =EmisRes!H28 -> 0.00025069701 | AE8: =AD8 -> 0.00025069701 | AF8: =J8*1000 -> 77.177346 | AG8: =L8 -> 0.039275865 | AH8: =N8 -> 0.00021727074 | AI8: =AD8 -> 0.00025069701 | AJ8: =AG8 -> 0.039275865
A9: * | B9: SERESBIO | C9: Emissions: BIO to RES | D9: PJ | E9: RESBIO | F9: RESBIOEA | G9: 2010 | H9: 55 | I9: 1 | L9: =EmisRes!I27 -> 0.12680826 | M9: =L9 -> 0.12680826 | N9: =EmisRes!J27 -> 0.70373709 | O9: =N9 -> 0.70373709 | P9: =EmisRes!K27 -> 0.6052139 | Q9: =P9 -> 0.6052139 | R9: =EmisRes!L27 -> 1.1519338 | S9: =R9 -> 1.1519338 | T9: =EmisRes!M27 -> 5.1881544 | U9: =T9 -> 5.1881544 | V9: =EmisRes!N27 -> 0.1872974 | W9: =V9 -> 0.1872974 | X9: =EmisRes!O27 -> 0.0039808319 | Y9: =X9 -> 0.0039808319 | Z9: =P9*EmisRes!N243 -> 0.045693649 | AA9: =Z9 -> 0.045693649 | AB9: =R9*EmisRes!K65 -> 0.23038676 | AC9: =AB9 -> 0.23038676 | AD9: =EmisRes!H27 -> 0.010748065 | AE9: =AD9 -> 0.010748065 | AF9: =J9*1000 -> 0 | AG9: =L9 -> 0.12680826 | AH9: =N9 -> 0.70373709 | AI9: =AD9 -> 0.010748065 | AJ9: =AG9 -> 0.12680826
A10: R2,R3,R4,R5,R6 | B10: SERESDSL | C10: Emissions: DSL to RES | D10: PJ | E10: RESDSL | F10: RESDSLEA | G10: 2010 | H10: 55 | I10: 1 | J10: =EmisRes!D9 -> 0.077177346 | K10: =J10 -> 0.077177346 | L10: =EmisRes!I29 -> 0.055800636 | M10: =L10 -> 0.055800636 | N10: =EmisRes!J29 -> 0.0073780841 | O10: =N10 -> 0.0073780841 | P10: =EmisRes!K29 -> 0.0066030752 | Q10: =P10 -> 0.0066030752 | R10: =EmisRes!L29 -> 0.0021700247 | S10: =R10 -> 0.0021700247 | T10: =EmisRes!M29 -> 0.015500177 | U10: =T10 -> 0.015500177 | V10: =EmisRes!N29 -> 0.0055180629 | W10: =V10 -> 0.0055180629 | X10: =EmisRes!O29 -> 0.00056869027 | Y10: =X10 -> 0.00056869027 | Z10: =P10*EmisRes!K133 -> 0.0019809226 | AA10: =Z10 -> 0.0019809226 | AB10: =R10*EmisRes!K57 -> 0.00019530223 | AC10: =AB10 -> 0.00019530223 | AD10: =EmisRes!H29 -> 0.1320615 | AE10: =AD10 -> 0.1320615 | AF10: =J10*1000 -> 77.177346 | AG10: =L10 -> 0.055800636 | AH10: =N10 -> 0.0073780841 | AI10: =AD10 -> 0.1320615 | AJ10: =AG10 -> 0.055800636
