Workbook
Name __HDV50: #REF!
Name __HDV50: #REF!
Name __HDV50: #REF!
Name __LDV50: #REF!
Name __LDV50: #REF!
Name __LDV50: #REF!
Name _1995_Implicit_GDP_Deflator: #REF!
Name _1995_Implicit_GDP_Deflator: #REF!
Name _1995_Implicit_GDP_Deflator: #REF!
Name _2001_Implicit_GDP_Deflator: #REF!
Name _2001_Implicit_GDP_Deflator: #REF!
Name _2001_Implicit_GDP_Deflator: #REF!
Name Age_of_car: #REF!
Name Age_of_car: #REF!
Name Age_of_car: #REF!
Name avg_water_heater_PJ: '[1]AEO HW'!$B$33
Name btu_per_watthr: #REF!
Name btu_per_watthr: #REF!
Name btu_per_watthr: #REF!
Name conv: #REF!
Name conv: #REF!
Name conv: #REF!
Name days_per_year: #REF!
Name days_per_year: #REF!
Name days_per_year: #REF!
Name Diesel_Car_CO: #REF!
Name Diesel_Car_CO: #REF!
Name Diesel_Car_CO: #REF!
Name Diesel_Car_Nox: #REF!
Name Diesel_Car_Nox: #REF!
Name Diesel_Car_Nox: #REF!
Name Diesel_Car_PM: #REF!
Name Diesel_Car_PM: #REF!
Name Diesel_Car_PM: #REF!
Name Diesel_Car_VOCs: #REF!
Name Diesel_Car_VOCs: #REF!
Name Diesel_Car_VOCs: #REF!
Name Diesel_HDT_CO: #REF!
Name Diesel_HDT_CO: #REF!
Name Diesel_HDT_CO: #REF!
Name Diesel_HDT_NOx: #REF!
Name Diesel_HDT_NOx: #REF!
Name Diesel_HDT_NOx: #REF!
Name Diesel_HDT_PM: #REF!
Name Diesel_HDT_PM: #REF!
Name Diesel_HDT_PM: #REF!
Name Diesel_HDT_SO2: #REF!
Name Diesel_HDT_SO2: #REF!
Name Diesel_HDT_SO2: #REF!
Name Diesel_HDT_VOCs: #REF!
Name Diesel_HDT_VOCs: #REF!
Name Diesel_HDT_VOCs: #REF!
Name Diesel_LDT_CO: #REF!
Name Diesel_LDT_CO: #REF!
Name Diesel_LDT_CO: #REF!
Name Diesel_LDT_Nox: #REF!
Name Diesel_LDT_Nox: #REF!
Name Diesel_LDT_Nox: #REF!
Name Diesel_LDT_PM: #REF!
Name Diesel_LDT_PM: #REF!

Sheet Readme
B1: Readme - 05-12-2022
B3: For questions contact: Ozge Kaplan, kaplan.ozge@epa.gov, 919-541-5069
B4: Contributors:
B5: Mine Isik, Former ORISE
B6: Andrew Zalesak, ORISE
B8: General Notes
B9: Tabs for pages that consist primarily of input data are colored blue
B10: Tabs for pages that consist primarily of calculations are white
B11: Tabs for pages that are read into Answer are colored yellow
B12: The tabs generally should be navigated from right to left, e.g., the
B13: pages with input data tables are the right-most. Calculations
B14: come next (with each subsequent page typically building on the
... B20: Population Data ("Population")
C21: '- U.S. Census Bureau projections
C22: '- U.S. EPA ORD Integrated Land Use Scenarios model projections
C23: - NYC Population Estimates
B24: Vehicle Miles Traveled Breakdown by Region ("Demands")
C25: '- EIA Household Transportation Energy Use Survey, 2001
B27: Price Deflators to Convert Costs to $2000 ("GDPdeflator")
C28: '- Bureau of Economic Analysis NIPA Table 1.1.9
B30: Vehicle Sales Data by Class ("Sales Data")
C31: '- EIA Annual Energy Outlook 2008, Table 51
B33: Technology Cost and Efficiency Estimates ("AEO08 T59","AEO08 T60","OTAQ-Car","OTAQ-Truck","QM2002")
C34: '- EIA Annual Energy Outlook 2008, Tables 59 and 60
C35: '- OTAQ vehicle assumptions for SGM provided by Simon Mui
C36: '- Vehicle maintenance estimates from DOE's Quality Metrics Report 2002
B38: Emissions (ICF WA on County Level MOVES runs)
C39: -county simulated MOVES runs
B41: Existing Fleet Info
C42: '- Transportation Energy Data book, Edition 21
C43: - NYC.GOV
B46: General Flow of Operations for Preparing Data for Input to ANSWER
B47: Demand Calculation:
C48: '- Regional VMT demands are calculated in "VMT by Region"
B50: Vehicle Characterization:
C51: '- Vehicle efficiency and cost calculations for vehicles described in AEO are provided in the "Costs" and "Efficiencies" pages
C52: - Additional vehicle types are characterized in "AdditionalVehs"
C53: '- The AEO and additional vehicle data are consolidated in "ConsolidatedVehData"
B55: Emissions Characterization:
C56: - Emission factors from MOVES are consolidated in "NewEmisData"
...

Sheet ANSv6.0-Commodities
A1: ANSWER-Commodities
B7: CommName | C7: CommDesc | D7: CommUnit | E7: Set Memberships | F7: Comment

Sheet ANSv6.1-Commodities
A1: ANSWER-Commodities
B7: CommName | C7: CommDesc | D7: CommUnit | E7: Set Memberships | F7: Comment

Sheet Commodities
B6: ~FI_Comm
B7: Region | C7: Csets | D7: CommName | E7: CommDesc | F7: Unit | G7: LimType | H7: CTSLvl | I7: PeakTS | J7: Ctype | O7: Comment
B8: *Demands
B9: R2,R3,R4,R5,R6 | C9: DEM | D9: TL | E9: Transportation Light Duty | F9: bn-vmt
B10: *Emissions Commodities
B11: *R2,R3,R4,R5,R6 | C11: ENV | D11: NH3 | E11: Ammonia | F11: kt
B12: *R2,R3,R4,R5,R6 | C12: ENV | D12: CO2T | E12: Transportaiton sector CO2 | F12: kt
B13: *R2,R3,R4,R5,R6 | C13: ENV | D13: NOXT | E13: Transportation sector NOx | F13: kt
B14: *R2,R3,R4,R5,R6 | C14: ENV | D14: SO2T | E14: Transportation sector SO2 | F14: kt
B15: *R2,R3,R4,R5,R6 | C15: ENV | D15: PM10T | E15: Transportation sector PM10 | F15: kt
B16: *R2,R3,R4,R5,R6 | C16: ENV | D16: PM25T | E16: Transportation sector PM25 | F16: kt
B23: *Energy Carriers
B24: R2,R3,R4,R5,R6 | C24: NRG | D24: TRNDSL | E24: DSL to TRN | F24: PJ
B25: R2,R3,R4,R5,R6 | C25: NRG | D25: TLGSL | E25: GSL to TRN | F25: PJ
B26: *R2,R3,R4,R5,R6 | C26: NRG | D26: TLE85X | E26: E85X to TL | F26: PJ
B27: *R2,R3,R4,R5,R6 | C27: NRG | D27: TRNCNG | E27: CNG to TRN | F27: PJ
B28: R2,R3,R4,R5,R6 | C28: NRG | D28: TRNCNGL | E28: CNG to TRN - Light Duty Vehicles | F28: PJ
B29: *R2,R3,R4,R5,R6 | C29: NRG | D29: TRNCNGX | E29: CNGX to TRN | F29: PJ
B30: *R2,R3,R4,R5,R6 | C30: NRG | D30: TRNLPGX | E30: LPGX to TRN | F30: PJ
B31: *R2,R3,R4,R5,R6 | C31: NRG | D31: TRNLPGEA | E31: LPG to TRN after Collection | F31: PJ
B32: R2,R3,R4,R5,R6 | C32: NRG | D32: TRNELC | E32: ELC to TRN | F32: PJ
B33: R2,R3,R4,R5,R6 | C33: NRG | D33: TRNH2 | E33: H2 to TRN | F33: PJ
B44: *Energy Carriers
B45: R2,R3,R4,R5,R6 | C45: NRG | D45: ELC | E45: Electricity | F45: PJ
B46: *R2,R3,R4,R5,R6 | C46: NRG | D46: TRNNGA | E46: Natural Gas to Transportation Sector | F46: PJ
B47: *R2,R3,R4,R5,R6 | C47: NRG | D47: TRNCNGH | E47: CNG to TRN - Heavy Duty Vehicles | F47: PJ
B48: *R2,R3,R4,R5,R6 | C48: NRG | D48: TRNCNGX | E48: CNGX to TRN | F48: PJ
B49: *R2,R3,R4,R5,R6 | C49: NRG | D49: TRDSLL | E49: DSLL to Blend | F49: PJ
B50: *R2,R3,R4,R5,R6 | C50: NRG | D50: TRDSLU | E50: DSLU to Blend | F50: PJ
B51: *R2,R3,R4,R5,R6 | C51: NRG | D51: TRNDSLB | E51: DSL combo of DSLL and DSLU | F51: PJ
B52: *R2,R3,R4,R5,R6 | C52: NRG | D52: TRNE10 | E52: E10 Blend | F52: PJ
B53: *R2,R3,R4,R5,R6 | C53: NRG | D53: TRNE85 | E53: E85 Blend | F53: PJ
B54: *R2,R3,R4,R5,R6 | C54: NRG | D54: TRNETH | E54: Ethanol to Transportation Sector | F54: PJ
B55: *R2,R3,R4,R5,R6 | C55: NRG | D55: TRGSLC1 | E55: CONV GSL to TRN after Collection | F55: PJ
B56: *R2,R3,R4,R5,R6 | C56: NRG | D56: TRGSLR1 | E56: REF GSL to TRN after Collection | F56: PJ
... B71: R2,R3,R4,R5,R6 | C71: NRG | D71: ZZDMY | E71: Dummy commodity | F71: PJ
B72: *Emissions Commodities
B73: *R2,R3,R4,R5,R6 | C73: ENV | D73: CO2 | E73: Carbon dioxide emissions | F73: Mt
B74: R2,R3,R4,R5,R6 | C74: ENV | D74: NOX | E74: NOx emissions | F74: kt
B75: R2,R3,R4,R5,R6 | C75: ENV | D75: SO2 | E75: SO2 emissions | F75: kt
...

Sheet ANSv6.0-Technologies
A1: ANSWER-Technologies
B7: TechName | C7: TechDesc | D7: TACTUnit | E7: TCAPUnit | F7: Set Memberships | G7: Comment

Sheet ANSv6.1-Technologies
A1: ANSWER-Technologies
B7: TechName | C7: TechDesc | D7: TACTUnit | E7: TCAPUnit | F7: Set Memberships | G7: Comment

Sheet Technologies
B6: ~FI_Process
B7: Region | C7: Sets | D7: TechName | E7: TechDesc | F7: Tact | G7: Tcap | H7: PrimaryCG | I7: Vintage
B8: * Light Duty Vehicle Demand Technologies - Existing
B9: =TechData_existing!A7 -> R2,R3,R4,R5,R6 | C9: DMD | D9: =TechData_existing!B7 -> TLEMCGSL | E9: =TechData_existing!C7 -> TL.GSL.MC.Existing fleet | F9: bn-vmt | G9: bn-vmt/a
B10: =TechData_existing!A8 -> R2,R3,R4,R5,R6 | C10: DMD | D10: =TechData_existing!B8 -> TLECGSL | E10: =TechData_existing!C8 -> TL.GSL.C.Existing fleet | F10: bn-vmt | G10: bn-vmt/a
B11: =TechData_existing!A9 -> R2,R3,R4,R5,R6 | C11: DMD | D11: =TechData_existing!B9 -> TLEFDSL | E11: =TechData_existing!C9 -> TL.DSL.F.Existing fleet | F11: bn-vmt | G11: bn-vmt/a
B12: =TechData_existing!A10 -> R2,R3,R4,R5,R6 | C12: DMD | D12: =TechData_existing!B10 -> TLEFGSL | E12: =TechData_existing!C10 -> TL.GSL.F.Existing fleet | F12: bn-vmt | G12: bn-vmt/a
B13: =TechData_existing!A11 -> R2,R3,R4,R5,R6 | C13: DMD | D13: =TechData_existing!B11 -> TLESSGSL | E13: =TechData_existing!C11 -> TL.GSL.SS.Existing fleet | F13: bn-vmt | G13: bn-vmt/a
B14: =TechData_existing!A12 -> R2,R3,R4,R5,R6 | C14: DMD | D14: =TechData_existing!B12 -> TLELSGSL | E14: =TechData_existing!C12 -> TL.GSL.LS.Existing fleet | F14: bn-vmt | G14: bn-vmt/a
B15: =TechData_existing!A13 -> R2,R3,R4,R5,R6 | C15: DMD | D15: =TechData_existing!B13 -> TLEMGSL | E15: =TechData_existing!C13 -> TL.GSL.M.Existing Fleet | F15: bn-vmt | G15: bn-vmt/a
B16: =TechData_existing!A14 -> R2,R3,R4,R5,R6 | C16: DMD | D16: =TechData_existing!B14 -> TLEPGSL | E16: =TechData_existing!C14 -> TL.GSL.P.Existing Fleet | F16: bn-vmt | G16: bn-vmt/a
B17: =TechData_existing!A15 -> R2,R3,R4,R5,R6 | C17: DMD | D17: =TechData_existing!B15 -> TLEPDSL | E17: =TechData_existing!C15 -> TL.DSL.P.Existing fleet | F17: bn-vmt | G17: bn-vmt/a
B18: =TechData_existing!A16 -> * | C18: DMD | D18: =TechData_existing!B16 -> TLEETHX | E18: =TechData_existing!C16 -> TL.E85X.F.Existing fleet | F18: bn-vmt | G18: bn-vmt/a
B19: =TechData_existing!A17 -> * | C19: DMD | D19: =TechData_existing!B17 -> TLECNGX | E19: =TechData_existing!C17 -> TL.CNGX.F.Existing fleet | F19: bn-vmt | G19: bn-vmt/a
B20: =TechData_existing!A18 -> * | C20: DMD | D20: =TechData_existing!B18 -> TLELPGX | E20: =TechData_existing!C18 -> TL.LPGX.F.Existing fleet | F20: bn-vmt | G20: bn-vmt/a
B21: =TechData_existing!A19 -> R2,R3,R4,R5,R6 | C21: DMD | D21: =TechData_existing!B19 -> TLEELC | E21: =TechData_existing!C19 -> TL.ELC.F.Existing fleet | F21: bn-vmt | G21: bn-vmt/a
B29: * Process Technologies
B30: * | C30: PRE | D30: PNGACNG | E30: Conv: NGA to CNG | F30: PJ | G30: PJ/a
B31: * Collectors
B32: *R2,R3,R4,R5,R6 | C32: PRE | D32: SCTRNCNGL | E32: Collector: CNG to TRN LDV | F32: PJ | G32: PJ/a
B33: *R2,R3,R4,R5,R6 | C33: PRE | D33: SCCNGCNGX | E33: Collector: CNG to CNGX | F33: PJ | G33: PJ/a
B34: *R2,R3,R4,R5,R6 | C34: PRE | D34: SCGSLCNGX | E34: Collector: GSL to CNGX | F34: PJ | G34: PJ/a
B35: *R2,R3,R4,R5,R6 | C35: PRE | D35: SCGSLLPGX | E35: Collector: GSL to LPGX | F35: PJ | G35: PJ/a
B36: *R2,R3,R4,R5,R6 | C36: PRE | D36: SCLPGLPGX | E36: Collector: LPG to LPGX | F36: PJ | G36: PJ/a
B37: *R2,R3,R4,R5,R6 | C37: PRE | D37: SCTLGSLE85 | E37: Collector: GSL to E85X | F37: PJ | G37: PJ/a
B38: *R2,R3,R4,R5,R6 | C38: PRE | D38: SCTLE85E85 | E38: Collector: E85 to E85X | F38: PJ | G38: PJ/a
B39: *R2,R3,R4,R5,R6 | C39: PRE | D39: SCTLGSLGSL | E39: Collector: GSLB to TRNGSL | F39: PJ | G39: PJ/a
B40: *R2,R3,R4,R5,R6 | C40: PRE | D40: SCTRGSLRB | E40: Collector: GSLR to TRN for blending | F40: PJ | G40: PJ/a
B41: *R2,R3,R4,R5,R6 | C41: PRE | D41: SCTRGSLCB | E41: Collector: GSLC to TRN for blending | F41: PJ | G41: PJ/a
B42: *R2,R3,R4,R5,R6 | C42: PRE | D42: SCTLE10GSL | E42: Collector: TRNE10 to GSL | F42: PJ | G42: PJ/a
B43: *R2,R3,R4,R5,R6 | C43: PRE | D43: SCDSLLDSL | E43: Collector: DSLL to DSLB | F43: PJ | G43: PJ/a
... B46: *R2,R3,R4,R5,R6 | C46: PRE | D46: SCTRNELC | E46: Collector: ELC to TRN | F46: PJ | G46: PJ/a
B47: *
B48: *
B49: *
B50: *R2,R3,R4,R5,R6 | C50: PRE | D50: SETLGSL | E50: Collector: TRNGSL to TLGSL | F50: PJ | G50: PJ/a
B51: *R2,R3,R4,R5,R6 | C51: PRE | D51: SETLCNG | E51: Collector: TRNCNG to TLCNG | F51: PJ | G51: PJ/a
B52: *R2,R3,R4,R5,R6 | C52: PRE | D52: SCGSL2CNGX | E52: Collector: TRNGSL to TLCNGX | F52: PJ | G52: PJ/a
B53: *R2,R3,R4,R5,R6 | C53: PRE | D53: SCCNG2CNGX | E53: Collector: TRNCNG to TLCNGX | F53: PJ | G53: PJ/a
B54: *R2,R3,R4,R5,R6 | C54: PRE | D54: SETLLPG | E54: Collector: TRNLPG to TLLPG | F54: PJ | G54: PJ/a
...

Sheet CommData
A1: CommData | B1: R1,R2,R3,R4,R5,R6
E5: ~FI_T
A6: Region | B6: CommName | C6: *CommDesc | D6: *Units | E6: COM_PROJ~2010 | F6: COM_PROJ~2015 | G6: COM_PROJ~2020 | H6: COM_PROJ~2025 | I6: COM_PROJ~2030 | J6: COM_PROJ~2035 | K6: COM_PROJ~2040 | L6: COM_PROJ~2045 | M6: COM_PROJ~2050 | N6: COM_PROJ~2055 | O6: COM_FR~IDAM | P6: COM_FR~IDPM | Q6: COM_FR~IN | R6: COM_FR~IP | S6: COM_FR~SDAM | T6: COM_FR~SDPM | U6: COM_FR~SN | V6: COM_FR~SP | W6: COM_FR~WDAM | X6: COM_FR~WDPM | Y6: COM_FR~WN | Z6: COM_FR~WP
A7: *Energy Demands by End Use
A8: R2 | B8: =Commodities!$D$9 -> TL | C8: =Commodities!$E$9 -> Transportation Light Duty | D8: bn-vmt | E8: ='VMT NYC'!D86 -> 4.3486256 | F8: ='VMT NYC'!E86 -> 4.534572 | G8: ='VMT NYC'!F86 -> 4.7084541 | H8: ='VMT NYC'!G86 -> 7.9819328 | I8: ='VMT NYC'!H86 -> 8.1753543 | J8: ='VMT NYC'!I86 -> 8.3687758 | K8: ='VMT NYC'!J86 -> 8.545568 | L8: ='VMT NYC'!K86 -> 8.7223601 | ... N8: ='VMT NYC'!M86 -> 8.6598825 | O8: 0.0129 | P8: 0.0037 | Q8: 0.3172 | R8: 0.0005 | S8: 0.0501 | T8: 0.0066 | U8: 0.2775 | V8: 0.0001 | W8: 0.0127 | X8: 0.0064 | Y8: 0.3117 | Z8: 0.0006
A9: R3 | B9: =Commodities!$D$9 -> TL | C9: =Commodities!$E$9 -> Transportation Light Duty | D9: bn-vmt | E9: ='VMT NYC'!D90 -> 3.0099004 | F9: ='VMT NYC'!E90 -> 3.0873783 | G9: ='VMT NYC'!F90 -> 3.2294859 | H9: ='VMT NYC'!G90 -> 3.1377448 | I9: ='VMT NYC'!H90 -> 3.2042445 | J9: ='VMT NYC'!I90 -> 3.2707442 | K9: ='VMT NYC'!J90 -> 3.3165636 | L9: ='VMT NYC'!K90 -> 3.3623829 | ... N9: ='VMT NYC'!M90 -> 3.5219104 | O9: 0.0129 | P9: 0.0037 | Q9: 0.3172 | R9: 0.0005 | S9: 0.0501 | T9: 0.0066 | U9: 0.2775 | V9: 0.0001 | W9: 0.0127 | X9: 0.0064 | Y9: 0.3117 | Z9: 0.0006
A10: R4 | B10: =Commodities!$D$9 -> TL | C10: =Commodities!$E$9 -> Transportation Light Duty | D10: bn-vmt | E10: ='VMT NYC'!D94 -> 3.1068522 | F10: ='VMT NYC'!E94 -> 3.0848577 | G10: ='VMT NYC'!F94 -> 3.1426988 | H10: ='VMT NYC'!G94 -> 3.5648024 | I10: ='VMT NYC'!H94 -> 3.630499 | J10: ='VMT NYC'!I94 -> 3.6961955 | K10: ='VMT NYC'!J94 -> 3.7574888 | L10: ='VMT NYC'!K94 -> 3.8187822 | ... N10: ='VMT NYC'!M94 -> 3.9166558 | O10: 0.0129 | P10: 0.0037 | Q10: 0.3172 | R10: 0.0005 | S10: 0.0501 | T10: 0.0066 | U10: 0.2775 | V10: 0.0001 | W10: 0.0127 | X10: 0.0064 | Y10: 0.3117 | Z10: 0.0006
A11: R5 | B11: =Commodities!$D$9 -> TL | C11: =Commodities!$E$9 -> Transportation Light Duty | D11: bn-vmt | E11: ='VMT NYC'!D98 -> 2.0302486 | F11: ='VMT NYC'!E98 -> 2.079645 | G11: ='VMT NYC'!F98 -> 2.1430161 | H11: ='VMT NYC'!G98 -> 2.184425 | I11: ='VMT NYC'!H98 -> 2.2367737 | J11: ='VMT NYC'!I98 -> 2.2891223 | K11: ='VMT NYC'!J98 -> 2.3300414 | L11: ='VMT NYC'!K98 -> 2.3709604 | ... N11: ='VMT NYC'!M98 -> 2.4323318 | O11: 0.0129 | P11: 0.0037 | Q11: 0.3172 | R11: 0.0005 | S11: 0.0501 | T11: 0.0066 | U11: 0.2775 | V11: 0.0001 | W11: 0.0127 | X11: 0.0064 | Y11: 0.3117 | Z11: 0.0006
A12: R6 | B12: =Commodities!$D$9 -> TL | C12: =Commodities!$E$9 -> Transportation Light Duty | D12: bn-vmt | E12: ='VMT NYC'!D102 -> 7.1614064 | F12: ='VMT NYC'!E102 -> 6.8764354 | G12: ='VMT NYC'!F102 -> 6.9182672 | H12: ='VMT NYC'!G102 -> 4.7126752 | I12: ='VMT NYC'!H102 -> 4.8365343 | J12: ='VMT NYC'!I102 -> 4.9603934 | K12: ='VMT NYC'!J102 -> 5.0656795 | L12: ='VMT NYC'!K102 -> 5.1709656 | ... N12: ='VMT NYC'!M102 -> 5.229749 | O12: 0.0129 | P12: 0.0037 | Q12: 0.3172 | R12: 0.0005 | S12: 0.0501 | T12: 0.0066 | U12: 0.2775 | V12: 0.0001 | W12: 0.0127 | X12: 0.0064 | Y12: 0.3117 | Z12: 0.0006
A13: *R7 | B13: =Commodities!$D$9 -> TL | C13: =Commodities!$E$9 -> Transportation Light Duty | D13: bn-vmt | E13: 0 | F13: 0 | G13: 0 | H13: 0 | I13: 0 | J13: 0 | K13: 0 | L13: 0 | M13: 0 | N13: 0
A14: *R8 | B14: =Commodities!$D$9 -> TL | C14: =Commodities!$E$9 -> Transportation Light Duty | D14: bn-vmt | E14: 0 | F14: 0 | G14: 0 | H14: 0 | I14: 0 | J14: 0 | K14: 0 | L14: 0 | M14: 0 | N14: 0
A15: *R9 | B15: =Commodities!$D$9 -> TL | C15: =Commodities!$E$9 -> Transportation Light Duty | D15: bn-vmt | E15: 0 | F15: 0 | G15: 0 | H15: 0 | I15: 0 | J15: 0 | K15: 0 | L15: 0 | M15: 0 | N15: 0
A17: *NYC (R2-R6) | E17: =SUM(E8:E12) -> 19.657033 | F17: =SUM(F8:F12) -> 19.662888 | G17: =SUM(G8:G12) -> 20.141922 | H17: =SUM(H8:H12) -> 21.58158 | I17: =SUM(I8:I12) -> 22.083406 | J17: =SUM(J8:J12) -> 22.585231 | K17: =SUM(K8:K12) -> 23.015341 | L17: =SUM(L8:L12) -> 23.445451 | ... N17: =SUM(N8:N12) -> 23.76053

Sheet TechData_existing
A1: TechData | B1: R1,R2,R3,R4,R5,R6 | L1: R2 | M1: R2 | N1: R2 | O1: R2 | P1: R3 | Q1: R3 | R1: R3 | S1: R3 | T1: R4 | U1: R4 | V1: R4 | W1: R4 | X1: R5 | Y1: R5 | Z1: R5 | AA1: R5 | AB1: R6 | AC1: R6 | AD1: R6 | AE1: R6
F4: ~FI_T
A5: Region | B5: TechName | C5: *TechDesc | D5: *Units | E5: CommIN | F5: CommOUT | G5: NCAP_START | H5: NCAP_LIFE | I5: EFF | J5: NCAP_FOM | K5: NCAP_DRATE | L5: PRC_RESID~R2~2010 | M5: PRC_RESID~R2~2015 | N5: PRC_RESID~R2~2020 | O5: PRC_RESID~R2~2025 | P5: PRC_RESID~R3~2010 | Q5: PRC_RESID~R3~2015 | R5: PRC_RESID~R3~2020 | S5: PRC_RESID~R3~2025 | T5: PRC_RESID~R4~2010 | U5: PRC_RESID~R4~2015 | V5: PRC_RESID~R4~2020 | W5: PRC_RESID~R4~2025 | X5: PRC_RESID~R5~2010 | Y5: PRC_RESID~R5~2015 | Z5: PRC_RESID~R5~2020 | AA5: PRC_RESID~R5~2025 | AB5: PRC_RESID~R6~2010 | AC5: PRC_RESID~R6~2015 | AD5: PRC_RESID~R6~2020 | AE5: PRC_RESID~R6~2025 | AF5: NCAP_AFA | AH5: NCAP_BND~2010 | AI5: NCAP_BND~2015 | AJ5: NCAP_BND~2020 | AK5: NCAP_BND~2025 | AL5: NCAP_BND~2030 | AM5: NCAP_BND~2035 | AN5: NCAP_BND~2040 | AO5: NCAP_BND~2045 | AP5: NCAP_BND~2050 | AQ5: NCAP_BND~2055
A6: * Light Duty Vehicle Demand Technologies - Residuals
A7: =Technologies!B64 -> R2,R3,R4,R5,R6 | B7: =Technologies!D64 -> TLEMCGSL | C7: =Technologies!E64 -> TL.GSL.MC.Existing fleet | D7: bn-vmt, bn-vmt/a | E7: =Commodities!$D$25 -> TLGSL | F7: =Commodities!$D$9 -> TL | G7: 2010 | H7: 15 | I7: =ResidDataAndCalcs!D33 -> 0.085302862 | J7: =ConsolidatedVehData!AB8 -> 38.459799 | K7: 0.18 | L7: =ResidDataAndCalcs!D46 -> 0.13427116 | M7: =ResidDataAndCalcs!E46 -> 0.10070337 | N7: =ResidDataAndCalcs!F46 -> 0.067135579 | O7: =ResidDataAndCalcs!G46 -> 0.033567789 | P7: =ResidDataAndCalcs!I46 -> 0.092935757 | Q7: =ResidDataAndCalcs!J46 -> 0.069701818 | R7: =ResidDataAndCalcs!K46 -> 0.046467878 | S7: =ResidDataAndCalcs!L46 -> 0.023233939 | T7: =ResidDataAndCalcs!N46 -> 0.095929307 | U7: =ResidDataAndCalcs!O46 -> 0.07194698 | V7: =ResidDataAndCalcs!P46 -> 0.047964653 | W7: =ResidDataAndCalcs!Q46 -> 0.023982327 | X7: =ResidDataAndCalcs!S46 -> 0.062687354 | Y7: =ResidDataAndCalcs!T46 -> 0.047015516 | Z7: =ResidDataAndCalcs!U46 -> 0.031343677 | AA7: =ResidDataAndCalcs!V46 -> 0.015671839 | AB7: =ResidDataAndCalcs!X46 -> 0.22112051 | AC7: =ResidDataAndCalcs!Y46 -> 0.16584038 | AD7: =ResidDataAndCalcs!Z46 -> 0.11056026 | AE7: =ResidDataAndCalcs!AA46 -> 0.055280128 | AF7: 1 | AH7: 0 | AI7: 0 | AJ7: 0 | AK7: 0 | AL7: 0 | AM7: 0 | AN7: 0 | AO7: 0 | AP7: 0 | AQ7: 0
A8: =Technologies!B65 -> R2,R3,R4,R5,R6 | B8: =Technologies!D65 -> TLECGSL | C8: =Technologies!E65 -> TL.GSL.C.Existing fleet | D8: bn-vmt, bn-vmt/a | E8: =Commodities!$D$25 -> TLGSL | F8: =Commodities!$D$9 -> TL | G8: 2010 | H8: 15 | I8: =ResidDataAndCalcs!E33 -> 0.10517029 | J8: =ConsolidatedVehData!AB9 -> 38.459799 | K8: 0.18 | L8: =ResidDataAndCalcs!D47 -> 2.7921674 | M8: =ResidDataAndCalcs!E47 -> 2.0941255 | N8: =ResidDataAndCalcs!F47 -> 1.3960837 | O8: =ResidDataAndCalcs!G47 -> 0.69804184 | P8: =ResidDataAndCalcs!I47 -> 1.9325981 | Q8: =ResidDataAndCalcs!J47 -> 1.4494486 | R8: =ResidDataAndCalcs!K47 -> 0.96629906 | S8: =ResidDataAndCalcs!L47 -> 0.48314953 | T8: =ResidDataAndCalcs!N47 -> 1.994849 | U8: =ResidDataAndCalcs!O47 -> 1.4961367 | V8: =ResidDataAndCalcs!P47 -> 0.99742448 | W8: =ResidDataAndCalcs!Q47 -> 0.49871224 | X8: =ResidDataAndCalcs!S47 -> 1.3035829 | Y8: =ResidDataAndCalcs!T47 -> 0.97768717 | Z8: =ResidDataAndCalcs!U47 -> 0.65179145 | AA8: =ResidDataAndCalcs!V47 -> 0.32589572 | AB8: =ResidDataAndCalcs!X47 -> 4.5981988 | AC8: =ResidDataAndCalcs!Y47 -> 3.4486491 | AD8: =ResidDataAndCalcs!Z47 -> 2.2990994 | AE8: =ResidDataAndCalcs!AA47 -> 1.1495497 | AF8: 1 | AH8: 0 | AI8: 0 | AJ8: 0 | AK8: 0 | AL8: 0 | AM8: 0 | AN8: 0 | AO8: 0 | AP8: 0 | AQ8: 0
A9: =Technologies!B66 -> R2,R3,R4,R5,R6 | B9: =Technologies!D66 -> TLEFDSL | C9: =Technologies!E66 -> TL.DSL.F.Existing fleet | D9: bn-vmt, bn-vmt/a | E9: =Commodities!$D$24 -> TRNDSL | F9: =Commodities!$D$9 -> TL | G9: 2010 | H9: 15 | I9: =ResidDataAndCalcs!G33 -> 0.10118525 | J9: =ConsolidatedVehData!AB10 -> 43.267274 | K9: 0.18 | L9: =ResidDataAndCalcs!D48 -> 0.013107509 | M9: =ResidDataAndCalcs!E48 -> 0.0098306321 | N9: =ResidDataAndCalcs!F48 -> 0.0065537547 | O9: =ResidDataAndCalcs!G48 -> 0.0032768774 | P9: =ResidDataAndCalcs!I48 -> 0.0090723602 | Q9: =ResidDataAndCalcs!J48 -> 0.0068042702 | R9: =ResidDataAndCalcs!K48 -> 0.0045361801 | S9: =ResidDataAndCalcs!L48 -> 0.0022680901 | T9: =ResidDataAndCalcs!N48 -> 0.0093645896 | U9: =ResidDataAndCalcs!O48 -> 0.0070234422 | V9: =ResidDataAndCalcs!P48 -> 0.0046822948 | W9: =ResidDataAndCalcs!Q48 -> 0.0023411474 | X9: =ResidDataAndCalcs!S48 -> 0.0061195204 | Y9: =ResidDataAndCalcs!T48 -> 0.0045896403 | Z9: =ResidDataAndCalcs!U48 -> 0.0030597602 | AA9: =ResidDataAndCalcs!V48 -> 0.0015298801 | AB9: =ResidDataAndCalcs!X48 -> 0.021585717 | AC9: =ResidDataAndCalcs!Y48 -> 0.016189288 | AD9: =ResidDataAndCalcs!Z48 -> 0.010792858 | AE9: =ResidDataAndCalcs!AA48 -> 0.0053964292 | AF9: 1 | AH9: 0 | AI9: 0 | AJ9: 0 | AK9: 0 | AL9: 0 | AM9: 0 | AN9: 0 | AO9: 0 | AP9: 0 | AQ9: 0
A10: =Technologies!B67 -> R2,R3,R4,R5,R6 | B10: =Technologies!D67 -> TLEFGSL | C10: =Technologies!E67 -> TL.GSL.F.Existing fleet | D10: bn-vmt, bn-vmt/a | E10: =Commodities!$D$25 -> TLGSL | F10: =Commodities!$D$9 -> TL | G10: 2010 | H10: 15 | I10: =ResidDataAndCalcs!F33 -> 0.091482555 | J10: =ConsolidatedVehData!AB11 -> 43.267274 | K10: 0.18 | L10: =ResidDataAndCalcs!D49 -> 1.0075519 | M10: =ResidDataAndCalcs!E49 -> 0.75566389 | N10: =ResidDataAndCalcs!F49 -> 0.50377593 | O10: =ResidDataAndCalcs!G49 -> 0.25188796 | P10: =ResidDataAndCalcs!I49 -> 0.69737683 | Q10: =ResidDataAndCalcs!J49 -> 0.52303262 | R10: =ResidDataAndCalcs!K49 -> 0.34868842 | S10: =ResidDataAndCalcs!L49 -> 0.17434421 | T10: =ResidDataAndCalcs!N49 -> 0.71984001 | U10: =ResidDataAndCalcs!O49 -> 0.53988001 | V10: =ResidDataAndCalcs!P49 -> 0.35992 | W10: =ResidDataAndCalcs!Q49 -> 0.17996 | X10: =ResidDataAndCalcs!S49 -> 0.47039708 | Y10: =ResidDataAndCalcs!T49 -> 0.35279781 | Z10: =ResidDataAndCalcs!U49 -> 0.23519854 | AA10: =ResidDataAndCalcs!V49 -> 0.11759927 | AB10: =ResidDataAndCalcs!X49 -> 1.6592572 | AC10: =ResidDataAndCalcs!Y49 -> 1.2444429 | AD10: =ResidDataAndCalcs!Z49 -> 0.82962859 | AE10: =ResidDataAndCalcs!AA49 -> 0.4148143 | AF10: 1 | AH10: 0 | AI10: 0 | AJ10: 0 | AK10: 0 | AL10: 0 | AM10: 0 | AN10: 0 | AO10: 0 | AP10: 0 | AQ10: 0
A11: =Technologies!B68 -> R2,R3,R4,R5,R6 | B11: =Technologies!D68 -> TLESSGSL | C11: =Technologies!E68 -> TL.GSL.SS.Existing fleet | D11: bn-vmt, bn-vmt/a | E11: =Commodities!$D$25 -> TLGSL | F11: =Commodities!$D$9 -> TL | G11: 2010 | H11: 15 | I11: =ResidDataAndCalcs!H33 -> 0.083859009 | J11: =ConsolidatedVehData!AB12 -> 43.267274 | K11: 0.18 | L11: =ResidDataAndCalcs!D51 -> 0.090047103 | M11: =ResidDataAndCalcs!E51 -> 0.067535327 | N11: =ResidDataAndCalcs!F51 -> 0.045023552 | O11: =ResidDataAndCalcs!G51 -> 0.022511776 | P11: =ResidDataAndCalcs!I51 -> 0.062326086 | Q11: =ResidDataAndCalcs!J51 -> 0.046744564 | R11: =ResidDataAndCalcs!K51 -> 0.031163043 | S11: =ResidDataAndCalcs!L51 -> 0.015581521 | T11: =ResidDataAndCalcs!N51 -> 0.064333669 | U11: =ResidDataAndCalcs!O51 -> 0.048250252 | V11: =ResidDataAndCalcs!P51 -> 0.032166834 | W11: =ResidDataAndCalcs!Q51 -> 0.016083417 | X11: =ResidDataAndCalcs!S51 -> 0.042040411 | Y11: =ResidDataAndCalcs!T51 -> 0.031530308 | Z11: =ResidDataAndCalcs!U51 -> 0.021020206 | AA11: =ResidDataAndCalcs!V51 -> 0.010510103 | AB11: =ResidDataAndCalcs!X51 -> 0.14829143 | AC11: =ResidDataAndCalcs!Y51 -> 0.11121857 | AD11: =ResidDataAndCalcs!Z51 -> 0.074145714 | AE11: =ResidDataAndCalcs!AA51 -> 0.037072857 | AF11: 1 | AH11: 0 | AI11: 0 | AJ11: 0 | AK11: 0 | AL11: 0 | AM11: 0 | AN11: 0 | AO11: 0 | AP11: 0 | AQ11: 0
A12: =Technologies!B69 -> R2,R3,R4,R5,R6 | B12: =Technologies!D69 -> TLELSGSL | C12: =Technologies!E69 -> TL.GSL.LS.Existing fleet | D12: bn-vmt, bn-vmt/a | E12: =Commodities!$D$25 -> TLGSL | F12: =Commodities!$D$9 -> TL | G12: 2010 | H12: 15 | I12: =ResidDataAndCalcs!I33 -> 0.07005577 | J12: =ConsolidatedVehData!AB13 -> 43.267274 | K12: 0.18 | L12: =ResidDataAndCalcs!D50 -> 0.064089061 | M12: =ResidDataAndCalcs!E50 -> 0.048066795 | N12: =ResidDataAndCalcs!F50 -> 0.03204453 | O12: =ResidDataAndCalcs!G50 -> 0.016022265 | P12: =ResidDataAndCalcs!I50 -> 0.044359231 | Q12: =ResidDataAndCalcs!J50 -> 0.033269424 | R12: =ResidDataAndCalcs!K50 -> 0.022179616 | S12: =ResidDataAndCalcs!L50 -> 0.011089808 | T12: =ResidDataAndCalcs!N50 -> 0.045788085 | U12: =ResidDataAndCalcs!O50 -> 0.034341064 | V12: =ResidDataAndCalcs!P50 -> 0.022894042 | W12: =ResidDataAndCalcs!Q50 -> 0.011447021 | X12: =ResidDataAndCalcs!S50 -> 0.029921345 | Y12: =ResidDataAndCalcs!T50 -> 0.022441009 | Z12: =ResidDataAndCalcs!U50 -> 0.014960673 | AA12: =ResidDataAndCalcs!V50 -> 0.0074803363 | AB12: =ResidDataAndCalcs!X50 -> 0.10554319 | AC12: =ResidDataAndCalcs!Y50 -> 0.07915739 | AD12: =ResidDataAndCalcs!Z50 -> 0.052771594 | AE12: =ResidDataAndCalcs!AA50 -> 0.026385797 | AF12: 1 | AH12: 0 | AI12: 0 | AJ12: 0 | AK12: 0 | AL12: 0 | AM12: 0 | AN12: 0 | AO12: 0 | AP12: 0 | AQ12: 0
A13: =Technologies!B70 -> R2,R3,R4,R5,R6 | B13: =Technologies!D70 -> TLEMGSL | C13: =Technologies!E70 -> TL.GSL.M.Existing Fleet | D13: bn-vmt, bn-vmt/a | E13: =Commodities!$D$25 -> TLGSL | F13: =Commodities!$D$9 -> TL | G13: 2010 | H13: 15 | I13: =ResidDataAndCalcs!J33 -> 0.091020522 | J13: =ConsolidatedVehData!AB14 -> 43.267274 | K13: 0.18 | L13: =ResidDataAndCalcs!D52 -> 0.060335101 | M13: =ResidDataAndCalcs!E52 -> 0.045251326 | N13: =ResidDataAndCalcs!F52 -> 0.030167551 | O13: =ResidDataAndCalcs!G52 -> 0.015083775 | P13: =ResidDataAndCalcs!I52 -> 0.041760929 | Q13: =ResidDataAndCalcs!J52 -> 0.031320697 | R13: =ResidDataAndCalcs!K52 -> 0.020880465 | S13: =ResidDataAndCalcs!L52 -> 0.010440232 | T13: =ResidDataAndCalcs!N52 -> 0.043106089 | U13: =ResidDataAndCalcs!O52 -> 0.032329566 | V13: =ResidDataAndCalcs!P52 -> 0.021553044 | W13: =ResidDataAndCalcs!Q52 -> 0.010776522 | X13: =ResidDataAndCalcs!S52 -> 0.028168729 | Y13: =ResidDataAndCalcs!T52 -> 0.021126547 | Z13: =ResidDataAndCalcs!U52 -> 0.014084365 | AA13: =ResidDataAndCalcs!V52 -> 0.0070421823 | AB13: =ResidDataAndCalcs!X52 -> 0.099361089 | AC13: =ResidDataAndCalcs!Y52 -> 0.074520817 | AD13: =ResidDataAndCalcs!Z52 -> 0.049680545 | AE13: =ResidDataAndCalcs!AA52 -> 0.024840272 | AF13: 1 | AH13: 0 | AI13: 0 | AJ13: 0 | AK13: 0 | AL13: 0 | AM13: 0 | AN13: 0 | AO13: 0 | AP13: 0 | AQ13: 0
A14: =Technologies!B71 -> R2,R3,R4,R5,R6 | B14: =Technologies!D71 -> TLEPGSL | C14: =Technologies!E71 -> TL.GSL.P.Existing Fleet | D14: bn-vmt, bn-vmt/a | E14: =Commodities!$D$25 -> TLGSL | F14: =Commodities!$D$9 -> TL | G14: 2010 | H14: 15 | I14: =ResidDataAndCalcs!K33 -> 0.075138134 | J14: =ConsolidatedVehData!AB15 -> 48.074749 | K14: 0.18 | L14: =ResidDataAndCalcs!D53 -> 0.1575951 | M14: =ResidDataAndCalcs!E53 -> 0.11819632 | N14: =ResidDataAndCalcs!F53 -> 0.078797548 | O14: =ResidDataAndCalcs!G53 -> 0.039398774 | P14: =ResidDataAndCalcs!I53 -> 0.10907942 | Q14: =ResidDataAndCalcs!J53 -> 0.081809563 | R14: =ResidDataAndCalcs!K53 -> 0.054539708 | S14: =ResidDataAndCalcs!L53 -> 0.027269854 | T14: =ResidDataAndCalcs!N53 -> 0.11259297 | U14: =ResidDataAndCalcs!O53 -> 0.084444727 | V14: =ResidDataAndCalcs!P53 -> 0.056296485 | W14: =ResidDataAndCalcs!Q53 -> 0.028148242 | X14: =ResidDataAndCalcs!S53 -> 0.073576633 | Y14: =ResidDataAndCalcs!T53 -> 0.055182475 | Z14: =ResidDataAndCalcs!U53 -> 0.036788316 | AA14: =ResidDataAndCalcs!V53 -> 0.018394158 | AB14: =ResidDataAndCalcs!X53 -> 0.25953086 | AC14: =ResidDataAndCalcs!Y53 -> 0.19464814 | AD14: =ResidDataAndCalcs!Z53 -> 0.12976543 | AE14: =ResidDataAndCalcs!AA53 -> 0.064882714 | AF14: 1 | AH14: 0 | AI14: 0 | AJ14: 0 | AK14: 0 | AL14: 0 | AM14: 0 | AN14: 0 | AO14: 0 | AP14: 0 | AQ14: 0
A15: =Technologies!B72 -> R2,R3,R4,R5,R6 | B15: =Technologies!D72 -> TLEPDSL | C15: =Technologies!E72 -> TL.DSL.P.Existing fleet | D15: bn-vmt, bn-vmt/a | E15: =Commodities!$D$24 -> TRNDSL | F15: =Commodities!$D$9 -> TL | G15: 2010 | H15: 15 | I15: =ResidDataAndCalcs!L33 -> 0.078776644 | J15: =ConsolidatedVehData!AB16 -> 48.074749 | K15: 0.18 | L15: =ResidDataAndCalcs!D54 -> 0.025380885 | M15: =ResidDataAndCalcs!E54 -> 0.019035663 | N15: =ResidDataAndCalcs!F54 -> 0.012690442 | O15: =ResidDataAndCalcs!G54 -> 0.0063452211 | P15: =ResidDataAndCalcs!I54 -> 0.017567375 | Q15: =ResidDataAndCalcs!J54 -> 0.013175531 | R15: =ResidDataAndCalcs!K54 -> 0.0087836873 | S15: =ResidDataAndCalcs!L54 -> 0.0043918436 | T15: =ResidDataAndCalcs!N54 -> 0.018133236 | U15: =ResidDataAndCalcs!O54 -> 0.013599927 | V15: =ResidDataAndCalcs!P54 -> 0.0090666182 | W15: =ResidDataAndCalcs!Q54 -> 0.0045333091 | X15: =ResidDataAndCalcs!S54 -> 0.011849607 | Y15: =ResidDataAndCalcs!T54 -> 0.0088872055 | Z15: =ResidDataAndCalcs!U54 -> 0.0059248037 | AA15: =ResidDataAndCalcs!V54 -> 0.0029624018 | AB15: =ResidDataAndCalcs!X54 -> 0.041797764 | AC15: =ResidDataAndCalcs!Y54 -> 0.031348323 | AD15: =ResidDataAndCalcs!Z54 -> 0.020898882 | AE15: =ResidDataAndCalcs!AA54 -> 0.010449441 | AF15: 1 | AH15: 0 | AI15: 0 | AJ15: 0 | AK15: 0 | AL15: 0 | AM15: 0 | AN15: 0 | AO15: 0 | AP15: 0 | AQ15: 0
A16: * | B16: =Technologies!D73 -> TLEETHX | C16: =Technologies!E73 -> TL.E85X.F.Existing fleet | D16: bn-vmt, bn-vmt/a | E16: =Commodities!$D$26 -> TLE85X | F16: =Commodities!$D$9 -> TL | G16: 2010 | H16: 15 | I16: =ConsolidatedVehData!AF18 -> 0.1596 | J16: =ConsolidatedVehData!AB18 -> 43.267274 | K16: 0.18 | AF16: 1 | AH16: 0 | AI16: 0 | AJ16: 0 | AK16: 0 | AL16: 0 | AM16: 0 | AN16: 0 | AO16: 0 | AP16: 0 | AQ16: 0
A17: * | B17: =Technologies!D74 -> TLECNGX | C17: =Technologies!E74 -> TL.CNGX.F.Existing fleet | D17: bn-vmt, bn-vmt/a | E17: TRNCNG | F17: =Commodities!$D$9 -> TL | G17: 2010 | H17: 15 | I17: =ConsolidatedVehData!AF19 -> 0.1712 | J17: =ConsolidatedVehData!AB19 -> 38.940547 | K17: 0.18 | AF17: 1 | AH17: 0 | AI17: 0 | AJ17: 0 | AK17: 0 | AL17: 0 | AM17: 0 | AN17: 0 | AO17: 0 | AP17: 0 | AQ17: 0
A18: * | B18: =Technologies!D75 -> TLELPGX | C18: =Technologies!E75 -> TL.LPGX.F.Existing fleet | D18: bn-vmt, bn-vmt/a | E18: TRNLPGX | F18: =Commodities!$D$9 -> TL | G18: 2010 | H18: 15 | I18: =ConsolidatedVehData!AF20 -> 0.1703 | J18: =ConsolidatedVehData!AB20 -> 38.940547 | K18: 0.18 | AF18: 1 | AH18: 0 | AI18: 0 | AJ18: 0 | AK18: 0 | AL18: 0 | AM18: 0 | AN18: 0 | AO18: 0 | AP18: 0 | AQ18: 0
A19: =Technologies!B76 -> R2,R3,R4,R5,R6 | B19: =Technologies!D76 -> TLEELC | C19: =Technologies!E76 -> TL.ELC.F.Existing fleet | D19: bn-vmt, bn-vmt/a | E19: =Commodities!$D$32 -> TRNELC | F19: =Commodities!$D$9 -> TL | G19: 2010 | H19: 15 | I19: =ConsolidatedVehData!AF21 -> 0.7225 | J19: =ConsolidatedVehData!AB21 -> 25.960365 | K19: 0.18 | L19: =ResidDataAndCalcs!D55 -> 0.0040804693 | M19: =ResidDataAndCalcs!E55 -> 0.0091717702 | N19: =ResidDataAndCalcs!F55 -> 0.0068788276 | O19: =ResidDataAndCalcs!G55 -> 0.0034394138 | P19: =ResidDataAndCalcs!I55 -> 0.0028242961 | Q19: =ResidDataAndCalcs!J55 -> 0.006348239 | R19: =ResidDataAndCalcs!K55 -> 0.0047611793 | S19: =ResidDataAndCalcs!L55 -> 0.0031741195 | T19: =ResidDataAndCalcs!N55 -> 0.0029152693 | U19: =ResidDataAndCalcs!O55 -> 0.0065527219 | V19: =ResidDataAndCalcs!P55 -> 0.0049145414 | W19: =ResidDataAndCalcs!Q55 -> 0.0032763609 | X19: =ResidDataAndCalcs!S55 -> 0.0019050541 | Y19: =ResidDataAndCalcs!T55 -> 0.0042820366 | Z19: =ResidDataAndCalcs!U55 -> 0.0032115274 | AA19: =ResidDataAndCalcs!V55 -> 0.0021410183 | AB19: =ResidDataAndCalcs!X55 -> 0.006719801 | AC19: =ResidDataAndCalcs!Y55 -> 0.01510426 | AD19: =ResidDataAndCalcs!Z55 -> 0.011328195 | AE19: =ResidDataAndCalcs!AA55 -> 0.0075521302 | AF19: 1 | AH19: 0 | AI19: 0 | AJ19: 0 | AK19: 0 | AL19: 0 | AM19: 0 | AN19: 0 | AO19: 0 | AP19: 0 | AQ19: 0
A21: * | L21: =SUM(L7:L19) -> 4.3486256 | M21: =SUM(M7:M19) -> 3.2675806 | N21: =SUM(N7:N19) -> 2.1791514 | O21: =SUM(O7:O19) -> 1.0895757 | P21: =SUM(P7:P19) -> 3.0099004 | Q21: =SUM(Q7:Q19) -> 2.2616553 | R21: =SUM(R7:R19) -> 1.5082992 | S21: =SUM(S7:S19) -> 0.75494315 | ... AE21: =SUM(AE7:AE19) -> 1.7962238
L23: =SUM(L7:L15,L19)-CommData!$E$8 -> 0 | P23: =SUM(P7:P15,P19)-CommData!$E$9 -> 0 | T23: =SUM(T7:T15,T19)-CommData!$E$10 -> 0 | X23: =SUM(X7:X15,X19)-CommData!$E$11 -> 0 | AB23: =SUM(AB7:AB15,AB19)-CommData!$E$12 -> 0

Sheet VMT NYC
A1: Description: Calculated regional light duty vehicle demand | R1: EMISSIONS INTENSITY FACTORS
R2: Transportation | S2: GJ Consumed | T2: PJ Consumed | U2: GJ/Liter | V2: Liters Consumed | W2: Gal. Consumed | X2: km/liter | Y2: Distance km | Z2: MPGe | AA2: Miles Traveled | AB2: Miles Traveled (B VKM) | AC2: Source | AD2: Average eff | AK2: Eff
A3: Inputs: | R3: Biofuel | S3: 0 | T3: =S3/1000000 -> 0 | V3: =S3*U3 -> 0 | W3: =V3*0.264172 -> 0 | X3: =W3*0.264172 -> 0 | AF3: car | AG3: =ResidDataAndCalcs!N86 -> 0.027631647 | AH3: =AG3/SUM($AG$3:$AG$6) -> 0.031386722 | AI3: =TechData_existing!B7 -> TLEMCGSL | AJ3: =TechData_existing!C7 -> TL.GSL.MC.Existing fleet | AK3: =TechData_existing!I7 -> 0.085302862
A4: Household Vehicles Energy Use, Energy Information Agency, U.S. Department of Energy, http://www.eia.doe.gov/emeu/rtecs/ | R4: CNG-Transit Bus | S4: 1420989 | T4: =S4/1000000 -> 1.420989 | V4: 1420989 | W4: =V4*0.264172 -> 375385.51 | X4: 0.003233282 | Y4: =S4*X4 -> 4594.4582 | Z4: =AA4/W4 -> 0.0076051499 | AA4: =Y4*0.621371 -> 2854.8631 | AC4: NYC GHG Inventory 14 | AF4: car | AG4: =ResidDataAndCalcs!O86 -> 0.46605378 | AH4: =AG4/SUM($AG$3:$AG$6) -> 0.52938939 | AI4: =TechData_existing!B8 -> TLECGSL | AJ4: =TechData_existing!C8 -> TL.GSL.C.Existing fleet | AK4: =TechData_existing!I8 -> 0.10517029
R5: Diesel-Commuter Rail | S5: 195751 | T5: =S5/1000000 -> 0.195751 | V5: 5064028 | W5: =V5*0.264172 -> 1337774.4 | X5: =Y5/V5 -> 17.005703 | Y5: =1.60934*AA5 -> 86117354 | Z5: 40 | AA5: =W5*Z5 -> 53510976 | AC5: Railtec Article | AF5: car | AG5: =ResidDataAndCalcs!P86/2 -> 0.1933378 | AH5: =AG5/SUM($AG$3:$AG$6) -> 0.21961195 | AI5: =TechData_existing!B9 -> TLEFDSL | AJ5: =TechData_existing!C9 -> TL.DSL.F.Existing fleet | AK5: =TechData_existing!I9 -> 0.10118525
R6: Diesel-Heavy Trucks | S6: 12555252 | T6: =S6/1000000 -> 12.555252 | V6: 326200350 | W6: =V6*0.264172 -> 86172999 | X6: 3.65 | Y6: =V6*X6 -> 1.1906313e+09 | Z6: =AA6/W6 -> 8.5853313 | AA6: =Y6*0.621371 -> 7.3982375e+08 | AC6: NYC GHG Inventory 14 | AF6: car | AG6: =AG5 -> 0.1933378 | AH6: =AG6/SUM($AG$3:$AG$6) -> 0.21961195 | AI6: =TechData_existing!B10 -> TLEFGSL | AJ6: =TechData_existing!C10 -> TL.GSL.F.Existing fleet | AK6: =TechData_existing!I10 -> 0.091482555
A7: Note: Calculates VMT/capita per region for 2000, then uses national growth in VMT/capita to project these values. Results used with regional population to derive regional VMT | R7: Diesel-Light Trucks | S7: 1356142 | T7: =S7/1000000 -> 1.356142 | V7: 35234181 | W7: =V7*0.264172 -> 9307884.1 | X7: 4.38 | Y7: =V7*X7 -> 1.5432571e+08 | Z7: =AA7/W7 -> 10.302398 | AA7: =Y7*0.621371 -> 95893522 | AB7: =S7*AD7/1000000 -> 0.10683232 | AC7: NYC GHG Inventory 14 | AD7: =AK11 -> 0.078776644 | AF7: truck | AG7: =ResidDataAndCalcs!Q86 -> 0.018764479 | AH7: =AG7/SUM($AG$7:$AG$11) -> 0.15684252 | AI7: =TechData_existing!B11 -> TLESSGSL | AJ7: =TechData_existing!C11 -> TL.GSL.SS.Existing fleet | AK7: =TechData_existing!I11 -> 0.083859009
R8: Diesel-Non Bus | S8: 290413 | T8: =S8/1000000 -> 0.290413 | V8: 7545275 | W8: =V8*0.264172 -> 1993250.4 | X8: 5.38 | Y8: =V8*X8 -> 40593580 | Z8: =AA8/W8 -> 12.654543 | AA8: =Y8*0.621371 -> 25223673 | AC8: NYC GHG Inventory 14 | AF8: truck | AG8: =ResidDataAndCalcs!R86 -> 0.015986614 | AH8: =AG8/SUM($AG$7:$AG$11) -> 0.13362379 | AI8: =TechData_existing!B12 -> TLELSGSL | AJ8: =TechData_existing!C12 -> TL.GSL.LS.Existing fleet | AK8: =TechData_existing!I12 -> 0.07005577
R9: Diesel-Cars | S9: 545254 | T9: =S9/1000000 -> 0.545254 | V9: 14166357 | W9: =V9*0.264172 -> 3742354.9 | X9: 6.73 | Y9: =V9*X9 -> 95339583 | Z9: =AA9/W9 -> 15.82994 | AA9: =Y9*0.621371 -> 59241252 | AB9: =S9*AD9/1000000 -> 0.055171662 | AC9: NYC GHG Inventory 14 | AD9: =AK5 -> 0.10118525 | AF9: truck | AG9: =ResidDataAndCalcs!S86 -> 0.011583698 | AH9: =AG9/SUM($AG$7:$AG$11) -> 0.096822105 | AI9: =TechData_existing!B13 -> TLEMGSL | AJ9: =TechData_existing!C13 -> TL.GSL.M.Existing Fleet | AK9: =TechData_existing!I13 -> 0.091020522
A10: NYC Light Duty Vehicle Miles Traveled (VMT) Adjusted to Account for Chosen Population Projection | R10: Diesel-Solid Waste | S10: 219257 | T10: =S10/1000000 -> 0.219257 | V10: 5671501 | W10: =V10*0.264172 -> 1498251.8 | X10: 3.65 | Y10: =V10*X10 -> 20700979 | Z10: =AA10/W10 -> 8.5853313 | AA10: =Y10*0.621371 -> 12862988 | AC10: NYC GHG Inventory 14 | AF10: truck | AG10: =ResidDataAndCalcs!T86/2 -> 0.036652094 | AH10: =AG10/SUM($AG$7:$AG$11) -> 0.30635579 | AI10: =TechData_existing!B14 -> TLEPGSL | AJ10: =TechData_existing!C14 -> TL.GSL.P.Existing Fleet | AK10: =TechData_existing!I14 -> 0.075138134
C11: 2005 | D11: 2010 | E11: 2015 | F11: 2020 | G11: 2025 | H11: 2030 | I11: 2035 | J11: 2040 | K11: 2045 | L11: 2050 | M11: 2055 | R11: Diesel-Transit Bus | S11: 7260325 | T11: =S11/1000000 -> 7.260325 | V11: 188631878 | W11: =V11*0.264172 -> 49831260 | X11: 5.38 | Y11: =V11*X11 -> 1.0148395e+09 | Z11: =AA11/W11 -> 12.654543 | AA11: =Y11*0.621371 -> 6.3059184e+08 | AC11: NYC GHG Inventory 14 | AF11: truck | AG11: =AG10 -> 0.036652094 | AH11: =AG11/SUM($AG$7:$AG$11) -> 0.30635579 | AI11: =TechData_existing!B15 -> TLEPDSL | AJ11: =TechData_existing!C15 -> TL.DSL.P.Existing fleet | AK11: =TechData_existing!I15 -> 0.078776644
A12: Scenario Pop from Population Tab (millions) | C12: ='Population NYC'!D15/1000000 -> 8.175133 | D12: ='Population NYC'!E15/1000000 -> 8.175133 | E12: ='Population NYC'!F15/1000000 -> 8.491079 | F12: ='Population NYC'!G15/1000000 -> 8.550971 | G12: ='Population NYC'!H15/1000000 -> 8.685999 | H12: ='Population NYC'!I15/1000000 -> 8.821027 | I12: ='Population NYC'!J15/1000000 -> 8.923086 | J12: ='Population NYC'!K15/1000000 -> 9.025145 | ... M12: ='Population NYC'!N15/1000000 -> 9.485589 | R12: Diesel-Ships & Boats | S12: 0 | T12: =S12/1000000 -> 0 | U12: 0.03866 | V12: =S12*U12 -> 0 | W12: =V12*0.264172 -> 0 | X12: 2 | Y12: =V12*X12 -> 0 | AA12: =Y12*0.621371 -> 0
A13: Scenario LDV vehicle miles traveled (bln-VMT) | C13: =AB19 -> 19.661797 | D13: =C13 -> 19.661797 | E13: =D13*'AEO14 DMD'!E32/'AEO14 DMD'!D32 -> 20.068306 | F13: =E13*'AEO14 DMD'!F32/'AEO14 DMD'!E32 -> 21.057218 | G13: =F13*'AEO14 DMD'!G32/'AEO14 DMD'!F32 -> 21.990086 | H13: =G13*'AEO14 DMD'!H32/'AEO14 DMD'!G32 -> 23.17928 | I13: =H13*'AEO14 DMD'!I32/'AEO14 DMD'!H32 -> 24.394242 | J13: =I13*'AEO14 DMD'!J32/'AEO14 DMD'!I32 -> 24.603292 | K13: =J13*'AEO14 DMD'!K32/'AEO14 DMD'!J32 -> 26.156676 | L13: =K13*'AEO14 DMD'!L32/'AEO14 DMD'!K32 -> 27.037894 | M13: =L13*'AEO14 DMD'!M32/'AEO14 DMD'!L32 -> 27.919111 | R13: Diesel-Other Off-Road Vehicles | S13: 0 | T13: =S13/1000000 -> 0 | X13: 2 | Y13: =V13*X13 -> 0 | AA13: =Y13*0.621371 -> 0
A14: Ratio (bln-VMT/million people) | C14: =C13/C12 -> 2.4050736 | D14: =D13/D12 -> 2.4050736 | E14: =D14*'AEO14 DMD'!E34/'AEO14 DMD'!D34 -> 2.3511439 | F14: =E14*'AEO14 DMD'!F34/'AEO14 DMD'!E34 -> 2.3670522 | G14: =F14*'AEO14 DMD'!G34/'AEO14 DMD'!F34 -> 2.3756671 | H14: =G14*'AEO14 DMD'!H34/'AEO14 DMD'!G34 -> 2.4102902 | I14: =H14*'AEO14 DMD'!I34/'AEO14 DMD'!H34 -> 2.4449944 | J14: =I14*'AEO14 DMD'!J34/'AEO14 DMD'!I34 -> 2.4449944 | K14: =J14*'AEO14 DMD'!K34/'AEO14 DMD'!J34 -> 2.4449944 | L14: =K14*'AEO14 DMD'!L34/'AEO14 DMD'!K34 -> 2.4449944 | M14: =L14*'AEO14 DMD'!M34/'AEO14 DMD'!L34 -> 2.4449944 | R14: Electricity-Subway | S14: 25432916 | T14: =S14/1000000 -> 25.432916 | U14: 1 | X14: =Y14/S14 -> 22.717018 | Y14: =AA14*1.6 -> 577760000 | AA14: 361100000 | AC14: NYC GHG Inventory 14
R15: Ethanol (E100) | S15: 0 | T15: =S15/1000000 -> 0 | U15: 0.02342 | V15: 0 | W15: =V15*0.264172 -> 0 | X15: 6.58 | Y15: =V15*X15 -> 0 | AA15: =Y15*0.621371 -> 0 | AC15: NYC GHG Inventory 14
A16: Assumed LDV VMT (from city data) | R16: Gas-Light Trucks | S16: 14846296 | T16: =S16/1000000 -> 14.846296 | U16: 0.03484 | V16: =S16*U16 -> 517244.95 | W16: =V16*0.264172 -> 136641.63 | X16: 6.21 | Y16: =V16*X16 -> 3212091.2 | Z16: =AA16/W16 -> 14.606824 | AA16: =Y16*0.621371 -> 1995900.3 | AB16: =S16*AD16/1000000 -> 2.4941777 | AC16: NYC GHG Inventory 14 | AD16: 0.168
C17: 2005 | D17: 2010 | E17: 2015 | F17: 2020 | G17: 2025 | H17: 2030 | I17: 2035 | J17: 2040 | K17: 2045 | L17: 2050 | M17: 2055 | R17: Gas-Cars | S17: 122351394 | T17: =S17/1000000 -> 122.35139 | U17: 0.03484 | V17: 3629210490 | W17: =V17*0.264172 -> 9.5873579e+08 | X17: 8.72 | Y17: =V17*X17 -> 3.1646715e+10 | Z17: =AA17/W17 -> 20.510709 | AA17: =Y17*0.621371 -> 1.9664351e+10 | AB17: =S17*AD17/1000000 -> 21.289143 | AC17: NYC GHG Inventory 14 | AD17: 0.174
A18: R1 - Supply Region | AF18: TL-DSL Ratio | AG18: =(T7+T9)/(T7+T9+T16+T17) -> 0.013669364
A19: Brooklyn | C19: =D19 -> 4.3486256e+09 | D19: 4.3486256e+09 | E19: 4.534572e+09 | F19: 4.7084541e+09 | G19: 7981932785 | H19: 8175354315 | I19: 8368775845 | J19: 8545567975 | K19: 8722360105 | L19: 8480175670 | R19: Transportation VMT Estimates | S19: km/year | U19: km/liter | V19: Gallons/year | W19: MPG Rating | X19: Total VMT | Y19: VMT/Person | Z19: References | AB19: =ResidDataAndCalcs!R33+'GHG Reports'!C103 -> 19.661797
A20: Bronx | C20: =D20 -> 3.0099004e+09 | D20: 3.0099004e+09 | E20: 3.0873783e+09 | F20: 3.2294859e+09 | G20: 3137744765 | H20: 3204244480 | I20: 3270744195 | J20: 3.3165636e+09 | K20: 3362382920 | L20: 3445751840 | R20: Biofuel | S20: =Y3 -> 0 | U20: =S20/V3 -> #DIV/0! | V20: =0.264172*S3 -> 0 | W20: =0.264172*S3 -> 0 | X20: =V20*W20 -> 0 | Y20: =X20/9000000 -> 0 | Z20: DOT RITA Bus Fuel Economy
A21: Manhathan | C21: =D21 -> 3.1068522e+09 | D21: 3.1068522e+09 | E21: 3.0848577e+09 | F21: 3.1426988e+09 | G21: 3564802430 | H21: 3.630499e+09 | I21: 3696195495 | J21: 3757488850 | K21: 3818782205 | L21: 3874745100 | R21: CNG-Transit Bus (GJ) | S21: =Y4 -> 4594.4582 | U21: =S21/V4 -> 0.003233282 | V21: =0.264172*S4 -> 375385.51 | W21: 50 | X21: =V21*W21 -> 18769275 | Y21: =X21/9000000 -> 2.085475 | Z21: Assumes 2.78 kBut/PMT
A22: Staten Island | C22: =D22 -> 2.0302486e+09 | D22: 2.0302486e+09 | E22: 2.079645e+09 | F22: 2.1430161e+09 | G22: 2184424990 | H22: 2236773655 | I22: 2289122320 | J22: 2330041375 | K22: 2370960430 | L22: 2405403290 | R22: Diesel-Commuter Rail | S22: =Y5 -> 86117354 | U22: =S22/V5 -> 17.005703 | V22: =0.264172*S5 -> 51711.933 | W22: 0.5 | X22: =V22*W22 -> 25855.967 | Y22: =X22/9000000 -> 0.0028728852 | Z22: 361.1 million miles by NYC subway in 2014
A23: Queens | C23: =D23 -> 7.1614064e+09 | D23: 7.1614064e+09 | E23: 6.8764354e+09 | F23: 6.9182672e+09 | G23: 4712675235 | H23: 4836534335 | I23: 4960393435 | J23: 5065679510 | K23: 5170965585 | L23: 5161858105 | R23: Diesel-Heavy Trucks | S23: =Y6 -> 1.1906313e+09 | U23: =S23/V6 -> 3.65 | V23: =0.264172*S6 -> 3316746 | W23: 5 | X23: =V23*W23 -> 16583730 | Y23: =X23/9000000 -> 1.8426367
R24: Diesel-Light Trucks | S24: =Y7 -> 1.5432571e+08 | U24: =S24/V7 -> 4.38 | V24: =0.264172*S7 -> 358254.74 | W24: 15 | X24: =V24*W24 -> 5373821.2 | Y24: =X24/9000000 -> 0.59709124
R25: Diesel-Non Bus | S25: =Y8 -> 40593580 | U25: =S25/V8 -> 5.38 | V25: =0.264172*S8 -> 76718.983 | W25: 25 | X25: =V25*W25 -> 1917974.6 | Y25: =X25/9000000 -> 0.21310829 | AB25: 30.87
R26: Diesel-Cars | S26: =Y9 -> 95339583 | U26: =S26/V9 -> 6.73 | V26: =0.264172*S9 -> 144040.84 | W26: 25 | X26: =V26*W26 -> 3601021 | Y26: =X26/9000000 -> 0.40011344 | AB26: 17.07
R27: Diesel-Solid Waste | S27: =Y10 -> 20700979 | U27: =S27/V10 -> 3.65 | V27: =0.264172*S10 -> 57921.56 | W27: 5 | X27: =V27*W27 -> 289607.8 | Y27: =X27/9000000 -> 0.032178645 | AB27: 19.54
R28: Diesel-Transit Bus | S28: =Y11 -> 1.0148395e+09 | U28: =S28/V11 -> 5.38 | V28: =0.264172*S11 -> 1917974.6 | W28: 5 | X28: =V28*W28 -> 9589872.9 | Y28: =X28/9000000 -> 1.0655414 | AB28: 5.78
R29: Diesel-Ships & Boats | S29: =Y12 -> 0 | U29: =S29/V12 -> #DIV/0! | V29: =0.264172*S12 -> 0 | W29: 0.1 | X29: =V29*W29 -> 0 | Y29: =X29/9000000 -> 0 | AB29: 27.49
R30: Diesel-Other Off-Road Vehicles | S30: =Y13 -> 0 | U30: =S30/V13 -> #DIV/0! | V30: =0.264172*S13 -> 0 | W30: 0.1 | X30: =V30*W30 -> 0 | Y30: =X30/9000000 -> 0
R31: Electricity-Subway (GJ) | S31: =Y14 -> 577760000 | U31: =S31/V14 -> #DIV/0! | V31: =0.264172*S14 -> 6718664.3 | W31: =X31/V31 -> 53.745802 | X31: 361100000 | Y31: =X31/9000000 -> 40.122222
R32: Ethanol | S32: =Y15 -> 0 | U32: =S32/V15 -> #DIV/0! | V32: =0.264172*S15 -> 0 | X32: =V32*W32 -> 0 | Y32: =X32/9000000 -> 0
R33: Gas-Light Trucks | S33: =Y16 -> 3212091.2 | U33: =S33/V16 -> 6.21 | V33: =0.264172*S16 -> 3921975.7 | W33: 15 | X33: =V33*W33 -> 58829636 | Y33: =X33/9000000 -> 6.5366262
R34: Gas-Cars | S34: =Y17 -> 3.1646715e+10 | U34: =S34/V17 -> 8.72 | V34: =0.264172*S17 -> 32321812 | W34: 25 | X34: =V34*W34 -> 8.0804531e+08 | Y34: =X34/9000000 -> 89.782812
R35: LDV Total | S35: =S24+S26+S33+S34 -> 3.1899593e+10 | V35: =V24+V26+V33+V34 -> 36746084 | X35: =X24+X26+X33+X34 -> 8.7584979e+08 | Y35: =X35/(D12*1000000) -> 107.13585 | Z35: Census Street Blog Post on NYC Car Ownership
R36: LDV Total | S36: =S21+S23+S25+S27+S28 -> 2.2667699e+09 | V36: =V21+V23+V25+V27+V28 -> 5744746.7 | X36: =X21+X23+X25+X27+X28 -> 47150461 | Y36: =X36/(D13*1000000) -> 2.3980749 | Z36: NYC Car Ownership by StatsBee
R37: Subway Ridership | S37: 1751000000 | U37: Subway Miles | V37: 361100000 | W37: Miles/GJ | X37: =V37/S14 -> 14.198136 | Y37: =V37/(D12*1000000) -> 44.170535 | Z37: NYC Estimated VMT/person-day
R39: NYC Car Ownership | S39: 2010 Population | U39: Households | V39: % Car Ownership | W39: Cars/Household | X39: Total Vehicles | Y39: Cars per Capita | Z39: Cars/100 People | AA39: Total Vehicles
R40: Brooklyn | S40: ='Population NYC'!E10 -> 2504700 | U40: =S40/3 -> 834900 | V40: 0.44 | W40: 1.65 | X40: =U40*V40*W40 -> 606137.4 | Y40: =X40/S40 -> 0.242 | Z40: 78 | AA40: =U40/100*Z40 -> 651222
R41: Bronx | S41: ='Population NYC'!E11 -> 1385108 | U41: =S41/3 -> 461702.67 | V41: 0.46 | W41: 1.65 | X41: =U41*V41*W41 -> 350432.32 | Y41: =X41/S41 -> 0.253 | Z41: 78 | AA41: =U41/100*Z41 -> 360128.08
...

Sheet TechData-Emis
A1: TechData | B1: R1,R2,R3,R4,R5,R6 | G1: * | H1: * | I1: * | J1: * | K1: * | L1: * | M1: * | N1: * | O1: * | P1: * | Q1: * | R1: * | S1: * | T1: * | AY1: * | AZ1: * | BA1: * | BB1: * | BC1: * | BD1: * | BE1: * | BF1: * | BG1: * | BH1: * | BI1: * | BJ1: * | BK1: * | BL1: * | BM1: * | BN1: * | BO1: * | BP1: * | BQ1: * | BR1: * | BS1: * | BT1: * | BU1: * | BV1: * | BW1: * | BX1: * | BY1: * | BZ1: * | CA1: * | CB1: * | CC1: * | CD1: * | CE1: * | CF1: * | CG1: * | CH1: * | CI1: * | CJ1: * | CK1: * | CL1: * | CM1: * | CN1: * | CO1: * | CP1: * | CQ1: * | CR1: * | CS1: * | CT1: * | CU1: * | CV1: * | CW1: * | CX1: * | CY1: * | CZ1: * | DA1: * | DB1: * | DC1: * | DD1: * | DE1: * | DF1: * | DG1: * | DH1: * | DI1: * | DJ1: * | DK1: * | DL1: * | DM1: * | DN1: * | DO1: * | DP1: * | DQ1: * | DR1: * | DS1: * | DT1: * | DU1: * | DV1: * | DW1: * | DX1: * | DY1: * | DZ1: * | EA1: * | EB1: * | EC1: * | ED1: * | EE1: * | EF1: * | EG1: * | EH1: * | EI1: * | EJ1: * | EK1: * | EL1: * | EM1: * | EN1: * | EO1: * | EP1: * | EQ1: * | ER1: * | ES1: * | ET1: * | EU1: * | EV1: * | EW1: * | EX1: * | EY1: * | EZ1: * | FA1: * | FB1: * | FC1: * | FD1: * | FE1: * | FF1: * | FG1: * | FH1: * | FI1: * | FJ1: * | FK1: * | FL1: * | FM1: * | FN1: * | FO1: * | FP1: * | FQ1: * | FR1: * | FS1: * | FT1: * | FU1: * | FV1: * | FW1: * | FX1: *
K2: CO2 | L2: CO2 | M2: CO2 | N2: CO2 | O2: CO2 | P2: CO2 | Q2: CO2 | R2: CO2 | S2: CO2 | T2: CO2 | U2: NOX | V2: NOX | W2: NOX | X2: NOX | Y2: NOX | Z2: NOX | AA2: NOX | AB2: NOX | AC2: NOX | AD2: NOX | AE2: SO2 | AF2: SO2 | AG2: SO2 | AH2: SO2 | AI2: SO2 | AJ2: SO2 | AK2: SO2 | AL2: SO2 | AM2: SO2 | AN2: SO2 | AO2: PM10 | AP2: PM10 | AQ2: PM10 | AR2: PM10 | AS2: PM10 | AT2: PM10 | AU2: PM10 | AV2: PM10 | AW2: PM10 | AX2: PM10 | AY2: PM25 | AZ2: PM25 | BA2: PM25 | BB2: PM25 | BC2: PM25 | BD2: PM25 | BE2: PM25 | BF2: PM25 | BG2: PM25 | BH2: PM25 | BI2: CO | BJ2: CO | BK2: CO | BL2: CO | BM2: CO | BN2: CO | BO2: CO | BP2: CO | BQ2: CO | BR2: CO | BS2: VOC | BT2: VOC | BU2: VOC | BV2: VOC | BW2: VOC | BX2: VOC | BY2: VOC | BZ2: VOC | CA2: VOC | CB2: VOC | CC2: NH3 | CD2: NH3 | CE2: NH3 | CF2: NH3 | CG2: NH3 | CH2: NH3 | CI2: NH3 | CJ2: NH3 | CK2: NH3 | CL2: NH3 | CM2: N2O | CN2: N2O | CO2: N2O | CP2: N2O | CQ2: N2O | CR2: N2O | CS2: N2O | CT2: N2O | CU2: N2O | CV2: N2O | CW2: BC | CX2: BC | CY2: BC | CZ2: BC | DA2: BC | DB2: BC | DC2: BC | DD2: BC | DE2: BC | DF2: BC | DG2: OC | DH2: OC | DI2: OC | DJ2: OC | DK2: OC | DL2: OC | DM2: OC | DN2: OC | DO2: OC | DP2: OC | DQ2: CH4 | DR2: CH4 | DS2: CH4 | DT2: CH4 | DU2: CH4 | DV2: CH4 | DW2: CH4 | DX2: CH4 | DY2: CH4 | DZ2: CH4 | EA2: =CONCATENATE(K2,"T") -> CO2T | EB2: =CONCATENATE(L2,"T") -> CO2T | EC2: =CONCATENATE(M2,"T") -> CO2T | ED2: =CONCATENATE(N2,"T") -> CO2T | EE2: =CONCATENATE(O2,"T") -> CO2T | EF2: =CONCATENATE(P2,"T") -> CO2T | EG2: =CONCATENATE(Q2,"T") -> CO2T | EH2: =CONCATENATE(R2,"T") -> CO2T | ... FX2: =CONCATENATE(BH2,"T") -> PM25T
F7: ~FI_T
A8: Region | B8: TechName | C8: *TechDesc | D8: *Units | E8: *CommIN | F8: *CommOUT | G8: *Type | H8: *Fuel | I8: *Adjustment | J8: *Categories for tracking emissions | K8: *ENV_ACT~CO2~2010 | L8: *ENV_ACT~CO2~2015 | M8: *ENV_ACT~CO2~2020 | N8: *ENV_ACT~CO2~2025 | O8: *ENV_ACT~CO2~2030 | P8: *ENV_ACT~CO2~2035 | Q8: *ENV_ACT~CO2~2040 | R8: *ENV_ACT~CO2~2045 | S8: *ENV_ACT~CO2~2050 | T8: *ENV_ACT~CO2~2055 | U8: ENV_ACT~NOX~2010 | V8: ENV_ACT~NOX~2015 | W8: ENV_ACT~NOX~2020 | X8: ENV_ACT~NOX~2025 | Y8: ENV_ACT~NOX~2030 | Z8: ENV_ACT~NOX~2035 | AA8: ENV_ACT~NOX~2040 | AB8: ENV_ACT~NOX~2045 | AC8: ENV_ACT~NOX~2050 | AD8: ENV_ACT~NOX~2055 | AE8: ENV_ACT~SO2~2010 | AF8: ENV_ACT~SO2~2015 | AG8: ENV_ACT~SO2~2020 | AH8: ENV_ACT~SO2~2025 | AI8: ENV_ACT~SO2~2030 | AJ8: ENV_ACT~SO2~2035 | AK8: ENV_ACT~SO2~2040 | AL8: ENV_ACT~SO2~2045 | AM8: ENV_ACT~SO2~2050 | AN8: ENV_ACT~SO2~2055 | AO8: ENV_ACT~PM10~2010 | AP8: ENV_ACT~PM10~2015 | AQ8: ENV_ACT~PM10~2020 | AR8: ENV_ACT~PM10~2025 | AS8: ENV_ACT~PM10~2030 | AT8: ENV_ACT~PM10~2035 | AU8: ENV_ACT~PM10~2040 | AV8: ENV_ACT~PM10~2045 | AW8: ENV_ACT~PM10~2050 | AX8: ENV_ACT~PM10~2055 | AY8: ENV_ACT~PM25~2010 | AZ8: ENV_ACT~PM25~2015 | BA8: ENV_ACT~PM25~2020 | BB8: ENV_ACT~PM25~2025 | BC8: ENV_ACT~PM25~2030 | BD8: ENV_ACT~PM25~2035 | BE8: ENV_ACT~PM25~2040 | BF8: ENV_ACT~PM25~2045 | BG8: ENV_ACT~PM25~2050 | BH8: ENV_ACT~PM25~2055 | BI8: ENV_ACT~CO~2010 | BJ8: ENV_ACT~CO~2015 | BK8: ENV_ACT~CO~2020 | BL8: ENV_ACT~CO~2025 | BM8: ENV_ACT~CO~2030 | BN8: ENV_ACT~CO~2035 | BO8: ENV_ACT~CO~2040 | BP8: ENV_ACT~CO~2045 | BQ8: ENV_ACT~CO~2050 | BR8: ENV_ACT~CO~2055 | BS8: ENV_ACT~VOC~2010 | BT8: ENV_ACT~VOC~2015 | BU8: ENV_ACT~VOC~2020 | BV8: ENV_ACT~VOC~2025 | BW8: ENV_ACT~VOC~2030 | BX8: ENV_ACT~VOC~2035 | BY8: ENV_ACT~VOC~2040 | BZ8: ENV_ACT~VOC~2045 | CA8: ENV_ACT~VOC~2050 | CB8: ENV_ACT~VOC~2055 | CC8: ENV_ACT~NH3~2010 | CD8: ENV_ACT~NH3~2015 | CE8: ENV_ACT~NH3~2020 | CF8: ENV_ACT~NH3~2025 | CG8: ENV_ACT~NH3~2030 | CH8: ENV_ACT~NH3~2035 | CI8: ENV_ACT~NH3~2040 | CJ8: ENV_ACT~NH3~2045 | CK8: ENV_ACT~NH3~2050 | CL8: ENV_ACT~NH3~2055 | CM8: ENV_ACT~N2O~2010 | CN8: ENV_ACT~N2O~2015 | CO8: ENV_ACT~N2O~2020 | CP8: ENV_ACT~N2O~2025 | CQ8: ENV_ACT~N2O~2030 | CR8: ENV_ACT~N2O~2035 | CS8: ENV_ACT~N2O~2040 | CT8: ENV_ACT~N2O~2045 | CU8: ENV_ACT~N2O~2050 | CV8: ENV_ACT~N2O~2055 | CW8: ENV_ACT~BC~2010 | CX8: ENV_ACT~BC~2015 | CY8: ENV_ACT~BC~2020 | CZ8: ENV_ACT~BC~2025 | DA8: ENV_ACT~BC~2030 | DB8: ENV_ACT~BC~2035 | DC8: ENV_ACT~BC~2040 | DD8: ENV_ACT~BC~2045 | DE8: ENV_ACT~BC~2050 | DF8: ENV_ACT~BC~2055 | DG8: ENV_ACT~OC~2010 | DH8: ENV_ACT~OC~2015 | DI8: ENV_ACT~OC~2020 | DJ8: ENV_ACT~OC~2025 | DK8: ENV_ACT~OC~2030 | DL8: ENV_ACT~OC~2035 | DM8: ENV_ACT~OC~2040 | DN8: ENV_ACT~OC~2045 | DO8: ENV_ACT~OC~2050 | DP8: ENV_ACT~OC~2055 | DQ8: ENV_ACT~CH4~2010 | DR8: ENV_ACT~CH4~2015 | DS8: ENV_ACT~CH4~2020 | DT8: ENV_ACT~CH4~2025 | DU8: ENV_ACT~CH4~2030 | DV8: ENV_ACT~CH4~2035 | DW8: ENV_ACT~CH4~2040 | DX8: ENV_ACT~CH4~2045 | DY8: ENV_ACT~CH4~2050 | DZ8: ENV_ACT~CH4~2055 | EA8: *ENV_ACT~CO2T~2010 | EB8: *ENV_ACT~CO2T~2015 | EC8: *ENV_ACT~CO2T~2020 | ED8: *ENV_ACT~CO2T~2025 | EE8: *ENV_ACT~CO2T~2030 | EF8: *ENV_ACT~CO2T~2035 | EG8: *ENV_ACT~CO2T~2040 | EH8: *ENV_ACT~CO2T~2045 | EI8: *ENV_ACT~CO2T~2050 | EJ8: *ENV_ACT~CO2T~2055 | EK8: *ENV_ACT~NOXT~2010 | EL8: *ENV_ACT~NOXT~2015 | EM8: *ENV_ACT~NOXT~2020 | EN8: *ENV_ACT~NOXT~2025 | EO8: *ENV_ACT~NOXT~2030 | EP8: *ENV_ACT~NOXT~2035 | EQ8: *ENV_ACT~NOXT~2040 | ER8: *ENV_ACT~NOXT~2045 | ES8: *ENV_ACT~NOXT~2050 | ET8: *ENV_ACT~NOXT~2055 | EU8: *ENV_ACT~SO2T~2010 | EV8: *ENV_ACT~SO2T~2015 | EW8: *ENV_ACT~SO2T~2020 | EX8: *ENV_ACT~SO2T~2025 | EY8: *ENV_ACT~SO2T~2030 | EZ8: *ENV_ACT~SO2T~2035 | FA8: *ENV_ACT~SO2T~2040 | FB8: *ENV_ACT~SO2T~2045 | FC8: *ENV_ACT~SO2T~2050 | FD8: *ENV_ACT~SO2T~2055 | FE8: *ENV_ACT~PM10T~2010 | FF8: *ENV_ACT~PM10T~2015 | FG8: *ENV_ACT~PM10T~2020 | FH8: *ENV_ACT~PM10T~2025 | FI8: *ENV_ACT~PM10T~2030 | FJ8: *ENV_ACT~PM10T~2035 | FK8: *ENV_ACT~PM10T~2040 | FL8: *ENV_ACT~PM10T~2045 | FM8: *ENV_ACT~PM10T~2050 | FN8: *ENV_ACT~PM10T~2055 | FO8: *ENV_ACT~PM25T~2010 | FP8: *ENV_ACT~PM25T~2015 | FQ8: *ENV_ACT~PM25T~2020 | FR8: *ENV_ACT~PM25T~2025 | FS8: *ENV_ACT~PM25T~2030 | FT8: *ENV_ACT~PM25T~2035 | FU8: *ENV_ACT~PM25T~2040 | FV8: *ENV_ACT~PM25T~2045 | FW8: *ENV_ACT~PM25T~2050 | FX8: *ENV_ACT~PM25T~2055
A9: * Existing Vehicles
