Workbook
Name __HDV50: #REF!
Name __LDV50: #REF!
Name _1995_Implicit_GDP_Deflator: #REF!
Name _2001_Implicit_GDP_Deflator: #REF!
Name Age_of_car: #REF!
Name avg_water_heater_PJ: '[1]AEO HW'!$B$33
Name Aviation_Detail_Table: '[2]Marine and Aviation'!$I$27:$Z$31
Name Aviation_Detail_Table_Years: '[2]Marine and Aviation'!$I$27:$Z$27
Name btu_per_watthr: #REF!
Name CH4GWP_20YR: '[2]RELA TABLE'!$D$8
Name ConEd_Steam_Table: '[2]ConEd Steam'!$I$11:$Z$15
Name ConEd_Steam_Years: '[2]ConEd Steam'!$I$11:$Z$11
Name conv: #REF!
Name Convert_MMbtu_to_GJ: '[2]Unit conversions'!$F$25
Name days_per_year: #REF!
Name Diesel_Car_CO: #REF!
Name Diesel_Car_Nox: #REF!
Name Diesel_Car_PM: #REF!
Name Diesel_Car_VOCs: #REF!
Name Diesel_HDT_CO: #REF!
Name Diesel_HDT_NOx: #REF!
Name Diesel_HDT_PM: #REF!
Name Diesel_HDT_SO2: #REF!
Name Diesel_HDT_VOCs: #REF!
Name Diesel_LDT_CO: #REF!
Name Diesel_LDT_Nox: #REF!
Name Diesel_LDT_PM: #REF!
Name Diesel_LDT_VOCs: #REF!
Name Diesel_Rail_Table: [2]Transit!$I$26:$Z$29
Name Diesel_Rail_Table_Years: [2]Transit!$I$26:$Z$26
Name dollar____per__m: #REF!
Name EF_table_electricity_and_steam: '[2]EF EL and Steam'!$D$5:$Z$81
Name EF_table_road_trans: '[2]EF road transport'!$J$25:$AA$2225
Name Elec_Vehicle_Assump: '[2]EF road transport'!$B$16:$C$23
Name Electric_Traction_Summary_Table: [2]Transit!$I$12:$Z$22
Name Electric_Traction_Summary_Table_Years: [2]Transit!$I$12:$Z$12
Name Electricity_Table: '[2]Electricity '!$I$30:$Z$35
Name Electricity_table_Years: '[2]Electricity '!$I$30:$Z$30
Name Fuel_Oil_Table: '[2]Fuel Oils'!$I$11:$Z$30
Name Fuel_Oil_Table_Years: '[2]Fuel Oils'!$I$10:$Z$10
Name Fugitive_Table: [2]Fugitive!$I$10:$Z$13
Name Fugitive_Table_Years: [2]Fugitive!$I$10:$Z$10
Name Full_OnRoad_Transpo: 'ON-Road Historical share'!$Z$12:$AZ$48
Name Gas_Car_CO: #REF!
Name Gas_Car_Nox: #REF!
Name Gas_Car_PM: #REF!
Name Gas_Car_VOC: #REF!
Name Gas_HDT_CO: #REF!
Name Gas_HDT_NOx: #REF!
Name Gas_HDT_PM: #REF!
Name Gas_HDT_SO2: #REF!
Name Gas_HDT_VOCs: #REF!
Name Gas_LDT_CO: #REF!
Name Gas_LDT_NOx: #REF!
Name Gas_LDT_PM: #REF!
Name Gas_LDT_VOCs: #REF!
Name GWP_CH4: '[2]RELA TABLE'!$E$8
Name GWP_N2O: '[2]RELA TABLE'!$E$9
Name hours_per_day: #REF!
Name j_per_btu: #REF!

Sheet ANSv6.0-Commodities
A1: ANSWER-Commodities
B7: CommName | C7: CommDesc | D7: CommUnit | E7: Set Memberships | F7: Comment

Sheet ANSv6.1-Commodities
A1: ANSWER-Commodities
B7: CommName | C7: CommDesc | D7: CommUnit | E7: Set Memberships | F7: Comment

Sheet UC_TRNLDVa
A4: ~UC_Sets: R_E: AllRegions
F5: ~UC_T: UC_NCAP
A6: UC_N | B6: Pset_PN | C6: Pset_PD | D6: Pset_CO | E6: Pset_CI | F6: Cset_CN | G6: Year | H6: LimType | I6: UC_RHSRT | J6: UC_RHSRT~0 | K6: R0 | L6: R1 | M6: R2 | N6: R3 | O6: R4 | P6: R5 | Q6: R6
A7: ="UC_"&"NCAP"&D7&"MC" -> UC_NCAPTLMC | B7: TL* | C7: *.MC.*,*minicar* | D7: TL | G7: 2020 | H7: LO | I7: 0 | J7: 5 | M7: =1+M8 -> 0.99274707 | N7: =1+N8 -> 0.99274707 | O7: =1+O8 -> 0.99274707 | P7: =1+P8 -> 0.99274707 | Q7: =1+Q8 -> 0.99274707
B8: TL* | C8: -*.MC.*,-*minicar* | D8: TL | G8: 2020 | M8: -0.0072529276 | N8: =M8 -> -0.0072529276 | O8: =N8 -> -0.0072529276 | P8: =O8 -> -0.0072529276 | Q8: =P8 -> -0.0072529276
B9: TL* | C9: *.MC.*,*minicar* | D9: TL | G9: 2030 | M9: =1+M10 -> 0.99220818 | N9: =1+N10 -> 0.99220818 | O9: =1+O10 -> 0.99220818 | P9: =1+P10 -> 0.99220818 | Q9: =1+Q10 -> 0.99220818
B10: TL* | C10: -*.MC.*,-*minicar* | D10: TL | G10: 2030 | M10: -0.0077918216 | N10: =M10 -> -0.0077918216 | O10: =N10 -> -0.0077918216 | P10: =O10 -> -0.0077918216 | Q10: =P10 -> -0.0077918216
B11: TL* | C11: *.MC.*,*minicar* | D11: TL | G11: 2040 | M11: =1+M12 -> 0.99167792 | N11: =1+N12 -> 0.99167792 | O11: =1+O12 -> 0.99167792 | P11: =1+P12 -> 0.99167792 | Q11: =1+Q12 -> 0.99167792
B12: TL* | C12: -*.MC.*,-*minicar* | D12: TL | G12: 2040 | M12: -0.0083220753 | N12: =M12 -> -0.0083220753 | O12: =N12 -> -0.0083220753 | P12: =O12 -> -0.0083220753 | Q12: =P12 -> -0.0083220753
B13: TL* | C13: *.MC.*,*minicar* | D13: TL | G13: 2050 | M13: =1+M14 -> 0.99167792 | N13: =1+N14 -> 0.99167792 | O13: =1+O14 -> 0.99167792 | P13: =1+P14 -> 0.99167792 | Q13: =1+Q14 -> 0.99167792
B14: TL* | C14: -*.MC.*,-*minicar* | D14: TL | G14: 2050 | M14: -0.0083220753 | N14: =M14 -> -0.0083220753 | O14: =N14 -> -0.0083220753 | P14: =O14 -> -0.0083220753 | Q14: =P14 -> -0.0083220753
B15: TL* | C15: *.MC.*,*minicar* | D15: TL | G15: 2055 | M15: =1+M16 -> 0.99167792 | N15: =1+N16 -> 0.99167792 | O15: =1+O16 -> 0.99167792 | P15: =1+P16 -> 0.99167792 | Q15: =1+Q16 -> 0.99167792
B16: TL* | C16: -*.MC.*,-*minicar* | D16: TL | G16: 2055 | M16: -0.0083220753 | N16: =M16 -> -0.0083220753 | O16: =N16 -> -0.0083220753 | P16: =O16 -> -0.0083220753 | Q16: =P16 -> -0.0083220753
A17: ="UC_"&"NCAP"&D17&"C" -> UC_NCAPTLC | B17: TLC*,TLEC* | D17: TL | G17: 2020 | H17: LO | I17: 0 | J17: 5 | M17: =1+M18 -> 0.76256803 | N17: =1+N18 -> 0.76256803 | O17: =1+O18 -> 0.76256803 | P17: =1+P18 -> 0.76256803 | Q17: =1+Q18 -> 0.76256803
B18: TL*,-TLC*,-TLEC* | D18: TL | G18: 2020 | M18: -0.23743197 | N18: =M18 -> -0.23743197 | O18: =N18 -> -0.23743197 | P18: =O18 -> -0.23743197 | Q18: =P18 -> -0.23743197
B19: TLC*,TLEC* | D19: TL | G19: 2030 | M19: =1+M20 -> 0.74672589 | N19: =1+N20 -> 0.74672589 | O19: =1+O20 -> 0.74672589 | P19: =1+P20 -> 0.74672589 | Q19: =1+Q20 -> 0.74672589
B20: TL*,-TLC*,-TLEC* | D20: TL | G20: 2030 | M20: -0.25327411 | N20: =M20 -> -0.25327411 | O20: =N20 -> -0.25327411 | P20: =O20 -> -0.25327411 | Q20: =P20 -> -0.25327411
B21: TLC*,TLEC* | D21: TL | G21: 2040 | M21: =1+M22 -> 0.72915267 | N21: =1+N22 -> 0.72915267 | O21: =1+O22 -> 0.72915267 | P21: =1+P22 -> 0.72915267 | Q21: =1+Q22 -> 0.72915267
B22: TL*,-TLC*,-TLEC* | D22: TL | G22: 2040 | M22: -0.27084733 | N22: =M22 -> -0.27084733 | O22: =N22 -> -0.27084733 | P22: =O22 -> -0.27084733 | Q22: =P22 -> -0.27084733
B23: TLC*,TLEC* | D23: TL | G23: 2050 | M23: =1+M24 -> 0.71035957 | N23: =1+N24 -> 0.71035957 | O23: =1+O24 -> 0.71035957 | P23: =1+P24 -> 0.71035957 | Q23: =1+Q24 -> 0.71035957
B24: TL*,-TLC*,-TLEC* | D24: TL | G24: 2050 | M24: -0.28964043 | N24: =M24 -> -0.28964043 | O24: =N24 -> -0.28964043 | P24: =O24 -> -0.28964043 | Q24: =P24 -> -0.28964043
B25: TLC*,TLEC* | D25: TL | G25: 2055 | M25: =1+M26 -> 0.71035957 | N25: =1+N26 -> 0.71035957 | O25: =1+O26 -> 0.71035957 | P25: =1+P26 -> 0.71035957 | Q25: =1+Q26 -> 0.71035957
B26: TL*,-TLC*,-TLEC* | D26: TL | G26: 2055 | M26: -0.28964043 | N26: =M26 -> -0.28964043 | O26: =N26 -> -0.28964043 | P26: =O26 -> -0.28964043 | Q26: =P26 -> -0.28964043
A27: ="UC_"&"NCAP"&D27&"LS" -> UC_NCAPTLLS | B27: TLLS*,TLELS* | D27: TL | G27: 2020 | H27: LO | I27: 0 | J27: 5 | M27: =1+M28 -> 0.87979923 | N27: =1+N28 -> 0.87979923 | O27: =1+O28 -> 0.87979923 | P27: =1+P28 -> 0.87979923 | Q27: =1+Q28 -> 0.87979923
B28: TL*,-TLLS*,-TLELS* | D28: TL | G28: 2020 | M28: -0.12020077 | N28: =M28 -> -0.12020077 | O28: =N28 -> -0.12020077 | P28: =O28 -> -0.12020077 | Q28: =P28 -> -0.12020077
B29: TLLS*,TLELS* | D29: TL | G29: 2030 | M29: =1+M30 -> 0.89061676 | N29: =1+N30 -> 0.89061676 | O29: =1+O30 -> 0.89061676 | P29: =1+P30 -> 0.89061676 | Q29: =1+Q30 -> 0.89061676
B30: TL*,-TLLS*,-TLELS* | D30: TL | G30: 2030 | M30: -0.10938324 | N30: =M30 -> -0.10938324 | O30: =N30 -> -0.10938324 | P30: =O30 -> -0.10938324 | Q30: =P30 -> -0.10938324
B31: TLLS*,TLELS* | D31: TL | G31: 2040 | M31: =1+M32 -> 0.89833097 | N31: =1+N32 -> 0.89833097 | O31: =1+O32 -> 0.89833097 | P31: =1+P32 -> 0.89833097 | Q31: =1+Q32 -> 0.89833097
B32: TL*,-TLLS*,-TLELS* | D32: TL | G32: 2040 | M32: -0.10166903 | N32: =M32 -> -0.10166903 | O32: =N32 -> -0.10166903 | P32: =O32 -> -0.10166903 | Q32: =P32 -> -0.10166903
B33: TLLS*,TLELS* | D33: TL | G33: 2050 | M33: =1+M34 -> 0.90550114 | N33: =1+N34 -> 0.90550114 | O33: =1+O34 -> 0.90550114 | P33: =1+P34 -> 0.90550114 | Q33: =1+Q34 -> 0.90550114
B34: TL*,-TLLS*,-TLELS* | D34: TL | G34: 2050 | M34: -0.094498859 | N34: =M34 -> -0.094498859 | O34: =N34 -> -0.094498859 | P34: =O34 -> -0.094498859 | Q34: =P34 -> -0.094498859
B35: TLLS*,TLELS* | D35: TL | G35: 2055 | M35: =1+M36 -> 0.90550114 | N35: =1+N36 -> 0.90550114 | O35: =1+O36 -> 0.90550114 | P35: =1+P36 -> 0.90550114 | Q35: =1+Q36 -> 0.90550114
B36: TL*,-TLLS*,-TLELS* | D36: TL | G36: 2055 | M36: -0.094498859 | N36: =M36 -> -0.094498859 | O36: =N36 -> -0.094498859 | P36: =O36 -> -0.094498859 | Q36: =P36 -> -0.094498859
A37: ="UC_"&"NCAP"&D37&"M" -> UC_NCAPTLM | B37: TL* | C37: *.M.*,*minivan* | D37: TL | G37: 2020 | H37: LO | I37: 0 | J37: 5 | M37: =1+M38 -> 0.95043514 | N37: =1+N38 -> 0.95043514 | O37: =1+O38 -> 0.95043514 | P37: =1+P38 -> 0.95043514 | Q37: =1+Q38 -> 0.95043514
B38: TL* | C38: -*.M.*,-*minivan* | D38: TL | G38: 2020 | M38: -0.049564862 | N38: =M38 -> -0.049564862 | O38: =N38 -> -0.049564862 | P38: =O38 -> -0.049564862 | Q38: =P38 -> -0.049564862
B39: TL* | C39: *.M.*,*minivan* | D39: TL | G39: 2030 | M39: =1+M40 -> 0.95443254 | N39: =1+N40 -> 0.95443254 | O39: =1+O40 -> 0.95443254 | P39: =1+P40 -> 0.95443254 | Q39: =1+Q40 -> 0.95443254
B40: TL* | C40: -*.M.*,-*minivan* | D40: TL | G40: 2030 | M40: -0.045567464 | N40: =M40 -> -0.045567464 | O40: =N40 -> -0.045567464 | P40: =O40 -> -0.045567464 | Q40: =P40 -> -0.045567464
B41: TL* | C41: *.M.*,*minivan* | D41: TL | G41: 2040 | M41: =1+M42 -> 0.95762208 | N41: =1+N42 -> 0.95762208 | O41: =1+O42 -> 0.95762208 | P41: =1+P42 -> 0.95762208 | Q41: =1+Q42 -> 0.95762208
B42: TL* | C42: -*.M.*,-*minivan* | D42: TL | G42: 2040 | M42: -0.042377922 | N42: =M42 -> -0.042377922 | O42: =N42 -> -0.042377922 | P42: =O42 -> -0.042377922 | Q42: =P42 -> -0.042377922
B43: TL* | C43: *.M.*,*minivan* | D43: TL | G43: 2050 | M43: =1+M44 -> 0.96058799 | N43: =1+N44 -> 0.96058799 | O43: =1+O44 -> 0.96058799 | P43: =1+P44 -> 0.96058799 | Q43: =1+Q44 -> 0.96058799
...

Sheet UC_TRNLDVb
A1: Light duty vehicle historical boundary calibration
F5: ~UC_Sets: R_S: AllRegions
K7: ~UC_T: UC_FLO
F8: UC_N | G8: Pset_PN | H8: Pset_PD | I8: Pset_CI | J8: Cset_CN | K8: Year | L8: LimType | M8: UC_RHSRT | N8: UC_RHSRT~0 | O8: AllRegions
A9: 2015 | B9: ='ON-Road Historical share'!L34 -> TL | C9: ='ON-Road Historical share'!M34 -> CNG | F9: ="UC_"&J9&C9&"FX"&A9 -> UC_TLCNGFX2015 | G9: =IF(D9="",B9&"*"&C9&"*",B9&"*"&C9&"*"&",-"&B9&"*"&D9) -> TL*CNG* | J9: =B9 -> TL | K9: =A9 -> 2015 | L9: FX | M9: 0 | N9: -1 | O9: =O10-1 -> -1
G10: =IF(D9="",B9&"*"&",-"&B9&"*"&C9&"*",B9&"*"&",-"&B9&"*"&C9&"*"&","&B9&"*"&D9&"*") -> TL*,-TL*CNG* | J10: =J9 -> TL | K10: =K9 -> 2015 | O10: ='ON-Road Historical share'!U34 -> 0
A11: 2020 | B11: =B9 -> TL | C11: =C9 -> CNG | F11: ="UC_"&J11&C11&"FX"&A11 -> UC_TLCNGFX2020 | G11: =IF(D11="",B11&"*"&C11&"*",B11&"*"&C11&"*"&",-"&B11&"*"&D11) -> TL*CNG* | J11: =B11 -> TL | K11: =A11 -> 2020 | L11: FX | M11: 0 | N11: -1 | O11: =O12-1 -> -1
G12: =IF(D11="",B11&"*"&",-"&B11&"*"&C11&"*",B11&"*"&",-"&B11&"*"&C11&"*"&","&B11&"*"&D11&"*") -> TL*,-TL*CNG* | J12: =J11 -> TL | K12: =K11 -> 2020 | O12: ='ON-Road Historical share'!W34 -> 0
A13: 2025 | B13: =B11 -> TL | C13: =C11 -> CNG | F13: ="UC_"&J13&C13&"FX"&A13 -> UC_TLCNGFX2025 | G13: =IF(D13="",B13&"*"&C13&"*",B13&"*"&C13&"*"&",-"&B13&"*"&D13) -> TL*CNG* | J13: =B13 -> TL | K13: =A13 -> 2025 | L13: FX | M13: 0 | N13: -1 | O13: =O14-1 -> -1
G14: =IF(D13="",B13&"*"&",-"&B13&"*"&C13&"*",B13&"*"&",-"&B13&"*"&C13&"*"&","&B13&"*"&D13&"*") -> TL*,-TL*CNG* | J14: =J13 -> TL | K14: =K13 -> 2025 | O14: ='ON-Road Historical share'!X34 -> 0
A15: =A9 -> 2015 | B15: ='ON-Road Historical share'!L35 -> TL | C15: ='ON-Road Historical share'!M35 -> DSL | D15: ='ON-Road Historical share'!N35 -> DHEV | F15: ="UC_"&J15&C15&"FX"&A15 -> UC_TLDSLFX2015 | G15: =IF(D15="",B15&"*"&C15&"*",B15&"*"&C15&"*"&",-"&B15&"*"&D15&"*") -> TL*DSL*,-TL*DHEV* | J15: =B15 -> TL | K15: =A15 -> 2015 | L15: FX | M15: 0 | N15: -1 | O15: =O16-1 -> -0.98811288
G16: =IF(D15="",B15&"*"&",-"&B15&"*"&C15&"*",B15&"*"&",-"&B15&"*"&C15&"*"&","&B15&"*"&D15&"*") -> TL*,-TL*DSL*,TL*DHEV* | J16: =J15 -> TL | K16: =K15 -> 2015 | O16: ='ON-Road Historical share'!V35 -> 0.011887125
A17: =A11 -> 2020 | B17: =B15 -> TL | C17: =C15 -> DSL | D17: =D15 -> DHEV | F17: ="UC_"&J17&C17&"FX"&A17 -> UC_TLDSLFX2020 | G17: =IF(D17="",B17&"*"&C17&"*",B17&"*"&C17&"*"&",-"&B17&"*"&D17&"*") -> TL*DSL*,-TL*DHEV* | J17: =B17 -> TL | K17: =A17 -> 2020 | L17: FX | M17: 0 | N17: -1 | O17: =O18-1 -> -0.99201253
G18: =IF(D17="",B17&"*"&",-"&B17&"*"&C17&"*",B17&"*"&",-"&B17&"*"&C17&"*"&","&B17&"*"&D17&"*") -> TL*,-TL*DSL*,TL*DHEV* | J18: =J17 -> TL | K18: =K17 -> 2020 | O18: ='ON-Road Historical share'!W35 -> 0.0079874655
A19: =A13 -> 2025 | B19: =B17 -> TL | C19: =C17 -> DSL | D19: =D17 -> DHEV | F19: ="UC_"&J19&C19&"FX"&A19 -> UC_TLDSLFX2025 | G19: =IF(D19="",B19&"*"&C19&"*",B19&"*"&C19&"*"&",-"&B19&"*"&D19&"*") -> TL*DSL*,-TL*DHEV* | J19: =B19 -> TL | K19: =A19 -> 2025 | L19: FX | M19: 0 | N19: -1 | O19: =O20-1 -> -0.99586311
G20: =IF(D19="",B19&"*"&",-"&B19&"*"&C19&"*",B19&"*"&",-"&B19&"*"&C19&"*"&","&B19&"*"&D19&"*") -> TL*,-TL*DSL*,TL*DHEV* | J20: =J19 -> TL | K20: =K19 -> 2025 | O20: ='ON-Road Historical share'!X35 -> 0.0041368872
A21: =A15 -> 2015 | B21: ='ON-Road Historical share'!L36 -> TL | C21: ='ON-Road Historical share'!M36 -> DHEV | F21: ="UC_"&J21&C21&"FX"&A21 -> UC_TLDHEVFX2015 | G21: =IF(D21="",B21&"*"&C21&"*",B21&"*"&C21&"*"&",-"&B21&"*"&D21) -> TL*DHEV* | J21: =B21 -> TL | K21: =A21 -> 2015 | L21: FX | M21: 0 | N21: -1 | O21: =O22-1 -> -1
G22: =IF(D21="",B21&"*"&",-"&B21&"*"&C21&"*",B21&"*"&",-"&B21&"*"&C21&"*"&","&B21&"*"&D21&"*") -> TL*,-TL*DHEV* | J22: =J21 -> TL | K22: =K21 -> 2015 | O22: ='ON-Road Historical share'!V36 -> 0
A23: =A17 -> 2020 | B23: =B21 -> TL | C23: =C21 -> DHEV | F23: ="UC_"&J23&C23&"FX"&A23 -> UC_TLDHEVFX2020 | G23: =IF(D23="",B23&"*"&C23&"*",B23&"*"&C23&"*"&",-"&B23&"*"&D23) -> TL*DHEV* | J23: =B23 -> TL | K23: =A23 -> 2020 | L23: FX | M23: 0 | N23: -1 | O23: =O24-1 -> -1
G24: =IF(D23="",B23&"*"&",-"&B23&"*"&C23&"*",B23&"*"&",-"&B23&"*"&C23&"*"&","&B23&"*"&D23&"*") -> TL*,-TL*DHEV* | J24: =J23 -> TL | K24: =K23 -> 2020 | O24: ='ON-Road Historical share'!W36 -> 0
A25: =A19 -> 2025 | B25: =B23 -> TL | C25: =C23 -> DHEV | F25: ="UC_"&J25&C25&"FX"&A25 -> UC_TLDHEVFX2025 | G25: =IF(D25="",B25&"*"&C25&"*",B25&"*"&C25&"*"&",-"&B25&"*"&D25) -> TL*DHEV* | J25: =B25 -> TL | K25: =A25 -> 2025 | L25: FX | M25: 0 | N25: -1 | O25: =O26-1 -> -1
G26: =IF(D25="",B25&"*"&",-"&B25&"*"&C25&"*",B25&"*"&",-"&B25&"*"&C25&"*"&","&B25&"*"&D25&"*") -> TL*,-TL*DHEV* | J26: =J25 -> TL | K26: =K25 -> 2025 | O26: ='ON-Road Historical share'!X36 -> 0
A27: =A21 -> 2015 | B27: ='ON-Road Historical share'!L37 -> TL | C27: ='ON-Road Historical share'!M37 -> ELC | F27: ="UC_"&J27&C27&"FX"&A27 -> UC_TLELCFX2015 | G27: =IF(D27="",B27&"*"&C27&"*",B27&"*"&C27&"*"&",-"&B27&"*"&D27) -> TL*ELC* | J27: =B27 -> TL | K27: =A27 -> 2015 | L27: FX | M27: 0 | N27: -1 | O27: =O28-1 -> -0.99990778
G28: =IF(D27="",B27&"*"&",-"&B27&"*"&C27&"*",B27&"*"&",-"&B27&"*"&C27&"*"&","&B27&"*"&D27&"*") -> TL*,-TL*ELC* | J28: =J27 -> TL | K28: =K27 -> 2015 | O28: ='ON-Road Historical share'!V37 -> 9.2224224e-05
A29: =A23 -> 2020 | B29: =B27 -> TL | C29: =C27 -> ELC | F29: ="UC_"&J29&C29&"FX"&A29 -> UC_TLELCFX2020 | G29: =IF(D29="",B29&"*"&C29&"*",B29&"*"&C29&"*"&",-"&B29&"*"&D29) -> TL*ELC* | J29: =B29 -> TL | K29: =A29 -> 2020 | L29: FX | M29: 0 | N29: -1 | O29: =O30-1 -> -0.98169971
G30: =IF(D29="",B29&"*"&",-"&B29&"*"&C29&"*",B29&"*"&",-"&B29&"*"&C29&"*"&","&B29&"*"&D29&"*") -> TL*,-TL*ELC* | J30: =J29 -> TL | K30: =K29 -> 2020 | O30: ='ON-Road Historical share'!W37 -> 0.018300293
A31: =A25 -> 2025 | B31: =B29 -> TL | C31: =C29 -> ELC | F31: ="UC_"&J31&C31&"FX"&A31 -> UC_TLELCFX2025 | G31: =IF(D31="",B31&"*"&C31&"*",B31&"*"&C31&"*"&",-"&B31&"*"&D31) -> TL*ELC* | J31: =B31 -> TL | K31: =A31 -> 2025 | L31: FX | M31: 0 | N31: -1 | O31: =O32-1 -> -0.96452203
G32: =IF(D31="",B31&"*"&",-"&B31&"*"&C31&"*",B31&"*"&",-"&B31&"*"&C31&"*"&","&B31&"*"&D31&"*") -> TL*,-TL*ELC* | J32: =J31 -> TL | K32: =K31 -> 2025 | O32: ='ON-Road Historical share'!X37 -> 0.03547797
A33: =A27 -> 2015 | B33: ='ON-Road Historical share'!L38 -> TL | C33: ='ON-Road Historical share'!M38 -> FCH | F33: ="UC_"&J33&C33&"FX"&A33 -> UC_TLFCHFX2015 | G33: =IF(D33="",B33&"*"&C33&"*",B33&"*"&C33&"*"&",-"&B33&"*"&D33) -> TL*FCH* | J33: =B33 -> TL | K33: =A33 -> 2015 | L33: FX | M33: 0 | N33: -1 | O33: =O34-1 -> -1
G34: =IF(D33="",B33&"*"&",-"&B33&"*"&C33&"*",B33&"*"&",-"&B33&"*"&C33&"*"&","&B33&"*"&D33&"*") -> TL*,-TL*FCH* | J34: =J33 -> TL | K34: =K33 -> 2015 | O34: ='ON-Road Historical share'!V38 -> 0
A35: =A29 -> 2020 | B35: =B33 -> TL | C35: =C33 -> FCH | F35: ="UC_"&J35&C35&"FX"&A35 -> UC_TLFCHFX2020 | G35: =IF(D35="",B35&"*"&C35&"*",B35&"*"&C35&"*"&",-"&B35&"*"&D35) -> TL*FCH* | J35: =B35 -> TL | K35: =A35 -> 2020 | L35: FX | M35: 0 | N35: -1 | O35: =O36-1 -> -1
G36: =IF(D35="",B35&"*"&",-"&B35&"*"&C35&"*",B35&"*"&",-"&B35&"*"&C35&"*"&","&B35&"*"&D35&"*") -> TL*,-TL*FCH* | J36: =J35 -> TL | K36: =K35 -> 2020 | O36: ='ON-Road Historical share'!W38 -> 0
A37: =A31 -> 2025 | B37: =B35 -> TL | C37: =C35 -> FCH | F37: ="UC_"&J37&C37&"FX"&A37 -> UC_TLFCHFX2025 | G37: =IF(D37="",B37&"*"&C37&"*",B37&"*"&C37&"*"&",-"&B37&"*"&D37) -> TL*FCH* | J37: =B37 -> TL | K37: =A37 -> 2025 | L37: FX | M37: 0 | N37: -1 | O37: =O38-1 -> -1
G38: =IF(D37="",B37&"*"&",-"&B37&"*"&C37&"*",B37&"*"&",-"&B37&"*"&C37&"*"&","&B37&"*"&D37&"*") -> TL*,-TL*FCH* | J38: =J37 -> TL | K38: =K37 -> 2025 | O38: ='ON-Road Historical share'!X38 -> 0
A39: =A33 -> 2015 | B39: ='ON-Road Historical share'!L39 -> TL | C39: ='ON-Road Historical share'!M39 -> GSL | D39: ='ON-Road Historical share'!N39 -> G*HEV | F39: ="UC_"&J39&C39&"FX"&A39 -> UC_TLGSLFX2015 | G39: =IF(D39="",B39&"*"&C39&"*",B39&"*"&C39&"*"&",-"&B39&"*"&D39&"*") -> TL*GSL*,-TL*G*HEV* | J39: =B39 -> TL | K39: =A39 -> 2015 | L39: FX | M39: 0 | N39: -1 | O39: =O40-1 -> -0.016279563
G40: =IF(D39="",B39&"*"&",-"&B39&"*"&C39&"*",B39&"*"&",-"&B39&"*"&C39&"*"&","&B39&"*"&D39&"*") -> TL*,-TL*GSL*,TL*G*HEV* | J40: =J39 -> TL | K40: =K39 -> 2015 | O40: ='ON-Road Historical share'!V39 -> 0.98372044
A41: =A35 -> 2020 | B41: =B39 -> TL | C41: =C39 -> GSL | D41: =D39 -> G*HEV | F41: ="UC_"&J41&C41&"FX"&A41 -> UC_TLGSLFX2020 | G41: =IF(D41="",B41&"*"&C41&"*",B41&"*"&C41&"*"&",-"&B41&"*"&D41&"*") -> TL*GSL*,-TL*G*HEV* | J41: =B41 -> TL | K41: =A41 -> 2020 | L41: FX | M41: 0 | N41: -1 | O41: =O42-1 -> -0.066438979
G42: =IF(D41="",B41&"*"&",-"&B41&"*"&C41&"*",B41&"*"&",-"&B41&"*"&C41&"*"&","&B41&"*"&D41&"*") -> TL*,-TL*GSL*,TL*G*HEV* | J42: =J41 -> TL | K42: =K41 -> 2020 | O42: ='ON-Road Historical share'!W39 -> 0.93356102
A43: =A37 -> 2025 | B43: =B41 -> TL | C43: =C41 -> GSL | D43: =D41 -> G*HEV | F43: ="UC_"&J43&C43&"FX"&A43 -> UC_TLGSLFX2025 | G43: =IF(D43="",B43&"*"&C43&"*",B43&"*"&C43&"*"&",-"&B43&"*"&D43&"*") -> TL*GSL*,-TL*G*HEV* | J43: =B43 -> TL | K43: =A43 -> 2025 | L43: FX | M43: 0 | N43: -1 | O43: =O44-1 -> -0.11526223
G44: =IF(D43="",B43&"*"&",-"&B43&"*"&C43&"*",B43&"*"&",-"&B43&"*"&C43&"*"&","&B43&"*"&D43&"*") -> TL*,-TL*GSL*,TL*G*HEV* | J44: =J43 -> TL | K44: =K43 -> 2025 | O44: ='ON-Road Historical share'!X39 -> 0.88473777
...

Sheet ON-Road Historical share
AA2: On-road transportation
AA4: Header key | AD4: NOTE
AA5: Feeds | AB5: Community tab via INDEX | AD5: Table 3 of this tab should be populated by values from "On Road Transportation Summary 20XX" workbook. Use the VMT values in "table 3" of the "20XX Summary" tab
AA6: Feeds | AB6: Historical tab via 'aggregate tag'
AA7: Feeds | AB7: Both Community and Historical tab
AD9: 1000 | AG9: This step is required to correct the the fact that, to avoid problems when dividing by zero. the model set some cells to values fractionally higher than zero.
AD10: 0.001 | AG10: Lower bound for percentage of VMT to utilize - anything with a percentage below this will be set to 0 VMT
AA11: Table 1
Z12: Aggregate tag | AA12: Data source | AB12: GPC Sector | AC12: GPC Sub-sector | AD12: GPC Sub-sector class | AE12: GPC Sub-sector class agg | AF12: Address/service | AG12: Fuel type | AH12: Reported units | AI12: CY2022 | AJ12: CY2021 | AK12: CY2020 | AL12: CY2019 | AM12: CY2018 | AN12: CY2017 | AO12: CY2016 | AP12: CY2015 | AQ12: CY2014 | AR12: CY2013 | AS12: CY2012 | AT12: CY2011 | AU12: CY2010 | AV12: CY2009 | AW12: CY2008 | AX12: CY2007 | AY12: CY2006 | AZ12: CY2005
Z13: Heavy duty trucks(private)CNG | AA13: NYMTC BPM | AB13: Transportation | AC13: On-road | AD13: Heavy duty trucks | AE13: Heavy duty trucks | AF13: (private) | AG13: CNG | AH13: VMT | AI13: 6398791.5 | AJ13: 5317833.8 | AK13: 4068498.7 | AL13: 3481673.7 | AM13: 2552442.9 | AN13: 1633232.8 | AO13: 805661.85 | AP13: 0 | AQ13: 0 | AR13: 0 | AS13: 0 | AT13: 0 | AU13: 0 | AV13: 0 | AW13: 0 | AX13: 0 | AY13: 0 | AZ13: 0
B14: Row Labels | C14: Sum of CY2010 | D14: Sum of CY2015 | E14: Sum of CY2019 | F14: Sum of CY2021 | G14: Sum of CY2022 | Z14: Heavy duty trucks(private)Diesel | AA14: NYMTC BPM | AB14: Transportation | AC14: On-road | AD14: Heavy duty trucks | AE14: Heavy duty trucks | AF14: (private) | AG14: Diesel | AH14: VMT | AI14: 5.5015747e+08 | AJ14: 5.3597055e+08 | AK14: 4.9440372e+08 | AL14: 5.3136798e+08 | AM14: 5.2184428e+08 | AN14: 5.0321127e+08 | AO14: 4.9875703e+08 | AP14: 4.9188555e+08 | AQ14: 4.8019396e+08 | AR14: 4.9395273e+08 | AS14: 4.9204316e+08 | AT14: 5.0093796e+08 | AU14: 5.0243622e+08 | AV14: 4.5058508e+08 | AW14: 4.9222673e+08 | AX14: 5.1459198e+08 | AY14: 5.0452045e+08 | AZ14: 4.9340266e+08
B15: Transportation | C15: 2.0844644e+10 | D15: 2.0891817e+10 | E15: 2.2863426e+10 | F15: 2.1505803e+10 | G15: 2.2706669e+10 | Z15: Heavy duty trucks(private)Electricity | AA15: NYMTC BPM | AB15: Transportation | AC15: On-road | AD15: Heavy duty trucks | AE15: Heavy duty trucks | AF15: (private) | AG15: Electricity | AH15: VMT | AI15: 0 | AJ15: 0 | AK15: 0 | AL15: 0 | AM15: 0 | AN15: 0 | AO15: 0 | AP15: 0 | AQ15: 0 | AR15: 0 | AS15: 0 | AT15: 0 | AU15: 0 | AV15: 0 | AW15: 0 | AX15: 0 | AY15: 0 | AZ15: 0
B16: On-road | C16: 2.0844644e+10 | D16: 2.0891817e+10 | E16: 2.2863426e+10 | F16: 2.1505803e+10 | G16: 2.2706669e+10 | R16: 2019 | Z16: Heavy duty trucks(private)Gasoline | AA16: NYMTC BPM | AB16: Transportation | AC16: On-road | AD16: Heavy duty trucks | AE16: Heavy duty trucks | AF16: (private) | AG16: Gasoline | AH16: VMT | AI16: 11503965 | AJ16: 9560569.4 | AK16: 7314461.9 | AL16: 6259434 | AM16: 4588820.1 | AN16: 2936223.3 | AO16: 1448377.6 | AP16: 0 | AQ16: 0 | AR16: 0 | AS16: 0 | AT16: 0 | AU16: 0 | AV16: 0 | AW16: 0 | AX16: 0 | AY16: 0 | AZ16: 0
B17: Buses | C17: 58802169 | D17: 66295314 | E17: 72286277 | F17: 75285302 | G17: 77867822 | P17: 2010 | Q17: 2015 | R17: 2021 | S17: 2022 | Z17: Heavy duty trucks(public)Diesel | AA17: NYMTC BPM | AB17: Transportation | AC17: On-road | AD17: Heavy duty trucks | AE17: Heavy duty trucks | AF17: (public) | AG17: Diesel | AH17: VMT | AI17: 1.0149074e+08 | AJ17: 98705425 | AK17: 90896735 | AL17: 97529071 | AM17: 95621910 | AN17: 92055591 | AO17: 91091462 | AP17: 89690607 | AQ17: 87558751 | AR17: 90067524 | AS17: 89719324 | AT17: 91341199 | AU17: 91614385 | AV17: 91587216 | AW17: 1.0005141e+08 | AX17: 1.0459742e+08 | AY17: 1.0255025e+08 | AZ17: 1.0029041e+08
B18: Diesel | C18: 58802169 | D18: 66295314 | E18: 45357985 | F18: 33218126 | G18: 27085733 | Z18: Heavy duty trucks(public)Diesel Hybrid | AA18: NYMTC BPM | AB18: Transportation | AC18: On-road | AD18: Heavy duty trucks | AE18: Heavy duty trucks | AF18: (public) | AG18: Diesel Hybrid | AH18: VMT | AI18: 1348977.7 | AJ18: 1121090.5 | AK18: 857706.76 | AL18: 733991.13 | AM18: 538090.85 | AN18: 344303.41 | AO18: 169834.93 | AP18: 0 | AQ18: 0 | AR18: 0 | AS18: 0 | AT18: 0 | AU18: 0 | AV18: 0 | AW18: 0 | AX18: 0 | AY18: 0 | AZ18: 0
B19: Electricity | C19: 0 | D19: 0 | E19: 0 | F19: 0 | G19: 23359.435 | P19: Billion VMT | Q19: Billion VMT | R19: Billion VMT | S19: Billion VMT | T19: Billion VMT | Z19: Heavy duty trucks(public)Gasoline | AA19: NYMTC BPM | AB19: Transportation | AC19: On-road | AD19: Heavy duty trucks | AE19: Heavy duty trucks | AF19: (public) | AG19: Gasoline | AH19: VMT | AI19: 793516.32 | AJ19: 659465.01 | AK19: 504533.39 | AL19: 431759.49 | AM19: 316524.03 | AN19: 202531.41 | AO19: 99902.898 | AP19: 0 | AQ19: 0 | AR19: 0 | AS19: 0 | AT19: 0 | AU19: 0 | AV19: 0 | AW19: 0 | AX19: 0 | AY19: 0 | AZ19: 0
B20: Gasoline | C20: 0 | D20: 0 | E20: 26928292 | F20: 42067176 | G20: 50758730 | P20: 2010 | Q20: 2015 | R20: 2020 | S20: 2022 | T20: 2025 | U20: Share 2010 | V20: Share 2015 | W20: Share 2020 | X20: Share 2025 | Z20: Medium duty trucks(private)CNG | AA20: NYMTC BPM | AB20: Transportation | AC20: On-road | AD20: Medium duty trucks | AE20: Medium duty trucks | AF20: (private) | AG20: CNG | AH20: VMT | AI20: 0 | AJ20: 0 | AK20: 0 | AL20: 0 | AM20: 0 | AN20: 0 | AO20: 0 | AP20: 0 | AQ20: 0 | AR20: 0 | AS20: 0 | AT20: 0 | AU20: 0 | AV20: 0 | AW20: 0 | AX20: 0 | AY20: 0 | AZ20: 0
B21: Heavy duty trucks | C21: 5.9405061e+08 | D21: 5.8157616e+08 | E21: 6.3980391e+08 | F21: 6.5133493e+08 | G21: 6.7169346e+08 | J21: Heavy duty trucks | K21: CNG | L21: THS | M21: CNG | P21: =(GETPIVOTDATA("Sum of CY"&$P$17,$B$14,"GPC Sector","Transportation","GPC Sub-sector","On-road","GPC Sub-sector class agg",$J21,"Fuel type",$K21))/10^6 -> 0 | Q21: =(GETPIVOTDATA("Sum of CY"&$Q$17,$B$14,"GPC Sector","Transportation","GPC Sub-sector","On-road","GPC Sub-sector class agg",$J21,"Fuel type",$K21))/10^6 -> 0 | R21: =(GETPIVOTDATA("Sum of CY"&$R$17,$B$14,"GPC Sector","Transportation","GPC Sub-sector","On-road","GPC Sub-sector class agg",$J21,"Fuel type",$K21)+GETPIVOTDATA("Sum of CY"&$R$16,$B$14,"GPC Sector","Transportation","GPC Sub-sector","On-road","GPC Sub-sector class agg",$J21,"Fuel type",$K21))/2/10^6 -> 4.3997537 | S21: =(GETPIVOTDATA("Sum of CY"&$S$17,$B$14,"GPC Sector","Transportation","GPC Sub-sector","On-road","GPC Sub-sector class agg",$J21,"Fuel type",$K21))/10^6 -> 6.3987915 | T21: =IF(R21+(S21-R21)*5/2<0,0,R21+(S21-R21)*5/2) -> 9.3973482 | U21: =P21/SUMIFS(P:P,$L:$L,$L21) -> 0 | V21: =Q21/SUMIFS(Q:Q,$L:$L,$L21) -> 0 | W21: =R21/SUMIFS(R:R,$L:$L,$L21) -> 0.0068153069 | X21: =S21/SUMIFS(S:S,$L:$L,$L21) -> 0.0095263568 | Z21: Medium duty trucks(private)Diesel | AA21: NYMTC BPM | AB21: Transportation | AC21: On-road | AD21: Medium duty trucks | AE21: Medium duty trucks | AF21: (private) | AG21: Diesel | AH21: VMT | AI21: 11279307 | AJ21: 27518399 | AK21: 40144153 | AL21: 65719096 | AM21: 82839477 | AN21: 97508882 | AO21: 1.1235775e+08 | AP21: 1.2758889e+08 | AQ21: 1.2048793e+08 | AR21: 1.1411586e+08 | AS21: 1.0810908e+08 | AT21: 1.0605027e+08 | AU21: 1.054526e+08 | AV21: 1.0180514e+08 | AW21: 1.0463898e+08 | AX21: 1.0318043e+08 | AY21: 98103289 | AZ21: 92375248
B22: CNG | C22: 0 | D22: 0 | E22: 3481673.7 | F22: 5317833.8 | G22: 6398791.5 | J22: Heavy duty trucks | K22: Diesel | L22: THS | M22: DSL | N22: DSLH | P22: =(GETPIVOTDATA("Sum of CY"&$P$17,$B$14,"GPC Sector","Transportation","GPC Sub-sector","On-road","GPC Sub-sector class agg",$J22,"Fuel type",$K22))/10^6 -> 594.05061 | Q22: =(GETPIVOTDATA("Sum of CY"&$Q$17,$B$14,"GPC Sector","Transportation","GPC Sub-sector","On-road","GPC Sub-sector class agg",$J22,"Fuel type",$K22))/10^6 -> 581.57616 | R22: =(GETPIVOTDATA("Sum of CY"&$R$17,$B$14,"GPC Sector","Transportation","GPC Sub-sector","On-road","GPC Sub-sector class agg",$J22,"Fuel type",$K22)+GETPIVOTDATA("Sum of CY"&$R$16,$B$14,"GPC Sector","Transportation","GPC Sub-sector","On-road","GPC Sub-sector class agg",$J22,"Fuel type",$K22))/2/10^6 -> 631.78651 | S22: =(GETPIVOTDATA("Sum of CY"&$S$17,$B$14,"GPC Sector","Transportation","GPC Sub-sector","On-road","GPC Sub-sector class agg",$J22,"Fuel type",$K22))/10^6 -> 651.64821 | T22: =IF(R22+(S22-R22)*5/2<0,0,R22+(S22-R22)*5/2) -> 681.44075 | U22: =P22/SUMIFS(P:P,$L:$L,$L22) -> 1 | V22: =Q22/SUMIFS(Q:Q,$L:$L,$L22) -> 1 | W22: =R22/SUMIFS(R:R,L:L,L22) -> 0.97865 | X22: =T22/SUMIFS(T:T,L:L,L22) -> 0.95858825 | Z22: Medium duty trucks(private)Electricity | AA22: NYMTC BPM | AB22: Transportation | AC22: On-road | AD22: Medium duty trucks | AE22: Medium duty trucks | AF22: (private) | AG22: Electricity | AH22: VMT | AI22: 6205269.6 | AJ22: 4937836.3 | AK22: 3706644.4 | AL22: 3511328.2 | AM22: 2600150.9 | AN22: 1676984.2 | AO22: 820134.07 | AP22: 0 | AQ22: 0 | AR22: 0 | AS22: 0 | AT22: 0 | AU22: 0 | AV22: 0 | AW22: 0 | AX22: 0 | AY22: 0 | AZ22: 0
B23: Diesel | C23: 5.9405061e+08 | D23: 5.8157616e+08 | E23: 6.2889705e+08 | F23: 6.3467597e+08 | G23: 6.5164821e+08 | J23: Heavy duty trucks | K23: Diesel Hybrid | L23: THS | M23: DSLH | P23: =(GETPIVOTDATA("Sum of CY"&$P$17,$B$14,"GPC Sector","Transportation","GPC Sub-sector","On-road","GPC Sub-sector class agg",$J23,"Fuel type",$K23))/10^6 -> 0 | Q23: =(GETPIVOTDATA("Sum of CY"&$Q$17,$B$14,"GPC Sector","Transportation","GPC Sub-sector","On-road","GPC Sub-sector class agg",$J23,"Fuel type",$K23))/10^6 -> 0 | R23: =(GETPIVOTDATA("Sum of CY"&$R$17,$B$14,"GPC Sector","Transportation","GPC Sub-sector","On-road","GPC Sub-sector class agg",$J23,"Fuel type",$K23)+GETPIVOTDATA("Sum of CY"&$R$16,$B$14,"GPC Sector","Transportation","GPC Sub-sector","On-road","GPC Sub-sector class agg",$J23,"Fuel type",$K23))/2/10^6 -> 0.92754082 | S23: =(GETPIVOTDATA("Sum of CY"&$S$17,$B$14,"GPC Sector","Transportation","GPC Sub-sector","On-road","GPC Sub-sector class agg",$J23,"Fuel type",$K23))/10^6 -> 1.3489777 | T23: =IF(R23+(S23-R23)*5/2<0,0,R23+(S23-R23)*5/2) -> 1.9811331 | U23: =P23/SUMIFS(P:P,$L:$L,$L23) -> 0 | V23: =Q23/SUMIFS(Q:Q,$L:$L,$L23) -> 0 | W23: =R23/SUMIFS(R:R,L:L,L23) -> 0.0014367794 | X23: =T23/SUMIFS(T:T,L:L,L23) -> 0.0027868761 | Z23: Medium duty trucks(private)Gasoline | AA23: NYMTC BPM | AB23: Transportation | AC23: On-road | AD23: Medium duty trucks | AE23: Medium duty trucks | AF23: (private) | AG23: Gasoline | AH23: VMT | AI23: 5.0550421e+08 | AJ23: 4.5310636e+08 | AK23: 3.9357101e+08 | AL23: 4.4877002e+08 | AM23: 4.2603506e+08 | AN23: 3.9566163e+08 | AO23: 3.7085217e+08 | AP23: 3.4990353e+08 | AQ23: 3.3939282e+08 | AR23: 3.3027735e+08 | AS23: 3.2160736e+08 | AT23: 3.2439318e+08 | AU23: 3.3180789e+08 | AV23: 3.2964821e+08 | AW23: 3.4883299e+08 | AX23: 3.5429561e+08 | AY23: 3.4714298e+08 | AZ23: 3.3702346e+08
B24: Diesel Hybrid | C24: 0 | D24: 0 | E24: 733991.13 | F24: 1121090.5 | G24: 1348977.7 | J24: Heavy duty trucks | K24: Electricity | L24: THS | M24: ELC | P24: =(GETPIVOTDATA("Sum of CY"&$P$17,$B$14,"GPC Sector","Transportation","GPC Sub-sector","On-road","GPC Sub-sector class agg",$J24,"Fuel type",$K24))/10^6 -> 0 | Q24: =(GETPIVOTDATA("Sum of CY"&$Q$17,$B$14,"GPC Sector","Transportation","GPC Sub-sector","On-road","GPC Sub-sector class agg",$J24,"Fuel type",$K24))/10^6 -> 0 | R24: =(GETPIVOTDATA("Sum of CY"&$R$17,$B$14,"GPC Sector","Transportation","GPC Sub-sector","On-road","GPC Sub-sector class agg",$J24,"Fuel type",$K24)+GETPIVOTDATA("Sum of CY"&$R$16,$B$14,"GPC Sector","Transportation","GPC Sub-sector","On-road","GPC Sub-sector class agg",$J24,"Fuel type",$K24))/2/10^6 -> 0 | S24: =(GETPIVOTDATA("Sum of CY"&$S$17,$B$14,"GPC Sector","Transportation","GPC Sub-sector","On-road","GPC Sub-sector class agg",$J24,"Fuel type",$K24))/10^6 -> 0 | T24: =IF(R24+(S24-R24)*5/2<0,0,R24+(S24-R24)*5/2) -> 0 | U24: =P24/SUMIFS(P:P,$L:$L,$L24) -> 0 | V24: =Q24/SUMIFS(Q:Q,$L:$L,$L24) -> 0 | W24: =R24/SUMIFS(R:R,L:L,L24) -> 0 | X24: =T24/SUMIFS(T:T,L:L,L24) -> 0 | Z24: Medium duty trucks(public)CNG | AA24: NYMTC BPM | AB24: Transportation | AC24: On-road | AD24: Medium duty trucks | AE24: Medium duty trucks | AF24: (public) | AG24: CNG | AH24: VMT | AI24: 203240.43 | AJ24: 479415.07 | AK24: 693742.48 | AL24: 1131591.1 | AM24: 1423438.4 | AN24: 1673275 | AO24: 1926293.1 | AP24: 2185919.8 | AQ24: 1892491.4 | AR24: 1625562.1 | AS24: 1375390.8 | AT24: 1180900.9 | AU24: 999669.21 | AV24: 804110.87 | AW24: 633860.62 | AX24: 426304.96 | AY24: 207454.24 | AZ24: 0
B25: Electricity | C25: 0 | D25: 0 | E25: 0 | F25: 0 | G25: 0 | J25: Heavy duty trucks | K25: Gasoline | L25: THS | M25: GSL | N25: GSLH | P25: =(GETPIVOTDATA("Sum of CY"&$P$17,$B$14,"GPC Sector","Transportation","GPC Sub-sector","On-road","GPC Sub-sector class agg",$J25,"Fuel type",$K25))/10^6 -> 0 | Q25: =(GETPIVOTDATA("Sum of CY"&$Q$17,$B$14,"GPC Sector","Transportation","GPC Sub-sector","On-road","GPC Sub-sector class agg",$J25,"Fuel type",$K25))/10^6 -> 0 | R25: =(GETPIVOTDATA("Sum of CY"&$R$17,$B$14,"GPC Sector","Transportation","GPC Sub-sector","On-road","GPC Sub-sector class agg",$J25,"Fuel type",$K25)+GETPIVOTDATA("Sum of CY"&$R$16,$B$14,"GPC Sector","Transportation","GPC Sub-sector","On-road","GPC Sub-sector class agg",$J25,"Fuel type",$K25))/2/10^6 -> 8.455614 | S25: =(GETPIVOTDATA("Sum of CY"&$S$17,$B$14,"GPC Sector","Transportation","GPC Sub-sector","On-road","GPC Sub-sector class agg",$J25,"Fuel type",$K25))/10^6 -> 12.297481 | T25: =IF(R25+(S25-R25)*5/2<0,0,R25+(S25-R25)*5/2) -> 18.060281 | U25: =P25/SUMIFS(P:P,$L:$L,$L25) -> 0 | V25: =Q25/SUMIFS(Q:Q,$L:$L,$L25) -> 0 | W25: =R25/SUMIFS(R:R,L:L,L25) -> 0.013097916 | X25: =T25/SUMIFS(T:T,L:L,L25) -> 0.025405545 | Z25: Medium duty trucks(public)Diesel | AA25: NYMTC BPM | AB25: Transportation | AC25: On-road | AD25: Medium duty trucks | AE25: Medium duty trucks | AF25: (public) | AG25: Diesel | AH25: VMT | AI25: 29125917 | AJ25: 27669746 | AK25: 25492232 | AL25: 30858138 | AM25: 31130769 | AN25: 30758549 | AO25: 30711878 | AP25: 30914243 | AQ25: 29858653 | AR25: 28932714 | AS25: 28054156 | AT25: 28178739 | AU25: 28703354 | AV25: 28939167 | AW25: 30498827 | AX25: 30851646 | AY25: 30108174 | AZ25: 29114935
B26: Gasoline | C26: 0 | D26: 0 | E26: 6691193.5 | F26: 10220034 | G26: 12297481 | J26: Medium duty trucks | K26: CNG | L26: TM | M26: CNG | P26: =(GETPIVOTDATA("Sum of CY"&$P$17,$B$14,"GPC Sector","Transportation","GPC Sub-sector","On-road","GPC Sub-sector class agg",$J26,"Fuel type",$K26))/10^6 -> 0.99966921 | Q26: =(GETPIVOTDATA("Sum of CY"&$Q$17,$B$14,"GPC Sector","Transportation","GPC Sub-sector","On-road","GPC Sub-sector class agg",$J26,"Fuel type",$K26))/10^6 -> 2.1859198 | R26: =(GETPIVOTDATA("Sum of CY"&$R$17,$B$14,"GPC Sector","Transportation","GPC Sub-sector","On-road","GPC Sub-sector class agg",$J26,"Fuel type",$K26)+GETPIVOTDATA("Sum of CY"&$R$16,$B$14,"GPC Sector","Transportation","GPC Sub-sector","On-road","GPC Sub-sector class agg",$J26,"Fuel type",$K26))/2/10^6 -> 1.029896 | S26: =(GETPIVOTDATA("Sum of CY"&$S$17,$B$14,"GPC Sector","Transportation","GPC Sub-sector","On-road","GPC Sub-sector class agg",$J26,"Fuel type",$K26))/10^6 -> 0.51914421 | T26: =IF(R26+(S26-R26)*5/2<0,0,R26+(S26-R26)*5/2) -> 0 | U26: =P26/SUMIFS(P:P,$L:$L,$L26) -> 0.001869385 | V26: =Q26/SUMIFS(Q:Q,$L:$L,$L26) -> 0.003761968 | W26: =R26/SUMIFS(R:R,L:L,L26) -> 0.0016907618 | X26: =T26/SUMIFS(T:T,L:L,L26) -> 0 | Z26: Medium duty trucks(public)Electricity | AA26: NYMTC BPM | AB26: Transportation | AC26: On-road | AD26: Medium duty trucks | AE26: Medium duty trucks | AF26: (public) | AG26: Electricity | AH26: VMT | AI26: 109437.16 | AJ26: 87084.344 | AK26: 65370.721 | AL26: 0 | AM26: 0 | AN26: 0 | AO26: 0 | AP26: 0 | AQ26: 0 | AR26: 0 | AS26: 0 | AT26: 0 | AU26: 0 | AV26: 0 | AW26: 0 | AX26: 0 | AY26: 0 | AZ26: 0
B27: Medium duty trucks | C27: 5.3475835e+08 | D27: 5.8105751e+08 | E27: 6.274107e+08 | F27: 5.9097663e+08 | G27: 6.3351645e+08 | J27: Medium duty trucks | K27: Diesel | L27: TM | M27: DSL | N27: DSLH | P27: =(GETPIVOTDATA("Sum of CY"&$P$17,$B$14,"GPC Sector","Transportation","GPC Sub-sector","On-road","GPC Sub-sector class agg",$J27,"Fuel type",$K27))/10^6 -> 173.46369 | Q27: =(GETPIVOTDATA("Sum of CY"&$Q$17,$B$14,"GPC Sector","Transportation","GPC Sub-sector","On-road","GPC Sub-sector class agg",$J27,"Fuel type",$K27))/10^6 -> 198.52404 | R27: =(GETPIVOTDATA("Sum of CY"&$R$17,$B$14,"GPC Sector","Transportation","GPC Sub-sector","On-road","GPC Sub-sector class agg",$J27,"Fuel type",$K27)+GETPIVOTDATA("Sum of CY"&$R$16,$B$14,"GPC Sector","Transportation","GPC Sub-sector","On-road","GPC Sub-sector class agg",$J27,"Fuel type",$K27))/2/10^6 -> 114.84175 | S27: =(GETPIVOTDATA("Sum of CY"&$S$17,$B$14,"GPC Sector","Transportation","GPC Sub-sector","On-road","GPC Sub-sector class agg",$J27,"Fuel type",$K27))/10^6 -> 78.928818 | T27: =IF(R27+(S27-R27)*5/2<0,0,R27+(S27-R27)*5/2) -> 25.059416 | U27: =P27/SUMIFS(P:P,$L:$L,$L27) -> 0.32437771 | V27: =Q27/SUMIFS(Q:Q,$L:$L,$L27) -> 0.34165988 | W27: =R27/SUMIFS(R:R,L:L,L27) -> 0.18853365 | X27: =T27/SUMIFS(T:T,L:L,L27) -> 0.03739532 | Z27: Medium duty trucks(public)Gasoline | AA27: NYMTC BPM | AB27: Transportation | AC27: On-road | AD27: Medium duty trucks | AE27: Medium duty trucks | AF27: (public) | AG27: Gasoline | AH27: VMT | AI27: 38365540 | AJ27: 34953813 | AK27: 30888269 | AL27: 35867768 | AM27: 34714445 | AN27: 32907375 | AO27: 31524379 | AP27: 30444016 | AQ27: 29449261 | AR27: 28581066 | AS27: 27756626 | AT27: 27923282 | AU27: 28487102 | AV27: 28765219 | AW27: 30361708 | AX27: 30759426 | AY27: 30063296 | AZ27: 29114935
B28: CNG | C28: 999669.21 | D28: 2185919.8 | E28: 1310439.1 | F28: 749352.93 | G28: 519144.21 | J28: Medium duty trucks | K28: Electricity | L28: TM | M28: ELC | P28: =(GETPIVOTDATA("Sum of CY"&$P$17,$B$14,"GPC Sector","Transportation","GPC Sub-sector","On-road","GPC Sub-sector class agg",$J28,"Fuel type",$K28))/10^6 -> 0 | Q28: =(GETPIVOTDATA("Sum of CY"&$Q$17,$B$14,"GPC Sector","Transportation","GPC Sub-sector","On-road","GPC Sub-sector class agg",$J28,"Fuel type",$K28))/10^6 -> 0 | R28: =(GETPIVOTDATA("Sum of CY"&$R$17,$B$14,"GPC Sector","Transportation","GPC Sub-sector","On-road","GPC Sub-sector class agg",$J28,"Fuel type",$K28)+GETPIVOTDATA("Sum of CY"&$R$16,$B$14,"GPC Sector","Transportation","GPC Sub-sector","On-road","GPC Sub-sector class agg",$J28,"Fuel type",$K28))/2/10^6 -> 4.2681244 | S28: =(GETPIVOTDATA("Sum of CY"&$S$17,$B$14,"GPC Sector","Transportation","GPC Sub-sector","On-road","GPC Sub-sector class agg",$J28,"Fuel type",$K28))/10^6 -> 6.3147068 | T28: =IF(R28+(S28-R28)*5/2<0,0,R28+(S28-R28)*5/2) -> 9.3845804 | U28: =P28/SUMIFS(P:P,$L:$L,$L28) -> 0 | V28: =Q28/SUMIFS(Q:Q,$L:$L,$L28) -> 0 | W28: =R28/SUMIFS(R:R,L:L,L28) -> 0.0070069034 | X28: =T28/SUMIFS(T:T,L:L,L28) -> 0.014004292 | Z28: Medium duty trucks(public)Gasoline Hybrid | AA28: NYMTC BPM | AB28: Transportation | AC28: On-road | AD28: Medium duty trucks | AE28: Medium duty trucks | AF28: (public) | AG28: Gasoline Hybrid | AH28: VMT | AI28: 1829163.9 | AJ28: 1455552.6 | AK28: 1092624.9 | AL28: 1035046.9 | AM28: 766451.24 | AN28: 494321.78 | AO28: 241740.79 | AP28: 0 | AQ28: 0 | AR28: 0 | AS28: 0 | AT28: 0 | AU28: 0 | AV28: 0 | AW28: 0 | AX28: 0 | AY28: 0 | AZ28: 0
B29: Diesel | C29: 1.7346369e+08 | D29: 1.9852404e+08 | E29: 1.3575274e+08 | F29: 93930763 | G29: 78928818 | J29: Medium duty trucks | K29: Gasoline | L29: TM | M29: GSL | N29: GSLAH | P29: =(GETPIVOTDATA("Sum of CY"&$P$17,$B$14,"GPC Sector","Transportation","GPC Sub-sector","On-road","GPC Sub-sector class agg",$J29,"Fuel type",$K29))/10^6 -> 360.29499 | Q29: =(GETPIVOTDATA("Sum of CY"&$Q$17,$B$14,"GPC Sector","Transportation","GPC Sub-sector","On-road","GPC Sub-sector class agg",$J29,"Fuel type",$K29))/10^6 -> 380.34755 | R29: =(GETPIVOTDATA("Sum of CY"&$R$17,$B$14,"GPC Sector","Transportation","GPC Sub-sector","On-road","GPC Sub-sector class agg",$J29,"Fuel type",$K29)+GETPIVOTDATA("Sum of CY"&$R$16,$B$14,"GPC Sector","Transportation","GPC Sub-sector","On-road","GPC Sub-sector class agg",$J29,"Fuel type",$K29))/2/10^6 -> 487.74626 | S29: =(GETPIVOTDATA("Sum of CY"&$S$17,$B$14,"GPC Sector","Transportation","GPC Sub-sector","On-road","GPC Sub-sector class agg",$J29,"Fuel type",$K29))/10^6 -> 545.83686 | T29: =IF(R29+(S29-R29)*5/2<0,0,R29+(S29-R29)*5/2) -> 632.97276 | U29: =P29/SUMIFS(P:P,$L:$L,$L29) -> 0.67375291 | V29: =Q29/SUMIFS(Q:Q,$L:$L,$L29) -> 0.65457815 | W29: =R29/SUMIFS(R:R,L:L,L29) -> 0.8007243 | X29: =T29/SUMIFS(T:T,L:L,L29) -> 0.94456387 | Z29: Passenger cars(private)CNG | AA29: NYMTC BPM | AB29: Transportation | AC29: On-road | AD29: Passenger cars | AE29: Passenger cars | AF29: (private) | AG29: CNG | AH29: VMT | AI29: 0 | AJ29: 0 | AK29: 0 | AL29: 0 | AM29: 0 | AN29: 0 | AO29: 0 | AP29: 0 | AQ29: 0 | AR29: 0 | AS29: 0 | AT29: 0 | AU29: 0 | AV29: 0 | AW29: 0 | AX29: 0 | AY29: 0 | AZ29: 0
B30: Diesel Hybrid | C30: 0 | D30: 0 | E30: 49681.19 | F30: 74984.536 | G30: 87753.153 | J30: Medium duty trucks | K30: Gasoline Hybrid | L30: TM | M30: GSLAH | P30: =(GETPIVOTDATA("Sum of CY"&$P$17,$B$14,"GPC Sector","Transportation","GPC Sub-sector","On-road","GPC Sub-sector class agg",$J30,"Fuel type",$K30))/10^6 -> 0 | Q30: =(GETPIVOTDATA("Sum of CY"&$Q$17,$B$14,"GPC Sector","Transportation","GPC Sub-sector","On-road","GPC Sub-sector class agg",$J30,"Fuel type",$K30))/10^6 -> 0 | R30: =(GETPIVOTDATA("Sum of CY"&$R$17,$B$14,"GPC Sector","Transportation","GPC Sub-sector","On-road","GPC Sub-sector class agg",$J30,"Fuel type",$K30)+GETPIVOTDATA("Sum of CY"&$R$16,$B$14,"GPC Sector","Transportation","GPC Sub-sector","On-road","GPC Sub-sector class agg",$J30,"Fuel type",$K30))/2/10^6 -> 1.2452997 | S30: =(GETPIVOTDATA("Sum of CY"&$S$17,$B$14,"GPC Sector","Transportation","GPC Sub-sector","On-road","GPC Sub-sector class agg",$J30,"Fuel type",$K30))/10^6 -> 1.8291639 | T30: =IF(R30+(S30-R30)*5/2<0,0,R30+(S30-R30)*5/2) -> 2.7049601 | U30: =P30/SUMIFS(P:P,$L:$L,$L30) -> 0 | V30: =Q30/SUMIFS(Q:Q,$L:$L,$L30) -> 0 | W30: =R30/SUMIFS(R:R,L:L,L30) -> 0.0020443863 | X30: =T30/SUMIFS(T:T,L:L,L30) -> 0.0040365206 | Z30: Passenger cars(private)Diesel | AA30: NYMTC BPM | AB30: Transportation | AC30: On-road | AD30: Passenger cars | AE30: Passenger cars | AF30: (private) | AG30: Diesel | AH30: VMT | AI30: 1.35695e+08 | AJ30: 1.4437044e+08 | AK30: 1.3173031e+08 | AL30: 1.8782774e+08 | AM30: 2.0056401e+08 | AN30: 2.1055994e+08 | AO30: 2.2449686e+08 | AP30: 2.3373521e+08 | AQ30: 2.1338913e+08 | AR30: 2.0071866e+08 | AS30: 1.8734238e+08 | AT30: 1.7681504e+08 | AU30: 1.6846715e+08 | AV30: 1.477483e+08 | AW30: 1.3670816e+08 | AX30: 1.2828366e+08 | AY30: 1.1487412e+08 | AZ30: 1.0151048e+08
B31: Electricity | C31: 0 | D31: 0 | E31: 3511328.2 | F31: 5024920.7 | G31: 6314706.8 | J31: Buses | K31: Diesel | L31: TB | M31: DSL | N31: DSLAH | P31: =(GETPIVOTDATA("Sum of CY"&$P$17,$B$14,"GPC Sector","Transportation","GPC Sub-sector","On-road","GPC Sub-sector class agg",$J31,"Fuel type",$K31))/10^6 -> 58.802169 | Q31: =(GETPIVOTDATA("Sum of CY"&$Q$17,$B$14,"GPC Sector","Transportation","GPC Sub-sector","On-road","GPC Sub-sector class agg",$J31,"Fuel type",$K31))/10^6 -> 66.295314 | R31: =(GETPIVOTDATA("Sum of CY"&$R$17,$B$14,"GPC Sector","Transportation","GPC Sub-sector","On-road","GPC Sub-sector class agg",$J31,"Fuel type",$K31)+GETPIVOTDATA("Sum of CY"&$R$16,$B$14,"GPC Sector","Transportation","GPC Sub-sector","On-road","GPC Sub-sector class agg",$J31,"Fuel type",$K31))/2/10^6 -> 39.288055 | S31: =(GETPIVOTDATA("Sum of CY"&$S$17,$B$14,"GPC Sector","Transportation","GPC Sub-sector","On-road","GPC Sub-sector class agg",$J31,"Fuel type",$K31))/10^6 -> 27.085733 | T31: =IF(R31+(S31-R31)*5/2<0,0,R31+(S31-R31)*5/2) -> 8.7822489 | U31: =P31/SUMIFS(P:P,$L:$L,$L31) -> 1 | V31: =Q31/SUMIFS(Q:Q,$L:$L,$L31) -> 1 | W31: =R31/SUMIFS(R:R,L:L,L31) -> 0.532461 | X31: =T31/SUMIFS(T:T,L:L,L31) -> 0.10456195 | Z31: Passenger cars(private)Diesel Hybrid | AA31: NYMTC BPM | AB31: Transportation | AC31: On-road | AD31: Passenger cars | AE31: Passenger cars | AF31: (private) | AG31: Diesel Hybrid | AH31: VMT | AI31: 0 | AJ31: 0 | AK31: 0 | AL31: 0 | AM31: 0 | AN31: 0 | AO31: 0 | AP31: 0 | AQ31: 0 | AR31: 0 | AS31: 0 | AT31: 0 | AU31: 0 | AV31: 0 | AW31: 0 | AX31: 0 | AY31: 0 | AZ31: 0
B32: Gasoline | C32: 3.6029499e+08 | D32: 3.8034755e+08 | E32: 4.8575147e+08 | F32: 4.8974106e+08 | G32: 5.4583686e+08 | J32: Buses | K32: Electricity | L32: TB | M32: ELC | P32: =(GETPIVOTDATA("Sum of CY"&$P$17,$B$14,"GPC Sector","Transportation","GPC Sub-sector","On-road","GPC Sub-sector class agg",$J32,"Fuel type",$K32))/10^6 -> 0 | Q32: =(GETPIVOTDATA("Sum of CY"&$Q$17,$B$14,"GPC Sector","Transportation","GPC Sub-sector","On-road","GPC Sub-sector class agg",$J32,"Fuel type",$K32))/10^6 -> 0 | R32: =(GETPIVOTDATA("Sum of CY"&$R$17,$B$14,"GPC Sector","Transportation","GPC Sub-sector","On-road","GPC Sub-sector class agg",$J32,"Fuel type",$K32)+GETPIVOTDATA("Sum of CY"&$R$16,$B$14,"GPC Sector","Transportation","GPC Sub-sector","On-road","GPC Sub-sector class agg",$J32,"Fuel type",$K32))/2/10^6 -> 0 | S32: =(GETPIVOTDATA("Sum of CY"&$S$17,$B$14,"GPC Sector","Transportation","GPC Sub-sector","On-road","GPC Sub-sector class agg",$J32,"Fuel type",$K32))/10^6 -> 0.023359436 | T32: =IF(R32+(S32-R32)*5/2<0,0,R32+(S32-R32)*5/2) -> 0.058398589 | U32: =P32/SUMIFS(P:P,$L:$L,$L32) -> 0 | V32: =Q32/SUMIFS(Q:Q,$L:$L,$L32) -> 0 | W32: =R32/SUMIFS(R:R,L:L,L32) -> 0 | X32: =T32/SUMIFS(T:T,L:L,L32) -> 0.00069529686 | Z32: Passenger cars(private)Electricity | AA32: NYMTC BPM | AB32: Transportation | AC32: On-road | AD32: Passenger cars | AE32: Passenger cars | AF32: (private) | AG32: Electricity | AH32: VMT | AI32: 5.1605221e+08 | AJ32: 4.2124991e+08 | AK32: 2.9089884e+08 | AL32: 3.0556262e+08 | AM32: 2.2896976e+08 | AN32: 1.5384059e+08 | AO32: 84861122 | AP32: 0 | AQ32: 0 | AR32: 0 | AS32: 0 | AT32: 0 | AU32: 0 | AV32: 0 | AW32: 0 | AX32: 0 | AY32: 0 | AZ32: 0
B33: Gasoline Hybrid | C33: 0 | D33: 0 | E33: 1035046.9 | F33: 1455552.6 | G33: 1829163.9 | J33: Buses | K33: Gasoline | L33: TB | M33: GSL | N33: GSLAH | P33: =(GETPIVOTDATA("Sum of CY"&$P$17,$B$14,"GPC Sector","Transportation","GPC Sub-sector","On-road","GPC Sub-sector class agg",$J33,"Fuel type",$K33))/10^6 -> 0 | Q33: =(GETPIVOTDATA("Sum of CY"&$Q$17,$B$14,"GPC Sector","Transportation","GPC Sub-sector","On-road","GPC Sub-sector class agg",$J33,"Fuel type",$K33))/10^6 -> 0 | R33: =(GETPIVOTDATA("Sum of CY"&$R$17,$B$14,"GPC Sector","Transportation","GPC Sub-sector","On-road","GPC Sub-sector class agg",$J33,"Fuel type",$K33)+GETPIVOTDATA("Sum of CY"&$R$16,$B$14,"GPC Sector","Transportation","GPC Sub-sector","On-road","GPC Sub-sector class agg",$J33,"Fuel type",$K33))/2/10^6 -> 34.497734 | S33: =(GETPIVOTDATA("Sum of CY"&$S$17,$B$14,"GPC Sector","Transportation","GPC Sub-sector","On-road","GPC Sub-sector class agg",$J33,"Fuel type",$K33))/10^6 -> 50.75873 | T33: =IF(R33+(S33-R33)*5/2<0,0,R33+(S33-R33)*5/2) -> 75.150223 | U33: =P33/SUMIFS(P:P,$L:$L,$L33) -> 0 | V33: =Q33/SUMIFS(Q:Q,$L:$L,$L33) -> 0 | W33: =R33/SUMIFS(R:R,L:L,L33) -> 0.467539 | X33: =T33/SUMIFS(T:T,L:L,L33) -> 0.89474276 | Z33: Passenger cars(private)Fuel Cell | AA33: NYMTC BPM | AB33: Transportation | AC33: On-road | AD33: Passenger cars | AE33: Passenger cars | AF33: (private) | AG33: Fuel Cell | AH33: VMT | AI33: 0 | AJ33: 0 | AK33: 0 | AL33: 0 | AM33: 0 | AN33: 0 | AO33: 0 | AP33: 0 | AQ33: 0 | AR33: 0 | AS33: 0 | AT33: 0 | AU33: 0 | AV33: 0 | AW33: 0 | AX33: 0 | AY33: 0 | AZ33: 0
B34: Passenger cars | C34: 1.9657033e+10 | D34: 1.9662888e+10 | E34: 2.1523925e+10 | F34: 2.0188206e+10 | G34: 2.1323592e+10 | J34: Passenger cars | K34: CNG | L34: TL | M34: CNG | P34: =(GETPIVOTDATA("Sum of CY"&$P$17,$B$14,"GPC Sector","Transportation","GPC Sub-sector","On-road","GPC Sub-sector class agg",$J34,"Fuel type",$K34))/10^6 -> 0 | Q34: =(GETPIVOTDATA("Sum of CY"&$Q$17,$B$14,"GPC Sector","Transportation","GPC Sub-sector","On-road","GPC Sub-sector class agg",$J34,"Fuel type",$K34))/10^6 -> 0 | R34: =(GETPIVOTDATA("Sum of CY"&$R$17,$B$14,"GPC Sector","Transportation","GPC Sub-sector","On-road","GPC Sub-sector class agg",$J34,"Fuel type",$K34)+GETPIVOTDATA("Sum of CY"&$R$16,$B$14,"GPC Sector","Transportation","GPC Sub-sector","On-road","GPC Sub-sector class agg",$J34,"Fuel type",$K34))/2/10^6 -> 0 | S34: =(GETPIVOTDATA("Sum of CY"&$S$17,$B$14,"GPC Sector","Transportation","GPC Sub-sector","On-road","GPC Sub-sector class agg",$J34,"Fuel type",$K34))/10^6 -> 0 | T34: =IF(R34+(S34-R34)*5/2<0,0,R34+(S34-R34)*5/2) -> 0 | U34: =P34/SUMIFS(P:P,$L:$L,$L34) -> 0 | V34: =Q34/SUMIFS(Q:Q,$L:$L,$L34) -> 0 | W34: =R34/SUMIFS(R:R,L:L,L34) -> 0 | X34: =T34/SUMIFS(T:T,L:L,L34) -> 0 | Z34: Passenger cars(private)Gasoline | AA34: NYMTC BPM | AB34: Transportation | AC34: On-road | AD34: Passenger cars | AE34: Passenger cars | AF34: (private) | AG34: Gasoline | AH34: VMT | AI34: 1.941655e+10 | AJ34: 1.8575339e+10 | AK34: 1.5425812e+10 | AL34: 2.0215104e+10 | AM34: 2.0000031e+10 | AN34: 1.9586529e+10 | AO34: 1.9592916e+10 | AP34: 1.92342e+10 | AQ34: 1.8617848e+10 | AR34: 1.8632353e+10 | AS34: 1.8575946e+10 | AT34: 1.8811296e+10 | AU34: 1.9330346e+10 | AV34: 1.839386e+10 | AW34: 1.8596344e+10 | AX34: 1.922786e+10 | AY34: 1.9165763e+10 | AZ34: 1.909094e+10
B35: CNG | C35: 0 | D35: 0 | E35: 0 | F35: 0 | G35: 0 | J35: Passenger cars | K35: Diesel | L35: TL | M35: DSL | N35: DHEV | P35: =(GETPIVOTDATA("Sum of CY"&$P$17,$B$14,"GPC Sector","Transportation","GPC Sub-sector","On-road","GPC Sub-sector class agg",$J35,"Fuel type",$K35))/10^6 -> 168.46715 | Q35: =(GETPIVOTDATA("Sum of CY"&$Q$17,$B$14,"GPC Sector","Transportation","GPC Sub-sector","On-road","GPC Sub-sector class agg",$J35,"Fuel type",$K35))/10^6 -> 233.73521 | R35: =(GETPIVOTDATA("Sum of CY"&$R$17,$B$14,"GPC Sector","Transportation","GPC Sub-sector","On-road","GPC Sub-sector class agg",$J35,"Fuel type",$K35)+GETPIVOTDATA("Sum of CY"&$R$16,$B$14,"GPC Sector","Transportation","GPC Sub-sector","On-road","GPC Sub-sector class agg",$J35,"Fuel type",$K35))/2/10^6 -> 166.58711 | S35: =(GETPIVOTDATA("Sum of CY"&$S$17,$B$14,"GPC Sector","Transportation","GPC Sub-sector","On-road","GPC Sub-sector class agg",$J35,"Fuel type",$K35))/10^6 -> 136.39804 | T35: =IF(R35+(S35-R35)*5/2<0,0,R35+(S35-R35)*5/2) -> 91.114447 | U35: =P35/SUMIFS(P:P,$L:$L,$L35) -> 0.0085703245 | V35: =Q35/SUMIFS(Q:Q,$L:$L,$L35) -> 0.011887125 | W35: =R35/SUMIFS(R:R,L:L,L35) -> 0.0079874655 | X35: =T35/SUMIFS(T:T,L:L,L35) -> 0.0041368872 | Z35: Passenger cars(private)Gasoline Hybrid | AA35: NYMTC BPM | AB35: Transportation | AC35: On-road | AD35: Passenger cars | AE35: Passenger cars | AF35: (private) | AG35: Gasoline Hybrid | AH35: VMT | AI35: 1.1234244e+09 | AJ35: 9.2239951e+08 | AK35: 6.4207891e+08 | AL35: 6.8232775e+08 | AM35: 5.2082815e+08 | AN35: 3.6201683e+08 | AO35: 2.1696355e+08 | AP35: 73260466 | AQ35: 63748539 | AR35: 56644696 | AS35: 49357650 | AT35: 42793719 | AU35: 36603697 | AV35: 27832626 | AW35: 21080315 | AX35: 0 | AY35: 0 | AZ35: 0
B36: Diesel | C36: 1.6846715e+08 | D36: 2.3373521e+08 | E36: 1.8823325e+08 | F36: 1.4494096e+08 | G36: 1.3639804e+08 | J36: Passenger cars | K36: Diesel Hybrid | L36: TL | M36: DHEV | P36: =(GETPIVOTDATA("Sum of CY"&$P$17,$B$14,"GPC Sector","Transportation","GPC Sub-sector","On-road","GPC Sub-sector class agg",$J36,"Fuel type",$K36))/10^6 -> 0 | Q36: =(GETPIVOTDATA("Sum of CY"&$Q$17,$B$14,"GPC Sector","Transportation","GPC Sub-sector","On-road","GPC Sub-sector class agg",$J36,"Fuel type",$K36))/10^6 -> 0 | R36: =(GETPIVOTDATA("Sum of CY"&$R$17,$B$14,"GPC Sector","Transportation","GPC Sub-sector","On-road","GPC Sub-sector class agg",$J36,"Fuel type",$K36)+GETPIVOTDATA("Sum of CY"&$R$16,$B$14,"GPC Sector","Transportation","GPC Sub-sector","On-road","GPC Sub-sector class agg",$J36,"Fuel type",$K36))/2/10^6 -> 0 | S36: =(GETPIVOTDATA("Sum of CY"&$S$17,$B$14,"GPC Sector","Transportation","GPC Sub-sector","On-road","GPC Sub-sector class agg",$J36,"Fuel type",$K36))/10^6 -> 0 | T36: =IF(R36+(S36-R36)*5/2<0,0,R36+(S36-R36)*5/2) -> 0 | U36: =P36/SUMIFS(P:P,$L:$L,$L36) -> 0 | V36: =Q36/SUMIFS(Q:Q,$L:$L,$L36) -> 0 | W36: =R36/SUMIFS(R:R,L:L,L36) -> 0 | X36: =T36/SUMIFS(T:T,L:L,L36) -> 0 | Z36: Passenger cars(public)Diesel | AA36: NYMTC BPM | AB36: Transportation | AC36: On-road | AD36: Passenger cars | AE36: Passenger cars | AF36: (public) | AG36: Diesel | AH36: VMT | AI36: 703039.39 | AJ36: 570519.24 | AK36: 390768.72 | AL36: 405511.25 | AM36: 297871.47 | AN36: 192538.86 | AO36: 0 | AP36: 0 | AQ36: 0 | AR36: 0 | AS36: 0 | AT36: 0 | AU36: 0 | AV36: 0 | AW36: 0 | AX36: 0 | AY36: 0 | AZ36: 0
B37: Diesel Hybrid | C37: 0 | D37: 0 | E37: 0 | F37: 0 | G37: 0 | J37: Passenger cars | K37: Electricity | L37: TL | M37: ELC | P37: =(GETPIVOTDATA("Sum of CY"&$P$17,$B$14,"GPC Sector","Transportation","GPC Sub-sector","On-road","GPC Sub-sector class agg",$J37,"Fuel type",$K37))/10^6 -> 0.90905831 | Q37: =(GETPIVOTDATA("Sum of CY"&$Q$17,$B$14,"GPC Sector","Transportation","GPC Sub-sector","On-road","GPC Sub-sector class agg",$J37,"Fuel type",$K37))/10^6 -> 1.8133946 | R37: =(GETPIVOTDATA("Sum of CY"&$R$17,$B$14,"GPC Sector","Transportation","GPC Sub-sector","On-road","GPC Sub-sector class agg",$J37,"Fuel type",$K37)+GETPIVOTDATA("Sum of CY"&$R$16,$B$14,"GPC Sector","Transportation","GPC Sub-sector","On-road","GPC Sub-sector class agg",$J37,"Fuel type",$K37))/2/10^6 -> 381.67212 | S37: =(GETPIVOTDATA("Sum of CY"&$S$17,$B$14,"GPC Sector","Transportation","GPC Sub-sector","On-road","GPC Sub-sector class agg",$J37,"Fuel type",$K37))/10^6 -> 541.56249 | T37: =IF(R37+(S37-R37)*5/2<0,0,R37+(S37-R37)*5/2) -> 781.39806 | U37: =P37/SUMIFS(P:P,$L:$L,$L37) -> 4.6245957e-05 | V37: =Q37/SUMIFS(Q:Q,$L:$L,$L37) -> 9.2224224e-05 | W37: =R37/SUMIFS(R:R,L:L,L37) -> 0.018300293 | X37: =T37/SUMIFS(T:T,L:L,L37) -> 0.03547797 | Z37: Passenger cars(public)Electricity | AA37: NYMTC BPM | AB37: Transportation | AC37: On-road | AD37: Passenger cars | AE37: Passenger cars | AF37: (public) | AG37: Electricity | AH37: VMT | AI37: 25510287 | AJ37: 20967448 | AK37: 14616172 | AL37: 15564262 | AM37: 11918473 | AN37: 8331686 | AO37: 5058829.9 | AP37: 1813394.6 | AQ37: 1583208.3 | AR37: 1406782.3 | AS37: 1225806.5 | AT37: 1062789.4 | AU37: 909058.31 | AV37: 726947.08 | AW37: 550585.47 | AX37: 379090.94 | AY37: 188719.02 | AZ37: 0
B38: Electricity | C38: 909058.31 | D38: 1813394.6 | E38: 3.2112688e+08 | F38: 4.4221735e+08 | G38: 5.4156249e+08 | J38: Passenger cars | K38: Fuel Cell | L38: TL | M38: FCH | P38: =(GETPIVOTDATA("Sum of CY"&$P$17,$B$14,"GPC Sector","Transportation","GPC Sub-sector","On-road","GPC Sub-sector class agg",$J38,"Fuel type",$K38))/10^6 -> 0 | Q38: =(GETPIVOTDATA("Sum of CY"&$Q$17,$B$14,"GPC Sector","Transportation","GPC Sub-sector","On-road","GPC Sub-sector class agg",$J38,"Fuel type",$K38))/10^6 -> 0 | R38: =(GETPIVOTDATA("Sum of CY"&$R$17,$B$14,"GPC Sector","Transportation","GPC Sub-sector","On-road","GPC Sub-sector class agg",$J38,"Fuel type",$K38)+GETPIVOTDATA("Sum of CY"&$R$16,$B$14,"GPC Sector","Transportation","GPC Sub-sector","On-road","GPC Sub-sector class agg",$J38,"Fuel type",$K38))/2/10^6 -> 0 | S38: =(GETPIVOTDATA("Sum of CY"&$S$17,$B$14,"GPC Sector","Transportation","GPC Sub-sector","On-road","GPC Sub-sector class agg",$J38,"Fuel type",$K38))/10^6 -> 0 | T38: =IF(R38+(S38-R38)*5/2<0,0,R38+(S38-R38)*5/2) -> 0 | U38: =P38/SUMIFS(P:P,$L:$L,$L38) -> 0 | V38: =Q38/SUMIFS(Q:Q,$L:$L,$L38) -> 0 | W38: =R38/SUMIFS(R:R,L:L,L38) -> 0 | X38: =T38/SUMIFS(T:T,L:L,L38) -> 0 | Z38: Passenger cars(public)Gasoline | AA38: NYMTC BPM | AB38: Transportation | AC38: On-road | AD38: Passenger cars | AE38: Passenger cars | AF38: (public) | AG38: Gasoline | AH38: VMT | AI38: 60193563 | AJ38: 64760164 | AK38: 59615495 | AL38: 85616592 | AM38: 91969012 | AN38: 97039031 | AO38: 1.0390693e+08 | AP38: 1.0858461e+08 | AQ38: 1.0625847e+08 | AR38: 1.074871e+08 | AS38: 1.0830146e+08 | AT38: 1.1082517e+08 | AU38: 1.1506377e+08 | AV38: 1.1632625e+08 | AW38: 1.1879588e+08 | AX38: 1.2405676e+08 | AY38: 1.2487605e+08 | AZ38: 1.2560096e+08
B39: Fuel Cell | C39: 0 | D39: 0 | E39: 0 | F39: 0 | G39: 0 | J39: Passenger cars | K39: Gasoline | L39: TL | M39: GSL | N39: G*HEV | P39: =(GETPIVOTDATA("Sum of CY"&$P$17,$B$14,"GPC Sector","Transportation","GPC Sub-sector","On-road","GPC Sub-sector class agg",$J39,"Fuel type",$K39))/10^6 -> 19445.41 | Q39: =(GETPIVOTDATA("Sum of CY"&$Q$17,$B$14,"GPC Sector","Transportation","GPC Sub-sector","On-road","GPC Sub-sector class agg",$J39,"Fuel type",$K39))/10^6 -> 19342.785 | R39: =(GETPIVOTDATA("Sum of CY"&$R$17,$B$14,"GPC Sector","Transportation","GPC Sub-sector","On-road","GPC Sub-sector class agg",$J39,"Fuel type",$K39)+GETPIVOTDATA("Sum of CY"&$R$16,$B$14,"GPC Sector","Transportation","GPC Sub-sector","On-road","GPC Sub-sector class agg",$J39,"Fuel type",$K39))/2/10^6 -> 19470.41 | S39: =(GETPIVOTDATA("Sum of CY"&$S$17,$B$14,"GPC Sector","Transportation","GPC Sub-sector","On-road","GPC Sub-sector class agg",$J39,"Fuel type",$K39))/10^6 -> 19476.743 | T39: =IF(R39+(S39-R39)*5/2<0,0,R39+(S39-R39)*5/2) -> 19486.244 | U39: =P39/SUMIFS(P:P,$L:$L,$L39) -> 0.98923424 | V39: =Q39/SUMIFS(Q:Q,$L:$L,$L39) -> 0.98372044 | W39: =R39/SUMIFS(R:R,L:L,L39) -> 0.93356102 | X39: =T39/SUMIFS(T:T,L:L,L39) -> 0.88473777 | Z39: Passenger cars(public)Gasoline Hybrid | AA39: NYMTC BPM | AB39: Transportation | AC39: On-road | AD39: Passenger cars | AE39: Passenger cars | AF39: (public) | AG39: Gasoline Hybrid | AH39: VMT | AI39: 45463214 | AJ39: 38548714 | AK39: 27990497 | AL39: 31516999 | AM39: 26175605 | AN39: 20829477 | AO39: 16124534 | AP39: 11294162 | AQ39: 9827839.5 | AR39: 8732667.2 | AS39: 7609251.2 | AT39: 6597314.8 | AU39: 5643022 | AV39: 4512558 | AW39: 3417785.1 | AX39: 2353224.7 | AY39: 1171482.1 | AZ39: 0
B40: Gasoline | C40: 1.944541e+10 | D40: 1.9342785e+10 | E40: 2.030072e+10 | F40: 1.8640099e+10 | G40: 1.9476743e+10 | J40: Passenger cars | K40: Gasoline Hybrid | L40: TL | M40: G*HEV | P40: =(GETPIVOTDATA("Sum of CY"&$P$17,$B$14,"GPC Sector","Transportation","GPC Sub-sector","On-road","GPC Sub-sector class agg",$J40,"Fuel type",$K40))/10^6 -> 42.246719 | Q40: =(GETPIVOTDATA("Sum of CY"&$Q$17,$B$14,"GPC Sector","Transportation","GPC Sub-sector","On-road","GPC Sub-sector class agg",$J40,"Fuel type",$K40))/10^6 -> 84.554628 | R40: =(GETPIVOTDATA("Sum of CY"&$R$17,$B$14,"GPC Sector","Transportation","GPC Sub-sector","On-road","GPC Sub-sector class agg",$J40,"Fuel type",$K40)+GETPIVOTDATA("Sum of CY"&$R$16,$B$14,"GPC Sector","Transportation","GPC Sub-sector","On-road","GPC Sub-sector class agg",$J40,"Fuel type",$K40))/2/10^6 -> 837.39649 | S40: =(GETPIVOTDATA("Sum of CY"&$S$17,$B$14,"GPC Sector","Transportation","GPC Sub-sector","On-road","GPC Sub-sector class agg",$J40,"Fuel type",$K40))/10^6 -> 1168.8876 | T40: =IF(R40+(S40-R40)*5/2<0,0,R40+(S40-R40)*5/2) -> 1666.1243 | U40: =P40/SUMIFS(P:P,$L:$L,$L40) -> 0.002149191 | V40: =Q40/SUMIFS(Q:Q,$L:$L,$L40) -> 0.004300214 | W40: =R40/SUMIFS(R:R,L:L,L40) -> 0.040151221 | X40: =T40/SUMIFS(T:T,L:L,L40) -> 0.075647371 | Z40: School Bus(private)Diesel | AA40: NYMTC BPM | AB40: Transportation | AC40: On-road | AD40: School Bus | AE40: Buses | AF40: (private) | AG40: Diesel | AH40: VMT | AI40: 27085733 | AJ40: 33218126 | AK40: 39431287 | AL40: 45357985 | AM40: 51012827 | AN40: 56388434 | AO40: 61478026 | AP40: 66295314 | AQ40: 64796685 | AR40: 63298056 | AS40: 61799427 | AT40: 60300798 | AU40: 58802169 | AV40: 57303540 | AW40: 55804912 | AX40: 54306283 | AY40: 52807654 | AZ40: 51309025
B41: Gasoline Hybrid | C41: 42246719 | D41: 84554628 | E41: 7.1384475e+08 | F41: 9.6094823e+08 | G41: 1.1688876e+09 | Z41: School Bus(private)Electricity | AA41: NYMTC BPM | AB41: Transportation | AC41: On-road | AD41: School Bus | AE41: Buses | AF41: (private) | AG41: Electricity | AH41: VMT | AI41: 23359.435 | AJ41: 0 | AK41: 0 | AL41: 0 | AM41: 0 | AN41: 0 | AO41: 0 | AP41: 0 | AQ41: 0 | AR41: 0 | AS41: 0 | AT41: 0 | AU41: 0 | AV41: 0 | AW41: 0 | AX41: 0 | AY41: 0 | AZ41: 0
